2020-11-09T11:25:23.30311 btcusdt {"stream":"btcusdt@depth@100ms","data":{"e":"depthUpdate","E":1604921123295,"s":"BTCUSDT","U":6511127683,"u":6511127704,"b":[["15509.36000000","0.00000000"],["15508.21000000","0.00000000"],["15506.84000000","0.16429600"],["15505.85000000","0.00000000"],["15504.25000000","0.00000000"],["15504.04000000","0.00000000"],["15503.11000000","1.50000000"],["15501.65000000","0.50421800"],["15498.42000000","0.00000000"],["15477.24000000","0.00000000"]],"a":[["15512.92000000","1.44906600"],["15514.80000000","0.00128800"],["15514.81000000","7.39699400"],["15519.22000000","0.09621800"],["15524.47000000","0.40548900"],["15525.31000000","1.00000000"],["15525.62000000","0.00000000"],["15526.38000000","0.00000000"],["15526.63000000","1.50000000"],["15528.36000000","0.00000000"],["15529.69000000","0.00000000"],["15564.14000000","0.00000000"]]}}
2020-11-09T11:25:23.40414 btcusdt {"stream":"btcusdt@depth@100ms","data":{"e":"depthUpdate","E":1604921123395,"s":"BTCUSDT","U":6511127705,"u":6511127730,"b":[["15512.44000000","0.12800000"],["15511.80000000","0.01269200"],["15511.40000000","0.00727200"],["15509.68000000","0.00000000"],["15505.64000000","0.10000000"],["15504.28000000","0.01900000"],["15503.64000000","0.00000000"],["15501.86000000","0.00000000"],["15501.63000000","0.10084100"],["15495.77000000","1.12448200"],["15474.39000000","0.03100000"],["15437.41000000","0.00000000"]],"a":[["15512.92000000","1.50861800"],["15515.00000000","2.00588500"],["15515.61000000","0.01334200"],["15515.69000000","0.11427900"],["15516.13000000","0.00000000"],["15517.57000000","0.00000000"],["15521.10000000","0.00000000"],["15522.90000000","0.01382400"],["15522.98000000","0.10000000"],["15523.70000000","0.30000000"],["15525.03000000","1.25000000"],["15526.67000000","0.00000000"],["15561.26000000","0.03100000"]]}}
2020-11-09T11:25:23.50209 btcusdt {"stream":"btcusdt@depth@100ms","data":{"e":"depthUpdate","E":1604921123495,"s":"BTCUSDT","U":6511127731,"u":6511127744,"b":[["15509.17000000","0.11427900"],["15499.31000000","0.06726500"],["15430.15000000","0.00000000"],["15202.65000000","0.00174700"]],"a":[["15512.92000000","1.33853400"],["15513.12000000","0.00000000"],["15514.68000000","0.16373500"],["15514.69000000","1.97905100"],["15514.81000000","7.30000000"],["15519.94000000","0.06712600"],["15549.31000000","0.00000000"]]}}
2020-11-09T11:25:23.60248 btcusdt {"stream":"btcusdt@depth@100ms","data":{"e":"depthUpdate","E":1604921123595,"s":"BTCUSDT","U":6511127745,"u":6511127757,"b":[["15505.31000000","0.00000000"],["15504.67000000","0.00000000"],["15503.78000000","0.00000000"],["15502.44000000","0.03361400"],["15420.00000000","0.97585000"]],"a":[["15512.92000000","1.10736300"],["15514.68000000","0.26373500"],["15514.69000000","1.97905100"],["15525.30000000","0.12882200"],["15531.94000000","0.00000000"]]}}
2020-11-09T11:25:23.70322 btcusdt {"stream":"btcusdt@depth@100ms","data":{"e":"depthUpdate","E":1604921123695,"s":"BTCUSDT","U":6511127758,"u":6511127768,"b":[["15512.91000000","2.73253300"],["15505.01000000","0.20000000"],["15502.87000000","0.06717900"],["15501.09000000","0.31855700"]],"a":[["15512.92000000","0.75402400"],["15514.69000000","2.30486600"],["15523.26000000","1.25000000"],["15525.03000000","0.00000000"],["15538.64000000","0.15910000"],["15540.32000000","0.70982700"]]}}
2020-11-09T11:25:23.80407 btcusdt {"stream":"btcusdt@depth@100ms","data":{"e":"depthUpdate","E":1604921123795,"s":"BTCUSDT","U":6511127769,"u":6511127780,"b":[["15511.80000000","0.00000000"],["15510.83000000","0.01276400"],["15506.84000000","0.00000000"],["15505.99000000","0.16429600"],["15504.39000000","0.42392600"],["8888.00000000","6.23817800"]],"a":[["15512.92000000","0.70818800"],["15515.58000000","0.01284300"],["15515.61000000","0.00000000"],["15515.90000000","0.00000000"]]}}
2020-11-09T11:25:23.90293 btcusdt {"stream":"btcusdt@depth@100ms","data":{"e":"depthUpdate","E":1604921123895,"s":"BTCUSDT","U":6511127781,"u":6511127791,"b":[["15511.40000000","0.00000000"],["15509.32000000","0.00956800"],["15507.38000000","0.00000000"],["15501.66000000","0.02236400"],["15435.34000000","0.00647800"]],"a":[["15513.38000000","0.00958900"],["15515.27000000","0.00000000"],["15523.09000000","0.02968800"],["15525.52000000","0.00000000"],["15527.75000000","0.00000000"],["15543.49000000","0.00000000"]]}}
2020-11-09T11:25:24.00307 btcusdt {"stream":"btcusdt@depth@100ms","data":{"e":"depthUpdate","E":1604921123995,"s":"BTCUSDT","U":6511127792,"u":6511127800,"b":[["15512.44000000","0.00000000"],["15508.22000000","0.06731400"],["15507.60000000","0.05000000"],["15506.84000000","0.03626500"],["15506.24000000","0.32100000"],["15505.71000000","0.00000000"],["15467.56000000","0.00000000"]],"a":[["15517.74000000","0.32100000"],["15564.94000000","0.00000000"]]}}
2020-11-09T11:25:24.11242 btcusdt {"stream":"btcusdt@depth@100ms","data":{"e":"depthUpdate","E":1604921124095,"s":"BTCUSDT","U":6511127801,"u":6511127810,"b":[["15509.57000000","0.50000000"],["15508.49000000","0.10823000"]],"a":[["15512.92000000","0.68844400"],["15515.00000000","2.00000000"],["15516.66000000","0.50000000"],["15523.26000000","1.25000000"],["15523.39000000","0.00000000"],["15553.78000000","0.00097800"]]}}
2020-11-09T11:25:24.20275 btcusdt {"stream":"btcusdt@depth@100ms","data":{"e":"depthUpdate","E":1604921124196,"s":"BTCUSDT","U":6511127811,"u":6511127817,"b":[["15505.01000000","0.00000000"],["15476.21000000","0.00000000"],["15428.81000000","0.24000000"],["15399.00000000","0.48510300"]],"a":[["15517.98000000","0.01000000"],["15517.99000000","0.05000000"],["15525.25000000","0.24000000"]]}}
2020-11-09T11:25:24.30222 btcusdt {"stream":"btcusdt@depth@100ms","data":{"e":"depthUpdate","E":1604921124296,"s":"BTCUSDT","U":6511127818,"u":6511127822,"b":[["15401.73000000","0.00000000"]],"a":[["15520.63000000","0.00000000"],["15523.26000000","0.00000000"],["15523.54000000","1.25000000"]]}}
2020-11-09T11:25:24.40372 btcusdt {"stream":"btcusdt@depth@100ms","data":{"e":"depthUpdate","E":1604921124396,"s":"BTCUSDT","U":6511127823,"u":6511127827,"b":[["15506.24000000","0.00000000"]],"a":[["15512.92000000","0.62808200"],["15514.69000000","2.47024500"],["15519.22000000","0.00000000"],["15523.54000000","0.00000000"]]}}
2020-11-09T11:25:24.50349 btcusdt {"stream":"btcusdt@depth@100ms","data":{"e":"depthUpdate","E":1604921124496,"s":"BTCUSDT","U":6511127828,"u":6511127834,"b":[["15512.14000000","0.01677500"],["15510.83000000","0.00000000"],["15506.83000000","0.00000000"]],"a":[["15515.58000000","0.00000000"],["15516.60000000","0.01652700"],["15517.73000000","0.39751600"],["15524.28000000","1.25000000"]]}}
2020-11-09T11:25:24.60476 btcusdt {"stream":"btcusdt@depth@100ms","data":{"e":"depthUpdate","E":1604921124596,"s":"BTCUSDT","U":6511127835,"u":6511127840,"b":[["15512.31000000","0.00822100"],["15509.32000000","0.00000000"],["15428.81000000","0.00000000"]],"a":[["15513.38000000","0.00000000"],["15516.18000000","0.00992900"],["15518.96000000","0.20000000"]]}}
2020-11-09T11:25:24.70390 btcusdt {"stream":"btcusdt@depth@100ms","data":{"e":"depthUpdate","E":1604921124696,"s":"BTCUSDT","U":6511127841,"u":6511127846,"b":[["15505.01000000","0.20000000"],["15428.30000000","0.24000000"]],"a":[["15512.92000000","0.13000000"],["15517.55000000","0.00000000"],["15964.78000000","6.38303700"]]}}
2020-11-09T11:25:24.80526 btcusdt {"stream":"btcusdt@depth@100ms","data":{"e":"depthUpdate","E":1604921124796,"s":"BTCUSDT","U":6511127847,"u":6511127868,"b":[["15512.91000000","2.63242200"],["15512.52000000","0.00000000"],["15512.24000000","2.00000000"],["15511.38000000","0.00000000"],["15509.64000000","0.11427900"],["15509.17000000","0.00000000"],["15506.84000000","0.19307100"],["15504.39000000","0.00000000"]],"a":[["15512.92000000","0.63200000"],["15514.69000000","2.69652800"],["15515.69000000","0.00000000"],["15516.22000000","0.11427900"],["15517.74000000","0.00000000"],["15518.26000000","1.74800000"]]}}
2020-11-09T11:25:24.90375 btcusdt {"stream":"btcusdt@depth@100ms","data":{"e":"depthUpdate","E":1604921124896,"s":"BTCUSDT","U":6511127869,"u":6511127876,"b":[],"a":[["15514.68000000","0.16373500"],["15514.69000000","2.47024500"],["15523.54000000","1.25000000"],["15524.28000000","0.00000000"],["15527.67000000","0.45568200"],["15528.38000000","0.00000000"]]}}
2020-11-09T11:25:25.00221 btcusdt {"stream":"btcusdt@depth@100ms","data":{"e":"depthUpdate","E":1604921124996,"s":"BTCUSDT","U":6511127877,"u":6511127887,"b":[["15507.86000000","0.05000000"],["15507.60000000","0.00000000"],["15504.01000000","1.21913100"]],"a":[["15516.08000000","0.10000000"],["15516.69000000","1.00478300"],["15517.74000000","0.32100000"],["15517.97000000","0.05000000"],["15517.99000000","0.00000000"],["15521.61000000","0.00000000"],["15529.23000000","0.00000000"],["15540.00000000","2.19166300"]]}}
2020-11-09T11:25:25.10390 btcusdt {"stream":"btcusdt@depth@100ms","data":{"e":"depthUpdate","E":1604921125096,"s":"BTCUSDT","U":6511127888,"u":6511127898,"b":[["15505.57000000","0.22500000"],["15474.13000000","0.25000000"]],"a":[["15512.92000000","4.28200000"],["15514.69000000","0.00000000"],["15522.13000000","0.30212100"],["15524.53000000","0.00000000"],["15531.20000000","0.00000000"]]}}
2020-11-09T11:25:25.20367 btcusdt {"stream":"btcusdt@depth@100ms","data":{"e":"depthUpdate","E":1604921125196,"s":"BTCUSDT","U":6511127899,"u":6511127914,"b":[["15511.47000000","0.00000000"],["15509.48000000","0.00000000"],["15506.00000000","0.50000000"],["15505.01000000","0.00000000"],["15481.97000000","0.01550100"],["15472.00000000","0.02510000"],["15428.30000000","0.00000000"]],"a":[["15512.92000000","4.58641700"],["15517.73000000","0.40751600"],["15517.98000000","0.00000000"],["15522.62000000","0.17295300"],["15523.54000000","0.00000000"],["15523.82000000","1.25000000"],["15525.01000000","0.13422900"],["15551.70000000","0.25000000"],["15575.05000000","0.01540900"]]}}
2020-11-09T11:25:25.31192 btcusdt {"stream":"btcusdt@depth@100ms","data":{"e":"depthUpdate","E":1604921125296,"s":"BTCUSDT","U":6511127915,"u":6511127916,"b":[["15433.31000000","0.24000000"]],"a":[["15512.92000000","4.52633500"]]}}
2020-11-09T11:25:25.40272 btcusdt {"stream":"btcusdt@depth@100ms","data":{"e":"depthUpdate","E":1604921125396,"s":"BTCUSDT","U":6511127917,"u":6511127928,"b":[["15512.91000000","0.33440100"],["15509.64000000","0.00000000"],["15509.06000000","0.11427900"],["15508.50000000","0.03626500"],["15506.84000000","0.15680600"],["15471.00000000","2.00000000"]],"a":[["15512.92000000","6.17633500"],["15515.59000000","0.11427900"],["15516.22000000","0.00000000"],["15525.25000000","0.00000000"]]}}
2020-11-09T11:25:25.50563 btcusdt {"stream":"btcusdt@depth@100ms","data":{"e":"depthUpdate","E":1604921125496,"s":"BTCUSDT","U":6511127929,"u":6511127939,"b":[["15512.91000000","0.13242200"],["15508.50000000","0.00000000"],["15507.40000000","0.03626500"],["15505.99000000","0.00000000"],["15504.97000000","0.00000000"],["15504.01000000","0.14550000"],["15497.49000000","0.00000000"]],"a":[["15512.92000000","6.48133500"],["15514.80000000","0.78382400"],["15518.12000000","0.25762500"],["15524.69000000","0.00000000"]]}}
2020-11-09T11:25:25.60234 btcusdt {"stream":"btcusdt@depth@100ms","data":{"e":"depthUpdate","E":1604921125596,"s":"BTCUSDT","U":6511127940,"u":6511127953,"b":[["15512.91000000","0.13042200"],["15510.01000000","0.00000000"],["15508.51000000","0.16429600"],["15508.49000000","0.00000000"],["15506.85000000","0.02106400"],["15506.84000000","0.00000000"],["15506.01000000","0.15680600"],["15501.58000000","0.00000000"],["15497.58000000","0.20000000"],["15494.61000000","0.14850000"]],"a":[["15514.80000000","0.00128800"],["15519.87000000","0.15300000"],["15521.45000000","1.25000000"],["15523.82000000","0.00000000"]]}}
2020-11-09T11:25:25.70330 btcusdt {"stream":"btcusdt@depth@100ms","data":{"e":"depthUpdate","E":1604921125696,"s":"BTCUSDT","U":6511127954,"u":6511127961,"b":[["15433.31000000","0.00000000"]],"a":[["15514.67000000","0.10000000"],["15516.08000000","0.00000000"],["15521.44000000","0.00000000"],["15521.45000000","0.00000000"],["15523.24000000","0.00000000"]]}}
2020-11-09T11:25:25.80363 btcusdt {"stream":"btcusdt@depth@100ms","data":{"e":"depthUpdate","E":1604921125796,"s":"BTCUSDT","U":6511127962,"u":6511127968,"b":[["15512.91000000","0.10339200"],["15507.40000000","0.00000000"],["15506.02000000","0.03626500"],["15432.47000000","0.24000000"]],"a":[["15522.49000000","1.25000000"],["15531.74000000","0.00000000"],["15533.54000000","0.00000000"]]}}
2020-11-09T11:25:25.90384 btcusdt {"stream":"btcusdt@depth@100ms","data":{"e":"depthUpdate","E":1604921125896,"s":"BTCUSDT","U":6511127969,"u":6511127973,"b":[["15512.24000000","0.00000000"],["15502.90000000","0.45837400"]],"a":[["15512.92000000","8.48133500"],["15518.65000000","0.00000000"],["15528.19000000","1.12487800"]]}}
2020-11-09T11:25:26.00337 btcusdt {"stream":"btcusdt@depth@100ms","data":{"e":"depthUpdate","E":1604921125996,"s":"BTCUSDT","U":6511127974,"u":6511127988,"b":[["15509.06000000","0.00000000"],["15508.51000000","0.00000000"],["15508.49000000","0.11427900"],["15507.86000000","0.00000000"],["15507.40000000","0.16429600"],["15506.86000000","0.05000000"],["15506.01000000","0.00000000"],["15502.90000000","0.00000000"],["15420.00000000","0.59902000"]],"a":[["15513.38000000","0.02072600"],["15514.80000000","0.78382400"],["15517.73000000","0.45751600"],["15517.97000000","0.00000000"],["15525.79000000","0.45568200"],["15527.67000000","0.00000000"]]}}
2020-11-09T11:25:26.10379 btcusdt {"stream":"btcusdt@depth@100ms","data":{"e":"depthUpdate","E":1604921126097,"s":"BTCUSDT","U":6511127989,"u":6511127995,"b":[["15508.22000000","0.00000000"],["15505.71000000","0.15680600"]],"a":[["15517.35000000","0.16118400"],["15520.63000000","0.19539700"],["15533.01000000","0.18420000"],["15540.08000000","0.00000000"],["15570.00000000","48.53853300"]]}}
2020-11-09T11:25:26.20376 btcusdt {"stream":"btcusdt@depth@100ms","data":{"e":"depthUpdate","E":1604921126197,"s":"BTCUSDT","U":6511127996,"u":6511128006,"b":[["15505.71000000","0.00000000"],["15503.79000000","0.00000000"],["15432.47000000","0.00000000"]],"a":[["15512.92000000","8.57715200"],["15514.68000000","0.00000000"],["15514.80000000","0.00128800"],["15517.52000000","0.01000000"],["15517.73000000","0.44751600"],["15524.44000000","0.24000000"]]}}
2020-11-09T11:25:26.30403 btcusdt {"stream":"btcusdt@depth@100ms","data":{"e":"depthUpdate","E":1604921126297,"s":"BTCUSDT","U":6511128007,"u":6511128015,"b":[["15505.71000000","0.15680600"],["15504.77000000","0.00000000"],["15503.15000000","0.13426900"],["15502.19000000","0.30210600"],["15437.46000000","0.24000000"]],"a":[["15513.37000000","0.10000000"],["15514.67000000","0.00000000"],["15514.80000000","0.78382400"],["15567.50000000","2.00000000"]]}}
2020-11-09T11:25:26.40507 btcusdt {"stream":"btcusdt@depth@100ms","data":{"e":"depthUpdate","E":1604921126397,"s":"BTCUSDT","U":6511128016,"u":6511128066,"b":[["15512.91000000","0.00000000"],["15512.31000000","0.01512100"],["15510.63000000","0.00000000"],["15509.91000000","0.00000000"],["15509.46000000","0.00000000"],["15509.36000000","0.04000000"],["15508.74000000","0.00000000"],["15508.54000000","0.04000000"],["15508.49000000","0.00000000"],["15508.48000000","0.00000000"],["15508.47000000","0.00000000"],["15507.94000000","0.11427900"],["15507.92000000","0.00000000"],["15507.71000000","1.58300000"],["15507.13000000","0.24000000"],["15506.03000000","0.06738900"],["15505.71000000","0.00000000"],["15505.01000000","0.00000000"],["15502.45000000","0.00000000"],["15500.24000000","0.13420600"],["15481.97000000","0.00000000"]],"a":[["15512.32000000","9.80270700"],["15512.62000000","0.00690000"],["15512.81000000","0.05573700"],["15512.91000000","0.00627400"],["15512.92000000","8.07715200"],["15513.38000000","0.00000000"],["15514.79000000","0.78253600"],["15514.80000000","0.00128800"],["15514.81000000","2.00000000"],["15514.87000000","0.11427900"],["15515.59000000","0.00000000"],["15516.66000000","0.00000000"],["15517.81000000","1.19800000"],["15518.36000000","0.00690000"],["15518.60000000","1.08000000"],["15520.28000000","0.00000000"],["15526.53000000","1.36700000"],["15575.05000000","0.00000000"]]}}
2020-11-09T11:25:26.50635 btcusdt {"stream":"btcusdt@depth@100ms","data":{"e":"depthUpdate","E":1604921126497,"s":"BTCUSDT","U":6511128067,"u":6511128094,"b":[["15507.88000000","0.25759600"],["15506.86000000","0.00000000"],["15506.58000000","0.05000000"],["15505.98000000","0.00000000"],["15505.71000000","0.15680600"],["15503.28000000","1.25000000"],["15502.86000000","0.00000000"],["15202.65000000","0.00000000"]],"a":[["15512.32000000","11.80270700"],["15512.91000000","1.18881000"],["15512.92000000","7.77273500"],["15514.79000000","0.00000000"],["15514.99000000","0.00000000"],["15515.00000000","0.00000000"],["15516.88000000","0.25764300"],["15517.35000000","0.21118400"],["15517.73000000","0.39751600"],["15518.12000000","0.40912500"],["15518.73000000","0.01000000"],["15519.33000000","0.00000000"],["15519.73000000","0.00000000"],["15520.48000000","1.00851700"],["15520.66000000","0.00000000"],["15522.86000000","0.00000000"],["15523.85000000","0.00000000"],["15531.29000000","0.00000000"],["15624.00000000","0.00168300"]]}}
2020-11-09T11:25:26.60408 btcusdt {"stream":"btcusdt@depth@100ms","data":{"e":"depthUpdate","E":1604921126597,"s":"BTCUSDT","U":6511128095,"u":6511128103,"b":[["15508.55000000","0.08000000"],["15505.71000000","0.00000000"],["15501.19000000","0.03355200"]],"a":[["15512.32000000","12.20712500"],["15512.92000000","7.77073500"],["15513.37000000","0.00000000"],["15516.68000000","0.00312700"],["15519.13000000","0.01500000"]]}}
2020-11-09T11:25:26.70385 btcusdt {"stream":"btcusdt@depth@100ms","data":{"e":"depthUpdate","E":1604921126697,"s":"BTCUSDT","U":6511128104,"u":6511128120,"b":[["15512.31000000","0.00690000"],["15512.14000000","0.00000000"],["15511.85000000","0.00655200"],["15511.54000000","0.01787100"],["15509.57000000","0.00000000"],["15507.94000000","0.00000000"]],"a":[["15512.32000000","12.60712500"],["15512.90000000","0.78253600"],["15512.91000000","0.40627400"],["15512.92000000","7.46573500"],["15518.10000000","1.25000000"],["15518.70000000","0.10179000"],["15522.49000000","0.00000000"],["15522.78000000","0.50000000"],["15525.39000000","0.00000000"],["15612.00000000","0.10827300"],["15622.00000000","0.01100000"]]}}
2020-11-09T11:25:26.80428 btcusdt {"stream":"btcusdt@depth@100ms","data":{"e":"depthUpdate","E":1604921126797,"s":"BTCUSDT","U":6511128121,"u":6511128230,"b":[["15512.31000000","0.00000000"],["15511.85000000","0.00000000"],["15511.54000000","0.00000000"],["15511.48000000","0.00000000"],["15510.92000000","0.00690000"],["15510.67000000","0.00000000"],["15510.12000000","0.00000000"],["15510.00000000","0.00000000"],["15509.36000000","0.00000000"],["15508.99000000","0.00000000"],["15508.74000000","0.24000000"],["15508.55000000","0.00000000"],["15508.54000000","0.00000000"],["15508.31000000","0.00000000"],["15508.24000000","0.00000000"],["15507.88000000","0.00000000"],["15507.85000000","0.00000000"],["15507.72000000","0.03397300"],["15507.71000000","0.00000000"],["15507.44000000","0.00000000"],["15506.65000000","0.11427900"],["15506.38000000","1.59300000"],["15506.02000000","0.00000000"],["15505.57000000","0.00000000"],["15505.01000000","0.03626500"],["15504.69000000","0.15680600"],["15504.01000000","0.00000000"],["15502.57000000","0.00000000"],["15500.64000000","0.00000000"],["15498.80000000","0.43804200"],["15493.78000000","0.14550000"],["15492.37000000","0.00000000"],["15491.59000000","0.00000000"]],"a":[["15510.93000000","0.14712200"],["15511.30000000","0.20827100"],["15511.31000000","0.00000000"],["15511.39000000","0.37949800"],["15511.42000000","0.36524800"],["15511.45000000","0.00000000"],["15511.49000000","0.78084800"],["15511.55000000","0.84874200"],["15511.62000000","0.36767500"],["15511.86000000","0.00000000"],["15512.08000000","0.00128800"],["15512.09000000","0.00690000"],["15512.12000000","0.00000000"],["15512.21000000","1.48433000"],["15512.22000000","0.00000000"],["15512.23000000","0.00000000"],["15512.25000000","0.04491300"],["15512.27000000","0.00000000"],["15512.31000000","0.78253600"],["15512.32000000","8.15824500"],["15512.51000000","0.11427900"],["15512.81000000","0.00000000"],["15512.90000000","0.00000000"],["15512.92000000","7.46373500"],["15514.70000000","0.30090000"],["15514.80000000","0.00000000"],["15514.87000000","0.01700000"],["15514.98000000","0.25000000"],["15515.69000000","1.74800000"],["15515.84000000","0.30900000"],["15516.37000000","1.19800000"],["15516.52000000","0.00000000"],["15516.62000000","1.58300000"],["15516.78000000","1.59300000"],["15517.34000000","0.00000000"],["15517.36000000","0.00000000"],["15517.81000000","0.00000000"],["15518.26000000","0.00000000"],["15518.57000000","0.00000000"],["15518.70000000","0.00000000"],["15518.71000000","0.00000000"],["15519.51000000","0.00000000"],["15519.68000000","0.00000000"],["15519.78000000","0.00000000"],["15521.52000000","0.15300000"],["15536.07000000","0.00000000"],["15536.27000000","0.00000000"]]}}
2020-11-09T11:25:26.90944 btcusdt {"stream":"btcusdt@depth@100ms","data":{"e":"depthUpdate","E":1604921126897,"s":"BTCUSDT","U":6511128231,"u":6511128329,"b":[["15510.92000000","0.01380000"],["15509.34000000","2.00000000"],["15508.76000000","0.07361800"],["15508.74000000","0.00000000"],["15507.40000000","0.00000000"],["15507.39000000","0.00000000"],["15507.19000000","0.08000000"],["15507.13000000","0.00000000"],["15506.58000000","0.00000000"],["15505.71000000","0.21429600"],["15505.58000000","0.08000000"],["15504.69000000","0.00000000"],["15503.11000000","0.00000000"],["15500.33000000","1.50000000"],["15497.69000000","0.00294000"],["15488.98000000","0.00523400"],["15488.68000000","0.30000000"],["15483.62000000","0.00000000"],["15479.95000000","0.31800000"],["15435.34000000","0.00000000"],["15396.00000000","0.37683000"]],"a":[["15510.93000000","6.83545200"],["15511.06000000","0.00000000"],["15511.16000000","0.00690000"],["15511.28000000","0.00000000"],["15511.29000000","0.00000000"],["15511.30000000","0.00000000"],["15511.39000000","0.00000000"],["15511.42000000","0.00000000"],["15511.49000000","0.00000000"],["15511.54000000","0.00000000"],["15511.55000000","0.00000000"],["15511.62000000","0.00000000"],["15511.76000000","0.00000000"],["15512.21000000","0.00000000"],["15512.25000000","0.00000000"],["15512.30000000","0.00000000"],["15512.31000000","1.18253600"],["15512.32000000","7.80000000"],["15512.91000000","0.00627400"],["15512.92000000","2.16373500"],["15514.34000000","0.00000000"],["15514.87000000","0.00000000"],["15515.19000000","0.08200000"],["15515.36000000","0.03223500"],["15515.66000000","0.00000000"],["15515.68000000","0.06000000"],["15515.69000000","0.00000000"],["15515.75000000","0.01700000"],["15515.94000000","0.01700000"],["15516.57000000","1.74800000"],["15516.68000000","0.00000000"],["15516.78000000","1.61300000"],["15517.09000000","0.50000000"],["15517.34000000","0.01000000"],["15517.35000000","0.16118400"],["15517.43000000","0.08000000"],["15517.52000000","0.00000000"],["15517.68000000","0.00306000"],["15517.74000000","0.00000000"],["15518.60000000","0.00000000"],["15518.73000000","0.00000000"],["15518.85000000","0.00000000"],["15519.40000000","0.00000000"],["15521.11000000","0.00000000"],["15528.64000000","0.00000000"],["15529.18000000","0.00000000"],["15531.02000000","0.00000000"]]}}
2020-11-09T11:25:27.00463 btcusdt {"stream":"btcusdt@depth@100ms","data":{"e":"depthUpdate","E":1604921126997,"s":"BTCUSDT","U":6511128330,"u":6511128361,"b":[["15507.59000000","0.00000000"],["15505.70000000","0.00000000"],["15505.66000000","0.00000000"],["15505.65000000","0.03223700"],["15505.02000000","0.02500000"],["15505.01000000","0.00000000"],["15504.68000000","0.00000000"],["15504.28000000","0.00000000"],["15504.19000000","0.00000000"],["15503.29000000","0.03626500"],["15502.91000000","0.30000000"],["15501.08000000","1.50843600"],["15500.85000000","0.12894900"],["15500.33000000","0.00000000"],["15499.30000000","1.00000000"],["15496.75000000","0.00000000"],["15495.77000000","0.00000000"]],"a":[["15510.93000000","9.67055300"],["15512.31000000","0.40000000"],["15512.32000000","7.40000000"],["15514.81000000","0.00000000"],["15515.68000000","0.01000000"],["15515.70000000","0.32200000"],["15516.16000000","0.00000000"],["15516.36000000","0.05000000"],["15517.30000000","0.12894100"],["15522.90000000","0.00000000"],["15527.12000000","0.02500000"]]}}
2020-11-09T11:25:27.10675 btcusdt {"stream":"btcusdt@depth@100ms","data":{"e":"depthUpdate","E":1604921127097,"s":"BTCUSDT","U":6511128362,"u":6511128387,"b":[["15506.85000000","0.00000000"],["15506.65000000","0.00000000"],["15506.04000000","0.08000000"],["15505.71000000","0.05000000"],["15503.71000000","0.12894900"],["15503.30000000","0.34216600"],["15500.85000000","0.00000000"],["15497.59000000","0.00000000"],["15497.58000000","1.70000000"],["15494.42000000","0.23546000"],["15492.90000000","1.15606700"]],"a":[["15510.93000000","10.01050000"],["15512.51000000","0.00000000"],["15514.69000000","0.20000000"],["15516.60000000","0.00000000"],["15517.72000000","0.00000000"],["15522.61000000","0.02968800"],["15523.09000000","0.00000000"],["15524.43000000","0.02382800"],["15526.06000000","0.02422500"],["15570.00000000","48.91536300"]]}}
2020-11-09T11:25:27.20419 btcusdt {"stream":"btcusdt@depth@100ms","data":{"e":"depthUpdate","E":1604921127197,"s":"BTCUSDT","U":6511128388,"u":6511128415,"b":[["15509.70000000","0.01588500"],["15509.06000000","0.00606500"],["15505.64000000","0.00000000"],["15505.25000000","0.11427900"],["15503.30000000","0.36116600"],["15503.29000000","0.13626500"],["15503.15000000","0.00000000"],["15501.63000000","0.00000000"],["15501.56000000","0.13424000"],["15499.58000000","0.00000000"],["15497.58000000","0.00000000"],["15495.58000000","0.20000000"],["15437.46000000","0.00000000"]],"a":[["15513.15000000","0.00640000"],["15513.31000000","0.01988100"],["15513.65000000","0.11427900"],["15514.94000000","0.03400000"],["15515.68000000","0.00000000"],["15515.75000000","0.00000000"],["15515.94000000","0.00000000"],["15516.18000000","0.00000000"],["15516.36000000","0.06000000"],["15520.87000000","0.01382400"],["15524.46000000","0.02422500"],["15526.06000000","0.00000000"],["15545.77000000","0.02948100"]]}}
2020-11-09T11:25:27.30447 btcusdt {"stream":"btcusdt@depth@100ms","data":{"e":"depthUpdate","E":1604921127297,"s":"BTCUSDT","U":6511128416,"u":6511128432,"b":[["15503.30000000","0.19687000"],["15497.13000000","0.00000000"],["15441.73000000","0.24000000"],["15417.00000000","0.37683000"]],"a":[["15512.92000000","2.23898400"],["15513.64000000","0.08000000"],["15517.72000000","0.09623100"],["15519.75000000","0.00000000"],["15522.77000000","1.00000000"],["15523.34000000","1.50000000"],["15525.31000000","0.00000000"],["15525.58000000","0.02806500"],["15526.63000000","0.00000000"],["15527.33000000","0.00000000"],["15541.87000000","0.08927800"]]}}
2020-11-09T11:25:27.40637 btcusdt {"stream":"btcusdt@depth@100ms","data":{"e":"depthUpdate","E":1604921127397,"s":"BTCUSDT","U":6511128433,"u":6511128446,"b":[["15506.57000000","0.00000000"],["15503.30000000","0.36116600"],["15503.29000000","1.63626500"],["15502.44000000","0.00000000"],["15497.48000000","1.50000000"],["15441.73000000","0.00000000"],["15433.36000000","0.00647900"]],"a":[["15510.93000000","10.01250000"],["15512.32000000","7.30000000"],["15524.44000000","0.00000000"]]}}
2020-11-09T11:25:27.50644 btcusdt {"stream":"btcusdt@depth@100ms","data":{"e":"depthUpdate","E":1604921127497,"s":"BTCUSDT","U":6511128447,"u":6511128456,"b":[["15509.70000000","0.00000000"],["15500.30000000","0.03361900"],["15497.64000000","1.50000000"],["15497.48000000","0.00000000"],["15496.39000000","0.20000000"],["15465.58000000","0.01551800"]],"a":[["15510.93000000","10.02427000"],["15512.30000000","0.10000000"],["15513.31000000","0.00000000"],["15523.88000000","0.05681900"]]}}
2020-11-09T11:25:27.60649 btcusdt {"stream":"btcusdt@depth@100ms","data":{"e":"depthUpdate","E":1604921127597,"s":"BTCUSDT","U":6511128457,"u":6511128462,"b":[["15501.09000000","0.13435700"],["15500.18000000","0.93755100"],["15494.75000000","0.18420000"],["15440.77000000","0.24000000"]],"a":[["15541.24000000","0.00000000"],["15558.65000000","0.01542500"]]}}
2020-11-09T11:25:27.70787 btcusdt {"stream":"btcusdt@depth@100ms","data":{"e":"depthUpdate","E":1604921127697,"s":"BTCUSDT","U":6511128463,"u":6511128472,"b":[["15509.34000000","0.00000000"],["15506.03000000","0.00000000"],["15505.65000000","0.00000000"],["15503.71000000","0.00000000"],["15502.81000000","0.03223700"],["15500.59000000","0.12894900"],["15497.64000000","0.00000000"],["15440.77000000","0.00000000"]],"a":[["15519.02000000","0.00000000"],["15523.70000000","0.00000000"]]}}
2020-11-09T11:25:27.80525 btcusdt {"stream":"btcusdt@depth@100ms","data":{"e":"depthUpdate","E":1604921127797,"s":"BTCUSDT","U":6511128473,"u":6511128484,"b":[["15508.76000000","0.00000000"],["15505.03000000","0.16000000"],["15502.88000000","0.06736500"],["15417.00000000","0.00000000"]],"a":[["15511.87000000","1.03328600"],["15513.63000000","0.00306900"],["15516.69000000","0.00000000"],["15519.99000000","0.42971400"],["15521.04000000","0.30000000"],["15524.46000000","0.00000000"],["15524.47000000","0.00000000"]]}}
2020-11-09T11:25:27.90549 btcusdt {"stream":"btcusdt@depth@100ms","data":{"e":"depthUpdate","E":1604921127897,"s":"BTCUSDT","U":6511128485,"u":6511128491,"b":[["15500.46000000","0.87000000"],["15499.12000000","0.10086100"],["15497.49000000","1.50000000"],["15491.97000000","0.00000000"],["12408.00000000","0.18593900"]],"a":[["15519.99000000","0.45878500"],["15529.98000000","0.00000000"]]}}
2020-11-09T11:25:28.00564 btcusdt {"stream":"btcusdt@depth@100ms","data":{"e":"depthUpdate","E":1604921127998,"s":"BTCUSDT","U":6511128492,"u":6511128506,"b":[["15505.71000000","0.00000000"],["15503.30000000","0.41116600"],["15501.19000000","0.00000000"],["15500.24000000","0.00000000"],["15499.40000000","0.49430900"]],"a":[["15510.93000000","10.22793300"],["15512.30000000","0.00000000"],["15512.92000000","2.07524900"],["15515.83000000","0.05000000"],["15516.09000000","0.00000000"],["15516.36000000","0.01000000"],["15525.79000000","0.00000000"],["15612.00000000","0.00000000"]]}}
2020-11-09T11:25:28.10512 btcusdt {"stream":"btcusdt@depth@100ms","data":{"e":"depthUpdate","E":1604921128098,"s":"BTCUSDT","U":6511128507,"u":6511128516,"b":[["15506.32000000","0.01206300"],["15503.30000000","0.24687000"],["15500.46000000","0.00000000"],["15499.99000000","0.04343400"],["15499.04000000","0.13421500"],["15492.10000000","0.87000000"]],"a":[["15511.70000000","0.01900000"],["15513.63000000","0.13203500"],["15518.10000000","0.00000000"],["15524.02000000","0.45568200"]]}}
2020-11-09T11:25:28.20517 btcusdt {"stream":"btcusdt@depth@100ms","data":{"e":"depthUpdate","E":1604921128198,"s":"BTCUSDT","U":6511128517,"u":6511128533,"b":[["15509.06000000","0.00000000"],["15506.03000000","0.00686200"],["15505.59000000","0.16429600"],["15441.41000000","0.24000000"],["15396.00000000","0.48510300"]],"a":[["15510.93000000","4.92793300"],["15511.39000000","0.00653400"],["15513.15000000","0.00000000"],["15513.63000000","0.26099700"],["15515.47000000","0.31800000"],["15515.82000000","0.01000000"],["15516.36000000","0.00000000"],["15517.74000000","0.01500000"],["15519.13000000","0.00000000"],["15520.04000000","1.25000000"],["15523.93000000","0.24000000"],["15670.14000000","0.00000000"]]}}
2020-11-09T11:25:28.31648 btcusdt {"stream":"btcusdt@depth@100ms","data":{"e":"depthUpdate","E":1604921128298,"s":"BTCUSDT","U":6511128534,"u":6511128541,"b":[["15500.46000000","0.87000000"],["15441.41000000","0.00000000"]],"a":[["15510.93000000","4.50093300"],["15514.70000000","0.00690000"],["15516.77000000","0.10182600"],["15517.68000000","0.00000000"]]}}
2020-11-09T11:25:28.40508 btcusdt {"stream":"btcusdt@depth@100ms","data":{"e":"depthUpdate","E":1604921128398,"s":"BTCUSDT","U":6511128542,"u":6511128551,"b":[["15506.54000000","0.01933200"],["15506.32000000","0.00000000"],["15505.48000000","0.03223700"],["15502.81000000","0.00000000"],["15497.49000000","0.00000000"],["15497.31000000","1.50000000"],["15492.10000000","0.00000000"],["15442.02000000","0.24000000"]],"a":[["15521.12000000","0.00309000"],["15567.00000000","0.11938000"]]}}
2020-11-09T11:25:28.50576 btcusdt {"stream":"btcusdt@depth@100ms","data":{"e":"depthUpdate","E":1604921128498,"s":"BTCUSDT","U":6511128552,"u":6511128559,"b":[["15502.87000000","0.00000000"],["15501.09000000","0.00000000"],["15500.46000000","0.00000000"],["15492.10000000","0.87000000"],["15489.56000000","2.20619000"]],"a":[["15510.93000000","4.45238900"],["15609.00000000","0.10827300"]]}}
2020-11-09T11:25:28.60993 btcusdt {"stream":"btcusdt@depth@100ms","data":{"e":"depthUpdate","E":1604921128598,"s":"BTCUSDT","U":6511128560,"u":6511128563,"b":[["15501.37000000","0.06718600"],["15500.25000000","0.13437200"],["15459.26000000","0.00000000"]],"a":[["15510.93000000","4.45954100"]]}}
2020-11-09T11:25:28.70595 btcusdt {"stream":"btcusdt@depth@100ms","data":{"e":"depthUpdate","E":1604921128698,"s":"BTCUSDT","U":6511128564,"u":6511128564,"b":[["15393.00000000","5.19619300"]],"a":[]}}
2020-11-09T11:25:28.80526 btcusdt {"stream":"btcusdt@depth@100ms","data":{"e":"depthUpdate","E":1604921128798,"s":"BTCUSDT","U":6511128565,"u":6511128569,"b":[["15489.28000000","0.23992500"]],"a":[["15522.70000000","0.10086000"],["15524.33000000","0.06727700"],["15529.32000000","0.00690000"],["15534.60000000","0.00000000"]]}}
2020-11-09T11:25:28.90555 btcusdt {"stream":"btcusdt@depth@100ms","data":{"e":"depthUpdate","E":1604921128898,"s":"BTCUSDT","U":6511128570,"u":6511128589,"b":[["15507.72000000","0.00128900"],["15506.54000000","0.00000000"],["15506.41000000","0.01424300"],["15506.04000000","0.00000000"],["15506.03000000","0.00000000"],["15505.80000000","0.00861800"],["15505.65000000","0.03223700"],["15505.48000000","0.00000000"],["15503.73000000","0.12894900"],["15502.55000000","0.00000000"],["15500.59000000","0.00000000"],["15460.10000000","0.03020000"]],"a":[["15510.93000000","4.39932200"],["15515.32000000","1.74800000"],["15515.58000000","1.19800000"],["15516.37000000","0.00000000"],["15516.57000000","0.00000000"],["15524.02000000","0.00000000"],["15567.00000000","0.49621000"]]}}
2020-11-09T11:25:29.00452 btcusdt {"stream":"btcusdt@depth@100ms","data":{"e":"depthUpdate","E":1604921128998,"s":"BTCUSDT","U":6511128590,"u":6511128601,"b":[["15507.20000000","0.06447000"],["15507.19000000","0.00000000"],["15505.58000000","0.00000000"],["15505.16000000","0.08000000"],["15503.57000000","0.08000000"]],"a":[["15511.87000000","0.00000000"],["15512.30000000","2.57598000"],["15513.63000000","0.13203100"],["15515.46000000","0.05000000"],["15515.83000000","0.00000000"],["15520.04000000","0.00000000"],["15527.86000000","0.45568200"]]}}
2020-11-09T11:25:29.10845 btcusdt {"stream":"btcusdt@depth@100ms","data":{"e":"depthUpdate","E":1604921129098,"s":"BTCUSDT","U":6511128602,"u":6511128609,"b":[["15506.01000000","0.08000000"],["15503.74000000","0.10829600"],["15499.62000000","0.00000000"],["15414.00000000","0.37683000"]],"a":[["15510.93000000","9.69932200"],["15512.30000000","0.00000000"],["15520.73000000","1.25000000"],["15529.62000000","0.00000000"]]}}
2020-11-09T11:25:29.20665 btcusdt {"stream":"btcusdt@depth@100ms","data":{"e":"depthUpdate","E":1604921129198,"s":"BTCUSDT","U":6511128610,"u":6511128617,"b":[["15405.32000000","0.00000000"],["15382.03000000","0.38356400"]],"a":[["15515.53000000","0.01000000"],["15515.82000000","0.00000000"],["15519.14000000","1.25000000"],["15520.73000000","0.00000000"],["15521.93000000","0.13437200"],["15666.03000000","0.00100000"]]}}
2020-11-09T11:25:29.30732 btcusdt {"stream":"btcusdt@depth@100ms","data":{"e":"depthUpdate","E":1604921129298,"s":"BTCUSDT","U":6511128618,"u":6511128623,"b":[["15506.41000000","0.00000000"],["15505.88000000","0.01327600"],["15505.80000000","0.00000000"],["15505.27000000","0.00836900"]],"a":[["15520.45000000","0.06718600"],["15529.30000000","0.04116400"]]}}
2020-11-09T11:25:29.40516 btcusdt {"stream":"btcusdt@depth@100ms","data":{"e":"depthUpdate","E":1604921129398,"s":"BTCUSDT","U":6511128624,"u":6511128630,"b":[["15501.65000000","0.00000000"],["15501.08000000","0.50000000"],["15499.78000000","0.50434800"],["15499.07000000","1.00869600"]],"a":[["15510.93000000","9.68755200"],["15512.91000000","0.00000000"],["15514.99000000","0.13644700"]]}}
2020-11-09T11:25:29.50575 btcusdt {"stream":"btcusdt@depth@100ms","data":{"e":"depthUpdate","E":1604921129498,"s":"BTCUSDT","U":6511128631,"u":6511128632,"b":[["15499.07000000","0.00000000"],["14858.92000000","0.00084500"]],"a":[]}}
2020-11-09T11:25:29.60548 btcusdt {"stream":"btcusdt@depth@100ms","data":{"e":"depthUpdate","E":1604921129598,"s":"BTCUSDT","U":6511128633,"u":6511128652,"b":[["15506.38000000","0.00000000"],["15506.01000000","0.00000000"],["15505.15000000","1.59300000"],["15500.09000000","0.00000000"],["15497.31000000","0.00000000"],["15494.48000000","1.00871200"],["15474.39000000","0.00000000"],["15414.00000000","0.00000000"]],"a":[["15510.93000000","9.83755200"],["15514.31000000","0.03400000"],["15514.51000000","0.04000000"],["15514.94000000","0.00000000"],["15515.48000000","0.15700000"],["15515.55000000","1.59300000"],["15516.62000000","0.00000000"],["15516.78000000","0.00000000"],["15561.26000000","0.00000000"]]}}
2020-11-09T11:25:29.70527 btcusdt {"stream":"btcusdt@depth@100ms","data":{"e":"depthUpdate","E":1604921129698,"s":"BTCUSDT","U":6511128653,"u":6511128681,"b":[["15505.65000000","0.00000000"],["15505.25000000","0.00000000"],["15503.74000000","0.00000000"],["15503.73000000","0.00000000"],["15502.44000000","0.03223700"],["15502.20000000","0.03100000"],["15499.78000000","0.00000000"],["15499.59000000","0.12894900"],["15497.57000000","1.50000000"],["15496.70000000","0.14700000"]],"a":[["15510.93000000","9.50034900"],["15512.30000000","0.24373500"],["15513.62000000","0.10000000"],["15514.30000000","0.20000000"],["15517.06000000","0.00000000"],["15518.96000000","0.00000000"],["15518.97000000","0.00000000"],["15519.14000000","0.00000000"],["15523.87000000","0.19325100"],["15526.58000000","0.00000000"],["15531.99000000","0.00000000"],["15558.57000000","0.03100000"]]}}
2020-11-09T11:25:29.80692 btcusdt {"stream":"btcusdt@depth@100ms","data":{"e":"depthUpdate","E":1604921129798,"s":"BTCUSDT","U":6511128682,"u":6511128694,"b":[["15510.92000000","0.01304900"],["15505.74000000","0.11427900"],["15505.65000000","0.03223700"],["15503.73000000","0.12894900"],["15502.44000000","0.00000000"],["15502.19000000","0.00000000"],["15501.19000000","0.30253400"],["15499.59000000","0.00000000"],["15497.57000000","0.00000000"],["15496.86000000","0.50435600"]],"a":[["15510.93000000","9.42795300"],["15520.73000000","1.25000000"],["15609.00000000","0.00000000"]]}}
2020-11-09T11:25:29.90518 btcusdt {"stream":"btcusdt@depth@100ms","data":{"e":"depthUpdate","E":1604921129899,"s":"BTCUSDT","U":6511128695,"u":6511128700,"b":[["15506.01000000","0.03626500"],["15503.29000000","1.60000000"],["15491.40000000","0.05000000"]],"a":[["15510.93000000","9.36525100"],["15540.32000000","0.00000000"]]}}
2020-11-09T11:25:30.00595 btcusdt {"stream":"btcusdt@depth@100ms","data":{"e":"depthUpdate","E":1604921129999,"s":"BTCUSDT","U":6511128701,"u":6511128712,"b":[["15506.98000000","0.50000000"],["15393.00000000","5.30446600"]],"a":[["15510.93000000","9.28871900"],["15512.72000000","0.50000000"],["15515.07000000","1.19800000"],["15515.22000000","0.05000000"],["15515.46000000","0.00000000"],["15515.58000000","0.00000000"],["15520.31000000","0.20000000"],["15525.80000000","0.00000000"],["15526.52000000","0.45568200"],["15527.86000000","0.00000000"]]}}
2020-11-09T11:25:30.10682 btcusdt {"stream":"btcusdt@depth@100ms","data":{"e":"depthUpdate","E":1604921130099,"s":"BTCUSDT","U":6511128713,"u":6511128720,"b":[["15508.76000000","0.01378700"],["15505.88000000","0.00000000"],["15474.13000000","0.00000000"]],"a":[["15512.29000000","0.10000000"],["15513.62000000","0.00000000"],["15514.29000000","0.12895900"],["15516.77000000","0.00000000"],["15551.70000000","0.00000000"]]}}
2020-11-09T11:25:30.20777 btcusdt {"stream":"btcusdt@depth@100ms","data":{"e":"depthUpdate","E":1604921130199,"s":"BTCUSDT","U":6511128721,"u":6511128725,"b":[["15508.11000000","0.00753500"],["15505.27000000","0.00000000"]],"a":[["15517.35000000","0.00000000"],["15564.00000000","0.10827300"],["15730.00000000","1.92699900"]]}}
2020-11-09T11:25:30.40629 btcusdt {"stream":"btcusdt@depth@100ms","data":{"e":"depthUpdate","E":1604921130399,"s":"BTCUSDT","U":6511128726,"u":6511128730,"b":[["15508.76000000","0.00000000"],["15508.65000000","0.01526600"],["15442.02000000","0.00000000"],["15414.00000000","0.37683000"]],"a":[["15510.93000000","9.28156700"]]}}
2020-11-09T11:25:30.50635 btcusdt {"stream":"btcusdt@depth@100ms","data":{"e":"depthUpdate","E":1604921130499,"s":"BTCUSDT","U":6511128731,"u":6511128732,"b":[["15508.11000000","0.00000000"]],"a":[["15524.81000000","0.01522300"]]}}
2020-11-09T11:25:30.60545 btcusdt {"stream":"btcusdt@depth@100ms","data":{"e":"depthUpdate","E":1604921130599,"s":"BTCUSDT","U":6511128733,"u":6511128733,"b":[["15508.65000000","0.00000000"]],"a":[]}}
2020-11-09T11:25:30.70568 btcusdt {"stream":"btcusdt@depth@100ms","data":{"e":"depthUpdate","E":1604921130699,"s":"BTCUSDT","U":6511128734,"u":6511128734,"b":[["15510.92000000","0.00924900"]],"a":[]}}
2020-11-09T11:25:30.80648 btcusdt {"stream":"btcusdt@depth@100ms","data":{"e":"depthUpdate","E":1604921130799,"s":"BTCUSDT","U":6511128735,"u":6511128736,"b":[],"a":[["15520.45000000","0.24017100"],["15522.62000000","0.00000000"]]}}
2020-11-09T11:25:31.00572 btcusdt {"stream":"btcusdt@depth@100ms","data":{"e":"depthUpdate","E":1604921130999,"s":"BTCUSDT","U":6511128737,"u":6511128747,"b":[["15508.38000000","0.01448900"],["15507.92000000","0.00637100"],["15503.31000000","0.05000000"],["15503.30000000","0.19687000"],["15457.52000000","0.25000000"],["15454.42000000","0.00000000"]],"a":[["15513.57000000","0.88683800"],["15515.19000000","0.13200000"],["15515.22000000","0.00000000"],["15525.00000000","0.45885800"],["15526.52000000","0.00000000"]]}}
2020-11-09T11:25:31.10642 btcusdt {"stream":"btcusdt@depth@100ms","data":{"e":"depthUpdate","E":1604921131099,"s":"BTCUSDT","U":6511128748,"u":6511128829,"b":[["15510.92000000","0.00000000"],["15508.38000000","0.00000000"],["15508.04000000","0.61047400"],["15507.92000000","0.00000000"],["15507.72000000","0.00000000"],["15507.26000000","0.00000000"],["15507.20000000","0.00000000"],["15506.98000000","0.00000000"],["15506.21000000","0.00000000"],["15506.01000000","0.00000000"],["15506.00000000","0.00000000"],["15505.95000000","0.00000000"],["15505.74000000","0.00000000"],["15505.71000000","0.07328100"],["15505.65000000","0.00000000"],["15505.63000000","0.00000000"],["15505.59000000","0.00000000"],["15505.53000000","1.00000000"],["15505.35000000","0.00000000"],["15505.16000000","0.00000000"],["15505.15000000","0.00000000"],["15504.66000000","0.11427900"],["15503.85000000","0.03223800"],["15503.73000000","0.00000000"],["15502.32000000","0.22500000"],["15501.31000000","0.00000000"],["15498.81000000","0.12895000"],["15497.69000000","0.00000000"],["15497.45000000","0.00000000"],["15490.39000000","0.15450000"],["15488.68000000","0.00000000"],["15445.16000000","0.00000000"],["15438.58000000","0.96723900"],["12408.00000000","0.17593900"]],"a":[["15508.05000000","0.62977000"],["15510.13000000","0.00000000"],["15510.14000000","0.00000000"],["15510.69000000","0.08586800"],["15510.74000000","0.00000000"],["15510.75000000","0.00000000"],["15510.91000000","4.63042000"],["15510.92000000","0.78382400"],["15510.93000000","8.61829700"],["15511.07000000","0.01700000"],["15511.17000000","0.11427900"],["15511.27000000","0.00000000"],["15512.08000000","0.00000000"],["15512.30000000","0.08000000"],["15513.49000000","0.00000000"],["15513.51000000","1.19800000"],["15513.65000000","0.00000000"],["15513.85000000","0.00000000"],["15514.04000000","1.59300000"],["15514.31000000","0.00000000"],["15514.47000000","0.15700000"],["15514.75000000","0.29100000"],["15514.91000000","0.15540000"],["15514.97000000","0.16120100"],["15515.07000000","0.00000000"],["15515.32000000","0.00000000"],["15515.48000000","0.00000000"],["15515.55000000","0.00000000"],["15516.45000000","0.22400000"],["15518.35000000","0.14700000"],["15524.25000000","0.20000000"],["15527.90000000","0.00000000"],["15529.71000000","0.00000000"],["15531.05000000","0.00000000"],["15549.70000000","0.25000000"],["15582.81000000","0.00000000"]]}}
2020-11-09T11:25:31.20955 btcusdt {"stream":"btcusdt@depth@100ms","data":{"e":"depthUpdate","E":1604921131199,"s":"BTCUSDT","U":6511128830,"u":6511128869,"b":[["15505.92000000","2.00000000"],["15503.86000000","0.08000000"],["15503.31000000","0.00000000"],["15503.30000000","0.04006400"],["15503.29000000","1.65000000"],["15502.33000000","0.15680600"],["15501.08000000","0.00000000"],["15498.67000000","0.50000000"],["15494.42000000","0.00000000"],["15491.81000000","0.23748900"],["15446.29000000","0.24000000"],["14882.06000000","0.00000000"],["12900.00000000","35.56694500"]],"a":[["15508.05000000","0.62270200"],["15510.92000000","0.00128800"],["15510.93000000","7.38319600"],["15511.07000000","0.00000000"],["15511.69000000","0.20000000"],["15512.31000000","0.00000000"],["15512.55000000","0.03400000"],["15513.36000000","1.74800000"],["15513.57000000","0.00000000"],["15514.03000000","0.01000000"],["15514.46000000","0.01000000"],["15514.86000000","0.01500000"],["15515.53000000","0.00000000"],["15515.70000000","0.00000000"],["15517.06000000","1.25000000"],["15517.34000000","0.00000000"],["15517.74000000","0.00000000"],["15518.60000000","1.00869600"],["15520.48000000","0.00000000"],["15520.73000000","0.00000000"],["15524.53000000","0.02806500"],["15524.82000000","0.00000000"],["15525.58000000","0.00000000"],["15577.84000000","0.70930900"]]}}
2020-11-09T11:25:31.34431 btcusdt {"stream":"btcusdt@depth@100ms","data":{"e":"depthUpdate","E":1604921131299,"s":"BTCUSDT","U":6511128870,"u":6511128898,"b":[["15508.04000000","6.03002100"],["15505.92000000","0.00000000"],["15502.91000000","0.00000000"],["15501.56000000","0.00000000"],["15501.19000000","0.00000000"],["15500.04000000","0.30000000"],["15499.31000000","0.00000000"],["15499.30000000","0.00000000"],["15499.12000000","0.00000000"],["15498.27000000","0.30211400"],["15496.00000000","0.07179800"],["15481.45000000","0.00000000"],["15472.15000000","0.27954600"]],"a":[["15508.05000000","0.43213100"],["15510.68000000","0.30000000"],["15510.69000000","0.00000000"],["15510.90000000","0.78253600"],["15510.92000000","0.36128800"],["15510.93000000","7.30600000"],["15511.69000000","0.00000000"],["15512.29000000","0.00000000"],["15513.63000000","0.12896200"],["15514.30000000","0.00000000"]]}}
2020-11-09T11:25:31.40984 btcusdt {"stream":"btcusdt@depth@100ms","data":{"e":"depthUpdate","E":1604921131399,"s":"BTCUSDT","U":6511128899,"u":6511128942,"b":[["15509.36000000","0.00690000"],["15508.82000000","0.56785000"],["15508.32000000","0.01462700"],["15508.11000000","0.02926700"],["15508.09000000","0.07557200"],["15508.04000000","5.80556900"],["15505.71000000","0.00000000"],["15503.85000000","0.00000000"],["15502.92000000","0.37594100"],["15502.32000000","0.00000000"],["15502.10000000","0.03223800"],["15500.26000000","0.01935500"],["15498.64000000","0.13426000"],["15497.76000000","0.14850000"],["15497.03000000","1.00000000"],["15496.00000000","0.00452100"],["15491.81000000","0.00202100"],["15433.36000000","0.00000000"]],"a":[["15508.05000000","0.00000000"],["15509.37000000","0.50690000"],["15509.78000000","0.02008700"],["15510.64000000","0.26899000"],["15510.66000000","0.00000000"],["15510.67000000","0.23926900"],["15510.90000000","0.00000000"],["15510.91000000","3.83300200"],["15510.92000000","0.36000000"],["15510.93000000","7.30400000"],["15513.51000000","0.00000000"],["15514.04000000","2.79100000"],["15514.45000000","0.20000000"],["15514.97000000","0.00000000"],["15520.86000000","0.01932900"],["15533.36000000","0.00000000"]]}}
2020-11-09T11:25:31.50680 btcusdt {"stream":"btcusdt@depth@100ms","data":{"e":"depthUpdate","E":1604921131499,"s":"BTCUSDT","U":6511128943,"u":6511128993,"b":[["15509.36000000","0.56785700"],["15508.82000000","0.00000000"],["15508.04000000","5.41047400"],["15507.64000000","0.00781300"],["15505.46000000","0.11427900"],["15504.66000000","0.00000000"],["15497.63000000","0.00300000"],["15493.67000000","0.06727700"],["15488.61000000","0.30600000"],["14880.15000000","0.00069900"]],"a":[["15509.37000000","7.74168100"],["15509.78000000","0.00000000"],["15509.83000000","0.00985100"],["15510.64000000","0.00000000"],["15510.67000000","0.00128800"],["15510.91000000","0.00000000"],["15510.92000000","0.00000000"],["15510.93000000","7.30200000"],["15511.17000000","0.00000000"],["15511.39000000","0.00000000"],["15511.91000000","0.11427900"],["15512.22000000","0.24000000"],["15512.32000000","2.00000000"],["15512.55000000","0.00000000"],["15512.72000000","0.00000000"],["15512.92000000","0.07524900"],["15513.15000000","0.01700000"],["15513.16000000","0.01700000"],["15513.36000000","0.00000000"],["15513.98000000","1.74800000"],["15514.03000000","0.00000000"],["15514.19000000","0.32100000"],["15514.28000000","0.06000000"],["15514.46000000","0.00000000"],["15514.86000000","0.00000000"],["15515.19000000","0.08200000"],["15515.78000000","0.01000000"],["15516.18000000","0.01500000"],["15522.88000000","0.05681900"],["15523.88000000","0.00000000"],["15526.91000000","0.87000000"]]}}
2020-11-09T11:25:31.60594 btcusdt {"stream":"btcusdt@depth@100ms","data":{"e":"depthUpdate","E":1604921131599,"s":"BTCUSDT","U":6511128994,"u":6511129002,"b":[["15509.36000000","0.51755200"],["15503.29000000","1.90758300"],["15496.08000000","1.00872800"],["15494.48000000","0.00000000"],["15446.29000000","0.00000000"]],"a":[["15509.37000000","8.04289900"],["15510.93000000","7.30000000"],["15513.97000000","0.00305600"]]}}
2020-11-09T11:25:31.70615 btcusdt {"stream":"btcusdt@depth@100ms","data":{"e":"depthUpdate","E":1604921131699,"s":"BTCUSDT","U":6511129003,"u":6511129013,"b":[["15509.36000000","0.00000000"],["15499.04000000","0.00000000"],["15492.81000000","0.23546800"],["15480.13000000","0.03875900"],["15445.53000000","0.24172200"]],"a":[["15508.59000000","0.50931000"],["15509.37000000","7.54239900"],["15839.46000000","0.00000000"]]}}
2020-11-09T11:25:31.80594 btcusdt {"stream":"btcusdt@depth@100ms","data":{"e":"depthUpdate","E":1604921131799,"s":"BTCUSDT","U":6511129014,"u":6511129059,"b":[["15508.32000000","5.87391900"],["15508.09000000","0.00000000"],["15507.90000000","0.00000000"],["15504.53000000","0.72000000"],["15500.25000000","0.00000000"],["15497.65000000","0.50435600"],["15496.86000000","0.00000000"]],"a":[["15508.33000000","0.50931000"],["15508.58000000","0.00000000"],["15508.59000000","0.00000000"],["15508.84000000","0.00627400"],["15508.85000000","0.00690000"],["15509.33000000","0.00000000"],["15509.35000000","2.17474500"],["15509.36000000","0.20000000"],["15509.37000000","7.00000000"],["15509.78000000","0.02008700"],["15510.93000000","2.00000000"],["15513.97000000","0.00000000"],["15514.13000000","0.08200000"],["15524.25000000","0.00000000"]]}}
2020-11-09T11:25:31.90676 btcusdt {"stream":"btcusdt@depth@100ms","data":{"e":"depthUpdate","E":1604921131899,"s":"BTCUSDT","U":6511129060,"u":6511129094,"b":[["15508.32000000","6.28417700"],["15508.04000000","0.00690000"],["15505.53000000","0.00000000"],["15505.13000000","0.12000000"],["15501.66000000","0.00000000"],["15500.19000000","0.02236400"],["15497.93000000","0.13437600"],["15492.81000000","0.00000000"],["15490.53000000","0.23546800"],["15430.77000000","0.00648000"]],"a":[["15508.33000000","0.62927900"],["15509.34000000","0.00000000"],["15509.35000000","0.00000000"],["15510.68000000","0.00000000"],["15512.91000000","0.30000000"],["15514.38000000","0.28000000"],["15514.45000000","0.00000000"],["15514.69000000","0.00000000"],["15517.99000000","0.02968800"],["15522.61000000","0.00000000"]]}}
2020-11-09T11:25:32.00672 btcusdt {"stream":"btcusdt@depth@100ms","data":{"e":"depthUpdate","E":1604921131999,"s":"BTCUSDT","U":6511129095,"u":6511129117,"b":[["15508.32000000","6.38775100"],["15507.98000000","0.00880200"],["15507.64000000","0.00000000"],["15496.04000000","0.13421400"]],"a":[["15508.33000000","0.55283000"],["15509.34000000","0.00000000"],["15509.35000000","0.00000000"],["15509.83000000","0.00000000"],["15509.96000000","0.00822100"],["15510.14000000","0.01931700"],["15511.70000000","0.00000000"],["15514.03000000","0.05000000"],["15514.28000000","0.01000000"],["15514.90000000","0.20000000"],["15519.99000000","0.42971400"],["15567.50000000","0.00000000"],["15841.50000000","0.00066500"]]}}
2020-11-09T11:25:32.10701 btcusdt {"stream":"btcusdt@depth@100ms","data":{"e":"depthUpdate","E":1604921132100,"s":"BTCUSDT","U":6511129118,"u":6511129138,"b":[["15508.32000000","13.38047200"],["15508.11000000","0.00000000"],["15503.87000000","0.10829900"]],"a":[["15508.33000000","0.54963000"],["15509.32000000","3.55701400"],["15509.33000000","0.00000000"],["15509.34000000","0.00000000"],["15514.90000000","0.00000000"],["15517.99000000","0.05875900"],["15528.28000000","0.00000000"]]}}
2020-11-09T11:25:32.20754 btcusdt {"stream":"btcusdt@depth@100ms","data":{"e":"depthUpdate","E":1604921132200,"s":"BTCUSDT","U":6511129139,"u":6511129160,"b":[["15508.32000000","13.36884500"],["15507.98000000","0.00000000"],["15507.31000000","0.01734500"],["15506.69000000","0.00745600"],["15499.41000000","0.20000000"],["15480.13000000","0.00000000"]],"a":[["15508.33000000","0.54643000"],["15509.32000000","3.10108800"],["15509.83000000","0.00908800"],["15509.96000000","0.00000000"],["15510.64000000","0.39509000"],["15513.97000000","0.01000000"],["15514.28000000","0.00000000"],["15517.98000000","0.17405700"],["15519.49000000","0.00000000"],["15519.73000000","0.03355400"],["15520.19000000","0.00200000"],["15520.45000000","0.06718600"],["15566.00000000","2.16527200"]]}}
2020-11-09T11:25:32.30746 btcusdt {"stream":"btcusdt@depth@100ms","data":{"e":"depthUpdate","E":1604921132300,"s":"BTCUSDT","U":6511129161,"u":6511129165,"b":[["15499.41000000","0.00000000"],["15242.99000000","0.00000000"]],"a":[["15508.33000000","0.54003000"],["15520.19000000","0.00000000"],["25000.00000000","20.89396300"]]}}
2020-11-09T11:25:32.40616 btcusdt {"stream":"btcusdt@depth@100ms","data":{"e":"depthUpdate","E":1604921132400,"s":"BTCUSDT","U":6511129166,"u":6511129175,"b":[["15508.32000000","13.36884500"],["15507.31000000","0.00000000"],["15503.78000000","0.03223800"],["15502.10000000","0.00000000"],["15414.00000000","0.00000000"]],"a":[["15508.33000000","0.53683000"],["15509.32000000","3.10108800"],["15519.30000000","0.00000000"]]}}
2020-11-09T11:25:32.51183 btcusdt {"stream":"btcusdt@depth@100ms","data":{"e":"depthUpdate","E":1604921132500,"s":"BTCUSDT","U":6511129176,"u":6511129198,"b":[["15508.32000000","7.96527100"],["15506.69000000","0.00000000"],["15503.78000000","0.00000000"],["15502.11000000","0.03223800"],["15498.80000000","0.30900000"],["15495.72000000","1.50000000"],["15491.41000000","0.12910400"]],"a":[["15508.33000000","0.54230500"],["15509.32000000","3.10108800"],["15509.83000000","0.00000000"],["15511.90000000","0.10000000"],["15512.91000000","0.20000000"],["15513.46000000","1.19800000"],["15514.04000000","1.59300000"],["15514.90000000","0.40000000"],["15521.88000000","0.05681900"],["15522.88000000","0.00000000"]]}}
2020-11-09T11:25:32.60598 btcusdt {"stream":"btcusdt@depth@100ms","data":{"e":"depthUpdate","E":1604921132600,"s":"BTCUSDT","U":6511129199,"u":6511129218,"b":[["15508.32000000","8.06474500"],["15495.72000000","0.00000000"],["15494.60000000","0.03872300"]],"a":[["15508.33000000","0.54310500"],["15509.32000000","3.10108800"],["15511.89000000","0.20000000"],["15512.91000000","0.00000000"],["15514.83000000","0.01000000"],["15514.90000000","0.00000000"],["15515.78000000","0.00000000"],["15538.31000000","0.00000000"],["15540.80000000","0.25792600"],["15548.56000000","0.00000000"],["25000.00000000","20.89296300"]]}}
2020-11-09T11:25:32.70661 btcusdt {"stream":"btcusdt@depth@100ms","data":{"e":"depthUpdate","E":1604921132700,"s":"BTCUSDT","U":6511129219,"u":6511129235,"b":[["15508.32000000","7.96117100"],["15503.30000000","0.02106400"],["15499.41000000","0.20000000"],["15495.63000000","0.00000000"],["15495.52000000","1.50000000"],["15324.57000000","0.00000000"]],"a":[["15508.33000000","0.54390500"],["15509.32000000","0.00000000"],["15520.00000000","5.57780900"],["15520.87000000","0.00000000"],["15522.98000000","0.00000000"]]}}
2020-11-09T11:25:32.80797 btcusdt {"stream":"btcusdt@depth@100ms","data":{"e":"depthUpdate","E":1604921132800,"s":"BTCUSDT","U":6511129236,"u":6511129277,"b":[["15508.32000000","0.41325800"],["15505.46000000","0.00000000"],["15504.97000000","0.11427900"],["15503.13000000","0.00000000"],["15502.34000000","0.01900000"],["15501.63000000","0.25760500"],["15501.02000000","0.12897200"],["15500.90000000","0.19169800"],["15499.41000000","0.00000000"],["15498.81000000","0.00000000"],["15497.47000000","0.10086700"],["15495.70000000","1.50000000"],["15495.52000000","0.00000000"],["15490.92000000","0.19419500"]],"a":[["15508.33000000","2.55198900"],["15509.35000000","2.07159600"],["15510.63000000","0.20000000"],["15511.03000000","0.11427900"],["15511.89000000","0.00000000"],["15511.91000000","0.00000000"],["15512.32000000","0.00000000"],["15512.91000000","0.00304000"],["15515.23000000","0.26459100"],["15515.36000000","0.00000000"],["15517.09000000","0.00000000"],["15517.73000000","0.00000000"],["15519.15000000","0.01382400"],["15519.99000000","0.40548900"],["15522.29000000","0.00000000"],["15529.07000000","0.00000000"],["15541.93000000","0.00000000"]]}}
2020-11-09T11:25:32.90900 btcusdt {"stream":"btcusdt@depth@100ms","data":{"e":"depthUpdate","E":1604921132900,"s":"BTCUSDT","U":6511129278,"u":6511129312,"b":[["15508.32000000","0.00000000"],["15508.04000000","0.01380000"],["15505.02000000","0.00000000"],["15504.91000000","0.01804400"],["15503.87000000","0.00000000"],["15503.29000000","1.55000000"],["15502.88000000","0.00000000"],["15500.90000000","0.00000000"],["15500.85000000","0.10000000"],["15463.66000000","0.00000000"],["15420.00000000","0.59253500"]],"a":[["15508.05000000","1.83472900"],["15508.19000000","0.00690000"],["15508.28000000","0.00000000"],["15508.31000000","0.06431500"],["15508.32000000","0.00000000"],["15508.33000000","2.85660500"],["15509.10000000","0.01604200"],["15509.35000000","0.00000000"],["15509.78000000","0.00000000"],["15510.14000000","0.00000000"],["15513.62000000","0.20000000"],["15513.96000000","0.50000000"],["15514.19000000","0.00000000"],["15517.99000000","0.08298400"],["15527.12000000","0.00000000"],["15536.99000000","0.16090600"]]}}
2020-11-09T11:25:33.00660 btcusdt {"stream":"btcusdt@depth@100ms","data":{"e":"depthUpdate","E":1604921133000,"s":"BTCUSDT","U":6511129313,"u":6511129338,"b":[["15504.15000000","0.00804100"],["15500.40000000","0.06717200"],["15500.30000000","0.00000000"],["15325.57000000","0.00065300"]],"a":[["15508.05000000","1.77146400"],["15508.33000000","2.55198900"],["15508.79000000","0.00807400"],["15509.09000000","0.20000000"],["15510.62000000","0.10000000"],["15510.63000000","0.00000000"],["15511.90000000","0.00000000"],["15512.81000000","0.32100000"],["15512.91000000","0.50304000"],["15513.45000000","0.06000000"],["15513.97000000","0.00000000"],["15514.03000000","0.00000000"],["15514.46000000","0.01000000"],["15514.83000000","0.00000000"],["15514.86000000","0.01500000"],["15516.18000000","0.00000000"],["15517.30000000","0.00000000"],["15517.71000000","0.40548900"],["15519.99000000","0.00000000"],["15557.94000000","0.00000000"]]}}
2020-11-09T11:25:33.10802 btcusdt {"stream":"btcusdt@depth@100ms","data":{"e":"depthUpdate","E":1604921133100,"s":"BTCUSDT","U":6511129339,"u":6511129365,"b":[["15508.04000000","0.00000000"],["15506.52000000","0.00690000"],["15505.90000000","2.00000000"],["15505.13000000","0.00000000"],["15505.03000000","0.00000000"],["15505.00000000","0.98663500"],["15504.97000000","0.00000000"],["15502.34000000","0.04400000"],["15500.08000000","0.00000000"],["15498.10000000","0.03362300"],["15497.63000000","0.00000000"]],"a":[["15506.53000000","0.00690000"],["15507.93000000","0.25537700"],["15508.04000000","0.24789700"],["15508.05000000","9.37487700"],["15510.67000000","0.00000000"],["15510.93000000","0.00000000"],["15512.62000000","0.31590000"],["15513.15000000","0.00000000"],["15513.60000000","0.25771400"],["15514.47000000","0.00000000"],["15518.40000000","0.31800000"],["15520.74000000","0.00000000"],["15524.48000000","0.31900000"],["15606.00000000","0.11961300"]]}}
2020-11-09T11:25:33.20770 btcusdt {"stream":"btcusdt@depth@100ms","data":{"e":"depthUpdate","E":1604921133200,"s":"BTCUSDT","U":6511129366,"u":6511129433,"b":[["15506.52000000","6.68396700"],["15505.07000000","0.07908700"],["15504.93000000","0.04000000"],["15503.86000000","0.00000000"],["15503.60000000","0.11427900"],["15503.29000000","1.50000000"],["15502.33000000","0.00000000"],["15501.38000000","0.15881600"],["15501.37000000","0.00000000"],["15500.41000000","0.05000000"],["15498.80000000","0.00000000"],["15489.13000000","0.15300000"],["15488.61000000","0.00000000"],["15411.00000000","1.08967400"]],"a":[["15506.53000000","0.50690000"],["15507.25000000","0.00000000"],["15507.26000000","0.00000000"],["15507.28000000","0.02008700"],["15507.89000000","0.39191300"],["15507.90000000","0.00000000"],["15507.91000000","0.00000000"],["15507.93000000","0.00000000"],["15507.97000000","0.00000000"],["15508.01000000","0.00000000"],["15508.04000000","0.78382400"],["15508.05000000","2.00400000"],["15508.31000000","0.00000000"],["15508.33000000","2.16692200"],["15509.09000000","0.00000000"],["15510.49000000","0.11427900"],["15510.61000000","0.20000000"],["15510.95000000","0.03400000"],["15511.03000000","0.00000000"],["15511.78000000","1.74800000"],["15512.51000000","1.19800000"],["15512.78000000","0.06000000"],["15512.79000000","0.15700000"],["15512.83000000","1.17364100"],["15512.91000000","0.50000000"],["15513.16000000","0.00000000"],["15513.46000000","0.00000000"],["15513.98000000","0.00000000"],["15514.51000000","0.00000000"],["15517.43000000","0.00000000"],["15527.68000000","0.00000000"]]}}
2020-11-09T11:25:33.30722 btcusdt {"stream":"btcusdt@depth@100ms","data":{"e":"depthUpdate","E":1604921133300,"s":"BTCUSDT","U":6511129434,"u":6511129458,"b":[["15506.52000000","14.37037300"],["15499.99000000","0.00988000"],["15498.38000000","0.06719500"],["15497.03000000","1.30600000"],["15496.98000000","0.15000000"],["15387.00000000","0.37683000"]],"a":[["15506.53000000","0.50250000"],["15507.89000000","0.00000000"],["15508.02000000","1.00264600"],["15508.03000000","0.00000000"],["15508.04000000","0.00128800"],["15508.18000000","0.00000000"],["15510.61000000","0.28000000"],["15513.62000000","0.00000000"],["15557.00000000","0.00065500"],["15621.25000000","0.00000000"]]}}
2020-11-09T11:25:33.40729 btcusdt {"stream":"btcusdt@depth@100ms","data":{"e":"depthUpdate","E":1604921133400,"s":"BTCUSDT","U":6511129459,"u":6511129467,"b":[["15506.52000000","9.07037300"],["15502.93000000","0.08000000"],["15497.44000000","0.03355400"],["15470.00000000","0.03232000"],["15430.77000000","0.00000000"]],"a":[["15506.53000000","0.49930000"],["15508.02000000","0.00000000"],["15508.04000000","0.47478300"],["15513.95000000","0.20000000"]]}}
2020-11-09T11:25:33.50897 btcusdt {"stream":"btcusdt@depth@100ms","data":{"e":"depthUpdate","E":1604921133500,"s":"BTCUSDT","U":6511129468,"u":6511129476,"b":[["15501.03000000","0.06738000"],["15482.80000000","0.00000000"],["15475.04000000","0.25795600"]],"a":[["15509.09000000","0.20000000"],["15510.61000000","0.08000000"],["15512.69000000","0.10000000"],["15513.95000000","0.00000000"],["15564.00000000","0.48510300"],["15620.41000000","0.00066900"]]}}
2020-11-09T11:25:33.60722 btcusdt {"stream":"btcusdt@depth@100ms","data":{"e":"depthUpdate","E":1604921133601,"s":"BTCUSDT","U":6511129477,"u":6511129492,"b":[["15506.52000000","14.37037300"],["15496.08000000","0.00000000"],["15468.00000000","2.00000000"],["15466.75000000","0.00000000"],["15466.65000000","0.00000000"],["15445.53000000","0.00172200"]],"a":[["15506.53000000","0.49610000"],["15508.03000000","0.20000000"],["15508.04000000","1.00738300"],["15508.72000000","0.01994800"],["15509.10000000","0.00000000"],["15509.36000000","0.00000000"],["15512.94000000","0.01000000"],["15514.46000000","0.00000000"],["15535.50000000","0.00000000"],["15556.00000000","2.75486200"]]}}
2020-11-09T11:25:33.70853 btcusdt {"stream":"btcusdt@depth@100ms","data":{"e":"depthUpdate","E":1604921133701,"s":"BTCUSDT","U":6511129493,"u":6511129498,"b":[["15497.03000000","2.31467900"]],"a":[["15506.53000000","0.49290000"],["15508.64000000","0.00913800"],["15508.79000000","0.00000000"],["15509.09000000","0.00000000"],["15523.93000000","0.00000000"]]}}
2020-11-09T11:25:33.80970 btcusdt {"stream":"btcusdt@depth@100ms","data":{"e":"depthUpdate","E":1604921133801,"s":"BTCUSDT","U":6511129499,"u":6511129505,"b":[["15504.54000000","0.13500000"],["15242.99000000","0.00590400"]],"a":[["15506.53000000","0.48970000"],["15508.33000000","2.15977000"],["15510.48000000","0.20000000"],["15514.29000000","0.00000000"],["15535.89000000","0.85397900"]]}}
2020-11-09T11:25:33.90802 btcusdt {"stream":"btcusdt@depth@100ms","data":{"e":"depthUpdate","E":1604921133901,"s":"BTCUSDT","U":6511129506,"u":6511129515,"b":[["15500.78000000","0.19479500"],["15500.19000000","0.00000000"],["15493.23000000","0.19580100"],["15428.98000000","0.00648100"]],"a":[["15506.53000000","0.42636300"],["15513.44000000","0.20000000"],["15524.53000000","0.00000000"],["15525.00000000","0.00317600"],["15606.00000000","0.01134000"]]}}
2020-11-09T11:25:34.00724 btcusdt {"stream":"btcusdt@depth@100ms","data":{"e":"depthUpdate","E":1604921134001,"s":"BTCUSDT","U":6511129516,"u":6511129527,"b":[["15500.95000000","0.05000000"],["15500.41000000","0.00000000"],["15490.01000000","0.02236400"],["15460.16000000","0.01034900"],["15460.06000000","0.01034900"]],"a":[["15506.53000000","0.42316300"],["15512.61000000","0.05000000"],["15513.45000000","0.01000000"],["15517.99000000","0.56673100"],["15518.50000000","0.00000000"],["15522.08000000","0.01030700"]]}}
2020-11-09T11:25:34.10776 btcusdt {"stream":"btcusdt@depth@100ms","data":{"e":"depthUpdate","E":1604921134101,"s":"BTCUSDT","U":6511129528,"u":6511129538,"b":[["15506.52000000","14.37037300"],["15504.15000000","0.00000000"],["15502.66000000","0.00781000"],["15387.00000000","0.48510300"]],"a":[["15506.53000000","0.41996300"],["15508.33000000","2.15577000"],["15508.64000000","0.00000000"],["15508.72000000","0.01824700"],["15525.00000000","0.00000000"]]}}
2020-11-09T11:25:34.21036 btcusdt {"stream":"btcusdt@depth@100ms","data":{"e":"depthUpdate","E":1604921134201,"s":"BTCUSDT","U":6511129539,"u":6511129553,"b":[["15506.52000000","12.32037300"],["15443.95000000","0.24000000"],["15411.00000000","0.71284400"]],"a":[["15506.53000000","0.42076300"],["15507.01000000","0.00748100"],["15508.33000000","2.14777000"],["15512.61000000","0.06000000"],["15513.34000000","0.01500000"],["15513.45000000","0.00000000"],["15514.86000000","0.00000000"],["15522.91000000","0.24000000"],["15528.00000000","0.00146600"]]}}
2020-11-09T11:25:34.32386 btcusdt {"stream":"btcusdt@depth@100ms","data":{"e":"depthUpdate","E":1604921134301,"s":"BTCUSDT","U":6511129554,"u":6511129563,"b":[["15506.52000000","13.84348200"],["15504.91000000","0.00000000"],["15443.95000000","0.00000000"]],"a":[["15506.53000000","0.41756300"],["15508.33000000","2.14377000"],["15508.72000000","0.00000000"],["15561.00000000","0.26473100"]]}}
2020-11-09T11:25:34.40913 btcusdt {"stream":"btcusdt@depth@100ms","data":{"e":"depthUpdate","E":1604921134401,"s":"BTCUSDT","U":6511129564,"u":6511129577,"b":[["15503.33000000","0.01510600"],["15502.77000000","0.00906400"],["15502.66000000","0.00000000"],["15441.81000000","0.24000000"]],"a":[["15506.53000000","0.41436300"],["15507.01000000","0.00000000"],["15507.15000000","0.00769800"],["15507.30000000","0.01671300"],["15508.33000000","2.13977000"],["15510.48000000","0.00000000"],["15511.77000000","0.20000000"],["15512.92000000","0.00000000"],["15549.57000000","0.00000000"]]}}
2020-11-09T11:25:34.50925 btcusdt {"stream":"btcusdt@depth@100ms","data":{"e":"depthUpdate","E":1604921134501,"s":"BTCUSDT","U":6511129578,"u":6511129590,"b":[["15503.33000000","0.00000000"],["15503.04000000","0.01681200"]],"a":[["15506.53000000","0.39777500"],["15506.70000000","0.12800000"],["15507.30000000","0.01311200"],["15508.33000000","2.01177000"],["15515.00000000","0.00339400"],["15520.88000000","0.05681900"],["15521.88000000","0.00000000"]]}}
2020-11-09T11:25:34.60848 btcusdt {"stream":"btcusdt@depth@100ms","data":{"e":"depthUpdate","E":1604921134601,"s":"BTCUSDT","U":6511129591,"u":6511129611,"b":[["15502.77000000","0.00000000"],["15502.37000000","0.00631400"],["15438.91000000","0.50000000"],["15435.82000000","0.00000000"]],"a":[["15506.53000000","0.40257500"],["15506.99000000","0.00693700"],["15507.15000000","0.00000000"],["15508.33000000","2.00000000"],["15509.36000000","0.00000000"],["15510.48000000","0.20000000"],["15511.77000000","0.00000000"],["15514.53000000","0.09626000"],["15515.94000000","0.19274900"],["15518.31000000","0.30000000"],["15520.17000000","0.50000000"],["15521.04000000","0.00000000"],["15522.78000000","0.00000000"],["15558.65000000","0.00000000"]]}}
2020-11-09T11:25:34.70838 btcusdt {"stream":"btcusdt@depth@100ms","data":{"e":"depthUpdate","E":1604921134701,"s":"BTCUSDT","U":6511129612,"u":6511129614,"b":[],"a":[["15506.53000000","0.40737500"]]}}
2020-11-09T11:25:34.80858 btcusdt {"stream":"btcusdt@depth@100ms","data":{"e":"depthUpdate","E":1604921134801,"s":"BTCUSDT","U":6511129615,"u":6511129625,"b":[["15498.10000000","0.00000000"],["15497.47000000","0.00000000"]],"a":[["15506.53000000","0.31852100"],["15508.84000000","0.00000000"],["15512.09000000","0.00780500"],["15521.04000000","1.50000000"],["15522.70000000","0.33632800"],["15523.34000000","0.00000000"],["15535.63000000","0.00000000"]]}}
2020-11-09T11:25:34.90824 btcusdt {"stream":"btcusdt@depth@100ms","data":{"e":"depthUpdate","E":1604921134901,"s":"BTCUSDT","U":6511129626,"u":6511129635,"b":[["15504.53000000","0.00000000"],["15503.53000000","0.26000000"],["15497.56000000","0.03362300"],["15456.55000000","0.16174400"]],"a":[["15506.53000000","0.31532100"],["15512.53000000","0.29200000"],["15514.04000000","0.00000000"],["15517.71000000","0.42931700"],["15524.43000000","0.00000000"],["15603.00000000","0.11827300"]]}}
2020-11-09T11:25:35.00920 btcusdt {"stream":"btcusdt@depth@100ms","data":{"e":"depthUpdate","E":1604921135001,"s":"BTCUSDT","U":6511129636,"u":6511129646,"b":[["15504.41000000","0.50000000"],["15501.03000000","0.11738000"],["15500.95000000","0.00000000"],["15496.76000000","0.10087100"],["15408.00000000","0.43183000"]],"a":[["15506.53000000","0.31212100"],["15510.53000000","0.50000000"],["15512.52000000","0.05000000"],["15512.61000000","0.01000000"],["15515.93000000","1.00885800"],["15518.60000000","0.00000000"]]}}
2020-11-09T11:25:35.10953 btcusdt {"stream":"btcusdt@depth@100ms","data":{"e":"depthUpdate","E":1604921135101,"s":"BTCUSDT","U":6511129647,"u":6511129655,"b":[["15390.00000000","0.60008800"]],"a":[["15506.53000000","0.30892100"],["15507.30000000","0.01603700"],["15508.05000000","2.00000000"],["15511.77000000","0.12898400"],["15513.44000000","0.00000000"],["15528.00000000","0.00000000"]]}}
2020-11-09T11:25:35.20889 btcusdt {"stream":"btcusdt@depth@100ms","data":{"e":"depthUpdate","E":1604921135201,"s":"BTCUSDT","U":6511129656,"u":6511129666,"b":[["15506.52000000","12.84348200"],["15501.38000000","0.00201000"],["15500.26000000","0.00000000"]],"a":[["15506.53000000","0.30572100"],["15507.30000000","0.01970600"],["15512.29000000","0.01000000"],["15512.61000000","0.00000000"],["15512.77000000","0.20000000"],["15525.00000000","0.03610500"]]}}
2020-11-09T11:25:35.30840 btcusdt {"stream":"btcusdt@depth@100ms","data":{"e":"depthUpdate","E":1604921135301,"s":"BTCUSDT","U":6511129667,"u":6511129679,"b":[["15506.52000000","14.29348200"],["15504.54000000","0.00000000"],["15502.21000000","0.15680600"],["15135.93000000","0.00396400"]],"a":[["15506.53000000","0.30252100"],["15507.30000000","0.01709600"],["15509.36000000","0.30000000"],["15510.48000000","0.00000000"],["15510.62000000","0.00000000"],["15561.00000000","0.64156100"],["15700.00000000","71.77099700"]]}}
2020-11-09T11:25:35.40852 btcusdt {"stream":"btcusdt@depth@100ms","data":{"e":"depthUpdate","E":1604921135401,"s":"BTCUSDT","U":6511129680,"u":6511129690,"b":[["15506.52000000","14.29348200"]],"a":[["15506.53000000","0.29932100"],["15507.30000000","0.01643500"],["15512.77000000","0.00000000"],["15513.63000000","0.00000000"],["15519.62000000","1.00000000"],["15522.77000000","0.00000000"]]}}
2020-11-09T11:25:35.50876 btcusdt {"stream":"btcusdt@depth@100ms","data":{"e":"depthUpdate","E":1604921135501,"s":"BTCUSDT","U":6511129691,"u":6511129693,"b":[],"a":[["15506.53000000","0.29612100"],["15509.36000000","0.20000000"],["15510.48000000","0.10000000"]]}}
2020-11-09T11:25:35.60826 btcusdt {"stream":"btcusdt@depth@100ms","data":{"e":"depthUpdate","E":1604921135602,"s":"BTCUSDT","U":6511129694,"u":6511129701,"b":[["15506.52000000","14.29348200"]],"a":[["15506.53000000","0.23277700"],["15507.30000000","0.01538200"],["15509.36000000","0.00000000"],["15510.48000000","0.30000000"]]}}
2020-11-09T11:25:35.70733 btcusdt {"stream":"btcusdt@depth@100ms","data":{"e":"depthUpdate","E":1604921135702,"s":"BTCUSDT","U":6511129702,"u":6511129707,"b":[["15503.61000000","0.11500000"]],"a":[["15506.53000000","0.16954500"],["15507.30000000","0.01273500"],["15603.00000000","0.01000000"]]}}
2020-11-09T11:25:35.80838 btcusdt {"stream":"btcusdt@depth@100ms","data":{"e":"depthUpdate","E":1604921135802,"s":"BTCUSDT","U":6511129708,"u":6511129712,"b":[["15506.52000000","12.84348200"],["15502.20000000","0.00000000"]],"a":[["15506.53000000","0.16634500"],["15558.57000000","0.00000000"],["15568.65000000","0.01541500"]]}}
2020-11-09T11:25:35.90971 btcusdt {"stream":"btcusdt@depth@100ms","data":{"e":"depthUpdate","E":1604921135902,"s":"BTCUSDT","U":6511129713,"u":6511129723,"b":[["15503.29000000","0.00000000"],["15499.26000000","1.50000000"],["15469.15000000","0.03100000"],["15390.00000000","0.70836100"],["15110.93000000","0.00661700"]],"a":[["15506.53000000","0.16279900"],["15510.48000000","0.20000000"],["15511.76000000","0.10000000"],["15517.98000000","0.19957500"],["15526.37000000","0.00000000"],["15555.99000000","0.35241900"]]}}
2020-11-09T11:25:36.00939 btcusdt {"stream":"btcusdt@depth@100ms","data":{"e":"depthUpdate","E":1604921136002,"s":"BTCUSDT","U":6511129724,"u":6511129742,"b":[["15506.52000000","8.43730200"],["15501.03000000","0.06738000"],["15501.02000000","0.00000000"],["15500.95000000","0.05000000"],["15500.78000000","0.00000000"],["15498.06000000","0.12897200"],["15472.13000000","0.00000000"],["15366.82000000","0.00000000"],["15297.91000000","0.00000000"]],"a":[["15506.53000000","0.16151000"],["15507.30000000","0.01290200"],["15512.28000000","0.05000000"],["15512.52000000","0.00000000"],["15528.19000000","0.00000000"],["15622.68000000","0.00000000"],["15639.08000000","0.00000000"],["15707.99000000","0.00187700"]]}}
2020-11-09T11:25:36.11210 btcusdt {"stream":"btcusdt@depth@100ms","data":{"e":"depthUpdate","E":1604921136102,"s":"BTCUSDT","U":6511129743,"u":6511129754,"b":[["15500.18000000","0.00000000"],["15499.40000000","0.00000000"],["15495.70000000","0.00000000"],["15472.15000000","0.02954600"],["15408.00000000","0.05500000"]],"a":[["15506.53000000","0.15831000"],["15507.30000000","0.00000000"],["15509.36000000","0.20000000"],["15510.48000000","0.00000000"],["15525.01000000","1.27980200"],["15549.70000000","0.00000000"],["15558.00000000","2.11115200"]]}}
2020-11-09T11:25:36.20961 btcusdt {"stream":"btcusdt@depth@100ms","data":{"e":"depthUpdate","E":1604921136202,"s":"BTCUSDT","U":6511129755,"u":6511129768,"b":[["15506.52000000","6.43730200"],["15505.90000000","2.04912000"],["15503.61000000","0.00000000"],["15503.30000000","0.00000000"],["15500.05000000","0.02106400"],["15494.47000000","1.50000000"]],"a":[["15506.53000000","0.15511000"],["15509.36000000","0.30000000"],["15511.75000000","0.20000000"],["15511.76000000","0.00000000"],["15512.27000000","0.01000000"],["15512.29000000","0.00000000"],["15517.15000000","0.10000000"],["15520.00000000","5.47780900"]]}}
2020-11-09T11:25:36.30968 btcusdt {"stream":"btcusdt@depth@100ms","data":{"e":"depthUpdate","E":1604921136302,"s":"BTCUSDT","U":6511129769,"u":6511129774,"b":[["15506.52000000","9.63730200"],["15505.75000000","0.07872600"],["15505.07000000","0.00000000"],["15502.34000000","0.02500000"],["15490.54000000","0.01936700"]],"a":[["15506.53000000","0.15191000"]]}}
2020-11-09T11:25:36.40915 btcusdt {"stream":"btcusdt@depth@100ms","data":{"e":"depthUpdate","E":1604921136402,"s":"BTCUSDT","U":6511129775,"u":6511129802,"b":[["15506.52000000","6.37694700"],["15505.90000000","0.04912000"],["15503.31000000","0.00000000"],["15503.28000000","0.00000000"],["15502.21000000","0.00000000"],["15501.04000000","0.15680600"],["15500.99000000","0.00000000"],["15499.83000000","1.25000000"],["15499.75000000","0.22500000"]],"a":[["15506.53000000","2.14871000"],["15508.03000000","1.30000100"],["15508.04000000","0.00128800"],["15509.36000000","0.20000000"],["15509.37000000","5.00000000"],["15510.48000000","0.10000000"]]}}
2020-11-09T11:25:36.50910 btcusdt {"stream":"btcusdt@depth@100ms","data":{"e":"depthUpdate","E":1604921136502,"s":"BTCUSDT","U":6511129803,"u":6511129818,"b":[["15500.40000000","0.00000000"],["15499.83000000","0.00000000"],["15499.78000000","1.25000000"],["15498.64000000","0.00000000"],["15498.27000000","0.00000000"],["15497.65000000","0.00000000"],["15497.03000000","1.30600000"],["15496.76000000","0.00000000"],["15496.39000000","0.00000000"],["15495.79000000","0.50645500"],["15495.58000000","0.00000000"],["15495.43000000","1.00889100"],["15493.52000000","0.20000000"],["15441.81000000","0.00000000"]],"a":[["15506.53000000","2.39185600"]]}}
2020-11-09T11:25:36.60889 btcusdt {"stream":"btcusdt@depth@100ms","data":{"e":"depthUpdate","E":1604921136602,"s":"BTCUSDT","U":6511129819,"u":6511129827,"b":[["15499.75000000","0.00000000"],["15498.40000000","0.06724200"],["15496.75000000","0.13448300"],["15495.88000000","0.30258700"],["15494.67000000","0.10086500"],["15489.28000000","0.00000000"]],"a":[["15506.53000000","2.48944700"]]}}
2020-11-09T11:25:36.70869 btcusdt {"stream":"btcusdt@depth@100ms","data":{"e":"depthUpdate","E":1604921136702,"s":"BTCUSDT","U":6511129828,"u":6511129832,"b":[["15503.60000000","0.00000000"]],"a":[["15506.53000000","2.46968900"],["15509.35000000","0.20000000"],["15509.36000000","0.00000000"],["15510.49000000","0.00000000"]]}}
2020-11-09T11:25:36.81127 btcusdt {"stream":"btcusdt@depth@100ms","data":{"e":"depthUpdate","E":1604921136802,"s":"BTCUSDT","U":6511129833,"u":6511129847,"b":[["15506.52000000","7.38094700"],["15500.51000000","0.01900000"],["15495.76000000","0.20000000"],["15384.00000000","0.43183000"]],"a":[["15506.53000000","0.47594200"],["15509.35000000","0.00000000"],["15510.48000000","0.00000000"],["15510.94000000","0.20000000"],["15511.74000000","0.10000000"],["15516.81000000","0.01382400"],["15519.15000000","0.00000000"]]}}
2020-11-09T11:25:36.91021 btcusdt {"stream":"btcusdt@depth@100ms","data":{"e":"depthUpdate","E":1604921136902,"s":"BTCUSDT","U":6511129848,"u":6511129861,"b":[["15506.52000000","8.43411700"],["15506.33000000","0.00200000"],["15502.11000000","0.00000000"],["15500.14000000","0.03224800"],["15493.57000000","0.00200000"],["15492.87000000","0.00200000"]],"a":[["15506.53000000","0.43886500"],["15506.70000000","0.00000000"],["15558.00000000","2.00287900"]]}}
2020-11-09T11:25:37.01106 btcusdt {"stream":"btcusdt@depth@100ms","data":{"e":"depthUpdate","E":1604921137002,"s":"BTCUSDT","U":6511129862,"u":6511129898,"b":[["15506.52000000","3.44357600"],["15504.93000000","0.00000000"],["15503.57000000","0.00000000"],["15503.53000000","0.00000000"],["15503.13000000","0.08000000"],["15502.93000000","0.00000000"],["15502.53000000","0.10000000"],["15501.57000000","0.08000000"],["15500.95000000","0.00000000"],["15500.92000000","1.25000000"],["15500.85000000","0.00000000"],["15500.15000000","0.05000000"],["15499.78000000","0.00000000"],["15498.50000000","0.10000000"],["15493.76000000","0.00200000"],["15476.42000000","0.00000000"],["15463.49000000","0.00400000"]],"a":[["15506.53000000","0.38972500"],["15510.24000000","0.03400000"],["15510.95000000","0.00000000"],["15511.48000000","1.19800000"],["15512.10000000","0.08200000"],["15512.28000000","0.00000000"],["15512.29000000","0.05000000"],["15512.51000000","0.00000000"],["15514.13000000","0.00000000"],["15522.91000000","0.00000000"],["15622.00000000","0.00000000"]]}}
2020-11-09T11:25:37.10937 btcusdt {"stream":"btcusdt@depth@100ms","data":{"e":"depthUpdate","E":1604921137102,"s":"BTCUSDT","U":6511129899,"u":6511129939,"b":[["15506.52000000","5.99398000"],["15506.28000000","0.07594500"],["15505.90000000","0.00000000"],["15505.75000000","0.00000000"],["15500.92000000","0.00000000"],["15500.78000000","0.00000000"],["15499.92000000","1.25251000"],["15499.60000000","0.41004500"],["15498.83000000","0.19323200"],["15497.56000000","0.00000000"],["15496.70000000","0.00000000"],["15492.87000000","0.00400000"],["15486.06000000","0.14550000"],["15467.76000000","0.25000000"]],"a":[["15506.53000000","0.05447100"],["15507.28000000","0.00000000"],["15509.36000000","0.08000000"],["15511.46000000","0.15700000"],["15512.09000000","0.00780500"],["15512.79000000","0.00000000"],["15513.30000000","0.15300000"],["15516.45000000","0.14400000"],["15517.06000000","0.00000000"],["15518.28000000","0.20000000"],["15519.02000000","0.00000000"],["15519.12000000","1.25000000"],["15522.32000000","0.00000000"],["15526.26000000","0.00000000"],["15545.29000000","0.25000000"],["15568.65000000","0.00000000"]]}}
2020-11-09T11:25:37.20982 btcusdt {"stream":"btcusdt@depth@100ms","data":{"e":"depthUpdate","E":1604921137203,"s":"BTCUSDT","U":6511129940,"u":6511129965,"b":[["15506.98000000","1.00000000"],["15506.75000000","0.00690000"],["15506.52000000","5.99398000"],["15506.45000000","0.07161600"],["15506.28000000","0.00000000"],["15495.57000000","0.03362200"],["15494.60000000","0.00000000"],["15441.07000000","0.24000000"]],"a":[["15506.53000000","0.00000000"],["15506.99000000","0.01383700"],["15509.72000000","0.84000000"],["15511.04000000","1.74800000"],["15511.73000000","0.12898500"],["15511.77000000","0.00000000"],["15511.78000000","0.00000000"],["15511.88000000","0.84000000"],["15512.21000000","0.01000000"],["15512.22000000","0.00000000"],["15512.27000000","0.00000000"],["15514.38000000","0.00000000"],["15522.18000000","0.24690000"],["15620.00000000","6.97338200"]]}}
2020-11-09T11:25:37.33124 btcusdt {"stream":"btcusdt@depth@100ms","data":{"e":"depthUpdate","E":1604921137303,"s":"BTCUSDT","U":6511129966,"u":6511129982,"b":[["15506.98000000","1.20066500"],["15506.66000000","0.07530400"],["15506.52000000","5.61771500"],["15506.45000000","0.00000000"],["15501.58000000","0.08000000"],["15500.15000000","0.00000000"],["15500.06000000","0.05000000"],["15493.57000000","0.00400000"]],"a":[["15507.30000000","0.01233800"],["15511.75000000","0.00000000"],["15512.94000000","0.00000000"],["15513.34000000","0.00000000"],["15513.40000000","0.01000000"],["15513.80000000","0.01500000"],["15515.93000000","0.00000000"],["15518.16000000","1.30592300"]]}}
2020-11-09T11:25:37.41036 btcusdt {"stream":"btcusdt@depth@100ms","data":{"e":"depthUpdate","E":1604921137403,"s":"BTCUSDT","U":6511129983,"u":6511129989,"b":[["15506.66000000","0.00000000"],["15428.98000000","0.00000000"]],"a":[["15506.99000000","0.25181800"],["15512.81000000","0.00000000"],["15515.00000000","0.00000000"],["15522.18000000","0.00690000"],["15566.00000000","0.16527200"]]}}
2020-11-09T11:25:37.51137 btcusdt {"stream":"btcusdt@depth@100ms","data":{"e":"depthUpdate","E":1604921137503,"s":"BTCUSDT","U":6511129990,"u":6511130029,"b":[["15506.98000000","8.52316700"],["15503.05000000","0.08000000"],["15502.38000000","0.03224400"],["15500.22000000","0.12897500"],["15500.14000000","0.00000000"],["15499.92000000","0.00251000"],["15499.78000000","1.25000000"],["15498.06000000","0.00000000"],["15493.97000000","0.00000000"]],"a":[["15506.99000000","0.19935900"],["15507.30000000","0.01663600"],["15509.36000000","0.00000000"],["15509.72000000","0.00000000"],["15510.24000000","0.00000000"],["15510.64000000","0.00000000"],["15511.04000000","0.00000000"],["15511.07000000","0.03400000"],["15511.46000000","0.00000000"],["15511.48000000","0.00000000"],["15511.80000000","0.32100000"],["15511.88000000","0.00000000"],["15511.90000000","1.74800000"],["15512.07000000","1.19800000"],["15512.10000000","0.00000000"],["15512.38000000","0.15700000"],["15512.83000000","0.00000000"],["15513.29000000","0.20000000"],["15514.10000000","0.08200000"],["15514.38000000","3.93000000"],["15519.88000000","0.05681900"],["15520.88000000","0.00000000"],["15520.99000000","0.24000000"]]}}
2020-11-09T11:25:37.60948 btcusdt {"stream":"btcusdt@depth@100ms","data":{"e":"depthUpdate","E":1604921137603,"s":"BTCUSDT","U":6511130030,"u":6511130121,"b":[["15507.29000000","13.17652700"],["15507.14000000","0.00690000"],["15507.01000000","0.00000000"],["15507.00000000","0.00000000"],["15506.99000000","0.03268400"],["15506.98000000","7.58824100"],["15506.84000000","0.07687900"],["15506.65000000","0.00000000"],["15506.52000000","2.11771500"],["15506.25000000","0.00000000"],["15505.13000000","0.78600000"],["15504.53000000","1.00000000"],["15504.41000000","0.00000000"],["15503.57000000","1.28000000"],["15503.13000000","0.00000000"],["15502.54000000","0.00868500"],["15502.53000000","0.00000000"],["15502.37000000","0.00000000"],["15501.57000000","0.00000000"],["15497.38000000","0.00291000"],["15488.35000000","0.30000000"],["15477.29000000","0.03876600"]],"a":[["15506.99000000","0.00000000"],["15507.30000000","0.02422400"],["15508.01000000","0.10064600"],["15508.02000000","0.00000000"],["15508.03000000","0.20000000"],["15508.05000000","0.00000000"],["15508.18000000","0.54167800"],["15508.33000000","0.00000000"],["15508.71000000","0.02008700"],["15509.37000000","0.00000000"],["15510.52000000","0.25000000"],["15510.61000000","0.00000000"],["15510.94000000","0.00000000"],["15511.07000000","0.00000000"],["15511.73000000","0.00000000"],["15511.74000000","0.00000000"],["15511.79000000","0.00000000"],["15511.80000000","0.00000000"],["15511.90000000","0.00000000"],["15511.94000000","0.03400000"],["15512.07000000","0.00000000"],["15512.20000000","0.00000000"],["15512.52000000","0.30395200"],["15512.68000000","0.72900200"],["15512.70000000","1.19800000"],["15512.77000000","1.84800000"],["15512.90000000","0.25000000"],["15513.28000000","0.20000000"],["15513.29000000","0.00000000"],["15513.96000000","0.00000000"],["15514.08000000","0.29100100"],["15514.09000000","0.50000000"],["15514.38000000","0.00000000"],["15514.90000000","0.27092500"],["15515.83000000","0.25087400"],["15517.70000000","0.26277400"],["15517.97000000","7.03469000"],["15558.00000000","2.11115200"]]}}
2020-11-09T11:25:37.70915 btcusdt {"stream":"btcusdt@depth@100ms","data":{"e":"depthUpdate","E":1604921137703,"s":"BTCUSDT","U":6511130122,"u":6511130164,"b":[["15507.29000000","13.54363500"],["15506.98000000","7.30000000"],["15506.84000000","0.00000000"],["15504.42000000","0.16500000"],["15500.95000000","0.05000000"],["15500.73000000","0.28800000"],["15500.06000000","0.00000000"],["15497.78000000","1.50000000"],["15497.02000000","0.15450000"],["15494.47000000","0.00000000"],["15441.07000000","0.00000000"],["15197.14000000","0.00174700"]],"a":[["15507.30000000","0.02313100"],["15508.01000000","0.00000000"],["15508.03000000","0.00000000"],["15508.18000000","0.00000000"],["15508.71000000","0.00000000"],["15510.51000000","0.00000000"],["15512.20000000","0.20000000"],["15512.21000000","0.00000000"],["15512.29000000","0.00000000"],["15512.52000000","0.00000000"],["15512.62000000","0.00690000"],["15512.67000000","1.60300200"],["15512.68000000","0.00000000"],["15512.76000000","0.06000000"],["15512.90000000","0.00000000"],["15513.30000000","0.00000000"],["15513.40000000","0.00000000"],["15513.72000000","0.01000000"],["15513.80000000","0.00000000"],["15514.12000000","0.01500000"],["15514.75000000","0.00000000"],["15519.12000000","0.00000000"],["15520.68000000","1.25000000"],["15520.99000000","0.00000000"],["15564.50000000","2.00000000"]]}}
2020-11-09T11:25:37.80965 btcusdt {"stream":"btcusdt@depth@100ms","data":{"e":"depthUpdate","E":1604921137803,"s":"BTCUSDT","U":6511130165,"u":6511130170,"b":[["15503.02000000","1.25000000"],["15502.39000000","0.20000000"],["15500.23000000","0.20000000"],["15499.78000000","0.00000000"]],"a":[["15515.94000000","0.00000000"],["15522.91000000","0.24000000"]]}}
2020-11-09T11:25:37.90927 btcusdt {"stream":"btcusdt@depth@100ms","data":{"e":"depthUpdate","E":1604921137903,"s":"BTCUSDT","U":6511130171,"u":6511130196,"b":[["15507.29000000","13.72363500"],["15506.98000000","2.00000000"],["15505.14000000","0.02106400"],["15504.48000000","0.03224000"],["15504.42000000","0.00000000"],["15502.38000000","0.00000000"],["15502.32000000","0.12896100"],["15502.01000000","0.19193000"],["15500.22000000","0.00000000"],["15500.05000000","0.00000000"],["15487.74000000","0.10000000"],["15441.42000000","0.24000000"],["15429.75000000","0.00648000"]],"a":[["15507.30000000","0.02653500"],["15510.51000000","0.06448500"],["15513.60000000","0.00000000"],["15517.15000000","0.00000000"],["15517.70000000","0.28699900"],["15517.98000000","0.17405700"],["15517.99000000","0.51343500"],["15519.53000000","0.10000000"],["15524.01000000","0.25768100"]]}}
2020-11-09T11:25:38.01126 btcusdt {"stream":"btcusdt@depth@100ms","data":{"e":"depthUpdate","E":1604921138003,"s":"BTCUSDT","U":6511130197,"u":6511130214,"b":[["15503.02000000","0.00000000"],["15501.50000000","1.25000000"],["15500.45000000","1.00000000"],["15500.28000000","1.50000000"],["15497.78000000","0.00000000"],["15497.03000000","0.30600000"],["15475.04000000","0.50795600"],["15471.01000000","0.25000000"]],"a":[["15507.30000000","0.03044000"],["15508.07000000","0.01759600"],["15517.69000000","0.05875900"],["15517.70000000","0.31251700"],["15517.99000000","0.45568200"],["15520.68000000","0.00000000"],["15522.91000000","0.00000000"]]}}
2020-11-09T11:25:38.11035 btcusdt {"stream":"btcusdt@depth@100ms","data":{"e":"depthUpdate","E":1604921138103,"s":"BTCUSDT","U":6511130215,"u":6511130233,"b":[["15507.29000000","13.86109500"],["15504.54000000","0.10828500"],["15501.04000000","0.00000000"],["15441.42000000","0.00000000"]],"a":[["15507.30000000","0.03244000"],["15507.76000000","0.00952500"],["15510.51000000","0.00000000"],["15512.18000000","0.24000100"],["15512.19000000","0.20000000"],["15513.28000000","0.00000000"],["15515.18000000","0.33379500"],["15515.23000000","0.26459100"],["15517.96000000","0.48374700"],["15517.99000000","0.00000000"],["15520.78000000","1.25000000"]]}}
2020-11-09T11:25:38.21223 btcusdt {"stream":"btcusdt@depth@100ms","data":{"e":"depthUpdate","E":1604921138203,"s":"BTCUSDT","U":6511130234,"u":6511130276,"b":[["15507.75000000","9.40881700"],["15507.52000000","0.00690000"],["15507.36000000","0.02786200"],["15507.35000000","0.00000000"],["15507.30000000","5.30000000"],["15507.29000000","0.87338900"],["15505.66000000","1.25000000"],["15501.50000000","0.00000000"],["15446.49000000","0.24000000"]],"a":[["15507.30000000","0.00000000"],["15507.76000000","0.01642500"],["15510.52000000","0.00000000"],["15512.18000000","0.00000000"],["15512.20000000","0.00000000"],["15512.38000000","0.00000000"],["15512.53000000","0.00000000"],["15512.67000000","0.00000000"],["15513.32000000","0.15700000"],["15513.49000000","0.29200000"],["15514.07000000","0.20000000"],["15514.08000000","0.00000000"],["15514.90000000","0.00000000"],["15515.18000000","0.00000000"],["15515.83000000","0.00000000"],["15517.70000000","0.04974300"],["15517.97000000","0.00000000"],["15527.28000000","0.24000000"],["15553.91000000","0.01543000"],["15561.00000000","0.26473100"]]}}
2020-11-09T11:25:38.31082 btcusdt {"stream":"btcusdt@depth@100ms","data":{"e":"depthUpdate","E":1604921138303,"s":"BTCUSDT","U":6511130277,"u":6511130327,"b":[["15508.03000000","8.96779000"],["15507.89000000","0.00690000"],["15507.79000000","0.00000000"],["15507.75000000","5.66212800"],["15507.36000000","0.00000000"],["15507.30000000","0.18000000"],["15507.29000000","0.40514800"],["15507.10000000","0.00200000"],["15504.10000000","0.01473900"],["15503.04000000","0.00000000"],["15502.39000000","0.00000000"],["15502.35000000","0.05000000"],["15500.95000000","0.00000000"],["15446.49000000","0.00000000"]],"a":[["15507.76000000","0.00000000"],["15508.04000000","0.00818800"],["15512.19000000","0.00000000"],["15512.70000000","0.00000000"],["15512.76000000","0.00000000"],["15512.77000000","1.74800000"],["15513.20000000","1.19800000"],["15513.72000000","0.00000000"],["15514.06000000","0.30000000"],["15514.08000000","0.06000000"],["15514.12000000","0.00000000"],["15514.18000000","0.01000000"],["15514.58000000","0.01500000"],["15516.44000000","0.00000000"],["15558.00000000","2.00287900"]]}}
2020-11-09T11:25:38.42471 btcusdt {"stream":"btcusdt@depth@100ms","data":{"e":"depthUpdate","E":1604921138403,"s":"BTCUSDT","U":6511130328,"u":6511130343,"b":[["15508.03000000","9.25049000"],["15507.75000000","5.37942800"],["15505.66000000","0.00000000"],["15503.48000000","0.00946600"],["15503.02000000","1.25000000"],["15502.54000000","0.00000000"],["15461.26000000","0.16169400"],["15456.55000000","0.00000000"],["15455.24000000","0.24000000"],["15431.01000000","2.42500000"],["15429.75000000","0.00000000"],["15384.00000000","0.05500000"],["15370.70000000","4.82500000"]],"a":[["15582.66000000","2.53300000"],["15642.97000000","6.20500000"],["15711.89000000","7.77500000"]]}}
2020-11-09T11:25:38.51470 btcusdt {"stream":"btcusdt@depth@100ms","data":{"e":"depthUpdate","E":1604921138503,"s":"BTCUSDT","U":6511130344,"u":6511130416,"b":[["15509.28000000","1.00690000"],["15508.82000000","0.00000000"],["15508.81000000","0.00000000"],["15508.24000000","0.09605400"],["15508.23000000","0.09132100"],["15508.22000000","0.00000000"],["15508.15000000","0.08157800"],["15508.07000000","0.00000000"],["15508.04000000","2.35000000"],["15508.03000000","5.78967600"],["15507.75000000","0.05500000"],["15503.02000000","0.00000000"],["15502.87000000","0.10000000"],["15501.72000000","0.50000000"],["15501.03000000","0.07032000"],["15499.83000000","1.25000000"],["15498.67000000","0.00000000"],["15498.50000000","0.00000000"],["15495.79000000","0.00201000"],["15495.43000000","0.00000000"],["15491.98000000","0.29400000"]],"a":[["15508.04000000","0.00000000"],["15508.07000000","0.00000000"],["15508.19000000","0.00000000"],["15508.85000000","0.00000000"],["15509.29000000","6.20590000"],["15509.74000000","0.00000000"],["15509.76000000","2.00000000"],["15510.35000000","0.02008700"],["15510.52000000","0.00000000"],["15510.53000000","0.47940800"],["15511.94000000","0.00000000"],["15512.46000000","0.00000000"],["15512.77000000","0.00000000"],["15513.20000000","0.00000000"],["15513.28000000","0.00000000"],["15513.32000000","0.00000000"],["15513.49000000","0.00000000"],["15513.70000000","0.03400000"],["15513.89000000","1.19800000"],["15514.07000000","0.00000000"],["15514.20000000","0.15700000"],["15514.37000000","0.29200000"],["15514.53000000","1.84426000"],["15514.97000000","0.20000000"],["15515.83000000","0.20000000"],["15516.80000000","0.00000000"],["15517.05000000","0.00000000"],["15519.12000000","1.25000000"],["15520.78000000","0.00000000"],["15535.89000000","0.00000000"]]}}
2020-11-09T11:25:38.61025 btcusdt {"stream":"btcusdt@depth@100ms","data":{"e":"depthUpdate","E":1604921138603,"s":"BTCUSDT","U":6511130417,"u":6511130486,"b":[["15509.28000000","0.00000000"],["15508.24000000","0.00000000"],["15508.23000000","0.00000000"],["15508.15000000","6.41047400"],["15508.03000000","2.35000000"],["15507.87000000","0.00000000"],["15507.75000000","0.00000000"],["15507.30000000","0.00000000"],["15507.29000000","0.32727600"],["15506.52000000","2.01414100"],["15505.15000000","0.15680600"],["15505.13000000","0.00000000"],["15504.54000000","0.00000000"],["15504.53000000","0.00000000"],["15504.43000000","0.08000000"],["15503.57000000","0.00000000"],["15502.87000000","0.18000000"],["15500.23000000","0.00000000"],["15499.83000000","0.00000000"],["15496.84000000","0.50437200"],["15496.48000000","1.00874500"],["15455.24000000","0.00000000"],["15408.00000000","0.43183000"],["15301.99000000","8.47900000"]],"a":[["15508.16000000","0.70908300"],["15508.49000000","0.11516900"],["15508.51000000","0.00000000"],["15508.73000000","0.00690000"],["15509.23000000","0.11788000"],["15509.28000000","0.00627400"],["15509.29000000","7.58960000"],["15509.74000000","0.02008700"],["15510.35000000","0.00000000"],["15511.15000000","0.08000000"],["15511.47000000","0.38737800"],["15513.26000000","1.19800000"],["15513.89000000","0.00000000"],["15514.08000000","0.00000000"],["15514.18000000","0.00000000"],["15514.58000000","0.00000000"],["15514.90000000","0.06000000"],["15515.71000000","0.01000000"],["15516.11000000","0.01500000"],["15516.55000000","0.06715100"],["15518.31000000","0.00000000"],["15519.94000000","0.00000000"],["15520.72000000","0.30000000"]]}}
2020-11-09T11:25:38.70984 btcusdt {"stream":"btcusdt@depth@100ms","data":{"e":"depthUpdate","E":1604921138703,"s":"BTCUSDT","U":6511130487,"u":6511130520,"b":[["15508.15000000","6.58960000"],["15508.04000000","0.00000000"],["15508.03000000","0.00000000"],["15504.43000000","0.00000000"],["15504.42000000","0.78600000"],["15504.10000000","0.00000000"],["15503.82000000","1.00000000"],["15502.87000000","0.10000000"],["15502.86000000","0.08000000"],["15502.25000000","0.00000000"],["15501.64000000","0.00000000"],["15501.03000000","0.06738000"],["15499.83000000","1.25000000"],["15491.98000000","0.00000000"],["15454.02000000","0.24000000"]],"a":[["15508.16000000","1.20908300"],["15509.29000000","7.30690000"],["15512.29000000","0.30000000"],["15512.82000000","0.03400000"],["15513.70000000","0.00000000"],["15514.06000000","0.00000000"],["15519.12000000","0.00000000"],["15520.02000000","1.25000000"],["15522.70000000","0.10086000"],["15525.68000000","0.23546800"]]}}
2020-11-09T11:25:38.81234 btcusdt {"stream":"btcusdt@depth@100ms","data":{"e":"depthUpdate","E":1604921138804,"s":"BTCUSDT","U":6511130521,"u":6511130529,"b":[["15506.52000000","2.01014100"],["15504.95000000","0.11427900"],["15503.48000000","0.00000000"],["15500.52000000","0.20000000"],["15489.22000000","0.15709300"]],"a":[["15508.16000000","1.21623500"],["15512.81000000","0.11427900"],["15606.00000000","0.38817000"]]}}
2020-11-09T11:25:38.91380 btcusdt {"stream":"btcusdt@depth@100ms","data":{"e":"depthUpdate","E":1604921138904,"s":"BTCUSDT","U":6511130530,"u":6511130538,"b":[["15468.00000000","0.00000000"],["15454.02000000","0.00000000"],["15430.60000000","0.00648000"]],"a":[["15508.16000000","3.21623500"],["15513.55000000","1.74800000"],["15514.53000000","0.09626000"],["15514.89000000","0.20000000"],["15525.83000000","0.00000000"],["15527.28000000","0.00000000"]]}}
2020-11-09T11:25:39.01171 btcusdt {"stream":"btcusdt@depth@100ms","data":{"e":"depthUpdate","E":1604921139004,"s":"BTCUSDT","U":6511130539,"u":6511130554,"b":[["15508.15000000","6.23165100"],["15502.35000000","0.00000000"],["15502.33000000","0.05000000"],["15450.40000000","0.00077200"],["15387.00000000","0.37683000"]],"a":[["15508.16000000","3.48685200"],["15512.97000000","0.32100000"],["15514.08000000","0.05000000"],["15514.90000000","0.01000000"],["15517.70000000","0.02422500"],["15517.71000000","0.40548900"],["15517.99000000","0.02551800"],["15523.89000000","0.02382800"],["15527.20000000","0.24000000"]]}}
2020-11-09T11:25:39.10953 btcusdt {"stream":"btcusdt@depth@100ms","data":{"e":"depthUpdate","E":1604921139104,"s":"BTCUSDT","U":6511130555,"u":6511130564,"b":[["15505.06000000","0.01315900"],["15504.42000000","0.00000000"],["15504.35000000","0.08000000"],["15503.82000000","0.00000000"],["15503.75000000","0.08000000"],["15500.73000000","0.00000000"],["15465.50000000","2.00000000"]],"a":[["15508.16000000","3.48522500"],["15509.00000000","0.01446800"],["15512.68000000","0.12897000"]]}}
2020-11-09T11:25:39.20986 btcusdt {"stream":"btcusdt@depth@100ms","data":{"e":"depthUpdate","E":1604921139204,"s":"BTCUSDT","U":6511130565,"u":6511130577,"b":[["15508.15000000","0.93165100"],["15500.52000000","0.00000000"],["15500.28000000","0.00000000"],["15497.24000000","1.50000000"],["15454.25000000","0.24000000"],["15408.00000000","0.54010300"],["15357.76000000","0.00000000"]],"a":[["15512.19000000","0.11427900"],["15512.81000000","0.00000000"],["15513.25000000","0.01000000"],["15513.54000000","0.12897600"],["15514.90000000","0.00000000"],["15985.44000000","0.04000000"]]}}
2020-11-09T11:25:39.30972 btcusdt {"stream":"btcusdt@depth@100ms","data":{"e":"depthUpdate","E":1604921139304,"s":"BTCUSDT","U":6511130578,"u":6511130587,"b":[["15508.15000000","0.93165100"],["15500.01000000","0.00000000"],["15454.25000000","0.00000000"]],"a":[["15509.22000000","0.20000000"],["15511.14000000","0.10000000"],["15512.29000000","0.20000000"],["15514.97000000","0.00000000"],["15527.20000000","0.00000000"]]}}
2020-11-09T11:25:39.41028 btcusdt {"stream":"btcusdt@depth@100ms","data":{"e":"depthUpdate","E":1604921139404,"s":"BTCUSDT","U":6511130588,"u":6511130606,"b":[["15505.41000000","0.01521700"],["15505.15000000","0.00000000"],["15505.06000000","0.00000000"],["15504.95000000","0.00000000"],["15503.06000000","0.15680600"],["15478.33000000","0.50000000"],["15475.22000000","0.00000000"],["15450.40000000","0.24077200"]],"a":[["15509.00000000","0.00000000"],["15509.54000000","0.01746700"],["15511.13000000","0.20000000"],["15512.02000000","0.03400000"],["15512.29000000","0.00000000"],["15512.82000000","0.00000000"],["15515.33000000","0.00097300"],["15521.44000000","0.24000000"],["15606.00000000","0.49644300"]]}}
2020-11-09T11:25:39.51160 btcusdt {"stream":"btcusdt@depth@100ms","data":{"e":"depthUpdate","E":1604921139504,"s":"BTCUSDT","U":6511130607,"u":6511130611,"b":[["15505.38000000","0.00644300"],["15461.26000000","0.00000000"]],"a":[["15508.16000000","3.42467200"],["15509.69000000","0.00886700"],["15514.77000000","0.29700000"]]}}
2020-11-09T11:25:39.61060 btcusdt {"stream":"btcusdt@depth@100ms","data":{"e":"depthUpdate","E":1604921139604,"s":"BTCUSDT","U":6511130612,"u":6511130631,"b":[["15508.15000000","0.00690000"],["15507.29000000","0.02874700"],["15506.98000000","0.00000000"],["15506.52000000","0.01014100"],["15503.06000000","0.00000000"],["15502.35000000","0.15680600"],["15500.90000000","1.13769700"]],"a":[["15508.16000000","8.72467200"],["15508.54000000","0.02008700"],["15508.81000000","0.00000000"],["15509.74000000","0.00000000"],["15512.19000000","0.00000000"],["15513.58000000","0.90496500"],["15514.58000000","0.01000000"],["15515.71000000","0.00000000"]]}}
2020-11-09T11:25:39.71293 btcusdt {"stream":"btcusdt@depth@100ms","data":{"e":"depthUpdate","E":1604921139704,"s":"BTCUSDT","U":6511130632,"u":6511130653,"b":[["15505.64000000","0.01900900"],["15505.47000000","0.00000000"],["15505.41000000","0.00000000"],["15504.35000000","0.08873800"],["15502.93000000","0.27797200"],["15501.73000000","0.41880200"],["15501.04000000","0.71056400"]],"a":[["15508.16000000","8.74475900"],["15508.54000000","0.00000000"],["15509.21000000","0.27000000"],["15509.54000000","0.00000000"],["15509.69000000","0.00000000"],["15509.80000000","0.01340000"],["15511.14000000","0.00000000"],["15511.66000000","0.29400000"],["15514.19000000","0.10216600"],["15515.83000000","0.00000000"],["15533.31000000","0.00000000"],["15577.18000000","0.00000000"],["15985.44000000","0.00000000"]]}}
2020-11-09T11:25:39.81483 btcusdt {"stream":"btcusdt@depth@100ms","data":{"e":"depthUpdate","E":1604921139804,"s":"BTCUSDT","U":6511130654,"u":6511130658,"b":[["15505.38000000","0.00000000"]],"a":[["15508.48000000","0.20000000"],["15508.66000000","0.00739400"],["15511.13000000","0.00000000"],["15514.19000000","0.00000000"]]}}
2020-11-09T11:25:39.91140 btcusdt {"stream":"btcusdt@depth@100ms","data":{"e":"depthUpdate","E":1604921139904,"s":"BTCUSDT","U":6511130659,"u":6511130682,"b":[["15505.64000000","0.00000000"],["15505.14000000","0.00000000"],["15504.54000000","0.01910300"],["15504.45000000","0.50000000"],["15502.02000000","0.02106400"],["15501.05000000","0.02236400"],["15500.45000000","0.00000000"],["15497.86000000","1.00000000"],["15497.24000000","0.00000000"],["15494.74000000","1.50000000"],["15490.01000000","0.00000000"],["14897.02000000","0.00000000"]],"a":[["15508.16000000","8.74675900"],["15508.93000000","0.01862900"],["15509.80000000","0.00000000"],["15511.01000000","0.50000000"],["15511.46000000","0.20000000"],["15511.80000000","0.01687000"],["15517.96000000","0.00000000"],["15519.99000000","0.05189300"],["15522.48000000","0.12122400"],["15523.89000000","0.00000000"]]}}
2020-11-09T11:25:40.01347 btcusdt {"stream":"btcusdt@depth@100ms","data":{"e":"depthUpdate","E":1604921140004,"s":"BTCUSDT","U":6511130683,"u":6511130691,"b":[["15508.15000000","0.00000700"],["15506.99000000","0.00000000"],["15497.02000000","0.00000000"],["15472.91000000","0.00120700"]],"a":[["15508.16000000","8.20986500"],["15512.67000000","0.05000000"],["15514.08000000","0.00000000"],["15519.61000000","0.45568200"]]}}
2020-11-09T11:25:40.11179 btcusdt {"stream":"btcusdt@depth@100ms","data":{"e":"depthUpdate","E":1604921140104,"s":"BTCUSDT","U":6511130692,"u":6511130695,"b":[],"a":[["15508.16000000","8.40986500"],["15508.47000000","0.15500000"],["15509.22000000","0.00000000"],["15522.13000000","0.00000000"]]}}
2020-11-09T11:25:40.21080 btcusdt {"stream":"btcusdt@depth@100ms","data":{"e":"depthUpdate","E":1604921140204,"s":"BTCUSDT","U":6511130696,"u":6511130705,"b":[["15503.47000000","0.11427900"],["15460.10000000","0.00000000"],["15387.00000000","0.00000000"],["15055.00000000","7.19269800"]],"a":[["15508.16000000","3.10986500"],["15513.25000000","0.00000000"],["15516.11000000","0.00000000"],["15518.51000000","0.30218500"],["15525.01000000","1.14557300"],["15561.00000000","0.15645800"]]}}
2020-11-09T11:25:40.31812 btcusdt {"stream":"btcusdt@depth@100ms","data":{"e":"depthUpdate","E":1604921140304,"s":"BTCUSDT","U":6511130706,"u":6511130717,"b":[["15508.15000000","0.00000000"],["15505.10000000","0.07000000"]],"a":[["15507.90000000","0.50000000"],["15508.03000000","0.00690000"],["15508.12000000","0.02886000"],["15508.14000000","0.04836800"],["15508.16000000","2.76769000"],["15512.66000000","0.00303500"],["15512.77000000","0.01000000"],["15514.98000000","0.26500000"]]}}
2020-11-09T11:25:40.41088 btcusdt {"stream":"btcusdt@depth@100ms","data":{"e":"depthUpdate","E":1604921140404,"s":"BTCUSDT","U":6511130718,"u":6511130745,"b":[["15507.89000000","0.00001200"],["15460.07000000","0.16170700"],["15430.60000000","0.00000000"]],"a":[["15507.90000000","7.74872600"],["15508.14000000","0.02828100"],["15508.16000000","2.29596400"],["15508.47000000","0.00000000"],["15508.49000000","0.00000000"],["15509.23000000","0.00000000"],["15509.29000000","2.00690000"],["15509.76000000","0.00000000"],["15510.53000000","0.00000000"],["15511.01000000","0.00000000"],["15511.14000000","0.11427900"],["15512.66000000","0.00000000"],["15512.70000000","1.74800000"],["15512.72000000","1.19800000"],["15512.97000000","0.00000000"],["15513.26000000","0.00000000"],["15513.55000000","0.00000000"],["15606.00000000","0.11961300"]]}}
2020-11-09T11:25:40.51234 btcusdt {"stream":"btcusdt@depth@100ms","data":{"e":"depthUpdate","E":1604921140504,"s":"BTCUSDT","U":6511130746,"u":6511130764,"b":[["15507.89000000","0.00201200"],["15504.91000000","0.01828500"],["15504.54000000","0.00601200"],["15504.35000000","0.08000000"],["15501.03000000","0.00000000"],["15459.25000000","0.03020000"]],"a":[["15507.90000000","8.57778400"],["15508.14000000","0.03028100"],["15508.62000000","0.00943400"],["15508.66000000","0.00000000"],["15509.21000000","0.17000000"],["15511.13000000","0.10000000"],["15514.01000000","0.01000000"],["15514.58000000","0.00000000"]]}}
2020-11-09T11:25:40.61351 btcusdt {"stream":"btcusdt@depth@100ms","data":{"e":"depthUpdate","E":1604921140605,"s":"BTCUSDT","U":6511130765,"u":6511130772,"b":[["15507.89000000","0.00002600"],["15507.29000000","0.00000000"],["15503.47000000","0.00000000"],["15500.95000000","0.06735800"],["15411.00000000","1.08967400"],["15197.14000000","0.00000000"],["14436.29000000","0.00000000"]],"a":[["15520.02000000","0.00000000"]]}}
2020-11-09T11:25:40.71101 btcusdt {"stream":"btcusdt@depth@100ms","data":{"e":"depthUpdate","E":1604921140705,"s":"BTCUSDT","U":6511130773,"u":6511130779,"b":[["15504.91000000","0.00000000"],["15504.36000000","0.01240600"],["15500.90000000","0.00000000"]],"a":[["15508.16000000","2.28881200"],["15518.10000000","1.25000000"]]}}
2020-11-09T11:25:40.81337 btcusdt {"stream":"btcusdt@depth@100ms","data":{"e":"depthUpdate","E":1604921140805,"s":"BTCUSDT","U":6511130780,"u":6511130787,"b":[["15504.54000000","0.00000000"],["15504.05000000","0.00698400"],["15501.04000000","0.00000000"],["15500.05000000","5.48809800"],["15450.40000000","0.00077200"]],"a":[["15507.90000000","3.27778400"],["15547.67000000","0.00000000"],["15603.00000000","0.38683000"]]}}
2020-11-09T11:25:40.91355 btcusdt {"stream":"btcusdt@depth@100ms","data":{"e":"depthUpdate","E":1604921140905,"s":"BTCUSDT","U":6511130788,"u":6511130809,"b":[["15507.89000000","0.00000000"],["15507.52000000","0.00041100"],["15504.36000000","0.00000000"],["15503.31000000","0.01659500"],["15502.93000000","0.00000000"],["15501.73000000","0.00000000"],["15500.05000000","0.00000000"],["15430.35000000","0.00648000"]],"a":[["15507.53000000","3.83280100"],["15507.72000000","0.00690000"],["15507.84000000","0.02951900"],["15507.86000000","0.03371100"],["15507.87000000","0.03201700"],["15507.88000000","0.02008700"],["15507.89000000","5.30000000"],["15507.90000000","2.42320400"],["15514.20000000","0.00000000"],["15606.00000000","0.01134000"]]}}
2020-11-09T11:25:41.01317 btcusdt {"stream":"btcusdt@depth@100ms","data":{"e":"depthUpdate","E":1604921141005,"s":"BTCUSDT","U":6511130810,"u":6511130841,"b":[["15507.52000000","0.00731100"],["15504.05000000","0.00000000"],["15502.99000000","0.00844900"],["15502.33000000","0.00000000"],["15502.32000000","0.00000000"],["15502.02000000","0.07106400"],["15500.33000000","0.22500000"],["15499.60000000","0.00000000"],["15472.91000000","0.00000000"]],"a":[["15507.53000000","5.99618200"],["15507.87000000","0.06146500"],["15507.88000000","0.00000000"],["15507.90000000","2.15763900"],["15507.99000000","0.00717800"],["15508.62000000","0.00000000"],["15509.29000000","0.00690000"],["15511.68000000","0.05000000"],["15511.81000000","0.01000000"],["15512.29000000","0.32100000"],["15512.67000000","0.00000000"],["15512.77000000","0.00000000"],["15512.90000000","0.15700000"],["15512.99000000","0.29200000"],["15513.62000000","0.01000000"],["15514.01000000","0.00000000"],["15514.37000000","0.00000000"],["15521.44000000","0.00000000"]]}}
2020-11-09T11:25:41.11327 btcusdt {"stream":"btcusdt@depth@100ms","data":{"e":"depthUpdate","E":1604921141105,"s":"BTCUSDT","U":6511130842,"u":6511130853,"b":[["15502.02000000","0.02106400"],["15501.64000000","0.05000000"],["15497.84000000","0.12895200"]],"a":[["15508.09000000","0.00200000"],["15509.21000000","0.00000000"],["15511.65000000","0.16123600"],["15511.68000000","0.00000000"],["15512.00000000","0.05000000"],["15513.62000000","0.00000000"],["15513.94000000","0.01000000"],["15524.01000000","0.00000000"],["15561.00000000","0.26473100"]]}}
2020-11-09T11:25:41.21194 btcusdt {"stream":"btcusdt@depth@100ms","data":{"e":"depthUpdate","E":1604921141205,"s":"BTCUSDT","U":6511130854,"u":6511130861,"b":[["15382.03000000","0.00000000"]],"a":[["15508.30000000","0.01209200"],["15508.93000000","0.00000000"],["15511.81000000","0.00000000"],["15512.13000000","0.01000000"],["15514.34000000","0.01500000"],["15514.98000000","0.25000000"],["15544.82000000","0.01200000"]]}}
2020-11-09T11:25:41.31178 btcusdt {"stream":"btcusdt@depth@100ms","data":{"e":"depthUpdate","E":1604921141305,"s":"BTCUSDT","U":6511130862,"u":6511130867,"b":[["15507.52000000","0.00690000"],["15503.14000000","0.00974900"],["15502.99000000","0.00000000"],["15380.01000000","0.38361400"]],"a":[["15507.89000000","0.00000000"],["15520.57000000","0.24000000"]]}}
2020-11-09T11:25:41.41157 btcusdt {"stream":"btcusdt@depth@100ms","data":{"e":"depthUpdate","E":1604921141405,"s":"BTCUSDT","U":6511130868,"u":6511130877,"b":[["15504.48000000","0.00000000"],["15502.78000000","0.03224400"],["15501.72000000","0.00000000"],["15500.64000000","0.12897500"],["15498.56000000","0.50000000"],["15497.84000000","0.00000000"],["15449.65000000","0.24000000"],["15430.35000000","0.00000000"]],"a":[["15508.48000000","0.00000000"],["15511.12000000","0.20000000"]]}}
2020-11-09T11:25:41.51433 btcusdt {"stream":"btcusdt@depth@100ms","data":{"e":"depthUpdate","E":1604921141505,"s":"BTCUSDT","U":6511130878,"u":6511130886,"b":[["15502.87000000","0.00000000"],["15502.02000000","0.00000000"],["15500.53000000","0.10000000"],["15411.00000000","0.71284400"]],"a":[["15507.53000000","5.93613100"],["15508.30000000","0.00000000"],["15518.10000000","0.00000000"],["15518.23000000","1.25000000"],["15545.29000000","0.25160800"]]}}
2020-11-09T11:25:41.61261 btcusdt {"stream":"btcusdt@depth@100ms","data":{"e":"depthUpdate","E":1604921141605,"s":"BTCUSDT","U":6511130887,"u":6511130897,"b":[["15507.52000000","0.00000600"],["15503.31000000","0.00000000"],["15503.14000000","0.00000000"],["15494.74000000","0.00000000"],["15493.47000000","1.50000000"],["15364.10000000","0.00065100"]],"a":[["15507.53000000","5.43613100"],["15511.12000000","0.00000000"],["15511.99000000","0.00302300"],["15515.50000000","0.00000000"]]}}
2020-11-09T11:25:41.71185 btcusdt {"stream":"btcusdt@depth@100ms","data":{"e":"depthUpdate","E":1604921141705,"s":"BTCUSDT","U":6511130898,"u":6511130927,"b":[["15505.10000000","0.00000000"],["15504.35000000","0.00000000"],["15503.75000000","0.00000000"],["15503.05000000","0.00000000"],["15502.86000000","0.00000000"],["15502.17000000","0.08000000"],["15501.58000000","0.08000000"],["15500.62000000","0.08000000"],["15500.33000000","0.00000000"],["15500.05000000","0.02106400"],["15498.83000000","0.00000000"],["14643.20000000","0.00171000"]],"a":[["15507.53000000","5.35894700"],["15507.83000000","0.20000000"],["15509.28000000","0.00000000"],["15511.19000000","0.01700000"],["15511.20000000","0.01700000"],["15511.54000000","0.08200000"],["15511.73000000","1.74800000"],["15512.02000000","0.00000000"],["15512.05000000","0.00000000"],["15512.70000000","0.00000000"],["15512.72000000","0.00000000"],["15512.90000000","0.00000000"],["15514.10000000","0.00000000"],["15517.68000000","0.29235200"],["15517.97000000","6.75132400"]]}}
2020-11-09T11:25:41.81388 btcusdt {"stream":"btcusdt@depth@100ms","data":{"e":"depthUpdate","E":1604921141805,"s":"BTCUSDT","U":6511130928,"u":6511130936,"b":[["15506.52000000","0.00000000"],["15499.83000000","1.25000000"],["15489.22000000","0.00000000"]],"a":[["15508.72000000","0.08000000"],["15510.91000000","0.02000000"],["15511.57000000","1.19800000"],["15511.82000000","0.15700000"],["15512.78000000","0.00000000"]]}}
2020-11-09T11:25:41.91220 btcusdt {"stream":"btcusdt@depth@100ms","data":{"e":"depthUpdate","E":1604921141905,"s":"BTCUSDT","U":6511130937,"u":6511130957,"b":[["15507.52000000","0.01014700"],["15501.92000000","0.11427900"],["15501.05000000","0.00000000"],["15500.05000000","0.04342800"],["15429.98000000","0.00648000"],["14643.20000000","0.02511000"]],"a":[["15507.83000000","0.00000000"],["15508.16000000","2.28681200"],["15508.72000000","0.00000000"],["15510.91000000","0.00000000"],["15511.12000000","0.20000000"],["15511.57000000","0.00000000"],["15511.73000000","0.00000000"],["15512.05000000","1.19800000"],["15512.37000000","1.74800000"],["15512.73000000","1.36000000"],["15517.97000000","0.00000000"],["15517.99000000","0.04934600"],["15518.10000000","1.25000000"],["15518.23000000","0.00000000"],["15519.99000000","0.02806500"]]}}
2020-11-09T11:25:42.01466 btcusdt {"stream":"btcusdt@depth@100ms","data":{"e":"depthUpdate","E":1604921142005,"s":"BTCUSDT","U":6511130958,"u":6511130982,"b":[["15507.52000000","0.00001100"],["15502.02000000","0.00000000"],["15501.64000000","0.00000000"],["15500.52000000","0.05000000"],["15499.83000000","0.00000000"],["15499.78000000","1.25000000"],["15499.03000000","0.42226600"],["15475.58000000","0.00000000"],["14903.17000000","0.00067100"]],"a":[["15507.53000000","5.20731800"],["15511.59000000","1.19800000"],["15512.05000000","0.00000000"],["15515.92000000","0.00000000"],["15517.97000000","0.45568200"],["15517.99000000","0.07741100"],["15518.09000000","1.25000000"],["15518.10000000","0.00000000"],["15519.61000000","0.00000000"],["15519.99000000","0.00000000"],["15538.64000000","0.00000000"],["15600.99000000","0.00000000"]]}}
2020-11-09T11:25:42.11271 btcusdt {"stream":"btcusdt@depth@100ms","data":{"e":"depthUpdate","E":1604921142105,"s":"BTCUSDT","U":6511130983,"u":6511131001,"b":[["15503.02000000","0.01282400"],["15502.82000000","0.00918200"],["15500.54000000","0.10834300"],["15491.10000000","0.00000000"],["15472.41000000","0.52760000"],["15467.76000000","0.00000000"],["15449.65000000","0.00000000"]],"a":[["15507.53000000","5.90231800"],["15508.30000000","0.01806600"],["15508.72000000","0.08000000"],["15511.99000000","0.00000000"],["15513.18000000","0.25772300"],["15518.09000000","0.00000000"],["15518.36000000","1.25690000"],["15518.92000000","0.13440500"],["15545.29000000","0.00160800"],["15567.53000000","0.00000000"],["15594.02000000","5.05350000"]]}}
2020-11-09T11:25:42.21272 btcusdt {"stream":"btcusdt@depth@100ms","data":{"e":"depthUpdate","E":1604921142205,"s":"BTCUSDT","U":6511131002,"u":6511131010,"b":[["15487.92000000","0.15910000"],["15444.18000000","0.24000000"],["15435.30000000","0.00000000"],["15360.23000000","0.00000000"]],"a":[["15507.53000000","6.05947000"],["15510.83000000","0.44000000"],["15512.73000000","0.00000000"],["15566.00000000","0.69287200"]]}}
2020-11-09T11:25:42.31247 btcusdt {"stream":"btcusdt@depth@100ms","data":{"e":"depthUpdate","E":1604921142306,"s":"BTCUSDT","U":6511131011,"u":6511131021,"b":[["15499.82000000","1.25000000"],["15499.78000000","0.00000000"],["15444.18000000","0.00000000"],["15432.14000000","5.05350000"],["14442.25000000","0.00069300"]],"a":[["15507.83000000","0.20000000"],["15508.30000000","0.00000000"],["15511.12000000","0.00000000"],["15511.53000000","1.74800000"],["15512.37000000","0.00000000"],["15603.00000000","0.01000000"]]}}
2020-11-09T11:25:42.41242 btcusdt {"stream":"btcusdt@depth@100ms","data":{"e":"depthUpdate","E":1604921142406,"s":"BTCUSDT","U":6511131022,"u":6511131028,"b":[["15429.98000000","0.00000000"],["15359.88000000","0.00067800"]],"a":[["15507.83000000","0.00000000"],["15508.14000000","0.02828100"],["15510.82000000","0.20000000"],["15512.68000000","0.00000000"],["15620.00000000","6.96238200"]]}}
2020-11-09T11:25:42.51248 btcusdt {"stream":"btcusdt@depth@100ms","data":{"e":"depthUpdate","E":1604921142506,"s":"BTCUSDT","U":6511131029,"u":6511131033,"b":[["15503.02000000","0.00000000"],["15441.96000000","0.24000000"],["15387.00000000","0.37683000"]],"a":[["15509.25000000","0.04000000"],["15603.00000000","0.11827300"]]}}
2020-11-09T11:25:42.61202 btcusdt {"stream":"btcusdt@depth@100ms","data":{"e":"depthUpdate","E":1604921142606,"s":"BTCUSDT","U":6511131034,"u":6511131041,"b":[["15507.52000000","0.00201100"],["15502.82000000","0.00000000"],["15502.45000000","0.00693300"]],"a":[["15507.83000000","0.20000000"],["15509.45000000","0.09661100"],["15510.82000000","0.00000000"],["15511.40000000","0.08000000"],["15619.00000000","0.01100000"]]}}
2020-11-09T11:25:42.71242 btcusdt {"stream":"btcusdt@depth@100ms","data":{"e":"depthUpdate","E":1604921142706,"s":"BTCUSDT","U":6511131042,"u":6511131048,"b":[["15507.52000000","0.00002500"]],"a":[["15507.53000000","11.35947000"],["15507.83000000","0.00000000"],["15509.24000000","0.20000000"],["15516.22000000","0.19483400"],["15561.00000000","0.64156100"],["15577.62000000","0.00000000"]]}}
2020-11-09T11:25:42.81364 btcusdt {"stream":"btcusdt@depth@100ms","data":{"e":"depthUpdate","E":1604921142806,"s":"BTCUSDT","U":6511131049,"u":6511131065,"b":[["15500.54000000","0.15834300"],["15500.52000000","0.00000000"],["15499.31000000","0.98806800"],["15498.78000000","0.19362000"]],"a":[["15507.53000000","6.05322600"],["15511.68000000","0.05000000"],["15511.81000000","0.01000000"],["15511.86000000","0.03224400"],["15512.00000000","0.00000000"],["15512.13000000","0.00000000"],["15513.62000000","0.01000000"],["15513.94000000","0.00000000"],["15514.02000000","0.01500000"],["15514.34000000","0.00000000"],["15517.43000000","0.21968500"],["15517.98000000","0.00000000"]]}}
2020-11-09T11:25:42.91189 btcusdt {"stream":"btcusdt@depth@100ms","data":{"e":"depthUpdate","E":1604921142906,"s":"BTCUSDT","U":6511131066,"u":6511131070,"b":[["15429.98000000","0.00648000"]],"a":[["15507.53000000","6.05130700"],["15509.24000000","0.00000000"],["15510.82000000","0.20000000"],["15577.99000000","0.00067400"]]}}
2020-11-09T11:25:43.01288 btcusdt {"stream":"btcusdt@depth@100ms","data":{"e":"depthUpdate","E":1604921143006,"s":"BTCUSDT","U":6511131071,"u":6511131071,"b":[],"a":[["15515.82000000","0.12897500"]]}}
2020-11-09T11:25:43.11371 btcusdt {"stream":"btcusdt@depth@100ms","data":{"e":"depthUpdate","E":1604921143106,"s":"BTCUSDT","U":6511131072,"u":6511131075,"b":[["15499.82000000","0.00000000"],["15468.76000000","0.25000000"]],"a":[["15514.89000000","0.00000000"],["15546.29000000","0.25000000"]]}}
2020-11-09T11:25:43.21255 btcusdt {"stream":"btcusdt@depth@100ms","data":{"e":"depthUpdate","E":1604921143206,"s":"BTCUSDT","U":6511131076,"u":6511131084,"b":[["15505.70000000","0.01370300"],["15505.46000000","0.00636400"],["15502.45000000","0.00000000"],["15499.77000000","1.25000000"]],"a":[["15507.53000000","6.17930700"],["15507.90000000","2.02963900"],["15508.30000000","0.01998900"],["15511.39000000","0.12898100"],["15511.79000000","0.20000000"]]}}
2020-11-09T11:25:43.32317 btcusdt {"stream":"btcusdt@depth@100ms","data":{"e":"depthUpdate","E":1604921143306,"s":"BTCUSDT","U":6511131085,"u":6511131086,"b":[],"a":[["15510.82000000","0.00000000"],["15511.79000000","0.00000000"]]}}
2020-11-09T11:25:43.41335 btcusdt {"stream":"btcusdt@depth@100ms","data":{"e":"depthUpdate","E":1604921143406,"s":"BTCUSDT","U":6511131087,"u":6511131089,"b":[["15500.00000000","14.46055400"]],"a":[["15508.30000000","0.00000000"],["15509.24000000","0.20000000"]]}}
2020-11-09T11:25:43.51368 btcusdt {"stream":"btcusdt@depth@100ms","data":{"e":"depthUpdate","E":1604921143506,"s":"BTCUSDT","U":6511131090,"u":6511131092,"b":[],"a":[["15509.44000000","0.10000000"],["15511.13000000","0.00000000"],["15511.39000000","0.00000000"]]}}
2020-11-09T11:25:43.61313 btcusdt {"stream":"btcusdt@depth@100ms","data":{"e":"depthUpdate","E":1604921143606,"s":"BTCUSDT","U":6511131093,"u":6511131131,"b":[["15507.52000000","0.00000000"],["15507.14000000","0.00001400"],["15502.35000000","0.00000000"],["15501.92000000","0.00000000"],["15501.18000000","0.11427900"]],"a":[["15507.15000000","4.86086200"],["15507.21000000","0.02008700"],["15507.42000000","0.00000000"],["15507.48000000","0.08898800"],["15507.49000000","0.04150300"],["15507.53000000","2.55146200"],["15508.12000000","0.00000000"],["15508.14000000","0.00000000"],["15508.16000000","2.20000000"],["15510.53000000","0.03400000"],["15510.65000000","0.11427900"],["15511.14000000","0.00000000"],["15511.19000000","0.00000000"],["15511.20000000","0.00000000"],["15517.68000000","0.00000000"]]}}
2020-11-09T11:25:43.71495 btcusdt {"stream":"btcusdt@depth@100ms","data":{"e":"depthUpdate","E":1604921143706,"s":"BTCUSDT","U":6511131132,"u":6511131149,"b":[["15500.96000000","0.15680600"],["15500.54000000","0.10834300"],["15500.52000000","0.05000000"],["15497.93000000","0.00000000"]],"a":[["15507.15000000","7.07028700"],["15507.53000000","2.51234600"],["15508.16000000","0.20000000"],["15511.31000000","0.05000000"],["15511.44000000","0.01000000"],["15511.68000000","0.00000000"],["15511.81000000","0.00000000"],["15513.25000000","0.01000000"],["15513.62000000","0.00000000"]]}}
2020-11-09T11:25:43.81349 btcusdt {"stream":"btcusdt@depth@100ms","data":{"e":"depthUpdate","E":1604921143806,"s":"BTCUSDT","U":6511131150,"u":6511131163,"b":[["15499.03000000","0.00100000"],["15494.94000000","0.13440100"],["15492.90000000","0.00000000"],["15486.79000000","0.07722000"]],"a":[["15507.15000000","7.05947600"],["15507.72000000","0.00890000"],["15509.44000000","0.00000000"],["15510.52000000","0.10000000"],["15511.82000000","0.44900000"],["15512.99000000","0.00000000"],["15513.98000000","0.12897500"],["15515.82000000","0.00000000"]]}}
2020-11-09T11:25:43.91397 btcusdt {"stream":"btcusdt@depth@100ms","data":{"e":"depthUpdate","E":1604921143907,"s":"BTCUSDT","U":6511131164,"u":6511131169,"b":[["15490.43000000","1.14451700"],["15429.98000000","0.00000000"]],"a":[["15508.30000000","0.01685200"],["15511.79000000","0.20000000"],["15515.90000000","1.25000000"],["15518.36000000","0.00690000"]]}}
2020-11-09T11:25:44.01455 btcusdt {"stream":"btcusdt@depth@100ms","data":{"e":"depthUpdate","E":1604921144007,"s":"BTCUSDT","U":6511131170,"u":6511131176,"b":[["15505.50000000","0.00881900"],["15505.46000000","0.00000000"]],"a":[["15508.30000000","0.00000000"],["15511.79000000","0.00000000"],["15515.90000000","0.00000000"],["15515.91000000","1.25000000"],["15527.74000000","0.00690000"]]}}
2020-11-09T11:25:44.12276 btcusdt {"stream":"btcusdt@depth@100ms","data":{"e":"depthUpdate","E":1604921144107,"s":"BTCUSDT","U":6511131177,"u":6511131184,"b":[["15500.96000000","0.00000000"],["15387.00000000","0.00000000"]],"a":[["15507.15000000","7.06147600"],["15507.47000000","0.10000000"],["15507.53000000","2.50519400"],["15508.30000000","0.01966800"],["15510.52000000","0.00000000"],["15525.00000000","0.00000000"]]}}
2020-11-09T11:25:44.21436 btcusdt {"stream":"btcusdt@depth@100ms","data":{"e":"depthUpdate","E":1604921144207,"s":"BTCUSDT","U":6511131185,"u":6511131201,"b":[["15502.35000000","0.15680600"]],"a":[["15507.20000000","0.20000000"],["15507.47000000","0.00000000"],["15508.30000000","0.01874200"],["15508.71000000","0.10000000"],["15509.24000000","0.00000000"],["15510.51000000","0.12899300"],["15511.58000000","0.20000000"],["15513.65000000","0.01500000"],["15514.02000000","0.00000000"],["15518.84000000","0.13440100"],["15521.93000000","0.00000000"],["15528.00000000","0.03610500"],["15560.00000000","4.53087500"]]}}
2020-11-09T11:25:44.31416 btcusdt {"stream":"btcusdt@depth@100ms","data":{"e":"depthUpdate","E":1604921144307,"s":"BTCUSDT","U":6511131202,"u":6511131247,"b":[["15507.14000000","0.00000000"],["15507.10000000","0.00000200"],["15505.50000000","0.00000000"],["15502.35000000","0.00000000"],["15500.96000000","0.15680600"],["15411.00000000","1.08967400"]],"a":[["15507.11000000","3.22531300"],["15507.13000000","0.00690000"],["15507.14000000","0.05422000"],["15507.15000000","2.29323900"],["15507.18000000","0.02008700"],["15507.21000000","0.00000000"],["15507.48000000","0.00000000"],["15507.49000000","0.00000000"],["15507.52000000","1.23750200"],["15507.53000000","2.28000000"],["15507.84000000","0.00000000"],["15507.86000000","0.00000000"],["15507.87000000","0.00000000"],["15507.90000000","2.00000000"],["15508.16000000","0.00000000"],["15511.39000000","1.25368900"],["15511.57000000","0.00000000"],["15511.58000000","0.00000000"],["15511.65000000","0.00000000"]]}}
2020-11-09T11:25:44.41452 btcusdt {"stream":"btcusdt@depth@100ms","data":{"e":"depthUpdate","E":1604921144407,"s":"BTCUSDT","U":6511131248,"u":6511131266,"b":[["15505.70000000","0.00000000"],["15429.56000000","0.00648100"]],"a":[["15507.11000000","3.12322500"],["15507.14000000","0.19422000"],["15507.15000000","2.04256900"],["15507.16000000","0.00000000"],["15507.18000000","0.00000000"],["15507.90000000","0.00000000"],["15508.30000000","0.00000000"],["15511.79000000","0.00000000"],["15517.86000000","0.30000000"],["15520.72000000","0.00000000"]]}}
2020-11-09T11:25:44.51812 btcusdt {"stream":"btcusdt@depth@100ms","data":{"e":"depthUpdate","E":1604921144507,"s":"BTCUSDT","U":6511131267,"u":6511131292,"b":[["15507.10000000","0.00000000"],["15506.75000000","0.00001200"]],"a":[["15506.76000000","6.33272600"],["15506.94000000","0.00690000"],["15506.97000000","0.02008700"],["15507.08000000","0.08569400"],["15507.11000000","0.33047500"],["15507.14000000","0.05422000"],["15507.52000000","0.00000000"],["15507.53000000","2.13000000"],["15510.02000000","0.11427900"],["15510.65000000","0.00000000"],["15511.85000000","0.20000000"]]}}
2020-11-09T11:25:44.61376 btcusdt {"stream":"btcusdt@depth@100ms","data":{"e":"depthUpdate","E":1604921144607,"s":"BTCUSDT","U":6511131293,"u":6511131314,"b":[["15500.52000000","0.00000000"],["15500.06000000","0.05000000"]],"a":[["15506.76000000","6.23356700"],["15506.94000000","0.02698700"],["15506.97000000","0.00000000"],["15507.10000000","0.17000000"],["15507.11000000","0.24646200"],["15507.20000000","0.00000000"],["15508.70000000","0.20000000"],["15510.24000000","0.75000000"],["15511.14000000","0.06000000"],["15511.31000000","0.00000000"],["15511.44000000","0.00000000"],["15511.81000000","0.01000000"],["15512.29000000","0.00000000"],["15513.25000000","0.00000000"],["15514.98000000","0.00000000"],["15545.62000000","0.15910000"]]}}
2020-11-09T11:25:44.71488 btcusdt {"stream":"btcusdt@depth@100ms","data":{"e":"depthUpdate","E":1604921144707,"s":"BTCUSDT","U":6511131315,"u":6511131316,"b":[],"a":[["15506.76000000","6.73356700"],["15507.99000000","0.00000000"]]}}
2020-11-09T11:25:44.81456 btcusdt {"stream":"btcusdt@depth@100ms","data":{"e":"depthUpdate","E":1604921144807,"s":"BTCUSDT","U":6511131317,"u":6511131323,"b":[["15505.53000000","0.01560400"],["15500.96000000","0.00000000"],["15499.31000000","0.00000000"],["15498.14000000","0.44570300"]],"a":[["15506.76000000","6.67353200"],["15507.88000000","0.01875400"],["15511.39000000","0.00000000"]]}}
2020-11-09T11:25:44.91534 btcusdt {"stream":"btcusdt@depth@100ms","data":{"e":"depthUpdate","E":1604921144907,"s":"BTCUSDT","U":6511131324,"u":6511131334,"b":[["15503.43000000","0.50000000"],["15502.35000000","0.15680600"],["15471.00000000","0.00000000"],["15429.56000000","0.00000000"]],"a":[["15507.88000000","0.01256400"],["15510.44000000","0.50000000"],["15511.52000000","0.32200000"],["15511.81000000","0.00000000"],["15512.20000000","0.01000000"],["15515.91000000","0.00000000"]]}}
2020-11-09T11:25:45.01394 btcusdt {"stream":"btcusdt@depth@100ms","data":{"e":"depthUpdate","E":1604921145007,"s":"BTCUSDT","U":6511131335,"u":6511131346,"b":[["15500.51000000","0.06900000"],["15500.06000000","0.00000000"],["12700.00000000","42.55164500"]],"a":[["15507.88000000","0.01461600"],["15510.52000000","0.05000000"],["15511.14000000","0.01000000"],["15511.85000000","0.00000000"],["15515.11000000","1.25000000"],["15517.41000000","0.00000000"],["15603.00000000","0.01000000"]]}}
2020-11-09T11:25:45.11423 btcusdt {"stream":"btcusdt@depth@100ms","data":{"e":"depthUpdate","E":1604921145107,"s":"BTCUSDT","U":6511131347,"u":6511131353,"b":[],"a":[["15507.88000000","0.01799800"],["15508.69000000","0.20000000"],["15508.70000000","0.00000000"],["15558.00000000","2.11115200"]]}}
2020-11-09T11:25:45.21465 btcusdt {"stream":"btcusdt@depth@100ms","data":{"e":"depthUpdate","E":1604921145207,"s":"BTCUSDT","U":6511131354,"u":6511131360,"b":[["15505.30000000","0.00637200"],["15470.00000000","2.03232000"]],"a":[["15507.57000000","0.00709000"],["15510.51000000","0.13899300"],["15511.14000000","0.00000000"],["15512.60000000","0.01500000"],["15513.65000000","0.00000000"]]}}
2020-11-09T11:25:45.31470 btcusdt {"stream":"btcusdt@depth@100ms","data":{"e":"depthUpdate","E":1604921145307,"s":"BTCUSDT","U":6511131361,"u":6511131367,"b":[["15506.75000000","0.00201200"],["15502.78000000","0.00000000"],["15502.35000000","0.00000000"],["15501.19000000","0.15680600"],["15501.01000000","0.03224400"],["15500.64000000","0.00000000"],["15496.86000000","0.12897500"]],"a":[]}}
2020-11-09T11:25:45.41418 btcusdt {"stream":"btcusdt@depth@100ms","data":{"e":"depthUpdate","E":1604921145407,"s":"BTCUSDT","U":6511131368,"u":6511131376,"b":[["15506.75000000","0.00002600"],["15505.53000000","0.00000000"],["15505.37000000","0.01522600"],["15496.04000000","0.00000000"],["15429.21000000","0.00648100"]],"a":[["15506.93000000","0.20000000"],["15507.53000000","2.14774900"],["15507.88000000","0.00000000"],["15508.69000000","0.00000000"]]}}
2020-11-09T11:25:45.51363 btcusdt {"stream":"btcusdt@depth@100ms","data":{"e":"depthUpdate","E":1604921145507,"s":"BTCUSDT","U":6511131377,"u":6511131450,"b":[["15506.75000000","0.00000000"],["15506.33000000","0.00000000"],["15505.37000000","1.01905200"],["15505.08000000","0.00000000"],["15504.62000000","0.07901600"],["15501.66000000","0.11427900"],["15501.18000000","0.00000000"],["15494.02000000","0.13440700"]],"a":[["15505.38000000","0.21729000"],["15505.95000000","1.75020700"],["15505.96000000","0.00000000"],["15505.97000000","0.00000000"],["15505.98000000","0.05869600"],["15506.07000000","0.00690000"],["15506.34000000","0.00000000"],["15506.56000000","0.06567400"],["15506.61000000","0.46356700"],["15506.62000000","0.00000000"],["15506.69000000","0.06823100"],["15506.76000000","2.42441500"],["15506.88000000","0.02008700"],["15506.94000000","0.00690000"],["15507.07000000","1.30292300"],["15507.08000000","0.00000000"],["15507.53000000","2.14574900"],["15509.35000000","0.11427900"],["15509.63000000","0.03400000"],["15510.02000000","0.00000000"],["15510.23000000","0.37500200"],["15510.42000000","1.04624900"],["15510.43000000","1.74800000"],["15510.53000000","0.00000000"],["15510.87000000","1.19800000"],["15511.39000000","0.00000000"],["15511.53000000","0.00000000"],["15511.59000000","0.00000000"],["15513.53000000","0.55697200"],["15515.11000000","0.00000000"],["15517.41000000","0.00000000"],["15518.09000000","1.25000000"]]}}
2020-11-09T11:25:45.61378 btcusdt {"stream":"btcusdt@depth@100ms","data":{"e":"depthUpdate","E":1604921145608,"s":"BTCUSDT","U":6511131451,"u":6511131491,"b":[["15505.37000000","6.66063800"],["15505.30000000","0.00000000"],["15505.18000000","0.00963100"],["15500.51000000","0.01900000"],["15500.06000000","0.05000000"],["15497.38000000","0.00000000"],["15488.35000000","0.00000000"]],"a":[["15505.38000000","0.19648800"],["15505.94000000","0.00000000"],["15505.95000000","0.00000000"],["15506.61000000","1.41542400"],["15506.75000000","0.27500000"],["15506.76000000","2.03072600"],["15507.07000000","0.00000000"],["15507.10000000","0.00000000"],["15507.22000000","0.00883300"],["15507.57000000","0.00000000"],["15509.85000000","0.05000000"],["15509.98000000","0.01000000"],["15510.42000000","0.00000000"],["15510.51000000","0.00000000"],["15510.52000000","0.00000000"],["15510.82000000","0.00000000"],["15511.46000000","0.00000000"],["15511.52000000","0.00000000"],["15511.79000000","0.01000000"],["15512.20000000","0.00000000"],["15513.54000000","0.00000000"]]}}
2020-11-09T11:25:45.71651 btcusdt {"stream":"btcusdt@depth@100ms","data":{"e":"depthUpdate","E":1604921145708,"s":"BTCUSDT","U":6511131492,"u":6511131514,"b":[["15505.37000000","8.76522500"],["15504.71000000","0.07313400"],["15504.69000000","0.00000000"],["15504.62000000","0.00000000"]],"a":[["15505.38000000","0.18812200"],["15505.98000000","0.00000000"],["15506.56000000","0.00000000"],["15506.69000000","0.00000000"],["15506.76000000","1.94711700"],["15506.93000000","0.00000000"],["15506.95000000","0.00200000"],["15507.11000000","0.20000000"],["15507.14000000","0.00627400"],["15507.15000000","2.00200000"],["15508.70000000","0.20000000"],["15508.71000000","0.00000000"],["15509.84000000","0.10000000"],["15517.41000000","1.25000000"],["15518.09000000","0.00000000"],["15533.95000000","0.00000000"],["15535.38000000","0.00000000"]]}}
2020-11-09T11:25:45.81466 btcusdt {"stream":"btcusdt@depth@100ms","data":{"e":"depthUpdate","E":1604921145808,"s":"BTCUSDT","U":6511131515,"u":6511131524,"b":[["15504.87000000","0.07825700"],["15504.71000000","0.00000000"]],"a":[["15505.38000000","0.12272900"],["15506.75000000","0.00000000"],["15507.22000000","0.00000000"],["15510.23000000","0.00000000"],["15510.24000000","0.00000000"],["15510.39000000","0.31800000"],["15511.88000000","0.75000000"]]}}
2020-11-09T11:25:45.91818 btcusdt {"stream":"btcusdt@depth@100ms","data":{"e":"depthUpdate","E":1604921145908,"s":"BTCUSDT","U":6511131525,"u":6511131556,"b":[["15506.06000000","1.39900000"],["15505.76000000","0.25000000"],["15505.44000000","0.05960200"],["15505.37000000","7.76522500"],["15505.17000000","0.07368500"],["15504.95000000","0.00000000"],["15504.87000000","0.00000000"],["15502.78000000","0.03224400"],["15502.42000000","0.11427900"],["15501.66000000","0.00000000"],["15501.01000000","0.00000000"],["15500.05000000","0.02106400"],["15498.56000000","0.00000000"],["15497.86000000","0.00000000"],["15496.01000000","0.50000000"],["15494.98000000","1.00000000"],["15493.47000000","0.00000000"],["15487.70000000","0.02236400"],["15458.27000000","0.00000000"],["15442.76000000","0.38744700"],["15429.21000000","0.00000000"]],"a":[["15505.38000000","0.00000000"],["15509.35000000","0.00000000"],["15510.14000000","0.11427900"],["15510.19000000","0.32100000"],["15517.41000000","0.00000000"],["15518.09000000","0.00000000"]]}}
2020-11-09T11:25:46.01605 btcusdt {"stream":"btcusdt@depth@100ms","data":{"e":"depthUpdate","E":1604921146008,"s":"BTCUSDT","U":6511131557,"u":6511131602,"b":[["15506.06000000","7.02649500"],["15505.76000000","0.07880200"],["15505.72000000","0.00690000"],["15505.54000000","0.00000000"],["15505.52000000","0.07546900"],["15505.42000000","0.04291000"],["15505.37000000","2.22721300"],["15505.17000000","0.00000000"],["15504.45000000","0.00000000"],["15503.43000000","0.00000000"],["15500.54000000","0.15834300"],["15500.06000000","0.00000000"],["15477.29000000","0.00000000"]],"a":[["15506.07000000","0.50173300"],["15506.61000000","0.00000000"],["15506.88000000","0.00000000"],["15507.11000000","0.00000000"],["15508.69000000","0.20000000"],["15508.70000000","0.00000000"],["15509.63000000","0.00000000"],["15509.83000000","0.20000000"],["15509.85000000","0.00000000"],["15509.98000000","0.00000000"],["15510.25000000","0.03400000"],["15510.43000000","0.00000000"],["15510.55000000","0.05000000"],["15510.68000000","0.01000000"],["15511.05000000","1.74800000"],["15511.79000000","0.00000000"],["15512.49000000","0.01000000"],["15512.60000000","0.00000000"],["15512.89000000","0.01500000"],["15513.53000000","0.00000000"],["15518.19000000","1.25000000"]]}}
2020-11-09T11:25:46.11487 btcusdt {"stream":"btcusdt@depth@100ms","data":{"e":"depthUpdate","E":1604921146108,"s":"BTCUSDT","U":6511131603,"u":6511131609,"b":[["15497.44000000","0.00000000"],["15494.02000000","0.00000000"],["15493.17000000","1.50000000"]],"a":[["15506.07000000","0.49533300"],["15507.15000000","2.00000000"],["15510.19000000","0.00000000"],["15533.00000000","0.04222000"]]}}
2020-11-09T11:25:46.21483 btcusdt {"stream":"btcusdt@depth@100ms","data":{"e":"depthUpdate","E":1604921146208,"s":"BTCUSDT","U":6511131610,"u":6511131621,"b":[["15505.37000000","2.21506100"],["15505.29000000","0.01296200"],["15496.86000000","0.16257700"],["15493.17000000","0.00000000"],["15492.78000000","0.13440900"],["14888.00000000","11.69955200"]],"a":[["15506.07000000","0.49213300"],["15506.53000000","0.00711400"],["15506.84000000","0.01743700"],["15507.53000000","2.12800000"],["15512.29000000","0.12898400"],["15521.04000000","1.51030800"]]}}
2020-11-09T11:25:46.34657 btcusdt {"stream":"btcusdt@depth@100ms","data":{"e":"depthUpdate","E":1604921146308,"s":"BTCUSDT","U":6511131622,"u":6511131623,"b":[],"a":[["15506.07000000","0.48893300"],["15512.28000000","0.20000000"]]}}
2020-11-09T11:25:46.41443 btcusdt {"stream":"btcusdt@depth@100ms","data":{"e":"depthUpdate","E":1604921146408,"s":"BTCUSDT","U":6511131624,"u":6511131628,"b":[["15493.21000000","1.50000000"],["15476.82000000","0.03876700"],["15428.52000000","0.00648100"]],"a":[["15506.07000000","0.48573300"],["15553.91000000","0.00000000"]]}}
2020-11-09T11:25:46.51780 btcusdt {"stream":"btcusdt@depth@100ms","data":{"e":"depthUpdate","E":1604921146508,"s":"BTCUSDT","U":6511131629,"u":6511131634,"b":[["15505.29000000","0.00000000"],["15505.18000000","0.00000000"],["15504.90000000","0.01734900"],["15504.64000000","0.00906500"]],"a":[["15506.07000000","0.48253300"],["15510.88000000","0.32100000"]]}}
2020-11-09T11:25:46.61599 btcusdt {"stream":"btcusdt@depth@100ms","data":{"e":"depthUpdate","E":1604921146608,"s":"BTCUSDT","U":6511131635,"u":6511131635,"b":[["15411.00000000","0.71284400"]],"a":[]}}
2020-11-09T11:25:46.81681 btcusdt {"stream":"btcusdt@depth@100ms","data":{"e":"depthUpdate","E":1604921146808,"s":"BTCUSDT","U":6511131636,"u":6511131642,"b":[["15505.58000000","0.00890300"],["15505.29000000","0.01253300"],["15504.90000000","0.00000000"],["15504.64000000","0.00000000"]],"a":[["15506.53000000","0.00000000"],["15506.74000000","0.00879400"],["15518.19000000","0.00000000"]]}}
2020-11-09T11:25:46.91982 btcusdt {"stream":"btcusdt@depth@100ms","data":{"e":"depthUpdate","E":1604921146908,"s":"BTCUSDT","U":6511131643,"u":6511131656,"b":[["15506.06000000","4.82749500"],["15505.76000000","0.00000000"],["15505.44000000","0.00000000"],["15505.42000000","0.00000000"],["15500.95000000","0.00000000"],["15500.54000000","0.05000000"],["15498.75000000","0.87970300"]],"a":[["15506.07000000","0.59851000"],["15515.91000000","0.00000000"]]}}
2020-11-09T11:25:47.01632 btcusdt {"stream":"btcusdt@depth@100ms","data":{"e":"depthUpdate","E":1604921147008,"s":"BTCUSDT","U":6511131657,"u":6511131663,"b":[["15506.06000000","5.82749500"],["15500.54000000","0.00000000"],["15500.06000000","0.05000000"]],"a":[["15506.07000000","0.58095600"],["15518.09000000","1.25000000"],["15518.91000000","0.12887500"],["15525.30000000","0.00000000"]]}}
2020-11-09T11:25:47.11717 btcusdt {"stream":"btcusdt@depth@100ms","data":{"e":"depthUpdate","E":1604921147108,"s":"BTCUSDT","U":6511131664,"u":6511131671,"b":[["15506.06000000","7.82949500"],["15500.95000000","0.10833800"],["15441.96000000","0.00000000"],["15387.00000000","0.37683000"]],"a":[["15518.09000000","0.00000000"],["15518.19000000","1.25000000"],["15528.00000000","0.00000000"]]}}
2020-11-09T11:25:47.21766 btcusdt {"stream":"btcusdt@depth@100ms","data":{"e":"depthUpdate","E":1604921147208,"s":"BTCUSDT","U":6511131672,"u":6511131674,"b":[["15506.06000000","3.32949500"]],"a":[["15510.24000000","0.12899000"],["15528.00000000","0.01431800"]]}}
2020-11-09T11:25:47.31728 btcusdt {"stream":"btcusdt@depth@100ms","data":{"e":"depthUpdate","E":1604921147308,"s":"BTCUSDT","U":6511131675,"u":6511131679,"b":[["15498.79000000","0.06739200"]],"a":[["15506.74000000","0.00000000"],["15506.84000000","0.00000000"],["15509.38000000","0.01222300"],["15509.46000000","0.00732600"]]}}
2020-11-09T11:25:47.41723 btcusdt {"stream":"btcusdt@depth@100ms","data":{"e":"depthUpdate","E":1604921147408,"s":"BTCUSDT","U":6511131680,"u":6511131682,"b":[["15440.93000000","0.24000000"]],"a":[["15506.07000000","0.58295600"],["15506.76000000","1.93996500"]]}}
2020-11-09T11:25:47.51540 btcusdt {"stream":"btcusdt@depth@100ms","data":{"e":"depthUpdate","E":1604921147509,"s":"BTCUSDT","U":6511131683,"u":6511131684,"b":[],"a":[["15520.57000000","0.00000000"],["15584.46000000","0.00000000"]]}}
2020-11-09T11:25:47.61538 btcusdt {"stream":"btcusdt@depth@100ms","data":{"e":"depthUpdate","E":1604921147609,"s":"BTCUSDT","U":6511131685,"u":6511131689,"b":[["15465.58000000","0.00000000"]],"a":[["15515.11000000","1.25000000"],["15518.19000000","0.00000000"],["15519.10000000","0.03797300"],["15552.67000000","0.01543100"]]}}
2020-11-09T11:25:47.71504 btcusdt {"stream":"btcusdt@depth@100ms","data":{"e":"depthUpdate","E":1604921147709,"s":"BTCUSDT","U":6511131690,"u":6511131691,"b":[["15495.76000000","0.00000000"],["15400.00000000","4.39886600"]],"a":[]}}
2020-11-09T11:25:47.81616 btcusdt {"stream":"btcusdt@depth@100ms","data":{"e":"depthUpdate","E":1604921147809,"s":"BTCUSDT","U":6511131692,"u":6511131694,"b":[["15506.06000000","3.33149500"],["15491.52000000","0.20000000"]],"a":[["15506.07000000","0.58797600"]]}}
2020-11-09T11:25:47.91571 btcusdt {"stream":"btcusdt@depth@100ms","data":{"e":"depthUpdate","E":1604921147909,"s":"BTCUSDT","U":6511131695,"u":6511131695,"b":[],"a":[["15564.50000000","0.00000000"]]}}
2020-11-09T11:25:48.01685 btcusdt {"stream":"btcusdt@depth@100ms","data":{"e":"depthUpdate","E":1604921148009,"s":"BTCUSDT","U":6511131696,"u":6511131702,"b":[["15506.06000000","8.63149500"],["15500.51000000","0.06900000"],["15500.06000000","0.00000000"]],"a":[["15506.07000000","0.52770800"],["15509.30000000","0.00686100"],["15509.46000000","0.00000000"],["15512.29000000","0.00000000"]]}}
2020-11-09T11:25:48.11726 btcusdt {"stream":"btcusdt@depth@100ms","data":{"e":"depthUpdate","E":1604921148109,"s":"BTCUSDT","U":6511131703,"u":6511131707,"b":[["15506.06000000","3.33149500"],["15468.76000000","0.00000000"]],"a":[["15506.76000000","0.00000000"],["15546.29000000","0.00000000"],["15563.00000000","2.00000000"]]}}
2020-11-09T11:25:48.21808 btcusdt {"stream":"btcusdt@depth@100ms","data":{"e":"depthUpdate","E":1604921148209,"s":"BTCUSDT","U":6511131708,"u":6511131708,"b":[],"a":[["15511.39000000","0.12898700"]]}}
2020-11-09T11:25:48.31633 btcusdt {"stream":"btcusdt@depth@100ms","data":{"e":"depthUpdate","E":1604921148309,"s":"BTCUSDT","U":6511131709,"u":6511131709,"b":[],"a":[["15519.90000000","0.24000000"]]}}
2020-11-09T11:25:48.61595 btcusdt {"stream":"btcusdt@depth@100ms","data":{"e":"depthUpdate","E":1604921148609,"s":"BTCUSDT","U":6511131710,"u":6511131713,"b":[["15499.00000000","1.27065900"],["15496.50000000","0.20000000"],["15491.52000000","0.00000000"],["15440.93000000","0.00000000"]],"a":[]}}
2020-11-09T11:25:48.71678 btcusdt {"stream":"btcusdt@depth@100ms","data":{"e":"depthUpdate","E":1604921148709,"s":"BTCUSDT","U":6511131714,"u":6511131730,"b":[["15506.06000000","0.03784800"],["15505.52000000","0.00000000"],["15505.37000000","0.11047400"],["15502.42000000","0.00000000"],["15502.02000000","0.15680600"],["15501.90000000","0.11427900"],["15501.19000000","0.00000000"],["15500.71000000","0.12897500"],["15500.06000000","4.70745900"],["15496.86000000","0.03360200"]],"a":[["15506.79000000","0.02008700"],["15511.79000000","0.20000000"],["15550.30000000","0.00000000"],["31030.02000000","0.02797200"]]}}
2020-11-09T11:25:48.81660 btcusdt {"stream":"btcusdt@depth@100ms","data":{"e":"depthUpdate","E":1604921148809,"s":"BTCUSDT","U":6511131731,"u":6511131780,"b":[["15506.06000000","0.00000000"],["15505.72000000","0.00000000"],["15505.58000000","0.00000000"],["15505.37000000","0.03517700"],["15500.95000000","0.00000000"],["15500.71000000","0.00000000"],["15500.06000000","0.00000000"],["15496.94000000","0.12897500"]],"a":[["15505.38000000","2.17033200"],["15505.59000000","0.00000000"],["15505.68000000","0.19589200"],["15505.69000000","0.26306700"],["15505.70000000","0.12871400"],["15505.72000000","0.00000000"],["15505.73000000","0.07473800"],["15505.90000000","0.00690000"],["15506.03000000","0.99615600"],["15506.04000000","0.06977700"],["15506.07000000","2.01392000"],["15506.45000000","0.02008700"],["15506.79000000","0.00000000"],["15509.66000000","0.11427900"],["15510.14000000","0.00000000"],["15511.79000000","0.00000000"],["15536.54000000","0.83020600"]]}}
2020-11-09T11:25:48.91743 btcusdt {"stream":"btcusdt@depth@100ms","data":{"e":"depthUpdate","E":1604921148909,"s":"BTCUSDT","U":6511131781,"u":6511131817,"b":[["15505.37000000","0.63701700"],["15505.29000000","0.00000000"],["15505.21000000","0.00862500"],["15502.02000000","0.00000000"],["15500.95000000","0.08000000"],["15500.51000000","0.01900000"],["15500.01000000","0.05000000"],["15499.77000000","0.00000000"],["15498.99000000","1.25000000"],["15498.79000000","0.00000000"],["15497.03000000","0.00000000"],["15479.54000000","0.00000000"],["15459.64000000","0.01552400"],["15428.52000000","0.00000000"]],"a":[["15505.38000000","4.40686000"],["15505.68000000","0.00000000"],["15506.03000000","0.00000000"],["15507.14000000","0.00000000"],["15507.53000000","0.12800000"],["15509.86000000","0.05000000"],["15509.99000000","0.01000000"],["15510.14000000","0.32100000"],["15510.24000000","0.36948500"],["15510.55000000","0.00000000"],["15510.68000000","0.00000000"],["15510.82000000","0.81900100"],["15510.88000000","0.00000000"],["15511.80000000","0.02687000"],["15512.20000000","0.01500000"],["15512.49000000","0.00000000"],["15512.89000000","0.00000000"],["15513.05000000","0.15150000"],["15569.88000000","0.00000000"]]}}
2020-11-09T11:25:49.01733 btcusdt {"stream":"btcusdt@depth@100ms","data":{"e":"depthUpdate","E":1604921149009,"s":"BTCUSDT","U":6511131818,"u":6511131835,"b":[["15505.37000000","5.93701700"],["15505.21000000","0.00000000"],["15504.91000000","0.00834000"],["15504.60000000","0.01490100"],["15502.01000000","0.00000000"],["15500.95000000","0.23680600"],["15498.41000000","0.06738400"],["15493.21000000","0.00000000"],["15492.93000000","1.50000000"],["15486.80000000","0.30600000"],["15473.83000000","0.12122500"]],"a":[["15505.38000000","2.40686000"],["15506.07000000","2.07259200"],["15506.09000000","0.04264500"],["15506.11000000","0.04264600"],["15515.11000000","0.00000000"],["15517.04000000","1.25000000"]]}}
2020-11-09T11:25:49.11562 btcusdt {"stream":"btcusdt@depth@100ms","data":{"e":"depthUpdate","E":1604921149110,"s":"BTCUSDT","U":6511131836,"u":6511131855,"b":[["15505.37000000","7.93701700"],["15500.53000000","0.35762100"],["15499.27000000","0.10834900"],["15492.93000000","0.00000000"],["15467.30000000","0.25000000"]],"a":[["15505.38000000","1.33729500"],["15505.68000000","0.23326100"],["15506.07000000","0.07259200"],["15506.26000000","0.00200000"],["15507.12000000","1.00345000"],["15508.67000000","0.29345100"],["15508.68000000","0.30000000"],["15509.83000000","0.00000000"],["15509.84000000","0.00000000"],["15511.39000000","0.00000000"],["15512.28000000","0.00000000"],["15544.83000000","0.25000000"]]}}
2020-11-09T11:25:49.21654 btcusdt {"stream":"btcusdt@depth@100ms","data":{"e":"depthUpdate","E":1604921149210,"s":"BTCUSDT","U":6511131856,"u":6511131860,"b":[],"a":[["15505.38000000","1.33409500"],["15510.24000000","0.00000000"],["15510.38000000","0.40900200"],["15550.26000000","0.00200000"]]}}
2020-11-09T11:25:49.32618 btcusdt {"stream":"btcusdt@depth@100ms","data":{"e":"depthUpdate","E":1604921149310,"s":"BTCUSDT","U":6511131861,"u":6511131867,"b":[["15465.50000000","0.00000000"]],"a":[["15506.26000000","0.00400000"],["15508.50000000","0.01226600"],["15509.38000000","0.00000000"],["15512.91000000","0.00000000"],["15521.04000000","0.01030800"],["15570.02000000","0.00478900"]]}}
2020-11-09T11:25:49.48536 btcusdt {"stream":"btcusdt@depth@100ms","data":{"e":"depthUpdate","E":1604921149410,"s":"BTCUSDT","U":6511131868,"u":6511131874,"b":[["15504.91000000","0.00000000"],["15504.37000000","0.00827900"],["15441.40000000","0.24000000"],["15427.84000000","0.00648100"]],"a":[["15505.38000000","1.33089500"],["15508.44000000","0.00737300"],["15509.30000000","0.00000000"]]}}
2020-11-09T11:25:49.51920 btcusdt {"stream":"btcusdt@depth@100ms","data":{"e":"depthUpdate","E":1604921149510,"s":"BTCUSDT","U":6511131875,"u":6511131881,"b":[["15501.91000000","0.15680600"],["15500.95000000","0.08000000"],["15496.94000000","0.00000000"],["15492.88000000","1.50000000"]],"a":[["15505.38000000","1.33489500"],["15506.07000000","0.06757200"],["15551.17000000","0.00000000"]]}}
2020-11-09T11:25:49.61729 btcusdt {"stream":"btcusdt@depth@100ms","data":{"e":"depthUpdate","E":1604921149610,"s":"BTCUSDT","U":6511131882,"u":6511131886,"b":[["15500.71000000","0.12897500"],["15464.50000000","2.00000000"]],"a":[["15505.38000000","1.33102600"],["15506.07000000","0.06557200"],["15508.50000000","0.00000000"]]}}
2020-11-09T11:25:49.71733 btcusdt {"stream":"btcusdt@depth@100ms","data":{"e":"depthUpdate","E":1604921149710,"s":"BTCUSDT","U":6511131887,"u":6511131904,"b":[["15505.37000000","13.12889600"],["15499.71000000","0.50000000"],["15496.01000000","0.00000000"]],"a":[["15505.38000000","0.50400000"],["15505.68000000","0.00000000"],["15505.69000000","0.00000000"],["15505.70000000","0.00000000"],["15505.73000000","0.00000000"],["15506.04000000","0.00000000"],["15509.66000000","0.00000000"],["15510.12000000","0.23463900"],["15510.13000000","0.11427900"],["15511.04000000","0.91745100"],["15550.26000000","0.00000000"]]}}
2020-11-09T11:25:49.81847 btcusdt {"stream":"btcusdt@depth@100ms","data":{"e":"depthUpdate","E":1604921149810,"s":"BTCUSDT","U":6511131905,"u":6511131912,"b":[["15503.92000000","0.50000000"]],"a":[["15505.38000000","0.50080000"],["15508.68000000","0.20000000"],["15509.84000000","0.33000200"],["15509.85000000","0.10000000"],["15509.94000000","0.50000000"],["15510.39000000","0.00000000"],["15511.39000000","0.50000000"],["15515.47000000","0.00000000"],["15518.40000000","0.00000000"],["15521.00000000","1.00000000"],["15524.12000000","0.00000000"],["15528.69000000","0.00000000"],["15532.45000000","0.00000000"]]}}
2020-11-09T11:25:49.91675 btcusdt {"stream":"btcusdt@depth@100ms","data":{"e":"depthUpdate","E":1604921149910,"s":"BTCUSDT","U":6511131913,"u":6511131915,"b":[],"a":[["15505.38000000","0.50262000"],["15511.39000000","0.00000000"]]}}
2020-11-09T11:25:50.02101 btcusdt {"stream":"btcusdt@depth@100ms","data":{"e":"depthUpdate","E":1604921150010,"s":"BTCUSDT","U":6511131916,"u":6511131921,"b":[["15504.37000000","0.00000000"],["15500.05000000","0.07106400"],["15500.01000000","0.00000000"]],"a":[["15505.38000000","0.50662000"],["15508.44000000","0.00000000"],["15538.16000000","0.03861400"]]}}
2020-11-09T11:25:50.11794 btcusdt {"stream":"btcusdt@depth@100ms","data":{"e":"depthUpdate","E":1604921150110,"s":"BTCUSDT","U":6511131922,"u":6511131932,"b":[["15504.58000000","0.00918400"],["15502.93000000","0.15680600"],["15501.91000000","0.00000000"],["15429.60000000","0.24202600"],["15429.37000000","5.99620000"],["15126.00000000","0.01312500"]],"a":[["15508.68000000","0.21225900"],["15508.71000000","0.00701700"],["15510.13000000","0.00000000"],["15510.65000000","0.11427900"],["15603.67000000","0.00000000"]]}}
2020-11-09T11:25:50.21719 btcusdt {"stream":"btcusdt@depth@100ms","data":{"e":"depthUpdate","E":1604921150210,"s":"BTCUSDT","U":6511131933,"u":6511131938,"b":[["15465.94000000","0.00000000"],["14030.00000000","1.96071000"]],"a":[["15505.38000000","0.44620600"],["15513.29000000","0.31800000"],["15563.37000000","0.00000000"],["15595.56000000","5.99620000"]]}}
2020-11-09T11:25:50.31665 btcusdt {"stream":"btcusdt@depth@100ms","data":{"e":"depthUpdate","E":1604921150310,"s":"BTCUSDT","U":6511131939,"u":6511131945,"b":[["15494.75000000","0.00000000"],["15492.90000000","0.18420000"],["15469.64000000","0.60470000"]],"a":[["15516.83000000","1.25000000"],["15517.04000000","0.00000000"],["15533.01000000","0.00000000"],["15560.54000000","0.60970000"]]}}
2020-11-09T11:25:50.41697 btcusdt {"stream":"btcusdt@depth@100ms","data":{"e":"depthUpdate","E":1604921150410,"s":"BTCUSDT","U":6511131946,"u":6511131949,"b":[["15498.79000000","0.20000000"]],"a":[["15505.38000000","0.44820600"],["15516.83000000","0.00000000"],["15517.04000000","1.25000000"]]}}
2020-11-09T11:25:50.51695 btcusdt {"stream":"btcusdt@depth@100ms","data":{"e":"depthUpdate","E":1604921150510,"s":"BTCUSDT","U":6511131950,"u":6511131951,"b":[["15459.64000000","0.00000000"]],"a":[["15552.67000000","0.00000000"]]}}
2020-11-09T11:25:50.61749 btcusdt {"stream":"btcusdt@depth@100ms","data":{"e":"depthUpdate","E":1604921150610,"s":"BTCUSDT","U":6511131952,"u":6511131952,"b":[["15505.37000000","13.13089600"]],"a":[]}}
2020-11-09T11:25:50.71707 btcusdt {"stream":"btcusdt@depth@100ms","data":{"e":"depthUpdate","E":1604921150710,"s":"BTCUSDT","U":6511131953,"u":6511131956,"b":[["15498.79000000","0.00000000"]],"a":[["15515.11000000","1.25000000"],["15517.04000000","0.00000000"],["15556.00000000","0.75486200"]]}}
2020-11-09T11:25:50.81718 btcusdt {"stream":"btcusdt@depth@100ms","data":{"e":"depthUpdate","E":1604921150810,"s":"BTCUSDT","U":6511131957,"u":6511131964,"b":[["15505.37000000","13.35779800"]],"a":[["15506.07000000","0.00690000"],["15506.09000000","0.00000000"],["15506.11000000","0.00000000"],["15508.68000000","0.01225900"],["15509.83000000","0.20000000"],["15516.22000000","0.51283400"]]}}
2020-11-09T11:25:50.91694 btcusdt {"stream":"btcusdt@depth@100ms","data":{"e":"depthUpdate","E":1604921150911,"s":"BTCUSDT","U":6511131965,"u":6511131970,"b":[["15505.37000000","13.31515200"],["15498.42000000","0.20000000"]],"a":[["15505.38000000","0.49085100"],["15505.40000000","0.04264500"],["15511.39000000","0.50000000"],["15585.28000000","0.00000000"]]}}
2020-11-09T11:25:51.01877 btcusdt {"stream":"btcusdt@depth@100ms","data":{"e":"depthUpdate","E":1604921151011,"s":"BTCUSDT","U":6511131971,"u":6511131976,"b":[["15500.05000000","0.02106400"],["15500.01000000","0.05000000"],["15498.78000000","0.00180000"]],"a":[["15505.38000000","0.48848200"],["15511.39000000","0.00000000"],["15555.00000000","5.56809700"]]}}
2020-11-09T11:25:51.21892 btcusdt {"stream":"btcusdt@depth@100ms","data":{"e":"depthUpdate","E":1604921151211,"s":"BTCUSDT","U":6511131977,"u":6511131977,"b":[],"a":[["15515.11000000","0.00000000"]]}}
2020-11-09T11:25:51.31794 btcusdt {"stream":"btcusdt@depth@100ms","data":{"e":"depthUpdate","E":1604921151311,"s":"BTCUSDT","U":6511131978,"u":6511131984,"b":[["15503.93000000","0.15680600"],["15502.93000000","0.00000000"]],"a":[["15505.38000000","0.43019300"],["15510.35000000","0.31800000"],["15516.96000000","0.00000000"]]}}
2020-11-09T11:25:51.41726 btcusdt {"stream":"btcusdt@depth@100ms","data":{"e":"depthUpdate","E":1604921151411,"s":"BTCUSDT","U":6511131985,"u":6511131989,"b":[["15446.37000000","0.00000000"]],"a":[["15517.04000000","0.00000000"],["15517.67000000","1.25000000"],["15521.84000000","0.00000000"]]}}
2020-11-09T11:25:51.51731 btcusdt {"stream":"btcusdt@depth@100ms","data":{"e":"depthUpdate","E":1604921151511,"s":"BTCUSDT","U":6511131990,"u":6511131990,"b":[],"a":[["15514.07000000","0.00364300"]]}}
2020-11-09T11:25:51.61805 btcusdt {"stream":"btcusdt@depth@100ms","data":{"e":"depthUpdate","E":1604921151611,"s":"BTCUSDT","U":6511131991,"u":6511131991,"b":[["15495.88000000","0.00000000"]],"a":[]}}
2020-11-09T11:25:51.71804 btcusdt {"stream":"btcusdt@depth@100ms","data":{"e":"depthUpdate","E":1604921151711,"s":"BTCUSDT","U":6511131992,"u":6511131999,"b":[["15496.73000000","0.30079400"],["15474.47000000","0.01550900"]],"a":[["15508.58000000","0.00770400"],["15508.71000000","0.00000000"],["15515.11000000","1.25000000"],["15517.67000000","0.00000000"],["15544.82000000","0.00000000"],["15567.50000000","0.01541600"]]}}
2020-11-09T11:25:51.81791 btcusdt {"stream":"btcusdt@depth@100ms","data":{"e":"depthUpdate","E":1604921151811,"s":"BTCUSDT","U":6511132000,"u":6511132001,"b":[["15503.93000000","0.00000000"],["15502.93000000","0.15680600"]],"a":[]}}
2020-11-09T11:25:51.91749 btcusdt {"stream":"btcusdt@depth@100ms","data":{"e":"depthUpdate","E":1604921151911,"s":"BTCUSDT","U":6511132002,"u":6511132004,"b":[["15498.42000000","0.00000000"]],"a":[["15519.15000000","0.31800000"],["15541.90000000","0.38000000"]]}}
2020-11-09T11:25:52.01905 btcusdt {"stream":"btcusdt@depth@100ms","data":{"e":"depthUpdate","E":1604921152011,"s":"BTCUSDT","U":6511132005,"u":6511132008,"b":[["15500.05000000","0.07106400"],["15500.01000000","0.00000000"]],"a":[["15508.66000000","0.10000000"],["15509.85000000","0.00000000"]]}}
2020-11-09T11:25:52.12291 btcusdt {"stream":"btcusdt@depth@100ms","data":{"e":"depthUpdate","E":1604921152111,"s":"BTCUSDT","U":6511132009,"u":6511132011,"b":[["15505.37000000","13.31315200"],["15498.77000000","0.19489800"]],"a":[["15547.83000000","0.01210000"]]}}
2020-11-09T11:25:52.35098 btcusdt {"stream":"btcusdt@depth@100ms","data":{"e":"depthUpdate","E":1604921152311,"s":"BTCUSDT","U":6511132012,"u":6511132013,"b":[],"a":[["15505.38000000","0.44622000"],["15565.00000000","0.62178600"]]}}
2020-11-09T11:25:52.41807 btcusdt {"stream":"btcusdt@depth@100ms","data":{"e":"depthUpdate","E":1604921152411,"s":"BTCUSDT","U":6511132014,"u":6511132016,"b":[["15498.42000000","0.20000000"]],"a":[["15505.38000000","0.38611500"],["15522.08000000","0.32830700"]]}}
2020-11-09T11:25:52.51957 btcusdt {"stream":"btcusdt@depth@100ms","data":{"e":"depthUpdate","E":1604921152511,"s":"BTCUSDT","U":6511132017,"u":6511132017,"b":[["15505.37000000","13.31237300"]],"a":[]}}
2020-11-09T11:25:52.62048 btcusdt {"stream":"btcusdt@depth@100ms","data":{"e":"depthUpdate","E":1604921152611,"s":"BTCUSDT","U":6511132018,"u":6511132018,"b":[["15505.37000000","13.31037300"]],"a":[]}}
2020-11-09T11:25:52.71857 btcusdt {"stream":"btcusdt@depth@100ms","data":{"e":"depthUpdate","E":1604921152712,"s":"BTCUSDT","U":6511132019,"u":6511132020,"b":[],"a":[["15515.11000000","0.00000000"],["15515.91000000","1.25000000"]]}}
2020-11-09T11:25:52.81827 btcusdt {"stream":"btcusdt@depth@100ms","data":{"e":"depthUpdate","E":1604921152812,"s":"BTCUSDT","U":6511132021,"u":6511132023,"b":[["15505.37000000","13.28997300"],["15499.27000000","0.00000000"]],"a":[["15505.40000000","0.00000000"]]}}
2020-11-09T11:25:52.92291 btcusdt {"stream":"btcusdt@depth@100ms","data":{"e":"depthUpdate","E":1604921152912,"s":"BTCUSDT","U":6511132024,"u":6511132031,"b":[["15505.37000000","13.24732800"],["15502.93000000","0.00000000"],["15500.96000000","0.15680600"],["15408.00000000","0.43183000"]],"a":[["15511.03000000","0.50000000"],["15515.10000000","1.25000000"],["15515.91000000","0.00000000"],["15525.01000000","1.46357300"]]}}
2020-11-09T11:25:53.01859 btcusdt {"stream":"btcusdt@depth@100ms","data":{"e":"depthUpdate","E":1604921153012,"s":"BTCUSDT","U":6511132032,"u":6511132042,"b":[["15505.37000000","10.60332800"],["15505.00000000","1.01912900"],["15500.05000000","0.02106400"],["15500.01000000","0.05000000"]],"a":[["15508.57000000","0.29998100"],["15508.65000000","0.20000000"],["15508.67000000","0.00000000"],["15509.83000000","0.00000000"],["15510.18000000","0.11427900"],["15510.65000000","0.00000000"]]}}
2020-11-09T11:25:53.12098 btcusdt {"stream":"btcusdt@depth@100ms","data":{"e":"depthUpdate","E":1604921153112,"s":"BTCUSDT","U":6511132043,"u":6511132047,"b":[["15500.06000000","0.10834700"],["15498.42000000","0.00000000"],["15496.50000000","0.00000000"],["15491.52000000","0.20000000"],["15250.00000000","10.88383300"]],"a":[]}}
2020-11-09T11:25:53.21893 btcusdt {"stream":"btcusdt@depth@100ms","data":{"e":"depthUpdate","E":1604921153212,"s":"BTCUSDT","U":6511132048,"u":6511132049,"b":[["15408.00000000","0.05500000"]],"a":[["15509.93000000","0.12899400"]]}}
2020-11-09T11:25:53.32163 btcusdt {"stream":"btcusdt@depth@100ms","data":{"e":"depthUpdate","E":1604921153312,"s":"BTCUSDT","U":6511132050,"u":6511132053,"b":[["14480.20000000","0.01000000"]],"a":[["15509.93000000","0.00000000"],["15511.57000000","0.25772400"],["15519.36000000","0.00000000"]]}}
2020-11-09T11:25:53.41809 btcusdt {"stream":"btcusdt@depth@100ms","data":{"e":"depthUpdate","E":1604921153412,"s":"BTCUSDT","U":6511132054,"u":6511132063,"b":[["15505.37000000","5.35096000"],["15505.00000000","0.98663500"],["15500.06000000","0.00000000"],["15387.00000000","0.48510300"]],"a":[["15505.38000000","2.38611500"],["15510.43000000","0.20000000"],["15515.10000000","0.00000000"],["15515.11000000","1.25000000"],["15527.94000000","0.31800000"]]}}
2020-11-09T11:25:53.63774 btcusdt {"stream":"btcusdt@depth@100ms","data":{"e":"depthUpdate","E":1604921153512,"s":"BTCUSDT","U":6511132064,"u":6511132076,"b":[["15505.37000000","10.67405800"],["15500.80000000","0.01216100"],["15500.07000000","0.02106400"],["15500.05000000","0.00000000"],["15498.14000000","0.00000000"],["15497.76000000","0.00000000"]],"a":[["15505.38000000","0.53766700"],["15506.93000000","0.18000000"],["15510.43000000","0.00000000"]]}}
2020-11-09T11:25:53.63811 btcusdt {"stream":"btcusdt@depth@100ms","data":{"e":"depthUpdate","E":1604921153612,"s":"BTCUSDT","U":6511132077,"u":6511132097,"b":[["15505.37000000","12.91835900"],["15505.13000000","0.00000000"],["15505.08000000","0.07530600"],["15500.07000000","0.00000000"],["15499.00000000","1.04565900"],["15496.99000000","0.02106400"]],"a":[["15505.38000000","0.07169200"],["15506.45000000","0.00000000"],["15506.93000000","0.00000000"],["15507.11000000","0.20000000"],["15508.69000000","0.00000000"],["15515.11000000","1.25000000"]]}}
2020-11-09T11:25:53.72017 btcusdt {"stream":"btcusdt@depth@100ms","data":{"e":"depthUpdate","E":1604921153712,"s":"BTCUSDT","U":6511132098,"u":6511132101,"b":[["15505.14000000","0.07658200"],["15505.08000000","0.00000000"]],"a":[["15514.50000000","0.06712400"],["15516.55000000","0.00000000"]]}}
2020-11-09T11:25:53.81972 btcusdt {"stream":"btcusdt@depth@100ms","data":{"e":"depthUpdate","E":1604921153812,"s":"BTCUSDT","U":6511132102,"u":6511132110,"b":[["15505.25000000","0.07747500"],["15505.14000000","0.00000000"],["15504.60000000","0.02289400"],["15504.58000000","0.00000000"]],"a":[["15505.38000000","0.02904700"],["15505.84000000","0.00880700"],["15506.15000000","0.01694700"],["15508.58000000","0.00000000"],["15508.68000000","0.00000000"]]}}
2020-11-09T11:25:53.91907 btcusdt {"stream":"btcusdt@depth@100ms","data":{"e":"depthUpdate","E":1604921153912,"s":"BTCUSDT","U":6511132111,"u":6511132118,"b":[["15505.37000000","7.82571400"],["15505.25000000","0.00000000"],["15501.64000000","0.02106400"],["15496.99000000","0.00000000"]],"a":[["15505.38000000","0.77924700"],["15510.12000000","0.00000000"],["15510.14000000","0.00000000"]]}}
2020-11-09T11:25:54.01949 btcusdt {"stream":"btcusdt@depth@100ms","data":{"e":"depthUpdate","E":1604921154012,"s":"BTCUSDT","U":6511132119,"u":6511132120,"b":[["15500.05000000","0.05000000"],["15500.01000000","0.00000000"]],"a":[]}}
2020-11-09T11:25:54.12048 btcusdt {"stream":"btcusdt@depth@100ms","data":{"e":"depthUpdate","E":1604921154112,"s":"BTCUSDT","U":6511132121,"u":6511132126,"b":[["15505.37000000","13.12571400"],["15467.30000000","0.00000000"]],"a":[["15505.38000000","0.77847700"],["15510.17000000","0.23464000"],["15510.19000000","0.32100000"],["15544.83000000","0.00000000"]]}}
2020-11-09T11:25:54.21925 btcusdt {"stream":"btcusdt@depth@100ms","data":{"e":"depthUpdate","E":1604921154212,"s":"BTCUSDT","U":6511132127,"u":6511132136,"b":[["15505.37000000","13.12771400"],["15505.29000000","0.07766200"],["15500.96000000","0.00000000"]],"a":[["15505.38000000","0.01225000"],["15506.15000000","0.00000000"],["15510.18000000","0.00000000"],["15510.70000000","0.11427900"],["15558.00000000","2.00287900"],["15561.00000000","0.26473100"]]}}
2020-11-09T11:25:54.31904 btcusdt {"stream":"btcusdt@depth@100ms","data":{"e":"depthUpdate","E":1604921154312,"s":"BTCUSDT","U":6511132137,"u":6511132147,"b":[["15504.91000000","0.00615000"],["15504.60000000","0.01490100"],["15502.35000000","0.15680600"]],"a":[["15505.84000000","0.00000000"],["15506.24000000","0.00666300"],["15506.39000000","0.01824200"],["15507.11000000","0.00000000"],["15510.17000000","0.00000000"],["15510.19000000","0.00000000"],["15515.11000000","0.00000000"],["15517.66000000","1.25000000"]]}}
2020-11-09T11:25:54.42102 btcusdt {"stream":"btcusdt@depth@100ms","data":{"e":"depthUpdate","E":1604921154412,"s":"BTCUSDT","U":6511132148,"u":6511132155,"b":[["15505.31000000","0.07588500"],["15505.29000000","0.00000000"],["15408.00000000","0.43183000"]],"a":[["15508.56000000","0.20000000"],["15508.66000000","0.00000000"],["15509.83000000","0.10000000"],["15519.62000000","0.00000000"],["15521.52000000","1.15300000"]]}}
2020-11-09T11:25:54.52100 btcusdt {"stream":"btcusdt@depth@100ms","data":{"e":"depthUpdate","E":1604921154513,"s":"BTCUSDT","U":6511132156,"u":6511132167,"b":[["15505.34000000","0.07773500"],["15505.31000000","0.00000000"],["15504.91000000","0.00000000"],["15499.36000000","0.40989700"],["15403.56000000","0.00000000"],["15242.99000000","0.00000000"]],"a":[["15506.24000000","0.00000000"],["15506.39000000","0.00000000"],["15508.57000000","0.00000000"],["15511.03000000","0.00000000"],["15511.83000000","0.32200000"],["15521.52000000","0.15300000"]]}}
2020-11-09T11:25:54.62018 btcusdt {"stream":"btcusdt@depth@100ms","data":{"e":"depthUpdate","E":1604921154613,"s":"BTCUSDT","U":6511132168,"u":6511132201,"b":[["15506.24000000","0.00690000"],["15505.43000000","0.07213000"],["15505.42000000","0.03384800"],["15505.41000000","0.03384800"],["15505.40000000","0.03249400"],["15505.39000000","0.03249400"],["15505.38000000","0.00000000"],["15505.37000000","8.04630100"],["15505.34000000","0.00000000"],["15502.85000000","0.11427900"],["15501.90000000","0.00000000"],["15499.33000000","0.22500000"]],"a":[["15505.38000000","0.00000000"],["15505.90000000","0.00000000"],["15506.07000000","0.00000000"],["15506.25000000","0.00690000"],["15506.26000000","0.00000000"],["15506.94000000","0.00000000"],["15506.95000000","0.00000000"],["15507.12000000","0.00000000"],["15507.30000000","0.02008700"],["15509.60000000","0.00000000"],["15509.84000000","0.00000000"],["15510.04000000","0.01700000"],["15510.25000000","0.00000000"],["15510.38000000","0.00000000"],["15510.70000000","0.00000000"],["15510.82000000","0.00000000"],["15511.04000000","0.00000000"],["15511.05000000","0.00000000"],["15511.16000000","1.75490000"],["15511.20000000","0.11427900"],["15521.44000000","1.00000000"],["15606.00000000","0.38817000"]]}}
2020-11-09T11:25:54.72145 btcusdt {"stream":"btcusdt@depth@100ms","data":{"e":"depthUpdate","E":1604921154713,"s":"BTCUSDT","U":6511132202,"u":6511132230,"b":[["15505.43000000","0.00000000"],["15505.42000000","0.00000000"],["15505.40000000","0.00000000"],["15505.39000000","0.00000000"],["15505.37000000","7.83449400"],["15503.92000000","0.00000000"],["15500.77000000","1.25000000"],["15500.72000000","0.05000000"],["15500.05000000","0.00000000"],["15498.99000000","0.00000000"]],"a":[["15506.25000000","0.79697700"],["15506.89000000","0.02008700"],["15507.30000000","0.00000000"],["15508.65000000","0.00000000"],["15509.82000000","0.20000000"],["15509.86000000","0.00000000"],["15509.99000000","0.00000000"],["15510.04000000","0.03400000"],["15511.14000000","0.06000000"],["15511.80000000","0.01687000"],["15512.20000000","0.00000000"],["15512.67000000","0.01000000"],["15513.07000000","0.01500000"],["15517.04000000","0.00000000"],["15517.66000000","1.25000000"]]}}
2020-11-09T11:25:54.82008 btcusdt {"stream":"btcusdt@depth@100ms","data":{"e":"depthUpdate","E":1604921154813,"s":"BTCUSDT","U":6511132231,"u":6511132247,"b":[["15506.24000000","5.80494300"],["15505.38000000","0.15680600"],["15505.37000000","7.33449400"],["15505.00000000","1.11568000"],["15504.15000000","0.50000000"],["15502.35000000","0.00000000"],["15490.43000000","0.00000000"],["15402.85000000","0.00383000"]],"a":[["15506.89000000","0.00000000"],["15508.56000000","0.00000000"],["15509.81000000","0.20000000"],["15509.92000000","0.50000000"],["15511.83000000","0.00000000"],["15517.66000000","0.00000000"],["15517.68000000","1.25000000"]]}}
2020-11-09T11:25:54.92073 btcusdt {"stream":"btcusdt@depth@100ms","data":{"e":"depthUpdate","E":1604921154913,"s":"BTCUSDT","U":6511132248,"u":6511132266,"b":[["15506.24000000","8.05164300"],["15505.41000000","0.00000000"],["15505.37000000","7.30200000"],["15500.77000000","0.00000000"],["15500.76000000","1.25000000"],["15499.03000000","1.00100000"],["15494.98000000","0.00000000"],["15493.23000000","1.18386700"],["15460.50000000","0.00200000"],["15441.40000000","0.00000000"],["15427.84000000","0.00000000"],["15387.00000000","0.37683000"]],"a":[["15507.15000000","0.00000000"],["15511.53000000","0.50000000"],["15517.68000000","0.00000000"],["15519.90000000","0.00000000"],["15521.31000000","1.50000000"]]}}
2020-11-09T11:25:55.02371 btcusdt {"stream":"btcusdt@depth@100ms","data":{"e":"depthUpdate","E":1604921155013,"s":"BTCUSDT","U":6511132267,"u":6511132282,"b":[["15504.98000000","0.01597400"],["15504.60000000","0.00000000"],["15500.72000000","0.00000000"],["15500.52000000","0.05000000"],["15499.33000000","0.00000000"],["15497.57000000","0.30900000"],["15495.57000000","0.00000000"],["15494.67000000","0.00000000"],["15460.50000000","0.00400000"],["15452.94000000","0.00302000"],["15195.60000000","0.00000000"]],"a":[["15506.25000000","0.75710000"],["15508.60000000","0.01543500"],["15511.14000000","0.01000000"],["15511.19000000","0.05000000"],["15517.81000000","1.25000000"]]}}
2020-11-09T11:25:55.12752 btcusdt {"stream":"btcusdt@depth@100ms","data":{"e":"depthUpdate","E":1604921155113,"s":"BTCUSDT","U":6511132283,"u":6511132293,"b":[["15506.24000000","7.90559200"],["15504.61000000","0.00816600"],["15501.59000000","0.10833100"],["15467.48000000","0.25000000"]],"a":[["15508.59000000","0.00621900"],["15511.06000000","0.32100000"],["15521.31000000","0.00000000"],["15521.50000000","1.50000000"],["15534.10000000","0.18420000"],["15545.01000000","0.25000000"],["15676.96000000","0.00000000"]]}}
2020-11-09T11:25:55.22010 btcusdt {"stream":"btcusdt@depth@100ms","data":{"e":"depthUpdate","E":1604921155213,"s":"BTCUSDT","U":6511132294,"u":6511132302,"b":[["15506.24000000","7.90398500"],["15502.93000000","0.13500000"],["15496.44000000","0.03362000"],["15474.47000000","0.00000000"]],"a":[["15511.05000000","0.01000000"],["15511.14000000","0.00000000"],["15518.92000000","0.00000000"],["15521.50000000","0.00000000"],["15567.50000000","0.00000000"]]}}
2020-11-09T11:25:55.33740 btcusdt {"stream":"btcusdt@depth@100ms","data":{"e":"depthUpdate","E":1604921155313,"s":"BTCUSDT","U":6511132303,"u":6511132315,"b":[["15505.51000000","0.00836900"],["15505.47000000","0.01739700"],["15504.98000000","0.00000000"],["15504.61000000","0.00000000"]],"a":[["15506.25000000","0.76110000"],["15508.59000000","0.00000000"],["15508.60000000","0.00000000"],["15509.48000000","0.00779200"],["15509.54000000","0.01995300"],["15518.84000000","0.00000000"],["15564.00000000","0.10827300"],["15670.42000000","0.00431700"]]}}
2020-11-09T11:25:55.57451 btcusdt {"stream":"btcusdt@depth@100ms","data":{"e":"depthUpdate","E":1604921155413,"s":"BTCUSDT","U":6511132316,"u":6511132327,"b":[["15506.24000000","7.89388500"],["15505.47000000","0.01366100"],["15499.37000000","0.20000000"],["15495.44000000","0.10085900"],["15445.30000000","0.24000000"],["15428.70000000","0.00648100"],["15408.00000000","0.54010300"]],"a":[["15515.83000000","0.22250200"],["15517.43000000","0.00000000"],["15520.51000000","0.13439800"],["15523.76000000","0.24000000"]]}}
2020-11-09T11:25:55.57489 btcusdt {"stream":"btcusdt@depth@100ms","data":{"e":"depthUpdate","E":1604921155513,"s":"BTCUSDT","U":6511132328,"u":6511132329,"b":[["15505.51000000","0.00000000"]],"a":[["15509.48000000","0.00000000"]]}}
2020-11-09T11:25:55.61929 btcusdt {"stream":"btcusdt@depth@100ms","data":{"e":"depthUpdate","E":1604921155613,"s":"BTCUSDT","U":6511132330,"u":6511132330,"b":[],"a":[["15606.00000000","0.49644300"]]}}
2020-11-09T11:25:55.72171 btcusdt {"stream":"btcusdt@depth@100ms","data":{"e":"depthUpdate","E":1604921155713,"s":"BTCUSDT","U":6511132331,"u":6511132331,"b":[],"a":[["15506.25000000","0.77712700"]]}}
2020-11-09T11:25:55.82075 btcusdt {"stream":"btcusdt@depth@100ms","data":{"e":"depthUpdate","E":1604921155813,"s":"BTCUSDT","U":6511132332,"u":6511132332,"b":[],"a":[["15506.25000000","0.71704100"]]}}
2020-11-09T11:25:55.96962 btcusdt {"stream":"btcusdt@depth@100ms","data":{"e":"depthUpdate","E":1604921155913,"s":"BTCUSDT","U":6511132333,"u":6511132335,"b":[["15505.47000000","0.01810500"],["15242.99000000","0.00590400"]],"a":[]}}
2020-11-09T11:25:56.04882 btcusdt {"stream":"btcusdt@depth@100ms","data":{"e":"depthUpdate","E":1604921156013,"s":"BTCUSDT","U":6511132336,"u":6511132343,"b":[["15505.59000000","0.00988800"],["15500.54000000","0.05000000"],["15500.52000000","0.00000000"]],"a":[["15509.50000000","0.00942200"],["15509.82000000","0.00000000"],["15510.82000000","0.20000000"],["15511.14000000","0.05000000"],["15511.19000000","0.00000000"]]}}
2020-11-09T11:25:56.12091 btcusdt {"stream":"btcusdt@depth@100ms","data":{"e":"depthUpdate","E":1604921156114,"s":"BTCUSDT","U":6511132344,"u":6511132346,"b":[["15387.00000000","0.00000000"]],"a":[["15521.44000000","0.00000000"],["15521.58000000","0.13440600"]]}}
2020-11-09T11:25:56.22125 btcusdt {"stream":"btcusdt@depth@100ms","data":{"e":"depthUpdate","E":1604921156214,"s":"BTCUSDT","U":6511132347,"u":6511132349,"b":[["15505.37000000","7.30000000"]],"a":[["15509.44000000","0.20000000"],["15510.82000000","0.00000000"]]}}
2020-11-09T11:25:56.32166 btcusdt {"stream":"btcusdt@depth@100ms","data":{"e":"depthUpdate","E":1604921156314,"s":"BTCUSDT","U":6511132350,"u":6511132357,"b":[["15505.47000000","0.01287200"],["15500.76000000","0.00000000"],["15499.76000000","1.25000000"],["15499.36000000","0.00000000"],["15411.00000000","1.08967400"]],"a":[]}}
2020-11-09T11:25:56.42284 btcusdt {"stream":"btcusdt@depth@100ms","data":{"e":"depthUpdate","E":1604921156414,"s":"BTCUSDT","U":6511132358,"u":6511132363,"b":[["15505.47000000","0.01595900"],["15459.82000000","0.01552400"]],"a":[["15520.51000000","0.00000000"],["15521.07000000","1.00000000"],["15552.85000000","0.01543100"]]}}
2020-11-09T11:25:56.52393 btcusdt {"stream":"btcusdt@depth@100ms","data":{"e":"depthUpdate","E":1604921156514,"s":"BTCUSDT","U":6511132364,"u":6511132366,"b":[["15493.23000000","0.19580100"]],"a":[["15522.55000000","0.13440200"],["15564.00000000","0.48510300"]]}}
2020-11-09T11:25:56.62232 btcusdt {"stream":"btcusdt@depth@100ms","data":{"e":"depthUpdate","E":1604921156614,"s":"BTCUSDT","U":6511132367,"u":6511132367,"b":[["15491.99000000","0.97178300"]],"a":[]}}
2020-11-09T11:25:56.72033 btcusdt {"stream":"btcusdt@depth@100ms","data":{"e":"depthUpdate","E":1604921156714,"s":"BTCUSDT","U":6511132368,"u":6511132370,"b":[["15505.47000000","0.00000000"]],"a":[["15561.00000000","0.15645800"],["15568.00000000","0.05000000"]]}}
2020-11-09T11:25:56.82139 btcusdt {"stream":"btcusdt@depth@100ms","data":{"e":"depthUpdate","E":1604921156814,"s":"BTCUSDT","U":6511132371,"u":6511132374,"b":[["15505.47000000","0.01220000"],["15125.60000000","0.00000000"]],"a":[]}}
2020-11-09T11:25:56.92179 btcusdt {"stream":"btcusdt@depth@100ms","data":{"e":"depthUpdate","E":1604921156914,"s":"BTCUSDT","U":6511132375,"u":6511132376,"b":[["15505.47000000","0.01220400"]],"a":[]}}
2020-11-09T11:25:57.02228 btcusdt {"stream":"btcusdt@depth@100ms","data":{"e":"depthUpdate","E":1604921157014,"s":"BTCUSDT","U":6511132377,"u":6511132384,"b":[["15505.47000000","0.01751500"],["15500.63000000","0.05000000"],["15500.54000000","0.00000000"]],"a":[["15506.25000000","0.64321000"],["15511.05000000","0.06000000"],["15511.14000000","0.00000000"]]}}
2020-11-09T11:25:57.12459 btcusdt {"stream":"btcusdt@depth@100ms","data":{"e":"depthUpdate","E":1604921157114,"s":"BTCUSDT","U":6511132385,"u":6511132386,"b":[["15505.47000000","0.01730900"]],"a":[]}}
2020-11-09T11:25:57.22416 btcusdt {"stream":"btcusdt@depth@100ms","data":{"e":"depthUpdate","E":1604921157214,"s":"BTCUSDT","U":6511132387,"u":6511132392,"b":[["15505.47000000","0.01487800"]],"a":[["15518.51000000","0.00000000"],["15603.00000000","0.11827300"]]}}
2020-11-09T11:25:57.32072 btcusdt {"stream":"btcusdt@depth@100ms","data":{"e":"depthUpdate","E":1604921157314,"s":"BTCUSDT","U":6511132393,"u":6511132397,"b":[["15505.47000000","0.01382500"],["15499.31000000","0.43888700"]],"a":[["15512.09000000","0.00690000"],["15516.81000000","0.31464400"]]}}
2020-11-09T11:25:57.42282 btcusdt {"stream":"btcusdt@depth@100ms","data":{"e":"depthUpdate","E":1604921157414,"s":"BTCUSDT","U":6511132398,"u":6511132399,"b":[["15506.24000000","8.05069100"],["15505.38000000","0.00000000"]],"a":[]}}
2020-11-09T11:25:57.62723 btcusdt {"stream":"btcusdt@depth@100ms","data":{"e":"depthUpdate","E":1604921157614,"s":"BTCUSDT","U":6511132400,"u":6511132403,"b":[["15505.47000000","0.01863500"]],"a":[["15506.25000000","0.62110900"]]}}
2020-11-09T11:25:57.72141 btcusdt {"stream":"btcusdt@depth@100ms","data":{"e":"depthUpdate","E":1604921157714,"s":"BTCUSDT","U":6511132404,"u":6511132404,"b":[["15492.88000000","0.00000000"]],"a":[]}}
2020-11-09T11:25:57.82328 btcusdt {"stream":"btcusdt@depth@100ms","data":{"e":"depthUpdate","E":1604921157815,"s":"BTCUSDT","U":6511132405,"u":6511132474,"b":[["15507.52000000","6.30108300"],["15507.32000000","0.00690000"],["15507.15000000","0.00000000"],["15507.12000000","0.00000000"],["15507.02000000","0.00000000"],["15506.99000000","0.07352900"],["15506.32000000","0.00000000"],["15506.26000000","0.00000000"],["15506.25000000","5.30000000"],["15506.24000000","2.37101200"],["15505.47000000","0.01667200"],["15505.37000000","2.00000000"],["15504.15000000","0.00000000"],["15503.52000000","0.11427900"],["15502.85000000","0.00000000"],["15499.76000000","0.00000000"],["15495.46000000","1.50000000"]],"a":[["15506.25000000","0.00000000"],["15507.13000000","0.00000000"],["15507.53000000","0.12750000"],["15508.22000000","0.00000000"],["15508.72000000","0.00000000"],["15509.25000000","0.00000000"],["15509.44000000","0.00000000"],["15509.54000000","0.00000000"],["15509.81000000","0.00000000"],["15509.83000000","0.00000000"],["15510.04000000","0.00000000"],["15510.09000000","0.04000000"],["15510.47000000","0.00000000"],["15510.82000000","0.00000000"],["15510.83000000","0.00000000"],["15510.87000000","0.00000000"],["15511.14000000","0.10000000"],["15511.16000000","0.00690000"],["15511.20000000","0.00000000"],["15511.31000000","0.00000000"],["15511.40000000","0.00000000"],["15511.54000000","0.00000000"],["15511.65000000","0.04000000"],["15511.85000000","0.00000000"],["15511.88000000","0.00000000"],["15511.89000000","0.11427900"],["15512.20000000","0.04000000"],["15513.53000000","0.75000000"],["15515.96000000","0.08200000"],["15521.22000000","1.50000000"]]}}
2020-11-09T11:25:57.92379 btcusdt {"stream":"btcusdt@depth@100ms","data":{"e":"depthUpdate","E":1604921157915,"s":"BTCUSDT","U":6511132475,"u":6511132553,"b":[["15507.52000000","10.77706100"],["15507.36000000","0.07198900"],["15507.09000000","0.00000000"],["15506.99000000","0.00000000"],["15506.24000000","2.15880600"],["15504.84000000","1.25000000"],["15504.13000000","0.04000000"],["15503.58000000","0.02000000"],["15502.94000000","0.08000000"],["15502.93000000","0.00000000"],["15502.88000000","0.00000000"],["15502.67000000","0.16000000"],["15502.17000000","0.00000000"],["15501.87000000","0.08201000"],["15501.58000000","0.00000000"],["15500.72000000","0.05000000"],["15500.63000000","0.00000000"],["15500.62000000","0.00000000"],["15498.41000000","0.00000000"],["15498.13000000","0.14550000"],["15496.84000000","0.00000000"],["15490.13000000","0.74106400"],["15428.70000000","0.00000000"]],"a":[["15507.53000000","0.07237900"],["15509.50000000","0.00000000"],["15509.92000000","0.00000000"],["15509.94000000","0.00000000"],["15510.82000000","0.00000000"],["15511.05000000","0.00000000"],["15511.06000000","0.00000000"],["15511.11000000","0.00000000"],["15511.14000000","0.00000000"],["15511.15000000","0.00000000"],["15511.47000000","0.00000000"],["15511.53000000","0.00000000"],["15511.66000000","0.00000000"],["15511.67000000","0.01700000"],["15511.68000000","0.01700000"],["15511.82000000","0.00000000"],["15511.89000000","1.86227900"],["15512.01000000","0.05000000"],["15512.14000000","0.01000000"],["15512.35000000","0.00000000"],["15512.66000000","0.00000000"],["15512.67000000","0.00000000"],["15512.71000000","0.15700000"],["15512.92000000","0.29200000"],["15512.99000000","1.19800000"],["15513.05000000","0.00000000"],["15513.07000000","0.00000000"],["15513.53000000","0.00000000"],["15513.95000000","0.01000000"],["15514.09000000","0.00000000"],["15514.23000000","0.00000000"],["15514.35000000","0.01500000"],["15514.37000000","0.75000000"],["15515.96000000","0.00000000"],["15516.04000000","0.50000000"],["15516.22000000","0.31800000"],["15517.81000000","0.00000000"],["15518.99000000","1.25000000"],["15606.00000000","0.11961300"]]}}
2020-11-09T11:25:58.02140 btcusdt {"stream":"btcusdt@depth@100ms","data":{"e":"depthUpdate","E":1604921158015,"s":"BTCUSDT","U":6511132554,"u":6511132591,"b":[["15507.42000000","0.07757200"],["15507.39000000","0.00000000"],["15507.36000000","0.00000000"],["15505.75000000","0.78600000"],["15505.37000000","2.00644900"],["15505.20000000","1.00000000"],["15504.30000000","0.96000000"],["15504.13000000","0.00000000"],["15503.58000000","0.00000000"],["15502.67000000","0.00000000"],["15498.40000000","0.00000000"],["15497.93000000","0.50436400"],["15497.57000000","1.31772800"],["15497.52000000","0.00306000"],["15497.16000000","0.15450000"],["15496.48000000","0.00000000"],["15491.99000000","0.00000000"],["15486.79000000","0.00000000"]],"a":[["15507.53000000","0.06202900"],["15510.09000000","0.00000000"],["15510.35000000","0.00000000"],["15511.65000000","0.00000000"],["15511.89000000","1.74800000"],["15512.20000000","0.00000000"],["15512.71000000","0.00000000"],["15512.92000000","0.00000000"],["15512.99000000","0.00000000"],["15513.77000000","1.19800000"],["15513.85000000","0.15700000"],["15513.97000000","0.00000000"],["15514.07000000","0.29564300"],["15516.04000000","0.00000000"],["15518.99000000","0.00000000"],["15519.10000000","1.28797300"],["15523.76000000","0.00000000"],["15536.54000000","0.00000000"]]}}
2020-11-09T11:25:58.12482 btcusdt {"stream":"btcusdt@depth@100ms","data":{"e":"depthUpdate","E":1604921158115,"s":"BTCUSDT","U":6511132592,"u":6511132627,"b":[["15507.52000000","10.74709700"],["15507.47000000","0.00000000"],["15507.42000000","0.00000000"],["15506.05000000","0.00400000"],["15505.48000000","0.08000000"],["15505.47000000","0.01322900"],["15500.95000000","0.00000000"],["15499.07000000","0.06684400"],["15490.92000000","0.00000000"],["15488.38000000","0.29700000"]],"a":[["15507.53000000","0.00690000"],["15510.44000000","0.00000000"],["15511.67000000","0.00000000"],["15511.68000000","0.00000000"],["15511.89000000","0.00000000"],["15512.30000000","0.00000000"],["15513.12000000","0.01700000"],["15513.13000000","0.01700000"],["15513.15000000","1.74800000"],["15514.34000000","0.20000000"],["15514.49000000","0.10000000"],["15514.53000000","0.00000000"],["15517.00000000","0.50000000"],["15519.10000000","0.03797300"],["15519.41000000","0.00000000"],["15519.90000000","1.25000000"],["15603.00000000","0.49510300"]]}}
2020-11-09T11:25:58.22392 btcusdt {"stream":"btcusdt@depth@100ms","data":{"e":"depthUpdate","E":1604921158215,"s":"BTCUSDT","U":6511132628,"u":6511132649,"b":[["15507.52000000","10.90316100"],["15505.85000000","0.01258100"],["15505.60000000","0.18000000"],["15505.47000000","0.00000000"],["15504.11000000","0.11427900"],["15503.52000000","0.00000000"],["15501.64000000","0.00000000"],["15498.01000000","1.50000000"],["15495.46000000","0.00000000"],["15495.26000000","1.01869400"],["12600.00000000","51.40017100"]],"a":[["15512.14000000","0.00000000"],["15513.11000000","0.20000000"],["15513.76000000","0.00000000"],["15513.84000000","0.01000000"],["15514.17000000","0.32100000"],["15514.51000000","0.11427900"],["15515.18000000","0.00000000"],["15525.01000000","0.31800000"]]}}
2020-11-09T11:25:58.34329 btcusdt {"stream":"btcusdt@depth@100ms","data":{"e":"depthUpdate","E":1604921158315,"s":"BTCUSDT","U":6511132650,"u":6511132661,"b":[["15507.52000000","11.05996700"],["15506.24000000","2.00200000"],["15505.75000000","0.00000000"],["15505.20000000","0.00000000"],["15445.30000000","0.00000000"]],"a":[["15507.99000000","0.00662500"],["15508.30000000","0.01608500"],["15512.68000000","0.20000000"],["15513.57000000","0.10000000"],["15514.34000000","0.00000000"],["15514.49000000","0.00000000"],["15526.60000000","1.02942100"]]}}
2020-11-09T11:25:58.42265 btcusdt {"stream":"btcusdt@depth@100ms","data":{"e":"depthUpdate","E":1604921158415,"s":"BTCUSDT","U":6511132662,"u":6511132689,"b":[["15506.52000000","0.00000000"],["15505.97000000","0.00000000"],["15505.60000000","0.00000000"],["15505.48000000","0.00000000"],["15504.84000000","0.00000000"],["15504.30000000","0.00000000"],["15504.12000000","0.06739500"],["15503.44000000","0.04000000"],["15502.89000000","0.04000000"],["15501.84000000","0.72000000"],["15469.15000000","0.00000000"],["15429.98000000","0.00648000"]],"a":[["15511.56000000","0.08000000"],["15511.67000000","0.01700000"],["15511.99000000","0.00000000"],["15512.00000000","0.01700000"],["15513.05000000","1.19800000"],["15513.12000000","0.00000000"],["15513.13000000","0.00000000"],["15513.77000000","0.00000000"],["15514.17000000","0.00000000"],["15526.09000000","0.24000000"],["15555.99000000","0.32141900"]]}}
2020-11-09T11:25:58.52263 btcusdt {"stream":"btcusdt@depth@100ms","data":{"e":"depthUpdate","E":1604921158515,"s":"BTCUSDT","U":6511132690,"u":6511132700,"b":[["15502.88000000","1.25000000"]],"a":[["15507.99000000","0.00000000"],["15508.30000000","0.00000000"],["15509.44000000","0.01710200"],["15509.51000000","0.00853400"],["15511.31000000","0.01700000"],["15512.00000000","0.00000000"],["15512.10000000","1.74800000"],["15513.15000000","0.00000000"],["15519.88000000","0.00000000"],["15522.53000000","0.05681900"]]}}
2020-11-09T11:25:58.62250 btcusdt {"stream":"btcusdt@depth@100ms","data":{"e":"depthUpdate","E":1604921158615,"s":"BTCUSDT","U":6511132701,"u":6511132708,"b":[["15504.84000000","1.25000000"],["15502.88000000","0.00000000"],["15469.67000000","0.03458800"],["14600.00000000","102.93400100"]],"a":[["15511.57000000","0.00000000"],["15514.16000000","0.32100000"],["15556.51000000","0.03100000"],["15606.00000000","0.01134000"]]}}
2020-11-09T11:25:58.72502 btcusdt {"stream":"btcusdt@depth@100ms","data":{"e":"depthUpdate","E":1604921158715,"s":"BTCUSDT","U":6511132709,"u":6511132736,"b":[["15508.48000000","0.00690000"],["15508.30000000","0.50000000"],["15507.70000000","0.02415500"],["15507.69000000","0.02903600"],["15507.68000000","0.02832700"],["15507.60000000","0.07690600"],["15507.53000000","0.03268400"],["15507.52000000","6.17609400"],["15505.85000000","0.00000000"],["15505.59000000","0.00000000"],["15505.14000000","0.11427900"],["15504.84000000","0.00000000"],["15504.11000000","0.00000000"],["15502.88000000","1.25000000"],["15500.98000000","0.22500000"]],"a":[["15507.53000000","0.00000000"],["15507.72000000","0.00000000"],["15508.03000000","0.00000000"],["15508.09000000","0.00000000"],["15508.49000000","0.00690000"],["15508.73000000","0.00000000"],["15509.29000000","0.00000000"],["15509.44000000","0.00000000"],["15509.45000000","0.07499600"],["15509.51000000","0.00000000"],["15511.31000000","0.00000000"],["15511.67000000","0.00000000"],["15513.05000000","0.00000000"],["15519.38000000","0.25769400"],["15530.87000000","0.31800000"]]}}
2020-11-09T11:25:58.82202 btcusdt {"stream":"btcusdt@depth@100ms","data":{"e":"depthUpdate","E":1604921158815,"s":"BTCUSDT","U":6511132737,"u":6511132787,"b":[["15508.48000000","7.69097000"],["15508.30000000","0.00000000"],["15507.70000000","0.00000000"],["15507.69000000","0.00000000"],["15507.68000000","0.00000000"],["15507.65000000","0.00000000"],["15507.60000000","0.00000000"],["15507.53000000","0.03397300"],["15507.52000000","5.50661700"],["15505.78000000","0.48000000"],["15505.23000000","1.00000000"],["15504.84000000","1.25000000"],["15504.13000000","0.08000000"],["15503.49000000","1.04000000"],["15503.44000000","0.00000000"],["15502.89000000","0.05000000"],["15502.88000000","0.00000000"],["15501.84000000","0.00000000"],["15500.72000000","0.00000000"],["15496.87000000","0.13439300"],["15494.94000000","0.00000000"],["15471.00000000","0.83176400"]],"a":[["15509.44000000","0.00257800"],["15511.32000000","0.00000000"],["15511.56000000","0.00000000"],["15511.92000000","0.01700000"],["15512.01000000","0.00000000"],["15512.10000000","0.00000000"],["15512.20000000","0.01700000"],["15512.70000000","1.74800000"],["15513.50000000","1.19800000"],["15513.58000000","0.00000000"],["15513.84000000","0.00000000"],["15513.95000000","0.00000000"],["15514.15000000","0.01000000"],["15514.34000000","0.05000000"],["15514.35000000","0.00000000"],["15514.37000000","0.00000000"],["15514.91000000","0.16540000"],["15515.31000000","0.01500000"],["15515.74000000","0.75000000"],["15561.00000000","0.26473100"]]}}
2020-11-09T11:25:58.92367 btcusdt {"stream":"btcusdt@depth@100ms","data":{"e":"depthUpdate","E":1604921158915,"s":"BTCUSDT","U":6511132788,"u":6511132901,"b":[["15510.22000000","0.50000000"],["15510.21000000","0.50000000"],["15509.53000000","0.01477000"],["15509.49000000","0.07735200"],["15509.44000000","0.15545000"],["15509.43000000","9.49776700"],["15509.26000000","0.00000000"],["15508.96000000","0.00690000"],["15508.57000000","0.02462500"],["15508.56000000","0.02237200"],["15508.55000000","0.01451900"],["15508.54000000","0.00000000"],["15508.49000000","1.15299700"],["15508.48000000","0.23207500"],["15507.85000000","0.38000000"],["15507.71000000","0.18000000"],["15507.32000000","0.55290000"],["15506.96000000","0.48000000"],["15506.25000000","0.00000000"],["15505.78000000","0.00000000"],["15505.67000000","0.03223800"],["15505.23000000","0.00000000"],["15505.10000000","0.00000000"],["15504.05000000","0.00000000"],["15503.64000000","0.12895100"],["15503.49000000","0.00000000"],["15502.78000000","0.00000000"],["15501.87000000","0.00201000"],["15500.71000000","0.00000000"],["15500.62000000","1.50000000"],["15499.31000000","0.00000000"],["15498.01000000","0.00000000"],["15429.98000000","0.00000000"]],"a":[["15508.49000000","0.00000000"],["15509.44000000","0.00000000"],["15509.45000000","0.00000000"],["15511.86000000","0.00000000"],["15511.92000000","0.00000000"],["15512.20000000","0.00000000"],["15512.68000000","0.00000000"],["15512.70000000","0.00000000"],["15513.11000000","0.00000000"],["15513.17000000","0.00000000"],["15513.49000000","0.00000000"],["15513.50000000","0.00000000"],["15513.64000000","0.00000000"],["15513.70000000","0.00000000"],["15513.77000000","0.00000000"],["15513.84000000","0.20000000"],["15513.85000000","0.00000000"],["15513.98000000","0.00000000"],["15514.07000000","0.00364300"],["15514.25000000","0.00000000"],["15514.26000000","0.00000000"],["15514.51000000","0.00000000"],["15514.76000000","0.00000000"],["15514.98000000","0.01700000"],["15514.99000000","0.15344700"],["15515.02000000","0.00000000"],["15515.18000000","0.00000000"],["15515.29000000","0.00000000"],["15515.30000000","1.74800000"],["15515.32000000","0.11427900"],["15515.41000000","0.00000000"],["15515.73000000","0.00000000"],["15517.00000000","0.00000000"],["15517.86000000","0.00000000"],["15518.22000000","0.50000000"],["15518.35000000","0.00000000"],["15518.60000000","0.10085700"],["15520.02000000","0.12894300"],["15520.17000000","0.00000000"],["15520.38000000","0.06727500"],["15520.94000000","0.30000000"],["15521.07000000","0.00000000"],["15521.22000000","0.00000000"],["15522.70000000","0.00000000"],["15523.93000000","0.00000000"],["15524.33000000","0.00000000"]]}}
2020-11-09T11:25:59.02484 btcusdt {"stream":"btcusdt@depth@100ms","data":{"e":"depthUpdate","E":1604921159015,"s":"BTCUSDT","U":6511132902,"u":6511132992,"b":[["15511.15000000","0.00000000"],["15510.42000000","0.01371900"],["15510.40000000","0.07204900"],["15510.37000000","6.72954300"],["15510.26000000","0.00000000"],["15510.23000000","0.00000000"],["15510.22000000","0.00000000"],["15510.21000000","0.01023900"],["15509.53000000","0.00000000"],["15509.51000000","0.00000000"],["15509.49000000","0.00000000"],["15509.44000000","0.15545000"],["15509.43000000","0.00000000"],["15508.57000000","0.00000000"],["15508.56000000","0.00000000"],["15508.55000000","0.00000000"],["15508.49000000","0.00000000"],["15508.48000000","0.00690000"],["15507.85000000","0.00000000"],["15507.71000000","0.00000000"],["15507.48000000","0.08000000"],["15507.32000000","0.00690000"],["15506.96000000","0.00000000"],["15506.93000000","0.08000000"],["15506.78000000","0.00000000"],["15506.05000000","0.08400000"],["15505.88000000","0.08000000"],["15505.67000000","0.00000000"],["15504.84000000","0.00000000"],["15503.62000000","1.25000000"],["15502.76000000","0.00000000"],["15501.59000000","0.00000000"],["15501.38000000","0.29301000"],["15501.35000000","0.14700000"],["15500.50000000","0.15990000"],["15499.37000000","0.00000000"],["15496.86000000","0.00000000"],["15492.78000000","0.00000000"]],"a":[["15510.38000000","0.00000000"],["15511.16000000","0.00690000"],["15511.82000000","0.00000000"],["15513.18000000","0.00000000"],["15513.57000000","0.00000000"],["15514.15000000","0.00000000"],["15514.16000000","0.00000000"],["15514.34000000","0.00000000"],["15514.50000000","0.00000000"],["15514.76000000","0.30000000"],["15514.77000000","0.00000000"],["15514.91000000","0.15540000"],["15515.10000000","0.32100000"],["15515.18000000","0.50000000"],["15515.51000000","0.05000000"],["15515.64000000","0.01000000"],["15515.74000000","0.00000000"],["15515.99000000","1.19800000"],["15516.31000000","0.29200000"],["15516.34000000","0.15700000"],["15516.45000000","0.00000000"],["15517.35000000","0.03223200"],["15517.45000000","0.01000000"],["15517.81000000","0.75000000"],["15518.16000000","0.29700000"],["15523.11000000","1.00866300"],["15523.22000000","0.50000000"],["15524.87000000","1.00000000"]]}}
