2020-11-09T11:26:30.64033 btcusdt {"stream":"btcusdt@depth@100ms","data":{"e":"depthUpdate","E":1604921190632,"s":"BTCUSDT","U":6511138681,"u":6511138693,"b":[["15488.66000000","0.06724200"],["15484.80000000","1.50000000"],["15484.75000000","0.00000000"],["15477.38000000","0.08800000"],["15437.09000000","0.24000000"]],"a":[["15497.71000000","9.07470700"],["15497.78000000","0.00000000"],["15499.98000000","0.00000000"],["15504.19000000","0.01000000"],["15505.35000000","0.00000000"],["15511.34000000","0.03364100"],["15519.10000000","0.00000000"]]}}
2020-11-09T11:26:30.74074 btcusdt {"stream":"btcusdt@depth@100ms","data":{"e":"depthUpdate","E":1604921190732,"s":"BTCUSDT","U":6511138694,"u":6511138704,"b":[["15493.86000000","0.01871400"],["15484.00000000","0.19390200"]],"a":[["15497.71000000","3.78270700"],["15498.29000000","2.01762700"],["15499.06000000","0.01974200"],["15501.75000000","0.50000000"],["15502.03000000","0.00000000"],["15511.34000000","0.03797300"],["15550.81000000","0.00000000"]]}}
2020-11-09T11:26:30.84066 btcusdt {"stream":"btcusdt@depth@100ms","data":{"e":"depthUpdate","E":1604921190832,"s":"BTCUSDT","U":6511138705,"u":6511138709,"b":[["15485.83000000","0.00291000"],["15482.64000000","0.01937700"]],"a":[["15497.71000000","3.78670700"],["15498.28000000","1.00881500"],["15532.92000000","0.00180000"]]}}
2020-11-09T11:26:30.93872 btcusdt {"stream":"btcusdt@depth@100ms","data":{"e":"depthUpdate","E":1604921190932,"s":"BTCUSDT","U":6511138710,"u":6511138722,"b":[["15493.07000000","0.00000000"],["15492.76000000","0.00747900"],["12400.00000000","25.88911800"]],"a":[["15497.71000000","1.49070700"],["15498.75000000","0.00928600"],["15498.89000000","0.30000000"],["15501.74000000","2.18952800"],["15548.88000000","0.00000000"],["15575.96000000","0.00000000"]]}}
2020-11-09T11:26:31.03837 btcusdt {"stream":"btcusdt@depth@100ms","data":{"e":"depthUpdate","E":1604921191032,"s":"BTCUSDT","U":6511138723,"u":6511138732,"b":[["15493.86000000","0.00000000"],["15492.86000000","0.04780600"],["15492.64000000","0.00000000"],["15492.43000000","0.05000000"],["15491.03000000","0.00000000"],["15490.27000000","0.00000000"],["15458.90000000","0.03100000"]],"a":[["15497.71000000","1.43058700"],["15498.62000000","0.25117800"],["15545.69000000","0.03100000"]]}}
2020-11-09T11:26:31.14020 btcusdt {"stream":"btcusdt@depth@100ms","data":{"e":"depthUpdate","E":1604921191132,"s":"BTCUSDT","U":6511138733,"u":6511138744,"b":[["15490.87000000","0.02106400"],["15485.15000000","0.00000000"],["15485.13000000","1.50000000"],["15484.80000000","0.00000000"],["15458.96000000","0.25000000"],["15437.09000000","0.00000000"],["15427.76000000","0.24000000"]],"a":[["15497.71000000","1.44862500"],["15502.47000000","0.32200000"],["15503.78000000","0.25789300"],["15536.45000000","0.25000000"]]}}
2020-11-09T11:26:31.23818 btcusdt {"stream":"btcusdt@depth@100ms","data":{"e":"depthUpdate","E":1604921191232,"s":"BTCUSDT","U":6511138745,"u":6511138753,"b":[["15491.40000000","0.10846700"],["15405.00000000","1.39662200"],["14850.00000000","47.11198500"],["11244.45000000","0.00000000"]],"a":[["15497.71000000","3.41711000"],["15600.00000000","211.57737500"],["15652.68000000","0.00100000"]]}}
2020-11-09T11:26:31.33868 btcusdt {"stream":"btcusdt@depth@100ms","data":{"e":"depthUpdate","E":1604921191332,"s":"BTCUSDT","U":6511138754,"u":6511138760,"b":[],"a":[["15498.17000000","0.00757400"],["15498.75000000","0.00000000"],["15498.89000000","0.20000000"],["15499.06000000","0.00000000"],["15499.98000000","0.10000000"],["15501.11000000","0.11427900"],["15508.00000000","1.00947600"]]}}
2020-11-09T11:26:31.43984 btcusdt {"stream":"btcusdt@depth@100ms","data":{"e":"depthUpdate","E":1604921191432,"s":"BTCUSDT","U":6511138761,"u":6511138769,"b":[["15489.09000000","0.97442800"],["15381.00000000","0.37683000"],["14880.15000000","0.00000000"]],"a":[["15497.71000000","8.11102500"],["15501.75000000","1.42747300"],["15524.48000000","0.00000000"],["15600.00000000","211.46910200"],["15674.90000000","0.00000000"]]}}
2020-11-09T11:26:31.53889 btcusdt {"stream":"btcusdt@depth@100ms","data":{"e":"depthUpdate","E":1604921191532,"s":"BTCUSDT","U":6511138770,"u":6511138780,"b":[],"a":[["15497.71000000","3.61102500"],["15498.16000000","1.01260200"],["15498.28000000","0.00000000"],["15498.62000000","0.00000000"],["15498.63000000","0.00000000"],["15498.88000000","0.10000000"],["15498.89000000","0.00000000"],["15499.98000000","0.00000000"],["15501.74000000","0.00000000"],["15508.11000000","0.06724200"]]}}
2020-11-09T11:26:31.64050 btcusdt {"stream":"btcusdt@depth@100ms","data":{"e":"depthUpdate","E":1604921191632,"s":"BTCUSDT","U":6511138781,"u":6511138793,"b":[["15497.70000000","0.03454000"],["15492.76000000","0.00000000"],["15492.33000000","0.00637700"],["15462.00000000","0.00000000"],["15384.00000000","0.16327300"]],"a":[["15497.71000000","3.41102500"],["15498.87000000","0.20000000"],["15498.88000000","0.00000000"],["15499.98000000","0.10000000"],["15500.59000000","0.02874700"],["15558.00000000","2.48798200"]]}}
2020-11-09T11:26:31.74197 btcusdt {"stream":"btcusdt@depth@100ms","data":{"e":"depthUpdate","E":1604921191732,"s":"BTCUSDT","U":6511138794,"u":6511138812,"b":[["15491.92000000","0.11427900"],["15491.39000000","0.11192500"],["15485.34000000","0.00000000"],["15485.13000000","0.00000000"],["15471.68000000","0.00201700"],["14878.50000000","0.00070200"]],"a":[["15497.71000000","3.24477400"],["15498.16000000","0.00000000"],["15498.86000000","0.00000000"],["15498.90000000","0.00000000"],["15499.97000000","0.15219400"],["15501.76000000","2.00000000"],["15524.38000000","0.00201700"],["15533.71000000","0.11187100"],["15590.51000000","0.02206400"]]}}
2020-11-09T11:26:31.84827 btcusdt {"stream":"btcusdt@depth@100ms","data":{"e":"depthUpdate","E":1604921191833,"s":"BTCUSDT","U":6511138813,"u":6511138822,"b":[["15490.55000000","0.00000000"],["15489.86000000","0.00000000"],["15488.16000000","0.02767100"],["15486.74000000","0.14850000"],["15485.29000000","0.00000000"],["15479.91000000","0.02236400"],["15421.18000000","0.02964400"]],"a":[["15497.71000000","3.22390900"],["15555.00000000","5.67637000"]]}}
2020-11-09T11:26:31.93960 btcusdt {"stream":"btcusdt@depth@100ms","data":{"e":"depthUpdate","E":1604921191933,"s":"BTCUSDT","U":6511138823,"u":6511138831,"b":[["15485.21000000","1.50000000"],["15459.53000000","0.00202500"],["15458.00000000","2.00000000"]],"a":[["15497.71000000","1.16388100"],["15498.87000000","0.00000000"],["15499.96000000","0.20000000"],["15537.03000000","0.00202500"],["15841.50000000","0.00000000"]]}}
2020-11-09T11:26:32.03941 btcusdt {"stream":"btcusdt@depth@100ms","data":{"e":"depthUpdate","E":1604921192033,"s":"BTCUSDT","U":6511138832,"u":6511138851,"b":[["15492.43000000","0.00000000"],["15492.34000000","0.05000000"],["15490.45000000","0.00000000"],["15490.09000000","0.00200000"],["15490.08000000","0.48621000"],["15489.58000000","1.25000000"],["15489.27000000","0.00000000"],["15488.66000000","0.00000000"],["15485.44000000","0.50473000"],["15485.21000000","0.00000000"],["15485.08000000","1.00946000"],["15484.46000000","0.10000000"],["15483.60000000","0.13448700"]],"a":[["15498.16000000","1.01260000"],["15498.92000000","1.40601300"],["15499.78000000","0.51221800"],["15502.44000000","0.00000000"],["15503.40000000","0.75000000"],["15514.10000000","0.00000000"],["15674.90000000","0.00129000"]]}}
2020-11-09T11:26:32.14124 btcusdt {"stream":"btcusdt@depth@100ms","data":{"e":"depthUpdate","E":1604921192133,"s":"BTCUSDT","U":6511138852,"u":6511138861,"b":[["15492.42000000","0.11469500"],["15492.35000000","0.16000000"],["15492.33000000","0.00000000"],["15492.05000000","0.00718400"],["15487.58000000","0.30505300"],["15485.53000000","0.03362200"],["15485.09000000","1.50000000"]],"a":[["15498.48000000","0.01881800"],["15507.86000000","0.30222500"],["15533.33000000","0.00988000"]]}}
2020-11-09T11:26:32.24214 btcusdt {"stream":"btcusdt@depth@100ms","data":{"e":"depthUpdate","E":1604921192233,"s":"BTCUSDT","U":6511138862,"u":6511138867,"b":[["15485.09000000","0.00000000"],["15483.03000000","1.08313200"],["15427.76000000","0.00000000"]],"a":[["15498.91000000","0.15219400"],["15499.97000000","0.00000000"],["15843.26000000","0.00066800"]]}}
2020-11-09T11:26:32.34182 btcusdt {"stream":"btcusdt@depth@100ms","data":{"e":"depthUpdate","E":1604921192333,"s":"BTCUSDT","U":6511138868,"u":6511138873,"b":[["15405.00000000","1.01979200"]],"a":[["15507.86000000","0.00000000"],["15512.71000000","0.00000000"],["15514.55000000","0.00000000"],["15720.00000000","5.93755600"]]}}
2020-11-09T11:26:32.44115 btcusdt {"stream":"btcusdt@depth@100ms","data":{"e":"depthUpdate","E":1604921192433,"s":"BTCUSDT","U":6511138874,"u":6511138888,"b":[["15497.70000000","0.00000500"],["15491.92000000","0.00000000"],["15490.50000000","0.22500000"],["15484.55000000","1.50000000"],["15420.79000000","0.00164000"]],"a":[["15497.71000000","0.84782200"],["15500.20000000","0.22700100"],["15500.59000000","0.00000000"],["15500.68000000","0.00000000"],["15501.76000000","1.72000000"],["15507.86000000","0.30254100"],["15514.48000000","1.50000000"],["15522.24000000","0.00000000"]]}}
2020-11-09T11:26:32.53999 btcusdt {"stream":"btcusdt@depth@100ms","data":{"e":"depthUpdate","E":1604921192533,"s":"BTCUSDT","U":6511138889,"u":6511138909,"b":[["15492.36000000","0.05358300"],["15492.34000000","0.00000000"],["15492.08000000","0.00727500"],["15492.05000000","0.00000000"],["15402.00000000","0.57882000"]],"a":[["15497.71000000","0.33801000"],["15498.90000000","0.20000000"],["15499.78000000","0.00000000"],["15499.96000000","0.00000000"],["15500.85000000","0.05000000"],["15500.92000000","0.01000000"],["15501.75000000","0.50000000"],["15502.26000000","0.00000000"],["15502.39000000","0.00000000"],["15502.72000000","0.01690000"],["15503.12000000","0.01500000"],["15504.19000000","0.00000000"],["15504.59000000","0.00000000"],["15507.79000000","0.03362200"],["15513.77000000","1.50000000"],["15514.48000000","0.00000000"]]}}
2020-11-09T11:26:32.64365 btcusdt {"stream":"btcusdt@depth@100ms","data":{"e":"depthUpdate","E":1604921192633,"s":"BTCUSDT","U":6511138910,"u":6511138914,"b":[["15405.51000000","0.24000000"]],"a":[["15498.90000000","0.00000000"],["15499.97000000","0.20000000"],["15511.77000000","0.03535800"],["15538.81000000","0.00078400"]]}}
2020-11-09T11:26:32.74272 btcusdt {"stream":"btcusdt@depth@100ms","data":{"e":"depthUpdate","E":1604921192733,"s":"BTCUSDT","U":6511138915,"u":6511138936,"b":[["15492.85000000","0.00000000"],["15485.40000000","0.15300000"]],"a":[["15497.71000000","0.28897300"],["15498.92000000","0.00000000"],["15499.99000000","0.00000000"],["15500.00000000","0.00000000"],["15500.86000000","0.00000000"],["15501.01000000","0.00000000"],["15501.15000000","0.00690000"],["15501.68000000","0.03400000"],["15501.76000000","0.00000000"],["15501.95000000","0.00000000"],["15502.04000000","0.00000000"],["15502.42000000","0.00000000"],["15502.61000000","1.19800000"],["15502.76000000","0.18000000"],["15503.88000000","0.50000000"],["15517.64000000","0.00000000"]]}}
2020-11-09T11:26:32.83933 btcusdt {"stream":"btcusdt@depth@100ms","data":{"e":"depthUpdate","E":1604921192833,"s":"BTCUSDT","U":6511138937,"u":6511138949,"b":[["15492.43000000","0.11427900"],["15492.09000000","0.02500000"],["15484.53000000","0.50000000"],["15481.43000000","0.00000000"],["15477.67000000","0.29700000"],["15188.31000000","0.00000000"]],"a":[["15498.91000000","0.00000000"],["15499.98000000","0.00000000"],["15500.19000000","0.15219400"],["15501.67000000","0.10000000"],["15502.57000000","0.20000000"],["15505.11000000","0.00000000"],["15513.84000000","0.02500000"]]}}
2020-11-09T11:26:32.94086 btcusdt {"stream":"btcusdt@depth@100ms","data":{"e":"depthUpdate","E":1604921192933,"s":"BTCUSDT","U":6511138950,"u":6511138960,"b":[["15495.55000000","0.01881700"],["15492.42000000","0.10000000"],["15492.08000000","0.00000000"],["15479.09000000","0.64218100"],["14500.00000000","265.08099000"]],"a":[["15497.71000000","0.28975400"],["15497.96000000","0.13941000"],["15500.20000000","0.00200000"],["15500.52000000","0.08000000"],["15501.66000000","0.31800200"]]}}
2020-11-09T11:26:33.04056 btcusdt {"stream":"btcusdt@depth@100ms","data":{"e":"depthUpdate","E":1604921193033,"s":"BTCUSDT","U":6511138961,"u":6511138966,"b":[["15495.13000000","0.00872700"],["15492.36000000","0.00358300"],["15492.32000000","0.05000000"]],"a":[["15500.85000000","0.00000000"],["15501.15000000","0.05690000"],["15597.00000000","1.21375200"]]}}
2020-11-09T11:26:33.14216 btcusdt {"stream":"btcusdt@depth@100ms","data":{"e":"depthUpdate","E":1604921193133,"s":"BTCUSDT","U":6511138967,"u":6511138975,"b":[["15490.87000000","0.00000000"],["15484.97000000","1.50000000"],["15484.96000000","0.00000000"],["15484.55000000","0.00000000"]],"a":[["15508.11000000","0.00000000"],["15549.45000000","0.00000000"],["15555.00000000","3.67637000"],["19780.00000000","0.30347300"]]}}
2020-11-09T11:26:33.24153 btcusdt {"stream":"btcusdt@depth@100ms","data":{"e":"depthUpdate","E":1604921193233,"s":"BTCUSDT","U":6511138976,"u":6511138985,"b":[["15490.51000000","0.02106400"],["15384.00000000","0.54010300"],["15381.00000000","0.48510300"]],"a":[["15498.16000000","0.00000000"],["15498.29000000","0.01762700"],["15498.92000000","1.40601200"],["15500.92000000","0.00000000"],["15501.15000000","0.06690000"],["15503.40000000","0.00000000"],["15504.91000000","0.75000000"]]}}
2020-11-09T11:26:33.43278 btcusdt {"stream":"btcusdt@depth@100ms","data":{"e":"depthUpdate","E":1604921193333,"s":"BTCUSDT","U":6511138986,"u":6511139001,"b":[["15495.55000000","0.00000000"],["15495.53000000","0.01491000"],["15485.53000000","0.00000000"],["15485.36000000","1.50000000"],["15485.22000000","0.00000000"],["15484.97000000","0.00000000"],["15483.60000000","0.00000000"]],"a":[["15497.71000000","0.28905700"],["15499.97000000","0.00000000"],["15502.44000000","0.20000000"],["15502.57000000","0.00000000"],["15503.87000000","0.00000000"],["15554.00000000","16.41037700"],["15615.50000000","0.00000000"]]}}
2020-11-09T11:26:33.44114 btcusdt {"stream":"btcusdt@depth@100ms","data":{"e":"depthUpdate","E":1604921193433,"s":"BTCUSDT","U":6511139002,"u":6511139006,"b":[["14480.20000000","0.00000000"]],"a":[["15503.78000000","0.00000000"],["15514.30000000","0.25786400"],["15525.36000000","0.00405900"],["15555.00000000","4.05320000"]]}}
2020-11-09T11:26:33.53982 btcusdt {"stream":"btcusdt@depth@100ms","data":{"e":"depthUpdate","E":1604921193533,"s":"BTCUSDT","U":6511139007,"u":6511139049,"b":[["15497.70000000","6.99307800"],["15497.46000000","0.00000000"],["15497.43000000","0.00000000"],["15497.19000000","0.00690000"],["15496.74000000","0.02979700"],["15496.68000000","0.00011600"],["15494.12000000","0.00000000"],["15493.11000000","0.15371600"],["15492.94000000","0.11427900"],["15492.86000000","0.00000000"],["15492.43000000","0.00000000"],["15485.53000000","0.03362100"],["15483.79000000","0.13448600"]],"a":[["15497.71000000","0.09001300"],["15497.96000000","0.12800000"],["15498.29000000","0.00000000"],["15498.91000000","0.40601300"],["15498.92000000","0.00000000"],["15498.95000000","0.00000000"],["15500.19000000","0.00000000"],["15501.11000000","0.00000000"],["15501.60000000","0.11427900"],["15501.65000000","0.15219400"],["15501.82000000","0.94198000"],["15501.83000000","0.00000000"],["15502.43000000","0.48550000"],["15502.44000000","0.00000000"],["15503.13000000","0.54376700"]]}}
2020-11-09T11:26:33.64050 btcusdt {"stream":"btcusdt@depth@100ms","data":{"e":"depthUpdate","E":1604921193634,"s":"BTCUSDT","U":6511139050,"u":6511139072,"b":[["15497.70000000","7.46406500"],["15492.64000000","0.05000000"],["15492.32000000","0.00000000"],["15488.22000000","0.14400000"],["14203.00000000","1.00000000"]],"a":[["15497.71000000","0.05371900"],["15501.15000000","0.00690000"],["15502.19000000","0.05000000"],["15502.32000000","0.01000000"],["15502.72000000","0.00690000"],["15503.12000000","0.00000000"],["15503.88000000","0.00000000"],["15504.09000000","1.46139600"],["15504.12000000","0.01000000"],["15504.45000000","0.50200000"],["15504.52000000","0.01500000"],["15505.59000000","0.00000000"],["15508.00000000","0.00000000"],["15509.28000000","0.00306000"],["15509.62000000","1.00949200"],["15610.50000000","0.01100000"]]}}
2020-11-09T11:26:33.74054 btcusdt {"stream":"btcusdt@depth@100ms","data":{"e":"depthUpdate","E":1604921193734,"s":"BTCUSDT","U":6511139073,"u":6511139081,"b":[["15489.56000000","0.03360400"],["14643.20000000","0.00171000"]],"a":[["15497.90000000","0.00200000"],["15504.05000000","0.00000000"],["15504.45000000","0.00200000"],["15504.53000000","0.50000000"],["15513.61000000","1.50000000"],["15513.77000000","0.00000000"]]}}
2020-11-09T11:26:33.84110 btcusdt {"stream":"btcusdt@depth@100ms","data":{"e":"depthUpdate","E":1604921193834,"s":"BTCUSDT","U":6511139082,"u":6511139084,"b":[["15495.53000000","0.00000000"],["15495.47000000","0.01422000"]],"a":[["15505.74000000","0.30000000"]]}}
2020-11-09T11:26:33.94238 btcusdt {"stream":"btcusdt@depth@100ms","data":{"e":"depthUpdate","E":1604921193934,"s":"BTCUSDT","U":6511139085,"u":6511139093,"b":[["15494.25000000","0.11427900"],["15493.77000000","0.02106400"],["15492.94000000","0.00000000"],["15490.51000000","0.00000000"],["15485.68000000","0.00000000"],["15485.36000000","0.00000000"]],"a":[["15501.60000000","0.00000000"],["15506.25000000","0.00000000"]]}}
2020-11-09T11:26:34.04139 btcusdt {"stream":"btcusdt@depth@100ms","data":{"e":"depthUpdate","E":1604921194034,"s":"BTCUSDT","U":6511139094,"u":6511139106,"b":[["15497.70000000","7.06577000"],["15492.95000000","0.05000000"],["15492.64000000","0.00000000"],["15487.96000000","0.10081100"],["15486.20000000","0.50471400"],["15485.84000000","1.00942700"],["15485.68000000","0.00000000"],["15485.44000000","0.00000000"],["15485.08000000","0.00000000"],["14643.20000000","0.02511000"]],"a":[["15497.71000000","0.55371900"],["15503.12000000","0.27188300"]]}}
2020-11-09T11:26:34.14130 btcusdt {"stream":"btcusdt@depth@100ms","data":{"e":"depthUpdate","E":1604921194134,"s":"BTCUSDT","U":6511139107,"u":6511139117,"b":[["15497.70000000","1.76577000"],["15492.63000000","0.00000000"],["15491.84000000","0.00000000"],["15489.69000000","0.00000000"],["15485.45000000","0.02236400"],["15485.34000000","1.50000000"],["15479.91000000","0.00000000"]],"a":[["15502.57000000","0.20000000"],["15503.70000000","0.20000000"],["25000.00000000","20.89396300"]]}}
2020-11-09T11:26:34.24127 btcusdt {"stream":"btcusdt@depth@100ms","data":{"e":"depthUpdate","E":1604921194234,"s":"BTCUSDT","U":6511139118,"u":6511139126,"b":[["15497.70000000","1.04407800"],["15494.25000000","0.00000000"],["15493.63000000","0.12000000"],["15492.87000000","0.08400000"],["15489.58000000","0.00000000"],["15489.57000000","1.25000000"],["15485.34000000","0.00000000"]],"a":[["15555.00000000","3.67637000"]]}}
2020-11-09T11:26:34.34177 btcusdt {"stream":"btcusdt@depth@100ms","data":{"e":"depthUpdate","E":1604921194334,"s":"BTCUSDT","U":6511139127,"u":6511139142,"b":[["15497.70000000","1.04407800"],["15496.29000000","0.01027200"],["15495.13000000","0.00000000"],["15493.45000000","0.11427900"],["15485.19000000","0.00000000"],["15484.95000000","0.00000000"]],"a":[["15497.71000000","0.49366900"],["15500.50000000","0.25245100"],["15500.51000000","0.38126400"],["15501.65000000","0.00000000"],["15501.67000000","0.00000000"]]}}
2020-11-09T11:26:34.44152 btcusdt {"stream":"btcusdt@depth@100ms","data":{"e":"depthUpdate","E":1604921194434,"s":"BTCUSDT","U":6511139143,"u":6511139156,"b":[["15496.69000000","0.01304800"],["15495.47000000","0.00000000"],["15494.41000000","0.50000000"],["15485.25000000","1.50000000"]],"a":[["15497.71000000","0.51170700"],["15501.14000000","0.34035200"],["15501.21000000","0.16000000"],["15501.25000000","0.50000000"],["15501.63000000","0.11427900"],["15502.78000000","0.16000000"],["15503.26000000","0.16000000"],["15513.61000000","0.00000000"],["15514.14000000","1.50000000"],["25000.00000000","20.89296300"]]}}
2020-11-09T11:26:34.54355 btcusdt {"stream":"btcusdt@depth@100ms","data":{"e":"depthUpdate","E":1604921194534,"s":"BTCUSDT","U":6511139157,"u":6511139171,"b":[["15497.70000000","0.34760500"],["15494.12000000","0.04780600"],["15493.11000000","0.10591000"],["15463.72000000","0.00400000"]],"a":[["15497.71000000","0.36573700"],["15497.96000000","0.00000000"],["15498.07000000","0.12800000"],["15501.66000000","0.00000000"],["15501.75000000","0.00000000"],["15503.70000000","0.00000000"],["15504.37000000","1.02640200"],["15514.14000000","0.00000000"],["15525.36000000","0.00000000"]]}}
2020-11-09T11:26:34.64302 btcusdt {"stream":"btcusdt@depth@100ms","data":{"e":"depthUpdate","E":1604921194634,"s":"BTCUSDT","U":6511139172,"u":6511139199,"b":[["15497.51000000","0.00400000"],["15497.03000000","0.03083000"],["15496.74000000","0.00000000"],["15494.12000000","0.00000000"],["15493.77000000","0.00000000"],["15492.96000000","0.04780600"],["15491.40000000","0.00000000"],["15490.64000000","0.02106400"],["15465.16000000","0.00200000"],["15463.72000000","0.00600000"],["15381.00000000","0.37683000"]],"a":[["15497.71000000","2.51803800"],["15498.91000000","0.00000000"],["15500.49000000","0.20000000"],["15502.57000000","0.00000000"],["15502.99000000","0.03226000"],["15503.11000000","0.50000000"],["15503.12000000","0.00000000"],["15504.09000000","0.00000000"],["15504.53000000","0.00000000"],["15504.73000000","0.50000000"],["15504.74000000","0.12904000"],["15505.74000000","0.00000000"],["15512.80000000","1.50000000"],["15526.06000000","0.00451600"]]}}
2020-11-09T11:26:34.74298 btcusdt {"stream":"btcusdt@depth@100ms","data":{"e":"depthUpdate","E":1604921194734,"s":"BTCUSDT","U":6511139200,"u":6511139202,"b":[["15493.45000000","0.00000000"],["15486.46000000","0.00400000"]],"a":[]}}
2020-11-09T11:26:34.84235 btcusdt {"stream":"btcusdt@depth@100ms","data":{"e":"depthUpdate","E":1604921194834,"s":"BTCUSDT","U":6511139203,"u":6511139210,"b":[["15496.69000000","0.00000000"],["15493.85000000","0.01683000"],["15493.00000000","0.11427900"],["15402.00000000","0.68709300"]],"a":[["15501.63000000","0.00000000"],["15510.03000000","0.50000000"],["15512.55000000","0.00000000"],["15512.80000000","0.00000000"]]}}
2020-11-09T11:26:34.94319 btcusdt {"stream":"btcusdt@depth@100ms","data":{"e":"depthUpdate","E":1604921194934,"s":"BTCUSDT","U":6511139211,"u":6511139220,"b":[["15496.29000000","0.00065800"],["15493.44000000","0.00841000"],["15381.00000000","0.00000000"],["15325.57000000","0.00000000"]],"a":[["15500.48000000","0.15219400"],["15500.51000000","0.22907000"],["15504.73000000","0.00000000"],["15504.86000000","0.50000000"],["15512.70000000","0.00000000"]]}}
2020-11-09T11:26:35.04378 btcusdt {"stream":"btcusdt@depth@100ms","data":{"e":"depthUpdate","E":1604921195034,"s":"BTCUSDT","U":6511139221,"u":6511139226,"b":[["15493.01000000","0.05000000"],["15492.95000000","0.00000000"]],"a":[["15497.71000000","2.39733100"],["15504.86000000","0.00000000"],["15505.05000000","0.50000000"]]}}
2020-11-09T11:26:35.14167 btcusdt {"stream":"btcusdt@depth@100ms","data":{"e":"depthUpdate","E":1604921195134,"s":"BTCUSDT","U":6511139227,"u":6511139232,"b":[["15493.85000000","0.00000000"],["15493.68000000","0.01475800"],["15405.00000000","1.39662200"]],"a":[["15497.71000000","0.50000000"],["15498.92000000","0.40601200"],["15500.48000000","0.00000000"]]}}
2020-11-09T11:26:35.24185 btcusdt {"stream":"btcusdt@depth@100ms","data":{"e":"depthUpdate","E":1604921195234,"s":"BTCUSDT","U":6511139233,"u":6511139241,"b":[["15493.44000000","0.00000000"],["15311.62000000","0.00072500"]],"a":[["15498.99000000","0.00000000"],["15500.48000000","0.15219400"],["15500.49000000","0.00000000"],["15501.67000000","0.12906100"],["15502.31000000","0.20000000"],["15558.50000000","0.00000000"]]}}
2020-11-09T11:26:35.34535 btcusdt {"stream":"btcusdt@depth@100ms","data":{"e":"depthUpdate","E":1604921195334,"s":"BTCUSDT","U":6511139242,"u":6511139246,"b":[["15497.70000000","0.31404500"],["15486.53000000","0.00000000"],["15479.34000000","0.00000000"]],"a":[["15497.71000000","0.49677300"],["15555.00000000","4.05320000"]]}}
2020-11-09T11:26:35.44203 btcusdt {"stream":"btcusdt@depth@100ms","data":{"e":"depthUpdate","E":1604921195435,"s":"BTCUSDT","U":6511139247,"u":6511139251,"b":[["15497.70000000","0.31326200"],["15490.26000000","0.00000000"]],"a":[["15526.06000000","0.00000000"],["15554.50000000","2.00000000"],["15620.41000000","0.00000000"]]}}
2020-11-09T11:26:35.54142 btcusdt {"stream":"btcusdt@depth@100ms","data":{"e":"depthUpdate","E":1604921195535,"s":"BTCUSDT","U":6511139252,"u":6511139261,"b":[["15493.11000000","0.00000000"],["15492.96000000","0.00000000"],["15491.40000000","0.15371600"],["15487.65000000","0.13444200"],["15485.25000000","0.00000000"]],"a":[["15498.91000000","0.15219400"],["15500.48000000","0.00000000"],["15526.86000000","0.00064500"],["15599.00000000","12.96592000"]]}}
2020-11-09T11:26:35.64371 btcusdt {"stream":"btcusdt@depth@100ms","data":{"e":"depthUpdate","E":1604921195635,"s":"BTCUSDT","U":6511139262,"u":6511139284,"b":[["15497.70000000","0.00000000"],["15497.51000000","0.01090000"],["15497.03000000","0.00000000"],["15493.00000000","0.00000000"],["15492.07000000","0.11427900"]],"a":[["15497.52000000","6.72127500"],["15497.62000000","0.00690000"],["15497.69000000","0.00000000"],["15497.70000000","0.00000000"],["15497.71000000","0.00000000"],["15498.92000000","0.00000000"],["15500.50000000","0.00000000"],["15501.06000000","0.11427900"],["15502.43000000","0.00000000"],["15537.22000000","0.02949800"]]}}
2020-11-09T11:26:35.74110 btcusdt {"stream":"btcusdt@depth@100ms","data":{"e":"depthUpdate","E":1604921195735,"s":"BTCUSDT","U":6511139285,"u":6511139295,"b":[["15485.50000000","1.50000000"]],"a":[["15497.52000000","6.95327900"],["15501.14000000","0.00000000"],["15501.82000000","0.00000000"],["15502.98000000","0.20000000"],["15508.03000000","1.00949200"],["15509.62000000","0.00000000"],["15510.43000000","1.50000000"]]}}
2020-11-09T11:26:35.84213 btcusdt {"stream":"btcusdt@depth@100ms","data":{"e":"depthUpdate","E":1604921195835,"s":"BTCUSDT","U":6511139296,"u":6511139299,"b":[["15485.50000000","0.00000000"],["15485.38000000","1.50000000"],["15420.21000000","0.00000000"]],"a":[["15497.52000000","6.89320400"]]}}
2020-11-09T11:26:35.94304 btcusdt {"stream":"btcusdt@depth@100ms","data":{"e":"depthUpdate","E":1604921195935,"s":"BTCUSDT","U":6511139300,"u":6511139303,"b":[["15485.38000000","0.00000000"]],"a":[["15500.50000000","0.20000000"],["15502.31000000","0.00000000"],["15532.60000000","0.00000000"]]}}
2020-11-09T11:26:36.04184 btcusdt {"stream":"btcusdt@depth@100ms","data":{"e":"depthUpdate","E":1604921196035,"s":"BTCUSDT","U":6511139304,"u":6511139313,"b":[["15497.51000000","0.01490000"],["15495.36000000","0.00000000"],["15493.01000000","0.00000000"],["15492.43000000","0.05000000"],["15485.44000000","1.50000000"]],"a":[["15497.52000000","8.89320400"],["15514.29000000","0.36962900"],["15515.13000000","0.00000000"],["15555.00000000","3.67637000"]]}}
2020-11-09T11:26:36.14206 btcusdt {"stream":"btcusdt@depth@100ms","data":{"e":"depthUpdate","E":1604921196135,"s":"BTCUSDT","U":6511139314,"u":6511139327,"b":[["15493.86000000","0.01589700"],["15493.68000000","0.00000000"],["15492.43000000","0.09780600"],["15491.40000000","0.10591000"],["15458.96000000","0.00000000"]],"a":[["15497.52000000","8.88483500"],["15505.34000000","0.09633600"],["15506.61000000","0.30000000"],["15507.03000000","0.21346700"],["15509.41000000","1.00000000"],["15511.61000000","0.00000000"],["15512.50000000","0.30900000"],["15536.45000000","0.00000000"],["15620.14000000","0.00066800"]]}}
2020-11-09T11:26:36.24272 btcusdt {"stream":"btcusdt@depth@100ms","data":{"e":"depthUpdate","E":1604921196235,"s":"BTCUSDT","U":6511139328,"u":6511139336,"b":[["15497.51000000","0.00000000"],["15493.32000000","0.00757000"],["15492.88000000","0.10591000"],["15491.40000000","0.00000000"],["15420.79000000","0.00000000"]],"a":[["15497.51000000","0.00230100"],["15501.66000000","0.16134300"],["15504.24000000","0.00128900"],["15549.00000000","0.64116000"]]}}
2020-11-09T11:26:36.34228 btcusdt {"stream":"btcusdt@depth@100ms","data":{"e":"depthUpdate","E":1604921196335,"s":"BTCUSDT","U":6511139337,"u":6511139379,"b":[["15497.19000000","0.01380000"],["15495.17000000","0.05594900"],["15494.42000000","0.25000100"],["15492.88000000","0.00000000"],["15492.44000000","0.94682600"],["15492.43000000","0.05000000"],["15491.67000000","0.10591000"],["15491.40000000","0.04780600"],["15490.87000000","0.23352200"],["15490.20000000","0.24450700"],["15490.01000000","0.61674700"]],"a":[["15497.20000000","5.87470700"],["15497.36000000","0.00690000"],["15497.46000000","0.02589200"],["15497.47000000","0.02600000"],["15497.49000000","0.00000000"],["15497.52000000","7.33862400"],["15501.71000000","0.05000000"],["15501.84000000","1.75800000"],["15502.19000000","0.00000000"],["15502.32000000","0.00000000"],["15502.47000000","0.00000000"],["15503.64000000","0.01000000"],["15504.04000000","0.01500000"],["15504.12000000","0.00000000"],["15504.52000000","0.00000000"]]}}
2020-11-09T11:26:36.44508 btcusdt {"stream":"btcusdt@depth@100ms","data":{"e":"depthUpdate","E":1604921196435,"s":"BTCUSDT","U":6511139380,"u":6511139483,"b":[["15497.19000000","0.00000000"],["15496.68000000","0.00000000"],["15496.65000000","0.00000000"],["15496.61000000","0.00000000"],["15496.35000000","0.00000000"],["15496.29000000","0.00000000"],["15496.00000000","0.00000000"],["15495.81000000","0.00690000"],["15495.79000000","0.00000000"],["15495.17000000","0.00000000"],["15495.16000000","0.00000000"],["15495.00000000","0.00000000"],["15494.69000000","0.00000000"],["15494.47000000","0.26541700"],["15494.46000000","0.03083000"],["15494.43000000","0.00129000"],["15494.42000000","0.00000000"],["15492.44000000","0.92292100"],["15492.07000000","0.00000000"],["15491.92000000","0.00000000"],["15491.07000000","0.11427900"],["15490.87000000","0.00000000"],["15490.75000000","0.00000000"],["15490.64000000","0.00000000"],["15490.50000000","0.00000000"],["15490.21000000","0.25503900"],["15490.20000000","0.02106400"],["15490.01000000","0.61674700"],["15488.09000000","0.12905200"],["15487.96000000","0.00000000"],["15487.49000000","0.00000000"],["15485.86000000","0.10081200"],["15477.67000000","0.00000000"],["15419.70000000","0.00648500"]],"a":[["15495.82000000","0.50000000"],["15496.30000000","0.00000000"],["15496.36000000","0.00000000"],["15496.42000000","0.00000000"],["15496.62000000","0.00000000"],["15496.66000000","0.00000000"],["15496.69000000","0.00000000"],["15496.95000000","0.04644800"],["15496.96000000","0.04513700"],["15497.16000000","0.00000000"],["15497.18000000","0.00000000"],["15497.19000000","6.09010000"],["15497.20000000","7.77724700"],["15497.35000000","0.03138100"],["15497.36000000","0.03684200"],["15497.46000000","0.00000000"],["15497.47000000","0.00000000"],["15497.52000000","2.03862400"],["15497.71000000","0.00200000"],["15499.30000000","0.11427900"],["15501.06000000","0.00000000"],["15501.25000000","0.00000000"],["15501.42000000","0.03400000"],["15501.67000000","1.32706100"],["15501.68000000","0.00000000"],["15501.77000000","1.74800000"],["15501.84000000","0.01000000"],["15501.93000000","0.29100000"],["15502.61000000","0.00000000"],["15503.05000000","0.25790700"],["15504.24000000","0.00000000"],["15506.15000000","0.00300000"],["15514.30000000","0.00000000"]]}}
2020-11-09T11:26:36.54601 btcusdt {"stream":"btcusdt@depth@100ms","data":{"e":"depthUpdate","E":1604921196535,"s":"BTCUSDT","U":6511139484,"u":6511139521,"b":[["15494.41000000","0.00000000"],["15492.43000000","0.00000000"],["15492.10000000","0.05000000"],["15490.21000000","0.00000000"],["15490.20000000","0.00000000"],["15490.08000000","0.00000000"],["15490.06000000","0.22500000"],["15489.57000000","0.00000000"],["15489.56000000","0.00000000"],["15488.61000000","1.25000000"],["15488.23000000","0.65036100"],["15487.92000000","0.00000000"],["15487.03000000","0.00000000"],["15420.62000000","0.00164000"]],"a":[["15495.82000000","2.38787100"],["15496.06000000","0.07050700"],["15496.31000000","0.00000000"],["15496.94000000","0.15219400"],["15497.10000000","0.03017700"],["15497.19000000","5.30756400"],["15497.20000000","7.31970100"],["15498.91000000","0.00000000"],["15498.99000000","0.20000000"],["15499.76000000","0.22500100"],["15500.50000000","0.00000000"],["15500.73000000","0.03400000"],["15501.42000000","0.00000000"],["15505.98000000","1.25000000"],["15507.26000000","0.00000000"],["15550.28000000","0.00000000"],["15550.48000000","0.00539200"]]}}
2020-11-09T11:26:36.64464 btcusdt {"stream":"btcusdt@depth@100ms","data":{"e":"depthUpdate","E":1604921196635,"s":"BTCUSDT","U":6511139522,"u":6511139597,"b":[["15495.81000000","0.00000000"],["15495.65000000","0.39900000"],["15495.03000000","0.42898400"],["15494.97000000","0.00690000"],["15494.93000000","0.00000000"],["15494.48000000","0.00000000"],["15494.47000000","0.00000000"],["15494.46000000","0.00000000"],["15494.43000000","0.00000000"],["15494.13000000","0.12000000"],["15494.12000000","0.00000000"],["15493.99000000","0.00000000"],["15493.86000000","0.00000000"],["15493.32000000","0.00000000"],["15493.10000000","0.00000000"],["15492.88000000","0.08000000"],["15492.60000000","0.01917700"],["15492.44000000","0.00000000"],["15492.12000000","0.00654700"],["15490.07000000","0.00000000"],["15490.06000000","0.00000000"],["15490.01000000","0.00000000"],["15489.10000000","0.00000000"],["15488.62000000","0.02106400"],["15488.61000000","0.00000000"],["15488.23000000","0.00000000"],["15487.86000000","0.03360400"],["15486.80000000","0.00000000"],["15486.34000000","1.25000000"],["15485.83000000","0.00000000"],["15479.27000000","0.15910000"],["15457.04000000","0.00000000"]],"a":[["15495.04000000","0.00000000"],["15495.66000000","0.00690000"],["15495.81000000","0.00000000"],["15495.82000000","0.50492200"],["15495.86000000","0.07050700"],["15495.90000000","0.00000000"],["15496.06000000","0.00000000"],["15496.77000000","0.00751200"],["15496.93000000","0.78253600"],["15496.95000000","0.00000000"],["15496.96000000","0.00000000"],["15497.10000000","0.00000000"],["15497.35000000","0.00000000"],["15497.71000000","0.00600000"],["15498.17000000","0.00000000"],["15499.65000000","0.25000000"],["15500.73000000","0.03400000"],["15500.84000000","0.30600000"],["15501.07000000","1.74800000"],["15501.77000000","0.00000000"],["15504.91000000","0.00000000"]]}}
2020-11-09T11:26:36.74793 btcusdt {"stream":"btcusdt@depth@100ms","data":{"e":"depthUpdate","E":1604921196735,"s":"BTCUSDT","U":6511139598,"u":6511139645,"b":[["15495.65000000","1.39470200"],["15495.64000000","0.00000000"],["15495.03000000","0.02998400"],["15494.44000000","0.03083000"],["15491.92000000","0.12905200"],["15491.67000000","0.00000000"],["15491.40000000","0.00000000"],["15490.01000000","0.22125400"],["15488.09000000","0.00000000"],["15486.34000000","0.00000000"],["15486.19000000","1.25000000"],["15476.55000000","0.32700000"]],"a":[["15495.66000000","0.00000000"],["15495.81000000","0.00000000"],["15495.82000000","0.40037600"],["15495.86000000","0.00000000"],["15496.31000000","0.07050700"],["15496.92000000","0.46736500"],["15496.93000000","0.00000000"],["15497.09000000","0.10000000"],["15497.18000000","1.10037700"],["15498.07000000","0.00000000"],["15499.30000000","0.00000000"],["15499.65000000","0.00000000"],["15500.51000000","0.12907000"],["15500.76000000","0.75000000"],["15501.67000000","1.19800000"],["15504.33000000","0.20000000"],["15509.81000000","0.00000000"],["15515.03000000","0.00000000"],["15597.00000000","1.59058200"],["15606.42000000","0.00320400"]]}}
2020-11-09T11:26:36.84358 btcusdt {"stream":"btcusdt@depth@100ms","data":{"e":"depthUpdate","E":1604921196835,"s":"BTCUSDT","U":6511139646,"u":6511139673,"b":[["15495.81000000","0.81500000"],["15495.73000000","0.00690000"],["15495.65000000","0.00000000"],["15492.43000000","0.00000000"],["15492.29000000","0.00000000"],["15491.64000000","0.11427900"],["15491.07000000","0.00000000"],["15490.10000000","0.72837400"],["15490.01000000","0.11534400"],["15489.69000000","0.25000100"],["15489.19000000","0.50197300"],["15488.99000000","0.90407400"],["15488.89000000","1.50600000"],["15488.23000000","0.58583500"],["15486.85000000","0.32662400"],["15486.84000000","0.50474600"],["15486.27000000","0.87826800"],["15486.20000000","0.00000000"],["15405.51000000","0.00000000"]],"a":[["15495.82000000","0.40727600"],["15496.31000000","0.00000000"],["15496.92000000","0.00000000"],["15497.18000000","0.00000000"],["15500.43000000","0.11427900"],["15586.49000000","0.00000000"]]}}
2020-11-09T11:26:36.94799 btcusdt {"stream":"btcusdt@depth@100ms","data":{"e":"depthUpdate","E":1604921196935,"s":"BTCUSDT","U":6511139674,"u":6511139692,"b":[["15495.81000000","5.53373300"],["15494.13000000","0.12000000"],["15493.65000000","0.12000000"],["15493.63000000","0.00000000"],["15490.01000000","0.22125400"],["15488.23000000","0.00000000"],["15486.27000000","0.00000000"],["15419.70000000","0.00000000"]],"a":[["15495.82000000","0.02112500"],["15496.94000000","0.00000000"],["15497.09000000","0.00000000"],["15497.18000000","0.78253600"],["15498.99000000","0.00000000"],["15499.75000000","0.45219400"],["15501.66000000","0.00000000"]]}}
2020-11-09T11:26:37.04538 btcusdt {"stream":"btcusdt@depth@100ms","data":{"e":"depthUpdate","E":1604921197035,"s":"BTCUSDT","U":6511139693,"u":6511139761,"b":[["15496.76000000","5.55918600"],["15496.74000000","0.00000000"],["15496.62000000","0.00000000"],["15496.59000000","0.00000000"],["15496.29000000","0.00690000"],["15496.02000000","0.00000000"],["15495.91000000","0.03083000"],["15495.82000000","0.03268400"],["15495.81000000","0.53513300"],["15495.46000000","0.00000000"],["15495.37000000","0.00000000"],["15494.44000000","0.00000000"],["15492.72000000","1.25000000"],["15492.10000000","0.00000000"],["15491.93000000","0.09859100"],["15490.13000000","1.05670300"],["15490.11000000","0.00000000"],["15490.10000000","0.00000000"],["15490.01000000","0.17344800"],["15489.69000000","0.00000000"],["15489.19000000","0.00000000"],["15488.99000000","0.00000000"],["15488.61000000","0.00000000"],["15486.19000000","0.00000000"],["15452.41000000","0.00000000"]],"a":[["15495.82000000","0.00000000"],["15496.77000000","0.01441200"],["15497.18000000","0.00000000"],["15497.20000000","0.00707000"],["15497.36000000","0.00690000"],["15497.39000000","0.00000000"],["15497.52000000","0.02874700"],["15499.75000000","0.15219400"],["15499.76000000","0.00000000"],["15500.51000000","0.00000000"],["15500.63000000","0.05000000"],["15500.75000000","0.10000000"],["15500.76000000","0.00000000"],["15501.00000000","0.00000000"],["15501.71000000","0.00000000"],["15502.50000000","0.75000000"],["15502.97000000","0.00000000"],["15502.98000000","0.00000000"],["15512.94000000","0.00000000"],["15516.45000000","0.00000000"]]}}
2020-11-09T11:26:37.14638 btcusdt {"stream":"btcusdt@depth@100ms","data":{"e":"depthUpdate","E":1604921197135,"s":"BTCUSDT","U":6511139762,"u":6511139820,"b":[["15497.18000000","1.69102500"],["15496.97000000","0.00690000"],["15496.88000000","0.03083000"],["15496.78000000","0.00000000"],["15496.76000000","0.45115300"],["15496.67000000","0.00000000"],["15495.91000000","0.00000000"],["15495.81000000","0.08398000"],["15492.72000000","0.00000000"],["15492.60000000","0.00000000"],["15492.33000000","0.01974100"],["15489.14000000","0.00000000"],["15487.55000000","0.29700000"],["15486.85000000","0.00000000"],["15486.48000000","1.00949200"],["15486.31000000","0.00309000"],["15485.84000000","0.00000000"],["15458.00000000","0.00000000"]],"a":[["15496.77000000","0.00000000"],["15497.19000000","0.01446400"],["15498.48000000","0.00000000"],["15499.75000000","0.00000000"],["15500.43000000","0.00000000"],["15500.63000000","0.00000000"],["15500.75000000","0.00000000"],["15500.84000000","0.00000000"],["15501.25000000","0.05000000"],["15501.38000000","0.01000000"],["15501.59000000","0.04523600"],["15501.66000000","0.15219400"],["15501.67000000","0.00000000"],["15501.84000000","0.00000000"],["15502.25000000","1.20490000"],["15502.44000000","0.10000000"],["15502.50000000","0.00000000"],["15503.05000000","0.00000000"],["15503.18000000","0.01000000"],["15503.64000000","0.00000000"],["15504.12000000","0.75000000"],["15510.43000000","0.00000000"],["15514.28000000","0.25787000"],["15514.41000000","0.00000000"],["15514.55000000","1.06717000"]]}}
2020-11-09T11:26:37.24811 btcusdt {"stream":"btcusdt@depth@100ms","data":{"e":"depthUpdate","E":1604921197235,"s":"BTCUSDT","U":6511139821,"u":6511139893,"b":[["15497.35000000","9.51596500"],["15497.28000000","0.00690000"],["15497.21000000","0.05513900"],["15497.20000000","5.32197600"],["15497.19000000","0.00000000"],["15497.18000000","0.45115300"],["15497.03000000","0.03083000"],["15496.92000000","0.00000000"],["15496.88000000","0.00000000"],["15496.76000000","0.00000000"],["15495.92000000","0.15000000"],["15495.81000000","0.00000000"],["15492.12000000","0.00000000"],["15492.00000000","0.00904100"],["15491.64000000","0.00000000"],["15490.13000000","0.00000000"],["15489.69000000","0.00000000"],["15489.19000000","0.00000000"],["15489.02000000","0.00000000"],["15488.99000000","0.00000000"],["15488.61000000","1.25000000"],["15477.76000000","0.28800000"],["15458.90000000","0.00000000"]],"a":[["15497.19000000","0.00000000"],["15497.20000000","0.00000000"],["15497.36000000","0.01380000"],["15500.73000000","0.00000000"],["15501.07000000","0.00000000"],["15501.21000000","0.00000000"],["15501.25000000","0.00000000"],["15501.40000000","0.01700000"],["15501.41000000","0.01700000"],["15501.66000000","0.00000000"],["15501.67000000","0.05000000"],["15501.75000000","1.74800000"],["15502.02000000","0.04000000"],["15502.44000000","0.00000000"],["15502.76000000","0.00000000"],["15502.78000000","0.00000000"],["15503.26000000","0.00000000"],["15503.57000000","0.06000000"],["15503.70000000","0.25219400"],["15503.94000000","0.08000000"],["15504.06000000","0.04000000"],["15505.05000000","0.00000000"],["15505.12000000","0.81800000"],["15505.98000000","0.00000000"],["15507.25000000","1.25000000"],["15508.03000000","0.00000000"],["15509.41000000","0.00000000"],["15510.07000000","1.00949200"],["15512.22000000","0.00000000"],["15512.63000000","1.00000000"],["15532.70000000","0.00200000"],["15545.69000000","0.00000000"]]}}
2020-11-09T11:26:37.34385 btcusdt {"stream":"btcusdt@depth@100ms","data":{"e":"depthUpdate","E":1604921197336,"s":"BTCUSDT","U":6511139894,"u":6511139940,"b":[["15497.99000000","1.48491700"],["15497.67000000","0.00690000"],["15497.52000000","0.03083000"],["15497.40000000","0.00000000"],["15497.36000000","5.30627500"],["15497.35000000","0.50612900"],["15497.21000000","0.00000000"],["15497.20000000","5.32197600"],["15497.18000000","0.00000000"],["15497.03000000","0.00000000"],["15495.92000000","0.00000000"],["15494.14000000","0.04780600"],["15493.66000000","0.08000000"],["15492.00000000","0.00000000"],["15491.93000000","0.05078500"],["15460.07000000","0.03100000"],["15387.00000000","0.37683000"]],"a":[["15497.36000000","0.00000000"],["15497.51000000","0.00000000"],["15497.52000000","0.00000000"],["15497.62000000","0.00000000"],["15497.71000000","0.00000000"],["15497.90000000","0.00000000"],["15498.00000000","0.00935900"],["15500.52000000","0.00000000"],["15501.93000000","0.00000000"],["15502.25000000","0.00690000"],["15502.84000000","1.19800000"],["15503.18000000","0.00000000"],["15503.60000000","0.01000000"],["15503.93000000","0.12905400"],["15505.12000000","0.31800000"],["15505.20000000","0.50200000"],["15506.15000000","0.00000000"],["15506.61000000","0.00000000"],["15507.35000000","0.00000000"],["15507.82000000","0.30134700"],["15507.86000000","0.00000000"],["15527.26000000","0.03000000"],["15546.86000000","0.03100000"]]}}
2020-11-09T11:26:37.45514 btcusdt {"stream":"btcusdt@depth@100ms","data":{"e":"depthUpdate","E":1604921197436,"s":"BTCUSDT","U":6511139941,"u":6511139972,"b":[["15497.99000000","1.82342800"],["15497.36000000","5.45627500"],["15497.35000000","0.05497600"],["15493.77000000","0.02106400"],["15492.43000000","0.05000000"],["15491.93000000","0.00078500"],["15488.62000000","0.00000000"],["15485.44000000","0.00000000"],["15452.11000000","0.03020000"],["15420.50000000","0.00648400"],["15405.00000000","1.01979200"]],"a":[["15498.00000000","2.00935900"],["15501.38000000","0.00000000"],["15501.40000000","0.00000000"],["15501.41000000","0.00000000"],["15501.67000000","0.00000000"],["15501.75000000","0.00000000"],["15502.21000000","0.03400000"],["15502.44000000","0.15219400"],["15502.56000000","1.74800000"],["15502.61000000","0.01000000"],["15503.60000000","0.00000000"],["15503.70000000","0.10000000"],["15504.04000000","0.00000000"],["15504.21000000","0.00000000"],["15504.41000000","0.01000000"],["15504.81000000","0.01500000"],["15506.01000000","0.00000000"],["15532.70000000","0.00000000"]]}}
2020-11-09T11:26:37.54780 btcusdt {"stream":"btcusdt@depth@100ms","data":{"e":"depthUpdate","E":1604921197536,"s":"BTCUSDT","U":6511139973,"u":6511139984,"b":[["15497.52000000","0.00000000"],["15497.36000000","5.30627500"],["15491.56000000","0.48381200"],["15488.00000000","1.50000000"],["15381.00000000","0.10827300"]],"a":[["15498.00000000","2.00080600"],["15501.14000000","0.08000000"],["15502.48000000","0.05000000"],["15508.89000000","0.05681900"],["15510.39000000","0.00000000"],["15527.26000000","0.00000000"]]}}
2020-11-09T11:26:37.64421 btcusdt {"stream":"btcusdt@depth@100ms","data":{"e":"depthUpdate","E":1604921197636,"s":"BTCUSDT","U":6511139985,"u":6511140000,"b":[["15497.99000000","1.92933800"],["15497.36000000","0.00627500"],["15492.33000000","0.00000000"],["15491.67000000","0.25241200"],["15491.40000000","0.20000000"],["15490.10000000","0.70447100"],["15490.01000000","0.06753800"]],"a":[["15498.00000000","2.00880600"],["15502.44000000","0.00000000"],["15503.56000000","0.15219400"],["15505.20000000","0.00200000"],["15505.27000000","1.25000000"],["15507.25000000","0.00000000"]]}}
2020-11-09T11:26:37.74294 btcusdt {"stream":"btcusdt@depth@100ms","data":{"e":"depthUpdate","E":1604921197736,"s":"BTCUSDT","U":6511140001,"u":6511140007,"b":[["15497.99000000","1.78491000"],["15455.00000000","2.33297000"]],"a":[["15498.00000000","2.01680600"],["15505.28000000","0.50000000"],["15526.81000000","0.00000000"],["15544.82000000","0.00000000"]]}}
2020-11-09T11:26:37.84200 btcusdt {"stream":"btcusdt@depth@100ms","data":{"e":"depthUpdate","E":1604921197836,"s":"BTCUSDT","U":6511140008,"u":6511140024,"b":[["15497.99000000","1.78691000"],["15491.67000000","0.00000000"],["15491.56000000","0.00000000"],["15489.10000000","0.48828600"],["15488.87000000","0.06724100"],["15488.76000000","0.13448200"],["15451.41000000","0.00202900"],["15403.97000000","0.24000000"],["15202.97000000","0.00065800"]],"a":[["15498.00000000","2.01880600"],["15502.01000000","0.15219400"],["15502.44000000","0.10000000"],["15503.56000000","0.00000000"],["15503.70000000","0.00000000"],["15508.51000000","0.06724100"],["15511.75000000","0.24000000"],["15541.29000000","0.00202900"]]}}
2020-11-09T11:26:37.94481 btcusdt {"stream":"btcusdt@depth@100ms","data":{"e":"depthUpdate","E":1604921197936,"s":"BTCUSDT","U":6511140025,"u":6511140045,"b":[["15497.51000000","0.04230000"],["15494.14000000","0.04780600"],["15494.13000000","0.00000000"],["15493.66000000","0.00000000"],["15493.65000000","0.00000000"],["15492.87000000","0.00400000"],["15492.59000000","0.04000000"],["15491.93000000","0.20078500"],["15491.76000000","0.56000000"],["15491.33000000","0.32000000"],["15450.39000000","0.01553300"]],"a":[["15498.00000000","0.02200000"],["15504.73000000","0.00000000"],["15505.27000000","0.00000000"],["15506.26000000","1.25000000"]]}}
2020-11-09T11:26:38.04373 btcusdt {"stream":"btcusdt@depth@100ms","data":{"e":"depthUpdate","E":1604921198036,"s":"BTCUSDT","U":6511140046,"u":6511140080,"b":[["15498.77000000","1.00000000"],["15498.49000000","0.00690000"],["15498.03000000","0.49967800"],["15498.02000000","0.48714000"],["15498.01000000","0.48714000"],["15497.99000000","0.58781000"],["15497.55000000","0.04230000"],["15497.51000000","0.00000000"],["15497.35000000","0.00000000"],["15494.14000000","0.59380600"],["15493.66000000","0.97000000"],["15492.90000000","1.12000000"],["15492.59000000","0.00000000"],["15491.93000000","0.00078500"],["15491.76000000","0.00000000"],["15491.33000000","0.00000000"],["15404.58000000","0.24000000"],["15403.97000000","0.00000000"]],"a":[["15498.00000000","0.00000000"],["15498.78000000","5.30690000"],["15498.93000000","0.00000000"],["15499.00000000","0.77402200"],["15499.42000000","0.00000000"],["15502.21000000","0.00000000"],["15502.45000000","0.00000000"],["15502.58000000","0.00000000"],["15502.70000000","0.01700000"],["15502.71000000","0.01700000"],["15503.18000000","0.15700000"],["15503.33000000","0.29200000"],["15504.09000000","0.20000000"],["15529.36000000","0.72475900"],["15533.78000000","0.01210000"]]}}
2020-11-09T11:26:38.15010 btcusdt {"stream":"btcusdt@depth@100ms","data":{"e":"depthUpdate","E":1604921198136,"s":"BTCUSDT","U":6511140081,"u":6511140104,"b":[["15498.77000000","0.57620900"],["15498.03000000","0.00000000"],["15498.02000000","0.00000000"],["15498.01000000","0.00000000"],["15497.99000000","0.13665700"],["15492.91000000","0.05000000"],["15492.43000000","0.00000000"]],"a":[["15498.78000000","8.37436000"],["15502.48000000","0.00000000"],["15502.61000000","0.00000000"],["15503.26000000","0.05000000"],["15503.39000000","0.01000000"],["15504.41000000","0.00000000"],["15504.81000000","0.00000000"],["15505.19000000","0.09000000"],["15505.59000000","0.01500000"],["15506.26000000","0.00000000"],["15506.27000000","0.00000000"],["15506.49000000","1.25000000"],["15512.63000000","0.00000000"]]}}
2020-11-09T11:26:38.24672 btcusdt {"stream":"btcusdt@depth@100ms","data":{"e":"depthUpdate","E":1604921198236,"s":"BTCUSDT","U":6511140105,"u":6511140119,"b":[["15497.80000000","0.00200000"],["15497.20000000","0.00000000"],["15494.15000000","0.42050400"],["15493.78000000","0.49653400"],["15492.92000000","0.62700000"],["15492.35000000","0.00000000"],["15491.67000000","0.10846000"],["15488.65000000","0.00200000"]],"a":[["15498.78000000","8.43833000"],["15503.32000000","0.12905500"],["15506.17000000","0.30000000"],["15510.03000000","0.00000000"],["15512.67000000","0.50000000"],["15555.00000000","3.56809700"],["15597.00000000","1.21375200"]]}}
2020-11-09T11:26:38.34421 btcusdt {"stream":"btcusdt@depth@100ms","data":{"e":"depthUpdate","E":1604921198336,"s":"BTCUSDT","U":6511140120,"u":6511140129,"b":[["15497.99000000","0.03074700"],["15495.83000000","0.10591000"],["15491.67000000","0.00000000"],["15488.65000000","0.00400000"],["15463.30000000","0.00200000"],["15420.50000000","0.00000000"],["15381.00000000","0.48510300"]],"a":[["15500.00000000","0.25000000"],["15500.52000000","0.15219400"],["15502.01000000","0.00000000"]]}}
2020-11-09T11:26:38.44470 btcusdt {"stream":"btcusdt@depth@100ms","data":{"e":"depthUpdate","E":1604921198436,"s":"BTCUSDT","U":6511140130,"u":6511140161,"b":[["15494.15000000","0.00000000"],["15494.14000000","0.00000000"],["15493.78000000","0.00000000"],["15493.66000000","0.00000000"],["15492.94000000","0.00853500"],["15492.93000000","0.04780600"],["15492.92000000","0.00000000"],["15492.91000000","0.05000000"],["15492.90000000","0.00000000"],["15492.88000000","0.00000000"],["15492.55000000","0.01840300"],["15492.11000000","0.02000000"],["15491.41000000","0.27596400"],["15491.35000000","0.24000000"],["15489.99000000","0.00200000"],["15489.69000000","0.25000100"],["15488.90000000","1.00386100"],["15463.30000000","0.00400000"]],"a":[["15499.85000000","0.04000000"],["15499.99000000","0.08000000"],["15500.00000000","0.30175500"],["15501.40000000","0.04000000"],["15501.88000000","0.04000000"],["15501.97000000","0.24000000"],["15502.02000000","0.00000000"],["15503.57000000","0.00000000"],["15503.94000000","0.00000000"],["15504.06000000","0.00000000"]]}}
2020-11-09T11:26:38.54511 btcusdt {"stream":"btcusdt@depth@100ms","data":{"e":"depthUpdate","E":1604921198536,"s":"BTCUSDT","U":6511140162,"u":6511140191,"b":[["15498.77000000","0.38545200"],["15494.06000000","0.01773800"],["15493.90000000","0.00985200"],["15493.66000000","0.28000000"],["15492.94000000","0.00000000"],["15492.91000000","0.29000000"],["15492.55000000","0.00000000"],["15492.43000000","0.16000000"],["15492.11000000","0.00000000"],["15491.35000000","0.00000000"]],"a":[["15498.99000000","0.08000000"],["15499.85000000","0.00000000"],["15499.99000000","0.00000000"],["15500.51000000","0.10000000"],["15501.40000000","0.00000000"],["15501.62000000","0.03400000"],["15501.68000000","0.04000000"],["15501.88000000","0.00000000"],["15501.96000000","1.74800000"],["15501.97000000","0.00000000"],["15502.44000000","0.00000000"],["15502.56000000","0.00000000"],["15502.70000000","0.00000000"],["15502.71000000","0.00000000"],["15502.77000000","0.02000000"],["15503.23000000","0.08000000"],["15503.72000000","0.04000000"],["15506.69000000","0.00000000"],["15555.00000000","3.94492700"]]}}
2020-11-09T11:26:38.64368 btcusdt {"stream":"btcusdt@depth@100ms","data":{"e":"depthUpdate","E":1604921198636,"s":"BTCUSDT","U":6511140192,"u":6511140197,"b":[["15498.77000000","0.37851000"],["15495.03000000","0.02712900"]],"a":[["15498.99000000","0.00000000"],["15506.48000000","0.01934700"],["15513.27000000","0.00000000"],["15514.11000000","1.00000000"]]}}
2020-11-09T11:26:38.74377 btcusdt {"stream":"btcusdt@depth@100ms","data":{"e":"depthUpdate","E":1604921198736,"s":"BTCUSDT","U":6511140198,"u":6511140207,"b":[["15495.03000000","0.00000000"],["15494.57000000","0.01810100"],["15494.06000000","0.00000000"],["15480.29000000","0.00201000"]],"a":[["15498.78000000","8.37832500"],["15498.88000000","0.01421600"],["15503.70000000","0.20000000"],["15506.17000000","0.00000000"],["15511.29000000","0.00201000"],["15529.92000000","0.11189800"]]}}
2020-11-09T11:26:38.84425 btcusdt {"stream":"btcusdt@depth@100ms","data":{"e":"depthUpdate","E":1604921198836,"s":"BTCUSDT","U":6511140208,"u":6511140216,"b":[["15495.83000000","0.00000000"],["15494.58000000","0.10591000"],["15490.87000000","0.43568100"],["15490.81000000","0.47185100"],["15486.84000000","0.00000000"],["15484.61000000","0.06724100"],["15484.60000000","0.00000000"],["15244.08000000","0.00000000"],["15188.79000000","0.00174700"]],"a":[]}}
2020-11-09T11:26:38.94415 btcusdt {"stream":"btcusdt@depth@100ms","data":{"e":"depthUpdate","E":1604921198936,"s":"BTCUSDT","U":6511140217,"u":6511140228,"b":[["15494.57000000","0.00000000"],["15494.03000000","0.01803900"],["15493.90000000","0.00000000"],["15490.87000000","0.00000000"],["15490.81000000","0.00000000"],["15490.11000000","0.02236400"],["15487.86000000","0.00000000"],["15485.86000000","0.00000000"],["15485.45000000","0.00000000"],["15421.27000000","0.00648400"],["15381.00000000","0.37683000"]],"a":[["15498.88000000","0.00000000"]]}}
2020-11-09T11:26:39.04380 btcusdt {"stream":"btcusdt@depth@100ms","data":{"e":"depthUpdate","E":1604921199036,"s":"BTCUSDT","U":6511140229,"u":6511140253,"b":[["15498.77000000","0.00000000"],["15497.55000000","0.00000000"],["15495.82000000","0.00000000"],["15494.65000000","0.00873100"],["15494.58000000","0.00000000"],["15492.94000000","0.10591000"],["15492.92000000","0.05000000"],["15492.91000000","0.24000000"],["15479.80000000","0.05000000"]],"a":[["15498.50000000","6.06490100"],["15498.73000000","0.01247500"],["15498.77000000","5.30000000"],["15498.78000000","2.63143000"],["15498.98000000","0.00000000"],["15499.02000000","0.00756900"],["15499.75000000","0.20000000"],["15520.80000000","0.01214900"]]}}
2020-11-09T11:26:39.14527 btcusdt {"stream":"btcusdt@depth@100ms","data":{"e":"depthUpdate","E":1604921199137,"s":"BTCUSDT","U":6511140254,"u":6511140285,"b":[["15498.49000000","0.00890000"],["15493.77000000","0.00000000"],["15490.31000000","0.02106400"],["15488.22000000","0.00000000"],["15480.93000000","0.23535300"],["15387.00000000","0.48510300"]],"a":[["15498.50000000","8.30876100"],["15498.78000000","2.06397000"],["15499.99000000","0.08000000"],["15501.59000000","0.04523600"],["15501.60000000","0.00000000"],["15501.62000000","0.00000000"],["15501.85000000","0.00000000"],["15501.96000000","0.00000000"],["15502.20000000","0.01700000"],["15502.36000000","0.00000000"],["15502.54000000","0.00000000"],["15502.84000000","0.00000000"],["15503.59000000","0.00000000"],["15504.30000000","0.30900000"]]}}
2020-11-09T11:26:39.24312 btcusdt {"stream":"btcusdt@depth@100ms","data":{"e":"depthUpdate","E":1604921199237,"s":"BTCUSDT","U":6511140286,"u":6511140302,"b":[["15493.66000000","0.00000000"],["15492.91000000","0.00000000"],["15492.47000000","0.02000000"],["15491.34000000","0.48000000"],["15452.12000000","0.16179000"],["15444.91000000","0.00000000"]],"a":[["15498.50000000","8.56095500"],["15500.51000000","0.00000000"],["15500.52000000","0.00000000"],["15501.51000000","0.01700000"],["15501.52000000","0.01700000"],["15501.85000000","1.74800000"],["15502.20000000","0.00000000"],["15502.81000000","1.19800000"],["15511.11000000","0.00065800"],["15514.05000000","1.50000000"]]}}
2020-11-09T11:26:39.34406 btcusdt {"stream":"btcusdt@depth@100ms","data":{"e":"depthUpdate","E":1604921199337,"s":"BTCUSDT","U":6511140303,"u":6511140317,"b":[["15494.86000000","0.01867800"],["15494.03000000","0.00000000"],["15493.73000000","0.50000000"],["15492.93000000","0.00000000"],["15492.90000000","0.11427900"],["15491.67000000","0.04780600"]],"a":[["15499.02000000","0.00000000"],["15499.24000000","0.00861300"],["15499.55000000","0.01333600"],["15500.00000000","0.30777300"],["15502.23000000","0.11427900"],["15503.26000000","0.37100000"],["15522.48000000","0.00000000"],["15558.00000000","2.11115200"],["15600.00000000","211.57737500"]]}}
2020-11-09T11:26:39.44351 btcusdt {"stream":"btcusdt@depth@100ms","data":{"e":"depthUpdate","E":1604921199437,"s":"BTCUSDT","U":6511140318,"u":6511140325,"b":[["15493.77000000","0.25100200"],["15491.40000000","0.00000000"],["15421.27000000","0.00000000"]],"a":[["15499.14000000","0.08200000"],["15499.90000000","0.50000000"],["15502.09000000","0.50000000"],["15505.28000000","0.00000000"],["15511.41000000","0.12125000"]]}}
2020-11-09T11:26:39.54416 btcusdt {"stream":"btcusdt@depth@100ms","data":{"e":"depthUpdate","E":1604921199537,"s":"BTCUSDT","U":6511140326,"u":6511140362,"b":[["15498.49000000","0.00000000"],["15497.99000000","0.03764700"],["15493.77000000","0.00000000"],["15491.41000000","0.00000000"],["15490.10000000","0.00000000"],["15489.69000000","0.00000000"],["15489.10000000","0.00000000"],["15488.90000000","0.00000000"],["15488.61000000","0.00000000"],["15487.53000000","1.25000000"]],"a":[["15498.00000000","11.75555200"],["15498.25000000","0.00690000"],["15498.42000000","0.00904600"],["15498.43000000","0.00929000"],["15498.49000000","0.78253600"],["15498.50000000","8.00191800"],["15498.72000000","0.13500000"],["15498.73000000","0.00000000"],["15498.77000000","0.00000000"],["15498.78000000","2.00000000"],["15499.75000000","0.00000000"],["15499.90000000","0.00000000"],["15502.09000000","0.00000000"],["15502.28000000","1.19800000"],["15502.81000000","0.00000000"],["15503.38000000","0.50000000"],["15561.00000000","0.26473100"]]}}
2020-11-09T11:26:39.64422 btcusdt {"stream":"btcusdt@depth@100ms","data":{"e":"depthUpdate","E":1604921199637,"s":"BTCUSDT","U":6511140363,"u":6511140389,"b":[["15492.94000000","0.00000000"],["15492.92000000","0.00000000"],["15492.32000000","0.05000000"],["15491.67000000","0.00000000"],["15491.40000000","0.10591000"],["15490.12000000","0.04780600"],["15458.77000000","0.25000000"]],"a":[["15498.00000000","14.19108300"],["15498.24000000","0.13500000"],["15498.50000000","7.88605800"],["15499.55000000","0.00000000"],["15501.69000000","0.30600000"],["15502.47000000","0.05000000"],["15502.60000000","0.01000000"],["15503.26000000","0.00000000"],["15503.36000000","0.50000000"],["15503.38000000","0.00000000"],["15503.39000000","0.00000000"],["15504.40000000","0.01000000"],["15504.80000000","0.01500000"],["15505.19000000","0.08000000"],["15505.59000000","0.00000000"],["15505.61000000","0.00309000"],["15536.26000000","0.25068000"],["15539.62000000","0.00252900"]]}}
2020-11-09T11:26:39.74534 btcusdt {"stream":"btcusdt@depth@100ms","data":{"e":"depthUpdate","E":1604921199737,"s":"BTCUSDT","U":6511140390,"u":6511140408,"b":[["15497.99000000","0.03964700"],["15492.90000000","0.00000000"],["15492.10000000","0.11427900"],["14250.00000000","37.58873500"]],"a":[["15498.00000000","11.47203500"],["15498.49000000","0.00000000"],["15498.69000000","0.00200000"],["15499.14000000","0.00200000"],["15500.12000000","0.28000000"],["15501.65000000","0.11427900"],["15501.66000000","0.24000000"],["15501.68000000","0.00000000"],["15502.15000000","0.28000000"],["15502.23000000","0.00000000"],["15502.76000000","0.32200000"],["15503.23000000","0.00000000"],["15503.72000000","0.00000000"],["15555.00000000","3.56809700"]]}}
2020-11-09T11:26:39.84341 btcusdt {"stream":"btcusdt@depth@100ms","data":{"e":"depthUpdate","E":1604921199837,"s":"BTCUSDT","U":6511140409,"u":6511140425,"b":[["15497.99000000","0.03764700"],["15420.50000000","0.00648400"]],"a":[["15498.00000000","8.72926300"],["15498.72000000","0.00000000"],["15500.12000000","0.00000000"],["15501.62000000","0.04000000"],["15501.66000000","0.00000000"],["15502.15000000","0.00000000"],["15503.36000000","0.00000000"],["15503.50000000","0.00000000"],["15503.56000000","0.16000000"],["15503.66000000","0.04000000"],["15503.84000000","0.00000000"]]}}
2020-11-09T11:26:39.94360 btcusdt {"stream":"btcusdt@depth@100ms","data":{"e":"depthUpdate","E":1604921199937,"s":"BTCUSDT","U":6511140426,"u":6511140431,"b":[["15497.99000000","0.03666800"],["15494.86000000","0.00000000"],["15490.07000000","0.40703900"],["13900.00000000","32.99116600"]],"a":[["15499.99000000","0.00000000"],["15504.45000000","0.50200000"]]}}
2020-11-09T11:26:40.04520 btcusdt {"stream":"btcusdt@depth@100ms","data":{"e":"depthUpdate","E":1604921200037,"s":"BTCUSDT","U":6511140432,"u":6511140442,"b":[["15494.65000000","0.00000000"],["15492.70000000","0.00956400"],["15492.32000000","0.00000000"],["15492.10000000","0.16427900"],["12468.00000000","6.15430700"]],"a":[["15498.00000000","8.72610400"],["15498.46000000","0.00736000"],["15498.62000000","0.00082200"],["15499.24000000","0.00000000"],["15582.50000000","0.00000000"]]}}
2020-11-09T11:26:40.14504 btcusdt {"stream":"btcusdt@depth@100ms","data":{"e":"depthUpdate","E":1604921200137,"s":"BTCUSDT","U":6511140443,"u":6511140448,"b":[["15491.41000000","0.04780600"],["15490.12000000","0.00000000"],["15488.21000000","0.20000000"]],"a":[["15500.20000000","0.08200000"],["15558.00000000","2.00287900"],["15564.00000000","0.10827300"]]}}
2020-11-09T11:26:40.24343 btcusdt {"stream":"btcusdt@depth@100ms","data":{"e":"depthUpdate","E":1604921200237,"s":"BTCUSDT","U":6511140449,"u":6511140452,"b":[["15492.62000000","0.11427900"],["15492.10000000","0.05000000"],["15244.08000000","0.00590300"]],"a":[["15512.36000000","0.00000000"]]}}
2020-11-09T11:26:40.34346 btcusdt {"stream":"btcusdt@depth@100ms","data":{"e":"depthUpdate","E":1604921200337,"s":"BTCUSDT","U":6511140453,"u":6511140456,"b":[["15497.99000000","0.00890000"],["15488.21000000","0.00000000"],["15420.62000000","0.00000000"],["15381.00000000","0.00000000"]],"a":[]}}
2020-11-09T11:26:40.44554 btcusdt {"stream":"btcusdt@depth@100ms","data":{"e":"depthUpdate","E":1604921200437,"s":"BTCUSDT","U":6511140457,"u":6511140459,"b":[["15492.42000000","0.11443000"]],"a":[["15498.77000000","0.01306600"],["15502.27000000","0.00284300"]]}}
2020-11-09T11:26:40.55653 btcusdt {"stream":"btcusdt@depth@100ms","data":{"e":"depthUpdate","E":1604921200537,"s":"BTCUSDT","U":6511140460,"u":6511140468,"b":[["15497.36000000","0.00000000"],["15493.35000000","0.00674200"],["15492.70000000","0.00000000"],["15405.00000000","1.39662200"]],"a":[["15498.00000000","8.66570000"],["15498.46000000","0.00958800"],["15503.32000000","0.00000000"],["15505.45000000","0.30000000"]]}}
2020-11-09T11:26:40.64904 btcusdt {"stream":"btcusdt@depth@100ms","data":{"e":"depthUpdate","E":1604921200637,"s":"BTCUSDT","U":6511140469,"u":6511140469,"b":[["15420.20000000","0.00164000"]],"a":[]}}
2020-11-09T11:26:40.74780 btcusdt {"stream":"btcusdt@depth@100ms","data":{"e":"depthUpdate","E":1604921200737,"s":"BTCUSDT","U":6511140470,"u":6511140477,"b":[["15493.35000000","0.01821500"],["15492.98000000","0.00981800"],["15492.42000000","0.10000000"],["15404.58000000","0.00000000"]],"a":[["15498.46000000","0.00854500"],["15597.00000000","1.59058200"]]}}
2020-11-09T11:26:40.85188 btcusdt {"stream":"btcusdt@depth@100ms","data":{"e":"depthUpdate","E":1604921200837,"s":"BTCUSDT","U":6511140478,"u":6511140479,"b":[["15490.07000000","0.00000000"]],"a":[["15558.00000000","2.11115200"]]}}
2020-11-09T11:26:40.94709 btcusdt {"stream":"btcusdt@depth@100ms","data":{"e":"depthUpdate","E":1604921200937,"s":"BTCUSDT","U":6511140480,"u":6511140486,"b":[["15493.35000000","0.00000000"],["15493.05000000","0.01508800"],["15492.98000000","0.00000000"],["15492.04000000","0.00751000"]],"a":[["15498.00000000","8.66386100"],["15498.46000000","0.00000000"],["15498.62000000","0.00164500"]]}}
2020-11-09T11:26:41.04602 btcusdt {"stream":"btcusdt@depth@100ms","data":{"e":"depthUpdate","E":1604921201037,"s":"BTCUSDT","U":6511140487,"u":6511140487,"b":[],"a":[["15498.46000000","0.00800300"]]}}
2020-11-09T11:26:41.14555 btcusdt {"stream":"btcusdt@depth@100ms","data":{"e":"depthUpdate","E":1604921201137,"s":"BTCUSDT","U":6511140488,"u":6511140492,"b":[["15497.99000000","0.01090000"],["15493.05000000","0.00000000"],["15492.18000000","0.01805400"],["15488.76000000","0.00000000"],["15486.64000000","0.13448100"]],"a":[]}}
2020-11-09T11:26:41.24805 btcusdt {"stream":"btcusdt@depth@100ms","data":{"e":"depthUpdate","E":1604921201238,"s":"BTCUSDT","U":6511140493,"u":6511140498,"b":[],"a":[["15502.27000000","0.13190500"],["15506.40000000","0.10000000"],["15510.08000000","0.50000000"],["15510.24000000","0.00000000"],["15512.67000000","0.00000000"],["15533.31000000","1.33842900"]]}}
2020-11-09T11:26:41.34356 btcusdt {"stream":"btcusdt@depth@100ms","data":{"e":"depthUpdate","E":1604921201338,"s":"BTCUSDT","U":6511140499,"u":6511140502,"b":[["15486.81000000","0.50475900"],["15476.02000000","0.21000000"]],"a":[["15498.00000000","8.60366900"],["15498.24000000","0.00000000"]]}}
2020-11-09T11:26:41.44486 btcusdt {"stream":"btcusdt@depth@100ms","data":{"e":"depthUpdate","E":1604921201438,"s":"BTCUSDT","U":6511140503,"u":6511140511,"b":[["15497.99000000","0.01188500"],["15495.17000000","0.01698800"],["15495.08000000","0.00935200"],["15492.18000000","0.00000000"],["15492.04000000","0.00000000"]],"a":[["15498.00000000","8.54866900"],["15498.46000000","0.00981600"],["15502.27000000","0.00284300"]]}}
2020-11-09T11:26:41.54730 btcusdt {"stream":"btcusdt@depth@100ms","data":{"e":"depthUpdate","E":1604921201538,"s":"BTCUSDT","U":6511140512,"u":6511140514,"b":[["15497.99000000","0.01388500"],["15402.00000000","0.31026300"]],"a":[["15498.46000000","0.00000000"]]}}
2020-11-09T11:26:41.64935 btcusdt {"stream":"btcusdt@depth@100ms","data":{"e":"depthUpdate","E":1604921201638,"s":"BTCUSDT","U":6511140515,"u":6511140518,"b":[["15488.21000000","0.20000000"]],"a":[["15498.50000000","7.78605800"],["15499.99000000","0.10000000"],["15540.74000000","0.00065800"]]}}
2020-11-09T11:26:41.74777 btcusdt {"stream":"btcusdt@depth@100ms","data":{"e":"depthUpdate","E":1604921201738,"s":"BTCUSDT","U":6511140519,"u":6511140523,"b":[["15497.99000000","0.01311800"],["15405.00000000","1.01979200"]],"a":[["15498.00000000","8.34774600"],["15502.98000000","0.20000000"]]}}
2020-11-09T11:26:41.84621 btcusdt {"stream":"btcusdt@depth@100ms","data":{"e":"depthUpdate","E":1604921201838,"s":"BTCUSDT","U":6511140524,"u":6511140528,"b":[["15489.32000000","0.38638500"],["15407.31000000","0.24000000"],["14850.00000000","47.62844300"]],"a":[["15498.00000000","8.34186100"],["15498.62000000","0.00246300"]]}}
2020-11-09T11:26:41.94800 btcusdt {"stream":"btcusdt@depth@100ms","data":{"e":"depthUpdate","E":1604921201938,"s":"BTCUSDT","U":6511140529,"u":6511140532,"b":[["15491.40000000","0.00000000"],["15488.21000000","0.00000000"],["15483.03000000","0.00000000"],["15188.79000000","0.00000000"]],"a":[]}}
2020-11-09T11:26:42.04540 btcusdt {"stream":"btcusdt@depth@100ms","data":{"e":"depthUpdate","E":1604921202038,"s":"BTCUSDT","U":6511140533,"u":6511140547,"b":[["15492.63000000","0.10591000"],["15489.32000000","0.00000000"],["15480.65000000","1.08469000"]],"a":[["15498.00000000","8.44186100"],["15499.14000000","0.08200000"],["15499.99000000","0.00000000"],["15500.20000000","0.20200000"],["15501.19000000","0.18000000"],["15501.62000000","0.00000000"],["15501.78000000","0.08200000"],["15502.44000000","0.08000000"],["15502.77000000","0.00000000"],["15503.56000000","0.00000000"],["15503.66000000","0.00000000"],["15508.41000000","0.13448300"]]}}
2020-11-09T11:26:42.14522 btcusdt {"stream":"btcusdt@depth@100ms","data":{"e":"depthUpdate","E":1604921202138,"s":"BTCUSDT","U":6511140548,"u":6511140554,"b":[["15497.99000000","0.01111800"],["15488.21000000","0.20000000"],["15458.77000000","0.00000000"],["15402.00000000","0.68709300"],["15359.88000000","0.00000000"]],"a":[["15499.14000000","0.00200000"],["15536.26000000","0.00068000"]]}}
2020-11-09T11:26:42.24734 btcusdt {"stream":"btcusdt@depth@100ms","data":{"e":"depthUpdate","E":1604921202238,"s":"BTCUSDT","U":6511140555,"u":6511140556,"b":[],"a":[["15502.27000000","0.16417500"],["15502.43000000","0.12905500"]]}}
2020-11-09T11:26:42.34518 btcusdt {"stream":"btcusdt@depth@100ms","data":{"e":"depthUpdate","E":1604921202338,"s":"BTCUSDT","U":6511140557,"u":6511140572,"b":[["15488.21000000","0.00000000"]],"a":[["15498.00000000","3.06665200"],["15498.46000000","0.00726300"],["15498.49000000","0.00000000"],["15498.76000000","0.00000000"],["15500.20000000","0.08200000"],["15501.19000000","0.00000000"],["15501.62000000","0.04000000"],["15501.78000000","0.00200000"],["15502.43000000","0.00000000"],["15502.75000000","0.06000000"],["15502.98000000","0.00000000"],["15503.64000000","0.04000000"]]}}
2020-11-09T11:26:42.44557 btcusdt {"stream":"btcusdt@depth@100ms","data":{"e":"depthUpdate","E":1604921202438,"s":"BTCUSDT","U":6511140573,"u":6511140591,"b":[["15497.99000000","0.86359800"],["15492.92000000","2.00000000"],["15492.62000000","0.00000000"],["15491.34000000","0.00000000"],["15359.57000000","0.00068000"]],"a":[["15498.00000000","2.96665200"],["15498.46000000","0.00000000"],["15499.99000000","0.10000000"],["15500.20000000","0.00200000"],["15501.84000000","0.20000000"],["15502.28000000","0.00000000"],["15502.82000000","1.19800000"],["15505.45000000","0.00000000"],["15514.05000000","0.00000000"],["15561.00000000","0.64156100"]]}}
2020-11-09T11:26:42.54790 btcusdt {"stream":"btcusdt@depth@100ms","data":{"e":"depthUpdate","E":1604921202538,"s":"BTCUSDT","U":6511140592,"u":6511140613,"b":[["15497.99000000","1.23997100"],["15492.92000000","0.00000000"]],"a":[["15498.00000000","7.77149200"],["15498.46000000","0.00865900"],["15501.62000000","0.00000000"],["15501.84000000","0.00000000"],["15502.27000000","0.00000000"],["15502.44000000","0.00000000"],["15502.59000000","0.00000000"],["15502.74000000","0.20000000"],["15502.75000000","0.00000000"],["15503.24000000","0.04000000"],["15503.64000000","0.00000000"],["15504.79000000","0.04000000"],["15505.01000000","0.32100000"],["15505.26000000","0.04000000"],["15514.11000000","0.00000000"]]}}
2020-11-09T11:26:42.64552 btcusdt {"stream":"btcusdt@depth@100ms","data":{"e":"depthUpdate","E":1604921202638,"s":"BTCUSDT","U":6511140614,"u":6511140626,"b":[["15497.99000000","0.83145300"],["15492.92000000","0.24000000"],["15488.21000000","0.20000000"],["15442.00000000","0.74302700"],["15438.91000000","0.00000000"]],"a":[["15498.00000000","8.18001000"],["15498.46000000","0.00782400"],["15512.60000000","1.00000000"],["15513.78000000","1.50000000"],["15577.99000000","0.00000000"]]}}
2020-11-09T11:26:42.74539 btcusdt {"stream":"btcusdt@depth@100ms","data":{"e":"depthUpdate","E":1604921202738,"s":"BTCUSDT","U":6511140627,"u":6511140642,"b":[["15492.92000000","0.00000000"],["15491.89000000","0.08000000"]],"a":[["15498.19000000","0.00400000"],["15498.46000000","0.00859300"],["15499.98000000","0.08000000"],["15501.21000000","0.24000000"],["15502.76000000","0.56200000"],["15503.23000000","0.24000000"],["15503.24000000","0.00000000"],["15504.79000000","0.00000000"],["15505.26000000","0.00000000"],["15506.44000000","0.30000000"]]}}
2020-11-09T11:26:42.84506 btcusdt {"stream":"btcusdt@depth@100ms","data":{"e":"depthUpdate","E":1604921202838,"s":"BTCUSDT","U":6511140643,"u":6511140648,"b":[],"a":[["15498.00000000","2.88001000"],["15498.46000000","0.00817400"],["15578.30000000","0.00067600"]]}}
2020-11-09T11:26:42.94692 btcusdt {"stream":"btcusdt@depth@100ms","data":{"e":"depthUpdate","E":1604921202938,"s":"BTCUSDT","U":6511140649,"u":6511140655,"b":[],"a":[["15498.46000000","0.00689500"],["15499.98000000","0.00000000"],["15502.59000000","0.00284500"],["15506.44000000","0.00000000"],["15512.60000000","0.00000000"],["15513.78000000","0.00000000"]]}}
2020-11-09T11:26:43.04579 btcusdt {"stream":"btcusdt@depth@100ms","data":{"e":"depthUpdate","E":1604921203038,"s":"BTCUSDT","U":6511140656,"u":6511140656,"b":[["15490.51000000","0.52191300"]],"a":[]}}
2020-11-09T11:26:43.14710 btcusdt {"stream":"btcusdt@depth@100ms","data":{"e":"depthUpdate","E":1604921203139,"s":"BTCUSDT","U":6511140657,"u":6511140666,"b":[["15459.25000000","0.25000000"]],"a":[["15498.00000000","1.84343500"],["15498.46000000","0.00952600"],["15498.49000000","1.06341900"],["15501.84000000","0.20000000"],["15502.74000000","0.00000000"],["15536.74000000","0.25000000"]]}}
2020-11-09T11:26:43.24539 btcusdt {"stream":"btcusdt@depth@100ms","data":{"e":"depthUpdate","E":1604921203239,"s":"BTCUSDT","U":6511140667,"u":6511140684,"b":[["15497.99000000","1.23000300"],["15494.25000000","0.97000000"],["15493.57000000","0.08400000"],["15493.53000000","0.96000000"],["15492.47000000","0.00000000"],["15492.32000000","0.10845200"],["15491.89000000","0.00000000"]],"a":[["15498.00000000","2.52348300"],["15498.41000000","0.00000000"],["15498.46000000","0.00872000"],["15498.49000000","0.00000000"]]}}
2020-11-09T11:26:43.34542 btcusdt {"stream":"btcusdt@depth@100ms","data":{"e":"depthUpdate","E":1604921203339,"s":"BTCUSDT","U":6511140685,"u":6511140697,"b":[["15497.99000000","1.72683000"],["15494.26000000","0.10591000"],["15492.63000000","0.00000000"],["15488.21000000","0.00000000"]],"a":[["15498.00000000","0.50000000"],["15498.41000000","2.20654700"],["15498.42000000","0.00000000"],["15498.43000000","0.00000000"],["15498.50000000","7.77244400"],["15502.59000000","0.00000000"],["15513.70000000","1.00000000"],["15949.75000000","0.64719700"]]}}
2020-11-09T11:26:43.44584 btcusdt {"stream":"btcusdt@depth@100ms","data":{"e":"depthUpdate","E":1604921203439,"s":"BTCUSDT","U":6511140698,"u":6511140708,"b":[["15496.75000000","0.01964900"],["15495.17000000","0.00000000"],["15494.26000000","0.00000000"],["15493.60000000","0.04000000"],["15493.57000000","0.00400000"],["15491.67000000","0.10591000"],["15487.86000000","0.03360300"],["15460.07000000","0.00000000"]],"a":[["15498.41000000","3.13611900"],["15501.84000000","0.00000000"],["15546.86000000","0.00000000"]]}}
2020-11-09T11:26:43.54742 btcusdt {"stream":"btcusdt@depth@100ms","data":{"e":"depthUpdate","E":1604921203539,"s":"BTCUSDT","U":6511140709,"u":6511140722,"b":[["15496.75000000","0.02605100"],["15495.08000000","0.00000000"]],"a":[["15498.40000000","3.11347100"],["15498.41000000","0.00000000"],["15498.46000000","0.00000000"],["15498.50000000","7.62843000"],["15499.99000000","0.00000000"],["15500.52000000","0.15219400"],["15501.13000000","0.10000000"],["15501.65000000","0.00000000"]]}}
2020-11-09T11:26:43.64776 btcusdt {"stream":"btcusdt@depth@100ms","data":{"e":"depthUpdate","E":1604921203639,"s":"BTCUSDT","U":6511140723,"u":6511140737,"b":[["15490.87000000","0.03100000"],["15488.90000000","0.20000000"]],"a":[["15498.00000000","0.49871000"],["15498.37000000","1.16421500"],["15498.39000000","0.00000000"],["15498.40000000","0.00000000"],["15498.50000000","2.32843000"],["15514.50000000","1.50000000"],["15522.00000000","0.32462800"],["15546.82000000","0.03100000"]]}}
2020-11-09T11:26:43.74586 btcusdt {"stream":"btcusdt@depth@100ms","data":{"e":"depthUpdate","E":1604921203739,"s":"BTCUSDT","U":6511140738,"u":6511140746,"b":[["15493.63000000","0.11427900"],["15492.33000000","0.04780600"],["15491.41000000","0.00000000"],["15486.34000000","0.10081200"],["15469.00000000","0.00000000"],["15384.00000000","0.43183000"]],"a":[["15498.00000000","0.47316600"],["15501.69000000","0.00000000"],["15514.50000000","0.00000000"]]}}
2020-11-09T11:26:43.84718 btcusdt {"stream":"btcusdt@depth@100ms","data":{"e":"depthUpdate","E":1604921203839,"s":"BTCUSDT","U":6511140747,"u":6511140759,"b":[["15497.99000000","3.72883000"],["15487.71000000","0.15450000"],["15407.31000000","0.00000000"],["15384.00000000","0.05500000"]],"a":[["15498.37000000","0.00000000"],["15498.50000000","0.32843000"],["15498.68000000","1.00753400"],["15498.78000000","0.00000000"],["15500.51000000","0.23854900"],["15501.77000000","0.87845000"],["15504.09000000","0.00000000"],["15513.70000000","0.00000000"]]}}
2020-11-09T11:26:43.94881 btcusdt {"stream":"btcusdt@depth@100ms","data":{"e":"depthUpdate","E":1604921203939,"s":"BTCUSDT","U":6511140760,"u":6511140819,"b":[["15498.18000000","5.72164000"],["15498.09000000","0.00690000"],["15498.02000000","0.00000000"],["15497.99000000","2.40055000"],["15497.30000000","0.04170800"],["15496.75000000","0.00000000"],["15494.05000000","0.01263000"],["15493.85000000","0.00781900"],["15493.74000000","0.04780600"],["15493.73000000","0.00000000"],["15493.64000000","0.00000000"],["15492.33000000","0.00000000"],["15491.40000000","0.22500000"],["15405.00000000","1.12806500"]],"a":[["15498.00000000","0.00000000"],["15498.19000000","0.48097700"],["15498.45000000","0.06785300"],["15498.46000000","0.00770300"],["15498.50000000","0.12800000"],["15498.68000000","0.00000000"],["15498.99000000","0.38801200"],["15500.52000000","0.00000000"],["15501.10000000","0.22500100"],["15501.13000000","0.00000000"],["15502.71000000","0.88345200"],["15502.75000000","0.15219400"],["15502.98000000","0.53801300"],["15503.70000000","0.00000000"],["15503.93000000","0.00000000"],["15504.12000000","0.00000000"],["15504.45000000","0.00200000"],["15504.74000000","0.62904000"],["15504.92000000","0.75000000"],["15505.61000000","0.00000000"],["15510.08000000","0.00000000"],["15512.59000000","0.50000000"],["15514.33000000","0.00000000"],["15514.62000000","1.00000000"]]}}
2020-11-09T11:26:44.05032 btcusdt {"stream":"btcusdt@depth@100ms","data":{"e":"depthUpdate","E":1604921204039,"s":"BTCUSDT","U":6511140820,"u":6511140839,"b":[["15498.18000000","8.13327300"],["15497.99000000","2.00200000"],["15492.32000000","0.15845200"],["15492.10000000","0.00000000"],["15468.00000000","2.00000000"],["15408.00000000","0.43183000"]],"a":[["15498.19000000","0.33686100"],["15501.09000000","0.28285100"],["15502.46000000","0.00000000"],["15502.70000000","0.36054700"],["15502.71000000","0.00000000"],["15502.82000000","0.00000000"],["15503.31000000","1.19800000"],["15503.69000000","0.10000000"]]}}
2020-11-09T11:26:44.15647 btcusdt {"stream":"btcusdt@depth@100ms","data":{"e":"depthUpdate","E":1604921204139,"s":"BTCUSDT","U":6511140840,"u":6511140861,"b":[["15498.18000000","3.41327300"],["15497.42000000","0.04170800"],["15497.30000000","0.00000000"],["15493.63000000","0.00000000"],["15491.67000000","0.00000000"],["15488.00000000","2.00473900"],["15487.86000000","0.00000000"],["15487.66000000","1.00947700"],["15486.81000000","0.00000000"],["15486.48000000","0.00000000"],["15486.34000000","0.00000000"]],"a":[["15498.19000000","0.12800000"],["15498.45000000","0.00000000"],["15498.50000000","0.00000000"],["15502.76000000","0.24000000"],["15503.69000000","0.00000000"],["15504.74000000","0.12904000"],["15505.06000000","0.50000000"]]}}
2020-11-09T11:26:44.24834 btcusdt {"stream":"btcusdt@depth@100ms","data":{"e":"depthUpdate","E":1604921204239,"s":"BTCUSDT","U":6511140862,"u":6511140900,"b":[["15498.24000000","5.79077300"],["15498.21000000","0.00690000"],["15498.19000000","0.08998200"],["15498.18000000","2.76427300"],["15497.64000000","0.04170800"],["15497.61000000","0.00000000"],["15497.42000000","0.00000000"],["15494.26000000","0.10591000"],["15493.74000000","0.00000000"],["15492.44000000","0.04780600"]],"a":[["15498.19000000","0.00000000"],["15498.25000000","0.01380000"],["15498.46000000","0.01682700"],["15501.08000000","0.15219400"],["15501.21000000","0.00000000"],["15501.52000000","0.00000000"],["15501.85000000","0.00000000"],["15502.02000000","0.04000000"],["15502.46000000","0.10000000"],["15502.70000000","0.00000000"],["15502.75000000","0.00000000"],["15502.76000000","0.00000000"],["15503.23000000","0.00000000"],["15503.30000000","0.74500100"],["15503.57000000","0.06000000"],["15504.04000000","0.04000000"],["15504.29000000","0.77370300"],["15564.00000000","0.48510300"]]}}
2020-11-09T11:26:44.34687 btcusdt {"stream":"btcusdt@depth@100ms","data":{"e":"depthUpdate","E":1604921204339,"s":"BTCUSDT","U":6511140901,"u":6511140923,"b":[["15498.24000000","7.20240600"],["15498.19000000","0.26998200"],["15498.18000000","2.35264000"],["15495.72000000","0.50000000"],["15489.90000000","0.14850000"],["15420.50000000","0.00000000"]],"a":[["15498.46000000","0.00912400"],["15501.08000000","0.00000000"],["15501.51000000","0.00000000"],["15501.77000000","0.00000000"],["15502.01000000","0.27000000"],["15502.12000000","0.50000000"],["15502.31000000","0.03400000"],["15502.46000000","1.05400200"],["15502.61000000","1.74800000"],["15502.97000000","0.15219400"],["15504.79000000","0.38250000"],["15505.06000000","0.00000000"],["15505.30000000","0.50000000"],["15506.39000000","0.68467400"],["15512.24000000","0.00000000"]]}}
2020-11-09T11:26:44.45230 btcusdt {"stream":"btcusdt@depth@100ms","data":{"e":"depthUpdate","E":1604921204439,"s":"BTCUSDT","U":6511140924,"u":6511140934,"b":[["15498.24000000","7.26740600"],["15494.27000000","0.04780600"],["15493.61000000","0.02106400"],["15492.44000000","0.00000000"],["15490.31000000","0.00000000"],["15488.26000000","0.03360800"]],"a":[["15498.25000000","0.00727000"],["15498.46000000","0.00000000"],["15498.71000000","0.00624700"],["15508.97000000","0.13447600"],["15514.62000000","0.00000000"]]}}
2020-11-09T11:26:44.54655 btcusdt {"stream":"btcusdt@depth@100ms","data":{"e":"depthUpdate","E":1604921204539,"s":"BTCUSDT","U":6511140935,"u":6511140943,"b":[["15498.18000000","2.17264000"],["15494.56000000","0.11427900"],["15492.43000000","0.00000000"],["15477.90000000","0.10000000"]],"a":[["15498.25000000","0.00690000"],["15501.58000000","0.15315300"],["15502.97000000","0.00000000"],["15514.12000000","0.23533600"]]}}
2020-11-09T11:26:44.65366 btcusdt {"stream":"btcusdt@depth@100ms","data":{"e":"depthUpdate","E":1604921204639,"s":"BTCUSDT","U":6511140944,"u":6511140954,"b":[],"a":[["15498.25000000","0.00000000"],["15498.62000000","0.00000000"],["15498.69000000","0.00000000"],["15498.71000000","0.00000000"],["15498.77000000","0.00000000"],["15498.99000000","0.34766000"],["15499.02000000","0.01766600"],["15501.09000000","0.00000000"],["15501.10000000","0.00000000"],["15502.01000000","0.00000000"],["15513.87000000","0.00000000"],["15558.00000000","2.00287900"]]}}
2020-11-09T11:26:44.74685 btcusdt {"stream":"btcusdt@depth@100ms","data":{"e":"depthUpdate","E":1604921204740,"s":"BTCUSDT","U":6511140955,"u":6511141000,"b":[["15498.99000000","5.77841600"],["15498.98000000","0.62005900"],["15498.61000000","0.00690000"],["15498.32000000","0.31076500"],["15498.31000000","0.00000000"],["15498.24000000","5.45677300"],["15498.19000000","0.18000000"],["15498.18000000","2.03737400"],["15497.67000000","0.04860800"],["15497.64000000","0.00000000"],["15493.61000000","0.07106400"],["15492.32000000","0.10845200"],["15487.03000000","0.10082500"],["15418.97000000","0.24000000"]],"a":[["15498.99000000","0.00000000"],["15499.00000000","0.78092200"],["15499.54000000","0.05962900"],["15500.51000000","0.00000000"],["15502.46000000","0.10000000"],["15502.47000000","0.00000000"],["15502.60000000","0.00000000"],["15502.98000000","0.00000000"],["15503.30000000","0.00000000"],["15503.31000000","1.24800000"],["15503.44000000","0.01000000"],["15503.70000000","0.32100000"],["15504.29000000","0.00000000"],["15504.40000000","0.00000000"],["15504.79000000","0.00000000"],["15504.80000000","0.00000000"],["15505.24000000","0.01000000"],["15505.64000000","0.01500000"],["15506.39000000","0.00000000"],["15514.05000000","1.00000000"],["15515.00000000","0.00066800"]]}}
2020-11-09T11:26:44.84786 btcusdt {"stream":"btcusdt@depth@100ms","data":{"e":"depthUpdate","E":1604921204840,"s":"BTCUSDT","U":6511141001,"u":6511141021,"b":[["15498.99000000","6.31979900"],["15498.19000000","0.00000000"],["15495.01000000","1.25000000"],["15494.21000000","0.01312400"],["15494.05000000","0.00000000"],["15491.14000000","0.29700000"],["15487.53000000","0.00000000"],["15486.70000000","1.45800000"],["15421.49000000","0.00648400"]],"a":[["15501.58000000","0.00095900"],["15502.98000000","0.00000000"],["15503.89000000","0.11427900"],["15504.17000000","0.00000000"],["15504.30000000","0.00000000"],["15504.92000000","0.00000000"],["15506.49000000","0.00000000"],["15506.55000000","0.30000000"],["15506.69000000","0.75000000"],["15514.05000000","0.00000000"]]}}
2020-11-09T11:26:44.94836 btcusdt {"stream":"btcusdt@depth@100ms","data":{"e":"depthUpdate","E":1604921204940,"s":"BTCUSDT","U":6511141022,"u":6511141037,"b":[["15495.73000000","0.05470600"],["15494.56000000","0.00000000"],["15494.27000000","0.00000000"],["15493.85000000","0.00000000"],["15482.67000000","0.35934900"]],"a":[["15502.46000000","0.00000000"],["15503.13000000","0.00000000"],["15503.69000000","0.10000000"],["15504.29000000","0.00000000"],["15504.37000000","0.00000000"],["15504.74000000","0.00000000"],["15507.97000000","0.00690000"],["15508.36000000","1.25000000"],["15561.00000000","0.26473100"]]}}
2020-11-09T11:26:45.04726 btcusdt {"stream":"btcusdt@depth@100ms","data":{"e":"depthUpdate","E":1604921205040,"s":"BTCUSDT","U":6511141038,"u":6511141070,"b":[["15498.99000000","13.83422700"],["15498.98000000","0.00000000"],["15498.32000000","0.00000000"],["15498.24000000","5.36500000"],["15495.90000000","0.25782800"],["15495.72000000","0.00000000"],["15495.13000000","0.03226000"],["15494.26000000","0.00000000"],["15492.31000000","0.00000000"],["15490.60000000","1.50000000"],["15488.00000000","0.50473900"],["15479.09000000","0.00000000"]],"a":[["15499.00000000","0.77324500"],["15502.96000000","0.03226000"],["15502.99000000","0.00000000"],["15503.69000000","0.00000000"],["15504.33000000","0.00000000"],["15505.00000000","0.10000000"],["15505.34000000","0.00000000"],["15507.45000000","0.12904000"],["15507.79000000","0.00000000"],["15508.36000000","0.00000000"],["15508.41000000","0.00000000"],["15509.97000000","0.00000000"],["15510.07000000","0.00000000"],["15510.50000000","1.25000000"],["15511.97000000","1.00944300"],["15513.83000000","2.45100000"],["15515.01000000","0.00413200"]]}}
2020-11-09T11:26:45.14780 btcusdt {"stream":"btcusdt@depth@100ms","data":{"e":"depthUpdate","E":1604921205140,"s":"BTCUSDT","U":6511141071,"u":6511141102,"b":[["15498.99000000","13.83622700"],["15498.25000000","0.04780600"],["15495.73000000","0.00690000"],["15495.15000000","0.08000000"],["15494.68000000","0.01507500"],["15494.21000000","0.00000000"],["15493.60000000","0.00000000"],["15492.04000000","0.30000000"],["15491.47000000","1.00000000"],["15490.01000000","0.00000000"],["15488.85000000","0.00000000"],["15488.20000000","0.00000000"],["15480.65000000","0.00080700"],["15418.97000000","0.00000000"]],"a":[["15499.54000000","0.00000000"],["15501.14000000","0.00000000"],["15503.31000000","0.05000000"],["15503.76000000","1.19800000"],["15503.89000000","0.00000000"],["15505.18000000","0.00000000"],["15505.25000000","0.00000000"],["15506.55000000","0.00000000"],["15506.69000000","0.00000000"],["15507.73000000","0.75000000"],["15508.45000000","0.03362000"],["15508.59000000","0.00000000"],["15510.42000000","0.13447900"],["15510.45000000","1.25000000"],["15510.50000000","0.00000000"],["15511.75000000","0.00000000"]]}}
2020-11-09T11:26:45.25013 btcusdt {"stream":"btcusdt@depth@100ms","data":{"e":"depthUpdate","E":1604921205240,"s":"BTCUSDT","U":6511141103,"u":6511141132,"b":[["15498.99000000","13.83732200"],["15495.66000000","0.08000000"],["15495.02000000","0.08000000"],["15494.93000000","0.32000000"],["15494.25000000","0.00000000"],["15493.53000000","0.00000000"],["15489.85000000","0.00300000"],["15488.59000000","0.14400000"],["15483.87000000","1.09456200"]],"a":[["15499.00000000","0.77913000"],["15502.31000000","0.00000000"],["15502.61000000","0.00000000"],["15502.82000000","0.01700000"],["15502.83000000","0.01700000"],["15503.18000000","0.00000000"],["15503.33000000","1.74800000"],["15503.76000000","0.00000000"],["15504.27000000","0.15700000"],["15504.39000000","0.29200000"],["15505.23000000","0.15219400"],["15505.30000000","0.00000000"],["15505.56000000","0.50000000"],["15508.30000000","0.00000000"],["15508.86000000","1.25000000"],["15510.45000000","0.00000000"],["15510.50000000","0.00000000"]]}}
2020-11-09T11:26:45.34598 btcusdt {"stream":"btcusdt@depth@100ms","data":{"e":"depthUpdate","E":1604921205340,"s":"BTCUSDT","U":6511141133,"u":6511141206,"b":[["15499.99000000","6.99767900"],["15499.91000000","0.00000000"],["15499.28000000","0.04870800"],["15499.14000000","0.03268400"],["15499.13000000","2.75000000"],["15499.06000000","0.00690000"],["15499.03000000","0.00000000"],["15499.02000000","0.00000000"],["15499.01000000","0.00000000"],["15498.99000000","0.65129300"],["15498.63000000","0.05391300"],["15498.56000000","0.00000000"],["15498.24000000","0.06500000"],["15497.67000000","0.00690000"],["15494.27000000","0.12903300"],["15491.92000000","0.00000000"],["15480.92000000","0.30600000"],["15422.80000000","0.24000000"],["15421.49000000","0.00000000"]],"a":[["15499.00000000","0.00000000"],["15499.02000000","0.00000000"],["15499.14000000","0.00000000"],["15500.00000000","0.31467300"],["15500.50000000","0.00000000"],["15502.71000000","0.08000000"],["15502.82000000","0.00000000"],["15502.83000000","0.00000000"],["15502.96000000","0.00000000"],["15503.44000000","0.02700000"],["15503.45000000","0.01700000"],["15503.71000000","0.00000000"],["15503.91000000","0.03225800"],["15504.28000000","0.00000000"],["15504.72000000","1.19800000"],["15505.56000000","0.00000000"],["15505.82000000","0.50000000"],["15508.86000000","0.00000000"],["15508.97000000","0.13447600"],["15510.50000000","1.25000000"]]}}
2020-11-09T11:26:45.44779 btcusdt {"stream":"btcusdt@depth@100ms","data":{"e":"depthUpdate","E":1604921205440,"s":"BTCUSDT","U":6511141207,"u":6511141255,"b":[["15499.99000000","7.39906200"],["15499.00000000","0.18000000"],["15498.99000000","0.10991000"],["15498.25000000","0.00000000"],["15498.24000000","0.00000000"],["15496.88000000","0.54600000"],["15495.91000000","0.04780600"],["15495.16000000","0.06748900"],["15495.15000000","0.00000000"],["15495.03000000","0.05000000"],["15493.62000000","0.00000000"],["15493.61000000","0.02106400"],["15492.85000000","0.50000000"],["15489.68000000","0.00000000"]],"a":[["15500.00000000","0.25397200"],["15500.53000000","0.00000000"],["15502.02000000","0.00000000"],["15502.71000000","0.00000000"],["15503.31000000","0.00000000"],["15503.33000000","0.00000000"],["15503.44000000","0.01700000"],["15503.57000000","0.00000000"],["15504.00000000","0.00000000"],["15504.04000000","0.00000000"],["15504.24000000","1.74800000"],["15504.27000000","0.00000000"],["15504.39000000","0.00000000"],["15504.48000000","0.05000000"],["15504.61000000","0.01000000"],["15505.01000000","0.00000000"],["15505.20000000","0.15900000"],["15505.24000000","0.00000000"],["15505.27000000","0.04000000"],["15505.32000000","0.29200000"],["15505.40000000","0.00000000"],["15505.51000000","0.02000000"],["15505.64000000","0.00000000"],["15505.69000000","0.00000000"],["15506.02000000","0.00000000"],["15506.41000000","0.01000000"],["15506.81000000","0.01500000"],["15507.29000000","0.04000000"],["15507.44000000","0.16000000"],["15514.61000000","0.25781800"]]}}
2020-11-09T11:26:45.54766 btcusdt {"stream":"btcusdt@depth@100ms","data":{"e":"depthUpdate","E":1604921205540,"s":"BTCUSDT","U":6511141256,"u":6511141274,"b":[["15499.99000000","7.56896700"],["15499.00000000","0.00000000"],["15495.22000000","0.01816600"],["15494.68000000","0.00000000"],["15493.48000000","0.19204100"]],"a":[["15503.70000000","0.00000000"],["15504.72000000","0.00000000"],["15505.23000000","1.35019400"],["15505.51000000","0.00000000"],["15505.67000000","0.02000000"],["15505.82000000","0.00000000"],["15507.82000000","0.00000000"],["15507.93000000","0.50000000"],["15508.89000000","0.00000000"],["15509.32000000","0.20000000"],["15511.10000000","0.05681900"],["15514.12000000","0.00000000"],["15515.83000000","0.23536500"]]}}
2020-11-09T11:26:45.64737 btcusdt {"stream":"btcusdt@depth@100ms","data":{"e":"depthUpdate","E":1604921205640,"s":"BTCUSDT","U":6511141275,"u":6511141281,"b":[],"a":[["15504.09000000","0.10000000"],["15505.00000000","0.00000000"],["15506.40000000","0.00000000"],["15506.50000000","0.11427900"],["15509.14000000","0.10000000"],["15512.63000000","0.30253500"],["15603.00000000","0.11827300"]]}}
2020-11-09T11:26:45.75178 btcusdt {"stream":"btcusdt@depth@100ms","data":{"e":"depthUpdate","E":1604921205740,"s":"BTCUSDT","U":6511141282,"u":6511141294,"b":[["15498.00000000","0.06807300"],["15495.92000000","0.08000000"],["15495.22000000","0.00000000"],["15494.73000000","0.00915300"],["15488.90000000","0.00000000"],["15422.80000000","0.00000000"],["15405.00000000","1.50489500"]],"a":[["15502.12000000","0.00000000"],["15504.09000000","0.00000000"],["15505.11000000","0.10000000"],["15517.01000000","0.24000000"],["15528.80000000","0.01609700"],["15529.36000000","0.00690000"]]}}
2020-11-09T11:26:45.84911 btcusdt {"stream":"btcusdt@depth@100ms","data":{"e":"depthUpdate","E":1604921205840,"s":"BTCUSDT","U":6511141295,"u":6511141341,"b":[["15499.03000000","0.00000000"],["15498.38000000","0.24000000"],["15498.21000000","0.02796400"],["15497.99000000","2.00000000"],["15497.71000000","0.00370700"],["15497.68000000","0.08000000"],["15497.33000000","0.03225500"],["15496.88000000","0.00000000"],["15496.24000000","0.11427900"],["15495.66000000","0.00000000"],["15495.13000000","0.00000000"],["15494.93000000","0.00000000"],["15493.61000000","0.00000000"],["15491.95000000","0.14550000"]],"a":[["15503.44000000","0.00000000"],["15503.45000000","0.00000000"],["15503.91000000","0.00000000"],["15504.10000000","0.00000000"],["15504.24000000","0.00000000"],["15505.13000000","1.74800000"],["15505.17000000","0.03400000"],["15505.20000000","0.00200000"],["15505.23000000","0.15219400"],["15505.32000000","0.00000000"],["15505.67000000","0.00000000"],["15505.80000000","0.03000000"],["15505.86000000","1.19800000"],["15506.11000000","0.00000000"],["15506.35000000","0.15700000"],["15506.52000000","0.29200000"],["15507.13000000","0.00000000"],["15507.45000000","0.03225300"],["15507.53000000","0.14000000"],["15509.13000000","0.12903300"],["15509.14000000","0.00000000"],["15510.47000000","0.00000000"],["15511.97000000","0.00000000"],["15512.07000000","0.10000000"],["15513.02000000","0.30000000"],["15513.83000000","1.45100000"],["15515.83000000","0.00000000"],["15516.10000000","1.00000000"],["15600.00000000","211.95420500"]]}}
2020-11-09T11:26:45.94870 btcusdt {"stream":"btcusdt@depth@100ms","data":{"e":"depthUpdate","E":1604921205940,"s":"BTCUSDT","U":6511141342,"u":6511141360,"b":[["15499.99000000","15.10815000"],["15499.28000000","0.00000000"],["15498.38000000","0.00000000"],["15497.68000000","0.00000000"],["15497.08000000","0.02000000"],["15495.43000000","0.01870400"],["15495.10000000","0.00900600"],["15494.73000000","0.00000000"],["15424.54000000","0.24000000"],["15422.49000000","0.00648400"]],"a":[["15500.00000000","0.25162500"],["15503.11000000","0.00000000"],["15504.23000000","0.15219400"],["15505.23000000","0.00000000"],["15505.85000000","0.50000000"],["15511.05000000","0.00000000"],["15514.94000000","1.00934600"],["15516.10000000","0.00000000"],["15519.99000000","0.23538300"]]}}
2020-11-09T11:26:46.04880 btcusdt {"stream":"btcusdt@depth@100ms","data":{"e":"depthUpdate","E":1604921206040,"s":"BTCUSDT","U":6511141361,"u":6511141419,"b":[["15502.06000000","0.00690000"],["15501.17000000","1.00000000"],["15500.40000000","0.41878500"],["15500.39000000","0.00000000"],["15500.36000000","0.30341100"],["15500.35000000","0.00000000"],["15500.27000000","0.28890700"],["15500.10000000","0.05504600"],["15500.00000000","0.00128900"],["15499.99000000","5.93006200"],["15498.99000000","0.00400000"],["15498.63000000","0.00000000"],["15498.18000000","2.02776800"],["15495.92000000","0.13000000"],["15495.91000000","0.00000000"],["15495.03000000","0.00000000"],["15493.32000000","0.14850000"]],"a":[["15500.00000000","0.00000000"],["15500.20000000","0.00000000"],["15500.64000000","0.00000000"],["15500.69000000","0.00000000"],["15500.88000000","0.00000000"],["15500.89000000","0.00000000"],["15501.15000000","0.00000000"],["15501.16000000","0.00000000"],["15501.23000000","0.00000000"],["15501.58000000","0.00000000"],["15501.59000000","0.00000000"],["15501.78000000","0.00000000"],["15501.90000000","0.00000000"],["15502.07000000","0.00690000"],["15502.25000000","0.00000000"],["15502.72000000","0.00000000"],["15504.03000000","0.04629100"],["15504.13000000","0.00257900"],["15504.14000000","0.63097500"],["15504.48000000","0.00000000"],["15505.13000000","0.00000000"],["15505.17000000","0.00000000"],["15505.18000000","0.05000000"],["15505.86000000","0.00000000"],["15505.87000000","0.00000000"],["15506.35000000","0.00000000"],["15506.50000000","0.00000000"],["15506.52000000","0.00000000"],["15507.02000000","1.19800000"],["15507.04000000","0.00000000"],["15507.19000000","0.15700000"],["15507.32000000","0.29200000"],["15507.33000000","0.01700000"],["15507.34000000","0.01700000"],["15507.50000000","0.00000000"],["15507.62000000","1.74800000"],["15507.73000000","0.00000000"],["15508.05000000","0.31800000"],["15508.10000000","0.11427900"],["15508.66000000","0.06724500"],["15509.04000000","0.75000000"],["15509.28000000","0.00000000"],["15511.32000000","0.20000000"],["15513.83000000","0.00000000"],["15516.11000000","1.00000000"]]}}
2020-11-09T11:26:46.15162 btcusdt {"stream":"btcusdt@depth@100ms","data":{"e":"depthUpdate","E":1604921206140,"s":"BTCUSDT","U":6511141420,"u":6511141474,"b":[["15502.06000000","1.51171400"],["15501.22000000","0.00000000"],["15501.17000000","0.00000000"],["15500.10000000","0.00000000"],["15500.00000000","0.00000000"],["15499.99000000","5.52867900"],["15498.22000000","0.04780600"],["15497.34000000","0.00000000"],["15495.93000000","0.36296900"],["15494.28000000","0.20000000"],["15490.86000000","0.00000000"],["15488.00000000","0.00000000"],["15487.66000000","0.00000000"],["15478.50000000","0.00000000"]],"a":[["15502.07000000","5.30000000"],["15503.11000000","0.00690000"],["15503.26000000","2.00000000"],["15504.03000000","0.00000000"],["15504.13000000","0.04629100"],["15504.14000000","0.47665900"],["15504.23000000","0.00000000"],["15504.61000000","0.00000000"],["15505.18000000","0.00000000"],["15505.79000000","0.15219400"],["15506.29000000","0.00000000"],["15506.41000000","0.00000000"],["15506.81000000","0.00000000"],["15507.02000000","0.06000000"],["15507.03000000","1.41146700"],["15507.19000000","0.00000000"],["15507.28000000","0.03400000"],["15507.32000000","0.00000000"],["15507.33000000","0.00000000"],["15507.34000000","0.00000000"],["15507.56000000","1.74800000"],["15507.62000000","0.00000000"],["15507.66000000","0.00000000"],["15507.83000000","0.15700000"],["15507.96000000","0.29200000"],["15508.44000000","0.00000000"],["15508.49000000","0.01000000"],["15508.85000000","0.32100000"],["15508.88000000","0.01500000"],["15515.82000000","0.50235100"]]}}
2020-11-09T11:26:46.24834 btcusdt {"stream":"btcusdt@depth@100ms","data":{"e":"depthUpdate","E":1604921206240,"s":"BTCUSDT","U":6511141475,"u":6511141515,"b":[["15502.06000000","1.91060600"],["15501.76000000","0.00000000"],["15501.18000000","0.13000000"],["15500.40000000","0.10591000"],["15500.36000000","0.00000000"],["15500.27000000","0.00000000"],["15498.22000000","0.00000000"],["15496.25000000","0.04780600"],["15496.24000000","0.00000000"],["15489.34000000","0.50464400"],["15488.99000000","1.00928900"]],"a":[["15502.07000000","2.00000000"],["15503.63000000","0.03228800"],["15504.13000000","0.00000000"],["15506.29000000","0.01700000"],["15506.30000000","0.01700000"],["15506.57000000","1.74800000"],["15506.87000000","0.16128300"],["15507.28000000","0.00000000"],["15507.56000000","0.00000000"],["15507.76000000","0.30300000"],["15507.92000000","0.20000000"],["15508.85000000","0.00000000"],["15510.72000000","0.00306000"],["15512.59000000","0.00000000"],["15514.29000000","0.00000000"],["15515.30000000","0.50000000"],["15516.11000000","0.00000000"],["15528.79000000","0.01609700"],["15528.80000000","0.00000000"]]}}
2020-11-09T11:26:46.34875 btcusdt {"stream":"btcusdt@depth@100ms","data":{"e":"depthUpdate","E":1604921206340,"s":"BTCUSDT","U":6511141516,"u":6511141522,"b":[["15496.06000000","0.00781900"],["15495.10000000","0.00000000"],["15422.49000000","0.00000000"]],"a":[["15502.53000000","0.00941900"],["15506.86000000","0.12902500"],["15506.87000000","0.00000000"],["15507.92000000","0.00000000"]]}}
2020-11-09T11:26:46.45220 btcusdt {"stream":"btcusdt@depth@100ms","data":{"e":"depthUpdate","E":1604921206440,"s":"BTCUSDT","U":6511141523,"u":6511141535,"b":[["15502.06000000","1.86572300"],["15497.29000000","0.08000000"]],"a":[["15502.07000000","2.00000000"],["15507.52000000","0.20000000"],["15508.45000000","0.00000000"],["15508.51000000","0.00000000"],["15508.97000000","0.00000000"],["15510.42000000","0.00000000"],["15512.63000000","0.00000000"],["15516.52000000","0.30260300"],["15528.79000000","0.00000000"]]}}
2020-11-09T11:26:46.54990 btcusdt {"stream":"btcusdt@depth@100ms","data":{"e":"depthUpdate","E":1604921206540,"s":"BTCUSDT","U":6511141536,"u":6511141538,"b":[],"a":[["15509.05000000","0.00000000"],["15511.10000000","0.00000000"],["15513.39000000","0.05681900"]]}}
2020-11-09T11:26:46.64903 btcusdt {"stream":"btcusdt@depth@100ms","data":{"e":"depthUpdate","E":1604921206641,"s":"BTCUSDT","U":6511141539,"u":6511141551,"b":[["15502.06000000","1.80670800"],["15499.19000000","0.00943100"],["15496.46000000","0.01568000"],["15496.06000000","0.00000000"],["15495.43000000","0.00000000"],["15300.00000000","35.98664100"]],"a":[["15502.07000000","7.30000000"],["15502.53000000","0.00000000"],["15502.84000000","0.00000000"],["15503.47000000","0.00862100"],["15507.52000000","0.00000000"],["15508.10000000","0.00000000"]]}}
2020-11-09T11:26:46.74935 btcusdt {"stream":"btcusdt@depth@100ms","data":{"e":"depthUpdate","E":1604921206741,"s":"BTCUSDT","U":6511141552,"u":6511141559,"b":[["15496.46000000","0.00000000"],["15492.32000000","0.00000000"]],"a":[["15502.07000000","1.93973300"],["15503.37000000","0.00716500"],["15503.47000000","0.00000000"],["15505.84000000","0.30900000"],["15506.88000000","0.43693300"]]}}
2020-11-09T11:26:46.84913 btcusdt {"stream":"btcusdt@depth@100ms","data":{"e":"depthUpdate","E":1604921206841,"s":"BTCUSDT","U":6511141560,"u":6511141565,"b":[["15502.06000000","1.83499100"],["15499.59000000","0.01635200"],["15424.54000000","0.00648300"]],"a":[["15503.39000000","0.01935100"],["15515.34000000","1.00000000"]]}}
2020-11-09T11:26:46.95055 btcusdt {"stream":"btcusdt@depth@100ms","data":{"e":"depthUpdate","E":1604921206941,"s":"BTCUSDT","U":6511141566,"u":6511141578,"b":[["15502.06000000","1.74886800"],["15499.59000000","0.00000000"],["15498.18000000","2.00000000"],["15496.25000000","0.00000000"],["15434.77000000","0.24000000"]],"a":[["15502.07000000","7.23973300"],["15506.16000000","1.12621000"],["15508.97000000","0.00000000"],["15510.45000000","1.25000000"],["15510.50000000","0.00000000"],["15512.60000000","0.50000000"],["15515.30000000","0.00000000"]]}}
2020-11-09T11:26:47.04719 btcusdt {"stream":"btcusdt@depth@100ms","data":{"e":"depthUpdate","E":1604921207041,"s":"BTCUSDT","U":6511141579,"u":6511141594,"b":[["15502.06000000","1.66400900"],["15501.30000000","0.00856300"],["15501.29000000","0.01931100"],["15499.19000000","0.00000000"],["15498.99000000","0.00200000"],["15498.00000000","0.11807300"],["15495.92000000","0.08000000"],["15495.17000000","0.04780600"]],"a":[["15502.07000000","7.73973300"],["15503.37000000","0.00000000"],["15503.39000000","0.00000000"],["15505.35000000","0.00964900"],["15506.11000000","0.01718100"],["15506.69000000","0.05000000"],["15507.02000000","0.01000000"]]}}
2020-11-09T11:26:47.15067 btcusdt {"stream":"btcusdt@depth@100ms","data":{"e":"depthUpdate","E":1604921207141,"s":"BTCUSDT","U":6511141595,"u":6511141637,"b":[["15502.06000000","1.13157400"],["15502.04000000","0.01099800"],["15502.02000000","0.01100000"],["15501.18000000","0.00000000"],["15499.99000000","5.30000000"],["15498.99000000","0.00000000"],["15497.29000000","0.00000000"],["15495.92000000","0.00000000"],["15493.48000000","0.00000000"]],"a":[["15502.07000000","12.51780300"],["15503.62000000","0.08000000"],["15505.06000000","0.01700000"],["15505.09000000","0.01700000"],["15505.52000000","0.01311500"],["15505.89000000","1.74800000"],["15506.11000000","0.00000000"],["15506.29000000","0.00000000"],["15506.30000000","0.00000000"],["15506.51000000","1.19800000"],["15506.57000000","0.00000000"],["15506.58000000","0.15700000"],["15506.59000000","0.29200000"],["15507.03000000","0.21346700"],["15507.13000000","0.20000000"],["15507.83000000","0.00000000"],["15507.96000000","0.00000000"],["15508.86000000","1.25000000"],["15510.18000000","0.30000000"],["15510.45000000","0.00000000"],["15511.35000000","0.00000000"],["15512.60000000","0.00000000"],["15515.44000000","0.50000000"],["15517.56000000","0.00000000"]]}}
2020-11-09T11:26:47.24715 btcusdt {"stream":"btcusdt@depth@100ms","data":{"e":"depthUpdate","E":1604921207241,"s":"BTCUSDT","U":6511141638,"u":6511141655,"b":[["15502.06000000","1.01099800"],["15499.99000000","0.00000000"],["15491.14000000","0.00000000"],["15489.52000000","0.30260900"],["15487.58000000","0.00283100"],["15460.62000000","0.25000000"],["15457.52000000","0.00000000"]],"a":[["15502.07000000","12.89831600"],["15503.25000000","0.10000000"],["15505.11000000","0.00000000"],["15505.16000000","0.03225500"],["15505.80000000","0.00000000"],["15506.68000000","0.01000000"],["15506.82000000","0.12902200"],["15507.02000000","0.00000000"],["15507.45000000","0.00000000"],["15509.13000000","0.00000000"],["15517.41000000","1.50000000"]]}}
2020-11-09T11:26:47.34727 btcusdt {"stream":"btcusdt@depth@100ms","data":{"e":"depthUpdate","E":1604921207341,"s":"BTCUSDT","U":6511141656,"u":6511141681,"b":[["15500.68000000","0.00706700"],["15500.40000000","0.00000000"],["15499.15000000","0.10591000"],["15499.14000000","0.00000000"],["15495.17000000","0.00000000"],["15493.33000000","0.04981800"],["15491.95000000","0.00000000"],["15491.48000000","0.66846400"],["15489.85000000","0.00000000"],["15480.92000000","0.00000000"],["15424.54000000","0.00000000"],["15387.00000000","0.10827300"]],"a":[["15502.07000000","7.59831600"],["15503.24000000","0.15219400"],["15503.62000000","0.00000000"],["15505.06000000","0.00000000"],["15505.09000000","0.00000000"],["15505.51000000","0.12903100"],["15505.79000000","0.00000000"],["15505.84000000","0.32600000"],["15506.06000000","0.01700000"],["15508.41000000","0.09630800"],["15508.86000000","0.00000000"],["15512.49000000","0.62892800"],["15515.44000000","0.00000000"],["15520.00000000","5.41337600"]]}}
2020-11-09T11:26:47.44782 btcusdt {"stream":"btcusdt@depth@100ms","data":{"e":"depthUpdate","E":1604921207441,"s":"BTCUSDT","U":6511141682,"u":6511141694,"b":[],"a":[["15502.07000000","2.03356300"],["15503.24000000","0.00000000"],["15503.25000000","0.00000000"],["15505.11000000","0.25219400"],["15506.67000000","0.20000000"],["15510.45000000","0.00000000"],["15510.87000000","1.25000000"],["15517.41000000","0.00000000"]]}}
2020-11-09T11:26:47.55077 btcusdt {"stream":"btcusdt@depth@100ms","data":{"e":"depthUpdate","E":1604921207541,"s":"BTCUSDT","U":6511141695,"u":6511141702,"b":[["15491.31000000","0.29100000"],["15441.46000000","0.00000000"],["15411.00000000","1.08967400"]],"a":[["15502.07000000","2.03556300"],["15503.62000000","0.08000000"],["15505.83000000","0.20000000"],["15508.97000000","1.25000000"],["15510.87000000","0.00000000"]]}}
2020-11-09T11:26:47.64816 btcusdt {"stream":"btcusdt@depth@100ms","data":{"e":"depthUpdate","E":1604921207641,"s":"BTCUSDT","U":6511141703,"u":6511141710,"b":[["15502.06000000","1.00064700"]],"a":[["15502.07000000","14.62419600"],["15505.47000000","0.01740700"],["15505.51000000","0.00000000"],["15505.52000000","0.00000000"],["15560.00000000","5.53087500"]]}}
2020-11-09T11:26:47.74838 btcusdt {"stream":"btcusdt@depth@100ms","data":{"e":"depthUpdate","E":1604921207741,"s":"BTCUSDT","U":6511141711,"u":6511141720,"b":[["15502.06000000","0.98786000"],["15498.21000000","0.00690000"],["15387.00000000","0.00000000"]],"a":[["15502.07000000","15.13270900"],["15503.25000000","0.25219400"],["15505.11000000","0.00000000"],["15517.24000000","1.50000000"]]}}
2020-11-09T11:26:47.84813 btcusdt {"stream":"btcusdt@depth@100ms","data":{"e":"depthUpdate","E":1604921207841,"s":"BTCUSDT","U":6511141721,"u":6511141732,"b":[["15499.15000000","0.00000000"],["15495.94000000","0.10591000"],["15495.17000000","0.02106400"],["15495.01000000","0.00000000"],["15489.62000000","0.00000000"],["15489.16000000","1.25000000"],["15424.54000000","0.00648300"]],"a":[["15506.47000000","1.25000000"],["15508.97000000","0.00000000"],["15511.51000000","0.06723200"],["15511.95000000","0.13446300"]]}}
2020-11-09T11:26:47.94842 btcusdt {"stream":"btcusdt@depth@100ms","data":{"e":"depthUpdate","E":1604921207941,"s":"BTCUSDT","U":6511141733,"u":6511141831,"b":[["15502.06000000","0.00000000"],["15502.04000000","0.00000000"],["15502.02000000","0.00000000"],["15501.30000000","0.00000000"],["15501.29000000","0.00000000"],["15500.68000000","0.00000000"],["15499.19000000","0.00000000"],["15499.14000000","0.00129000"],["15499.13000000","0.00000000"],["15495.94000000","0.00000000"],["15493.34000000","0.10591000"],["15493.32000000","0.00000000"],["15491.48000000","0.00000000"],["15491.31000000","0.00000000"],["15490.51000000","0.00000000"],["15489.16000000","0.00000000"],["15488.68000000","1.25000000"],["15408.00000000","0.54010300"],["14950.00000000","15.33420300"]],"a":[["15499.68000000","0.03977200"],["15499.69000000","0.03997400"],["15499.71000000","0.13913000"],["15500.48000000","1.06925700"],["15500.49000000","0.00000000"],["15500.51000000","0.25219400"],["15500.52000000","0.00000000"],["15500.60000000","0.00690000"],["15500.67000000","0.03228800"],["15501.09000000","0.19607300"],["15501.26000000","0.00000000"],["15501.27000000","0.00000000"],["15501.28000000","0.00000000"],["15501.30000000","0.00000000"],["15501.31000000","0.00000000"],["15501.70000000","0.33133500"],["15501.71000000","0.24092100"],["15501.74000000","0.22379000"],["15501.79000000","0.00000000"],["15501.98000000","4.96237300"],["15501.99000000","0.00000000"],["15502.03000000","0.00000000"],["15502.04000000","0.00000000"],["15502.05000000","5.19074900"],["15502.06000000","4.90000000"],["15502.07000000","2.49743900"],["15503.25000000","0.00000000"],["15503.63000000","0.00000000"],["15504.04000000","0.01700000"],["15504.05000000","0.01700000"],["15504.30000000","1.74800000"],["15505.71000000","1.19800000"],["15505.84000000","0.30900000"],["15505.89000000","0.00000000"],["15506.06000000","0.00000000"],["15506.51000000","0.00000000"],["15507.39000000","0.20290400"],["15513.33000000","1.00928900"],["15514.94000000","0.00000000"],["15631.96000000","0.00000000"]]}}
2020-11-09T11:26:48.05052 btcusdt {"stream":"btcusdt@depth@100ms","data":{"e":"depthUpdate","E":1604921208041,"s":"BTCUSDT","U":6511141832,"u":6511141920,"b":[["15498.68000000","0.00000000"],["15498.18000000","0.00000000"],["15498.00000000","0.06807300"],["15497.99000000","0.00000000"],["15495.94000000","0.08000000"],["15495.93000000","0.00000000"],["15495.17000000","0.00000000"],["15495.16000000","0.00000000"],["15494.28000000","0.05000000"],["15494.27000000","0.00000000"],["15493.34000000","0.00000000"],["15493.33000000","0.00201200"],["15492.85000000","0.00000000"],["15492.43000000","0.36537900"],["15492.10000000","0.12697400"],["15491.67000000","0.04780600"],["15491.47000000","0.00000000"],["15490.60000000","0.00000000"],["15489.66000000","0.50000000"],["15488.68000000","0.00000000"],["15488.60000000","1.25000000"],["15487.33000000","1.00000000"],["15486.35000000","0.00000000"],["15455.00000000","0.33297000"],["15434.77000000","0.00000000"]],"a":[["15499.15000000","2.64729900"],["15499.53000000","0.03228800"],["15499.66000000","0.00000000"],["15499.67000000","0.00000000"],["15499.68000000","0.00000000"],["15499.69000000","0.02604200"],["15500.31000000","0.00000000"],["15500.48000000","0.00000000"],["15500.67000000","0.00000000"],["15501.09000000","0.00000000"],["15501.68000000","0.39127000"],["15501.69000000","0.78253600"],["15501.70000000","0.00000000"],["15501.71000000","0.00000000"],["15501.74000000","0.00000000"],["15501.98000000","4.37437000"],["15502.05000000","5.13994900"],["15502.07000000","2.25192600"],["15503.54000000","0.30300000"],["15503.88000000","0.25000000"],["15504.13000000","0.14000000"],["15504.98000000","1.19800000"],["15505.11000000","0.06000000"],["15505.58000000","0.01000000"],["15505.71000000","0.00000000"],["15505.98000000","0.01500000"],["15506.48000000","0.02225700"],["15506.60000000","0.14850000"],["15506.68000000","0.00000000"],["15506.69000000","0.00000000"],["15506.88000000","0.11593300"],["15508.49000000","0.00000000"],["15508.88000000","0.00000000"],["15509.04000000","0.00000000"],["15511.76000000","1.00000000"],["15513.14000000","1.50000000"],["15514.02000000","1.20600000"],["15515.34000000","0.00000000"],["15517.01000000","0.00000000"],["15517.24000000","0.00000000"],["15603.00000000","0.49510300"]]}}
2020-11-09T11:26:48.14831 btcusdt {"stream":"btcusdt@depth@100ms","data":{"e":"depthUpdate","E":1604921208141,"s":"BTCUSDT","U":6511141921,"u":6511141952,"b":[["15496.30000000","0.16000000"],["15488.60000000","0.00000000"],["15487.68000000","1.25000000"],["15483.87000000","0.00000000"],["15477.90000000","0.00000000"],["15459.25000000","0.00000000"]],"a":[["15499.15000000","3.24550100"],["15499.51000000","0.00000000"],["15499.53000000","0.00000000"],["15500.51000000","0.00000000"],["15501.66000000","0.39126900"],["15501.67000000","0.78253600"],["15501.68000000","0.00000000"],["15501.69000000","0.00000000"],["15501.98000000","4.37437000"],["15502.06000000","5.20300000"],["15503.87000000","0.10212300"],["15503.91000000","0.32100000"],["15505.48000000","0.15300000"],["15506.67000000","0.00000000"],["15509.19000000","0.38800000"],["15511.58000000","0.19460200"],["15512.07000000","0.00000000"],["15514.61000000","0.00000000"],["15536.74000000","0.00000000"]]}}
2020-11-09T11:26:48.24832 btcusdt {"stream":"btcusdt@depth@100ms","data":{"e":"depthUpdate","E":1604921208241,"s":"BTCUSDT","U":6511141953,"u":6511142010,"b":[["15499.14000000","0.00000000"],["15499.06000000","0.00000000"],["15498.61000000","0.00000000"],["15498.21000000","0.00000000"],["15498.09000000","0.00000000"],["15498.00000000","0.05605500"],["15497.29000000","0.00000000"],["15493.43000000","0.19122800"],["15492.44000000","0.23448200"],["15492.12000000","0.28021600"],["15492.11000000","0.10845700"],["15490.12000000","0.62992900"],["15489.67000000","0.40130400"],["15489.35000000","0.25232300"],["15489.19000000","0.50197300"],["15489.00000000","1.29233700"],["15482.67000000","0.00000000"],["15482.00000000","1.19379200"],["15477.76000000","0.00000000"],["15456.00000000","2.05500000"]],"a":[["15498.32000000","0.03129900"],["15498.33000000","0.02976500"],["15498.37000000","0.50989300"],["15498.53000000","0.03228800"],["15498.62000000","0.00000000"],["15498.95000000","0.00000000"],["15498.96000000","0.00000000"],["15498.98000000","0.00000000"],["15499.07000000","0.00000000"],["15499.13000000","0.00000000"],["15499.15000000","2.66051200"],["15499.69000000","0.00000000"],["15499.71000000","0.00000000"],["15501.66000000","0.00000000"],["15501.98000000","0.00000000"],["15502.07000000","2.11692600"],["15503.04000000","0.22500100"],["15504.13000000","0.00000000"],["15504.87000000","0.15700000"],["15505.01000000","0.29200000"],["15505.83000000","0.00000000"],["15506.58000000","0.00000000"],["15506.59000000","0.00000000"],["15508.73000000","0.14850000"]]}}
2020-11-09T11:26:48.34815 btcusdt {"stream":"btcusdt@depth@100ms","data":{"e":"depthUpdate","E":1604921208341,"s":"BTCUSDT","U":6511142011,"u":6511142057,"b":[["15498.28000000","0.50000000"],["15498.21000000","1.97093700"],["15497.47000000","0.06904900"],["15494.28000000","0.00000000"],["15492.44000000","0.00000000"],["15492.43000000","0.41537900"],["15492.12000000","0.00000000"],["15490.12000000","0.00000000"],["15489.67000000","0.00000000"],["15489.35000000","0.00000000"],["15489.19000000","0.00000000"],["15489.00000000","0.00000000"],["15424.54000000","0.00000000"]],"a":[["15498.29000000","0.74376000"],["15498.31000000","0.31820000"],["15498.32000000","0.00000000"],["15498.33000000","0.00000000"],["15498.37000000","0.00000000"],["15498.50000000","0.00000000"],["15498.53000000","0.00000000"],["15499.14000000","0.00000000"],["15499.15000000","2.25219400"],["15501.66000000","0.00000000"],["15501.67000000","0.00000000"],["15502.03000000","4.80426500"],["15502.04000000","0.78253600"],["15503.91000000","0.00000000"],["15514.00000000","0.00872600"]]}}
2020-11-09T11:26:48.44881 btcusdt {"stream":"btcusdt@depth@100ms","data":{"e":"depthUpdate","E":1604921208441,"s":"BTCUSDT","U":6511142058,"u":6511142069,"b":[["15498.28000000","0.50000000"],["15498.21000000","0.00000000"],["15492.44000000","0.06748100"],["15492.10000000","0.02106400"],["15490.88000000","0.10591000"]],"a":[["15498.29000000","0.74056000"],["15502.02000000","0.78253600"],["15502.03000000","4.61943600"],["15502.04000000","0.00000000"],["15505.01000000","0.35451100"],["15528.78000000","0.01000000"]]}}
2020-11-09T11:26:48.54843 btcusdt {"stream":"btcusdt@depth@100ms","data":{"e":"depthUpdate","E":1604921208541,"s":"BTCUSDT","U":6511142070,"u":6511142078,"b":[["15498.28000000","5.80000000"],["15495.90000000","0.00000000"],["15493.43000000","0.00000000"],["15483.79000000","0.00000000"]],"a":[["15498.29000000","0.73357800"],["15499.14000000","0.84394300"],["15505.71000000","0.25783900"],["15511.80000000","0.05681900"],["15513.39000000","0.00000000"]]}}
2020-11-09T11:26:48.64848 btcusdt {"stream":"btcusdt@depth@100ms","data":{"e":"depthUpdate","E":1604921208642,"s":"BTCUSDT","U":6511142079,"u":6511142083,"b":[["15437.26000000","0.02228300"]],"a":[["15498.29000000","0.73037800"],["15504.33000000","0.20000000"],["15505.00000000","0.01000000"],["15505.58000000","0.00000000"]]}}
2020-11-09T11:26:48.74890 btcusdt {"stream":"btcusdt@depth@100ms","data":{"e":"depthUpdate","E":1604921208742,"s":"BTCUSDT","U":6511142084,"u":6511142090,"b":[["15498.28000000","5.84990000"]],"a":[["15498.29000000","0.66381700"],["15503.10000000","0.32200000"],["15507.03000000","0.00000000"],["15609.20000000","0.00161500"]]}}
2020-11-09T11:26:48.84867 btcusdt {"stream":"btcusdt@depth@100ms","data":{"e":"depthUpdate","E":1604921208842,"s":"BTCUSDT","U":6511142091,"u":6511142101,"b":[["15498.28000000","5.84785000"]],"a":[["15498.29000000","5.94690000"],["15498.31000000","0.11931600"],["15499.13000000","0.19888400"],["15499.14000000","0.00000000"],["15499.15000000","2.15219400"],["15502.01000000","0.10000000"],["15502.03000000","0.00000000"],["15502.06000000","0.30300000"],["15507.92000000","0.22705600"]]}}
2020-11-09T11:26:48.95225 btcusdt {"stream":"btcusdt@depth@100ms","data":{"e":"depthUpdate","E":1604921208942,"s":"BTCUSDT","U":6511142102,"u":6511142173,"b":[["15498.28000000","0.26766000"],["15490.87000000","0.03100000"],["15428.80000000","0.24000000"],["15420.78000000","0.00648400"]],"a":[["15498.29000000","4.54370000"],["15499.12000000","0.00000000"],["15499.15000000","2.00000000"],["15501.99000000","0.00000000"],["15502.00000000","0.93473000"],["15502.02000000","0.00000000"],["15504.04000000","0.00000000"],["15504.05000000","0.00000000"],["15504.30000000","0.00000000"],["15504.98000000","0.00000000"],["15505.27000000","0.00000000"],["15511.32000000","0.00000000"],["15512.11000000","0.24000000"],["15515.31000000","0.49950000"]]}}
2020-11-09T11:26:49.04979 btcusdt {"stream":"btcusdt@depth@100ms","data":{"e":"depthUpdate","E":1604921209042,"s":"BTCUSDT","U":6511142174,"u":6511142233,"b":[["15498.28000000","0.00000000"],["15498.00000000","0.02542700"],["15497.47000000","0.00000000"],["15497.33000000","0.00000000"],["15497.08000000","0.00000000"],["15495.94000000","0.00000000"],["15495.02000000","0.00000000"],["15494.43000000","0.02000000"],["15493.04000000","0.03225800"],["15488.59000000","0.00000000"]],"a":[["15498.01000000","1.91689400"],["15498.25000000","0.01888500"],["15498.28000000","5.91159600"],["15498.29000000","6.39603700"],["15498.31000000","0.00000000"],["15498.38000000","0.00000000"],["15498.50000000","0.00000000"],["15501.99000000","0.00000000"],["15502.05000000","0.18994900"],["15502.07000000","2.00963400"],["15502.29000000","0.00886800"],["15503.09000000","0.03400000"],["15503.21000000","0.28000000"],["15503.26000000","0.00000000"],["15503.35000000","1.74800000"],["15503.45000000","0.15700000"],["15503.58000000","1.49000000"],["15503.80000000","0.50000000"],["15503.91000000","0.25786600"],["15504.21000000","0.00000000"],["15504.29000000","0.05000000"],["15504.76000000","0.14000000"],["15504.87000000","0.00000000"],["15504.96000000","0.32100000"],["15505.01000000","0.06251100"],["15505.11000000","0.01000000"],["15505.21000000","0.28000000"],["15505.35000000","0.00000000"],["15505.47000000","0.00000000"],["15506.86000000","0.00000000"],["15507.29000000","0.00000000"],["15507.44000000","0.00000000"],["15507.53000000","0.00000000"],["15507.93000000","0.00000000"],["15514.28000000","0.00000000"]]}}
2020-11-09T11:26:49.14878 btcusdt {"stream":"btcusdt@depth@100ms","data":{"e":"depthUpdate","E":1604921209142,"s":"BTCUSDT","U":6511142234,"u":6511142264,"b":[["15491.40000000","0.00000000"],["15485.75000000","0.00000000"],["15459.54000000","0.25000000"]],"a":[["15498.01000000","4.27913100"],["15498.05000000","0.03228800"],["15498.24000000","0.00000000"],["15498.27000000","0.78253600"],["15498.28000000","0.10000000"],["15498.29000000","2.03213100"],["15501.99000000","0.49783600"],["15502.00000000","0.15219400"],["15502.01000000","0.00000000"],["15502.07000000","0.13000000"],["15502.56000000","0.03226200"],["15503.10000000","0.00000000"],["15505.16000000","0.00000000"],["15506.33000000","0.20000000"],["15509.98000000","0.30000000"],["15513.02000000","0.00000000"],["15537.03000000","0.25202500"]]}}
2020-11-09T11:26:49.24823 btcusdt {"stream":"btcusdt@depth@100ms","data":{"e":"depthUpdate","E":1604921209242,"s":"BTCUSDT","U":6511142265,"u":6511142283,"b":[["15494.34000000","0.50000000"],["15493.57000000","0.08400000"],["15485.76000000","0.00000000"],["15485.45000000","1.50000000"]],"a":[["15498.01000000","4.42644900"],["15498.27000000","0.00000000"],["15501.62000000","0.50000000"],["15501.98000000","0.20000000"],["15501.99000000","0.28283600"],["15502.00000000","0.00000000"],["15503.61000000","0.01000000"],["15504.84000000","0.01500000"],["15505.11000000","0.00000000"],["15505.98000000","0.00000000"],["15507.13000000","0.00000000"],["15509.32000000","0.00000000"]]}}
2020-11-09T11:26:49.34888 btcusdt {"stream":"btcusdt@depth@100ms","data":{"e":"depthUpdate","E":1604921209342,"s":"BTCUSDT","U":6511142284,"u":6511142296,"b":[["15498.00000000","0.02742700"],["15486.43000000","1.50000000"],["15485.45000000","0.00000000"]],"a":[["15498.01000000","2.33856500"],["15498.29000000","0.03213100"],["15498.48000000","0.00200000"],["15501.60000000","0.31453300"],["15501.61000000","0.12906300"],["15501.97000000","0.61742200"],["15501.98000000","0.32905900"],["15503.20000000","1.01400100"]]}}
2020-11-09T11:26:49.58253 btcusdt {"stream":"btcusdt@depth@100ms","data":{"e":"depthUpdate","E":1604921209442,"s":"BTCUSDT","U":6511142297,"u":6511142322,"b":[["15498.00000000","5.27742700"],["15486.43000000","0.00000000"],["15485.98000000","1.50000000"],["15420.78000000","0.00000000"],["15188.04000000","0.00174700"]],"a":[["15498.01000000","1.81773400"],["15498.05000000","0.00000000"],["15499.12000000","1.09944400"],["15499.13000000","0.00000000"],["15501.59000000","0.19888400"],["15501.98000000","0.20000000"],["15501.99000000","0.28000000"],["15502.19000000","0.03400000"],["15502.43000000","0.89013200"],["15502.44000000","1.74800000"],["15503.09000000","0.00000000"],["15503.20000000","0.00000000"],["15503.35000000","0.00000000"],["15503.44000000","0.97500000"],["15503.87000000","0.00000000"]]}}
2020-11-09T11:26:49.58289 btcusdt {"stream":"btcusdt@depth@100ms","data":{"e":"depthUpdate","E":1604921209542,"s":"BTCUSDT","U":6511142323,"u":6511142341,"b":[["15498.00000000","7.85652900"],["15477.80000000","0.29100000"]],"a":[["15498.01000000","1.79708900"],["15498.25000000","0.00000000"],["15498.28000000","0.00000000"],["15498.29000000","0.00000000"],["15501.58000000","0.47554100"],["15501.59000000","0.45107800"],["15501.60000000","0.00000000"],["15501.61000000","0.00000000"],["15501.99000000","0.08000000"],["15505.00000000","0.00000000"],["15506.82000000","0.00000000"],["15509.89000000","0.05681900"],["15511.80000000","0.00000000"]]}}
2020-11-09T11:26:49.65198 btcusdt {"stream":"btcusdt@depth@100ms","data":{"e":"depthUpdate","E":1604921209642,"s":"BTCUSDT","U":6511142342,"u":6511142352,"b":[["15490.41000000","1.00000000"],["15487.33000000","0.00000000"],["15486.17000000","1.50000000"],["15485.98000000","0.00000000"]],"a":[["15498.01000000","1.79388900"],["15501.97000000","0.29897400"],["15502.06000000","0.00000000"],["15502.07000000","0.12800000"],["15504.44000000","0.01200000"],["15505.56000000","0.12904500"]]}}
2020-11-09T11:26:49.75008 btcusdt {"stream":"btcusdt@depth@100ms","data":{"e":"depthUpdate","E":1604921209742,"s":"BTCUSDT","U":6511142353,"u":6511142363,"b":[["15498.00000000","6.80652900"],["15493.05000000","0.04780600"],["15491.67000000","0.00000000"],["15489.67000000","0.20000000"],["15466.38000000","0.00322700"]],"a":[["15498.01000000","1.79068900"],["15501.96000000","0.29897500"],["15501.97000000","0.00000000"],["15502.82000000","0.32100000"],["15570.02000000","0.00070600"]]}}
2020-11-09T11:26:49.85497 btcusdt {"stream":"btcusdt@depth@100ms","data":{"e":"depthUpdate","E":1604921209842,"s":"BTCUSDT","U":6511142364,"u":6511142370,"b":[["15498.00000000","2.60652900"],["15497.23000000","0.01681300"],["15493.04000000","0.00000000"],["15420.51000000","0.00648400"]],"a":[["15498.01000000","1.64469900"],["15501.58000000","0.49161400"],["15504.13000000","0.20000000"]]}}
2020-11-09T11:26:49.95119 btcusdt {"stream":"btcusdt@depth@100ms","data":{"e":"depthUpdate","E":1604921209942,"s":"BTCUSDT","U":6511142371,"u":6511142382,"b":[["15498.00000000","2.60575100"],["15497.29000000","0.00747200"],["15495.74000000","0.03225900"],["15494.32000000","0.11427900"],["15493.06000000","0.10591000"],["15491.44000000","0.47379500"],["15490.88000000","0.00000000"],["15480.03000000","0.01922500"],["15466.38000000","0.00000000"]],"a":[["15501.61000000","0.00944200"],["15502.29000000","0.00000000"],["15513.33000000","0.00000000"]]}}
2020-11-09T11:26:50.05130 btcusdt {"stream":"btcusdt@depth@100ms","data":{"e":"depthUpdate","E":1604921210042,"s":"BTCUSDT","U":6511142383,"u":6511142397,"b":[["15498.00000000","2.60575100"],["15492.43000000","0.36537900"],["15492.11000000","0.15845700"],["15491.44000000","0.00000000"],["15188.04000000","0.00000000"]],"a":[["15498.01000000","1.58452600"],["15501.40000000","0.47166500"],["15501.41000000","0.94332600"],["15502.05000000","0.00000000"],["15503.53000000","0.05000000"],["15504.29000000","0.00000000"],["15506.16000000","0.00000000"]]}}
2020-11-09T11:26:50.15042 btcusdt {"stream":"btcusdt@depth@100ms","data":{"e":"depthUpdate","E":1604921210142,"s":"BTCUSDT","U":6511142398,"u":6511142398,"b":[],"a":[["15570.15000000","0.00408600"]]}}
2020-11-09T11:26:50.25039 btcusdt {"stream":"btcusdt@depth@100ms","data":{"e":"depthUpdate","E":1604921210242,"s":"BTCUSDT","U":6511142399,"u":6511142407,"b":[["15498.00000000","7.90575100"]],"a":[["15498.01000000","0.26272800"],["15499.12000000","0.00000000"],["15501.96000000","0.00000000"],["15503.44000000","0.98500000"],["15503.61000000","0.00000000"],["15503.88000000","0.00000000"],["15504.13000000","0.00000000"]]}}
2020-11-09T11:26:50.35031 btcusdt {"stream":"btcusdt@depth@100ms","data":{"e":"depthUpdate","E":1604921210342,"s":"BTCUSDT","U":6511142408,"u":6511142452,"b":[["15498.47000000","6.26566500"],["15498.04000000","0.00000000"],["15498.00000000","2.10575100"],["15497.78000000","0.00000000"],["15497.23000000","0.00000000"],["15496.49000000","0.01617600"],["15494.85000000","0.11427900"],["15494.34000000","0.00000000"],["15494.32000000","0.00000000"],["15491.09000000","0.22500000"],["15420.51000000","0.00000000"],["14561.00000000","0.06388700"]],"a":[["15498.01000000","0.00000000"],["15499.15000000","0.00000000"],["15500.74000000","0.01715200"],["15501.40000000","0.00000000"],["15501.41000000","0.00000000"],["15501.58000000","0.06452300"],["15501.59000000","0.15219400"],["15502.07000000","0.00000000"],["15502.43000000","0.00000000"],["15502.81000000","0.10000000"],["15502.82000000","0.00000000"],["15503.43000000","0.00000000"],["15503.44000000","0.01000000"],["15503.49000000","0.11427900"],["15504.83000000","0.00000000"],["15505.13000000","0.75000000"],["15514.00000000","0.00000000"]]}}
2020-11-09T11:26:50.44994 btcusdt {"stream":"btcusdt@depth@100ms","data":{"e":"depthUpdate","E":1604921210442,"s":"BTCUSDT","U":6511142453,"u":6511142475,"b":[["15498.47000000","12.55595500"],["15497.29000000","0.00000000"],["15493.05000000","0.00000000"],["15492.44000000","0.11748100"],["15492.11000000","0.10845700"],["15491.67000000","0.20000000"],["15428.80000000","0.00000000"]],"a":[["15501.61000000","0.00000000"],["15503.44000000","0.00000000"],["15503.53000000","0.00000000"],["15503.54000000","0.00000000"],["15503.91000000","0.00000000"],["15504.25000000","0.05000000"],["15504.37000000","0.01000000"],["15504.44000000","0.00200000"],["15504.84000000","0.00000000"],["15506.17000000","0.01000000"],["15506.48000000","0.01934700"],["15506.57000000","0.01500000"],["15511.77000000","0.00000000"],["15513.28000000","0.25784000"],["15514.00000000","0.00801700"]]}}
2020-11-09T11:26:50.55066 btcusdt {"stream":"btcusdt@depth@100ms","data":{"e":"depthUpdate","E":1604921210542,"s":"BTCUSDT","U":6511142476,"u":6511142491,"b":[["15498.47000000","7.19990600"],["15498.01000000","0.16500000"],["15494.44000000","0.04780600"],["15493.57000000","0.00400000"],["15491.05000000","0.29100000"],["15489.60000000","0.00306000"]],"a":[["15498.48000000","0.74486300"],["15501.59000000","0.00000000"],["15503.03000000","0.15219400"],["15515.01000000","0.00000000"],["15603.00000000","0.11827300"]]}}
2020-11-09T11:26:50.64913 btcusdt {"stream":"btcusdt@depth@100ms","data":{"e":"depthUpdate","E":1604921210643,"s":"BTCUSDT","U":6511142492,"u":6511142513,"b":[["15494.43000000","0.00000000"],["15492.11000000","0.38845700"]],"a":[["15500.73000000","0.08000000"],["15501.57000000","0.28226100"],["15501.58000000","0.00000000"],["15502.43000000","0.89013200"],["15502.96000000","0.79104700"],["15502.97000000","1.19800000"],["15503.43000000","0.28164000"],["15503.44000000","0.00000000"],["15503.58000000","0.29200000"],["15503.79000000","0.25000000"],["15504.13000000","0.26333000"],["15504.25000000","0.00000000"],["15504.36000000","0.05000000"],["15505.00000000","0.56525700"],["15505.70000000","0.53341900"],["15506.32000000","0.72500200"],["15513.14000000","0.00000000"]]}}
2020-11-09T11:26:50.75073 btcusdt {"stream":"btcusdt@depth@100ms","data":{"e":"depthUpdate","E":1604921210743,"s":"BTCUSDT","U":6511142514,"u":6511142523,"b":[["15493.69000000","0.97000000"],["15492.11000000","0.10845700"]],"a":[["15498.48000000","0.68440000"],["15501.56000000","0.15219400"],["15502.77000000","0.18000000"],["15503.03000000","0.00000000"],["15504.76000000","0.00000000"],["15513.52000000","1.50000000"],["15554.50000000","0.00000000"],["15561.00000000","0.64156100"]]}}
2020-11-09T11:26:50.85041 btcusdt {"stream":"btcusdt@depth@100ms","data":{"e":"depthUpdate","E":1604921210843,"s":"BTCUSDT","U":6511142524,"u":6511142532,"b":[["15494.14000000","0.54600000"],["15492.99000000","2.00000000"],["15420.97000000","0.00648400"]],"a":[["15501.22000000","0.20000000"],["15502.68000000","0.16000000"],["15503.21000000","0.00000000"],["15503.22000000","0.20000000"],["15504.96000000","0.00000000"],["15505.21000000","0.00000000"]]}}
2020-11-09T11:26:50.94897 btcusdt {"stream":"btcusdt@depth@100ms","data":{"e":"depthUpdate","E":1604921210943,"s":"BTCUSDT","U":6511142533,"u":6511142543,"b":[["15497.13000000","0.01985600"],["15496.49000000","0.00000000"],["15493.06000000","0.00000000"],["15491.67000000","0.00000000"],["15429.16000000","0.24000000"]],"a":[["15500.74000000","0.00000000"],["15501.39000000","0.01512700"],["15501.98000000","0.00000000"],["15503.21000000","0.26100200"],["15503.29000000","0.32200000"],["15556.00000000","2.75486200"]]}}
2020-11-09T11:26:51.05114 btcusdt {"stream":"btcusdt@depth@100ms","data":{"e":"depthUpdate","E":1604921211043,"s":"BTCUSDT","U":6511142544,"u":6511142551,"b":[["15497.01000000","0.00910400"],["15496.31000000","0.10591000"],["15493.00000000","0.05000000"],["15492.44000000","0.06748100"],["15490.94000000","0.54066200"]],"a":[["15501.26000000","0.00834400"],["15503.48000000","0.05000000"],["15504.36000000","0.00000000"]]}}
2020-11-09T11:26:51.15010 btcusdt {"stream":"btcusdt@depth@100ms","data":{"e":"depthUpdate","E":1604921211143,"s":"BTCUSDT","U":6511142552,"u":6511142553,"b":[["15496.31000000","0.00000000"],["15493.70000000","0.10591000"]],"a":[]}}
2020-11-09T11:26:51.25139 btcusdt {"stream":"btcusdt@depth@100ms","data":{"e":"depthUpdate","E":1604921211243,"s":"BTCUSDT","U":6511142554,"u":6511142555,"b":[],"a":[["15503.42000000","0.01000000"],["15504.37000000","0.00000000"]]}}
2020-11-09T11:26:51.35404 btcusdt {"stream":"btcusdt@depth@100ms","data":{"e":"depthUpdate","E":1604921211343,"s":"BTCUSDT","U":6511142556,"u":6511142558,"b":[["15498.47000000","7.20190600"]],"a":[["15505.85000000","0.00000000"],["15510.18000000","1.30941100"]]}}
2020-11-09T11:26:51.45196 btcusdt {"stream":"btcusdt@depth@100ms","data":{"e":"depthUpdate","E":1604921211443,"s":"BTCUSDT","U":6511142559,"u":6511142560,"b":[["15411.00000000","0.71284400"]],"a":[["15498.48000000","0.62439300"]]}}
2020-11-09T11:26:51.55043 btcusdt {"stream":"btcusdt@depth@100ms","data":{"e":"depthUpdate","E":1604921211543,"s":"BTCUSDT","U":6511142561,"u":6511142566,"b":[["15498.47000000","12.82858500"],["15497.13000000","0.00000000"],["15497.01000000","0.00000000"]],"a":[["15501.26000000","0.00000000"],["15501.39000000","0.00000000"]]}}
2020-11-09T11:26:51.65135 btcusdt {"stream":"btcusdt@depth@100ms","data":{"e":"depthUpdate","E":1604921211643,"s":"BTCUSDT","U":6511142567,"u":6511142570,"b":[["15498.47000000","7.52858500"],["15488.99000000","0.00000000"]],"a":[["15504.89000000","0.01000000"],["15506.17000000","0.00000000"]]}}
2020-11-09T11:26:51.75523 btcusdt {"stream":"btcusdt@depth@100ms","data":{"e":"depthUpdate","E":1604921211743,"s":"BTCUSDT","U":6511142571,"u":6511142576,"b":[["15495.74000000","0.00000000"],["15493.70000000","0.00000000"],["15487.40000000","1.00934600"]],"a":[["15504.11000000","0.48832900"],["15504.12000000","0.50000000"],["15504.13000000","0.00000000"]]}}
2020-11-09T11:26:51.85359 btcusdt {"stream":"btcusdt@depth@100ms","data":{"e":"depthUpdate","E":1604921211843,"s":"BTCUSDT","U":6511142577,"u":6511142591,"b":[["15498.47000000","3.23829500"],["15498.00000000","2.10375100"],["15495.75000000","0.00000000"],["15494.45000000","0.10591000"],["15490.94000000","0.00000000"],["15490.41000000","0.00000000"],["15489.34000000","0.00000000"],["15487.76000000","0.50472200"],["15487.05000000","1.00000000"]],"a":[["15503.41000000","0.20000000"],["15503.43000000","0.48052400"],["15503.49000000","0.00000000"],["15554.00000000","14.41037700"],["15603.00000000","0.01000000"]]}}
2020-11-09T11:26:51.95242 btcusdt {"stream":"btcusdt@depth@100ms","data":{"e":"depthUpdate","E":1604921211943,"s":"BTCUSDT","U":6511142592,"u":6511142599,"b":[["15498.47000000","1.17829500"],["15494.85000000","0.00000000"],["15487.05000000","0.00000000"],["15352.73000000","0.00000000"]],"a":[["15503.43000000","0.00000000"],["15504.10000000","0.20000000"]]}}
2020-11-09T11:26:52.05023 btcusdt {"stream":"btcusdt@depth@100ms","data":{"e":"depthUpdate","E":1604921212043,"s":"BTCUSDT","U":6511142600,"u":6511142614,"b":[["15498.47000000","3.17829500"],["15493.00000000","0.00000000"],["15492.45000000","0.05000000"],["15489.95000000","1.00000000"],["15484.97000000","0.13447900"]],"a":[["15501.55000000","0.10000000"],["15502.81000000","0.00000000"],["15503.41000000","0.00000000"],["15503.42000000","0.06000000"],["15503.48000000","0.00000000"],["15504.10000000","0.00000000"],["15508.59000000","0.13447900"],["15553.00000000","2.09109100"],["15558.00000000","2.11115200"],["15600.00000000","211.94775300"]]}}
2020-11-09T11:26:52.14954 btcusdt {"stream":"btcusdt@depth@100ms","data":{"e":"depthUpdate","E":1604921212143,"s":"BTCUSDT","U":6511142615,"u":6511142615,"b":[],"a":[["15504.10000000","0.20000000"]]}}
2020-11-09T11:26:52.25416 btcusdt {"stream":"btcusdt@depth@100ms","data":{"e":"depthUpdate","E":1604921212243,"s":"BTCUSDT","U":6511142616,"u":6511142625,"b":[["15498.47000000","7.87320400"],["15400.00000000","4.40536000"]],"a":[["15498.48000000","0.56417700"],["15503.42000000","0.05000000"],["15503.57000000","0.01000000"],["15504.10000000","0.00000000"],["15505.29000000","0.01500000"],["15506.57000000","0.00000000"],["15507.46000000","0.03362000"]]}}
2020-11-09T11:26:52.35149 btcusdt {"stream":"btcusdt@depth@100ms","data":{"e":"depthUpdate","E":1604921212343,"s":"BTCUSDT","U":6511142626,"u":6511142629,"b":[["15497.49000000","0.00980000"]],"a":[["15501.82000000","0.00993600"],["15503.21000000","0.78890500"],["15503.32000000","1.05580900"]]}}
2020-11-09T11:26:52.45149 btcusdt {"stream":"btcusdt@depth@100ms","data":{"e":"depthUpdate","E":1604921212443,"s":"BTCUSDT","U":6511142630,"u":6511142637,"b":[["15498.47000000","8.47320400"],["15497.60000000","0.01705500"],["15486.57000000","0.87000000"],["15479.05000000","0.00000000"]],"a":[["15498.48000000","0.56216400"],["15501.72000000","0.01708500"],["15507.46000000","0.00000000"],["15508.59000000","0.00000000"]]}}
2020-11-09T11:26:52.54958 btcusdt {"stream":"btcusdt@depth@100ms","data":{"e":"depthUpdate","E":1604921212543,"s":"BTCUSDT","U":6511142638,"u":6511142641,"b":[["15498.47000000","8.47120400"],["15387.00000000","0.37683000"]],"a":[["15509.16000000","0.03362000"],["15510.11000000","0.13447900"]]}}
2020-11-09T11:26:52.65270 btcusdt {"stream":"btcusdt@depth@100ms","data":{"e":"depthUpdate","E":1604921212644,"s":"BTCUSDT","U":6511142642,"u":6511142644,"b":[["14892.14000000","0.00000000"]],"a":[["15501.79000000","0.00957700"],["15501.82000000","0.00000000"]]}}
2020-11-09T11:26:52.85068 btcusdt {"stream":"btcusdt@depth@100ms","data":{"e":"depthUpdate","E":1604921212844,"s":"BTCUSDT","U":6511142645,"u":6511142646,"b":[["15489.63000000","1.50000000"],["15486.17000000","0.00000000"]],"a":[]}}
2020-11-09T11:26:52.95120 btcusdt {"stream":"btcusdt@depth@100ms","data":{"e":"depthUpdate","E":1604921212944,"s":"BTCUSDT","U":6511142647,"u":6511142706,"b":[["15500.58000000","0.64900000"],["15500.07000000","0.49421000"],["15500.03000000","0.50000000"],["15499.29000000","0.00000000"],["15499.26000000","0.03796900"],["15499.25000000","0.00000000"],["15498.57000000","0.03955100"],["15498.55000000","0.03955100"],["15498.51000000","0.06901900"],["15498.49000000","0.03796900"],["15498.48000000","0.04084100"],["15498.47000000","7.72629500"],["15495.01000000","1.25000000"],["15493.69000000","0.00000000"],["15491.67000000","0.20000000"],["15491.44000000","0.44457300"],["15487.68000000","0.00000000"]],"a":[["15498.48000000","0.00000000"],["15500.59000000","0.57417000"],["15500.72000000","0.03231700"],["15501.22000000","0.00000000"],["15501.56000000","0.00000000"],["15501.57000000","0.00000000"],["15502.19000000","0.00000000"],["15502.43000000","0.00000000"],["15502.44000000","0.00000000"],["15502.68000000","0.00000000"],["15502.76000000","0.01700000"],["15502.77000000","0.00000000"],["15502.78000000","0.20000000"],["15502.96000000","0.00000000"],["15502.97000000","0.00000000"],["15503.00000000","1.74800000"],["15503.21000000","0.00000000"],["15503.32000000","0.00000000"],["15503.45000000","0.00000000"],["15503.51000000","0.00000000"],["15503.79000000","0.00000000"],["15504.11000000","0.00000000"],["15504.12000000","0.00000000"],["15504.20000000","0.02000000"],["15504.23000000","0.16000000"],["15504.32000000","0.15700000"],["15504.78000000","0.20000000"],["15505.00000000","0.00000000"],["15505.13000000","0.00000000"],["15505.70000000","0.00000000"],["15506.32000000","0.00000000"],["15506.47000000","0.00000000"],["15508.97000000","1.25000000"]]}}
2020-11-09T11:26:53.05357 btcusdt {"stream":"btcusdt@depth@100ms","data":{"e":"depthUpdate","E":1604921213044,"s":"BTCUSDT","U":6511142707,"u":6511142780,"b":[["15500.58000000","1.26860500"],["15500.28000000","0.00000000"],["15500.14000000","0.00000000"],["15500.03000000","0.00000000"],["15499.75000000","0.00000000"],["15499.53000000","0.00690000"],["15499.31000000","0.00000000"],["15499.26000000","0.00000000"],["15498.57000000","0.00000000"],["15498.55000000","0.00000000"],["15498.51000000","0.00000000"],["15498.49000000","0.00000000"],["15498.48000000","0.14129000"],["15498.47000000","7.33074700"],["15498.01000000","0.00000000"],["15498.00000000","2.02464900"],["15495.57000000","0.54600000"],["15495.41000000","0.42000000"],["15494.73000000","2.00000000"],["15494.14000000","0.00000000"],["15493.00000000","0.05000000"],["15492.99000000","0.00000000"],["15492.45000000","0.00000000"],["15491.67000000","0.00000000"],["15488.50000000","0.15150000"],["15482.99000000","0.29400000"]],"a":[["15500.59000000","0.00819000"],["15500.72000000","0.00000000"],["15500.73000000","0.00000000"],["15501.55000000","0.00000000"],["15502.56000000","0.00000000"],["15502.76000000","0.03400000"],["15503.22000000","0.00000000"],["15503.29000000","0.00000000"],["15503.31000000","0.00000000"],["15503.42000000","0.00000000"],["15503.57000000","0.00000000"],["15503.58000000","0.00000000"],["15503.80000000","0.00000000"],["15504.13000000","0.10000000"],["15504.14000000","0.47665900"],["15504.32000000","0.00000000"],["15504.72000000","1.19800000"],["15504.89000000","0.00000000"],["15504.99000000","0.29200000"],["15505.07000000","0.05000000"],["15505.08000000","0.15700000"],["15505.20000000","0.01200000"],["15505.29000000","0.00000000"],["15505.48000000","0.00000000"],["15505.65000000","0.00000000"],["15506.08000000","0.50000000"],["15506.91000000","0.00000000"],["15507.00000000","0.01000000"],["15507.40000000","0.01500000"],["15508.09000000","0.75000000"],["15513.52000000","0.00000000"]]}}
2020-11-09T11:26:53.15212 btcusdt {"stream":"btcusdt@depth@100ms","data":{"e":"depthUpdate","E":1604921213144,"s":"BTCUSDT","U":6511142781,"u":6511142798,"b":[["15500.58000000","1.67609400"],["15500.28000000","0.06901900"],["15494.44000000","0.00000000"],["15492.09000000","0.00000000"],["15429.16000000","0.00000000"]],"a":[["15504.71000000","0.15219400"],["15505.15000000","0.03225500"],["15505.56000000","0.00000000"],["15505.74000000","0.11427900"],["15506.08000000","0.00000000"],["15506.32000000","0.50000000"],["15508.24000000","0.12902200"],["15508.97000000","0.00000000"],["15510.26000000","1.25000000"],["15510.72000000","0.00000000"],["15512.11000000","0.00000000"],["15513.84000000","0.00000000"]]}}
2020-11-09T11:26:53.25195 btcusdt {"stream":"btcusdt@depth@100ms","data":{"e":"depthUpdate","E":1604921213244,"s":"BTCUSDT","U":6511142799,"u":6511142817,"b":[["15500.58000000","6.27609400"],["15498.49000000","0.04780600"],["15498.47000000","7.32874700"],["15496.98000000","0.02106400"],["15494.46000000","0.02500000"],["15492.10000000","0.00000000"],["15350.00000000","5.02229500"]],"a":[["15501.61000000","0.25854200"],["15502.99000000","0.98995100"],["15504.12000000","0.37833100"],["15504.70000000","0.77509700"],["15504.98000000","0.43975600"],["15505.84000000","0.00000000"],["15506.32000000","0.00000000"],["15507.13000000","0.97541400"],["15507.17000000","0.50000000"],["15514.55000000","0.00000000"],["15516.41000000","0.02500000"],["15561.00000000","0.26473100"]]}}
2020-11-09T11:26:53.35275 btcusdt {"stream":"btcusdt@depth@100ms","data":{"e":"depthUpdate","E":1604921213344,"s":"BTCUSDT","U":6511142818,"u":6511142830,"b":[["15498.49000000","0.00000000"],["15496.31000000","0.04780600"],["15492.95000000","0.50000000"],["15492.11000000","0.00000000"],["15489.66000000","0.00000000"],["15420.97000000","0.00000000"]],"a":[["15504.71000000","0.00000000"],["15505.70000000","0.15219400"],["15506.32000000","0.26050000"],["15506.33000000","0.52100000"],["15508.97000000","1.25000000"],["15510.26000000","0.00000000"],["15516.01000000","1.15976100"]]}}
2020-11-09T11:26:53.45183 btcusdt {"stream":"btcusdt@depth@100ms","data":{"e":"depthUpdate","E":1604921213444,"s":"BTCUSDT","U":6511142831,"u":6511142833,"b":[["15480.03000000","0.00000000"]],"a":[["15505.71000000","0.00000000"],["15558.00000000","2.00287900"]]}}
2020-11-09T11:26:53.55134 btcusdt {"stream":"btcusdt@depth@100ms","data":{"e":"depthUpdate","E":1604921213544,"s":"BTCUSDT","U":6511142834,"u":6511142862,"b":[["15501.36000000","0.50000000"],["15501.09000000","0.00690000"],["15500.61000000","0.15504000"],["15500.59000000","0.07593800"],["15500.58000000","5.77809400"],["15500.31000000","0.06901900"],["15500.28000000","0.00000000"],["15500.07000000","0.00000000"],["15479.00000000","0.00000000"]],"a":[["15500.59000000","0.00000000"],["15500.60000000","0.00000000"],["15501.61000000","0.00000000"],["15501.94000000","0.03231700"],["15502.76000000","0.01700000"],["15502.99000000","0.00000000"],["15503.00000000","0.00000000"],["15504.12000000","0.00000000"],["15504.69000000","0.15219400"],["15504.70000000","0.00000000"],["15504.98000000","0.00000000"],["15505.69000000","0.50000000"],["15505.70000000","0.00000000"],["15506.32000000","0.00000000"],["15509.89000000","0.00000000"],["15510.89000000","0.35381900"],["15511.95000000","0.00000000"],["15514.15000000","0.13446700"],["15514.69000000","0.25781400"]]}}
2020-11-09T11:26:53.65114 btcusdt {"stream":"btcusdt@depth@100ms","data":{"e":"depthUpdate","E":1604921213644,"s":"BTCUSDT","U":6511142863,"u":6511142923,"b":[["15501.61000000","3.87910200"],["15501.60000000","0.00000000"],["15501.37000000","0.09278700"],["15501.36000000","0.07910200"],["15500.61000000","0.00000000"],["15500.59000000","0.00000000"],["15500.58000000","4.81160500"],["15498.49000000","0.04780600"],["15498.48000000","0.19129000"],["15498.47000000","2.00000000"],["15496.31000000","0.00000000"],["15493.04000000","0.15300000"],["15493.00000000","0.00000000"],["15492.98000000","0.00294000"],["15490.88000000","0.14550000"],["15489.95000000","0.00000000"],["15476.91000000","0.00000000"],["15402.85000000","0.00000000"],["15372.94000000","0.38379100"],["15370.71000000","0.00000000"]],"a":[["15501.62000000","0.50690000"],["15501.94000000","0.00000000"],["15502.76000000","0.00000000"],["15504.13000000","0.00000000"],["15504.46000000","0.03400000"],["15504.70000000","1.74800000"],["15504.72000000","0.00000000"],["15504.99000000","0.00000000"],["15505.07000000","0.00000000"],["15505.15000000","1.23025500"],["15505.20000000","0.00200000"],["15505.68000000","0.10000000"],["15505.70000000","0.29200000"],["15506.05000000","0.05000000"],["15506.18000000","0.01000000"],["15507.00000000","0.00000000"],["15507.13000000","0.00000000"],["15507.40000000","0.00000000"],["15507.76000000","0.00000000"],["15507.99000000","0.01000000"],["15508.38000000","0.01500000"],["15508.73000000","0.00000000"],["15509.98000000","0.00000000"],["15510.11000000","0.00000000"],["15510.18000000","0.30000000"],["15511.76000000","0.00000000"],["15512.85000000","0.30000000"],["15513.34000000","0.36972600"],["15603.00000000","0.11827300"]]}}
2020-11-09T11:26:53.75139 btcusdt {"stream":"btcusdt@depth@100ms","data":{"e":"depthUpdate","E":1604921213744,"s":"BTCUSDT","U":6511142924,"u":6511142974,"b":[["15501.61000000","0.89659100"],["15500.59000000","0.10591000"],["15498.49000000","0.00000000"],["15497.83000000","0.12000000"],["15497.60000000","0.00000000"],["15497.19000000","0.54600000"],["15497.15000000","0.72000000"],["15496.31000000","0.04780600"],["15495.57000000","0.00000000"],["15495.41000000","0.00000000"],["15494.73000000","0.00000000"],["15494.45000000","0.00000000"],["15493.78000000","0.19465200"],["15492.96000000","1.00000000"],["15488.86000000","1.00939500"],["15487.40000000","0.00000000"],["14431.56000000","0.00000000"]],"a":[["15501.72000000","0.00000000"],["15501.99000000","0.00000000"],["15502.78000000","0.00000000"],["15503.62000000","0.00000000"],["15504.20000000","0.00000000"],["15504.23000000","0.00000000"],["15504.64000000","0.04000000"],["15504.78000000","0.00000000"],["15505.08000000","0.00000000"],["15505.15000000","0.03225500"],["15505.70000000","0.00000000"],["15505.74000000","0.11427900"],["15505.83000000","0.00000000"],["15505.91000000","0.00000000"],["15506.17000000","1.19800000"],["15506.18000000","0.09000000"],["15506.60000000","0.00000000"],["15506.64000000","0.33200000"],["15506.79000000","0.15700000"],["15506.92000000","0.02000000"],["15507.13000000","0.00000000"],["15507.17000000","0.00000000"],["15507.92000000","0.72705600"],["15508.97000000","0.00000000"],["15510.53000000","1.25000000"],["15512.06000000","0.13446900"],["15513.28000000","1.26720200"],["15515.20000000","1.00000000"]]}}
2020-11-09T11:26:53.85130 btcusdt {"stream":"btcusdt@depth@100ms","data":{"e":"depthUpdate","E":1604921213844,"s":"BTCUSDT","U":6511142975,"u":6511143001,"b":[["15501.61000000","0.57910200"],["15501.49000000","0.06901900"],["15501.45000000","0.00000000"],["15500.31000000","0.00000000"],["15499.76000000","0.01964300"],["15489.67000000","0.00000000"],["15487.76000000","0.00000000"],["15424.10000000","0.00648300"]],"a":[["15501.62000000","0.00690000"],["15503.82000000","0.01998800"],["15504.46000000","0.00000000"],["15504.63000000","0.10000000"],["15504.70000000","0.00000000"],["15505.15000000","0.00000000"],["15505.67000000","0.03400000"],["15505.68000000","0.00000000"],["15505.74000000","0.00000000"],["15505.91000000","1.74800000"],["15506.16000000","0.19888400"],["15507.91000000","0.20000000"],["15508.09000000","0.00000000"],["15508.24000000","0.00000000"],["15509.42000000","0.75000000"],["15513.34000000","0.00000000"]]}}
2020-11-09T11:26:53.95248 btcusdt {"stream":"btcusdt@depth@100ms","data":{"e":"depthUpdate","E":1604921213944,"s":"BTCUSDT","U":6511143002,"u":6511143026,"b":[["15501.53000000","0.06901900"],["15501.49000000","0.00000000"],["15500.18000000","0.00695600"],["15497.49000000","0.00000000"],["15492.44000000","0.00000000"],["15489.22000000","0.50466100"],["15442.20000000","0.24000000"],["15402.16000000","0.00383000"],["15387.00000000","0.00000000"]],"a":[["15501.79000000","0.00000000"],["15504.29000000","0.00876300"],["15506.33000000","0.20000000"],["15507.75000000","0.32100000"],["15508.02000000","0.03225500"],["15508.97000000","1.25000000"],["15509.16000000","0.00000000"],["15510.53000000","0.00000000"],["15510.73000000","0.03361700"],["15510.91000000","0.12902200"],["15511.58000000","0.00000000"],["15512.49000000","0.12892800"],["15513.28000000","0.25784000"],["15513.34000000","0.36972700"],["15516.15000000","0.50000000"],["15517.31000000","0.24000000"]]}}
2020-11-09T11:26:54.05116 btcusdt {"stream":"btcusdt@depth@100ms","data":{"e":"depthUpdate","E":1604921214044,"s":"BTCUSDT","U":6511143027,"u":6511143037,"b":[["15498.49000000","0.04780600"],["15498.48000000","0.14129000"],["15497.16000000","0.05000000"],["15496.31000000","0.00000000"],["15490.87000000","0.00000000"]],"a":[["15506.05000000","0.00000000"],["15506.16000000","0.00000000"],["15506.17000000","1.24800000"],["15513.34000000","0.00000000"],["15514.91000000","1.01622200"],["15546.82000000","0.00000000"]]}}
2020-11-09T11:26:54.15122 btcusdt {"stream":"btcusdt@depth@100ms","data":{"e":"depthUpdate","E":1604921214144,"s":"BTCUSDT","U":6511143038,"u":6511143078,"b":[["15502.32000000","0.54486900"],["15501.67000000","0.06901900"],["15501.66000000","0.08417500"],["15501.65000000","0.15504000"],["15501.64000000","0.03955100"],["15501.62000000","0.00000000"],["15501.61000000","0.00000000"],["15501.55000000","0.07910200"],["15501.53000000","0.00000000"],["15501.37000000","0.00000000"],["15501.36000000","0.00000000"],["15495.02000000","0.20000000"],["15490.01000000","0.69199600"],["15462.36000000","0.03100000"],["15459.54000000","0.00000000"],["15411.00000000","1.08967400"]],"a":[["15501.62000000","0.00000000"],["15502.33000000","0.00690000"],["15503.04000000","0.17145400"],["15503.32000000","0.03231700"],["15505.67000000","0.00000000"],["15505.91000000","0.00000000"],["15506.17000000","0.05000000"],["15506.39000000","0.03400000"],["15506.62000000","1.74800000"],["15506.87000000","0.19888400"],["15506.97000000","1.19800000"],["15507.74000000","0.20000000"],["15507.91000000","0.00000000"],["15508.97000000","0.00000000"],["15509.46000000","1.25000000"],["15515.20000000","0.00000000"],["15517.30000000","0.36971000"],["15537.03000000","0.00202500"],["15549.17000000","0.03100000"]]}}
2020-11-09T11:26:54.25323 btcusdt {"stream":"btcusdt@depth@100ms","data":{"e":"depthUpdate","E":1604921214244,"s":"BTCUSDT","U":6511143079,"u":6511143114,"b":[["15502.32000000","0.36197800"],["15502.01000000","0.00000000"],["15501.67000000","0.00000000"],["15500.59000000","0.00000000"],["15500.58000000","4.72160500"],["15500.12000000","0.01527700"],["15499.76000000","0.00000000"],["15498.77000000","0.50000000"],["15498.50000000","0.10591000"],["15498.49000000","0.00000000"],["15498.48000000","0.00129000"],["15497.20000000","0.06748500"],["15496.31000000","0.15620400"],["15496.30000000","0.00000000"],["15495.02000000","0.00000000"],["15494.47000000","0.20000000"]],"a":[["15502.33000000","5.30690000"],["15503.82000000","0.00000000"],["15504.46000000","0.50000000"],["15504.47000000","0.01752600"],["15504.63000000","0.00000000"],["15505.68000000","0.10000000"],["15506.17000000","0.00000000"],["15506.18000000","0.08000000"],["15506.81000000","0.05000000"],["15506.87000000","0.00000000"],["15506.94000000","0.01000000"],["15507.75000000","0.00000000"],["15507.99000000","0.00000000"],["15508.38000000","0.00000000"],["15508.75000000","0.01000000"],["15509.14000000","0.01500000"],["15511.41000000","0.00000000"],["15670.42000000","0.00000000"]]}}
2020-11-09T11:26:54.35147 btcusdt {"stream":"btcusdt@depth@100ms","data":{"e":"depthUpdate","E":1604921214345,"s":"BTCUSDT","U":6511143115,"u":6511143133,"b":[["15502.32000000","0.32400900"],["15501.66000000","0.00000000"],["15501.65000000","0.00000000"],["15501.64000000","0.00000000"],["15501.55000000","0.00000000"],["15500.58000000","4.61107500"],["15496.31000000","0.10839800"],["15495.02000000","0.04780600"],["15424.10000000","0.00000000"]],"a":[["15502.33000000","10.60410700"],["15505.67000000","0.12903300"],["15518.44000000","0.12123300"],["15561.00000000","0.15645800"],["15603.00000000","0.49510300"]]}}
2020-11-09T11:26:54.45313 btcusdt {"stream":"btcusdt@depth@100ms","data":{"e":"depthUpdate","E":1604921214445,"s":"BTCUSDT","U":6511143134,"u":6511143141,"b":[["15501.61000000","0.00200000"],["15482.00000000","0.00000000"],["15437.26000000","0.00000000"]],"a":[["15505.13000000","0.03225500"],["15506.74000000","0.12902200"],["15508.02000000","0.00000000"],["15510.91000000","0.00000000"],["15517.39000000","1.00000000"]]}}
2020-11-09T11:26:54.55140 btcusdt {"stream":"btcusdt@depth@100ms","data":{"e":"depthUpdate","E":1604921214545,"s":"BTCUSDT","U":6511143142,"u":6511143156,"b":[["15502.32000000","0.27551200"],["15500.18000000","0.00000000"],["15499.95000000","0.00784500"],["15484.66000000","1.16505000"]],"a":[["15502.33000000","12.60410700"],["15504.13000000","0.10000000"],["15504.29000000","0.00000000"],["15504.41000000","0.00691400"],["15505.68000000","0.00000000"],["15506.91000000","0.19888400"],["15509.19000000","0.28800000"],["15512.17000000","0.10000000"],["15517.30000000","0.00000000"],["15517.39000000","0.00000000"],["15664.13000000","0.00413400"]]}}
2020-11-09T11:26:54.65157 btcusdt {"stream":"btcusdt@depth@100ms","data":{"e":"depthUpdate","E":1604921214645,"s":"BTCUSDT","U":6511143157,"u":6511143165,"b":[["15497.15000000","0.00000000"],["15496.07000000","0.16000000"]],"a":[["15505.96000000","0.11427900"],["15513.00000000","0.50000000"],["15513.34000000","0.00000000"],["15516.15000000","0.00000000"],["15517.43000000","1.00000000"],["15517.71000000","1.50000000"]]}}
2020-11-09T11:26:54.75131 btcusdt {"stream":"btcusdt@depth@100ms","data":{"e":"depthUpdate","E":1604921214745,"s":"BTCUSDT","U":6511143166,"u":6511143176,"b":[["15500.58000000","0.01107500"],["15498.78000000","0.25000000"],["15497.83000000","0.00000000"],["15495.48000000","0.06000000"],["15495.03000000","0.65235400"],["15493.05000000","0.82797200"],["15349.21000000","0.01395500"]],"a":[["15502.33000000","12.54395200"],["15503.04000000","0.00000000"],["15504.28000000","0.08000000"],["15518.89000000","0.36972700"]]}}
2020-11-09T11:26:54.85121 btcusdt {"stream":"btcusdt@depth@100ms","data":{"e":"depthUpdate","E":1604921214845,"s":"BTCUSDT","U":6511143177,"u":6511143186,"b":[["15500.12000000","0.00000000"],["15499.95000000","0.00000000"],["15493.78000000","0.00000000"],["15492.98000000","0.00000000"],["15424.80000000","0.00648300"]],"a":[["15503.31000000","0.15219400"],["15504.41000000","0.00000000"],["15504.47000000","0.00000000"],["15504.69000000","0.00000000"],["15505.95000000","0.20000000"]]}}
2020-11-09T11:26:54.95164 btcusdt {"stream":"btcusdt@depth@100ms","data":{"e":"depthUpdate","E":1604921214945,"s":"BTCUSDT","U":6511143187,"u":6511143210,"b":[["15502.32000000","0.00000000"],["15501.61000000","0.50890000"],["15498.51000000","1.05360200"],["15496.90000000","0.11427900"],["15483.06000000","0.25763000"]],"a":[["15501.62000000","12.71336600"],["15501.71000000","0.00230000"],["15501.98000000","0.00690000"],["15502.23000000","0.03475600"],["15502.24000000","0.03350500"],["15502.25000000","0.00000000"],["15502.33000000","7.78115400"],["15503.32000000","0.00000000"],["15505.33000000","0.95991300"],["15506.97000000","0.00000000"],["15510.18000000","0.00000000"]]}}
2020-11-09T11:26:55.05353 btcusdt {"stream":"btcusdt@depth@100ms","data":{"e":"depthUpdate","E":1604921215045,"s":"BTCUSDT","U":6511143211,"u":6511143238,"b":[["15497.16000000","0.00000000"],["15482.99000000","0.00000000"],["14888.73000000","0.00174400"],["12050.85000000","0.11826100"]],"a":[["15501.62000000","13.02341800"],["15502.06000000","0.01022800"],["15502.22000000","0.29888400"],["15502.33000000","7.46756500"],["15504.13000000","0.00000000"],["15505.20000000","0.11627900"],["15505.52000000","0.29400000"],["15505.96000000","0.00000000"],["15506.09000000","0.05000000"],["15506.22000000","0.01000000"],["15506.36000000","1.19800000"],["15506.43000000","0.32100000"],["15506.81000000","0.00000000"],["15506.91000000","0.00000000"],["15506.94000000","0.00000000"],["15507.63000000","0.30000000"],["15508.03000000","0.01000000"],["15508.75000000","0.00000000"],["15509.92000000","0.19294000"],["15510.58000000","0.26067000"],["15606.00000000","0.11961300"]]}}
2020-11-09T11:26:55.15129 btcusdt {"stream":"btcusdt@depth@100ms","data":{"e":"depthUpdate","E":1604921215145,"s":"BTCUSDT","U":6511143239,"u":6511143247,"b":[["15498.01000000","0.05000000"],["15463.57000000","0.25000000"]],"a":[["15501.62000000","15.02341800"],["15502.22000000","0.45107800"],["15503.31000000","0.00000000"],["15510.14000000","0.30000000"],["15514.16000000","1.00000000"],["15517.43000000","0.00000000"],["15541.08000000","0.25000000"]]}}
2020-11-09T11:26:55.25189 btcusdt {"stream":"btcusdt@depth@100ms","data":{"e":"depthUpdate","E":1604921215245,"s":"BTCUSDT","U":6511143248,"u":6511143252,"b":[["15496.31000000","0.00000000"]],"a":[["15505.66000000","0.16130300"],["15508.42000000","0.01500000"],["15509.14000000","0.00000000"],["15549.55000000","1.73307500"]]}}
2020-11-09T11:26:55.35124 btcusdt {"stream":"btcusdt@depth@100ms","data":{"e":"depthUpdate","E":1604921215345,"s":"BTCUSDT","U":6511143253,"u":6511143260,"b":[["15501.55000000","0.01802300"],["15501.50000000","0.00745400"],["14428.25000000","0.00174400"]],"a":[["15501.62000000","14.96283700"],["15504.13000000","0.12904300"],["15505.66000000","0.00000000"],["15506.12000000","0.01298600"],["15506.16000000","0.00838800"]]}}
2020-11-09T11:26:55.46381 btcusdt {"stream":"btcusdt@depth@100ms","data":{"e":"depthUpdate","E":1604921215445,"s":"BTCUSDT","U":6511143261,"u":6511143265,"b":[["15497.15000000","0.00000000"],["15495.48000000","0.00000000"],["15424.80000000","0.00000000"]],"a":[["15510.14000000","0.00000000"]]}}
2020-11-09T11:26:55.55206 btcusdt {"stream":"btcusdt@depth@100ms","data":{"e":"depthUpdate","E":1604921215545,"s":"BTCUSDT","U":6511143266,"u":6511143270,"b":[["15501.61000000","0.50728700"],["15501.55000000","0.00000000"],["15496.97000000","0.06690000"]],"a":[["15504.13000000","0.00000000"],["15506.12000000","0.00000000"]]}}
2020-11-09T11:26:55.65352 btcusdt {"stream":"btcusdt@depth@100ms","data":{"e":"depthUpdate","E":1604921215645,"s":"BTCUSDT","U":6511143271,"u":6511143284,"b":[["15501.50000000","0.00000000"],["15501.28000000","0.01559900"],["15501.18000000","0.00863400"],["15500.58000000","0.00907500"],["15423.92000000","0.02230300"]],"a":[["15505.50000000","0.01700000"],["15505.51000000","0.01700000"],["15505.73000000","1.74800000"],["15505.74000000","0.01386100"],["15505.76000000","0.00910900"],["15506.16000000","0.00000000"],["15506.39000000","0.00000000"],["15506.62000000","0.00000000"]]}}
2020-11-09T11:26:55.75238 btcusdt {"stream":"btcusdt@depth@100ms","data":{"e":"depthUpdate","E":1604921215745,"s":"BTCUSDT","U":6511143285,"u":6511143288,"b":[["15499.00000000","0.00595200"]],"a":[["15501.62000000","9.66283700"],["15504.28000000","0.00000000"],["15603.00000000","0.11827300"]]}}
2020-11-09T11:26:55.85241 btcusdt {"stream":"btcusdt@depth@100ms","data":{"e":"depthUpdate","E":1604921215845,"s":"BTCUSDT","U":6511143289,"u":6511143295,"b":[["15501.28000000","0.00000000"],["15493.50000000","0.19349300"],["15489.74000000","1.00932100"],["15488.86000000","0.00000000"],["15424.10000000","0.00648300"]],"a":[["15501.62000000","9.60254900"],["15505.74000000","0.00000000"]]}}
2020-11-09T11:26:55.95242 btcusdt {"stream":"btcusdt@depth@100ms","data":{"e":"depthUpdate","E":1604921215945,"s":"BTCUSDT","U":6511143296,"u":6511143306,"b":[["15501.61000000","0.46228500"],["15501.18000000","0.00000000"],["15498.78000000","0.00000000"],["15498.51000000","0.00000000"],["15490.10000000","0.50466100"],["15489.22000000","0.00000000"]],"a":[["15501.62000000","14.90254900"],["15502.22000000","0.35107800"],["15504.13000000","0.10000000"],["15505.76000000","0.00000000"],["15606.00000000","0.49644300"]]}}
2020-11-09T11:26:56.05244 btcusdt {"stream":"btcusdt@depth@100ms","data":{"e":"depthUpdate","E":1604921216045,"s":"BTCUSDT","U":6511143307,"u":6511143317,"b":[["15498.50000000","0.00000000"],["15495.04000000","0.10591000"],["15493.50000000","0.00000000"]],"a":[["15503.10000000","0.08000000"],["15504.13000000","0.18000000"],["15504.33000000","0.42500100"],["15505.77000000","0.00000000"],["15506.36000000","0.00000000"],["15512.99000000","1.00932100"],["15514.91000000","0.00690000"]]}}
2020-11-09T11:26:56.15253 btcusdt {"stream":"btcusdt@depth@100ms","data":{"e":"depthUpdate","E":1604921216146,"s":"BTCUSDT","U":6511143318,"u":6511143331,"b":[["15501.61000000","0.46151100"],["15498.78000000","0.25000000"],["15498.49000000","1.00064600"],["15486.64000000","0.00000000"]],"a":[["15501.62000000","14.90384000"],["15502.05000000","0.10000000"],["15503.10000000","0.00000000"],["15504.13000000","0.08000000"],["15506.21000000","1.19800000"],["15507.74000000","0.00000000"],["15508.97000000","1.25000000"],["15509.46000000","0.00000000"]]}}
2020-11-09T11:26:56.25275 btcusdt {"stream":"btcusdt@depth@100ms","data":{"e":"depthUpdate","E":1604921216246,"s":"BTCUSDT","U":6511143332,"u":6511143350,"b":[["15498.78000000","0.52300200"],["15498.77000000","1.04600000"],["15497.65000000","0.88000000"],["15497.19000000","0.00000000"],["15496.07000000","0.00000000"]],"a":[["15501.62000000","9.60384000"],["15501.81000000","0.00200000"],["15502.05000000","0.00000000"],["15502.22000000","0.00000000"],["15504.12000000","0.25219400"],["15504.13000000","0.00000000"],["15506.21000000","0.00000000"],["15506.67000000","1.19800000"],["15508.97000000","0.00000000"],["15509.93000000","1.25000000"]]}}
2020-11-09T11:26:56.35239 btcusdt {"stream":"btcusdt@depth@100ms","data":{"e":"depthUpdate","E":1604921216346,"s":"BTCUSDT","U":6511143351,"u":6511143357,"b":[["15500.81000000","0.01764100"],["15489.74000000","0.00000000"],["15487.68000000","1.00932100"]],"a":[["15502.32000000","0.00000000"],["15504.86000000","0.01521200"],["15505.66000000","0.19888400"]]}}
2020-11-09T11:26:56.45222 btcusdt {"stream":"btcusdt@depth@100ms","data":{"e":"depthUpdate","E":1604921216446,"s":"BTCUSDT","U":6511143358,"u":6511143366,"b":[["15500.62000000","0.00896600"],["15497.65000000","0.72000000"]],"a":[["15501.62000000","9.54368700"],["15502.22000000","0.15219400"],["15504.12000000","0.10000000"],["15504.90000000","0.00893800"],["15508.21000000","1.25000000"],["15509.93000000","0.00000000"]]}}
2020-11-09T11:26:56.55267 btcusdt {"stream":"btcusdt@depth@100ms","data":{"e":"depthUpdate","E":1604921216546,"s":"BTCUSDT","U":6511143367,"u":6511143369,"b":[["15390.00000000","0.60008800"]],"a":[["15502.24000000","0.13350500"],["15504.12000000","0.00000000"]]}}
2020-11-09T11:26:56.65469 btcusdt {"stream":"btcusdt@depth@100ms","data":{"e":"depthUpdate","E":1604921216646,"s":"BTCUSDT","U":6511143370,"u":6511143374,"b":[["15498.77000000","0.50000000"],["15498.49000000","0.00000000"],["15497.65000000","0.00000000"],["15497.06000000","0.04000000"],["15495.67000000","0.08000000"]],"a":[]}}
2020-11-09T11:26:56.75366 btcusdt {"stream":"btcusdt@depth@100ms","data":{"e":"depthUpdate","E":1604921216746,"s":"BTCUSDT","U":6511143375,"u":6511143380,"b":[["15498.78000000","0.25000000"],["15442.20000000","0.00000000"],["15411.00000000","1.19794700"]],"a":[["15506.32000000","0.20000000"],["15510.73000000","0.00000000"],["15512.06000000","0.00000000"]]}}
2020-11-09T11:26:56.85333 btcusdt {"stream":"btcusdt@depth@100ms","data":{"e":"depthUpdate","E":1604921216846,"s":"BTCUSDT","U":6511143381,"u":6511143391,"b":[["15498.77000000","0.54000000"],["15497.65000000","0.08000000"],["15497.06000000","0.00000000"],["15495.67000000","0.00000000"]],"a":[["15502.05000000","0.19888400"],["15505.00000000","0.00212400"],["15505.66000000","0.00000000"],["15508.21000000","0.00000000"],["15509.46000000","1.25000000"],["15510.73000000","0.03361700"],["15511.68000000","0.13446900"]]}}
2020-11-09T11:26:56.95276 btcusdt {"stream":"btcusdt@depth@100ms","data":{"e":"depthUpdate","E":1604921216946,"s":"BTCUSDT","U":6511143392,"u":6511143393,"b":[],"a":[["15501.62000000","9.48356900"],["15502.33000000","7.46556500"]]}}
2020-11-09T11:26:57.05277 btcusdt {"stream":"btcusdt@depth@100ms","data":{"e":"depthUpdate","E":1604921217046,"s":"BTCUSDT","U":6511143394,"u":6511143397,"b":[["15498.01000000","0.00000000"],["15496.99000000","0.05000000"],["15493.37000000","0.19198500"],["15433.18000000","0.24000000"]],"a":[]}}
2020-11-09T11:26:57.15260 btcusdt {"stream":"btcusdt@depth@100ms","data":{"e":"depthUpdate","E":1604921217146,"s":"BTCUSDT","U":6511143398,"u":6511143399,"b":[["15500.00000000","0.00093000"]],"a":[["15501.62000000","14.78356900"]]}}
2020-11-09T11:26:57.35384 btcusdt {"stream":"btcusdt@depth@100ms","data":{"e":"depthUpdate","E":1604921217346,"s":"BTCUSDT","U":6511143400,"u":6511143405,"b":[["15501.61000000","0.46351100"]],"a":[["15501.62000000","7.64247500"],["15502.05000000","0.00000000"],["15504.13000000","0.19888400"],["15510.38000000","0.30000000"]]}}
2020-11-09T11:26:57.45248 btcusdt {"stream":"btcusdt@depth@100ms","data":{"e":"depthUpdate","E":1604921217446,"s":"BTCUSDT","U":6511143406,"u":6511143410,"b":[["15411.00000000","1.08967400"]],"a":[["15501.62000000","7.33242300"],["15502.24000000","0.03350500"],["15504.12000000","0.10000000"],["15750.00000000","67.51857900"]]}}
2020-11-09T11:26:57.55394 btcusdt {"stream":"btcusdt@depth@100ms","data":{"e":"depthUpdate","E":1604921217546,"s":"BTCUSDT","U":6511143411,"u":6511143413,"b":[["15481.18000000","0.29700000"]],"a":[["15501.62000000","7.56342800"]]}}
2020-11-09T11:26:57.65350 btcusdt {"stream":"btcusdt@depth@100ms","data":{"e":"depthUpdate","E":1604921217646,"s":"BTCUSDT","U":6511143414,"u":6511143415,"b":[],"a":[["15501.62000000","7.60524700"],["15507.92000000","0.50000000"]]}}
2020-11-09T11:26:57.75388 btcusdt {"stream":"btcusdt@depth@100ms","data":{"e":"depthUpdate","E":1604921217746,"s":"BTCUSDT","U":6511143416,"u":6511143421,"b":[],"a":[["15502.32000000","0.00000000"],["15504.11000000","0.10000000"],["15504.12000000","0.00000000"],["15511.11000000","0.22786000"],["15606.00000000","0.11961300"]]}}
2020-11-09T11:26:57.85282 btcusdt {"stream":"btcusdt@depth@100ms","data":{"e":"depthUpdate","E":1604921217846,"s":"BTCUSDT","U":6511143422,"u":6511143422,"b":[["15487.53000000","0.13446500"]],"a":[]}}
2020-11-09T11:26:57.95293 btcusdt {"stream":"btcusdt@depth@100ms","data":{"e":"depthUpdate","E":1604921217947,"s":"BTCUSDT","U":6511143423,"u":6511143431,"b":[["15498.77000000","0.54000000"],["15497.65000000","0.00000000"],["15495.69000000","0.08000000"]],"a":[["15501.62000000","8.10395600"],["15504.13000000","0.00000000"],["15603.00000000","0.49510300"],["15610.50000000","0.00000000"]]}}
2020-11-09T11:26:58.05719 btcusdt {"stream":"btcusdt@depth@100ms","data":{"e":"depthUpdate","E":1604921218047,"s":"BTCUSDT","U":6511143432,"u":6511143437,"b":[["15498.49000000","1.00064500"],["15497.67000000","2.00690000"],["15495.69000000","0.00000000"]],"a":[["15501.62000000","7.93609800"],["15506.32000000","0.00000000"]]}}
2020-11-09T11:26:58.16853 btcusdt {"stream":"btcusdt@depth@100ms","data":{"e":"depthUpdate","E":1604921218147,"s":"BTCUSDT","U":6511143438,"u":6511143442,"b":[["15501.61000000","0.57530000"]],"a":[["15502.22000000","0.00000000"],["15504.10000000","0.15219400"],["15505.95000000","0.00000000"],["15606.00000000","0.01134000"]]}}
2020-11-09T11:26:58.25361 btcusdt {"stream":"btcusdt@depth@100ms","data":{"e":"depthUpdate","E":1604921218247,"s":"BTCUSDT","U":6511143443,"u":6511143444,"b":[["15495.05000000","0.10840100"],["15433.18000000","0.00000000"]],"a":[]}}
2020-11-09T11:26:58.35288 btcusdt {"stream":"btcusdt@depth@100ms","data":{"e":"depthUpdate","E":1604921218347,"s":"BTCUSDT","U":6511143445,"u":6511143446,"b":[["15390.00000000","0.70836100"]],"a":[["15506.74000000","0.00000000"]]}}
2020-11-09T11:26:58.47801 btcusdt {"stream":"btcusdt@depth@100ms","data":{"e":"depthUpdate","E":1604921218447,"s":"BTCUSDT","U":6511143447,"u":6511143450,"b":[["15489.04000000","1.00932900"],["15487.68000000","0.00000000"]],"a":[["15509.58000000","0.12902200"],["15509.92000000","0.00000000"]]}}
2020-11-09T11:26:58.55386 btcusdt {"stream":"btcusdt@depth@100ms","data":{"e":"depthUpdate","E":1604921218547,"s":"BTCUSDT","U":6511143451,"u":6511143454,"b":[["15456.00000000","0.05500000"],["15400.71000000","0.01623300"]],"a":[["15533.78000000","0.00000000"],["15561.00000000","0.26473100"]]}}
2020-11-09T11:26:58.65345 btcusdt {"stream":"btcusdt@depth@100ms","data":{"e":"depthUpdate","E":1604921218647,"s":"BTCUSDT","U":6511143455,"u":6511143458,"b":[["15501.61000000","0.40449500"]],"a":[["15501.62000000","7.87696300"]]}}
2020-11-09T11:26:58.75377 btcusdt {"stream":"btcusdt@depth@100ms","data":{"e":"depthUpdate","E":1604921218747,"s":"BTCUSDT","U":6511143459,"u":6511143463,"b":[["15498.79000000","0.10591000"],["15497.67000000","0.08690000"],["15495.04000000","0.00000000"],["15457.00000000","2.00000000"]],"a":[]}}
2020-11-09T11:26:58.85390 btcusdt {"stream":"btcusdt@depth@100ms","data":{"e":"depthUpdate","E":1604921218847,"s":"BTCUSDT","U":6511143464,"u":6511143467,"b":[["14643.20000000","0.00171000"]],"a":[["15502.06000000","0.09380700"],["15506.32000000","0.20000000"],["15535.73000000","0.01210000"]]}}
2020-11-09T11:26:58.95528 btcusdt {"stream":"btcusdt@depth@100ms","data":{"e":"depthUpdate","E":1604921218947,"s":"BTCUSDT","U":6511143468,"u":6511143471,"b":[["15221.00000000","0.00000000"]],"a":[["15501.62000000","8.00496300"],["15502.33000000","7.33756500"],["15506.08000000","0.20000000"]]}}
2020-11-09T11:26:59.05446 btcusdt {"stream":"btcusdt@depth@100ms","data":{"e":"depthUpdate","E":1604921219047,"s":"BTCUSDT","U":6511143472,"u":6511143475,"b":[["15498.01000000","0.05000000"],["15496.99000000","0.00000000"]],"a":[["15506.08000000","0.00000000"],["15510.38000000","0.00000000"]]}}
2020-11-09T11:26:59.15625 btcusdt {"stream":"btcusdt@depth@100ms","data":{"e":"depthUpdate","E":1604921219147,"s":"BTCUSDT","U":6511143476,"u":6511143478,"b":[["15498.50000000","0.50000000"],["15423.03000000","0.24000000"]],"a":[["15504.53000000","0.50000000"]]}}
2020-11-09T11:26:59.25410 btcusdt {"stream":"btcusdt@depth@100ms","data":{"e":"depthUpdate","E":1604921219247,"s":"BTCUSDT","U":6511143479,"u":6511143482,"b":[["15501.61000000","0.40249500"],["14643.20000000","0.02511000"]],"a":[["15501.62000000","7.89770100"]]}}
2020-11-09T11:26:59.35454 btcusdt {"stream":"btcusdt@depth@100ms","data":{"e":"depthUpdate","E":1604921219347,"s":"BTCUSDT","U":6511143483,"u":6511143484,"b":[],"a":[["15506.32000000","0.00000000"],["15925.00000000","0.27787800"]]}}
2020-11-09T11:26:59.46459 btcusdt {"stream":"btcusdt@depth@100ms","data":{"e":"depthUpdate","E":1604921219447,"s":"BTCUSDT","U":6511143485,"u":6511143540,"b":[["15501.61000000","0.17119500"],["15498.78000000","0.00000000"],["15495.03000000","0.00000000"],["15493.05000000","0.00000000"],["15490.01000000","0.00000000"]],"a":[["15502.32000000","0.15219400"],["15504.10000000","0.00000000"],["15509.58000000","0.00000000"],["15511.62000000","0.16353900"],["15512.78000000","0.00000000"],["15514.34000000","0.00294000"]]}}
2020-11-09T11:26:59.55562 btcusdt {"stream":"btcusdt@depth@100ms","data":{"e":"depthUpdate","E":1604921219547,"s":"BTCUSDT","U":6511143541,"u":6511143559,"b":[["15501.61000000","0.00690000"],["15498.49000000","0.00000000"]],"a":[["15501.62000000","7.77758700"],["15502.22000000","0.00000000"],["15502.33000000","2.09082000"],["15504.46000000","0.00000000"],["15504.53000000","0.00000000"],["15504.63000000","0.19888400"],["15505.66000000","0.20000000"],["15506.68000000","0.12902200"],["15509.92000000","0.19089000"],["15510.87000000","0.10083200"],["15511.11000000","0.00065800"],["15555.00000000","4.06809700"]]}}
2020-11-09T11:26:59.65393 btcusdt {"stream":"btcusdt@depth@100ms","data":{"e":"depthUpdate","E":1604921219647,"s":"BTCUSDT","U":6511143560,"u":6511143565,"b":[["15498.01000000","0.21000000"],["15358.82000000","0.00100000"]],"a":[["15502.22000000","0.13500000"],["15506.32000000","0.20000000"],["15511.10000000","0.27295200"],["15517.71000000","0.00000000"]]}}
2020-11-09T11:26:59.75434 btcusdt {"stream":"btcusdt@depth@100ms","data":{"e":"depthUpdate","E":1604921219748,"s":"BTCUSDT","U":6511143566,"u":6511143569,"b":[["15501.61000000","0.00002300"],["15498.79000000","0.00000000"],["15495.06000000","0.10591000"]],"a":[["15501.62000000","7.71714400"]]}}
2020-11-09T11:26:59.85391 btcusdt {"stream":"btcusdt@depth@100ms","data":{"e":"depthUpdate","E":1604921219848,"s":"BTCUSDT","U":6511143570,"u":6511143580,"b":[],"a":[["15501.62000000","7.71636500"],["15502.21000000","0.10000000"],["15504.11000000","0.00000000"],["15505.42000000","0.05690000"],["15505.87000000","0.01000000"],["15506.09000000","0.00000000"],["15506.22000000","0.00000000"],["15507.68000000","0.01000000"],["15508.03000000","0.00000000"],["15508.07000000","0.01500000"],["15508.42000000","0.00000000"]]}}
2020-11-09T11:26:59.95461 btcusdt {"stream":"btcusdt@depth@100ms","data":{"e":"depthUpdate","E":1604921219948,"s":"BTCUSDT","U":6511143581,"u":6511143585,"b":[["15423.03000000","0.00000000"]],"a":[["15508.97000000","1.25000000"],["15509.46000000","0.00000000"],["15517.31000000","0.00000000"],["15532.15000000","1.08875000"]]}}
2020-11-09T11:27:00.05403 btcusdt {"stream":"btcusdt@depth@100ms","data":{"e":"depthUpdate","E":1604921220048,"s":"BTCUSDT","U":6511143586,"u":6511143590,"b":[["15501.61000000","0.30143100"],["15426.56000000","0.24000000"]],"a":[["15501.62000000","7.68401900"]]}}
2020-11-09T11:27:00.15533 btcusdt {"stream":"btcusdt@depth@100ms","data":{"e":"depthUpdate","E":1604921220148,"s":"BTCUSDT","U":6511143591,"u":6511143614,"b":[["15501.61000000","0.00000000"],["15498.78000000","0.01612000"],["15463.57000000","0.00000000"]],"a":[["15501.10000000","10.13980300"],["15501.58000000","0.01120500"],["15501.59000000","0.03234600"],["15501.62000000","7.18401900"],["15502.22000000","0.00000000"],["15503.11000000","0.01690000"],["15505.42000000","0.00690000"],["15505.77000000","0.05000000"],["15505.87000000","0.00000000"],["15506.22000000","0.01000000"],["15506.32000000","0.00000000"],["15507.68000000","0.00000000"],["15508.03000000","0.01000000"],["15508.07000000","0.00000000"],["15508.42000000","0.01500000"],["15541.08000000","0.00000000"]]}}
2020-11-09T11:27:00.25497 btcusdt {"stream":"btcusdt@depth@100ms","data":{"e":"depthUpdate","E":1604921220248,"s":"BTCUSDT","U":6511143615,"u":6511143638,"b":[["15501.09000000","0.01380000"],["15498.01000000","0.16000000"],["15496.91000000","0.05000000"],["15496.90000000","0.00000000"],["15496.40000000","0.11427900"],["15495.02000000","0.00000000"],["15493.38000000","0.04780600"],["15482.00000000","0.00500000"],["14419.65000000","0.00000000"]],"a":[["15501.10000000","12.52917900"],["15501.35000000","0.00690000"],["15501.59000000","0.00000000"],["15501.62000000","7.05214000"],["15502.20000000","0.01000000"],["15502.23000000","0.00000000"],["15502.24000000","0.00000000"],["15504.69000000","0.11427900"],["15505.20000000","0.00200000"],["15506.43000000","0.00000000"],["15510.38000000","0.30000000"],["15516.77000000","1.50000000"]]}}
2020-11-09T11:27:00.35511 btcusdt {"stream":"btcusdt@depth@100ms","data":{"e":"depthUpdate","E":1604921220348,"s":"BTCUSDT","U":6511143639,"u":6511143646,"b":[["15500.81000000","0.00000000"],["15499.69000000","0.01697700"],["15424.10000000","0.00000000"]],"a":[["15501.10000000","12.46911000"],["15501.62000000","6.89214000"],["15502.32000000","0.00000000"],["15503.87000000","0.01675200"],["15504.86000000","0.00000000"]]}}
2020-11-09T11:27:00.45724 btcusdt {"stream":"btcusdt@depth@100ms","data":{"e":"depthUpdate","E":1604921220448,"s":"BTCUSDT","U":6511143647,"u":6511143653,"b":[["15500.62000000","0.00000000"],["15499.67000000","0.00929900"],["14409.53000000","0.17349600"]],"a":[["15501.10000000","12.62130400"],["15503.86000000","0.00703400"],["15504.90000000","0.00000000"],["15506.17000000","0.20000000"]]}}
2020-11-09T11:27:00.55543 btcusdt {"stream":"btcusdt@depth@100ms","data":{"e":"depthUpdate","E":1604921220548,"s":"BTCUSDT","U":6511143654,"u":6511143661,"b":[["15496.98000000","0.00000000"],["15493.77000000","0.02106400"]],"a":[["15501.10000000","12.62582400"],["15505.86000000","0.32100000"],["15508.03000000","0.00000000"],["15520.00000000","6.09042400"],["17826.85000000","0.90120000"],["17836.94000000","0.01910000"]]}}
2020-11-09T11:27:00.65596 btcusdt {"stream":"btcusdt@depth@100ms","data":{"e":"depthUpdate","E":1604921220648,"s":"BTCUSDT","U":6511143662,"u":6511143663,"b":[],"a":[["15501.10000000","7.32582400"],["15507.51000000","0.01000000"]]}}
2020-11-09T11:27:00.75588 btcusdt {"stream":"btcusdt@depth@100ms","data":{"e":"depthUpdate","E":1604921220748,"s":"BTCUSDT","U":6511143664,"u":6511143665,"b":[],"a":[["15503.86000000","0.20591800"],["15504.63000000","0.00000000"]]}}
2020-11-09T11:27:00.85657 btcusdt {"stream":"btcusdt@depth@100ms","data":{"e":"depthUpdate","E":1604921220848,"s":"BTCUSDT","U":6511143666,"u":6511143677,"b":[["15501.09000000","0.51380000"],["15499.69000000","0.00000000"],["15499.67000000","0.00000000"],["15499.17000000","0.01236200"],["15499.10000000","0.00812000"],["15423.58000000","0.00648300"],["15244.08000000","0.00000000"]],"a":[["15501.10000000","7.08117700"],["15503.10000000","0.15219400"],["17836.94000000","0.00500000"]]}}
2020-11-09T11:27:00.95539 btcusdt {"stream":"btcusdt@depth@100ms","data":{"e":"depthUpdate","E":1604921220948,"s":"BTCUSDT","U":6511143678,"u":6511143679,"b":[["15501.09000000","0.51580000"]],"a":[["15516.67000000","0.24000000"]]}}
2020-11-09T11:27:01.05644 btcusdt {"stream":"btcusdt@depth@100ms","data":{"e":"depthUpdate","E":1604921221048,"s":"BTCUSDT","U":6511143680,"u":6511143687,"b":[["15496.91000000","0.00000000"],["15496.41000000","0.05000000"],["15495.07000000","0.04780600"],["15493.38000000","0.00000000"]],"a":[["15501.10000000","7.07919500"],["15502.20000000","0.00000000"],["15505.77000000","0.00000000"],["15506.33000000","0.25000000"]]}}
2020-11-09T11:27:01.15472 btcusdt {"stream":"btcusdt@depth@100ms","data":{"e":"depthUpdate","E":1604921221148,"s":"BTCUSDT","U":6511143688,"u":6511143694,"b":[["15487.00000000","0.02731700"],["15462.34000000","0.25000000"]],"a":[["15501.10000000","12.37919500"],["15503.09000000","0.01000000"],["15539.85000000","0.25000000"],["15556.00000000","0.75486200"],["17826.85000000","0.91530000"]]}}
2020-11-09T11:27:01.25625 btcusdt {"stream":"btcusdt@depth@100ms","data":{"e":"depthUpdate","E":1604921221248,"s":"BTCUSDT","U":6511143695,"u":6511143698,"b":[],"a":[["15505.70000000","0.01000000"],["15506.22000000","0.00000000"],["15507.90000000","0.01500000"],["15508.42000000","0.00000000"]]}}
2020-11-09T11:27:01.35666 btcusdt {"stream":"btcusdt@depth@100ms","data":{"e":"depthUpdate","E":1604921221349,"s":"BTCUSDT","U":6511143699,"u":6511143709,"b":[["15499.17000000","0.00000000"]],"a":[["15501.10000000","12.37826000"],["15501.57000000","0.15219400"],["15502.33000000","2.00000000"],["15503.08000000","0.19888400"],["15503.10000000","0.00000000"],["15503.11000000","0.00690000"],["15503.86000000","0.00703400"],["15503.87000000","0.00000000"],["15554.50000000","2.00000000"],["15652.68000000","0.00000000"]]}}
2020-11-09T11:27:01.47649 btcusdt {"stream":"btcusdt@depth@100ms","data":{"e":"depthUpdate","E":1604921221449,"s":"BTCUSDT","U":6511143710,"u":6511143724,"b":[["15501.09000000","0.51780000"],["15499.10000000","0.00000000"],["15498.77000000","0.50000000"],["15497.67000000","0.00690000"],["15497.29000000","0.08000000"],["15496.79000000","0.08000000"],["15495.72000000","0.08000000"]],"a":[["15501.10000000","7.01929700"],["15501.57000000","0.00000000"],["15501.62000000","1.59214000"],["15502.06000000","0.01022800"],["15503.07000000","0.15219400"],["15503.86000000","0.00000000"]]}}
2020-11-09T11:27:01.55634 btcusdt {"stream":"btcusdt@depth@100ms","data":{"e":"depthUpdate","E":1604921221549,"s":"BTCUSDT","U":6511143725,"u":6511143735,"b":[["15495.00000000","0.03224100"],["15305.31000000","0.00000000"]],"a":[["15501.10000000","6.64392700"],["15501.62000000","1.59014000"],["15503.06000000","0.01000000"],["15503.07000000","0.00000000"],["15503.08000000","0.00000000"],["15504.13000000","0.35107800"],["15516.52000000","0.00000000"],["15516.77000000","0.00000000"]]}}
2020-11-09T11:27:01.65581 btcusdt {"stream":"btcusdt@depth@100ms","data":{"e":"depthUpdate","E":1604921221649,"s":"BTCUSDT","U":6511143736,"u":6511143745,"b":[["15499.90000000","0.00690000"],["15498.87000000","0.01730400"],["15319.33000000","0.00100000"]],"a":[["15502.21000000","0.00000000"],["15503.57000000","0.01799900"],["15504.12000000","0.10000000"],["15504.67000000","0.00839300"],["15510.06000000","0.30262300"],["15530.00000000","0.07392600"],["17836.94000000","0.00000000"]]}}
2020-11-09T11:27:01.75735 btcusdt {"stream":"btcusdt@depth@100ms","data":{"e":"depthUpdate","E":1604921221749,"s":"BTCUSDT","U":6511143746,"u":6511143756,"b":[["15501.09000000","0.62958900"],["15498.77000000","1.04600000"],["15497.70000000","0.16000000"],["15497.38000000","0.03225500"],["15496.79000000","0.00000000"],["15495.72000000","0.00000000"],["15494.47000000","0.00000000"]],"a":[["15501.10000000","6.64322700"],["15501.58000000","0.00000000"],["15503.06000000","0.00000000"],["15504.13000000","0.19888400"]]}}
2020-11-09T11:27:01.85510 btcusdt {"stream":"btcusdt@depth@100ms","data":{"e":"depthUpdate","E":1604921221849,"s":"BTCUSDT","U":6511143757,"u":6511143765,"b":[["15501.09000000","0.12958900"],["15498.77000000","0.78000000"],["15496.87000000","0.11427900"],["15496.40000000","0.00000000"]],"a":[["15501.45000000","0.03182600"],["15503.05000000","0.15219400"],["15504.69000000","0.00000000"],["15505.17000000","0.11427900"]]}}
2020-11-09T11:27:01.95646 btcusdt {"stream":"btcusdt@depth@100ms","data":{"e":"depthUpdate","E":1604921221949,"s":"BTCUSDT","U":6511143766,"u":6511143773,"b":[["15439.14000000","0.66955900"],["15438.69000000","0.00000000"]],"a":[["15501.10000000","6.58096400"],["15502.32000000","0.10000000"],["15503.04000000","0.01000000"],["15504.12000000","0.00000000"]]}}
2020-11-09T11:27:02.05764 btcusdt {"stream":"btcusdt@depth@100ms","data":{"e":"depthUpdate","E":1604921222049,"s":"BTCUSDT","U":6511143774,"u":6511143799,"b":[["15499.92000000","0.01361500"],["15498.87000000","0.00000000"],["15498.77000000","0.74000000"],["15498.35000000","0.26000000"],["15497.70000000","0.24000000"],["15497.21000000","0.05000000"],["15496.97000000","0.00690000"],["15496.41000000","0.00000000"],["15495.85000000","0.00000000"],["15495.47000000","0.00000000"],["15494.78000000","0.00000000"]],"a":[["15501.10000000","6.57966700"],["15503.57000000","0.00000000"],["15504.74000000","0.01661100"],["15506.17000000","0.00000000"],["15508.97000000","0.00000000"],["15999.00000000","14.05451400"]]}}
2020-11-09T11:27:02.15580 btcusdt {"stream":"btcusdt@depth@100ms","data":{"e":"depthUpdate","E":1604921222149,"s":"BTCUSDT","U":6511143800,"u":6511143805,"b":[["15495.01000000","0.00000000"],["15490.54000000","1.25000000"]],"a":[["15501.10000000","11.87966700"],["15502.32000000","0.00000000"],["15504.12000000","0.10000000"],["15506.48000000","1.26934700"]]}}
2020-11-09T11:27:02.25601 btcusdt {"stream":"btcusdt@depth@100ms","data":{"e":"depthUpdate","E":1604921222249,"s":"BTCUSDT","U":6511143806,"u":6511143814,"b":[["15501.09000000","0.01780000"],["15492.44000000","0.20000000"],["15244.08000000","0.00590300"]],"a":[["15501.10000000","12.26382000"],["15501.45000000","0.00000000"],["15503.09000000","0.00000000"],["15516.96000000","1.50000000"],["15656.11000000","0.00170600"]]}}
2020-11-09T11:27:02.35687 btcusdt {"stream":"btcusdt@depth@100ms","data":{"e":"depthUpdate","E":1604921222349,"s":"BTCUSDT","U":6511143815,"u":6511143819,"b":[],"a":[["15501.10000000","12.39182000"],["15501.62000000","1.46214000"],["15503.05000000","0.00000000"],["15504.12000000","0.00000000"],["15506.17000000","0.20000000"]]}}
2020-11-09T11:27:02.45951 btcusdt {"stream":"btcusdt@depth@100ms","data":{"e":"depthUpdate","E":1604921222449,"s":"BTCUSDT","U":6511143820,"u":6511143827,"b":[],"a":[["15501.10000000","12.38643000"],["15501.61000000","0.15219400"],["15503.03000000","0.10000000"],["15505.61000000","0.25784000"],["15514.69000000","0.00000000"],["15550.12000000","0.00000000"],["17826.85000000","0.92030000"]]}}
2020-11-09T11:27:02.55752 btcusdt {"stream":"btcusdt@depth@100ms","data":{"e":"depthUpdate","E":1604921222549,"s":"BTCUSDT","U":6511143828,"u":6511143831,"b":[],"a":[["15501.10000000","12.32638800"],["15501.57000000","0.00805600"],["15503.02000000","0.01000000"],["15504.67000000","0.00000000"]]}}
2020-11-09T11:27:02.65741 btcusdt {"stream":"btcusdt@depth@100ms","data":{"e":"depthUpdate","E":1604921222649,"s":"BTCUSDT","U":6511143832,"u":6511143841,"b":[["15500.24000000","0.01451500"],["15499.92000000","0.00000000"]],"a":[["15501.87000000","0.01587400"],["15504.74000000","0.00000000"],["15506.48000000","0.01934700"],["15507.81000000","1.25000000"],["15510.73000000","0.00000000"],["15511.68000000","0.00000000"],["15586.27000000","0.00000000"],["15983.40000000","0.04000000"]]}}
2020-11-09T11:27:02.75980 btcusdt {"stream":"btcusdt@depth@100ms","data":{"e":"depthUpdate","E":1604921222749,"s":"BTCUSDT","U":6511143842,"u":6511143864,"b":[["15501.09000000","0.00000000"],["15500.58000000","0.00000000"],["15500.24000000","0.00000000"],["15500.00000000","0.00000000"],["15499.93000000","0.00690000"],["15499.90000000","0.00000000"],["15499.53000000","0.00000000"],["15499.00000000","0.00000000"],["15498.80000000","0.06951000"],["15498.78000000","0.00000000"],["15498.77000000","0.69588200"],["15497.20000000","0.00000000"],["15496.87000000","0.00000000"],["15496.03000000","0.11427900"],["15270.00000000","0.92753200"]],"a":[["15500.32000000","0.73075000"],["15500.59000000","1.46086700"],["15501.10000000","9.50273500"],["15501.57000000","0.00000000"],["15503.01000000","0.19888400"],["15504.13000000","0.00000000"],["15504.28000000","0.11427900"],["15505.17000000","0.00000000"],["15506.67000000","0.00000000"],["15509.37000000","0.03361800"],["15511.63000000","0.13447100"],["15622.42000000","0.00000000"]]}}
2020-11-09T11:27:02.85600 btcusdt {"stream":"btcusdt@depth@100ms","data":{"e":"depthUpdate","E":1604921222849,"s":"BTCUSDT","U":6511143865,"u":6511143919,"b":[["15498.78000000","0.00771900"],["15498.50000000","0.51451500"],["15498.48000000","0.00000000"],["15497.21000000","0.00000000"],["15495.07000000","0.00000000"],["15495.01000000","0.05000000"],["15493.78000000","0.04780600"],["15423.58000000","0.00000000"]],"a":[["15499.94000000","7.63765000"],["15500.22000000","0.03182600"],["15500.31000000","0.00000000"],["15500.32000000","0.00000000"],["15500.41000000","0.00000000"],["15500.59000000","0.02552500"],["15501.07000000","0.00000000"],["15501.09000000","0.00000000"],["15501.10000000","7.44329700"],["15501.62000000","1.42032100"],["15502.32000000","0.10000000"],["15502.33000000","0.00000000"],["15503.02000000","0.00000000"],["15503.03000000","0.00000000"],["15504.80000000","1.74800000"],["15504.83000000","0.03400000"],["15505.00000000","0.01212400"],["15505.28000000","0.05000000"],["15505.50000000","0.00000000"],["15505.51000000","0.00000000"],["15505.70000000","0.00000000"],["15505.73000000","0.00000000"],["15505.86000000","0.00000000"],["15505.97000000","1.19800000"],["15506.17000000","0.00000000"],["15506.33000000","0.20000000"],["15506.45000000","0.01000000"],["15506.85000000","0.01500000"],["15507.51000000","0.00000000"],["15507.90000000","0.00000000"],["15600.00000000","211.95035900"]]}}
2020-11-09T11:27:02.95638 btcusdt {"stream":"btcusdt@depth@100ms","data":{"e":"depthUpdate","E":1604921222949,"s":"BTCUSDT","U":6511143920,"u":6511143936,"b":[["15499.93000000","0.61868900"],["15499.91000000","0.01588300"],["15493.79000000","0.06748800"],["15477.81000000","0.00000000"]],"a":[["15499.94000000","2.88519500"],["15500.22000000","0.00000000"],["15501.29000000","0.00200000"],["15503.77000000","0.00610700"],["15504.59000000","0.25000000"],["15504.70000000","0.32100000"],["15505.96000000","0.20000000"],["15507.81000000","0.00000000"],["15508.96000000","1.25000000"],["15509.42000000","0.00000000"]]}}
2020-11-09T11:27:03.05684 btcusdt {"stream":"btcusdt@depth@100ms","data":{"e":"depthUpdate","E":1604921223050,"s":"BTCUSDT","U":6511143937,"u":6511143957,"b":[["15499.93000000","5.91868900"],["15495.06000000","0.00000000"],["15495.01000000","0.00000000"],["15494.98000000","0.05000000"],["15494.06000000","0.12902200"],["15493.80000000","0.10591000"],["15441.66000000","0.00000000"]],"a":[["15499.94000000","2.45432000"],["15500.59000000","0.00000000"],["15501.09000000","1.48086500"],["15501.10000000","7.42929100"],["15501.29000000","0.00400000"],["15501.61000000","0.00000000"],["15502.32000000","0.00000000"],["15504.13000000","0.25219400"],["15505.96000000","0.00000000"]]}}
2020-11-09T11:27:03.15608 btcusdt {"stream":"btcusdt@depth@100ms","data":{"e":"depthUpdate","E":1604921223150,"s":"BTCUSDT","U":6511143958,"u":6511143970,"b":[["15499.93000000","6.25621400"],["15499.91000000","0.00000000"],["15498.70000000","0.01643100"],["15492.44000000","0.00000000"]],"a":[["15499.94000000","0.72755000"],["15501.09000000","3.32331100"],["15504.28000000","0.00000000"],["15504.59000000","0.00000000"],["15504.98000000","0.11427900"],["15506.40000000","0.75000000"],["15508.96000000","0.00000000"],["15509.46000000","1.25000000"]]}}
2020-11-09T11:27:03.25632 btcusdt {"stream":"btcusdt@depth@100ms","data":{"e":"depthUpdate","E":1604921223250,"s":"BTCUSDT","U":6511143971,"u":6511143978,"b":[["15492.44000000","0.20000000"],["15405.50000000","0.00000000"]],"a":[["15499.94000000","0.72256900"],["15501.10000000","7.42800000"],["15504.97000000","0.01000000"],["15505.00000000","0.00212400"]]}}
2020-11-09T11:27:03.35831 btcusdt {"stream":"btcusdt@depth@100ms","data":{"e":"depthUpdate","E":1604921223350,"s":"BTCUSDT","U":6511143979,"u":6511143985,"b":[["15422.43000000","0.00648400"],["15369.35000000","0.00000000"]],"a":[["15499.94000000","0.71936900"],["15501.08000000","0.19888400"],["15503.01000000","0.00000000"],["15507.82000000","1.25000000"],["15509.46000000","0.00000000"]]}}
2020-11-09T11:27:03.45846 btcusdt {"stream":"btcusdt@depth@100ms","data":{"e":"depthUpdate","E":1604921223450,"s":"BTCUSDT","U":6511143986,"u":6511144002,"b":[["15498.86000000","0.00675800"],["15498.77000000","0.45588200"],["15498.70000000","0.00000000"],["15498.43000000","0.01795900"],["15498.35000000","0.00000000"],["15497.70000000","0.00000000"],["15496.79000000","0.04000000"],["15496.37000000","0.06000000"],["15495.34000000","0.16000000"]],"a":[["15499.94000000","0.71816800"],["15499.96000000","0.00199900"],["15499.98000000","0.00199900"],["15500.42000000","0.00901000"],["15500.71000000","0.01771800"],["15501.87000000","0.00000000"],["15983.40000000","0.00000000"]]}}
2020-11-09T11:27:03.55585 btcusdt {"stream":"btcusdt@depth@100ms","data":{"e":"depthUpdate","E":1604921223550,"s":"BTCUSDT","U":6511144003,"u":6511144008,"b":[["15499.93000000","6.25621400"],["15493.37000000","0.00000000"],["15492.44000000","0.00000000"],["15333.20000000","0.00000000"]],"a":[["15499.94000000","0.71496800"]]}}
2020-11-09T11:27:03.65625 btcusdt {"stream":"btcusdt@depth@100ms","data":{"e":"depthUpdate","E":1604921223650,"s":"BTCUSDT","U":6511144009,"u":6511144012,"b":[["15485.53000000","0.00000000"],["15297.05000000","0.00000000"]],"a":[["15499.94000000","0.65422600"],["15506.17000000","0.20000000"]]}}
2020-11-09T11:27:03.75985 btcusdt {"stream":"btcusdt@depth@100ms","data":{"e":"depthUpdate","E":1604921223750,"s":"BTCUSDT","U":6511144013,"u":6511144049,"b":[["15499.93000000","0.95621400"],["15497.29000000","0.00000000"],["15496.79000000","0.00000000"],["15496.37000000","0.00000000"],["15495.13000000","0.02000000"],["15494.96000000","0.16000000"],["15487.82000000","0.03361800"],["15484.66000000","0.00000000"],["15429.93000000","0.00800000"]],"a":[["15499.94000000","0.65327200"],["15500.71000000","0.01224900"],["15501.08000000","3.57390100"],["15501.09000000","0.00000000"],["15503.03000000","0.43107800"],["15504.03000000","0.03400000"],["15504.13000000","0.10000000"],["15504.19000000","0.11427900"],["15504.83000000","0.00000000"],["15504.98000000","0.00000000"],["15505.02000000","1.19800000"],["15505.18000000","0.29200000"],["15505.25000000","0.15700000"],["15505.97000000","0.00000000"],["15506.64000000","0.04000000"],["15506.79000000","0.00000000"],["15520.00000000","5.99091400"]]}}
2020-11-09T11:27:03.85753 btcusdt {"stream":"btcusdt@depth@100ms","data":{"e":"depthUpdate","E":1604921223850,"s":"BTCUSDT","U":6511144050,"u":6511144068,"b":[["15499.93000000","0.61868900"],["15498.86000000","0.00000000"],["15498.21000000","0.00625100"],["15495.34000000","0.00000000"],["15494.06000000","0.00000000"],["15492.40000000","0.12902200"],["15490.54000000","0.00000000"],["15490.01000000","0.00000000"],["15489.63000000","1.50000000"],["15484.18000000","1.17692800"],["15260.90000000","0.00000000"]],"a":[["15499.94000000","2.65327200"],["15500.40000000","0.00726900"],["15500.42000000","0.00000000"],["15500.70000000","0.10000000"],["15500.71000000","0.00000000"],["15504.13000000","0.00000000"]]}}
2020-11-09T11:27:03.95757 btcusdt {"stream":"btcusdt@depth@100ms","data":{"e":"depthUpdate","E":1604921223950,"s":"BTCUSDT","U":6511144069,"u":6511144090,"b":[["15499.93000000","0.50690000"],["15498.77000000","0.00870500"],["15498.47000000","0.00000000"],["15498.21000000","0.00000000"],["15493.31000000","0.24000000"],["15488.86000000","1.25000000"],["15488.63000000","0.00000000"],["15482.64000000","0.00000000"]],"a":[["15499.94000000","2.78579200"],["15500.69000000","0.15219400"],["15500.71000000","0.01990700"],["15501.10000000","7.30000000"],["15503.03000000","0.27888400"],["15505.09000000","0.08000000"],["15506.38000000","0.14400000"],["15506.92000000","0.00000000"],["15508.84000000","0.10000000"],["15512.17000000","0.00000000"],["15622.50000000","2.00000000"]]}}
2020-11-09T11:27:04.05831 btcusdt {"stream":"btcusdt@depth@100ms","data":{"e":"depthUpdate","E":1604921224050,"s":"BTCUSDT","U":6511144091,"u":6511144115,"b":[["15499.93000000","0.00479800"],["15498.50000000","0.01451500"],["15498.00000000","0.02464900"],["15496.03000000","0.00000000"],["15495.44000000","0.11427900"],["15495.05000000","0.00000000"],["15494.98000000","0.00000000"],["15494.97000000","0.05690000"],["15493.04000000","0.00000000"],["15488.86000000","0.00000000"]],"a":[["15499.94000000","8.21715200"],["15500.09000000","0.03182600"],["15500.71000000","0.01350900"],["15501.08000000","0.00000000"],["15505.26000000","0.00000000"],["15506.36000000","1.25000000"],["15507.82000000","0.00000000"]]}}
2020-11-09T11:27:04.16739 btcusdt {"stream":"btcusdt@depth@100ms","data":{"e":"depthUpdate","E":1604921224150,"s":"BTCUSDT","U":6511144116,"u":6511144139,"b":[["15499.93000000","0.00679800"],["15498.80000000","0.00000000"],["15495.35000000","0.50000000"],["15491.05000000","0.00000000"],["15490.88000000","0.00000000"],["15488.59000000","0.00000000"],["15488.50000000","0.00000000"],["15488.45000000","1.25000000"],["15426.56000000","0.00000000"]],"a":[["15499.94000000","8.56653300"],["15500.09000000","0.00000000"],["15502.05000000","0.08000000"],["15502.58000000","0.50000000"],["15504.02000000","0.00287800"],["15504.64000000","0.00000000"],["15505.60000000","0.10220900"],["15506.18000000","0.00000000"],["15506.64000000","0.00000000"],["15508.42000000","0.15450000"],["15516.67000000","0.00000000"],["15586.37000000","2.00000000"]]}}
