2020-11-09T11:25:59.12517 btcusdt {"stream":"btcusdt@depth@100ms","data":{"e":"depthUpdate","E":1604921159115,"s":"BTCUSDT","U":6511132993,"u":6511133082,"b":[["15511.15000000","0.46427900"],["15510.42000000","0.03384800"],["15510.41000000","0.00000000"],["15510.40000000","0.00000000"],["15510.37000000","0.12793700"],["15510.26000000","0.00000000"],["15510.21000000","0.00000000"],["15507.48000000","0.00000000"],["15506.93000000","0.00000000"],["15506.80000000","0.00000000"],["15506.05000000","0.00400000"],["15505.89000000","0.20000000"],["15505.88000000","0.00000000"],["15505.71000000","0.00000000"],["15505.33000000","0.02000000"],["15504.26000000","0.00000000"],["15503.19000000","0.00000000"],["15499.55000000","0.03359800"],["15496.21000000","0.20000000"],["15495.61000000","0.13439200"],["15491.52000000","0.00000000"],["15200.57000000","0.00000000"]],"a":[["15511.16000000","0.65975000"],["15511.79000000","0.10500000"],["15512.61000000","0.05345000"],["15513.09000000","0.01700000"],["15513.12000000","0.01700000"],["15513.46000000","0.00000000"],["15513.83000000","0.97400000"],["15513.92000000","1.74800000"],["15514.64000000","0.00000000"],["15514.97000000","0.00000000"],["15514.98000000","0.00000000"],["15514.99000000","0.13644700"],["15515.10000000","0.00000000"],["15515.12000000","0.00000000"],["15515.16000000","0.58779500"],["15515.17000000","0.00000000"],["15515.30000000","0.00000000"],["15515.51000000","1.24800000"],["15515.82000000","0.26575100"],["15515.86000000","0.00000000"],["15515.98000000","0.00000000"],["15515.99000000","0.00000000"],["15516.21000000","0.38350200"],["15516.34000000","0.00000000"],["15516.80000000","0.00000000"],["15516.81000000","0.01382400"],["15517.20000000","0.06655100"],["15517.35000000","0.00000000"],["15517.68000000","0.66735300"],["15517.95000000","6.71352100"],["15517.96000000","0.00000000"],["15518.60000000","0.00000000"],["15519.53000000","0.00000000"],["15520.02000000","0.00000000"],["15520.63000000","0.00000000"],["15520.94000000","0.00000000"],["15522.01000000","0.25767000"],["15524.47000000","0.30000000"],["15524.87000000","0.00000000"]]}}
2020-11-09T11:25:59.22384 btcusdt {"stream":"btcusdt@depth@100ms","data":{"e":"depthUpdate","E":1604921159215,"s":"BTCUSDT","U":6511133083,"u":6511133175,"b":[["15511.15000000","0.00000000"],["15510.42000000","0.00000000"],["15510.37000000","0.02868900"],["15509.79000000","0.00000000"],["15507.73000000","0.11427900"],["15505.89000000","0.00000000"],["15505.72000000","0.54600000"],["15505.14000000","0.00000000"],["15504.27000000","0.00000000"],["15503.62000000","0.00000000"],["15503.54000000","0.48000000"],["15502.88000000","1.25000000"],["15501.38000000","0.00201000"],["15501.35000000","0.00000000"],["15500.51000000","0.00000000"]],"a":[["15510.38000000","2.82218800"],["15510.43000000","0.09883100"],["15510.80000000","0.02008700"],["15511.00000000","0.00000000"],["15511.11000000","0.00000000"],["15511.12000000","0.00000000"],["15511.14000000","1.15533400"],["15511.15000000","0.00627400"],["15511.16000000","2.00690000"],["15511.66000000","0.00000000"],["15512.61000000","0.08000000"],["15513.09000000","0.00000000"],["15513.12000000","0.00000000"],["15513.83000000","0.00000000"],["15513.92000000","0.00000000"],["15515.15000000","0.12895800"],["15515.16000000","0.15700000"],["15515.31000000","0.00000000"],["15515.40000000","0.03223500"],["15515.50000000","0.00000000"],["15515.82000000","0.00000000"],["15516.21000000","0.00000000"],["15516.42000000","0.14550000"],["15516.68000000","0.12894400"],["15516.81000000","0.00000000"],["15517.20000000","0.00000000"],["15517.68000000","0.00000000"],["15517.85000000","0.01500000"],["15517.95000000","0.00000000"],["15517.96000000","0.00000000"],["15518.54000000","0.00000000"],["15520.38000000","0.00000000"],["15521.45000000","0.10085300"],["15522.14000000","0.29946900"],["15522.45000000","0.10000000"],["15525.68000000","0.00000000"],["15666.03000000","0.00000000"]]}}
2020-11-09T11:25:59.32620 btcusdt {"stream":"btcusdt@depth@100ms","data":{"e":"depthUpdate","E":1604921159315,"s":"BTCUSDT","U":6511133176,"u":6511133241,"b":[["15507.53000000","0.08397300"],["15507.15000000","0.01739600"],["15505.72000000","0.00000000"],["15505.33000000","0.00000000"],["15504.20000000","0.08000000"],["15503.54000000","0.00000000"],["15502.89000000","0.00000000"],["15502.75000000","0.08000000"],["15447.28000000","0.24000000"]],"a":[["15510.38000000","5.05123700"],["15511.10000000","0.00000000"],["15511.14000000","0.00000000"],["15511.15000000","0.18627400"],["15511.79000000","0.00000000"],["15512.56000000","0.00000000"],["15513.09000000","0.00000000"],["15513.10000000","0.00000000"],["15513.28000000","0.00000000"],["15513.36000000","0.00000000"],["15513.83000000","0.00000000"],["15513.90000000","0.00000000"],["15514.12000000","1.19800000"],["15514.55000000","0.29200000"],["15514.69000000","0.40345200"],["15514.74000000","0.00000000"],["15514.82000000","0.50000000"],["15514.84000000","0.00000000"],["15514.85000000","0.11427900"],["15514.90000000","0.00000000"],["15515.14000000","0.56627600"],["15515.32000000","0.00000000"],["15515.39000000","0.00000000"],["15515.51000000","0.05000000"],["15515.82000000","0.26575300"],["15516.21000000","0.30500000"],["15516.31000000","0.00000000"],["15517.68000000","0.66735200"],["15517.96000000","0.00000000"],["15518.22000000","0.00000000"],["15518.28000000","0.00000000"],["15519.00000000","0.06714100"],["15520.45000000","0.00000000"],["15523.18000000","0.06727700"],["15525.67000000","0.23546800"],["15525.97000000","1.00000000"]]}}
2020-11-09T11:25:59.42546 btcusdt {"stream":"btcusdt@depth@100ms","data":{"e":"depthUpdate","E":1604921159415,"s":"BTCUSDT","U":6511133242,"u":6511133259,"b":[["15507.87000000","0.01297000"],["15504.13000000","0.00000000"],["15501.88000000","0.01900000"],["15432.81000000","0.00647900"]],"a":[["15511.13000000","0.08000000"],["15511.83000000","0.01978800"],["15512.37000000","0.03400000"],["15513.17000000","1.74800000"],["15514.69000000","0.00000000"],["15514.82000000","0.00000000"],["15515.14000000","0.00000000"],["15515.37000000","0.50000000"],["15515.82000000","0.00000000"],["15517.41000000","0.00000000"],["15518.17000000","0.14850000"],["15518.95000000","0.01382400"]]}}
2020-11-09T11:25:59.52454 btcusdt {"stream":"btcusdt@depth@100ms","data":{"e":"depthUpdate","E":1604921159515,"s":"BTCUSDT","U":6511133260,"u":6511133282,"b":[["15510.37000000","0.02714100"],["15507.73000000","0.00000000"],["15507.39000000","0.00778500"]],"a":[["15510.38000000","5.05323700"],["15511.13000000","0.00000000"],["15511.76000000","0.00878700"],["15512.37000000","0.00000000"],["15512.69000000","0.00000000"],["15512.85000000","0.01700000"],["15512.86000000","0.01700000"],["15513.17000000","0.00000000"],["15513.66000000","1.74800000"],["15514.12000000","0.00000000"],["15514.58000000","1.19800000"],["15515.37000000","0.00000000"],["15517.33000000","0.25845100"],["15517.34000000","0.50000000"],["15519.43000000","0.06719300"],["15522.53000000","0.00000000"],["15523.38000000","0.05681900"],["15561.00000000","0.15645800"]]}}
2020-11-09T11:25:59.62537 btcusdt {"stream":"btcusdt@depth@100ms","data":{"e":"depthUpdate","E":1604921159615,"s":"BTCUSDT","U":6511133283,"u":6511133292,"b":[["15506.67000000","0.11427900"],["15504.13000000","0.00000000"]],"a":[["15510.38000000","3.34087900"],["15513.65000000","0.87400200"],["15515.15000000","0.44995800"],["15516.80000000","0.01000000"],["15517.45000000","0.00000000"],["15522.31000000","0.20000000"]]}}
2020-11-09T11:25:59.72284 btcusdt {"stream":"btcusdt@depth@100ms","data":{"e":"depthUpdate","E":1604921159715,"s":"BTCUSDT","U":6511133293,"u":6511133320,"b":[["15508.97000000","0.01645500"],["15507.87000000","0.00000000"],["15507.39000000","0.00000000"],["15507.16000000","0.50000000"],["15504.90000000","0.10000000"],["15503.56000000","0.30000000"],["15503.51000000","0.50000000"],["15502.69000000","1.00000000"],["15500.53000000","0.25762100"],["15500.04000000","0.00000000"],["15499.71000000","0.00000000"],["15499.03000000","0.00100000"]],"a":[["15510.38000000","3.28083800"],["15511.76000000","0.00000000"],["15511.83000000","0.00000000"],["15512.82000000","0.01866800"],["15513.27000000","0.25900000"],["15513.28000000","0.20000000"],["15513.52000000","0.50000000"],["15513.65000000","0.00000000"],["15514.76000000","0.10000000"],["15514.92000000","0.30900000"],["15516.21000000","0.00000000"],["15521.81000000","0.30000000"],["15523.02000000","1.00000000"],["15524.36000000","1.50000000"],["15524.47000000","0.00000000"],["15525.97000000","0.00000000"]]}}
2020-11-09T11:25:59.82538 btcusdt {"stream":"btcusdt@depth@100ms","data":{"e":"depthUpdate","E":1604921159815,"s":"BTCUSDT","U":6511133321,"u":6511133335,"b":[["15510.37000000","0.52714100"],["15509.45000000","0.15680600"],["15507.52000000","5.34981100"],["15506.24000000","2.00000000"],["15504.84000000","1.25000000"],["15504.21000000","0.08000000"],["15502.88000000","0.00000000"],["15464.50000000","0.00000000"]],"a":[["15510.38000000","0.62798800"],["15510.80000000","0.00000000"],["15513.51000000","1.12400100"],["15514.85000000","0.00000000"],["15515.15000000","0.32100000"],["15515.42000000","0.11427900"]]}}
2020-11-09T11:25:59.92295 btcusdt {"stream":"btcusdt@depth@100ms","data":{"e":"depthUpdate","E":1604921159916,"s":"BTCUSDT","U":6511133336,"u":6511133353,"b":[["15508.97000000","0.00000000"],["15502.70000000","0.20000000"]],"a":[["15510.38000000","0.39893900"],["15511.14000000","1.00658700"],["15511.15000000","0.00627400"],["15512.82000000","0.00000000"],["15512.85000000","0.00000000"],["15512.86000000","0.00000000"],["15513.28000000","0.00000000"],["15513.66000000","0.00000000"],["15514.58000000","0.00000000"],["15517.97000000","0.00000000"],["15517.99000000","0.05358300"],["15522.54000000","0.02382800"],["15525.67000000","0.00000000"],["15528.87000000","0.23546600"]]}}
2020-11-09T11:26:00.02306 btcusdt {"stream":"btcusdt@depth@100ms","data":{"e":"depthUpdate","E":1604921160016,"s":"BTCUSDT","U":6511133354,"u":6511133418,"b":[["15510.37000000","5.85533500"],["15509.80000000","0.07725000"],["15509.71000000","0.00000000"],["15507.52000000","0.04981100"],["15507.16000000","0.00000000"],["15506.41000000","0.54600000"],["15505.01000000","0.08000000"],["15504.96000000","0.96000000"],["15504.20000000","0.00000000"],["15503.44000000","0.44188500"],["15502.75000000","0.00000000"],["15500.01000000","0.02236400"],["15500.00000000","14.50055400"],["15499.98000000","0.50430700"],["15497.93000000","0.00000000"],["15487.70000000","0.00000000"],["15466.50000000","2.00000000"]],"a":[["15510.38000000","0.00200000"],["15510.43000000","0.00000000"],["15511.14000000","0.21604100"],["15512.61000000","0.00000000"],["15513.14000000","0.38956800"],["15513.15000000","0.46113400"],["15513.27000000","0.00000000"],["15513.46000000","0.25000000"],["15513.48000000","0.00000000"],["15513.50000000","0.00000000"],["15513.51000000","0.00000000"],["15513.84000000","0.00000000"],["15513.87000000","0.01700000"],["15513.88000000","0.01700000"],["15514.55000000","0.00000000"],["15514.75000000","0.77378700"],["15514.90000000","2.24842500"],["15514.91000000","0.20540000"],["15515.02000000","1.19800000"],["15515.14000000","0.00000000"],["15515.45000000","0.29200000"],["15515.51000000","0.00000000"],["15515.82000000","0.00000000"],["15517.99000000","0.00000000"],["15518.74000000","0.10000000"],["15519.73000000","0.00000000"],["15521.58000000","0.00000000"],["15522.55000000","0.00000000"],["15525.70000000","0.13438000"],["15526.52000000","0.48374700"]]}}
2020-11-09T11:26:00.12502 btcusdt {"stream":"btcusdt@depth@100ms","data":{"e":"depthUpdate","E":1604921160116,"s":"BTCUSDT","U":6511133419,"u":6511133449,"b":[["15510.37000000","8.14368900"],["15509.93000000","0.07851200"],["15509.80000000","0.00000000"],["15507.53000000","0.03397300"],["15506.68000000","0.01149900"],["15499.62000000","1.00861400"],["15497.57000000","0.30900000"],["15467.48000000","0.00000000"]],"a":[["15510.38000000","0.27922300"],["15511.13000000","0.00000000"],["15511.14000000","0.00000000"],["15511.16000000","0.00690000"],["15513.14000000","0.00000000"],["15513.15000000","0.00000000"],["15514.74000000","0.20000000"],["15514.75000000","1.02400100"],["15514.91000000","0.15540000"],["15515.33000000","0.05097300"],["15515.45000000","0.30200000"],["15515.64000000","0.00000000"],["15516.80000000","0.00000000"],["15517.26000000","0.01000000"],["15520.49000000","0.19068200"],["15522.54000000","0.04934600"],["15528.00000000","0.00000000"],["15545.01000000","0.00000000"],["15564.00000000","0.10827300"]]}}
2020-11-09T11:26:00.22372 btcusdt {"stream":"btcusdt@depth@100ms","data":{"e":"depthUpdate","E":1604921160216,"s":"BTCUSDT","U":6511133450,"u":6511133472,"b":[["15510.37000000","8.21704300"],["15509.93000000","0.00000000"],["15505.01000000","0.13000000"],["15503.05000000","0.19563800"],["15500.72000000","0.30000000"]],"a":[["15510.38000000","0.00200000"],["15511.14000000","0.00000000"],["15511.79000000","0.01000000"],["15513.13000000","0.00000000"],["15513.28000000","0.15900200"],["15514.90000000","2.04842500"],["15514.91000000","0.00690000"],["15515.02000000","0.00000000"],["15515.14000000","0.66229600"],["15515.42000000","0.00000000"],["15515.56000000","1.19800000"],["15517.34000000","0.00000000"],["15518.17000000","0.00000000"],["15525.00000000","0.03610500"],["15665.48000000","0.00100000"]]}}
2020-11-09T11:26:00.32389 btcusdt {"stream":"btcusdt@depth@100ms","data":{"e":"depthUpdate","E":1604921160316,"s":"BTCUSDT","U":6511133473,"u":6511133501,"b":[["15509.59000000","0.01891600"],["15504.22000000","0.20000000"],["15502.94000000","0.00000000"],["15200.00000000","28.52934300"]],"a":[["15513.86000000","0.20000000"],["15513.87000000","0.00000000"],["15513.88000000","0.00000000"],["15514.75000000","0.00000000"],["15514.90000000","0.30042500"],["15514.94000000","0.03400000"],["15515.15000000","0.00000000"],["15515.33000000","0.00097300"],["15515.42000000","0.77500200"],["15515.43000000","0.05000000"],["15515.45000000","0.29200000"],["15515.56000000","1.20800000"],["15515.97000000","1.74800000"],["15516.30000000","0.11427900"],["15517.26000000","0.00000000"],["15517.33000000","0.00000000"],["15517.37000000","0.01000000"],["15517.55000000","0.00000000"],["15517.77000000","0.01500000"],["15517.85000000","0.00000000"],["15517.95000000","0.00000000"]]}}
2020-11-09T11:26:00.42414 btcusdt {"stream":"btcusdt@depth@100ms","data":{"e":"depthUpdate","E":1604921160416,"s":"BTCUSDT","U":6511133502,"u":6511133571,"b":[["15511.93000000","0.50000000"],["15511.76000000","0.07886700"],["15511.17000000","0.00000000"],["15511.16000000","0.00128900"],["15511.15000000","0.00000000"],["15510.43000000","0.00000000"],["15510.38000000","0.00627500"],["15510.37000000","0.24795000"],["15509.11000000","0.00724900"],["15508.55000000","0.11427900"],["15507.53000000","0.03268400"],["15506.67000000","0.00000000"],["15506.42000000","0.08000000"],["15503.44000000","0.00000000"],["15501.37000000","0.14550000"],["15500.68000000","0.00306000"],["15491.64000000","0.29400000"]],"a":[["15510.38000000","0.00000000"],["15511.15000000","0.00000000"],["15511.16000000","0.00000000"],["15511.79000000","0.00000000"],["15511.80000000","0.00000000"],["15512.09000000","0.00000000"],["15512.62000000","0.00000000"],["15513.21000000","0.27835800"],["15513.22000000","0.26722300"],["15513.23000000","0.27835800"],["15513.24000000","0.13917900"],["15513.25000000","0.00000000"],["15513.26000000","0.00000000"],["15513.28000000","0.00000000"],["15513.31000000","0.00855900"],["15513.41000000","0.01675700"],["15513.46000000","0.00000000"],["15513.64000000","0.02008700"],["15514.62000000","0.00000000"],["15514.90000000","0.00000000"],["15514.92000000","0.00000000"],["15514.94000000","0.00000000"],["15515.01000000","0.00000000"],["15515.14000000","0.00000000"],["15515.16000000","0.00000000"],["15515.40000000","0.00000000"],["15515.42000000","0.00000000"],["15515.45000000","0.00000000"],["15515.56000000","0.01000000"],["15515.74000000","0.03400000"],["15515.84000000","0.00000000"],["15515.97000000","0.00000000"],["15516.42000000","0.00000000"],["15516.65000000","0.00000000"],["15516.68000000","0.00000000"],["15516.77000000","0.15700000"],["15516.91000000","0.29200000"],["15517.03000000","1.19800000"],["15517.10000000","1.74800000"],["15517.68000000","0.00000000"],["15517.72000000","0.00000000"],["15518.46000000","0.00000000"],["15518.85000000","0.50000000"],["15524.36000000","0.00000000"]]}}
2020-11-09T11:26:00.52381 btcusdt {"stream":"btcusdt@depth@100ms","data":{"e":"depthUpdate","E":1604921160516,"s":"BTCUSDT","U":6511133572,"u":6511133619,"b":[["15512.35000000","0.41236900"],["15511.93000000","0.00000000"],["15511.76000000","0.00000000"],["15511.37000000","0.07366300"],["15510.38000000","0.16308100"],["15510.37000000","0.05533500"],["15509.45000000","0.00000000"],["15507.60000000","0.16000000"],["15505.38000000","0.05000000"],["15505.01000000","0.08000000"],["15504.22000000","0.00000000"],["15491.40000000","0.00000000"],["15447.28000000","0.00000000"],["14423.13000000","0.00000000"]],"a":[["15512.36000000","6.04711100"],["15512.44000000","2.00000000"],["15513.02000000","0.00000000"],["15513.12000000","0.00000000"],["15513.21000000","0.00000000"],["15513.22000000","0.00000000"],["15513.23000000","0.00000000"],["15513.24000000","0.00000000"],["15513.58000000","0.02008700"],["15513.64000000","0.00000000"],["15515.02000000","0.03223600"],["15515.43000000","0.00000000"],["15515.56000000","0.00000000"],["15517.02000000","0.20000000"],["15517.26000000","0.05000000"],["15517.37000000","0.00000000"],["15517.39000000","0.01000000"],["15518.85000000","0.00000000"],["15519.06000000","0.00000000"],["15519.20000000","0.01690000"],["15519.29000000","0.50000000"],["15519.33000000","0.12894400"],["15519.90000000","0.00000000"],["15520.00000000","5.47780900"],["15520.75000000","1.25000000"],["15522.88000000","0.05681900"],["15523.38000000","0.00000000"]]}}
2020-11-09T11:26:00.62385 btcusdt {"stream":"btcusdt@depth@100ms","data":{"e":"depthUpdate","E":1604921160616,"s":"BTCUSDT","U":6511133620,"u":6511133632,"b":[["15510.38000000","0.00627500"],["15509.60000000","0.15680600"],["15390.00000000","0.60008800"],["14419.65000000","0.17337400"]],"a":[["15512.36000000","8.77032000"],["15513.11000000","0.17500000"],["15513.19000000","0.01377500"],["15515.37000000","0.01036200"],["15517.77000000","0.00000000"],["15519.17000000","0.01500000"],["15519.41000000","0.09621800"]]}}
2020-11-09T11:26:00.74094 btcusdt {"stream":"btcusdt@depth@100ms","data":{"e":"depthUpdate","E":1604921160716,"s":"BTCUSDT","U":6511133633,"u":6511133646,"b":[["15512.35000000","0.41159900"],["15510.18000000","0.00200000"],["15509.57000000","0.00876400"],["15509.11000000","0.00000000"],["15506.43000000","0.31300000"],["15506.25000000","1.00000100"],["15505.39000000","1.02822600"]],"a":[["15512.36000000","8.96293500"],["15513.31000000","0.00000000"],["15513.78000000","0.00778800"],["15515.82000000","0.11427900"],["15516.30000000","0.00000000"],["15526.51000000","0.00000000"]]}}
2020-11-09T11:26:00.82785 btcusdt {"stream":"btcusdt@depth@100ms","data":{"e":"depthUpdate","E":1604921160816,"s":"BTCUSDT","U":6511133647,"u":6511133657,"b":[["15508.55000000","0.00000000"],["15508.04000000","0.11427900"],["15507.53000000","0.00000000"],["15504.03000000","1.08678700"],["15502.70000000","0.00000000"],["15498.75000000","0.00000000"],["15411.00000000","1.19794700"],["15390.00000000","0.22325800"]],"a":[["15516.71000000","0.85933700"],["17836.94000000","0.90120000"],["17847.18000000","0.01910000"]]}}
2020-11-09T11:26:00.93157 btcusdt {"stream":"btcusdt@depth@100ms","data":{"e":"depthUpdate","E":1604921160916,"s":"BTCUSDT","U":6511133658,"u":6511133667,"b":[["15509.98000000","0.01923800"],["15509.59000000","0.00000000"],["15432.81000000","0.00000000"]],"a":[["15512.36000000","8.96147400"],["15513.41000000","0.00000000"],["15513.81000000","0.01504000"],["15517.71000000","0.00000000"],["15521.04000000","0.00000000"],["15525.58000000","0.40548900"],["15538.16000000","0.00000000"]]}}
2020-11-09T11:26:01.02605 btcusdt {"stream":"btcusdt@depth@100ms","data":{"e":"depthUpdate","E":1604921161016,"s":"BTCUSDT","U":6511133668,"u":6511133684,"b":[["15512.35000000","0.32394700"],["15510.37000000","0.03019400"],["15509.44000000","0.00000000"],["15507.52000000","0.02106400"],["15505.40000000","0.05000000"],["15505.38000000","0.00000000"],["15501.69000000","0.05000000"],["15414.00000000","0.37683000"]],"a":[["15512.36000000","8.96067600"],["15516.83000000","0.05000000"],["15517.26000000","0.00000000"],["15517.70000000","0.00000000"],["15522.54000000","0.02551800"],["15523.10000000","0.17122500"],["15524.23000000","0.02382800"],["15609.00000000","0.10827300"],["17847.18000000","0.00500000"]]}}
2020-11-09T11:26:01.13177 btcusdt {"stream":"btcusdt@depth@100ms","data":{"e":"depthUpdate","E":1604921161116,"s":"BTCUSDT","U":6511133685,"u":6511133697,"b":[["15499.65000000","1.09700000"],["15473.57000000","0.25000000"],["15289.54000000","0.00000000"]],"a":[["15512.36000000","8.95869400"],["15516.70000000","0.20000000"],["15517.69000000","0.00000000"],["15519.75000000","1.25000000"],["15520.75000000","0.00000000"],["15522.54000000","0.00000000"],["15522.94000000","0.02907100"],["15524.23000000","0.04934600"],["15551.14000000","0.29891500"]]}}
2020-11-09T11:26:01.22392 btcusdt {"stream":"btcusdt@depth@100ms","data":{"e":"depthUpdate","E":1604921161216,"s":"BTCUSDT","U":6511133698,"u":6511133720,"b":[["15511.18000000","0.01853700"],["15510.64000000","0.00721700"],["15509.98000000","0.00000000"],["15509.57000000","0.00000000"],["15305.31000000","0.00100000"]],"a":[["15512.36000000","8.89797300"],["15513.78000000","0.00000000"],["15513.81000000","0.00000000"],["15514.73000000","0.12895800"],["15515.14000000","0.01886100"],["15516.96000000","0.01000000"],["15517.39000000","0.00000000"],["15521.81000000","0.00000000"],["15523.01000000","0.02968800"],["15523.02000000","0.00000000"],["15524.56000000","0.30000000"],["15525.58000000","1.40548900"],["15526.77000000","0.00000000"],["15527.20000000","0.00000000"],["15555.01000000","0.13259300"],["15606.00000000","0.38817000"]]}}
2020-11-09T11:26:01.37634 btcusdt {"stream":"btcusdt@depth@100ms","data":{"e":"depthUpdate","E":1604921161316,"s":"BTCUSDT","U":6511133721,"u":6511133725,"b":[],"a":[["15512.36000000","8.70535800"],["15515.19000000","0.08924800"],["15517.02000000","0.00000000"],["15519.43000000","0.00000000"],["15545.16000000","0.03859700"]]}}
2020-11-09T11:26:01.42392 btcusdt {"stream":"btcusdt@depth@100ms","data":{"e":"depthUpdate","E":1604921161416,"s":"BTCUSDT","U":6511133726,"u":6511133735,"b":[["15511.18000000","0.00000000"],["15504.54000000","0.54346900"],["15503.06000000","0.20000000"],["15455.80000000","0.24000000"],["15434.78000000","0.00647800"]],"a":[["15514.25000000","0.47013900"],["15524.48000000","0.38618900"],["15527.99000000","0.01030300"],["17836.94000000","0.91530000"],["17847.18000000","0.00000000"]]}}
2020-11-09T11:26:01.53031 btcusdt {"stream":"btcusdt@depth@100ms","data":{"e":"depthUpdate","E":1604921161516,"s":"BTCUSDT","U":6511133736,"u":6511133753,"b":[["15512.35000000","0.32594700"],["15511.58000000","0.01419100"],["15511.38000000","0.00775900"],["15510.64000000","0.00000000"],["15510.37000000","0.02819400"],["15493.67000000","0.00000000"]],"a":[["15512.36000000","3.08859100"],["15514.24000000","0.08000000"],["15514.25000000","0.00000000"],["15515.14000000","0.00000000"],["15515.19000000","0.08200000"],["15515.87000000","0.00807300"],["15515.93000000","0.01341900"],["15516.70000000","0.00000000"],["15519.41000000","0.00000000"],["15522.88000000","0.00000000"],["15523.67000000","0.05681900"]]}}
2020-11-09T11:26:01.62579 btcusdt {"stream":"btcusdt@depth@100ms","data":{"e":"depthUpdate","E":1604921161616,"s":"BTCUSDT","U":6511133754,"u":6511133759,"b":[["15503.06000000","0.00000000"],["15495.42000000","0.06727100"],["15437.51000000","0.00000000"]],"a":[["15518.77000000","0.01000000"],["15519.20000000","0.00690000"],["15520.49000000","0.00000000"]]}}
2020-11-09T11:26:01.72468 btcusdt {"stream":"btcusdt@depth@100ms","data":{"e":"depthUpdate","E":1604921161717,"s":"BTCUSDT","U":6511133760,"u":6511133764,"b":[["15438.69000000","0.66957800"]],"a":[["15512.36000000","3.21559100"],["15522.14000000","0.00000000"],["15525.70000000","0.00000000"],["15564.00000000","0.00000000"]]}}
2020-11-09T11:26:01.82593 btcusdt {"stream":"btcusdt@depth@100ms","data":{"e":"depthUpdate","E":1604921161817,"s":"BTCUSDT","U":6511133765,"u":6511133769,"b":[],"a":[["15513.11000000","0.00000000"],["15522.14000000","0.30080400"],["15528.01000000","0.13437700"],["15535.00000000","0.84600800"],["17836.94000000","0.92030000"]]}}
2020-11-09T11:26:01.92696 btcusdt {"stream":"btcusdt@depth@100ms","data":{"e":"depthUpdate","E":1604921161917,"s":"BTCUSDT","U":6511133770,"u":6511133773,"b":[["15512.35000000","0.31623400"],["15503.65000000","0.20000000"]],"a":[["15512.36000000","8.51759100"]]}}
2020-11-09T11:26:02.02478 btcusdt {"stream":"btcusdt@depth@100ms","data":{"e":"depthUpdate","E":1604921162017,"s":"BTCUSDT","U":6511133774,"u":6511133784,"b":[["15512.35000000","0.31706500"],["15509.60000000","0.00000000"],["15508.05000000","0.15680600"],["15493.10000000","0.23544900"],["15490.53000000","0.00000000"]],"a":[["15512.36000000","6.47051400"],["15512.44000000","0.00000000"],["15513.18000000","0.01000000"],["15524.39000000","0.13438100"]]}}
2020-11-09T11:26:02.12481 btcusdt {"stream":"btcusdt@depth@100ms","data":{"e":"depthUpdate","E":1604921162117,"s":"BTCUSDT","U":6511133785,"u":6511133800,"b":[["15511.66000000","0.00618400"],["15511.38000000","0.00000000"],["15501.20000000","0.50428300"],["15500.84000000","1.00856600"],["15499.98000000","0.00000000"],["15499.62000000","0.00000000"],["15481.43000000","0.50000000"],["15478.33000000","0.00000000"]],"a":[["15512.36000000","1.17051400"],["15514.73000000","0.00000000"],["15515.58000000","0.00606600"],["15515.66000000","0.01579800"],["15515.87000000","0.00000000"],["15515.93000000","0.00000000"],["15548.52000000","0.00477100"],["15552.85000000","0.00000000"]]}}
2020-11-09T11:26:02.22460 btcusdt {"stream":"btcusdt@depth@100ms","data":{"e":"depthUpdate","E":1604921162217,"s":"BTCUSDT","U":6511133801,"u":6511133810,"b":[["15512.35000000","0.23106500"],["15505.01000000","0.08000000"]],"a":[["15512.36000000","5.73003400"],["15516.87000000","0.12893100"],["15517.18000000","0.32100000"],["15517.80000000","0.20000000"],["15519.75000000","1.25000000"]]}}
2020-11-09T11:26:02.32454 btcusdt {"stream":"btcusdt@depth@100ms","data":{"e":"depthUpdate","E":1604921162317,"s":"BTCUSDT","U":6511133811,"u":6511133816,"b":[["15497.17000000","0.01935800"],["15490.54000000","0.00000000"],["15455.80000000","0.48000000"]],"a":[["15512.36000000","7.73003400"],["15517.80000000","0.00000000"],["15522.24000000","0.03359500"]]}}
2020-11-09T11:26:02.42378 btcusdt {"stream":"btcusdt@depth@100ms","data":{"e":"depthUpdate","E":1604921162417,"s":"BTCUSDT","U":6511133817,"u":6511133821,"b":[["15512.35000000","0.23274700"]],"a":[["15512.36000000","2.61213400"],["15513.19000000","0.00000000"]]}}
2020-11-09T11:26:02.52522 btcusdt {"stream":"btcusdt@depth@100ms","data":{"e":"depthUpdate","E":1604921162517,"s":"BTCUSDT","U":6511133822,"u":6511133827,"b":[],"a":[["15512.36000000","2.43003400"],["15514.26000000","0.54825900"],["15517.17000000","0.00000000"],["15523.38000000","0.05681900"],["15523.67000000","0.00000000"]]}}
2020-11-09T11:26:02.62563 btcusdt {"stream":"btcusdt@depth@100ms","data":{"e":"depthUpdate","E":1604921162617,"s":"BTCUSDT","U":6511133828,"u":6511133829,"b":[],"a":[["15516.90000000","0.20000000"],["15520.75000000","0.19038900"]]}}
2020-11-09T11:26:02.72368 btcusdt {"stream":"btcusdt@depth@100ms","data":{"e":"depthUpdate","E":1604921162717,"s":"BTCUSDT","U":6511133830,"u":6511133831,"b":[],"a":[["15549.95000000","0.00067800"],["15606.00000000","0.49644300"]]}}
2020-11-09T11:26:02.82464 btcusdt {"stream":"btcusdt@depth@100ms","data":{"e":"depthUpdate","E":1604921162817,"s":"BTCUSDT","U":6511133832,"u":6511133837,"b":[],"a":[["15512.36000000","0.36977800"],["15513.51000000","0.10000000"],["15514.76000000","0.00000000"],["15516.87000000","0.00000000"],["15586.11000000","0.00000000"]]}}
2020-11-09T11:26:02.92573 btcusdt {"stream":"btcusdt@depth@100ms","data":{"e":"depthUpdate","E":1604921162917,"s":"BTCUSDT","U":6511133838,"u":6511133841,"b":[["15512.35000000","0.23360700"],["15504.54000000","0.00000000"]],"a":[["15516.77000000","0.47800000"],["25000.00000000","20.89396300"]]}}
2020-11-09T11:26:03.03122 btcusdt {"stream":"btcusdt@depth@100ms","data":{"e":"depthUpdate","E":1604921163017,"s":"BTCUSDT","U":6511133842,"u":6511133905,"b":[["15512.35000000","0.00000000"],["15511.66000000","0.00000000"],["15511.58000000","0.00000000"],["15511.37000000","0.00000000"],["15511.16000000","0.00000000"],["15510.38000000","0.00000000"],["15510.37000000","0.00000000"],["15510.20000000","0.56586600"],["15510.18000000","0.00000000"],["15508.96000000","0.00000000"],["15508.48000000","0.00000000"],["15508.16000000","0.00000000"],["15508.05000000","0.14434300"],["15508.04000000","0.00000000"],["15507.92000000","0.54600000"],["15507.61000000","0.01248500"],["15506.84000000","0.11427900"],["15506.68000000","0.00000000"],["15506.43000000","0.00000000"],["15506.41000000","0.00000000"],["15506.25000000","0.00000000"],["15505.39000000","0.00000000"],["15500.68000000","0.00000000"],["15491.64000000","0.00000000"]],"a":[["15510.21000000","0.00000000"],["15512.24000000","0.00000000"],["15512.33000000","0.60796900"],["15512.34000000","0.00000000"],["15512.35000000","0.00000000"],["15512.36000000","2.36977800"],["15513.50000000","0.30000000"],["15513.58000000","0.00000000"],["15513.78000000","0.01700000"],["15513.79000000","0.01700000"],["15514.23000000","0.31413100"],["15514.69000000","0.97745100"],["15514.82000000","1.74800000"],["15514.90000000","0.00000000"],["15515.02000000","0.95223600"],["15515.17000000","0.00000000"],["15515.74000000","0.00000000"],["15516.41000000","1.19800000"],["15516.45000000","0.00000000"],["15516.57000000","0.92000000"],["15516.70000000","0.00000000"],["15516.90000000","0.00000000"],["15517.03000000","0.00000000"],["15517.10000000","0.00000000"],["15517.13000000","0.92000000"],["15524.11000000","0.20000000"],["15541.00000000","0.80950600"],["15547.83000000","0.00000000"],["15622.27000000","0.00000000"]]}}
2020-11-09T11:26:03.12402 btcusdt {"stream":"btcusdt@depth@100ms","data":{"e":"depthUpdate","E":1604921163117,"s":"BTCUSDT","U":6511133906,"u":6511133974,"b":[["15511.76000000","0.50000000"],["15511.65000000","0.00690000"],["15511.58000000","0.01588200"],["15511.41000000","0.00813300"],["15511.05000000","0.06504300"],["15510.98000000","0.00000000"],["15510.74000000","0.00000000"],["15510.20000000","0.06540300"],["15508.05000000","0.18934300"],["15507.93000000","0.01241300"],["15507.92000000","0.12000000"],["15507.61000000","0.00000000"],["15506.25000000","1.00000200"],["15505.40000000","0.00000000"],["15505.38000000","0.05000000"],["15499.55000000","0.00000000"],["15495.61000000","0.00000000"],["15477.63000000","0.00000000"]],"a":[["15511.77000000","5.58949000"],["15512.17000000","0.00000000"],["15512.22000000","0.00000000"],["15512.23000000","0.00000000"],["15512.26000000","0.00000000"],["15512.32000000","0.01000000"],["15512.33000000","0.00000000"],["15512.35000000","0.01000000"],["15512.36000000","2.00200000"],["15512.92000000","0.03629400"],["15513.18000000","0.00000000"],["15513.50000000","0.00000000"],["15513.78000000","0.00000000"],["15513.79000000","0.00000000"],["15513.85000000","0.20000000"],["15514.23000000","0.00000000"],["15514.69000000","0.00000000"],["15514.74000000","0.00000000"],["15514.82000000","0.00000000"],["15515.76000000","0.05000000"],["15515.88000000","0.03400000"],["15515.90000000","0.01000000"],["15516.56000000","0.20000000"],["15516.83000000","0.00000000"],["15516.91000000","2.04000000"],["15516.96000000","0.00000000"],["15517.02000000","0.00000000"],["15517.71000000","0.01000000"],["15518.11000000","0.01500000"],["15518.77000000","0.00000000"],["15519.17000000","0.00000000"],["15524.11000000","0.00000000"]]}}
2020-11-09T11:26:03.22394 btcusdt {"stream":"btcusdt@depth@100ms","data":{"e":"depthUpdate","E":1604921163217,"s":"BTCUSDT","U":6511133975,"u":6511133992,"b":[["15508.05000000","0.14434300"],["15507.93000000","0.00000000"],["15505.39000000","0.01241300"],["15500.05000000","0.03359600"],["15497.31000000","0.13438400"]],"a":[["15511.77000000","7.41125500"],["15512.32000000","0.00000000"],["15513.86000000","0.00000000"],["15515.30000000","0.11427900"],["15515.75000000","0.16120200"],["15515.76000000","0.00000000"],["15515.82000000","0.00000000"],["15516.24000000","0.05000000"],["15517.18000000","0.00000000"],["15517.71000000","0.00000000"],["15518.18000000","0.01000000"]]}}
2020-11-09T11:26:03.32355 btcusdt {"stream":"btcusdt@depth@100ms","data":{"e":"depthUpdate","E":1604921163317,"s":"BTCUSDT","U":6511133993,"u":6511134003,"b":[["15498.38000000","0.00000000"],["15441.47000000","0.00000000"]],"a":[["15511.77000000","2.25253100"],["15512.31000000","0.20000000"],["15512.55000000","0.00200000"],["15516.70000000","0.20000000"],["15520.75000000","0.00000000"],["15524.11000000","0.20000000"],["15544.82000000","0.01200000"],["15558.96000000","0.01542500"]]}}
2020-11-09T11:26:03.42628 btcusdt {"stream":"btcusdt@depth@100ms","data":{"e":"depthUpdate","E":1604921163417,"s":"BTCUSDT","U":6511134004,"u":6511134010,"b":[["15507.83000000","0.11427900"],["15506.84000000","0.00000000"],["15434.78000000","0.00000000"],["15405.31000000","0.00000000"]],"a":[["15516.56000000","0.00000000"],["15524.11000000","0.00000000"],["15563.00000000","0.00000000"]]}}
2020-11-09T11:26:03.53177 btcusdt {"stream":"btcusdt@depth@100ms","data":{"e":"depthUpdate","E":1604921163517,"s":"BTCUSDT","U":6511134011,"u":6511134015,"b":[["15511.76000000","0.49817200"],["15504.84000000","0.00000000"],["15503.61000000","1.25000000"]],"a":[["15511.77000000","2.19236900"],["15524.11000000","0.20000000"]]}}
2020-11-09T11:26:03.62608 btcusdt {"stream":"btcusdt@depth@100ms","data":{"e":"depthUpdate","E":1604921163618,"s":"BTCUSDT","U":6511134016,"u":6511134024,"b":[["15506.43000000","0.01241300"],["15502.34000000","0.00000000"],["15369.15000000","0.00000000"]],"a":[["15511.77000000","2.22389000"],["15516.59000000","0.32100000"],["15524.48000000","0.36118900"],["15565.50000000","2.00000000"]]}}
2020-11-09T11:26:03.72661 btcusdt {"stream":"btcusdt@depth@100ms","data":{"e":"depthUpdate","E":1604921163718,"s":"BTCUSDT","U":6511134025,"u":6511134027,"b":[["15511.76000000","0.47844700"],["15332.99000000","0.00000000"]],"a":[["15511.77000000","2.22309400"]]}}
2020-11-09T11:26:03.82799 btcusdt {"stream":"btcusdt@depth@100ms","data":{"e":"depthUpdate","E":1604921163818,"s":"BTCUSDT","U":6511134028,"u":6511134040,"b":[["15501.11000000","0.02500000"],["15499.30000000","0.13368500"],["15499.07000000","0.00000000"],["15496.75000000","0.00000000"],["15496.73000000","0.00000000"]],"a":[["15511.77000000","2.24060500"],["15516.69000000","0.00000000"],["15525.91000000","0.02500000"],["25000.00000000","20.89296300"]]}}
2020-11-09T11:26:03.92690 btcusdt {"stream":"btcusdt@depth@100ms","data":{"e":"depthUpdate","E":1604921163918,"s":"BTCUSDT","U":6511134041,"u":6511134053,"b":[["15511.58000000","0.00000000"],["15511.41000000","0.00000000"],["15510.87000000","0.01532500"],["15499.14000000","0.30079100"],["15434.20000000","0.00647900"],["15296.83000000","0.00000000"],["14819.00000000","0.00000000"],["14745.00000000","0.06107800"],["14705.00000000","0.63919400"],["14664.00000000","0.00000000"],["14347.00000000","0.51553100"]],"a":[["15514.52000000","0.01379600"],["15515.66000000","0.00000000"]]}}
2020-11-09T11:26:04.02452 btcusdt {"stream":"btcusdt@depth@100ms","data":{"e":"depthUpdate","E":1604921164018,"s":"BTCUSDT","U":6511134054,"u":6511134064,"b":[["15510.85000000","0.00735600"],["15506.54000000","0.03223600"],["15503.93000000","0.50964100"],["15455.80000000","0.24000000"],["15260.67000000","0.00000000"]],"a":[["15511.77000000","2.25864300"],["15514.99000000","0.14267300"],["15515.58000000","0.00000000"],["15515.74000000","0.20000000"],["15515.75000000","0.00000000"],["15524.11000000","0.00000000"]]}}
2020-11-09T11:26:04.12434 btcusdt {"stream":"btcusdt@depth@100ms","data":{"e":"depthUpdate","E":1604921164118,"s":"BTCUSDT","U":6511134065,"u":6511134070,"b":[["15506.55000000","0.01241900"],["15506.43000000","0.00000000"],["15503.65000000","0.00000000"],["15501.93000000","0.50433200"],["15501.20000000","0.00000000"],["15339.00000000","0.12124900"]],"a":[]}}
2020-11-09T11:26:04.22466 btcusdt {"stream":"btcusdt@depth@100ms","data":{"e":"depthUpdate","E":1604921164218,"s":"BTCUSDT","U":6511134071,"u":6511134080,"b":[["15501.57000000","1.00866300"],["15500.84000000","0.00000000"],["15393.00000000","5.19619300"]],"a":[["15515.73000000","0.12894600"],["15515.82000000","0.12894100"],["15515.90000000","0.00000000"],["15516.37000000","0.01000000"],["15518.11000000","0.00000000"],["15518.58000000","0.01500000"],["15622.42000000","2.00000000"]]}}
2020-11-09T11:26:04.38521 btcusdt {"stream":"btcusdt@depth@100ms","data":{"e":"depthUpdate","E":1604921164318,"s":"BTCUSDT","U":6511134081,"u":6511134088,"b":[["15507.36000000","0.97000000"],["15505.39000000","0.00000000"]],"a":[["15511.77000000","2.19846400"],["15515.73000000","0.00000000"],["15516.70000000","0.00000000"],["15518.08000000","1.25000000"],["15519.75000000","0.00000000"],["15586.27000000","2.00000000"]]}}
2020-11-09T11:26:04.42454 btcusdt {"stream":"btcusdt@depth@100ms","data":{"e":"depthUpdate","E":1604921164418,"s":"BTCUSDT","U":6511134089,"u":6511134094,"b":[["15455.80000000","0.00000000"]],"a":[["15511.77000000","0.19846400"],["15518.08000000","0.00000000"],["15519.75000000","1.25000000"],["15520.76000000","0.19214800"],["15609.00000000","0.00000000"]]}}
2020-11-09T11:26:04.52575 btcusdt {"stream":"btcusdt@depth@100ms","data":{"e":"depthUpdate","E":1604921164518,"s":"BTCUSDT","U":6511134095,"u":6511134099,"b":[["15511.76000000","0.44523800"]],"a":[["15512.36000000","2.00000000"],["15515.30000000","0.00000000"],["15515.79000000","0.11427900"],["15550.12000000","2.00000000"]]}}
2020-11-09T11:26:04.62455 btcusdt {"stream":"btcusdt@depth@100ms","data":{"e":"depthUpdate","E":1604921164618,"s":"BTCUSDT","U":6511134100,"u":6511134110,"b":[["15510.99000000","0.01657200"],["15510.87000000","0.00000000"],["15508.58000000","0.50000000"],["15260.90000000","2.00000000"]],"a":[["15511.77000000","0.19708900"],["15514.52000000","0.00000000"],["15514.98000000","0.20000000"],["15515.12000000","0.50000000"],["15515.13000000","0.01434500"],["15515.74000000","0.00000000"],["15519.38000000","0.35391300"]]}}
2020-11-09T11:26:04.72560 btcusdt {"stream":"btcusdt@depth@100ms","data":{"e":"depthUpdate","E":1604921164718,"s":"BTCUSDT","U":6511134111,"u":6511134111,"b":[["15511.76000000","0.44723800"]],"a":[]}}
2020-11-09T11:26:04.82454 btcusdt {"stream":"btcusdt@depth@100ms","data":{"e":"depthUpdate","E":1604921164818,"s":"BTCUSDT","U":6511134112,"u":6511134112,"b":[["15297.05000000","2.00000000"]],"a":[]}}
2020-11-09T11:26:04.93272 btcusdt {"stream":"btcusdt@depth@100ms","data":{"e":"depthUpdate","E":1604921164918,"s":"BTCUSDT","U":6511134113,"u":6511134115,"b":[["15414.00000000","0.48510300"],["15333.20000000","2.00000000"]],"a":[["15595.96000000","0.00000000"]]}}
2020-11-09T11:26:05.02449 btcusdt {"stream":"btcusdt@depth@100ms","data":{"e":"depthUpdate","E":1604921165018,"s":"BTCUSDT","U":6511134116,"u":6511134119,"b":[["15508.05000000","0.00000000"],["15506.25000000","1.05000200"],["15505.38000000","0.00000000"],["15503.62000000","0.20000000"]],"a":[]}}
2020-11-09T11:26:05.12888 btcusdt {"stream":"btcusdt@depth@100ms","data":{"e":"depthUpdate","E":1604921165118,"s":"BTCUSDT","U":6511134120,"u":6511134125,"b":[["15369.35000000","2.00000000"]],"a":[["15511.77000000","0.12939600"],["15512.31000000","0.26671000"],["15564.00000000","0.10827300"]]}}
2020-11-09T11:26:05.22609 btcusdt {"stream":"btcusdt@depth@100ms","data":{"e":"depthUpdate","E":1604921165218,"s":"BTCUSDT","U":6511134126,"u":6511134128,"b":[["15405.50000000","2.00000000"]],"a":[["15511.77000000","0.12657500"],["15514.26000000","0.00000000"]]}}
2020-11-09T11:26:05.32455 btcusdt {"stream":"btcusdt@depth@100ms","data":{"e":"depthUpdate","E":1604921165318,"s":"BTCUSDT","U":6511134129,"u":6511134130,"b":[["15382.72000000","0.38354700"],["15380.01000000","0.00000000"]],"a":[]}}
2020-11-09T11:26:05.42562 btcusdt {"stream":"btcusdt@depth@100ms","data":{"e":"depthUpdate","E":1604921165419,"s":"BTCUSDT","U":6511134131,"u":6511134135,"b":[["15455.00000000","0.33297000"],["15454.53000000","0.24000000"],["15441.66000000","2.00000000"]],"a":[["15515.05000000","0.01401000"],["15515.13000000","0.00000000"]]}}
2020-11-09T11:26:05.52565 btcusdt {"stream":"btcusdt@depth@100ms","data":{"e":"depthUpdate","E":1604921165519,"s":"BTCUSDT","U":6511134136,"u":6511134137,"b":[["15511.76000000","0.44004800"],["15477.81000000","2.00000000"]],"a":[]}}
2020-11-09T11:26:05.72806 btcusdt {"stream":"btcusdt@depth@100ms","data":{"e":"depthUpdate","E":1604921165719,"s":"BTCUSDT","U":6511134138,"u":6511134141,"b":[],"a":[["15511.77000000","0.25357500"],["15516.59000000","0.00000000"],["15518.28000000","0.20000000"],["15522.31000000","0.00000000"]]}}
2020-11-09T11:26:05.82733 btcusdt {"stream":"btcusdt@depth@100ms","data":{"e":"depthUpdate","E":1604921165819,"s":"BTCUSDT","U":6511134142,"u":6511134145,"b":[["15503.93000000","0.00000000"]],"a":[["15511.77000000","0.23553700"],["15512.31000000","0.27717100"],["16500.00000000","114.31173400"]]}}
2020-11-09T11:26:05.92800 btcusdt {"stream":"btcusdt@depth@100ms","data":{"e":"depthUpdate","E":1604921165919,"s":"BTCUSDT","U":6511134146,"u":6511134154,"b":[["15511.76000000","0.43593900"],["15507.38000000","0.06000000"],["15507.36000000","0.00000000"]],"a":[["15511.77000000","6.54909700"]]}}
2020-11-09T11:26:06.02647 btcusdt {"stream":"btcusdt@depth@100ms","data":{"e":"depthUpdate","E":1604921166019,"s":"BTCUSDT","U":6511134155,"u":6511134164,"b":[["15507.83000000","0.00000000"],["15507.30000000","0.11427900"],["15504.03000000","0.00000000"]],"a":[["15511.77000000","8.73689800"],["15515.28000000","0.11427900"],["15515.79000000","0.00000000"],["15516.56000000","0.20000000"],["15518.08000000","1.25000000"],["15519.75000000","0.00000000"]]}}
2020-11-09T11:26:06.12685 btcusdt {"stream":"btcusdt@depth@100ms","data":{"e":"depthUpdate","E":1604921166119,"s":"BTCUSDT","U":6511134165,"u":6511134174,"b":[["15507.92000000","0.00000000"],["15507.38000000","0.00000000"],["15507.13000000","0.08000000"],["15506.59000000","0.04000000"],["15506.42000000","0.00000000"]],"a":[["15511.77000000","12.72153000"],["15516.07000000","0.00000000"],["15519.29000000","0.00000000"],["15526.59000000","1.50000000"]]}}
2020-11-09T11:26:06.22592 btcusdt {"stream":"btcusdt@depth@100ms","data":{"e":"depthUpdate","E":1604921166219,"s":"BTCUSDT","U":6511134175,"u":6511134201,"b":[["15511.76000000","0.00200000"],["15511.57000000","0.00200000"],["15511.05000000","0.00000000"],["15510.20000000","0.00690000"],["15506.60000000","0.01243400"],["15506.55000000","0.00000000"],["15503.61000000","0.00000000"],["15502.88000000","0.00000000"],["15502.76000000","1.25000000"]],"a":[["15511.77000000","12.91752800"],["15512.92000000","0.00000000"],["15513.51000000","0.00000000"],["15515.23000000","0.29859100"],["15515.81000000","0.20000000"],["15515.84000000","0.29700000"],["15515.88000000","0.00000000"],["15516.59000000","0.32100000"],["15516.84000000","0.50000000"],["15522.01000000","0.00000000"],["15701.99000000","1.27371900"]]}}
2020-11-09T11:26:06.32746 btcusdt {"stream":"btcusdt@depth@100ms","data":{"e":"depthUpdate","E":1604921166319,"s":"BTCUSDT","U":6511134202,"u":6511134303,"b":[["15511.76000000","0.00000000"],["15511.65000000","0.00000000"],["15511.57000000","0.00000000"],["15510.99000000","0.00000000"],["15510.85000000","0.00000000"],["15510.20000000","0.01380000"],["15507.30000000","0.00000000"],["15506.25000000","0.05000000"],["15504.96000000","0.00000000"],["15504.71000000","0.16000000"],["15503.64000000","0.00000000"],["15502.03000000","0.12894400"],["15501.93000000","0.00000000"],["15501.57000000","0.00000000"],["15497.59000000","1.00871200"],["15473.57000000","0.00000000"],["15454.53000000","0.00000000"],["15200.00000000","28.53109000"]],"a":[["15510.21000000","5.42483400"],["15510.29000000","0.00690000"],["15510.35000000","0.00000000"],["15510.36000000","0.00000000"],["15510.37000000","0.06538100"],["15510.86000000","0.00000000"],["15511.00000000","0.00000000"],["15511.07000000","0.00000000"],["15511.58000000","0.00000000"],["15511.66000000","0.00000000"],["15511.74000000","4.88199500"],["15511.75000000","0.00000000"],["15511.76000000","5.31627500"],["15511.77000000","6.49439600"],["15512.31000000","0.20000000"],["15512.35000000","0.00000000"],["15512.91000000","0.08000000"],["15513.28000000","0.13500000"],["15513.43000000","0.25767100"],["15513.52000000","0.00000000"],["15514.96000000","0.32100000"],["15514.97000000","1.19800000"],["15515.02000000","0.03223600"],["15515.12000000","0.00000000"],["15515.35000000","0.15700000"],["15515.44000000","0.29200000"],["15515.51000000","0.00000000"],["15515.89000000","1.74800000"],["15516.41000000","0.00000000"],["15516.54000000","0.12894400"],["15516.57000000","0.00000000"],["15516.59000000","0.00000000"],["15516.77000000","0.00000000"],["15516.91000000","0.00000000"],["15517.13000000","0.00000000"],["15519.33000000","0.00000000"],["15524.56000000","0.00000000"],["15526.09000000","0.00000000"],["15551.14000000","0.04891500"]]}}
2020-11-09T11:26:06.42690 btcusdt {"stream":"btcusdt@depth@100ms","data":{"e":"depthUpdate","E":1604921166419,"s":"BTCUSDT","U":6511134304,"u":6511134360,"b":[["15508.58000000","0.00000000"],["15507.52000000","0.00000000"],["15507.13000000","0.00000000"],["15506.59000000","0.00000000"],["15506.54000000","0.00000000"],["15506.25000000","0.00000000"],["15506.13000000","0.04000000"],["15505.12000000","0.11427900"],["15505.01000000","0.13000000"],["15504.62000000","0.08000000"],["15504.22000000","0.02106400"],["15504.00000000","0.03223800"],["15501.69000000","0.00000000"],["15501.37000000","0.00000000"],["15500.72000000","0.00000000"],["15499.65000000","0.00000000"],["15499.64000000","0.00000000"],["15495.26000000","0.00000000"],["15434.20000000","0.00000000"]],"a":[["15510.21000000","7.81263500"],["15511.73000000","0.01000000"],["15511.74000000","0.58733400"],["15511.77000000","2.22900000"],["15513.28000000","0.00000000"],["15513.48000000","0.11427900"],["15514.98000000","0.00000000"],["15515.03000000","0.30600000"],["15515.17000000","0.06000000"],["15515.28000000","0.00000000"],["15515.79000000","0.20000000"],["15516.24000000","0.00000000"],["15516.37000000","0.00000000"],["15516.52000000","0.14400000"],["15516.62000000","0.01000000"],["15517.02000000","0.01500000"],["15518.08000000","0.00000000"],["15518.18000000","0.00000000"],["15518.58000000","0.00000000"],["15519.00000000","0.06714100"],["15519.31000000","1.00871200"],["15519.90000000","1.25000000"],["15521.81000000","0.30000000"],["15523.11000000","0.00000000"],["15523.70000000","1.50000000"],["15526.59000000","0.00000000"]]}}
2020-11-09T11:26:06.52613 btcusdt {"stream":"btcusdt@depth@100ms","data":{"e":"depthUpdate","E":1604921166519,"s":"BTCUSDT","U":6511134361,"u":6511134386,"b":[["15502.76000000","0.00000000"],["15500.05000000","0.00000000"],["15497.95000000","0.50435600"],["15497.61000000","0.00000000"],["15492.67000000","1.16950500"],["15450.56000000","0.24000000"]],"a":[["15510.21000000","8.04811400"],["15510.22000000","0.01000000"],["15510.37000000","0.02990200"],["15511.72000000","0.10000000"],["15511.73000000","0.00000000"],["15511.77000000","2.12900000"],["15511.96000000","0.00200000"],["15512.31000000","0.00000000"],["15518.08000000","0.00000000"],["15519.00000000","1.31714100"],["15519.90000000","0.00000000"],["15520.00000000","5.47780900"],["15521.88000000","0.05681900"],["15523.38000000","0.00000000"]]}}
2020-11-09T11:26:06.62876 btcusdt {"stream":"btcusdt@depth@100ms","data":{"e":"depthUpdate","E":1604921166619,"s":"BTCUSDT","U":6511134387,"u":6511134402,"b":[["15504.71000000","0.00000000"],["15503.72000000","0.08000000"],["15503.62000000","0.00000000"],["15497.44000000","1.25000000"],["15496.21000000","0.00000000"],["15450.56000000","0.00000000"]],"a":[["15510.21000000","9.44811400"],["15511.72000000","0.24500000"],["15511.74000000","0.00000000"],["15513.47000000","0.00307500"],["15514.27000000","0.03400000"],["15515.23000000","0.26459100"],["15520.31000000","0.00000000"],["15701.99000000","0.00000000"]]}}
2020-11-09T11:26:06.72828 btcusdt {"stream":"btcusdt@depth@100ms","data":{"e":"depthUpdate","E":1604921166719,"s":"BTCUSDT","U":6511134403,"u":6511134418,"b":[["15507.60000000","0.00000000"],["15505.12000000","0.00000000"],["15491.52000000","0.20000000"]],"a":[["15510.21000000","9.68808900"],["15511.72000000","0.14500000"],["15513.71000000","1.25000000"],["15513.85000000","0.00000000"],["15515.00000000","1.74800000"],["15515.02000000","0.00000000"],["15515.08000000","0.00000000"],["15515.78000000","0.10199100"],["15515.89000000","0.00000000"],["15519.00000000","0.06714100"]]}}
2020-11-09T11:26:06.82714 btcusdt {"stream":"btcusdt@depth@100ms","data":{"e":"depthUpdate","E":1604921166819,"s":"BTCUSDT","U":6511134419,"u":6511134436,"b":[["15509.43000000","0.01618200"],["15506.25000000","0.16000000"],["15505.02000000","0.01243400"],["15503.76000000","0.11427900"],["15499.58000000","0.51824400"],["15497.44000000","0.00000000"],["15496.76000000","1.25000000"]],"a":[["15510.21000000","10.12402900"],["15512.02000000","0.03224100"],["15513.71000000","0.00000000"],["15513.99000000","0.12896500"],["15514.98000000","0.32100000"],["15515.09000000","0.00000000"],["15516.54000000","0.00000000"],["15516.70000000","1.25000000"],["15523.10000000","0.14700000"],["15541.00000000","0.00000000"]]}}
2020-11-09T11:26:06.92832 btcusdt {"stream":"btcusdt@depth@100ms","data":{"e":"depthUpdate","E":1604921166919,"s":"BTCUSDT","U":6511134437,"u":6511134452,"b":[["15503.05000000","0.00000000"],["15501.88000000","0.00000000"],["15498.77000000","0.00000000"],["15498.76000000","1.25000000"],["15496.76000000","0.00000000"],["15493.23000000","0.00000000"],["15432.64000000","0.00647900"]],"a":[["15510.21000000","10.30402900"],["15511.77000000","2.12900000"],["15515.09000000","1.25000000"],["15516.70000000","0.00000000"],["15517.99000000","0.02422500"],["15518.95000000","0.00000000"],["15519.33000000","0.10000000"],["15522.45000000","0.00000000"]]}}
2020-11-09T11:26:07.02783 btcusdt {"stream":"btcusdt@depth@100ms","data":{"e":"depthUpdate","E":1604921167019,"s":"BTCUSDT","U":6511134453,"u":6511134471,"b":[["15502.03000000","0.00000000"],["15499.58000000","0.00000000"],["15499.32000000","0.12896500"],["15498.76000000","0.00000000"],["15497.95000000","1.75435600"]],"a":[["15510.21000000","16.49939400"],["15510.28000000","0.00000000"],["15514.97000000","1.24800000"],["15515.09000000","0.00000000"],["15515.17000000","0.01000000"],["15515.78000000","0.00000000"],["15517.80000000","0.02968800"],["15521.03000000","1.00000000"],["15522.94000000","0.00000000"],["15523.01000000","0.00000000"],["15525.58000000","0.40548900"],["15526.52000000","0.45568200"]]}}
2020-11-09T11:26:07.12734 btcusdt {"stream":"btcusdt@depth@100ms","data":{"e":"depthUpdate","E":1604921167119,"s":"BTCUSDT","U":6511134472,"u":6511134566,"b":[["15510.20000000","0.00000000"],["15509.43000000","0.00000000"],["15508.76000000","0.00690000"],["15507.96000000","0.01917000"],["15507.33000000","0.00128900"],["15507.17000000","0.00000000"],["15505.01000000","0.05000000"],["15504.21000000","0.00000000"],["15503.51000000","0.00000000"],["15502.06000000","0.12896500"],["15500.99000000","0.50000000"],["15500.62000000","0.00000000"],["15499.32000000","0.00000000"],["15498.68000000","0.01900000"],["15497.95000000","0.50435600"],["15497.76000000","1.25000000"],["15497.26000000","1.50000000"]],"a":[["15508.77000000","0.99819300"],["15509.14000000","0.03148500"],["15509.15000000","0.06297000"],["15509.28000000","0.00000000"],["15509.38000000","0.00000000"],["15509.42000000","0.00000000"],["15509.43000000","0.01892900"],["15509.64000000","0.00000000"],["15509.71000000","0.00000000"],["15509.86000000","0.00000000"],["15509.92000000","0.00000000"],["15509.93000000","0.00000000"],["15510.08000000","5.63372800"],["15510.10000000","0.00000000"],["15510.11000000","0.00000000"],["15510.12000000","0.00000000"],["15510.20000000","0.78382500"],["15510.21000000","15.00205800"],["15511.72000000","0.00000000"],["15511.82000000","0.11427900"],["15512.00000000","0.29700000"],["15512.16000000","0.01686800"],["15513.06000000","0.25000000"],["15513.48000000","0.00000000"],["15514.11000000","0.15700000"],["15514.19000000","0.29200000"],["15514.26000000","1.19800000"],["15514.90000000","0.15150000"],["15514.95000000","0.01382400"],["15514.97000000","0.05000000"],["15514.98000000","0.00000000"],["15515.05000000","0.00000000"],["15515.35000000","0.00000000"],["15515.44000000","0.00000000"],["15516.71000000","2.10933700"],["15517.81000000","0.00000000"],["15517.99000000","0.05329600"],["15518.28000000","0.35300000"],["15525.57000000","0.48374700"],["15526.52000000","0.00000000"],["15548.98000000","0.25000000"]]}}
2020-11-09T11:26:07.22659 btcusdt {"stream":"btcusdt@depth@100ms","data":{"e":"depthUpdate","E":1604921167220,"s":"BTCUSDT","U":6511134567,"u":6511134613,"b":[["15506.60000000","0.00000000"],["15503.76000000","0.00000000"],["15503.56000000","0.00000000"],["15503.22000000","0.11427900"],["15502.93000000","0.00000000"],["15501.04000000","0.30000000"],["15500.50000000","0.00690000"],["15497.76000000","0.00000000"],["15497.57000000","0.00000000"],["15496.78000000","1.25000000"],["15414.00000000","0.00000000"]],"a":[["15508.77000000","3.16043000"],["15510.05000000","0.00000000"],["15510.06000000","0.00000000"],["15510.07000000","0.79253600"],["15510.08000000","0.00000000"],["15510.19000000","4.82085800"],["15510.20000000","0.00128900"],["15510.21000000","8.43594000"],["15510.22000000","0.00000000"],["15511.71000000","0.08000000"],["15512.36000000","0.00000000"],["15513.23000000","0.03400000"],["15513.53000000","0.32200000"],["15513.98000000","0.01000000"],["15514.27000000","0.00000000"],["15514.99000000","0.13644700"],["15515.09000000","1.25000000"],["15515.17000000","0.00000000"],["15515.18000000","0.51000000"],["15516.62000000","0.00000000"],["15516.71000000","0.85933700"]]}}
2020-11-09T11:26:07.37500 btcusdt {"stream":"btcusdt@depth@100ms","data":{"e":"depthUpdate","E":1604921167320,"s":"BTCUSDT","U":6511134614,"u":6511134624,"b":[["15506.04000000","0.00870700"],["15503.23000000","0.01243400"],["15471.43000000","0.25000000"]],"a":[["15508.77000000","3.45844100"],["15510.07000000","0.01000000"],["15510.21000000","8.13594000"],["15510.67000000","0.00930400"],["15511.76000000","5.30627500"]]}}
2020-11-09T11:26:07.42614 btcusdt {"stream":"btcusdt@depth@100ms","data":{"e":"depthUpdate","E":1604921167420,"s":"BTCUSDT","U":6511134625,"u":6511134636,"b":[["15507.96000000","0.00000000"],["15504.90000000","0.00000000"],["15502.31000000","0.10000000"],["15432.64000000","0.00000000"],["15390.00000000","0.60008800"],["14643.20000000","0.00171000"],["14500.00000000","265.08030000"]],"a":[["15508.77000000","3.39091300"],["15512.16000000","0.00000000"],["15521.11000000","1.50000000"],["15523.70000000","0.00000000"]]}}
2020-11-09T11:26:07.52617 btcusdt {"stream":"btcusdt@depth@100ms","data":{"e":"depthUpdate","E":1604921167520,"s":"BTCUSDT","U":6511134637,"u":6511134644,"b":[["15506.04000000","0.00000000"],["15504.77000000","0.00754900"]],"a":[["15508.77000000","3.28538500"],["15513.45000000","0.10000000"],["15520.03000000","0.24000000"],["15520.88000000","0.05681900"],["15521.88000000","0.00000000"]]}}
2020-11-09T11:26:07.62632 btcusdt {"stream":"btcusdt@depth@100ms","data":{"e":"depthUpdate","E":1604921167620,"s":"BTCUSDT","U":6511134645,"u":6511134660,"b":[["15508.76000000","0.00890000"],["15504.01000000","0.08000000"],["15502.69000000","0.00000000"],["15498.25000000","1.00120000"],["15448.35000000","0.24000000"]],"a":[["15508.77000000","8.58451900"],["15509.13000000","0.20000000"],["15509.14000000","0.00000000"],["15510.19000000","0.00000000"],["15510.21000000","7.93594000"],["15511.76000000","0.00627500"],["15519.28000000","0.80000000"],["15521.81000000","0.00000000"],["15523.22000000","0.00000000"]]}}
2020-11-09T11:26:07.72627 btcusdt {"stream":"btcusdt@depth@100ms","data":{"e":"depthUpdate","E":1604921167720,"s":"BTCUSDT","U":6511134661,"u":6511134665,"b":[["15503.65000000","0.25770000"],["14643.20000000","0.02511000"]],"a":[["15508.77000000","8.48451900"],["15510.06000000","0.26000000"]]}}
2020-11-09T11:26:07.82765 btcusdt {"stream":"btcusdt@depth@100ms","data":{"e":"depthUpdate","E":1604921167820,"s":"BTCUSDT","U":6511134666,"u":6511134670,"b":[["15503.23000000","0.00000000"],["15498.38000000","0.06719600"],["15390.00000000","0.70836100"]],"a":[["15508.77000000","8.68451900"],["15510.21000000","7.73594000"]]}}
2020-11-09T11:26:07.92782 btcusdt {"stream":"btcusdt@depth@100ms","data":{"e":"depthUpdate","E":1604921167920,"s":"BTCUSDT","U":6511134671,"u":6511134679,"b":[["15505.02000000","0.00000000"],["15504.77000000","0.00000000"],["15504.20000000","0.00802200"],["15431.21000000","0.00648000"]],"a":[["15509.23000000","0.00874100"],["15510.67000000","0.00000000"],["15513.35000000","1.25000000"],["15515.09000000","0.00000000"],["15537.03000000","1.04133000"]]}}
2020-11-09T11:26:08.02966 btcusdt {"stream":"btcusdt@depth@100ms","data":{"e":"depthUpdate","E":1604921168020,"s":"BTCUSDT","U":6511134680,"u":6511134698,"b":[["15508.76000000","0.01025600"],["15504.34000000","0.01582800"],["15504.12000000","0.00000000"],["15502.06000000","0.00000000"],["15499.32000000","0.12896500"],["15499.11000000","0.40771500"],["15497.26000000","0.00000000"],["15496.89000000","0.30000000"]],"a":[["15509.54000000","0.01522400"],["15513.44000000","0.05000000"],["15514.97000000","0.00000000"],["15517.99000000","0.45878500"],["15518.74000000","0.00000000"],["15524.47000000","0.02806500"],["15524.53000000","0.45568200"],["15525.57000000","0.00000000"],["15525.58000000","0.00000000"]]}}
2020-11-09T11:26:08.12767 btcusdt {"stream":"btcusdt@depth@100ms","data":{"e":"depthUpdate","E":1604921168120,"s":"BTCUSDT","U":6511134699,"u":6511134714,"b":[["15508.76000000","0.00000200"],["15506.64000000","0.06585700"],["15504.20000000","0.00000000"],["15501.57000000","0.19337300"],["15499.14000000","0.00000000"],["15498.69000000","1.00912700"],["15497.31000000","0.00000000"],["15497.27000000","0.30205100"],["15495.16000000","1.61189800"],["15493.23000000","0.19477400"],["14550.00000000","14.50344700"]],"a":[["15509.12000000","0.14500000"],["15510.06000000","0.10000000"],["15511.72000000","0.94237200"],["15511.77000000","2.12700000"],["15516.71000000","0.00000000"]]}}
2020-11-09T11:26:08.22791 btcusdt {"stream":"btcusdt@depth@100ms","data":{"e":"depthUpdate","E":1604921168220,"s":"BTCUSDT","U":6511134715,"u":6511134731,"b":[["15505.01000000","0.00000000"],["15504.34000000","0.00000000"],["15501.58000000","0.05000000"],["15500.81000000","0.06735000"],["15492.67000000","0.00000000"]],"a":[["15508.77000000","8.04675100"],["15509.15000000","0.00000000"],["15512.90000000","0.16121400"],["15513.22000000","0.01000000"],["15513.98000000","0.00000000"],["15514.10000000","0.01000000"],["15514.50000000","0.01500000"],["15515.18000000","0.50000000"],["15517.02000000","0.00000000"],["15527.11000000","0.00000000"]]}}
2020-11-09T11:26:08.33036 btcusdt {"stream":"btcusdt@depth@100ms","data":{"e":"depthUpdate","E":1604921168320,"s":"BTCUSDT","U":6511134732,"u":6511134794,"b":[["15508.76000000","0.00000000"],["15507.33000000","0.00000000"],["15507.32000000","0.00000000"],["15507.15000000","4.69870300"],["15506.64000000","0.00000000"],["15503.45000000","0.01993700"],["15503.22000000","0.00000000"],["15502.61000000","0.11427900"],["15500.99000000","0.00000000"],["15495.16000000","0.11189800"],["15490.03000000","1.12144900"]],"a":[["15507.16000000","1.18792100"],["15507.33000000","0.03619400"],["15507.34000000","0.00000000"],["15507.74000000","0.02474700"],["15507.97000000","0.00690000"],["15507.99000000","0.00000000"],["15508.60000000","0.04027200"],["15508.61000000","0.07583200"],["15508.62000000","0.03650200"],["15508.75000000","0.03247100"],["15508.76000000","0.00000000"],["15508.77000000","8.00795800"],["15508.96000000","0.00200000"],["15509.13000000","0.00000000"],["15509.43000000","0.00000000"],["15510.21000000","7.30000000"],["15511.09000000","0.11427900"],["15511.71000000","0.00000000"],["15511.72000000","0.00000000"],["15511.82000000","0.00000000"],["15512.49000000","0.03400000"],["15513.23000000","0.00000000"],["15513.35000000","2.44800000"],["15513.47000000","0.00000000"],["15513.55000000","1.74800000"],["15514.26000000","0.00000000"],["15515.00000000","0.00000000"],["15516.47000000","0.13423400"]]}}
2020-11-09T11:26:08.42832 btcusdt {"stream":"btcusdt@depth@100ms","data":{"e":"depthUpdate","E":1604921168420,"s":"BTCUSDT","U":6511134795,"u":6511134832,"b":[["15507.15000000","10.85380500"],["15501.58000000","0.00000000"],["15500.99000000","0.05000000"],["15498.25000000","0.00120000"],["15498.06000000","0.50000000"],["15496.78000000","0.00000000"],["15495.61000000","1.00000000"],["15431.21000000","0.00000000"]],"a":[["15507.16000000","0.94438000"],["15507.32000000","0.09500000"],["15507.33000000","0.00000000"],["15507.34000000","0.00000000"],["15507.74000000","0.00000000"],["15508.60000000","0.00000000"],["15508.61000000","0.00000000"],["15508.62000000","0.00000000"],["15508.75000000","0.00000000"],["15508.77000000","2.22392300"],["15509.12000000","0.00000000"],["15510.06000000","0.00000000"],["15512.01000000","0.05000000"],["15512.36000000","0.00090500"],["15512.90000000","0.00000000"],["15513.44000000","0.00000000"],["15515.82000000","0.00000000"],["15516.56000000","0.00000000"],["15520.03000000","0.00000000"]]}}
2020-11-09T11:26:08.52692 btcusdt {"stream":"btcusdt@depth@100ms","data":{"e":"depthUpdate","E":1604921168520,"s":"BTCUSDT","U":6511134833,"u":6511134856,"b":[["15502.08000000","0.12896500"],["15500.98000000","0.00000000"],["15499.32000000","0.00000000"],["15498.98000000","0.00000000"],["15498.76000000","0.00000000"],["15448.35000000","0.00000000"]],"a":[["15507.16000000","0.94118000"],["15507.32000000","0.00000000"],["15508.24000000","0.01908700"],["15508.59000000","0.20000000"],["15509.23000000","0.00000000"],["15509.54000000","0.00000000"],["15511.76000000","0.30627500"],["15512.00000000","0.00000000"],["15513.06000000","0.00000000"],["15513.35000000","1.19800000"],["15513.71000000","1.25000000"],["15513.98000000","0.20000000"],["15514.51000000","0.75000000"],["15515.81000000","0.00000000"],["15520.58000000","0.24000000"]]}}
2020-11-09T11:26:08.62685 btcusdt {"stream":"btcusdt@depth@100ms","data":{"e":"depthUpdate","E":1604921168620,"s":"BTCUSDT","U":6511134857,"u":6511134866,"b":[["15498.12000000","1.25000000"],["15439.98000000","0.24000000"]],"a":[["15507.16000000","0.93798000"],["15508.76000000","1.11196100"],["15508.96000000","0.00400000"],["15511.09000000","0.00000000"],["15511.75000000","0.08000000"],["15513.57000000","0.01000000"],["15514.10000000","0.00000000"],["15515.13000000","0.09625500"]]}}
2020-11-09T11:26:08.72743 btcusdt {"stream":"btcusdt@depth@100ms","data":{"e":"depthUpdate","E":1604921168720,"s":"BTCUSDT","U":6511134867,"u":6511134875,"b":[["15503.94000000","0.11427900"],["15502.61000000","0.00000000"],["15501.57000000","0.00000000"],["15494.60000000","1.50000000"]],"a":[["15507.16000000","0.93476200"],["15508.59000000","0.00000000"],["15510.06000000","0.20000000"],["15511.77000000","2.00000000"],["15512.50000000","0.11427900"]]}}
2020-11-09T11:26:08.82762 btcusdt {"stream":"btcusdt@depth@100ms","data":{"e":"depthUpdate","E":1604921168820,"s":"BTCUSDT","U":6511134876,"u":6511134894,"b":[["15507.15000000","10.85073200"],["15498.97000000","0.50440500"],["15498.61000000","1.00880900"],["15497.95000000","0.00000000"],["15497.59000000","0.00000000"],["15494.60000000","0.00000000"],["15494.44000000","0.00000000"]],"a":[["15507.16000000","1.05269800"],["15510.07000000","0.00000000"],["15513.71000000","0.00000000"],["15515.79000000","0.00000000"],["15516.70000000","0.00000000"],["15516.80000000","1.25000000"],["15520.28000000","0.20000000"],["15565.50000000","0.00000000"]]}}
2020-11-09T11:26:08.92695 btcusdt {"stream":"btcusdt@depth@100ms","data":{"e":"depthUpdate","E":1604921168920,"s":"BTCUSDT","U":6511134895,"u":6511134902,"b":[["15507.15000000","10.84999500"],["15494.36000000","0.00000000"],["15429.61000000","0.00648100"]],"a":[["15507.16000000","0.76053800"],["15517.99000000","0.48261300"],["15524.23000000","0.02551800"],["15606.00000000","0.11961300"]]}}
2020-11-09T11:26:09.02784 btcusdt {"stream":"btcusdt@depth@100ms","data":{"e":"depthUpdate","E":1604921169021,"s":"BTCUSDT","U":6511134903,"u":6511134917,"b":[["15504.01000000","0.00000000"],["15503.07000000","0.00808100"],["15500.99000000","0.00000000"],["15500.95000000","0.05000000"],["15499.31000000","0.20000000"],["15494.50000000","1.50000000"]],"a":[["15507.16000000","0.69436100"],["15508.15000000","0.00865900"],["15512.01000000","0.00000000"],["15513.34000000","0.05000000"],["15517.98000000","0.45568200"],["15524.47000000","0.00000000"],["15524.53000000","0.00000000"],["15700.99000000","1.40080100"]]}}
2020-11-09T11:26:09.12888 btcusdt {"stream":"btcusdt@depth@100ms","data":{"e":"depthUpdate","E":1604921169121,"s":"BTCUSDT","U":6511134918,"u":6511134926,"b":[["15500.75000000","0.50000000"],["15498.06000000","0.00000000"],["15459.82000000","0.00000000"],["15439.98000000","0.00000000"]],"a":[["15517.98000000","0.48374700"],["15520.58000000","0.00000000"],["15558.96000000","0.00000000"],["15563.50000000","2.00000000"],["15564.00000000","0.48510300"]]}}
2020-11-09T11:26:09.22820 btcusdt {"stream":"btcusdt@depth@100ms","data":{"e":"depthUpdate","E":1604921169221,"s":"BTCUSDT","U":6511134927,"u":6511134940,"b":[["15503.95000000","0.08000000"],["15499.81000000","0.00000000"],["15498.12000000","0.00000000"]],"a":[["15507.99000000","0.00779600"],["15508.15000000","0.00000000"],["15508.21000000","0.01609500"],["15508.24000000","0.00000000"],["15508.77000000","2.20588500"],["15513.22000000","0.00000000"],["15513.33000000","0.01000000"],["15513.52000000","0.12897500"],["15513.97000000","0.01500000"],["15514.50000000","0.00000000"]]}}
2020-11-09T11:26:09.33146 btcusdt {"stream":"btcusdt@depth@100ms","data":{"e":"depthUpdate","E":1604921169321,"s":"BTCUSDT","U":6511134941,"u":6511134954,"b":[["15506.64000000","0.07454800"],["15503.45000000","0.00000000"],["15503.07000000","0.00000000"],["15503.03000000","0.01526600"],["15502.61000000","0.00627100"],["15498.98000000","1.25000000"],["15390.00000000","0.60008800"],["15200.00000000","28.52934300"]],"a":[["15507.16000000","0.12800000"],["15507.64000000","0.00902500"],["15507.93000000","0.01382100"],["15507.99000000","0.00000000"],["15508.21000000","0.00000000"],["15509.61000000","0.54455400"]]}}
2020-11-09T11:26:09.42862 btcusdt {"stream":"btcusdt@depth@100ms","data":{"e":"depthUpdate","E":1604921169421,"s":"BTCUSDT","U":6511134955,"u":6511134973,"b":[["15505.01000000","0.15500000"],["15502.08000000","0.00000000"],["15500.30000000","0.22500000"],["15499.34000000","0.12896500"],["15499.11000000","0.00000000"],["15498.98000000","0.00000000"],["15497.85000000","1.25000000"]],"a":[["15509.60000000","0.27227800"],["15510.05000000","0.10000000"],["15510.17000000","3.58431400"],["15510.18000000","0.00000000"],["15510.19000000","0.00000000"],["15511.76000000","0.20627500"]]}}
2020-11-09T11:26:09.53137 btcusdt {"stream":"btcusdt@depth@100ms","data":{"e":"depthUpdate","E":1604921169521,"s":"BTCUSDT","U":6511134974,"u":6511134985,"b":[["15507.15000000","10.77981800"],["15500.75000000","0.00000000"],["15499.31000000","0.00000000"],["15498.12000000","0.50000000"],["15469.23000000","0.24000000"],["15393.00000000","5.30446600"]],"a":[["15507.16000000","0.56638000"],["15511.76000000","0.00000000"],["15516.80000000","0.00000000"],["15524.29000000","0.24000000"]]}}
2020-11-09T11:26:09.62855 btcusdt {"stream":"btcusdt@depth@100ms","data":{"e":"depthUpdate","E":1604921169621,"s":"BTCUSDT","U":6511134986,"u":6511134996,"b":[["15504.76000000","0.50000000"],["15494.50000000","0.00000000"],["15469.23000000","0.00000000"]],"a":[["15508.75000000","0.20000000"],["15511.44000000","0.50000000"],["15511.97000000","0.11427900"],["15512.50000000","0.00000000"],["15515.82000000","0.10000000"],["15517.42000000","1.25000000"],["15519.33000000","0.00000000"],["15524.29000000","0.00000000"]]}}
2020-11-09T11:26:09.73596 btcusdt {"stream":"btcusdt@depth@100ms","data":{"e":"depthUpdate","E":1604921169721,"s":"BTCUSDT","U":6511134997,"u":6511135008,"b":[["15507.15000000","5.48181800"],["15505.01000000","0.00000000"],["15503.25000000","0.01769700"],["15503.03000000","0.00000000"],["15501.21000000","0.19469400"],["15465.66000000","0.24000000"]],"a":[["15507.16000000","0.69438000"],["15511.99000000","0.03000000"],["15513.96000000","0.20000000"],["15517.42000000","0.00000000"],["15520.42000000","0.24000000"]]}}
2020-11-09T11:26:09.82937 btcusdt {"stream":"btcusdt@depth@100ms","data":{"e":"depthUpdate","E":1604921169821,"s":"BTCUSDT","U":6511135009,"u":6511135026,"b":[["15507.15000000","10.60322800"],["15502.88000000","0.00650800"],["15502.61000000","0.00000000"],["15501.11000000","0.00000000"]],"a":[["15507.16000000","0.63602400"],["15507.62000000","0.00619800"],["15507.64000000","0.00000000"],["15513.96000000","0.00000000"],["15516.66000000","0.00000000"],["15516.69000000","0.00000000"],["15525.91000000","0.00000000"],["15700.99000000","0.12700100"]]}}
2020-11-09T11:26:09.92996 btcusdt {"stream":"btcusdt@depth@100ms","data":{"e":"depthUpdate","E":1604921169921,"s":"BTCUSDT","U":6511135027,"u":6511135037,"b":[["15507.15000000","10.77093900"]],"a":[["15507.16000000","0.63521600"],["15508.74000000","0.20000000"],["15510.06000000","0.00000000"],["15513.35000000","1.19800000"],["15513.79000000","0.20000000"],["15516.80000000","0.00000000"],["15517.82000000","0.00000000"]]}}
2020-11-09T11:26:10.02797 btcusdt {"stream":"btcusdt@depth@100ms","data":{"e":"depthUpdate","E":1604921170021,"s":"BTCUSDT","U":6511135038,"u":6511135048,"b":[["15501.39000000","0.02500000"],["15501.05000000","0.05000000"],["15500.95000000","0.00000000"],["15490.56000000","0.05000000"]],"a":[["15507.16000000","0.63418200"],["15508.77000000","2.20000000"],["15512.01000000","0.05000000"],["15513.34000000","0.00000000"],["15518.08000000","1.25000000"],["15520.28000000","0.00000000"],["15523.17000000","0.02500000"]]}}
2020-11-09T11:26:10.13039 btcusdt {"stream":"btcusdt@depth@100ms","data":{"e":"depthUpdate","E":1604921170121,"s":"BTCUSDT","U":6511135049,"u":6511135054,"b":[["15507.15000000","5.47093900"],["15506.13000000","0.00000000"],["15504.14000000","0.12000000"],["15494.00000000","1.50000000"]],"a":[["15517.97000000","0.02551800"],["15524.23000000","0.00000000"]]}}
2020-11-09T11:26:10.23130 btcusdt {"stream":"btcusdt@depth@100ms","data":{"e":"depthUpdate","E":1604921170221,"s":"BTCUSDT","U":6511135055,"u":6511135098,"b":[["15507.15000000","0.01090000"],["15506.64000000","0.00000000"],["15504.62000000","0.00000000"],["15504.14000000","0.00000000"],["15504.00000000","0.00000000"],["15503.95000000","0.00000000"],["15503.72000000","0.00000000"],["15502.59000000","0.04000000"],["15502.35000000","0.08000000"],["15501.53000000","0.24000000"],["15500.30000000","0.00000000"],["15494.00000000","0.00000000"]],"a":[["15507.73000000","0.02474700"],["15508.74000000","0.00000000"],["15509.59000000","0.20000000"],["15510.51000000","0.03400000"],["15511.31000000","0.11427900"],["15511.57000000","1.74800000"],["15511.97000000","0.32200000"],["15511.99000000","0.00000000"],["15512.01000000","0.06000000"],["15512.16000000","1.19800000"],["15512.33000000","0.15700000"],["15512.41000000","0.29200000"],["15512.48000000","0.12897500"],["15512.49000000","0.00000000"],["15512.50000000","0.50000000"],["15512.90000000","0.20000000"],["15513.15000000","0.08000000"],["15513.33000000","0.00000000"],["15513.35000000","0.00000000"],["15513.53000000","0.00000000"],["15513.55000000","0.00000000"],["15514.11000000","0.00000000"],["15514.19000000","0.00000000"],["15514.96000000","0.00000000"],["15515.79000000","0.20000000"],["15516.84000000","0.00000000"]]}}
2020-11-09T11:26:10.37392 btcusdt {"stream":"btcusdt@depth@100ms","data":{"e":"depthUpdate","E":1604921170321,"s":"BTCUSDT","U":6511135099,"u":6511135144,"b":[["15507.15000000","0.00000000"],["15506.24000000","0.00000000"],["15504.22000000","0.00000000"],["15503.94000000","0.00000000"],["15503.45000000","0.11427900"],["15501.29000000","0.03224400"],["15501.04000000","0.00000000"],["15500.81000000","0.00000000"],["15500.02000000","0.00000000"],["15498.69000000","0.00000000"],["15497.16000000","0.00000000"],["15494.41000000","1.50000000"],["15490.13000000","0.00000000"]],"a":[["15506.26000000","1.83156600"],["15506.36000000","0.50420000"],["15506.70000000","0.00690000"],["15507.14000000","0.20319500"],["15507.15000000","1.41709100"],["15507.16000000","2.33000000"],["15507.60000000","0.00000000"],["15507.73000000","0.00000000"],["15508.77000000","2.00000000"],["15509.58000000","0.01140600"],["15509.59000000","0.28000000"],["15511.17000000","0.32100000"],["15511.43000000","0.00301800"],["15511.53000000","1.19800000"],["15511.77000000","0.00000000"],["15512.16000000","0.00000000"],["15512.30000000","0.50000000"],["15512.50000000","0.30900000"],["15513.15000000","0.00000000"],["15513.35000000","1.25000000"],["15515.19000000","0.00200000"],["15516.81000000","1.00884200"],["15518.08000000","0.00000000"],["15518.28000000","0.15300000"],["15519.31000000","0.00000000"],["15521.76000000","1.88656200"],["15537.10000000","0.00000000"]]}}
2020-11-09T11:26:10.42886 btcusdt {"stream":"btcusdt@depth@100ms","data":{"e":"depthUpdate","E":1604921170421,"s":"BTCUSDT","U":6511135145,"u":6511135198,"b":[["15506.25000000","0.15600400"],["15505.68000000","0.00000000"],["15505.01000000","0.01000000"],["15502.31000000","0.00000000"],["15501.05000000","0.00000000"],["15499.35000000","0.02106400"],["15499.03000000","0.10100000"],["15498.17000000","0.49357100"],["15498.13000000","0.00000000"],["15497.57000000","0.52200100"],["15497.52000000","0.00000000"],["15495.42000000","0.00000000"],["15488.38000000","0.00000000"],["15465.66000000","0.00000000"],["15429.61000000","0.00000000"]],"a":[["15506.26000000","2.62569500"],["15506.35000000","0.00000000"],["15506.36000000","0.00000000"],["15507.04000000","0.00000000"],["15507.13000000","0.20000000"],["15507.15000000","0.00000000"],["15507.55000000","0.02474700"],["15508.74000000","0.18000000"],["15508.75000000","0.00000000"],["15509.60000000","0.00000000"],["15510.05000000","0.00000000"],["15510.17000000","0.00000000"],["15510.98000000","1.19800000"],["15511.30000000","0.00000000"],["15511.43000000","0.00000000"],["15511.53000000","0.00000000"],["15511.97000000","0.00000000"],["15512.01000000","0.01000000"],["15512.67000000","0.01000000"],["15513.12000000","0.15450000"],["15513.57000000","0.00000000"],["15513.97000000","0.00000000"],["15516.16000000","0.19228200"]]}}
2020-11-09T11:26:10.52866 btcusdt {"stream":"btcusdt@depth@100ms","data":{"e":"depthUpdate","E":1604921170521,"s":"BTCUSDT","U":6511135199,"u":6511135219,"b":[["15502.92000000","0.00000000"],["15500.51000000","0.05000000"],["15499.35000000","0.02106400"],["15497.85000000","0.00000000"],["15497.76000000","1.25000000"],["15497.57000000","0.00000000"],["15493.84000000","0.06727700"],["15465.30000000","0.24000000"],["15460.72000000","0.01552300"]],"a":[["15506.26000000","1.88221200"],["15506.88000000","0.11593300"],["15507.12000000","1.36659700"],["15509.80000000","0.03224700"],["15511.16000000","0.05000000"],["15511.74000000","0.12898600"],["15512.02000000","0.00000000"],["15513.07000000","0.01500000"],["15513.99000000","0.00000000"],["15515.18000000","0.00000000"]]}}
2020-11-09T11:26:10.62874 btcusdt {"stream":"btcusdt@depth@100ms","data":{"e":"depthUpdate","E":1604921170621,"s":"BTCUSDT","U":6511135220,"u":6511135240,"b":[["15506.25000000","0.00690000"],["15503.45000000","0.00000000"],["15500.00000000","14.48015700"],["15499.36000000","0.37846100"],["15499.35000000","0.02106400"],["15498.97000000","0.00000000"],["15498.61000000","0.00000000"],["15491.34000000","0.00000000"],["15465.30000000","0.00000000"]],"a":[["15506.26000000","1.81897400"],["15506.84000000","0.02474700"],["15507.35000000","0.00400000"],["15507.55000000","0.00000000"],["15509.94000000","0.11427900"],["15511.31000000","0.00000000"],["15512.09000000","0.25772100"],["15519.38000000","0.09621900"],["15553.76000000","0.01543000"]]}}
2020-11-09T11:26:10.72865 btcusdt {"stream":"btcusdt@depth@100ms","data":{"e":"depthUpdate","E":1604921170722,"s":"BTCUSDT","U":6511135241,"u":6511135247,"b":[["15502.36000000","0.11427900"],["15497.76000000","0.00000000"],["15495.28000000","0.50443700"],["15493.70000000","1.00887400"]],"a":[["15506.26000000","2.01897400"],["15509.59000000","0.08000000"],["15510.36000000","0.50000000"]]}}
2020-11-09T11:26:10.83480 btcusdt {"stream":"btcusdt@depth@100ms","data":{"e":"depthUpdate","E":1604921170822,"s":"BTCUSDT","U":6511135248,"u":6511135256,"b":[["15498.29000000","1.00000000"],["15496.70000000","0.00000000"],["15496.50000000","1.25000000"],["15495.61000000","0.00000000"],["13900.00000000","33.00555400"]],"a":[["15506.26000000","2.03381200"],["15511.02000000","0.32200000"]]}}
2020-11-09T11:26:10.92862 btcusdt {"stream":"btcusdt@depth@100ms","data":{"e":"depthUpdate","E":1604921170922,"s":"BTCUSDT","U":6511135257,"u":6511135302,"b":[["15506.25000000","0.00000000"],["15506.05000000","0.00000000"],["15505.81000000","0.00690000"],["15505.37000000","1.92734900"],["15504.95000000","0.07341900"],["15504.76000000","0.00000000"],["15501.21000000","0.00000000"],["15500.02000000","5.06877700"],["15428.71000000","0.00648100"]],"a":[["15505.82000000","0.51110000"],["15505.97000000","0.29715900"],["15505.98000000","0.12709100"],["15506.03000000","0.07729500"],["15506.06000000","0.00000000"],["15506.14000000","0.15593200"],["15506.26000000","0.38574900"],["15506.73000000","0.02474700"],["15506.84000000","0.00000000"],["15507.12000000","0.00000000"],["15508.76000000","0.00000000"],["15509.85000000","0.03400000"],["15510.51000000","0.00000000"],["15510.57000000","1.74800000"],["15510.92000000","0.15700000"],["15510.98000000","1.49000000"],["15511.02000000","0.00000000"],["15511.57000000","0.00000000"],["15512.33000000","0.00000000"],["15512.41000000","0.00000000"],["15512.48000000","0.00000000"],["15518.45000000","1.00000000"],["15521.03000000","0.00000000"],["15522.63000000","0.00000000"],["15606.00000000","0.01134000"]]}}
2020-11-09T11:26:11.03102 btcusdt {"stream":"btcusdt@depth@100ms","data":{"e":"depthUpdate","E":1604921171022,"s":"BTCUSDT","U":6511135303,"u":6511135316,"b":[["15500.51000000","0.00000000"],["15500.03000000","0.05000000"],["15500.02000000","5.68955300"],["15500.01000000","0.00000000"],["15495.62000000","0.02236400"]],"a":[["15505.82000000","0.56313900"],["15506.26000000","0.21803800"],["15510.30000000","0.05000000"],["15510.43000000","0.01000000"],["15511.16000000","0.00000000"],["15512.01000000","0.00000000"],["15512.24000000","0.01000000"],["15512.67000000","0.00000000"]]}}
2020-11-09T11:26:11.12933 btcusdt {"stream":"btcusdt@depth@100ms","data":{"e":"depthUpdate","E":1604921171122,"s":"BTCUSDT","U":6511135317,"u":6511135325,"b":[["15503.25000000","0.00000000"],["15502.41000000","0.01656100"],["15490.03000000","0.00000000"]],"a":[["15505.82000000","0.76017700"],["15507.16000000","2.13000000"],["15512.90000000","0.00000000"],["15520.42000000","0.00000000"],["15561.00000000","0.26473100"]]}}
2020-11-09T11:26:11.23118 btcusdt {"stream":"btcusdt@depth@100ms","data":{"e":"depthUpdate","E":1604921171222,"s":"BTCUSDT","U":6511135326,"u":6511135336,"b":[["15502.88000000","0.00000000"],["15502.01000000","0.00682800"],["15500.54000000","0.10834400"],["15493.52000000","0.00000000"],["15489.52000000","0.20000000"],["15487.39000000","1.13837100"]],"a":[["15505.82000000","0.91838200"],["15510.58000000","0.32200000"],["15511.43000000","0.00000000"]]}}
2020-11-09T11:26:11.33622 btcusdt {"stream":"btcusdt@depth@100ms","data":{"e":"depthUpdate","E":1604921171322,"s":"BTCUSDT","U":6511135337,"u":6511135343,"b":[["15500.02000000","5.06877700"]],"a":[["15505.82000000","0.91198200"],["15509.22000000","0.80000000"],["15510.78000000","1.12000000"],["15511.32000000","1.12000000"]]}}
2020-11-09T11:26:11.42862 btcusdt {"stream":"btcusdt@depth@100ms","data":{"e":"depthUpdate","E":1604921171422,"s":"BTCUSDT","U":6511135344,"u":6511135360,"b":[["15500.04000000","2.74179800"],["15500.03000000","0.05000000"],["15500.02000000","0.06734400"],["15465.05000000","0.24000000"],["15428.71000000","0.00000000"]],"a":[["15505.82000000","0.84564500"],["15509.21000000","0.01142100"],["15509.58000000","0.00000000"],["15513.98000000","0.00000000"],["15519.43000000","0.24000000"]]}}
2020-11-09T11:26:11.52853 btcusdt {"stream":"btcusdt@depth@100ms","data":{"e":"depthUpdate","E":1604921171522,"s":"BTCUSDT","U":6511135361,"u":6511135365,"b":[["15496.59000000","0.49350800"],["15486.31000000","0.10000000"],["15411.00000000","0.82111700"]],"a":[["15505.82000000","0.68104000"]]}}
2020-11-09T11:26:11.63002 btcusdt {"stream":"btcusdt@depth@100ms","data":{"e":"depthUpdate","E":1604921171622,"s":"BTCUSDT","U":6511135366,"u":6511135372,"b":[["15496.59000000","0.00000000"],["15465.05000000","0.00000000"],["15464.30000000","0.24000000"]],"a":[["15505.82000000","0.68372500"],["15519.43000000","0.00000000"],["15541.87000000","0.00000000"]]}}
2020-11-09T11:26:11.73386 btcusdt {"stream":"btcusdt@depth@100ms","data":{"e":"depthUpdate","E":1604921171722,"s":"BTCUSDT","U":6511135373,"u":6511135398,"b":[["15505.37000000","0.00644900"],["15502.41000000","0.00000000"],["15502.36000000","0.00000000"],["15502.01000000","0.00000000"],["15501.89000000","0.11427900"],["15501.82000000","0.01762000"],["15501.64000000","0.24880300"],["15501.46000000","0.00671600"],["15500.04000000","5.12971600"],["15498.29000000","0.00000000"],["15460.72000000","0.00000000"],["15387.00000000","0.37683000"]],"a":[["15505.82000000","2.68052500"],["15506.28000000","0.00842100"],["15506.59000000","0.01621500"],["15507.62000000","0.00000000"],["15507.93000000","0.00000000"],["15509.44000000","0.11427900"],["15509.94000000","0.00000000"],["15510.21000000","5.30000000"],["15512.74000000","1.25000000"],["15513.35000000","0.00000000"],["15518.78000000","0.24000000"],["15537.69000000","0.08562400"],["15553.76000000","0.00000000"]]}}
2020-11-09T11:26:11.83014 btcusdt {"stream":"btcusdt@depth@100ms","data":{"e":"depthUpdate","E":1604921171822,"s":"BTCUSDT","U":6511135399,"u":6511135409,"b":[["15501.90000000","0.16000000"],["15497.27000000","0.00000000"],["15494.95000000","1.00000000"],["15476.39000000","0.00000000"]],"a":[["15505.82000000","2.74124800"],["15506.44000000","0.02419600"],["15506.73000000","0.00000000"],["15507.16000000","2.12800000"],["15526.60000000","0.00000000"]]}}
2020-11-09T11:26:11.93108 btcusdt {"stream":"btcusdt@depth@100ms","data":{"e":"depthUpdate","E":1604921171922,"s":"BTCUSDT","U":6511135410,"u":6511135423,"b":[["15505.81000000","0.00890000"],["15498.77000000","0.19164600"],["15498.38000000","0.00000000"],["15498.18000000","0.06720100"],["15496.87000000","0.00000000"],["15495.62000000","0.00000000"],["15495.27000000","0.30210200"],["15486.91000000","0.02236400"],["15428.28000000","0.00648100"],["15411.00000000","0.71284400"]],"a":[["15505.82000000","2.74324800"],["15512.74000000","1.25000000"],["15523.56000000","1.12344600"]]}}
2020-11-09T11:26:12.02997 btcusdt {"stream":"btcusdt@depth@100ms","data":{"e":"depthUpdate","E":1604921172022,"s":"BTCUSDT","U":6511135424,"u":6511135433,"b":[["15501.82000000","0.00000000"],["15501.66000000","0.01388500"],["15501.46000000","0.00000000"],["15501.29000000","0.03975500"],["15500.05000000","0.05000000"],["15500.03000000","0.00000000"],["15498.99000000","1.25000000"],["15497.14000000","0.13440100"],["15496.50000000","0.00000000"],["15464.30000000","0.00000000"]],"a":[]}}
2020-11-09T11:26:12.13368 btcusdt {"stream":"btcusdt@depth@100ms","data":{"e":"depthUpdate","E":1604921172122,"s":"BTCUSDT","U":6511135434,"u":6511135438,"b":[["15496.59000000","0.03360300"],["15494.64000000","0.13441000"],["15471.43000000","0.00000000"],["15447.98000000","0.24000000"]],"a":[["15548.98000000","0.00000000"]]}}
2020-11-09T11:26:12.23279 btcusdt {"stream":"btcusdt@depth@100ms","data":{"e":"depthUpdate","E":1604921172222,"s":"BTCUSDT","U":6511135439,"u":6511135442,"b":[["15447.98000000","0.00000000"]],"a":[["15510.35000000","0.20000000"],["15512.64000000","0.01500000"],["15513.07000000","0.00000000"]]}}
2020-11-09T11:26:12.33530 btcusdt {"stream":"btcusdt@depth@100ms","data":{"e":"depthUpdate","E":1604921172322,"s":"BTCUSDT","U":6511135443,"u":6511135447,"b":[["15505.81000000","0.00000000"],["15505.37000000","0.00000000"],["15505.01000000","0.00000000"],["15505.00000000","0.64692800"],["15495.75000000","1.04346700"]],"a":[["15505.82000000","2.67033800"],["15508.42000000","0.89857500"]]}}
2020-11-09T11:26:12.42895 btcusdt {"stream":"btcusdt@depth@100ms","data":{"e":"depthUpdate","E":1604921172423,"s":"BTCUSDT","U":6511135448,"u":6511135490,"b":[["15505.00000000","0.65382800"],["15504.95000000","0.00000000"],["15504.55000000","0.00000000"],["15503.66000000","0.01000000"],["15502.60000000","0.01000000"],["15501.64000000","0.00000000"],["15500.54000000","0.00000000"],["15500.04000000","0.00000000"],["15496.44000000","0.00000000"],["15495.44000000","0.00000000"],["15442.57000000","0.24000000"]],"a":[["15505.01000000","1.58710100"],["15505.02000000","0.00000000"],["15505.04000000","0.00000000"],["15505.38000000","0.00000000"],["15505.42000000","0.00690000"],["15505.70000000","0.00000000"],["15505.81000000","0.97981100"],["15505.82000000","2.26602300"],["15505.97000000","0.00000000"],["15505.98000000","0.00000000"],["15506.03000000","0.00000000"],["15506.14000000","0.00000000"],["15510.33000000","1.19800000"],["15510.98000000","0.29200000"]]}}
2020-11-09T11:26:12.53053 btcusdt {"stream":"btcusdt@depth@100ms","data":{"e":"depthUpdate","E":1604921172523,"s":"BTCUSDT","U":6511135491,"u":6511135517,"b":[["15502.60000000","0.00000000"],["15501.89000000","0.00000000"],["15501.66000000","0.00000000"],["15501.42000000","0.11427900"],["15500.95000000","0.08000000"],["15500.05000000","0.00000000"],["15500.01000000","0.05000000"],["15496.89000000","0.00000000"],["15493.10000000","0.00000000"],["15491.45000000","0.23546800"],["15467.07000000","0.00000000"]],"a":[["15505.01000000","3.71785600"],["15505.81000000","0.00627500"],["15508.77000000","0.00000000"],["15508.97000000","0.11427900"],["15509.44000000","0.00000000"],["15509.58000000","0.25000000"],["15509.79000000","0.06000000"],["15510.30000000","0.00000000"],["15510.43000000","0.00000000"],["15510.57000000","1.94800000"],["15511.43000000","0.01000000"],["15512.24000000","0.00000000"],["15514.51000000","0.00000000"]]}}
2020-11-09T11:26:12.62901 btcusdt {"stream":"btcusdt@depth@100ms","data":{"e":"depthUpdate","E":1604921172623,"s":"BTCUSDT","U":6511135518,"u":6511135529,"b":[["15503.65000000","0.00000000"],["15501.41000000","0.01574300"],["15501.29000000","0.03224400"],["15501.15000000","0.00682200"],["15495.65000000","0.38911600"],["15492.10000000","0.00000000"],["15485.54000000","0.87000000"],["15387.00000000","0.48510300"]],"a":[["15505.01000000","3.71465600"],["15506.26000000","0.20000000"],["15508.41000000","0.10000000"],["15508.74000000","0.08000000"]]}}
2020-11-09T11:26:12.73169 btcusdt {"stream":"btcusdt@depth@100ms","data":{"e":"depthUpdate","E":1604921172723,"s":"BTCUSDT","U":6511135530,"u":6511135532,"b":[["15496.81000000","0.03362500"]],"a":[["15505.01000000","3.71145600"],["15506.01000000","0.00200000"]]}}
2020-11-09T11:26:12.83171 btcusdt {"stream":"btcusdt@depth@100ms","data":{"e":"depthUpdate","E":1604921172823,"s":"BTCUSDT","U":6511135533,"u":6511135538,"b":[["15505.00000000","0.65041000"],["15495.65000000","0.00000000"],["15456.24000000","0.12132900"]],"a":[["15505.01000000","3.65995500"],["15505.81000000","0.01517400"]]}}
2020-11-09T11:26:12.93270 btcusdt {"stream":"btcusdt@depth@100ms","data":{"e":"depthUpdate","E":1604921172923,"s":"BTCUSDT","U":6511135539,"u":6511135550,"b":[["15495.89000000","0.10087400"],["15489.56000000","0.00000000"],["15485.98000000","0.38295000"],["15474.89000000","0.01550800"],["15428.28000000","0.00000000"]],"a":[["15505.01000000","3.65742100"],["15505.03000000","0.00066600"],["15505.05000000","0.00066700"],["15507.12000000","0.10000000"],["15508.41000000","0.00000000"],["15567.93000000","0.01541600"]]}}
2020-11-09T11:26:13.03316 btcusdt {"stream":"btcusdt@depth@100ms","data":{"e":"depthUpdate","E":1604921173023,"s":"BTCUSDT","U":6511135551,"u":6511135563,"b":[["15502.35000000","0.00000000"],["15501.53000000","0.00000000"],["15500.40000000","0.06000000"],["15500.00000000","14.40844600"]],"a":[["15505.01000000","3.65422100"],["15505.71000000","0.00695800"],["15505.81000000","0.00627500"],["15506.28000000","0.00000000"],["15506.59000000","0.00000000"],["15509.58000000","0.30000000"],["15509.79000000","0.01000000"],["15513.83000000","1.45100000"],["15565.51000000","0.00000000"]]}}
2020-11-09T11:26:13.12977 btcusdt {"stream":"btcusdt@depth@100ms","data":{"e":"depthUpdate","E":1604921173123,"s":"BTCUSDT","U":6511135564,"u":6511135574,"b":[["15502.59000000","0.00000000"],["15500.95000000","0.12000000"],["15466.24000000","0.25000000"]],"a":[["15505.01000000","1.59073000"],["15505.70000000","1.13963000"],["15514.62000000","1.00898800"],["15516.56000000","0.30000000"],["15516.81000000","0.00000000"],["15519.28000000","0.50000000"]]}}
2020-11-09T11:26:13.23083 btcusdt {"stream":"btcusdt@depth@100ms","data":{"e":"depthUpdate","E":1604921173223,"s":"BTCUSDT","U":6511135575,"u":6511135588,"b":[["15501.91000000","0.01000000"],["15499.25000000","0.08000000"],["15387.00000000","0.10827300"]],"a":[["15505.01000000","1.58591700"],["15509.20000000","0.12900100"],["15509.62000000","0.01000000"],["15509.79000000","0.00000000"],["15511.83000000","0.01500000"],["15512.64000000","0.00000000"],["15513.52000000","0.00000000"],["15516.54000000","0.50000000"],["15518.12000000","1.90912500"],["15519.28000000","0.00000000"],["15521.11000000","0.00000000"]]}}
2020-11-09T11:26:13.39542 btcusdt {"stream":"btcusdt@depth@100ms","data":{"e":"depthUpdate","E":1604921173323,"s":"BTCUSDT","U":6511135589,"u":6511135599,"b":[["15505.00000000","0.64532700"],["15429.37000000","0.00000000"]],"a":[["15505.01000000","3.55871700"],["15505.69000000","0.20000000"],["15505.70000000","0.00000000"],["15507.13000000","0.00000000"],["15510.90000000","1.25000000"],["15512.74000000","0.00000000"],["15543.77000000","0.25000000"],["15561.00000000","0.15645800"]]}}
2020-11-09T11:26:13.43360 btcusdt {"stream":"btcusdt@depth@100ms","data":{"e":"depthUpdate","E":1604921173423,"s":"BTCUSDT","U":6511135600,"u":6511135618,"b":[["15499.35000000","0.00000000"],["15495.28000000","0.00000000"],["15493.70000000","0.00000000"],["15492.90000000","0.00000000"],["15492.24000000","0.18420000"],["15491.19000000","1.00898800"],["15469.64000000","0.00000000"],["15468.98000000","0.60470000"],["15428.71000000","5.99620000"],["15427.47000000","0.00648100"],["15411.00000000","1.08967400"]],"a":[["15505.01000000","3.55784900"],["15518.78000000","0.00000000"],["15534.10000000","0.00000000"],["15534.43000000","0.18420000"],["15560.54000000","0.00500000"],["15562.13000000","0.60470000"],["15594.94000000","5.99620000"],["15595.56000000","0.00000000"]]}}
2020-11-09T11:26:13.53292 btcusdt {"stream":"btcusdt@depth@100ms","data":{"e":"depthUpdate","E":1604921173523,"s":"BTCUSDT","U":6511135619,"u":6511135632,"b":[["15503.66000000","0.00000000"],["15501.15000000","0.00000000"],["15500.70000000","0.00916700"],["15500.02000000","0.00000000"],["15497.81000000","0.00000000"],["15491.55000000","0.50449400"]],"a":[["15505.01000000","3.53984900"],["15505.47000000","0.00759200"],["15505.71000000","0.00000000"],["15505.80000000","0.01263900"],["15505.82000000","2.26013800"],["15506.25000000","0.06251100"]]}}
2020-11-09T11:26:13.63207 btcusdt {"stream":"btcusdt@depth@100ms","data":{"e":"depthUpdate","E":1604921173623,"s":"BTCUSDT","U":6511135633,"u":6511135642,"b":[["15505.00000000","0.64189100"],["15501.41000000","0.00000000"],["15500.98000000","0.01306500"],["15495.75000000","0.00000000"]],"a":[["15505.01000000","3.53984900"],["15505.78000000","0.01737900"],["15505.80000000","0.00000000"],["15509.19000000","0.01000000"],["15509.21000000","0.00000000"]]}}
2020-11-09T11:26:13.73405 btcusdt {"stream":"btcusdt@depth@100ms","data":{"e":"depthUpdate","E":1604921173723,"s":"BTCUSDT","U":6511135643,"u":6511135648,"b":[["15505.00000000","0.60795800"]],"a":[["15505.01000000","8.83984900"],["15505.47000000","0.00729500"],["15513.00000000","0.10000000"],["15515.82000000","0.00000000"]]}}
2020-11-09T11:26:13.83177 btcusdt {"stream":"btcusdt@depth@100ms","data":{"e":"depthUpdate","E":1604921173823,"s":"BTCUSDT","U":6511135649,"u":6511135657,"b":[["15505.00000000","0.56838900"]],"a":[["15505.01000000","3.88684900"],["15505.47000000","0.00794300"],["15505.82000000","2.25813800"],["15507.16000000","2.00000000"],["15511.79000000","0.14700000"]]}}
2020-11-09T11:26:13.93298 btcusdt {"stream":"btcusdt@depth@100ms","data":{"e":"depthUpdate","E":1604921173923,"s":"BTCUSDT","U":6511135658,"u":6511135665,"b":[["15505.00000000","0.58180000"],["15493.82000000","0.52399600"],["15427.47000000","0.00000000"]],"a":[["15505.01000000","3.82664000"],["15509.20000000","0.00000000"],["15524.54000000","0.00000000"]]}}
2020-11-09T11:26:14.03221 btcusdt {"stream":"btcusdt@depth@100ms","data":{"e":"depthUpdate","E":1604921174023,"s":"BTCUSDT","U":6511135666,"u":6511135673,"b":[["15505.00000000","0.57038900"],["15474.89000000","0.00000000"],["15387.00000000","0.00000000"]],"a":[["15505.01000000","3.82547800"],["15509.49000000","0.05000000"],["15509.58000000","0.25000000"],["15567.93000000","0.00000000"]]}}
2020-11-09T11:26:14.13101 btcusdt {"stream":"btcusdt@depth@100ms","data":{"e":"depthUpdate","E":1604921174123,"s":"BTCUSDT","U":6511135674,"u":6511135676,"b":[],"a":[["15505.01000000","3.84351600"],["15505.47000000","0.00617800"]]}}
2020-11-09T11:26:14.23073 btcusdt {"stream":"btcusdt@depth@100ms","data":{"e":"depthUpdate","E":1604921174224,"s":"BTCUSDT","U":6511135677,"u":6511135681,"b":[["15500.98000000","0.00000000"],["15498.78000000","0.06923000"],["15390.00000000","0.70836100"]],"a":[["15505.01000000","3.82615700"],["15585.00000000","0.64609400"]]}}
2020-11-09T11:26:14.33420 btcusdt {"stream":"btcusdt@depth@100ms","data":{"e":"depthUpdate","E":1604921174324,"s":"BTCUSDT","U":6511135682,"u":6511135685,"b":[["15501.15000000","0.01778000"],["15497.18000000","0.02106400"]],"a":[["15505.47000000","0.00960200"]]}}
2020-11-09T11:26:14.43083 btcusdt {"stream":"btcusdt@depth@100ms","data":{"e":"depthUpdate","E":1604921174424,"s":"BTCUSDT","U":6511135686,"u":6511135733,"b":[["15505.00000000","0.00000000"],["15503.45000000","0.00690000"],["15502.65000000","2.00000000"],["15502.14000000","0.20000000"],["15501.96000000","0.07323600"],["15501.91000000","0.01000000"],["15501.90000000","0.14397700"],["15501.42000000","0.00000000"],["15500.95000000","0.08000000"],["15498.78000000","0.00180000"],["15497.18000000","0.00000000"],["15427.47000000","0.00648100"]],"a":[["15503.46000000","0.50690000"],["15503.71000000","0.00000000"],["15504.20000000","0.02419600"],["15504.22000000","0.00000000"],["15504.23000000","0.00000000"],["15504.95000000","0.00000000"],["15505.01000000","3.32615700"],["15506.44000000","0.00000000"],["15507.16000000","2.98980000"],["15507.74000000","0.03400000"],["15508.73000000","0.01049000"],["15508.82000000","1.74800000"],["15508.97000000","0.00000000"],["15509.19000000","0.29800000"],["15509.49000000","0.34200000"],["15509.53000000","1.19800000"],["15509.61000000","0.00000000"],["15509.73000000","0.15700000"],["15509.85000000","0.00000000"],["15510.33000000","0.00000000"],["15510.57000000","0.20000000"],["15510.58000000","0.00000000"],["15510.89000000","0.29700000"],["15510.92000000","0.00000000"],["15510.98000000","0.00000000"],["15515.07000000","0.14700000"],["15519.00000000","0.00000000"],["15561.00000000","0.26473100"]]}}
2020-11-09T11:26:14.53652 btcusdt {"stream":"btcusdt@depth@100ms","data":{"e":"depthUpdate","E":1604921174524,"s":"BTCUSDT","U":6511135734,"u":6511135768,"b":[["15503.45000000","6.25558400"],["15502.66000000","0.01000000"],["15500.88000000","0.50000000"],["15498.12000000","0.00000000"]],"a":[["15503.46000000","0.50370000"],["15504.08000000","0.00000000"],["15504.20000000","0.00000000"],["15505.01000000","2.95651700"],["15505.47000000","0.00000000"],["15505.69000000","0.00000000"],["15506.87000000","0.20000000"],["15507.74000000","0.00000000"],["15507.85000000","0.50000000"],["15508.51000000","0.01700000"],["15508.52000000","0.01700000"],["15508.73000000","0.07049000"],["15509.49000000","0.29200000"],["15509.62000000","0.00000000"],["15509.88000000","0.01000000"],["15510.27000000","0.01500000"],["15510.35000000","0.00000000"],["15510.57000000","0.00000000"],["15511.29000000","0.06683700"],["15511.43000000","0.00000000"],["15511.83000000","0.00000000"],["15517.84000000","0.24000000"],["15522.15000000","0.00000000"],["15524.48000000","0.06718900"],["15527.87000000","0.00000000"]]}}
2020-11-09T11:26:14.63132 btcusdt {"stream":"btcusdt@depth@100ms","data":{"e":"depthUpdate","E":1604921174624,"s":"BTCUSDT","U":6511135769,"u":6511135782,"b":[["15503.45000000","8.59837600"],["15495.60000000","0.50000000"],["15491.45000000","0.00000000"],["15488.45000000","0.23543200"],["15469.67000000","0.00358800"]],"a":[["15505.20000000","0.00200000"],["15506.26000000","0.00000000"],["15507.11000000","0.20000000"],["15508.73000000","0.06000000"],["15511.29000000","0.00000000"],["15556.51000000","0.00000000"]]}}
2020-11-09T11:26:14.73084 btcusdt {"stream":"btcusdt@depth@100ms","data":{"e":"depthUpdate","E":1604921174724,"s":"BTCUSDT","U":6511135783,"u":6511135789,"b":[["15498.99000000","0.00000000"],["15495.88000000","1.25000000"]],"a":[["15503.46000000","0.23140000"],["15505.01000000","2.95585100"],["15505.03000000","0.00000000"],["15505.05000000","0.00000000"],["15513.28000000","0.06683400"]]}}
2020-11-09T11:26:14.84226 btcusdt {"stream":"btcusdt@depth@100ms","data":{"e":"depthUpdate","E":1604921174824,"s":"BTCUSDT","U":6511135790,"u":6511135805,"b":[["15502.84000000","0.07619100"],["15501.96000000","0.00000000"],["15496.99000000","0.02106400"],["15467.09000000","0.03100000"],["15018.25000000","0.00000000"]],"a":[["15503.46000000","0.16870100"],["15503.48000000","0.00133300"],["15505.40000000","0.01702600"],["15505.78000000","0.00000000"],["15506.87000000","0.00000000"],["15508.27000000","0.32200000"],["15510.90000000","0.00000000"],["15512.43000000","1.25000000"],["15553.93000000","0.03100000"]]}}
2020-11-09T11:26:14.93177 btcusdt {"stream":"btcusdt@depth@100ms","data":{"e":"depthUpdate","E":1604921174924,"s":"BTCUSDT","U":6511135806,"u":6511135816,"b":[["15502.86000000","0.07714000"],["15502.84000000","0.00000000"],["15502.66000000","0.00000000"],["15501.63000000","0.00000000"],["15498.65000000","1.25200000"],["15495.88000000","0.00000000"],["15427.47000000","0.00000000"]],"a":[["15503.46000000","0.16550100"],["15505.00000000","0.20000000"],["15510.26000000","0.20000000"],["15510.61000000","0.20000000"]]}}
2020-11-09T11:26:15.03163 btcusdt {"stream":"btcusdt@depth@100ms","data":{"e":"depthUpdate","E":1604921175024,"s":"BTCUSDT","U":6511135817,"u":6511135824,"b":[["15497.17000000","0.00000000"],["15490.75000000","0.01936600"],["15460.07000000","0.00000000"],["15454.71000000","0.16176300"]],"a":[["15503.46000000","0.16818600"],["15505.81000000","0.10627500"],["15507.12000000","0.00000000"]]}}
2020-11-09T11:26:15.13160 btcusdt {"stream":"btcusdt@depth@100ms","data":{"e":"depthUpdate","E":1604921175124,"s":"BTCUSDT","U":6511135825,"u":6511135826,"b":[["15016.38000000","0.00203900"]],"a":[["15503.46000000","0.16498600"]]}}
2020-11-09T11:26:15.23483 btcusdt {"stream":"btcusdt@depth@100ms","data":{"e":"depthUpdate","E":1604921175224,"s":"BTCUSDT","U":6511135827,"u":6511135834,"b":[["15500.41000000","0.10834700"],["15457.04000000","0.01552600"]],"a":[["15503.46000000","0.16178600"],["15505.81000000","0.00627500"],["15506.87000000","0.10000000"],["15510.61000000","0.00000000"],["15550.06000000","0.01543400"],["15550.77000000","0.00000000"]]}}
2020-11-09T11:26:15.33187 btcusdt {"stream":"btcusdt@depth@100ms","data":{"e":"depthUpdate","E":1604921175324,"s":"BTCUSDT","U":6511135835,"u":6511135850,"b":[["15502.88000000","0.07714000"],["15502.86000000","0.00000000"],["15501.15000000","0.00000000"],["15500.70000000","0.00000000"],["15500.19000000","0.11427900"],["15499.52000000","0.01489400"],["15499.21000000","0.00716000"],["15466.50000000","0.00000000"]],"a":[["15503.46000000","0.15858600"],["15503.92000000","0.00731100"],["15504.23000000","0.01787300"],["15505.40000000","0.00000000"],["15508.25000000","0.11427900"],["15510.20000000","0.13029300"],["15510.21000000","5.31035100"],["16086.98000000","0.00000000"]]}}
2020-11-09T11:26:15.43420 btcusdt {"stream":"btcusdt@depth@100ms","data":{"e":"depthUpdate","E":1604921175424,"s":"BTCUSDT","U":6511135851,"u":6511135854,"b":[["15425.93000000","0.00648200"]],"a":[["15503.46000000","0.15538600"],["15505.01000000","2.95385100"],["15509.19000000","0.28800000"]]}}
2020-11-09T11:26:15.53189 btcusdt {"stream":"btcusdt@depth@100ms","data":{"e":"depthUpdate","E":1604921175524,"s":"BTCUSDT","U":6511135855,"u":6511135874,"b":[["15500.20000000","0.00000000"],["15497.15000000","0.02106400"],["15496.99000000","0.00000000"],["15492.31000000","0.50451000"],["15491.95000000","1.00902100"],["15491.55000000","0.00000000"],["15491.19000000","0.00000000"],["15464.50000000","2.00000000"]],"a":[["15503.46000000","0.15818600"],["15504.58000000","0.45437700"],["15505.00000000","0.00000000"],["15505.81000000","0.00000000"],["15506.24000000","0.20000000"],["15515.19000000","0.00000000"],["15517.84000000","0.48000000"],["15518.38000000","0.05681900"],["15520.88000000","0.00000000"]]}}
2020-11-09T11:26:15.63135 btcusdt {"stream":"btcusdt@depth@100ms","data":{"e":"depthUpdate","E":1604921175624,"s":"BTCUSDT","U":6511135875,"u":6511135883,"b":[["15502.91000000","0.07377300"],["15502.88000000","0.00000000"],["15494.69000000","1.15465500"]],"a":[["15503.46000000","0.09493200"],["15504.57000000","0.22718900"],["15510.26000000","0.00000000"],["15513.00000000","0.00000000"],["16089.41000000","0.00062800"]]}}
2020-11-09T11:26:15.73052 btcusdt {"stream":"btcusdt@depth@100ms","data":{"e":"depthUpdate","E":1604921175724,"s":"BTCUSDT","U":6511135884,"u":6511135884,"b":[],"a":[["15515.89000000","0.10000000"]]}}
2020-11-09T11:26:15.83053 btcusdt {"stream":"btcusdt@depth@100ms","data":{"e":"depthUpdate","E":1604921175824,"s":"BTCUSDT","U":6511135885,"u":6511135890,"b":[["15502.93000000","0.07714000"],["15502.91000000","0.00000000"]],"a":[["15503.46000000","0.09253200"],["15507.11000000","0.00000000"]]}}
2020-11-09T11:26:15.93095 btcusdt {"stream":"btcusdt@depth@100ms","data":{"e":"depthUpdate","E":1604921175924,"s":"BTCUSDT","U":6511135891,"u":6511135895,"b":[["14800.00000000","91.43202900"]],"a":[["15503.46000000","0.08933200"],["15505.01000000","2.93581300"],["15507.84000000","0.20000000"],["15509.81000000","0.20000000"]]}}
2020-11-09T11:26:16.03210 btcusdt {"stream":"btcusdt@depth@100ms","data":{"e":"depthUpdate","E":1604921176024,"s":"BTCUSDT","U":6511135896,"u":6511135903,"b":[["15484.73000000","1.90537000"]],"a":[["15504.58000000","0.00000000"],["15508.50000000","0.05000000"],["15508.73000000","0.01000000"],["15510.20000000","0.00128900"],["15512.43000000","0.00000000"],["15512.74000000","1.25000000"],["15515.79000000","0.00000000"]]}}
2020-11-09T11:26:16.13219 btcusdt {"stream":"btcusdt@depth@100ms","data":{"e":"depthUpdate","E":1604921176125,"s":"BTCUSDT","U":6511135904,"u":6511135912,"b":[["15503.45000000","8.60037600"],["15503.11000000","0.07373300"],["15502.98000000","0.00000000"],["15502.93000000","0.00000000"]],"a":[["15503.46000000","0.06957400"],["15504.57000000","0.00000000"]]}}
2020-11-09T11:26:16.23303 btcusdt {"stream":"btcusdt@depth@100ms","data":{"e":"depthUpdate","E":1604921176225,"s":"BTCUSDT","U":6511135913,"u":6511135921,"b":[["15503.14000000","0.07353600"],["15503.11000000","0.00000000"],["15502.67000000","0.01838700"],["15499.52000000","0.00000000"]],"a":[["15504.23000000","0.00000000"],["15505.81000000","1.12907100"],["15506.84000000","0.01839400"],["15508.50000000","0.06000000"],["15508.73000000","0.00000000"]]}}
2020-11-09T11:26:16.33074 btcusdt {"stream":"btcusdt@depth@100ms","data":{"e":"depthUpdate","E":1604921176325,"s":"BTCUSDT","U":6511135922,"u":6511135923,"b":[["15494.41000000","0.00000000"],["15491.88000000","1.50000000"]],"a":[]}}
2020-11-09T11:26:16.43469 btcusdt {"stream":"btcusdt@depth@100ms","data":{"e":"depthUpdate","E":1604921176425,"s":"BTCUSDT","U":6511135924,"u":6511135942,"b":[["15503.47000000","6.51661900"],["15503.46000000","5.30000000"],["15503.45000000","7.84330600"],["15503.34000000","0.07223700"],["15503.14000000","0.00000000"],["15502.21000000","0.00793600"],["15500.41000000","0.00000000"],["15499.21000000","0.00000000"],["14900.00000000","110.63450200"]],"a":[["15503.46000000","0.00000000"],["15503.48000000","0.50133300"],["15503.92000000","0.00000000"],["15505.01000000","2.28575100"],["15505.81000000","0.00000000"],["15506.71000000","0.00721200"]]}}
2020-11-09T11:26:16.53302 btcusdt {"stream":"btcusdt@depth@100ms","data":{"e":"depthUpdate","E":1604921176525,"s":"BTCUSDT","U":6511135943,"u":6511135955,"b":[["15503.47000000","6.66074200"],["15503.46000000","0.00000000"],["15503.45000000","7.50665700"],["15503.38000000","0.07299900"],["15503.34000000","0.00000000"]],"a":[["15503.48000000","0.00133300"],["15505.82000000","2.05813800"],["15506.24000000","0.00000000"],["15506.83000000","0.20000000"],["15507.83000000","0.20000000"]]}}
2020-11-09T11:26:16.63229 btcusdt {"stream":"btcusdt@depth@100ms","data":{"e":"depthUpdate","E":1604921176625,"s":"BTCUSDT","U":6511135956,"u":6511135991,"b":[["15504.25000000","1.09346700"],["15504.24000000","0.00690000"],["15503.77000000","0.07459300"],["15503.49000000","0.00000000"],["15503.47000000","5.59055800"],["15503.45000000","2.00890000"],["15503.38000000","0.00000000"],["15502.21000000","0.00000000"],["15500.19000000","0.00000000"],["15498.28000000","0.50202500"],["15495.60000000","0.00000000"],["15491.73000000","0.00200000"],["15242.99000000","0.00000000"]],"a":[["15503.48000000","0.00000000"],["15504.26000000","0.50690000"],["15505.25000000","0.00000000"],["15508.27000000","0.00000000"],["15508.50000000","0.00000000"],["15508.82000000","0.00000000"],["15509.12000000","0.05000000"],["15509.25000000","0.01000000"],["15509.53000000","0.00000000"],["15509.58000000","1.74800000"],["15509.88000000","0.00000000"],["15510.06000000","1.19800000"],["15510.27000000","0.00000000"],["15510.80000000","0.75000000"],["15511.06000000","0.01000000"],["15511.45000000","0.01500000"]]}}
2020-11-09T11:26:16.73123 btcusdt {"stream":"btcusdt@depth@100ms","data":{"e":"depthUpdate","E":1604921176725,"s":"BTCUSDT","U":6511135992,"u":6511136006,"b":[["15504.25000000","1.23759000"],["15503.47000000","5.44643500"],["15503.26000000","0.00200000"],["15502.36000000","0.00996600"],["15500.95000000","0.00000000"],["15499.36000000","0.00000000"],["15498.77000000","0.00000000"],["15498.17000000","0.30000000"],["15490.01000000","0.19367300"],["15456.15000000","0.00329500"],["15442.57000000","0.00000000"]],"a":[["15505.01000000","2.15875100"],["15506.87000000","0.00000000"],["15514.24000000","0.00000000"],["15517.84000000","0.24000000"]]}}
2020-11-09T11:26:16.83293 btcusdt {"stream":"btcusdt@depth@100ms","data":{"e":"depthUpdate","E":1604921176825,"s":"BTCUSDT","U":6511136007,"u":6511136011,"b":[],"a":[["15504.26000000","0.63490000"],["15506.71000000","0.00000000"],["15507.82000000","0.08000000"],["15508.24000000","0.10000000"],["15528.01000000","0.00000000"]]}}
2020-11-09T11:26:16.93145 btcusdt {"stream":"btcusdt@depth@100ms","data":{"e":"depthUpdate","E":1604921176925,"s":"BTCUSDT","U":6511136012,"u":6511136017,"b":[["15499.04000000","0.06742400"],["15498.29000000","0.37775900"],["15425.93000000","0.00000000"]],"a":[["15510.06000000","0.00000000"],["15514.10000000","0.30241600"],["15522.14000000","0.00000000"]]}}
2020-11-09T11:26:17.03517 btcusdt {"stream":"btcusdt@depth@100ms","data":{"e":"depthUpdate","E":1604921177025,"s":"BTCUSDT","U":6511136018,"u":6511136021,"b":[["15500.66000000","0.11427900"]],"a":[["15508.74000000","0.13000000"],["15509.12000000","0.00000000"],["15509.48000000","1.19800000"]]}}
2020-11-09T11:26:17.13259 btcusdt {"stream":"btcusdt@depth@100ms","data":{"e":"depthUpdate","E":1604921177125,"s":"BTCUSDT","U":6511136022,"u":6511136041,"b":[["15504.25000000","1.23687300"],["15502.14000000","0.00000000"],["15500.14000000","0.08000000"]],"a":[["15504.26000000","0.63690000"],["15505.35000000","0.48320600"],["15507.73000000","0.01700000"],["15507.74000000","0.01700000"],["15508.51000000","0.00000000"],["15508.52000000","0.00000000"],["15508.59000000","1.74800000"],["15508.88000000","1.19800000"],["15509.39000000","0.32100000"],["15509.48000000","0.00000000"],["15509.58000000","0.00000000"],["15511.04000000","1.25000000"],["15511.17000000","0.00000000"],["15512.74000000","0.00000000"],["15512.91000000","0.00000000"],["15522.95000000","0.00000000"],["15524.39000000","0.00000000"]]}}
2020-11-09T11:26:17.23211 btcusdt {"stream":"btcusdt@depth@100ms","data":{"e":"depthUpdate","E":1604921177225,"s":"BTCUSDT","U":6511136042,"u":6511136061,"b":[["15504.25000000","1.09275000"],["15502.67000000","0.00000000"],["15502.36000000","0.00000000"],["15500.00000000","14.41668000"],["15499.67000000","0.01660700"],["15499.35000000","0.10835300"],["15498.65000000","0.00200000"],["15496.50000000","1.25000000"]],"a":[["15504.72000000","0.00777100"],["15505.03000000","0.01864500"],["15506.69000000","0.00000000"],["15506.84000000","0.00000000"],["15506.87000000","0.20000000"],["15507.84000000","0.00000000"],["15508.87000000","0.01000000"],["15509.25000000","0.00000000"],["15511.04000000","0.00000000"],["15512.59000000","1.25000000"],["15537.03000000","0.00000000"]]}}
2020-11-09T11:26:17.33310 btcusdt {"stream":"btcusdt@depth@100ms","data":{"e":"depthUpdate","E":1604921177325,"s":"BTCUSDT","U":6511136062,"u":6511136067,"b":[],"a":[["15507.73000000","0.00000000"],["15507.74000000","0.00000000"],["15508.28000000","0.01700000"],["15508.29000000","0.01700000"],["15508.59000000","0.00000000"],["15509.37000000","1.74800000"]]}}
2020-11-09T11:26:17.43371 btcusdt {"stream":"btcusdt@depth@100ms","data":{"e":"depthUpdate","E":1604921177425,"s":"BTCUSDT","U":6511136068,"u":6511136083,"b":[["15504.25000000","1.09275000"],["15426.72000000","0.00648200"],["15382.72000000","0.00000000"],["15380.01000000","0.38361400"]],"a":[["15504.26000000","0.57357200"],["15505.35000000","0.00000000"],["15506.86000000","0.00000000"],["15506.87000000","0.00000000"],["15507.13000000","0.10000000"],["15507.81000000","0.20000000"],["15508.24000000","0.00000000"],["15508.25000000","0.00000000"],["15508.88000000","0.00000000"]]}}
2020-11-09T11:26:17.53226 btcusdt {"stream":"btcusdt@depth@100ms","data":{"e":"depthUpdate","E":1604921177525,"s":"BTCUSDT","U":6511136084,"u":6511136087,"b":[["15498.65000000","1.25200000"],["15496.50000000","0.00000000"]],"a":[["15508.78000000","0.11427900"],["15509.36000000","1.19800000"]]}}
2020-11-09T11:26:17.63232 btcusdt {"stream":"btcusdt@depth@100ms","data":{"e":"depthUpdate","E":1604921177625,"s":"BTCUSDT","U":6511136088,"u":6511136094,"b":[["15504.25000000","1.07975000"],["15498.29000000","0.00000000"],["15442.58000000","0.24000000"]],"a":[["15507.13000000","0.00000000"],["15508.27000000","0.10000000"],["15510.68000000","0.01000000"],["15511.06000000","0.00000000"]]}}
2020-11-09T11:26:17.73298 btcusdt {"stream":"btcusdt@depth@100ms","data":{"e":"depthUpdate","E":1604921177725,"s":"BTCUSDT","U":6511136095,"u":6511136102,"b":[["15496.49000000","0.22500000"],["15460.36000000","0.16170400"],["15454.71000000","0.00000000"]],"a":[["15504.26000000","0.59161000"],["15506.19000000","0.22500100"],["15506.69000000","0.08000000"],["15506.82000000","0.20000000"],["15507.83000000","0.00000000"]]}}
2020-11-09T11:26:17.83213 btcusdt {"stream":"btcusdt@depth@100ms","data":{"e":"depthUpdate","E":1604921177825,"s":"BTCUSDT","U":6511136103,"u":6511136114,"b":[["15500.28000000","0.01703800"],["15499.67000000","0.00000000"],["15497.97000000","0.19107500"],["15495.27000000","0.00000000"]],"a":[["15504.72000000","0.00000000"],["15506.19000000","0.00000000"],["15506.81000000","0.10000000"],["15508.27000000","0.00000000"],["15508.82000000","1.19800000"],["15509.36000000","0.00000000"],["15510.37000000","0.00000000"],["15515.92000000","0.13440700"]]}}
2020-11-09T11:26:17.93190 btcusdt {"stream":"btcusdt@depth@100ms","data":{"e":"depthUpdate","E":1604921177925,"s":"BTCUSDT","U":6511136115,"u":6511136116,"b":[["15504.25000000","1.08175000"],["15493.28000000","0.30241200"]],"a":[]}}
2020-11-09T11:26:18.03162 btcusdt {"stream":"btcusdt@depth@100ms","data":{"e":"depthUpdate","E":1604921178025,"s":"BTCUSDT","U":6511136117,"u":6511136123,"b":[["15503.45000000","2.00690000"],["15500.28000000","0.00000000"],["15390.00000000","0.60008800"]],"a":[["15510.90000000","1.25000000"],["15512.59000000","0.00000000"],["15513.15000000","0.07500000"],["15533.52000000","1.14300200"]]}}
2020-11-09T11:26:18.13266 btcusdt {"stream":"btcusdt@depth@100ms","data":{"e":"depthUpdate","E":1604921178126,"s":"BTCUSDT","U":6511136124,"u":6511136128,"b":[["15499.04000000","0.00000000"],["15498.29000000","0.37766600"],["15466.24000000","0.00000000"],["15244.08000000","0.00590300"]],"a":[["15543.77000000","0.00000000"]]}}
2020-11-09T11:26:18.23161 btcusdt {"stream":"btcusdt@depth@100ms","data":{"e":"depthUpdate","E":1604921178226,"s":"BTCUSDT","U":6511136129,"u":6511136139,"b":[["15504.25000000","0.09546700"],["15503.77000000","0.00000000"],["15499.35000000","0.00000000"],["15411.00000000","1.19794700"]],"a":[["15508.27000000","0.12900800"],["15508.31000000","0.11427900"],["15508.78000000","0.00000000"],["15509.22000000","0.00000000"],["15511.07000000","0.01500000"],["15511.45000000","0.00000000"],["15526.20000000","2.02933800"]]}}
2020-11-09T11:26:18.33343 btcusdt {"stream":"btcusdt@depth@100ms","data":{"e":"depthUpdate","E":1604921178326,"s":"BTCUSDT","U":6511136140,"u":6511136146,"b":[],"a":[["15504.26000000","0.52766500"],["15505.81000000","0.20000000"],["15506.83000000","0.00000000"],["15509.48000000","0.12900900"],["15509.79000000","0.00000000"]]}}
2020-11-09T11:26:18.43332 btcusdt {"stream":"btcusdt@depth@100ms","data":{"e":"depthUpdate","E":1604921178426,"s":"BTCUSDT","U":6511136147,"u":6511136153,"b":[["15500.40000000","0.00000000"],["15498.61000000","0.30000000"]],"a":[["15505.20000000","0.41597400"],["15508.27000000","0.00000000"],["15509.07000000","0.32200000"],["15509.48000000","0.00000000"],["15517.84000000","0.00000000"]]}}
2020-11-09T11:26:18.53670 btcusdt {"stream":"btcusdt@depth@100ms","data":{"e":"depthUpdate","E":1604921178526,"s":"BTCUSDT","U":6511136154,"u":6511136158,"b":[["15503.47000000","0.14643500"],["15498.65000000","0.00200000"],["15496.50000000","1.25000000"],["15442.58000000","0.00000000"]],"a":[["15523.56000000","0.00000000"]]}}
2020-11-09T11:26:18.63543 btcusdt {"stream":"btcusdt@depth@100ms","data":{"e":"depthUpdate","E":1604921178626,"s":"BTCUSDT","U":6511136159,"u":6511136172,"b":[["15504.25000000","0.00200000"],["15501.90000000","0.00000000"],["15500.66000000","0.00000000"],["15500.19000000","0.11427900"],["15497.98000000","0.06744200"],["15441.79000000","0.24000000"]],"a":[["15504.26000000","2.56295700"],["15504.89000000","0.02419600"],["15507.16000000","0.98980000"],["15508.76000000","0.32000000"],["15509.28000000","0.32000000"],["15510.78000000","0.00000000"],["15511.32000000","0.00000000"]]}}
2020-11-09T11:26:18.73433 btcusdt {"stream":"btcusdt@depth@100ms","data":{"e":"depthUpdate","E":1604921178726,"s":"BTCUSDT","U":6511136173,"u":6511136179,"b":[["15503.47000000","0.00000000"],["15500.00000000","14.48839100"]],"a":[["15506.68000000","0.20000000"],["15507.70000000","0.11427900"],["15507.81000000","0.00000000"],["15508.31000000","0.00000000"],["15522.25000000","1.10930600"]]}}
2020-11-09T11:26:18.83389 btcusdt {"stream":"btcusdt@depth@100ms","data":{"e":"depthUpdate","E":1604921178826,"s":"BTCUSDT","U":6511136180,"u":6511136190,"b":[["15503.45000000","0.00690000"],["15501.29000000","0.00000000"],["15499.34000000","0.00000000"],["15498.57000000","0.03224700"],["15498.28000000","0.00202500"],["15496.91000000","0.00000000"],["15494.90000000","0.50000000"],["15494.01000000","0.12898900"]],"a":[["15504.51000000","0.02419600"],["15504.89000000","0.00000000"]]}}
2020-11-09T11:26:18.93318 btcusdt {"stream":"btcusdt@depth@100ms","data":{"e":"depthUpdate","E":1604921178926,"s":"BTCUSDT","U":6511136191,"u":6511136194,"b":[["15500.51000000","0.16000000"],["15411.00000000","1.08967400"]],"a":[["15508.78000000","0.50000000"],["15512.30000000","0.00000000"]]}}
2020-11-09T11:26:19.03293 btcusdt {"stream":"btcusdt@depth@100ms","data":{"e":"depthUpdate","E":1604921179026,"s":"BTCUSDT","U":6511136195,"u":6511136206,"b":[["15500.40000000","0.01532500"],["15497.15000000","0.00000000"],["15475.04000000","0.25795600"]],"a":[["15504.72000000","0.00940900"],["15505.80000000","0.20000000"],["15506.82000000","0.00000000"],["15508.11000000","0.03225100"],["15509.18000000","0.20000000"],["15509.80000000","0.00000000"],["15511.62000000","0.09628300"],["15553.83000000","0.00000000"],["15553.90000000","0.00000000"]]}}
2020-11-09T11:26:19.13237 btcusdt {"stream":"btcusdt@depth@100ms","data":{"e":"depthUpdate","E":1604921179126,"s":"BTCUSDT","U":6511136207,"u":6511136213,"b":[["15465.49000000","0.25000000"]],"a":[["15504.26000000","2.56095700"],["15504.50000000","0.20000000"],["15505.81000000","0.00000000"],["15518.12000000","0.40912500"],["15543.02000000","0.25000000"],["16450.00000000","8.62024900"]]}}
2020-11-09T11:26:19.23469 btcusdt {"stream":"btcusdt@depth@100ms","data":{"e":"depthUpdate","E":1604921179226,"s":"BTCUSDT","U":6511136214,"u":6511136223,"b":[["15500.19000000","0.00000000"],["15499.71000000","0.11427900"],["15496.98000000","0.00000000"]],"a":[["15504.26000000","2.50033700"],["15504.72000000","0.00695000"],["15505.41000000","0.13500000"],["15507.13000000","0.12901800"],["15508.27000000","0.16126100"],["15517.56000000","1.50000000"]]}}
2020-11-09T11:26:19.33391 btcusdt {"stream":"btcusdt@depth@100ms","data":{"e":"depthUpdate","E":1604921179326,"s":"BTCUSDT","U":6511136224,"u":6511136228,"b":[],"a":[["15504.72000000","0.00858900"],["15508.27000000","0.00000000"],["15508.75000000","0.12900700"],["15509.18000000","0.00000000"]]}}
2020-11-09T11:26:19.43441 btcusdt {"stream":"btcusdt@depth@100ms","data":{"e":"depthUpdate","E":1604921179426,"s":"BTCUSDT","U":6511136229,"u":6511136234,"b":[["15500.00000000","14.48015700"],["15499.56000000","0.01028000"]],"a":[["15504.72000000","0.00864600"],["15505.79000000","0.20000000"],["15506.68000000","0.00000000"]]}}
2020-11-09T11:26:19.53567 btcusdt {"stream":"btcusdt@depth@100ms","data":{"e":"depthUpdate","E":1604921179526,"s":"BTCUSDT","U":6511136235,"u":6511136243,"b":[["15500.40000000","0.00000000"],["15499.96000000","0.01332000"],["15499.73000000","0.50000000"],["15250.00000000","10.89653300"]],"a":[["15504.26000000","2.48229900"],["15507.47000000","0.50000000"],["15509.05000000","0.10000000"],["15517.88000000","0.05681900"],["15518.38000000","0.00000000"]]}}
2020-11-09T11:26:19.63985 btcusdt {"stream":"btcusdt@depth@100ms","data":{"e":"depthUpdate","E":1604921179626,"s":"BTCUSDT","U":6511136244,"u":6511136252,"b":[["15504.25000000","0.00000000"],["15504.24000000","0.00590000"],["15501.91000000","0.00000000"],["15497.98000000","0.00000000"],["15390.00000000","0.70836100"]],"a":[["15504.26000000","2.61864800"],["15505.41000000","0.00000000"],["15508.81000000","0.50000000"],["15510.36000000","0.00000000"],["15517.62000000","0.24000000"]]}}
2020-11-09T11:26:19.73367 btcusdt {"stream":"btcusdt@depth@100ms","data":{"e":"depthUpdate","E":1604921179727,"s":"BTCUSDT","U":6511136253,"u":6511136268,"b":[["15499.71000000","0.00000000"]],"a":[["15504.25000000","4.32423200"],["15504.26000000","2.16329200"],["15507.13000000","0.00000000"]]}}
2020-11-09T11:26:19.83829 btcusdt {"stream":"btcusdt@depth@100ms","data":{"e":"depthUpdate","E":1604921179827,"s":"BTCUSDT","U":6511136269,"u":6511136272,"b":[["15499.56000000","0.00143600"]],"a":[["15504.25000000","6.32423200"],["15504.71000000","0.15500000"],["15505.82000000","0.05813800"]]}}
2020-11-09T11:26:19.93366 btcusdt {"stream":"btcusdt@depth@100ms","data":{"e":"depthUpdate","E":1604921179927,"s":"BTCUSDT","U":6511136273,"u":6511136279,"b":[["15504.24000000","0.00790000"],["15499.12000000","0.00650100"],["15426.72000000","0.00000000"]],"a":[["15504.25000000","6.46423200"],["15504.45000000","0.00200000"],["15504.72000000","0.00828800"]]}}
2020-11-09T11:26:20.03498 btcusdt {"stream":"btcusdt@depth@100ms","data":{"e":"depthUpdate","E":1604921180027,"s":"BTCUSDT","U":6511136280,"u":6511136312,"b":[["15504.24000000","0.00000000"],["15503.45000000","0.01380000"]],"a":[["15503.46000000","4.94662300"],["15503.47000000","0.03896500"],["15503.86000000","0.00690000"],["15504.08000000","0.02419600"],["15504.15000000","0.09487000"],["15504.16000000","0.09004100"],["15504.25000000","2.32502000"],["15504.48000000","0.00000000"],["15504.51000000","0.00000000"],["15505.82000000","0.00000000"],["15506.98000000","0.11427900"],["15507.70000000","0.00000000"],["15513.45000000","0.00000000"],["15534.73000000","0.25000000"],["15538.76000000","0.25000000"],["15551.66000000","0.00000000"]]}}
2020-11-09T11:26:20.13556 btcusdt {"stream":"btcusdt@depth@100ms","data":{"e":"depthUpdate","E":1604921180127,"s":"BTCUSDT","U":6511136313,"u":6511136340,"b":[["15502.65000000","0.00000000"],["15499.96000000","0.00000000"],["15475.27000000","0.00000000"]],"a":[["15503.46000000","7.02236800"],["15504.08000000","0.00000000"],["15504.25000000","2.18867100"],["15504.71000000","0.00000000"],["15504.72000000","0.00000000"],["15505.01000000","0.15875100"],["15507.35000000","0.03800000"],["15507.94000000","0.05000000"],["15508.07000000","0.01000000"],["15508.28000000","0.00000000"],["15508.29000000","0.00000000"],["15508.41000000","1.74800000"],["15508.74000000","0.08000000"],["15508.87000000","0.00000000"],["15509.37000000","0.00000000"],["15509.88000000","0.01000000"],["15510.27000000","0.01500000"],["15510.68000000","0.00000000"],["15511.07000000","0.00000000"],["15539.82000000","0.01000000"]]}}
2020-11-09T11:26:20.23509 btcusdt {"stream":"btcusdt@depth@100ms","data":{"e":"depthUpdate","E":1604921180227,"s":"BTCUSDT","U":6511136341,"u":6511136346,"b":[["15503.45000000","0.01027400"],["15501.39000000","0.00000000"],["15467.51000000","0.01000000"]],"a":[["15503.46000000","5.90643200"],["15518.12000000","0.15150000"],["15523.17000000","0.00000000"]]}}
2020-11-09T11:26:20.33426 btcusdt {"stream":"btcusdt@depth@100ms","data":{"e":"depthUpdate","E":1604921180327,"s":"BTCUSDT","U":6511136347,"u":6511136389,"b":[["15503.45000000","0.00000000"],["15503.26000000","0.00000000"],["15501.87000000","0.00000000"],["15501.38000000","0.00000000"],["15500.94000000","0.00000000"],["15500.92000000","0.07590800"],["15500.88000000","0.19534300"],["15496.49000000","0.00000000"],["15493.45000000","0.00000000"],["15485.11000000","0.00000000"]],"a":[["15501.88000000","0.18117900"],["15502.17000000","0.00345000"],["15502.18000000","0.00690000"],["15502.49000000","0.07567000"],["15502.67000000","0.25000100"],["15502.68000000","0.00000000"],["15502.69000000","2.00000000"],["15503.27000000","1.95321700"],["15503.43000000","0.02410800"],["15503.45000000","5.79326800"],["15503.46000000","0.17346000"],["15504.44000000","0.00200000"],["15505.03000000","0.00000000"],["15506.09000000","0.01700000"],["15506.70000000","0.03690000"],["15507.35000000","0.02100000"],["15507.61000000","1.74800000"],["15507.69000000","1.19800000"],["15507.89000000","0.15700000"],["15508.02000000","0.29200000"],["15508.41000000","0.00000000"],["15508.82000000","0.00000000"],["15509.49000000","0.00000000"],["15509.73000000","0.00000000"],["15510.20000000","0.00000000"],["15531.70000000","0.00600000"],["15556.79000000","0.00000000"]]}}
2020-11-09T11:26:20.43417 btcusdt {"stream":"btcusdt@depth@100ms","data":{"e":"depthUpdate","E":1604921180427,"s":"BTCUSDT","U":6511136390,"u":6511136466,"b":[["15501.87000000","12.88479400"],["15501.17000000","0.07722800"],["15501.05000000","0.00000000"],["15500.98000000","2.00000000"],["15500.92000000","0.00000000"],["15500.89000000","0.00129000"],["15500.01000000","0.00000000"],["15499.30000000","0.00000000"],["15499.04000000","0.02500000"],["15498.69000000","0.05000000"],["15498.17000000","0.00000000"],["15496.81000000","0.00000000"],["15495.90000000","0.02106400"],["15495.89000000","0.00000000"],["15494.95000000","0.00000000"],["15494.13000000","0.00000000"],["15493.75000000","0.00000000"],["15492.36000000","1.00358300"],["15491.52000000","0.00000000"],["15490.27000000","0.15300000"],["15487.52000000","0.20000000"],["15482.76000000","0.28200000"],["15482.43000000","0.00282000"],["15474.29000000","0.27000000"],["15423.41000000","0.00648300"]],"a":[["15501.88000000","0.48914300"],["15502.17000000","0.00345000"],["15502.48000000","0.00000000"],["15502.49000000","0.00000000"],["15502.53000000","0.00000000"],["15502.56000000","0.00000000"],["15502.67000000","0.00000000"],["15502.68000000","1.00000000"],["15503.26000000","0.20000000"],["15503.27000000","0.00000000"],["15503.38000000","0.06614300"],["15503.39000000","0.00000000"],["15503.43000000","0.00000000"],["15503.45000000","0.00128900"],["15503.46000000","0.00000000"],["15503.47000000","0.00000000"],["15504.15000000","0.00000000"],["15504.16000000","0.00000000"],["15504.25000000","2.04867100"],["15504.50000000","0.00000000"],["15505.01000000","0.00000000"],["15505.79000000","0.00000000"],["15506.09000000","0.03400000"],["15507.35000000","0.00400000"],["15508.75000000","0.00000000"],["15508.81000000","0.00000000"],["15509.07000000","0.00000000"],["15511.12000000","0.00291000"],["15520.74000000","0.02500000"],["15538.60000000","0.01128800"],["15540.03000000","0.10000000"]]}}
2020-11-09T11:26:20.53551 btcusdt {"stream":"btcusdt@depth@100ms","data":{"e":"depthUpdate","E":1604921180527,"s":"BTCUSDT","U":6511136467,"u":6511136513,"b":[["15501.87000000","15.06969000"],["15501.53000000","0.07722800"],["15501.19000000","0.00000000"],["15501.17000000","0.00000000"],["15498.66000000","0.11427900"],["15495.16000000","0.24613600"],["15494.96000000","0.03361100"],["15494.83000000","0.30000000"],["15494.16000000","0.10083200"],["15493.42000000","0.28800000"],["15492.09000000","0.00303000"],["15485.98000000","0.00000000"],["15483.06000000","0.30600000"],["15470.00000000","0.03232000"],["14800.00000000","92.79223200"]],"a":[["15501.88000000","0.11019100"],["15502.17000000","0.00000000"],["15502.68000000","0.00000000"],["15502.69000000","0.00000000"],["15503.26000000","0.00000000"],["15504.24000000","0.00000000"],["15505.79000000","0.20000000"],["15506.68000000","0.20000000"],["15507.13000000","0.06000000"],["15507.94000000","0.00000000"],["15508.07000000","0.00000000"],["15508.30000000","0.01000000"],["15509.46000000","0.12900200"],["15509.88000000","0.00000000"],["15510.21000000","5.30000000"],["15511.74000000","0.00000000"],["15516.88000000","0.31446200"],["15517.88000000","0.00000000"],["15949.75000000","0.68719700"]]}}
2020-11-09T11:26:20.63963 btcusdt {"stream":"btcusdt@depth@100ms","data":{"e":"depthUpdate","E":1604921180627,"s":"BTCUSDT","U":6511136514,"u":6511136584,"b":[["15502.77000000","0.00690000"],["15502.26000000","0.07263200"],["15502.25000000","0.05757000"],["15502.23000000","0.27994900"],["15502.22000000","0.00000000"],["15502.21000000","0.20758300"],["15502.20000000","0.17002500"],["15502.19000000","0.00000000"],["15502.17000000","4.86797000"],["15501.87000000","2.14179600"],["15501.53000000","0.00000000"],["15500.89000000","0.00000000"],["15497.97000000","0.00000000"],["15497.79000000","0.12900200"],["15497.71000000","0.06745700"],["15495.90000000","0.00000000"],["15494.01000000","0.00000000"],["15488.45000000","0.00000000"],["15484.00000000","0.23619200"],["15460.36000000","0.00000000"],["15451.45000000","0.16179700"]],"a":[["15501.88000000","0.00000000"],["15502.18000000","0.00000000"],["15502.78000000","0.00062500"],["15503.38000000","0.01127000"],["15503.45000000","0.00000000"],["15503.86000000","0.00000000"],["15504.04000000","0.00000000"],["15504.24000000","0.02539700"],["15504.25000000","2.01920100"],["15504.26000000","2.12800000"],["15506.09000000","0.00000000"],["15506.98000000","0.00000000"],["15507.31000000","0.03400000"],["15507.61000000","0.00000000"],["15507.69000000","0.00000000"],["15508.21000000","1.19800000"],["15508.37000000","1.74800000"],["15511.12000000","0.00000000"],["15513.31000000","0.10000000"],["15514.34000000","0.00294000"],["15515.67000000","1.00000000"],["15515.89000000","0.00000000"],["15518.45000000","0.00000000"]]}}
2020-11-09T11:26:20.73464 btcusdt {"stream":"btcusdt@depth@100ms","data":{"e":"depthUpdate","E":1604921180727,"s":"BTCUSDT","U":6511136585,"u":6511136618,"b":[["15502.77000000","0.00000000"],["15502.64000000","0.00000000"],["15502.27000000","0.07614400"],["15502.26000000","0.13983100"],["15502.25000000","0.06705000"],["15502.23000000","0.00000000"],["15502.21000000","0.00128900"],["15502.20000000","0.00000000"],["15502.17000000","0.07280000"],["15501.87000000","2.00690000"],["15499.46000000","0.01455100"],["15498.68000000","0.00000000"],["15498.29000000","0.00000000"],["15498.18000000","0.00000000"],["15496.21000000","0.06720700"]],"a":[["15503.38000000","0.00000000"],["15504.23000000","0.01422400"],["15507.13000000","0.00000000"],["15507.81000000","0.05000000"],["15507.86000000","0.01000000"],["15508.30000000","0.00000000"],["15509.67000000","0.01000000"],["15514.95000000","0.00000000"],["15603.47000000","0.95789300"],["15626.73000000","0.00126200"],["16400.00000000","31.69988100"]]}}
2020-11-09T11:26:20.83842 btcusdt {"stream":"btcusdt@depth@100ms","data":{"e":"depthUpdate","E":1604921180827,"s":"BTCUSDT","U":6511136619,"u":6511136696,"b":[["15502.71000000","0.00000000"],["15502.27000000","0.06984400"],["15502.26000000","0.00000000"],["15502.25000000","0.00000000"],["15501.75000000","0.07857300"],["15500.14000000","0.00000000"],["15500.01000000","0.05000000"],["15499.25000000","0.00000000"],["15498.69000000","0.00000000"],["15498.50000000","0.04000000"],["15497.79000000","0.00000000"],["15497.11000000","0.08000000"],["15496.59000000","0.00000000"],["15494.79000000","0.01900000"],["15494.69000000","0.00400000"],["15494.50000000","0.12900200"],["15493.82000000","0.00000000"],["15493.75000000","0.50454300"],["15493.39000000","1.00908600"],["15492.31000000","0.00000000"],["15491.95000000","0.00000000"],["15469.00000000","2.00000000"],["15192.22000000","0.00174700"]],"a":[["15502.28000000","0.02184700"],["15502.70000000","0.06481400"],["15502.71000000","0.00000000"],["15502.72000000","0.00690000"],["15502.73000000","0.00000000"],["15502.74000000","0.00000000"],["15502.77000000","0.00000000"],["15502.78000000","0.12962500"],["15503.92000000","0.00767200"],["15504.22000000","2.02941200"],["15504.26000000","2.00000000"],["15505.19000000","0.08000000"],["15506.44000000","0.03400000"],["15506.70000000","0.00690000"],["15506.87000000","0.59796700"],["15506.99000000","1.08000000"],["15507.08000000","0.32100000"],["15507.13000000","1.19549900"],["15507.26000000","1.19800000"],["15507.31000000","0.00000000"],["15507.34000000","0.00000000"],["15507.50000000","1.74800000"],["15507.51000000","1.08000000"],["15507.81000000","0.00000000"],["15508.21000000","0.05000000"],["15508.37000000","0.00000000"],["15508.76000000","0.00000000"],["15509.28000000","0.00000000"],["15509.39000000","0.00000000"],["15509.67000000","0.00000000"],["15510.15000000","0.01000000"],["15510.27000000","0.00000000"],["15510.54000000","0.01500000"],["15511.75000000","0.00000000"],["15513.39000000","0.01382400"]]}}
2020-11-09T11:26:20.93408 btcusdt {"stream":"btcusdt@depth@100ms","data":{"e":"depthUpdate","E":1604921180927,"s":"BTCUSDT","U":6511136697,"u":6511136727,"b":[["15502.27000000","0.00000000"],["15502.21000000","0.00818900"],["15501.87000000","0.00690000"],["15501.81000000","0.00000000"],["15501.75000000","0.00000000"],["15500.01000000","0.00000000"],["15498.95000000","0.05000000"],["15497.14000000","0.00000000"],["15496.70000000","0.06725200"],["15496.50000000","0.00000000"],["15495.88000000","1.25000000"],["15495.01000000","0.02106400"],["15494.76000000","0.13441900"],["15494.64000000","0.00000000"],["15494.61000000","0.00000000"],["15467.66000000","0.00000000"],["15465.89000000","0.01000000"],["15423.41000000","0.00000000"]],"a":[["15502.22000000","0.48125100"],["15502.25000000","0.00690000"],["15502.28000000","0.01864700"],["15504.21000000","0.20000000"],["15505.80000000","0.00000000"],["15509.71000000","0.15000000"],["15532.91000000","0.00000000"]]}}
2020-11-09T11:26:21.03554 btcusdt {"stream":"btcusdt@depth@100ms","data":{"e":"depthUpdate","E":1604921181027,"s":"BTCUSDT","U":6511136728,"u":6511136750,"b":[["15499.46000000","0.00000000"],["15499.00000000","1.06135500"],["15498.66000000","0.00000000"],["15495.88000000","0.00000000"],["15495.10000000","1.25000000"],["15484.59000000","0.14700000"]],"a":[["15502.22000000","0.29419200"],["15502.28000000","0.03668500"],["15502.70000000","0.00000000"],["15502.91000000","0.01681500"],["15504.20000000","0.30000000"],["15504.24000000","0.00128900"],["15506.68000000","0.00000000"],["15506.81000000","0.00000000"],["15507.13000000","0.00000000"],["15522.25000000","0.00000000"],["15523.10000000","0.00000000"]]}}
2020-11-09T11:26:21.13580 btcusdt {"stream":"btcusdt@depth@100ms","data":{"e":"depthUpdate","E":1604921181127,"s":"BTCUSDT","U":6511136751,"u":6511136765,"b":[["15499.26000000","0.00000000"],["15499.12000000","0.00000000"],["15497.93000000","0.00741800"],["15495.84000000","0.00000000"],["15495.74000000","1.50000000"],["15495.10000000","0.00000000"],["15495.01000000","0.00000000"],["15494.65000000","1.25000000"],["15441.79000000","0.00000000"],["15402.00000000","0.31026300"]],"a":[["15502.22000000","2.29099200"],["15510.58000000","0.25776000"],["15552.62000000","0.11232300"]]}}
2020-11-09T11:26:21.23742 btcusdt {"stream":"btcusdt@depth@100ms","data":{"e":"depthUpdate","E":1604921181227,"s":"BTCUSDT","U":6511136766,"u":6511136783,"b":[["15500.53000000","0.00000000"],["15495.01000000","0.02106400"],["15494.65000000","0.00000000"],["15494.48000000","1.25000000"],["15493.42000000","0.00000000"],["15490.32000000","0.30600000"],["15486.90000000","0.00000000"],["15456.54000000","0.00000000"]],"a":[["15502.22000000","2.36547900"],["15506.89000000","0.01000000"],["15507.86000000","0.00000000"],["15508.63000000","0.15450000"],["15519.30000000","1.08108900"],["15526.91000000","0.00000000"],["15536.99000000","0.00000000"]]}}
2020-11-09T11:26:21.33335 btcusdt {"stream":"btcusdt@depth@100ms","data":{"e":"depthUpdate","E":1604921181327,"s":"BTCUSDT","U":6511136784,"u":6511136801,"b":[["15499.00000000","1.04565900"],["15497.29000000","0.01618100"],["15495.01000000","0.00000000"],["15467.09000000","0.00000000"]],"a":[["15502.77000000","0.20000000"],["15502.99000000","0.01470900"],["15504.23000000","0.00000000"],["15505.79000000","0.00000000"],["15506.99000000","1.40200000"],["15507.81000000","0.20000000"],["15512.50000000","1.31811800"],["15514.62000000","0.00000000"],["15519.87000000","1.02300000"],["15521.27000000","0.00000000"],["15553.93000000","0.00000000"],["15562.14000000","0.19100000"],["15592.52000000","0.00000000"],["15603.00000000","0.11827300"]]}}
2020-11-09T11:26:21.44139 btcusdt {"stream":"btcusdt@depth@100ms","data":{"e":"depthUpdate","E":1604921181428,"s":"BTCUSDT","U":6511136802,"u":6511136825,"b":[["15502.21000000","0.00000000"],["15502.17000000","0.00000000"],["15501.87000000","0.00000000"],["15500.98000000","0.00000000"],["15500.84000000","0.07712500"],["15498.21000000","0.11427900"],["15424.69000000","0.00648300"]],"a":[["15500.99000000","0.20383900"],["15501.88000000","1.32537600"],["15502.09000000","0.10286300"],["15502.18000000","1.32537500"],["15502.22000000","2.20073800"],["15502.71000000","0.01681500"],["15502.91000000","0.00000000"],["15506.44000000","0.01700000"],["15506.87000000","0.00000000"],["15507.26000000","0.00000000"],["15507.50000000","0.00000000"],["15511.84000000","0.14700000"],["15550.91000000","0.00000000"]]}}
2020-11-09T11:26:21.53758 btcusdt {"stream":"btcusdt@depth@100ms","data":{"e":"depthUpdate","E":1604921181528,"s":"BTCUSDT","U":6511136826,"u":6511136876,"b":[["15500.88000000","4.51595200"],["15500.84000000","0.00000000"],["15500.22000000","0.07554300"],["15498.95000000","0.00000000"],["15498.22000000","0.05000000"],["15493.78000000","0.00000000"],["15483.52000000","0.15150000"],["15474.21000000","1.19600000"],["15463.80000000","0.03100000"],["15440.69000000","0.24000000"],["15408.00000000","0.43183000"],["15387.00000000","0.37683000"]],"a":[["15500.89000000","2.00000000"],["15500.98000000","0.10148300"],["15500.99000000","0.00000000"],["15501.59000000","0.00690000"],["15501.78000000","0.10936500"],["15501.79000000","0.10555100"],["15501.88000000","0.00000000"],["15502.05000000","0.11130500"],["15502.18000000","0.00000000"],["15502.22000000","2.00600000"],["15502.77000000","0.00000000"],["15504.19000000","0.20000000"],["15504.22000000","0.00000000"],["15504.26000000","0.00000000"],["15505.42000000","0.05690000"],["15505.49000000","0.03400000"],["15505.57000000","0.29700000"],["15506.44000000","0.00000000"],["15506.55000000","1.74800000"],["15506.70000000","1.20490000"],["15507.36000000","0.01000000"],["15508.21000000","0.00000000"],["15508.36000000","0.25780200"],["15510.15000000","0.00000000"],["15512.55000000","0.00000000"],["15515.38000000","0.05681900"],["15516.88000000","0.00000000"],["15519.01000000","0.00000000"],["15524.64000000","0.00000000"],["15550.61000000","0.03212300"]]}}
2020-11-09T11:26:21.63443 btcusdt {"stream":"btcusdt@depth@100ms","data":{"e":"depthUpdate","E":1604921181628,"s":"BTCUSDT","U":6511136877,"u":6511136896,"b":[["15500.88000000","11.65087400"],["15500.33000000","0.07400000"],["15500.22000000","0.00000000"]],"a":[["15500.89000000","0.04312600"],["15500.98000000","0.00000000"],["15501.78000000","0.00000000"],["15501.79000000","0.00000000"],["15502.05000000","0.00000000"],["15502.09000000","0.00000000"],["15502.78000000","0.00262500"],["15504.20000000","0.10000000"],["15505.18000000","0.20000000"],["15506.99000000","1.08000000"],["15507.81000000","0.00000000"],["15532.42000000","0.00000000"]]}}
2020-11-09T11:26:21.73738 btcusdt {"stream":"btcusdt@depth@100ms","data":{"e":"depthUpdate","E":1604921181728,"s":"BTCUSDT","U":6511136897,"u":6511136926,"b":[["15501.58000000","0.38968900"],["15501.23000000","0.00690000"],["15501.14000000","0.00000000"],["15501.13000000","0.07409700"],["15500.90000000","0.14118500"],["15500.88000000","7.47296900"],["15500.78000000","0.00000000"],["15500.64000000","0.00840000"],["15500.41000000","0.00000000"],["15500.33000000","0.00000000"],["15497.93000000","0.00000000"],["15497.29000000","0.00000000"]],"a":[["15500.89000000","0.00000000"],["15501.59000000","0.01060000"],["15502.68000000","0.00886700"],["15502.78000000","0.00200000"],["15503.92000000","0.00000000"],["15524.03000000","0.00000000"],["15561.00000000","0.64156100"]]}}
2020-11-09T11:26:21.90645 btcusdt {"stream":"btcusdt@depth@100ms","data":{"e":"depthUpdate","E":1604921181828,"s":"BTCUSDT","U":6511136927,"u":6511136949,"b":[["15500.88000000","2.20224300"],["15498.57000000","0.00000000"],["15497.29000000","0.03225100"],["15495.01000000","0.02106400"],["15492.64000000","0.00000000"],["15491.88000000","0.00000000"],["15489.37000000","1.50000000"],["15433.68000000","0.00000000"],["15424.57000000","0.53056100"]],"a":[["15501.59000000","0.01540000"],["15505.42000000","0.00690000"],["15506.54000000","0.06000000"],["15506.89000000","0.00000000"],["15507.36000000","0.00000000"],["15508.01000000","0.01000000"],["15517.62000000","0.00000000"],["15579.59000000","0.26317300"],["15588.80000000","0.00000000"]]}}
2020-11-09T11:26:21.94456 btcusdt {"stream":"btcusdt@depth@100ms","data":{"e":"depthUpdate","E":1604921181928,"s":"BTCUSDT","U":6511136950,"u":6511136967,"b":[["15501.58000000","0.14168900"],["15501.44000000","0.01379100"],["15500.88000000","2.00690000"],["15500.64000000","0.00000000"],["15498.61000000","0.00000000"],["15497.01000000","0.97000000"],["15424.69000000","0.00000000"],["15192.22000000","0.00000000"]],"a":[["15501.59000000","0.01220000"],["15502.99000000","0.00000000"],["15503.65000000","0.01857800"],["15507.89000000","0.00000000"],["15508.00000000","0.00000000"],["15508.02000000","0.00000000"],["15508.25000000","0.00750000"],["15517.37000000","0.00201000"]]}}
2020-11-09T11:26:22.03856 btcusdt {"stream":"btcusdt@depth@100ms","data":{"e":"depthUpdate","E":1604921182028,"s":"BTCUSDT","U":6511136968,"u":6511137008,"b":[["15501.58000000","0.00890000"],["15501.13000000","0.00000000"],["15500.90000000","0.00000000"],["15498.51000000","0.05000000"],["15498.22000000","0.00000000"],["15498.21000000","0.00000000"],["15495.01000000","0.00000000"],["15494.90000000","0.00000000"],["15492.54000000","0.13443500"],["15492.15000000","0.50000000"],["15486.37000000","0.00201000"],["15473.69000000","0.00289300"],["15472.92000000","0.00000000"]],"a":[["15501.59000000","5.41147200"],["15501.90000000","0.00690000"],["15502.21000000","0.15219400"],["15502.68000000","0.00000000"],["15503.51000000","0.00646300"],["15503.64000000","0.10000000"],["15504.18000000","0.08000000"],["15504.20000000","0.00000000"],["15504.21000000","0.00000000"],["15505.22000000","0.00000000"],["15506.59000000","0.15700000"],["15506.64000000","0.29200000"],["15507.44000000","0.03225500"],["15508.11000000","0.00000000"],["15509.59000000","0.00000000"],["15513.81000000","0.30000000"],["15514.41000000","0.13443500"],["15515.82000000","0.19335100"],["15516.56000000","0.00000000"],["15523.87000000","0.00000000"]]}}
2020-11-09T11:26:22.14079 btcusdt {"stream":"btcusdt@depth@100ms","data":{"e":"depthUpdate","E":1604921182128,"s":"BTCUSDT","U":6511137009,"u":6511137037,"b":[["15500.88000000","0.00690000"],["15500.36000000","0.00838700"],["15499.73000000","0.00000000"],["15499.03000000","0.00100000"],["15495.35000000","0.10000000"],["15494.51000000","0.04780600"],["15491.41000000","0.00000000"],["15484.74000000","0.12915900"]],"a":[["15501.59000000","7.40827200"],["15502.20000000","0.01637300"],["15502.21000000","0.00000000"],["15502.68000000","0.00980300"],["15502.71000000","0.00000000"],["15502.99000000","0.01232000"],["15503.51000000","0.00000000"],["15503.63000000","0.15219400"],["15503.65000000","0.00000000"],["15505.22000000","0.03225500"],["15506.04000000","0.25000000"],["15507.08000000","0.45002200"],["15507.44000000","0.00000000"],["15509.46000000","0.00000000"],["15510.80000000","0.00000000"],["15512.55000000","0.50000000"],["15515.13000000","1.59625500"],["15516.54000000","0.00000000"],["15517.56000000","0.00000000"],["15519.38000000","0.00000000"]]}}
2020-11-09T11:26:22.27253 btcusdt {"stream":"btcusdt@depth@100ms","data":{"e":"depthUpdate","E":1604921182228,"s":"BTCUSDT","U":6511137038,"u":6511137064,"b":[["15501.58000000","0.00000100"],["15496.70000000","0.00000000"],["15494.96000000","0.00000000"],["15494.52000000","1.25000000"],["15494.48000000","0.00000000"],["15494.16000000","0.00000000"],["15493.84000000","0.00000000"],["15493.49000000","0.03360900"],["15490.63000000","0.00200000"],["15488.54000000","0.06725600"],["15484.73000000","0.00000000"],["15452.27000000","0.00200000"],["15181.77000000","0.00658600"]],"a":[["15501.59000000","7.60827200"],["15505.18000000","0.00000000"],["15505.48000000","0.12903500"],["15506.12000000","1.19800000"],["15506.20000000","0.01000000"],["15506.54000000","0.05000000"],["15506.70000000","0.00690000"],["15507.32000000","0.20000000"],["15508.40000000","0.01500000"],["15510.54000000","0.00000000"],["15511.96000000","0.00000000"],["15513.79000000","0.00000000"],["15603.00000000","0.01000000"]]}}
2020-11-09T11:26:22.33531 btcusdt {"stream":"btcusdt@depth@100ms","data":{"e":"depthUpdate","E":1604921182328,"s":"BTCUSDT","U":6511137065,"u":6511137077,"b":[["15500.51000000","0.00000000"],["15498.50000000","0.00000000"],["15497.71000000","0.00000000"],["15497.11000000","0.00000000"],["15496.36000000","0.04000000"],["15495.02000000","0.08000000"],["15492.38000000","0.03360900"]],"a":[["15501.59000000","7.58851400"],["15502.04000000","0.01489700"],["15506.03000000","0.12903900"],["15506.35000000","0.32100000"],["15506.53000000","0.20000000"],["15550.02000000","0.00270700"]]}}
2020-11-09T11:26:22.43493 btcusdt {"stream":"btcusdt@depth@100ms","data":{"e":"depthUpdate","E":1604921182428,"s":"BTCUSDT","U":6511137078,"u":6511137093,"b":[["15501.44000000","0.00000000"],["15495.17000000","0.32694900"],["15491.58000000","0.10082500"],["15424.07000000","0.00648300"],["15387.00000000","0.48510300"]],"a":[["15501.59000000","7.72851400"],["15502.00000000","0.01489700"],["15502.03000000","0.15219400"],["15502.04000000","0.00000000"],["15502.20000000","0.00000000"],["15503.63000000","0.00000000"],["15513.27000000","0.01933800"],["15520.86000000","0.00000000"],["15533.52000000","0.00000000"],["15540.74000000","1.96061700"],["15550.02000000","0.00070700"]]}}
2020-11-09T11:26:22.53525 btcusdt {"stream":"btcusdt@depth@100ms","data":{"e":"depthUpdate","E":1604921182528,"s":"BTCUSDT","U":6511137094,"u":6511137103,"b":[["15501.58000000","0.03660400"],["15501.56000000","0.03660300"],["15501.54000000","0.03660400"],["15492.55000000","0.20000000"],["15411.00000000","0.71284400"]],"a":[["15501.59000000","7.73251400"],["15501.78000000","0.00200000"],["15514.89000000","0.05681900"],["15515.38000000","0.00000000"],["15516.54000000","0.24000000"]]}}
2020-11-09T11:26:22.63856 btcusdt {"stream":"btcusdt@depth@100ms","data":{"e":"depthUpdate","E":1604921182628,"s":"BTCUSDT","U":6511137104,"u":6511137117,"b":[["15501.58000000","0.00887500"],["15500.36000000","0.00000000"],["15495.36000000","0.06750700"],["15492.55000000","0.00000000"],["15485.88000000","0.00201000"]],"a":[["15501.59000000","7.73651400"],["15502.68000000","0.00000000"],["15504.19000000","0.00000000"],["15510.21000000","0.00000000"],["15511.44000000","0.00000000"],["15516.88000000","0.00201000"],["15528.20000000","0.16099700"],["15558.00000000","2.11115200"]]}}
2020-11-09T11:26:22.73767 btcusdt {"stream":"btcusdt@depth@100ms","data":{"e":"depthUpdate","E":1604921182728,"s":"BTCUSDT","U":6511137118,"u":6511137126,"b":[["15490.56000000","0.00000000"],["15408.00000000","0.05500000"],["13070.00000000","1.11104600"]],"a":[["15501.59000000","7.74051400"],["15501.99000000","0.20000000"],["15502.78000000","0.00000000"],["15504.84000000","0.11427900"],["15507.07000000","0.20000000"],["15511.05000000","0.19439600"]]}}
2020-11-09T11:26:22.83587 btcusdt {"stream":"btcusdt@depth@100ms","data":{"e":"depthUpdate","E":1604921182828,"s":"BTCUSDT","U":6511137127,"u":6511137137,"b":[["15490.54000000","0.54199700"],["15490.39000000","1.08973400"]],"a":[["15502.28000000","0.01864700"],["15502.99000000","0.00000000"],["15503.06000000","1.01695500"],["15505.51000000","1.74800000"],["15506.53000000","0.00000000"],["15506.55000000","0.00000000"],["15507.07000000","0.00000000"],["15508.42000000","0.00000000"],["15548.26000000","0.00000000"]]}}
2020-11-09T11:26:22.93762 btcusdt {"stream":"btcusdt@depth@100ms","data":{"e":"depthUpdate","E":1604921182928,"s":"BTCUSDT","U":6511137138,"u":6511137141,"b":[["15481.58000000","0.35997300"]],"a":[["15502.03000000","0.00000000"],["15503.05000000","0.15219400"],["15619.00000000","0.00000000"]]}}
2020-11-09T11:26:23.03437 btcusdt {"stream":"btcusdt@depth@100ms","data":{"e":"depthUpdate","E":1604921183028,"s":"BTCUSDT","U":6511137142,"u":6511137166,"b":[["15498.51000000","0.00000000"],["15497.30000000","0.05000000"],["15496.21000000","0.00000000"],["15494.59000000","0.00000000"],["15494.52000000","0.00000000"],["15493.75000000","0.00000000"],["15493.63000000","0.22500000"],["15493.39000000","0.00000000"],["15484.60000000","0.05000000"],["15472.39000000","0.00000000"],["15467.77000000","0.25000000"],["15463.74000000","0.25000000"]],"a":[["15501.59000000","7.62037200"],["15502.22000000","2.00200000"],["15503.33000000","0.22500100"],["15505.48000000","0.00000000"],["15506.07000000","0.05000000"],["15506.54000000","0.00000000"],["15506.98000000","0.20000000"],["15508.45000000","0.09630800"],["15532.35000000","0.25000000"],["15536.39000000","0.25000000"],["15549.80000000","0.01226700"]]}}
2020-11-09T11:26:23.13550 btcusdt {"stream":"btcusdt@depth@100ms","data":{"e":"depthUpdate","E":1604921183128,"s":"BTCUSDT","U":6511137167,"u":6511137179,"b":[["15497.02000000","0.25767100"],["15495.16000000","0.11189800"],["15494.45000000","1.25000000"],["15494.22000000","0.06722100"],["15493.28000000","0.00000000"],["15489.49000000","0.50463200"],["15489.13000000","1.16224800"],["15111.77000000","0.00496300"]],"a":[["15501.98000000","0.15219400"],["15502.22000000","2.00000000"],["15503.05000000","0.00000000"],["15506.87000000","0.20000000"],["15615.50000000","0.01100000"]]}}
2020-11-09T11:26:23.23524 btcusdt {"stream":"btcusdt@depth@100ms","data":{"e":"depthUpdate","E":1604921183228,"s":"BTCUSDT","U":6511137180,"u":6511137189,"b":[["15497.02000000","0.00000000"],["15496.48000000","0.11427900"],["15493.06000000","0.13449900"],["15491.68000000","0.30262300"],["15405.00000000","1.12806500"]],"a":[["15501.98000000","0.00000000"],["15503.05000000","0.15219400"],["15504.22000000","0.68000000"],["15506.02000000","0.12902600"],["15506.87000000","0.00000000"]]}}
2020-11-09T11:26:23.33610 btcusdt {"stream":"btcusdt@depth@100ms","data":{"e":"depthUpdate","E":1604921183328,"s":"BTCUSDT","U":6511137190,"u":6511137195,"b":[["15487.39000000","0.00000000"]],"a":[["15501.59000000","7.62437200"],["15506.02000000","0.50000000"],["15506.98000000","0.00000000"],["15600.00000000","211.57737500"]]}}
2020-11-09T11:26:23.43544 btcusdt {"stream":"btcusdt@depth@100ms","data":{"e":"depthUpdate","E":1604921183428,"s":"BTCUSDT","U":6511137196,"u":6511137196,"b":[["15405.00000000","1.01979200"]],"a":[]}}
2020-11-09T11:26:23.53783 btcusdt {"stream":"btcusdt@depth@100ms","data":{"e":"depthUpdate","E":1604921183528,"s":"BTCUSDT","U":6511137197,"u":6511137201,"b":[["15484.46000000","1.14989300"],["15402.00000000","0.68709300"]],"a":[["15512.39000000","0.05681900"],["15514.89000000","0.00000000"],["15516.54000000","0.48000000"]]}}
2020-11-09T11:26:23.63649 btcusdt {"stream":"btcusdt@depth@100ms","data":{"e":"depthUpdate","E":1604921183629,"s":"BTCUSDT","U":6511137202,"u":6511137203,"b":[["15497.65000000","0.01251900"]],"a":[["15502.36000000","0.01912500"]]}}
2020-11-09T11:26:23.74297 btcusdt {"stream":"btcusdt@depth@100ms","data":{"e":"depthUpdate","E":1604921183729,"s":"BTCUSDT","U":6511137204,"u":6511137207,"b":[["15497.22000000","0.00852800"]],"a":[["15501.59000000","7.62108700"],["15502.05000000","0.00811000"],["15558.00000000","2.48798200"]]}}
2020-11-09T11:26:23.83791 btcusdt {"stream":"btcusdt@depth@100ms","data":{"e":"depthUpdate","E":1604921183829,"s":"BTCUSDT","U":6511137208,"u":6511137212,"b":[["15501.58000000","0.00516400"]],"a":[["15501.59000000","2.59316500"],["15506.03000000","0.00000000"]]}}
2020-11-09T11:26:23.93566 btcusdt {"stream":"btcusdt@depth@100ms","data":{"e":"depthUpdate","E":1604921183929,"s":"BTCUSDT","U":6511137213,"u":6511137221,"b":[["15496.49000000","0.04780600"],["15494.51000000","0.00000000"]],"a":[["15502.05000000","0.00830800"],["15503.05000000","0.00000000"],["15503.64000000","0.00000000"],["15504.17000000","0.15219400"],["15505.18000000","0.10000000"],["15508.74000000","0.00000000"]]}}
2020-11-09T11:26:24.04007 btcusdt {"stream":"btcusdt@depth@100ms","data":{"e":"depthUpdate","E":1604921184029,"s":"BTCUSDT","U":6511137222,"u":6511137231,"b":[["15501.58000000","0.00318700"],["15497.66000000","0.05000000"],["15497.30000000","0.00000000"],["15492.36000000","0.00358300"],["15489.78000000","1.00000000"]],"a":[["15501.59000000","2.67646200"],["15503.32000000","0.08000000"],["15504.24000000","2.38128900"]]}}
2020-11-09T11:26:24.13876 btcusdt {"stream":"btcusdt@depth@100ms","data":{"e":"depthUpdate","E":1604921184129,"s":"BTCUSDT","U":6511137232,"u":6511137235,"b":[],"a":[["15502.05000000","0.00816900"],["15543.02000000","0.00000000"],["15600.00000000","211.46910200"]]}}
2020-11-09T11:26:24.24669 btcusdt {"stream":"btcusdt@depth@100ms","data":{"e":"depthUpdate","E":1604921184229,"s":"BTCUSDT","U":6511137236,"u":6511137243,"b":[["15501.54000000","0.00000000"],["15495.75000000","0.10840400"]],"a":[["15502.05000000","0.00976700"],["15503.05000000","0.15219400"],["15504.16000000","0.10000000"],["15504.17000000","0.00000000"],["15505.18000000","0.00000000"]]}}
2020-11-09T11:26:24.33720 btcusdt {"stream":"btcusdt@depth@100ms","data":{"e":"depthUpdate","E":1604921184329,"s":"BTCUSDT","U":6511137244,"u":6511137256,"b":[["15500.00000000","14.44015700"],["15496.49000000","0.00000000"],["15496.48000000","0.00000000"],["15495.18000000","0.04780600"],["15465.49000000","0.00000000"],["15381.00000000","0.10827300"]],"a":[["15501.59000000","2.65789600"],["15503.32000000","0.00000000"],["15503.33000000","0.00000000"],["15506.58000000","0.00000000"],["15515.13000000","0.09625500"]]}}
2020-11-09T11:26:24.43615 btcusdt {"stream":"btcusdt@depth@100ms","data":{"e":"depthUpdate","E":1604921184429,"s":"BTCUSDT","U":6511137257,"u":6511137265,"b":[["15498.44000000","0.50000000"],["15494.79000000","0.00000000"]],"a":[["15501.59000000","2.65989600"],["15503.05000000","0.00000000"],["15503.06000000","0.00000000"],["15504.15000000","0.15219400"],["15504.97000000","0.50000000"],["15513.39000000","0.00000000"],["15515.49000000","1.50000000"]]}}
2020-11-09T11:26:24.53604 btcusdt {"stream":"btcusdt@depth@100ms","data":{"e":"depthUpdate","E":1604921184529,"s":"BTCUSDT","U":6511137266,"u":6511137271,"b":[["15399.00000000","0.10827300"]],"a":[["15501.59000000","2.61989600"],["15502.05000000","0.00768500"],["15555.00000000","5.67637000"],["15650.00000000","84.26586100"]]}}
2020-11-09T11:26:24.63577 btcusdt {"stream":"btcusdt@depth@100ms","data":{"e":"depthUpdate","E":1604921184629,"s":"BTCUSDT","U":6511137272,"u":6511137274,"b":[["15492.63000000","0.01900000"]],"a":[["15502.05000000","0.00000000"],["15511.23000000","0.01382400"]]}}
2020-11-09T11:26:24.73719 btcusdt {"stream":"btcusdt@depth@100ms","data":{"e":"depthUpdate","E":1604921184729,"s":"BTCUSDT","U":6511137275,"u":6511137277,"b":[["15497.10000000","0.11427900"],["15495.01000000","0.02106400"],["15402.00000000","0.31026300"]],"a":[]}}
2020-11-09T11:26:24.84044 btcusdt {"stream":"btcusdt@depth@100ms","data":{"e":"depthUpdate","E":1604921184829,"s":"BTCUSDT","U":6511137278,"u":6511137283,"b":[["15496.37000000","0.04780600"],["15495.18000000","0.00000000"]],"a":[["15501.59000000","2.40745600"],["15504.14000000","0.20000000"],["15504.16000000","0.00000000"]]}}
2020-11-09T11:26:24.93612 btcusdt {"stream":"btcusdt@depth@100ms","data":{"e":"depthUpdate","E":1604921184929,"s":"BTCUSDT","U":6511137284,"u":6511137295,"b":[["15501.58000000","0.00318700"],["15500.87000000","0.00000000"]],"a":[["15501.59000000","2.26745600"],["15501.99000000","0.00000000"],["15502.00000000","0.00000000"],["15502.13000000","0.01437000"],["15504.13000000","0.20000000"],["15504.84000000","0.00000000"],["15505.18000000","0.10000000"],["15505.42000000","0.12117900"]]}}
2020-11-09T11:26:25.03603 btcusdt {"stream":"btcusdt@depth@100ms","data":{"e":"depthUpdate","E":1604921185029,"s":"BTCUSDT","U":6511137296,"u":6511137303,"b":[["15501.58000000","5.30318700"],["15500.87000000","0.07855700"],["15497.65000000","0.00000000"],["15497.22000000","0.00000000"],["15496.88000000","0.01564400"],["15486.91000000","0.00000000"]],"a":[["15501.59000000","2.26132000"],["15502.13000000","0.00000000"]]}}
2020-11-09T11:26:25.13605 btcusdt {"stream":"btcusdt@depth@100ms","data":{"e":"depthUpdate","E":1604921185129,"s":"BTCUSDT","U":6511137304,"u":6511137314,"b":[["15490.55000000","0.02236400"],["15490.45000000","0.50460800"],["15490.09000000","1.01121600"],["15489.49000000","0.00000000"],["15489.13000000","0.15300000"],["15462.83000000","0.25000000"]],"a":[["15501.59000000","0.35519700"],["15506.04000000","0.00000000"],["15507.79000000","0.75000000"],["15540.34000000","0.25000000"]]}}
2020-11-09T11:26:25.23555 btcusdt {"stream":"btcusdt@depth@100ms","data":{"e":"depthUpdate","E":1604921185229,"s":"BTCUSDT","U":6511137315,"u":6511137328,"b":[["15501.58000000","5.47472900"],["15500.97000000","0.07806500"],["15500.87000000","0.00000000"],["15497.90000000","0.11427900"],["15497.10000000","0.00000000"],["15492.34000000","1.00000000"],["15489.78000000","0.00000000"],["15482.81000000","2.53814500"],["15436.80000000","4.50372300"],["15402.00000000","0.20199000"],["15399.00000000","0.48510300"]],"a":[["15501.59000000","0.16344800"],["15525.00000000","0.00000000"]]}}
2020-11-09T11:26:25.33678 btcusdt {"stream":"btcusdt@depth@100ms","data":{"e":"depthUpdate","E":1604921185329,"s":"BTCUSDT","U":6511137329,"u":6511137334,"b":[["15501.58000000","0.17398100"],["15496.88000000","0.00000000"],["15496.73000000","0.01948600"]],"a":[["15506.35000000","0.00000000"],["15506.93000000","0.32100000"]]}}
2020-11-09T11:26:25.43629 btcusdt {"stream":"btcusdt@depth@100ms","data":{"e":"depthUpdate","E":1604921185429,"s":"BTCUSDT","U":6511137335,"u":6511137346,"b":[["15501.58000000","0.00243900"],["15500.97000000","0.00000000"],["15496.40000000","0.00810400"],["15491.22000000","0.00200000"],["15453.16000000","0.00200000"]],"a":[["15501.59000000","0.16565900"],["15502.05000000","0.00628100"],["15502.24000000","0.01437000"],["15511.00000000","0.03610500"]]}}
2020-11-09T11:26:25.53650 btcusdt {"stream":"btcusdt@depth@100ms","data":{"e":"depthUpdate","E":1604921185529,"s":"BTCUSDT","U":6511137347,"u":6511137360,"b":[["15501.58000000","0.00000000"],["15497.90000000","0.00000000"],["15493.64000000","0.20000000"],["15453.16000000","0.00400000"]],"a":[["15501.57000000","1.52239200"],["15502.05000000","0.00000000"],["15502.21000000","1.02952300"],["15502.22000000","2.01437000"],["15502.24000000","0.00000000"],["15504.12000000","2.85634200"],["15504.77000000","0.11427900"],["15505.42000000","0.00690000"]]}}
2020-11-09T11:26:25.63821 btcusdt {"stream":"btcusdt@depth@100ms","data":{"e":"depthUpdate","E":1604921185629,"s":"BTCUSDT","U":6511137361,"u":6511137376,"b":[["15501.56000000","3.53532500"],["15500.85000000","0.07489100"],["15497.48000000","0.11427900"],["15493.64000000","0.00000000"],["15450.56000000","0.00200000"]],"a":[["15501.57000000","3.53534100"],["15502.11000000","0.00000000"],["15502.20000000","0.20000000"],["15502.21000000","0.00000000"],["15502.22000000","2.00000000"],["15504.13000000","0.00000000"],["15506.93000000","0.00000000"]]}}
2020-11-09T11:26:25.73887 btcusdt {"stream":"btcusdt@depth@100ms","data":{"e":"depthUpdate","E":1604921185730,"s":"BTCUSDT","U":6511137377,"u":6511137383,"b":[["15501.56000000","0.03532500"],["15500.85000000","0.00000000"],["15494.76000000","0.00000000"],["15493.49000000","0.00000000"],["15492.54000000","0.00000000"]],"a":[["15502.11000000","0.01437000"],["15530.87000000","0.00000000"]]}}
2020-11-09T11:26:25.84043 btcusdt {"stream":"btcusdt@depth@100ms","data":{"e":"depthUpdate","E":1604921185830,"s":"BTCUSDT","U":6511137384,"u":6511137394,"b":[["15501.56000000","0.03532500"],["15500.85000000","0.07891100"],["15491.78000000","0.13444600"],["15491.51000000","0.03361200"],["15489.56000000","0.13444900"]],"a":[["15501.57000000","3.52723300"],["15502.11000000","0.00000000"],["15505.12000000","0.31800000"]]}}
2020-11-09T11:26:25.93870 btcusdt {"stream":"btcusdt@depth@100ms","data":{"e":"depthUpdate","E":1604921185930,"s":"BTCUSDT","U":6511137395,"u":6511137402,"b":[["15500.85000000","0.00000000"],["15496.40000000","0.00000000"],["15459.25000000","0.00000000"],["15424.07000000","0.00000000"],["15384.00000000","0.16327300"],["15000.00000000","213.63199000"]],"a":[["15501.58000000","0.00095900"],["15502.11000000","0.01437000"]]}}
2020-11-09T11:26:26.03783 btcusdt {"stream":"btcusdt@depth@100ms","data":{"e":"depthUpdate","E":1604921186030,"s":"BTCUSDT","U":6511137403,"u":6511137412,"b":[["15497.66000000","0.00000000"],["15497.53000000","0.01203400"],["15497.49000000","0.05000000"],["15496.73000000","0.00000000"],["15467.77000000","0.50000000"],["15463.74000000","0.50000000"]],"a":[["15502.34000000","0.01340000"],["15502.36000000","0.00000000"],["15506.58000000","0.00000000"]]}}
2020-11-09T11:26:26.13675 btcusdt {"stream":"btcusdt@depth@100ms","data":{"e":"depthUpdate","E":1604921186130,"s":"BTCUSDT","U":6511137413,"u":6511137419,"b":[["15501.56000000","3.68532500"],["15500.85000000","0.07261600"]],"a":[["15501.57000000","3.46697400"],["15502.11000000","0.00000000"],["15502.20000000","0.00000000"],["15504.11000000","0.10000000"],["15505.18000000","0.00000000"]]}}
2020-11-09T11:26:26.23692 btcusdt {"stream":"btcusdt@depth@100ms","data":{"e":"depthUpdate","E":1604921186230,"s":"BTCUSDT","U":6511137420,"u":6511137428,"b":[["15501.56000000","3.84598000"],["15493.63000000","0.00000000"],["15464.50000000","0.00000000"],["15452.41000000","0.03020000"]],"a":[["15501.57000000","3.46309800"],["15501.59000000","0.14762100"],["15504.11000000","0.30000000"]]}}
2020-11-09T11:26:26.33754 btcusdt {"stream":"btcusdt@depth@100ms","data":{"e":"depthUpdate","E":1604921186330,"s":"BTCUSDT","U":6511137429,"u":6511137435,"b":[["15501.56000000","0.19598000"],["15495.01000000","0.00000000"]],"a":[["15501.57000000","3.06409800"],["15504.12000000","0.00000000"],["15504.18000000","0.00000000"],["15505.51000000","0.00000000"],["15506.18000000","1.74800000"]]}}
2020-11-09T11:26:26.43715 btcusdt {"stream":"btcusdt@depth@100ms","data":{"e":"depthUpdate","E":1604921186430,"s":"BTCUSDT","U":6511137436,"u":6511137471,"b":[["15501.56000000","0.00000000"],["15501.23000000","0.00000000"],["15501.22000000","0.00690000"],["15500.88000000","0.00530000"],["15500.85000000","0.00000000"],["15500.11000000","0.07233300"],["15499.04000000","0.00000000"],["15497.75000000","0.01735100"],["15497.53000000","0.00000000"],["15497.48000000","0.00000000"],["15497.35000000","0.00815600"],["15496.39000000","0.11427900"],["15496.37000000","0.00000000"],["15495.37000000","0.02106400"],["15462.00000000","2.00000000"],["15424.05000000","0.00648300"]],"a":[["15501.23000000","0.00690000"],["15501.24000000","1.53204900"],["15501.57000000","2.50240200"],["15501.98000000","0.01437000"],["15502.03000000","0.00886100"],["15502.11000000","0.00000000"],["15504.11000000","0.40000000"],["15504.14000000","0.00000000"],["15504.15000000","0.00000000"],["15505.11000000","0.10000000"],["15505.34000000","1.74800000"],["15506.18000000","0.00000000"],["15506.19000000","0.87160100"],["15516.54000000","0.24000000"],["15520.74000000","0.00000000"]]}}
2020-11-09T11:26:26.53766 btcusdt {"stream":"btcusdt@depth@100ms","data":{"e":"depthUpdate","E":1604921186530,"s":"BTCUSDT","U":6511137472,"u":6511137563,"b":[["15501.22000000","0.00000000"],["15500.88000000","0.00000000"],["15500.80000000","0.00000000"],["15500.68000000","0.00483300"],["15500.61000000","4.15690000"],["15500.50000000","0.00000000"],["15500.11000000","0.00000000"],["15500.00000000","14.21038100"],["15499.90000000","0.00000000"],["15499.49000000","0.06508600"],["15499.34000000","0.00000000"],["15497.49000000","0.00000000"],["15497.30000000","0.05000000"],["15496.38000000","0.00000000"],["15495.18000000","0.04780600"],["15494.83000000","0.00000000"],["15492.34000000","0.00000000"],["15492.09000000","0.00000000"],["15489.75000000","1.00000000"],["15483.06000000","0.00000000"],["15438.58000000","0.00000000"],["15431.18000000","0.96770300"]],"a":[["15500.51000000","0.00000000"],["15500.62000000","0.00000000"],["15500.81000000","0.00000000"],["15500.89000000","0.00000000"],["15501.18000000","0.00000000"],["15501.19000000","0.02627800"],["15501.20000000","0.00000000"],["15501.21000000","0.03625000"],["15501.22000000","0.00000000"],["15501.23000000","2.00690000"],["15501.24000000","0.01730500"],["15501.57000000","2.01777200"],["15501.77000000","0.00000000"],["15501.83000000","0.00000000"],["15501.98000000","0.00000000"],["15502.21000000","0.00000000"],["15504.02000000","0.11427900"],["15504.10000000","0.08000000"],["15504.25000000","0.01920100"],["15504.72000000","0.01700000"],["15504.73000000","0.01700000"],["15504.77000000","0.00000000"],["15505.48000000","0.15219400"],["15505.49000000","0.00000000"],["15505.71000000","0.05000000"],["15505.84000000","0.01000000"],["15505.99000000","0.32200000"],["15506.07000000","0.00000000"],["15506.20000000","0.00000000"],["15507.50000000","0.30900000"],["15507.65000000","0.01000000"],["15508.01000000","0.00000000"],["15508.04000000","0.01500000"],["15508.40000000","0.00000000"],["15521.29000000","0.00000000"],["15570.37000000","0.71030700"],["15577.84000000","0.00000000"]]}}
2020-11-09T11:26:26.63679 btcusdt {"stream":"btcusdt@depth@100ms","data":{"e":"depthUpdate","E":1604921186630,"s":"BTCUSDT","U":6511137564,"u":6511137587,"b":[["15501.12000000","0.01010000"],["15500.01000000","0.06508600"],["15499.49000000","0.00000000"],["15497.75000000","0.00000000"],["15497.35000000","0.00000000"],["15496.93000000","0.01448100"],["15495.75000000","0.00000000"],["15492.85000000","0.02500000"],["15492.21000000","0.30000000"],["15405.00000000","1.39662200"]],"a":[["15501.13000000","0.02852800"],["15501.18000000","0.03053700"],["15501.21000000","0.00000000"],["15501.87000000","0.03625000"],["15504.01000000","0.25219400"],["15504.10000000","0.00000000"],["15505.11000000","0.00000000"],["15505.37000000","0.00343500"],["15505.48000000","0.00000000"],["15515.49000000","0.00000000"],["15517.64000000","0.02500000"],["15555.00000000","5.56809700"]]}}
2020-11-09T11:26:26.73664 btcusdt {"stream":"btcusdt@depth@100ms","data":{"e":"depthUpdate","E":1604921186730,"s":"BTCUSDT","U":6511137588,"u":6511137594,"b":[["15500.61000000","0.00690000"],["15484.00000000","0.00078500"],["15481.15000000","0.23533500"]],"a":[["15501.13000000","0.02771000"],["15501.59000000","0.14562100"],["15516.98000000","1.50000000"],["16285.86000000","0.06003900"]]}}
2020-11-09T11:26:26.83699 btcusdt {"stream":"btcusdt@depth@100ms","data":{"e":"depthUpdate","E":1604921186830,"s":"BTCUSDT","U":6511137595,"u":6511137600,"b":[],"a":[["15501.13000000","0.02287200"],["15501.60000000","0.03625000"],["15501.87000000","0.00000000"],["15504.02000000","0.00000000"],["15506.02000000","0.00000000"],["15516.98000000","0.00000000"]]}}
2020-11-09T11:26:26.94042 btcusdt {"stream":"btcusdt@depth@100ms","data":{"e":"depthUpdate","E":1604921186930,"s":"BTCUSDT","U":6511137601,"u":6511137612,"b":[["15501.15000000","0.00690000"],["15491.68000000","0.00000000"],["15489.27000000","0.30094400"],["15424.05000000","0.00000000"]],"a":[["15501.13000000","0.00000000"],["15501.16000000","4.85690000"],["15501.18000000","0.01271800"],["15501.19000000","0.01959500"],["15502.21000000","0.20000000"],["15504.11000000","0.20000000"],["15504.62000000","0.11427900"],["15505.98000000","0.50000000"]]}}
2020-11-09T11:26:27.03776 btcusdt {"stream":"btcusdt@depth@100ms","data":{"e":"depthUpdate","E":1604921187030,"s":"BTCUSDT","U":6511137613,"u":6511137625,"b":[["15497.30000000","0.00000000"],["15496.94000000","0.05000000"],["15496.93000000","0.00000000"]],"a":[["15501.16000000","6.87473400"],["15502.03000000","0.00000000"],["15502.22000000","0.00000000"],["15504.10000000","0.08000000"],["15504.72000000","0.00000000"],["15504.73000000","0.00000000"],["15505.39000000","0.03400000"],["15515.79000000","1.50000000"]]}}
2020-11-09T11:26:27.13683 btcusdt {"stream":"btcusdt@depth@100ms","data":{"e":"depthUpdate","E":1604921187130,"s":"BTCUSDT","U":6511137626,"u":6511137661,"b":[["15501.15000000","0.00000000"],["15501.12000000","0.00000000"],["15500.01000000","0.00000000"],["15496.39000000","0.00000000"],["15495.84000000","0.11427900"],["15492.58000000","0.22500000"]],"a":[["15500.69000000","7.28991200"],["15501.07000000","0.03062400"],["15501.10000000","0.02941900"],["15501.12000000","0.97383500"],["15501.13000000","0.00000000"],["15501.15000000","5.30690000"],["15501.16000000","2.02473400"],["15501.18000000","0.00000000"],["15501.24000000","0.00000000"],["15501.57000000","2.00000000"],["15501.59000000","0.13021100"],["15501.60000000","0.00000000"],["15502.21000000","0.00000000"],["15502.28000000","0.24364800"],["15504.00000000","0.20000000"],["15504.97000000","0.00000000"],["15507.47000000","0.00000000"],["15507.85000000","0.00000000"]]}}
2020-11-09T11:26:27.23681 btcusdt {"stream":"btcusdt@depth@100ms","data":{"e":"depthUpdate","E":1604921187230,"s":"BTCUSDT","U":6511137662,"u":6511137689,"b":[["15500.68000000","0.01173300"],["15496.94000000","0.00000000"],["15496.37000000","0.05000000"],["15495.18000000","0.00000000"],["15494.12000000","0.04780600"],["14800.00000000","92.79310900"]],"a":[["15500.69000000","7.72713200"],["15501.07000000","0.00000000"],["15501.10000000","0.00000000"],["15501.12000000","0.00000000"],["15501.16000000","2.00690000"],["15501.19000000","0.00000000"],["15501.31000000","0.03625000"],["15501.57000000","0.00000000"],["15501.59000000","0.12432600"],["15505.16000000","0.05000000"],["15505.29000000","0.01000000"],["15505.71000000","0.00000000"],["15505.84000000","0.00000000"],["15505.99000000","0.00000000"],["15507.09000000","0.01000000"],["15507.65000000","0.00000000"]]}}
2020-11-09T11:26:27.33987 btcusdt {"stream":"btcusdt@depth@100ms","data":{"e":"depthUpdate","E":1604921187330,"s":"BTCUSDT","U":6511137690,"u":6511137695,"b":[],"a":[["15500.69000000","2.71384600"],["15501.59000000","0.00000000"],["15511.00000000","0.00000000"],["15519.30000000","0.00000000"]]}}
2020-11-09T11:26:27.43953 btcusdt {"stream":"btcusdt@depth@100ms","data":{"e":"depthUpdate","E":1604921187430,"s":"BTCUSDT","U":6511137696,"u":6511137704,"b":[["15423.17000000","0.00648300"],["15381.00000000","0.00000000"]],"a":[["15500.69000000","2.70719700"],["15501.15000000","5.33178600"],["15505.39000000","0.00000000"],["15506.58000000","0.20000000"],["15516.45000000","1.02301900"],["15558.00000000","2.11115200"]]}}
2020-11-09T11:26:27.53988 btcusdt {"stream":"btcusdt@depth@100ms","data":{"e":"depthUpdate","E":1604921187530,"s":"BTCUSDT","U":6511137705,"u":6511137709,"b":[],"a":[["15500.69000000","2.31484600"],["15500.89000000","0.00174100"],["15501.15000000","0.03178600"],["15504.64000000","0.03400000"]]}}
2020-11-09T11:26:27.64426 btcusdt {"stream":"btcusdt@depth@100ms","data":{"e":"depthUpdate","E":1604921187630,"s":"BTCUSDT","U":6511137710,"u":6511137713,"b":[["15492.39000000","0.20000000"],["15402.00000000","0.31026300"]],"a":[["15515.72000000","1.50000000"],["15515.79000000","0.00000000"]]}}
2020-11-09T11:26:27.73906 btcusdt {"stream":"btcusdt@depth@100ms","data":{"e":"depthUpdate","E":1604921187730,"s":"BTCUSDT","U":6511137714,"u":6511137732,"b":[["15500.68000000","0.01373300"],["15497.73000000","0.01438900"],["15497.30000000","0.00725400"],["15495.37000000","0.00000000"],["15494.45000000","0.00000000"],["15494.22000000","0.00000000"],["15493.27000000","1.25000000"],["15491.78000000","0.00000000"],["12400.00000000","25.89911800"]],"a":[["15500.69000000","2.27254900"],["15501.82000000","0.00669200"],["15501.96000000","0.01543800"],["15502.28000000","0.01864700"],["15502.34000000","0.00000000"],["15506.18000000","0.20000000"],["15506.58000000","0.00000000"],["15508.66000000","1.25000000"],["15510.90000000","0.00000000"]]}}
2020-11-09T11:26:27.83793 btcusdt {"stream":"btcusdt@depth@100ms","data":{"e":"depthUpdate","E":1604921187831,"s":"BTCUSDT","U":6511137733,"u":6511137766,"b":[["15500.68000000","0.00000000"],["15500.61000000","0.00000000"],["15500.00000000","14.06554200"],["15499.43000000","0.06666700"],["15496.57000000","0.11427900"],["15495.84000000","0.00000000"],["15493.27000000","0.00000000"],["15493.04000000","1.25000000"],["15491.24000000","0.06722700"],["15489.79000000","0.13445500"],["15423.17000000","0.00000000"]],"a":[["15500.01000000","0.67165000"],["15500.35000000","0.00690000"],["15500.62000000","0.70212300"],["15500.69000000","2.27254900"],["15501.10000000","0.06983700"],["15502.28000000","0.00000000"],["15505.42000000","1.20490000"],["15506.12000000","0.00000000"],["15508.66000000","1.25000000"],["15533.04000000","0.25806400"],["15537.69000000","0.00000000"],["15540.80000000","0.00000000"],["15600.00000000","211.57737500"]]}}
2020-11-09T11:26:27.94205 btcusdt {"stream":"btcusdt@depth@100ms","data":{"e":"depthUpdate","E":1604921187931,"s":"BTCUSDT","U":6511137767,"u":6511137797,"b":[["15500.00000000","14.22140800"],["15497.73000000","0.00000000"],["15496.58000000","0.05000000"],["15496.37000000","0.00000000"],["15494.50000000","0.00000000"],["15492.69000000","0.12902200"],["15491.51000000","0.00000000"],["15489.56000000","0.00000000"],["15440.69000000","0.00000000"]],"a":[["15500.01000000","2.66845000"],["15500.62000000","0.00000000"],["15500.68000000","0.20000000"],["15500.69000000","2.11383500"],["15501.23000000","0.00690000"],["15501.96000000","0.00000000"],["15504.00000000","0.00000000"],["15504.49000000","0.05000000"],["15504.62000000","0.12427900"],["15504.82000000","0.32200000"],["15505.16000000","0.00000000"],["15505.29000000","0.00000000"],["15506.42000000","0.01000000"],["15506.82000000","0.01500000"],["15506.99000000","2.33000000"],["15507.09000000","0.00000000"],["15508.04000000","0.00000000"],["15508.66000000","0.00000000"],["15515.72000000","0.00000000"],["15531.39000000","0.09907300"]]}}
2020-11-09T11:26:28.04017 btcusdt {"stream":"btcusdt@depth@100ms","data":{"e":"depthUpdate","E":1604921188031,"s":"BTCUSDT","U":6511137798,"u":6511137816,"b":[["15497.30000000","0.00000000"],["15497.05000000","0.01771300"],["15496.32000000","0.00640400"],["15489.52000000","0.23361500"],["15487.57000000","0.13446000"],["15460.06000000","0.00000000"]],"a":[["15500.01000000","2.41525000"],["15500.68000000","0.00000000"],["15501.62000000","0.00787300"],["15501.82000000","0.00000000"],["15501.93000000","0.01608100"],["15504.00000000","0.20000000"],["15506.99000000","1.08000000"],["15508.03000000","1.25000000"],["15515.58000000","0.00000000"],["15528.85000000","1.19584800"],["15553.44000000","0.00000000"]]}}
2020-11-09T11:26:28.13859 btcusdt {"stream":"btcusdt@depth@100ms","data":{"e":"depthUpdate","E":1604921188131,"s":"BTCUSDT","U":6511137817,"u":6511137827,"b":[["15500.00000000","13.57740800"],["15492.39000000","0.00000000"],["15402.00000000","0.68709300"]],"a":[["15500.01000000","2.49153200"],["15500.88000000","0.00200000"],["15501.10000000","0.00000000"],["15515.55000000","1.50000000"],["15537.97000000","2.00000000"],["15554.23000000","0.00000000"],["15563.68000000","0.38997200"],["15579.19000000","0.00000000"]]}}
2020-11-09T11:26:28.24054 btcusdt {"stream":"btcusdt@depth@100ms","data":{"e":"depthUpdate","E":1604921188231,"s":"BTCUSDT","U":6511137828,"u":6511137835,"b":[["15500.00000000","13.42112500"],["15497.05000000","0.00000000"],["15496.47000000","0.01700400"],["15460.16000000","0.00000000"]],"a":[["15500.01000000","2.64539800"],["15504.81000000","0.16130300"],["15558.49000000","0.00000000"]]}}
2020-11-09T11:26:28.33724 btcusdt {"stream":"btcusdt@depth@100ms","data":{"e":"depthUpdate","E":1604921188331,"s":"BTCUSDT","U":6511137836,"u":6511137837,"b":[],"a":[["15516.54000000","0.00000000"],["15600.00000000","211.95420500"]]}}
2020-11-09T11:26:28.44549 btcusdt {"stream":"btcusdt@depth@100ms","data":{"e":"depthUpdate","E":1604921188431,"s":"BTCUSDT","U":6511137838,"u":6511137848,"b":[["15500.00000000","12.85112500"],["15492.88000000","0.00000000"],["15422.50000000","0.00648400"]],"a":[["15500.01000000","2.25879800"],["15500.78000000","0.01638600"],["15501.93000000","0.00000000"],["15506.18000000","0.00000000"],["15515.55000000","0.00000000"]]}}
2020-11-09T11:26:28.53899 btcusdt {"stream":"btcusdt@depth@100ms","data":{"e":"depthUpdate","E":1604921188531,"s":"BTCUSDT","U":6511137849,"u":6511137855,"b":[["15496.32000000","0.00000000"],["15496.00000000","0.01389900"],["15453.58000000","0.01035300"]],"a":[["15500.59000000","0.00761300"],["15501.62000000","0.00000000"],["15515.58000000","1.50000000"],["15517.55000000","0.24000000"]]}}
2020-11-09T11:26:28.63860 btcusdt {"stream":"btcusdt@depth@100ms","data":{"e":"depthUpdate","E":1604921188631,"s":"BTCUSDT","U":6511137856,"u":6511137865,"b":[["15500.00000000","13.85112500"],["15492.39000000","0.20000000"],["15453.69000000","0.01035300"],["15442.13000000","0.24000000"]],"a":[["15500.01000000","2.20260300"],["15515.58000000","0.00000000"],["15612.88000000","0.00000000"]]}}
2020-11-09T11:26:28.73861 btcusdt {"stream":"btcusdt@depth@100ms","data":{"e":"depthUpdate","E":1604921188731,"s":"BTCUSDT","U":6511137866,"u":6511137882,"b":[["15500.00000000","13.94803500"],["15496.47000000","0.00000000"],["15496.15000000","0.01226100"],["15496.00000000","0.00452100"],["15492.63000000","0.04006400"]],"a":[["15500.01000000","0.22053800"],["15500.58000000","1.06072400"],["15500.59000000","0.00000000"],["15503.99000000","0.36609800"],["15504.81000000","0.00000000"],["15508.03000000","0.00000000"],["15508.88000000","1.25000000"],["15515.77000000","0.00000000"]]}}
2020-11-09T11:26:28.83924 btcusdt {"stream":"btcusdt@depth@100ms","data":{"e":"depthUpdate","E":1604921188831,"s":"BTCUSDT","U":6511137883,"u":6511137902,"b":[["15500.00000000","14.10190100"],["15495.49000000","0.12902200"],["15492.69000000","0.00000000"]],"a":[["15500.01000000","0.02998400"],["15500.35000000","0.00000000"],["15500.58000000","0.00000000"],["15501.25000000","0.03466900"],["15501.31000000","0.00000000"],["15503.99000000","0.00000000"],["15504.01000000","0.15219400"],["15504.11000000","0.00000000"],["15504.62000000","0.01000000"],["15505.97000000","0.10000000"],["15506.41000000","0.20000000"],["15508.88000000","0.00000000"],["15509.69000000","1.25000000"],["15515.34000000","1.50000000"],["15528.52000000","0.00690000"]]}}
2020-11-09T11:26:28.93831 btcusdt {"stream":"btcusdt@depth@100ms","data":{"e":"depthUpdate","E":1604921188931,"s":"BTCUSDT","U":6511137903,"u":6511137920,"b":[["15500.00000000","20.70190100"],["15497.30000000","0.04780600"],["15494.12000000","0.00000000"],["15493.04000000","0.00000000"]],"a":[["15500.01000000","0.02988500"],["15500.58000000","0.00502000"],["15500.69000000","0.14603800"],["15504.01000000","0.00000000"],["15504.82000000","0.00000000"],["15505.11000000","0.15219400"],["15505.40000000","0.32100000"],["15506.41000000","0.00000000"],["15509.69000000","0.00000000"],["15509.99000000","1.25000000"],["15511.04000000","0.03359800"],["15515.34000000","0.00000000"]]}}
2020-11-09T11:26:29.03948 btcusdt {"stream":"btcusdt@depth@100ms","data":{"e":"depthUpdate","E":1604921189031,"s":"BTCUSDT","U":6511137921,"u":6511137980,"b":[["15500.68000000","7.23357300"],["15500.58000000","0.08627200"],["15500.57000000","0.07001900"],["15500.29000000","0.00690000"],["15500.02000000","0.00000000"],["15500.00000000","14.98771100"],["15499.81000000","0.00200000"],["15499.80000000","0.06666700"],["15499.51000000","0.00000000"],["15499.45000000","0.00000000"],["15499.43000000","0.00000000"],["15498.44000000","0.00000000"],["15496.58000000","0.00000000"],["15496.57000000","0.00000000"],["15496.49000000","1.25000000"],["15496.37000000","0.05000000"],["15496.16000000","0.02106400"],["15492.63000000","0.01900000"],["15441.53000000","0.00200000"]],"a":[["15500.01000000","0.00000000"],["15500.58000000","0.00000000"],["15500.69000000","0.15293800"],["15501.15000000","0.00690000"],["15501.25000000","0.00000000"],["15504.00000000","0.00000000"],["15504.49000000","0.00000000"],["15504.63000000","0.05000000"],["15505.10000000","0.20000000"],["15505.11000000","0.00000000"],["15505.97000000","0.00000000"],["15506.58000000","0.00000000"],["15509.99000000","0.00000000"],["15510.88000000","0.00000000"],["15510.89000000","1.54700000"]]}}
2020-11-09T11:26:29.13891 btcusdt {"stream":"btcusdt@depth@100ms","data":{"e":"depthUpdate","E":1604921189131,"s":"BTCUSDT","U":6511137981,"u":6511138003,"b":[["15500.68000000","9.40406300"],["15500.00000000","14.83384500"],["15445.79000000","0.00200000"]],"a":[["15501.16000000","0.00690000"],["15504.25000000","0.00000000"],["15504.62000000","0.00000000"],["15504.63000000","0.00000000"],["15505.10000000","0.00000000"],["15505.19000000","0.13000000"],["15505.30000000","0.01000000"],["15505.40000000","0.00000000"],["15506.41000000","0.20000000"],["15506.42000000","0.00000000"],["15506.81000000","0.15219400"],["15506.82000000","0.00000000"],["15507.08000000","0.32100000"],["15507.10000000","0.01000000"],["15507.50000000","0.32400000"],["15509.39000000","0.12902200"],["15517.55000000","0.00000000"]]}}
2020-11-09T11:26:29.23938 btcusdt {"stream":"btcusdt@depth@100ms","data":{"e":"depthUpdate","E":1604921189231,"s":"BTCUSDT","U":6511138004,"u":6511138018,"b":[["15500.09000000","0.06666700"],["15499.80000000","0.00000000"],["15497.71000000","0.04780600"],["15497.30000000","0.00000000"],["15495.75000000","0.00782900"],["15493.90000000","1.00000000"],["15489.75000000","0.00000000"]],"a":[["15506.19000000","0.00000000"],["15506.41000000","0.20000000"],["15506.98000000","0.10000000"],["15508.45000000","0.00000000"],["15515.87000000","0.00000000"],["15519.64000000","0.24000000"]]}}
2020-11-09T11:26:29.34158 btcusdt {"stream":"btcusdt@depth@100ms","data":{"e":"depthUpdate","E":1604921189331,"s":"BTCUSDT","U":6511138019,"u":6511138042,"b":[["15500.68000000","8.81466000"],["15500.56000000","0.00000000"],["15500.09000000","0.00000000"],["15497.01000000","0.00000000"],["15496.36000000","0.00000000"],["15495.02000000","0.00000000"],["15491.24000000","0.00000000"],["15489.79000000","0.00000000"],["15426.14000000","0.00302000"]],"a":[["15500.69000000","0.02493800"],["15505.57000000","0.00000000"],["15505.86000000","0.00000000"],["15512.24000000","0.13445300"],["15515.83000000","0.00000000"],["15515.90000000","1.50000000"],["15515.92000000","0.00000000"],["15521.45000000","0.00000000"],["15523.18000000","0.00000000"]]}}
2020-11-09T11:26:29.43962 btcusdt {"stream":"btcusdt@depth@100ms","data":{"e":"depthUpdate","E":1604921189431,"s":"BTCUSDT","U":6511138043,"u":6511138218,"b":[["15500.68000000","0.00000000"],["15500.58000000","0.00000000"],["15500.57000000","0.00000000"],["15500.29000000","0.00000000"],["15500.00000000","0.00000000"],["15499.99000000","0.00000000"],["15499.92000000","0.00000000"],["15499.87000000","0.00000000"],["15499.81000000","0.00000000"],["15499.56000000","0.00000000"],["15499.03000000","0.00000000"],["15499.00000000","0.00000000"],["15498.94000000","0.10402800"],["15494.27000000","0.00000000"],["15494.15000000","0.00000000"],["15493.10000000","0.04000000"],["15492.85000000","0.02500000"],["15491.84000000","1.44000000"],["15491.02000000","0.06722700"],["15490.54000000","0.00000000"],["15490.39000000","0.00000000"],["15490.27000000","0.00000000"],["15489.58000000","0.13445300"],["15488.88000000","0.00000000"],["15488.09000000","0.00000000"],["15483.64000000","0.00000000"],["15482.36000000","0.00000000"],["15479.95000000","0.00000000"],["15479.56000000","0.15600000"],["15478.04000000","0.14850000"],["15422.50000000","0.00000000"]],"a":[["15498.95000000","6.21443400"],["15498.99000000","0.02032100"],["15499.00000000","0.80512400"],["15499.82000000","0.07567000"],["15500.01000000","7.90514400"],["15500.36000000","0.07614700"],["15500.46000000","0.00000000"],["15500.47000000","0.00756100"],["15500.59000000","5.63254800"],["15500.64000000","0.00690000"],["15500.68000000","0.00627500"],["15500.69000000","0.17493800"],["15501.25000000","0.00000000"],["15502.04000000","0.50000000"],["15502.27000000","0.01700000"],["15502.49000000","0.25000000"],["15502.55000000","1.74800000"],["15502.63000000","0.00000000"],["15502.71000000","0.08000000"],["15502.99000000","1.19800000"],["15503.05000000","0.00000000"],["15503.13000000","0.00000000"],["15503.42000000","0.00000000"],["15503.46000000","0.00000000"],["15503.47000000","0.00000000"],["15503.61000000","0.00000000"],["15503.65000000","0.15700000"],["15503.72000000","0.29200000"],["15504.04000000","0.00000000"],["15504.09000000","0.00000000"],["15504.21000000","0.78253600"],["15504.22000000","0.00000000"],["15504.26000000","0.00000000"],["15504.64000000","0.00000000"],["15504.65000000","0.00000000"],["15505.02000000","0.00000000"],["15505.03000000","0.00000000"],["15505.04000000","0.00000000"],["15505.05000000","0.00000000"],["15505.11000000","0.00000000"],["15505.18000000","0.00000000"],["15505.19000000","0.13000000"],["15505.25000000","0.28800000"],["15505.33000000","0.00000000"],["15505.34000000","0.00000000"],["15505.42000000","0.00690000"],["15505.97000000","0.00000000"],["15506.11000000","0.15300000"],["15506.41000000","0.20000000"],["15506.59000000","0.00000000"],["15506.64000000","0.00000000"],["15506.81000000","0.00000000"],["15506.87000000","0.00000000"],["15506.97000000","0.15219400"],["15506.98000000","0.10000000"],["15506.99000000","0.00000000"],["15507.02000000","0.12902200"],["15507.08000000","0.00000000"],["15507.15000000","0.00000000"],["15507.51000000","0.00000000"],["15507.78000000","0.00000000"],["15507.79000000","0.00000000"],["15507.82000000","0.00000000"],["15508.30000000","0.14850000"],["15508.36000000","0.00000000"],["15508.44000000","0.09631000"],["15508.77000000","0.00000000"],["15508.78000000","0.00000000"],["15509.39000000","0.00000000"],["15510.88000000","0.00000000"],["15510.89000000","0.29700000"],["15511.61000000","0.19724900"],["15512.35000000","0.00000000"],["15512.50000000","0.30900000"],["15512.78000000","0.10080800"],["15514.34000000","0.07018100"],["15515.90000000","0.00000000"],["15518.27000000","0.25778100"],["15519.87000000","0.87000000"],["15521.52000000","0.00000000"],["15527.56000000","0.00000000"],["15599.00000000","12.93668400"]]}}
2020-11-09T11:26:29.54056 btcusdt {"stream":"btcusdt@depth@100ms","data":{"e":"depthUpdate","E":1604921189531,"s":"BTCUSDT","U":6511138219,"u":6511138338,"b":[["15498.94000000","0.00190000"],["15497.71000000","0.00000000"],["15497.29000000","0.00000000"],["15496.49000000","0.00000000"],["15496.37000000","0.00000000"],["15496.16000000","0.00000000"],["15496.01000000","0.16000000"],["15495.75000000","0.00000000"],["15495.74000000","0.00000000"],["15495.49000000","0.00000000"],["15495.37000000","0.05000000"],["15495.36000000","0.50000000"],["15494.70000000","0.02106400"],["15493.90000000","0.00000000"],["15493.04000000","1.25000000"],["15492.63000000","0.98900000"],["15492.58000000","0.00000000"],["15492.40000000","0.04780600"],["15492.39000000","0.00000000"],["15492.29000000","1.50000000"],["15492.15000000","0.00000000"],["15490.32000000","0.00000000"],["15490.01000000","0.00000000"],["15489.13000000","0.00000000"],["15488.98000000","0.00214400"],["15488.20000000","1.00000000"],["15486.06000000","0.00000000"],["15482.23000000","0.14550000"],["15481.82000000","0.19377600"],["15481.58000000","0.00000000"],["15478.50000000","0.14550000"],["15476.91000000","0.00324000"],["15469.47000000","0.32400000"],["15463.80000000","0.00000000"],["15384.00000000","0.05500000"],["15380.01000000","0.00000000"],["15370.71000000","0.38384600"],["15344.32000000","0.00000000"],["15297.45000000","0.12943300"]],"a":[["15498.95000000","7.68288300"],["15499.38000000","0.00000000"],["15499.82000000","0.00000000"],["15499.99000000","0.00000000"],["15500.00000000","0.00000000"],["15500.01000000","7.40514400"],["15500.36000000","0.00000000"],["15500.59000000","0.22806700"],["15500.69000000","0.00690000"],["15501.01000000","0.30300000"],["15501.51000000","0.01700000"],["15501.76000000","2.00000000"],["15501.77000000","0.01700000"],["15502.15000000","0.00000000"],["15502.27000000","0.00000000"],["15502.42000000","0.15450000"],["15502.44000000","0.75000000"],["15502.49000000","0.00000000"],["15502.71000000","0.00000000"],["15503.42000000","0.05000000"],["15503.55000000","0.01000000"],["15503.99000000","0.20000000"],["15504.17000000","0.14550000"],["15504.21000000","0.30600000"],["15505.11000000","0.30000000"],["15505.19000000","0.08000000"],["15505.22000000","0.00000000"],["15505.30000000","0.00000000"],["15505.35000000","0.01000000"],["15505.59000000","0.00297000"],["15507.02000000","0.00000000"],["15507.10000000","0.00000000"],["15507.23000000","0.25783000"],["15507.26000000","1.25000000"],["15508.88000000","0.00000000"],["15508.92000000","0.25781100"],["15512.49000000","0.12892800"],["15512.50000000","1.30900000"],["15515.23000000","0.00690000"],["15515.67000000","0.00000000"],["15515.84000000","0.00000000"],["15516.52000000","0.00000000"],["15516.64000000","0.00000000"],["15518.12000000","0.00000000"],["15518.16000000","0.00000000"],["15518.27000000","0.00000000"],["15518.91000000","0.00000000"],["15524.24000000","0.00000000"],["15527.44000000","0.00000000"],["15534.16000000","0.06890000"],["15550.61000000","0.00112300"]]}}
2020-11-09T11:26:29.64214 btcusdt {"stream":"btcusdt@depth@100ms","data":{"e":"depthUpdate","E":1604921189631,"s":"BTCUSDT","U":6511138339,"u":6511138378,"b":[["15498.94000000","0.00390000"],["15496.13000000","0.00936500"],["15495.37000000","0.00000000"],["15495.17000000","0.00000000"],["15494.71000000","0.05000000"],["15494.70000000","0.00000000"],["15493.07000000","0.03100000"],["15493.04000000","0.00000000"],["15492.31000000","0.03226000"],["15491.07000000","0.00000000"],["15490.85000000","1.25000000"],["15490.07000000","0.12904000"],["15489.68000000","0.50000000"],["15489.52000000","0.03361500"],["15489.37000000","0.00000000"],["15485.54000000","0.00000000"],["15485.52000000","0.20000000"],["15479.05000000","0.87000000"],["15473.83000000","0.00000000"],["15442.13000000","0.00000000"]],"a":[["15498.95000000","8.43507700"],["15499.81000000","0.19500000"],["15500.00000000","0.78253600"],["15500.47000000","0.00000000"],["15500.59000000","0.23754200"],["15505.10000000","0.10253700"],["15506.97000000","0.00000000"],["15506.98000000","0.00000000"],["15510.24000000","0.10000000"],["15510.47000000","0.30000000"],["15512.71000000","1.50000000"],["15513.31000000","0.00000000"],["15513.81000000","0.00000000"],["15519.64000000","0.00000000"],["15548.88000000","0.03100000"]]}}
2020-11-09T11:26:29.73825 btcusdt {"stream":"btcusdt@depth@100ms","data":{"e":"depthUpdate","E":1604921189731,"s":"BTCUSDT","U":6511138379,"u":6511138445,"b":[["15498.94000000","0.00000000"],["15498.90000000","0.00000000"],["15498.78000000","0.00000000"],["15498.65000000","0.00000000"],["15495.35000000","0.00000000"],["15493.23000000","0.00000000"],["15493.06000000","0.00000000"],["15492.42000000","0.10000000"],["15492.40000000","0.00000000"],["15491.58000000","0.00000000"],["15491.03000000","0.04780600"],["15490.86000000","0.36291900"],["15490.85000000","0.00000000"],["15489.89000000","0.00000000"],["15488.54000000","0.00000000"],["15487.66000000","1.25000000"],["15487.52000000","0.00000000"],["15486.83000000","1.50000000"],["15481.69000000","0.19429800"],["15464.37000000","0.12124700"],["15441.08000000","0.24000000"],["15405.00000000","1.50489500"]],"a":[["15498.29000000","5.80515600"],["15498.55000000","0.01608900"],["15498.56000000","0.01816100"],["15498.63000000","0.49306800"],["15498.66000000","0.00000000"],["15498.79000000","0.00000000"],["15498.91000000","5.16520400"],["15498.93000000","0.00690000"],["15498.94000000","0.79599900"],["15498.95000000","8.07159700"],["15498.99000000","0.00000000"],["15499.81000000","0.22500000"],["15500.00000000","0.00000000"],["15500.01000000","2.00000000"],["15500.20000000","0.00200000"],["15501.00000000","0.20000000"],["15502.47000000","1.19800000"],["15502.99000000","0.00000000"],["15503.71000000","0.20142100"],["15505.40000000","0.25786000"],["15513.28000000","0.00000000"],["15513.43000000","0.00000000"],["15514.20000000","0.24000000"],["15563.50000000","0.00000000"]]}}
2020-11-09T11:26:29.83928 btcusdt {"stream":"btcusdt@depth@100ms","data":{"e":"depthUpdate","E":1604921189832,"s":"BTCUSDT","U":6511138446,"u":6511138541,"b":[["15498.28000000","0.00000000"],["15498.25000000","0.00000000"],["15498.03000000","0.00000000"],["15497.70000000","0.03254000"],["15492.63000000","0.97000000"],["15492.38000000","0.00000000"],["15492.24000000","0.00000000"],["15492.21000000","0.00000000"],["15491.39000000","0.22620400"],["15490.75000000","0.00000000"],["15490.46000000","0.03360200"],["15490.26000000","0.13446300"],["15490.07000000","0.00000000"],["15489.58000000","1.38445300"],["15488.85000000","0.30000000"],["15488.16000000","0.12848200"],["15487.74000000","0.00000000"],["15487.66000000","0.00000000"],["15487.49000000","0.12904000"],["15486.83000000","0.00000000"],["15486.73000000","0.06724200"],["15486.00000000","0.18621000"],["15485.15000000","1.50000000"],["15475.04000000","0.00000000"],["15472.91000000","0.00120700"],["15467.28000000","0.25810200"],["15408.00000000","0.43183000"],["15188.31000000","0.00174700"]],"a":[["15497.71000000","0.52309000"],["15497.79000000","0.07199800"],["15498.00000000","0.00690000"],["15498.04000000","0.00000000"],["15498.15000000","0.61028800"],["15498.16000000","0.00000000"],["15498.17000000","0.00000000"],["15498.26000000","0.00000000"],["15498.27000000","0.00000000"],["15498.29000000","7.48811700"],["15498.54000000","0.26366100"],["15498.55000000","0.00000000"],["15498.56000000","0.00000000"],["15498.90000000","4.57969600"],["15498.94000000","0.78253600"],["15498.95000000","2.47987600"],["15499.81000000","0.00000000"],["15500.00000000","0.08000000"],["15501.15000000","0.02390000"],["15501.77000000","0.00000000"],["15501.84000000","1.74800000"],["15502.45000000","0.15700000"],["15502.55000000","0.00000000"],["15502.58000000","0.29200000"],["15503.65000000","0.00000000"],["15503.72000000","0.00000000"],["15507.04000000","0.06722900"],["15511.23000000","0.00000000"],["15512.09000000","0.00000000"],["15514.20000000","0.00000000"],["15527.94000000","0.00000000"],["15528.85000000","0.00000000"],["15543.62000000","0.00000000"]]}}
2020-11-09T11:26:29.94051 btcusdt {"stream":"btcusdt@depth@100ms","data":{"e":"depthUpdate","E":1604921189932,"s":"BTCUSDT","U":6511138542,"u":6511138579,"b":[["15496.82000000","0.01400400"],["15496.15000000","0.00000000"],["15491.66000000","0.01900000"],["15485.15000000","0.00000000"],["15484.87000000","1.50000000"],["15481.97000000","0.10000000"],["15481.15000000","0.00000000"],["15479.34000000","0.23534400"],["15451.45000000","0.00000000"],["15444.91000000","0.16186600"],["15441.08000000","0.00000000"],["15420.21000000","0.00648400"]],"a":[["15497.71000000","2.77528400"],["15497.99000000","0.39471800"],["15498.14000000","0.78253600"],["15498.15000000","2.53975000"],["15498.29000000","7.31762700"],["15498.54000000","0.00000000"],["15498.90000000","0.00000000"],["15498.94000000","0.00000000"],["15498.95000000","2.00000000"],["15500.01000000","0.00000000"],["15500.78000000","0.00000000"],["15501.08000000","0.01870100"],["15503.05000000","0.00000000"],["15505.98000000","0.00000000"],["15507.95000000","0.01382400"],["15512.94000000","0.24000000"],["15528.08000000","0.24249800"],["15558.50000000","2.00000000"]]}}
2020-11-09T11:26:30.03880 btcusdt {"stream":"btcusdt@depth@100ms","data":{"e":"depthUpdate","E":1604921190032,"s":"BTCUSDT","U":6511138580,"u":6511138608,"b":[["15494.71000000","0.00000000"],["15492.64000000","0.05000000"],["15490.75000000","0.06753600"],["15490.46000000","0.00000000"],["15486.73000000","0.00000000"],["15486.53000000","0.06723700"],["15486.31000000","0.00000000"],["15484.87000000","0.00000000"],["15476.82000000","0.00000000"],["15471.01000000","0.00000000"]],"a":[["15497.71000000","3.48189600"],["15498.15000000","0.61028800"],["15498.90000000","0.08000000"],["15499.14000000","0.00200000"],["15499.99000000","0.20000000"],["15500.86000000","0.01700000"],["15501.51000000","0.00000000"],["15501.95000000","1.19800000"],["15502.26000000","0.05000000"],["15502.47000000","0.00000000"],["15503.42000000","0.00000000"],["15503.99000000","0.00000000"],["15527.99000000","0.00000000"],["15528.87000000","0.00000000"],["15545.16000000","0.00000000"]]}}
2020-11-09T11:26:30.13978 btcusdt {"stream":"btcusdt@depth@100ms","data":{"e":"depthUpdate","E":1604921190132,"s":"BTCUSDT","U":6511138609,"u":6511138622,"b":[["15489.86000000","0.03360300"],["15472.91000000","0.00000000"],["15462.83000000","0.00000000"]],"a":[["15497.71000000","3.68189600"],["15497.99000000","0.00000000"],["15498.14000000","0.00000000"],["15498.15000000","2.44216600"],["15500.53000000","0.31800000"],["15506.41000000","0.00000000"],["15514.12000000","0.23533600"],["15534.16000000","0.00000000"],["15540.34000000","0.00000000"]]}}
2020-11-09T11:26:30.23890 btcusdt {"stream":"btcusdt@depth@100ms","data":{"e":"depthUpdate","E":1604921190232,"s":"BTCUSDT","U":6511138623,"u":6511138634,"b":[["15482.59000000","0.00000000"]],"a":[["15497.71000000","3.68955300"],["15497.78000000","0.12910500"],["15497.99000000","0.39472000"],["15498.14000000","0.78253600"],["15498.15000000","0.61028800"],["15502.39000000","0.01000000"],["15503.55000000","0.00000000"],["15504.59000000","0.01500000"],["15507.50000000","0.30900000"],["15665.48000000","0.00000000"]]}}
2020-11-09T11:26:30.33790 btcusdt {"stream":"btcusdt@depth@100ms","data":{"e":"depthUpdate","E":1604921190332,"s":"BTCUSDT","U":6511138635,"u":6511138642,"b":[["15487.57000000","0.00000000"]],"a":[["15497.99000000","0.00000000"],["15498.14000000","0.00000000"],["15498.15000000","2.33193000"],["15501.83000000","0.12905700"],["15505.10000000","0.00000000"],["15508.96000000","0.00200000"],["15531.70000000","0.00400000"]]}}
2020-11-09T11:26:30.43906 btcusdt {"stream":"btcusdt@depth@100ms","data":{"e":"depthUpdate","E":1604921190432,"s":"BTCUSDT","U":6511138643,"u":6511138656,"b":[["15496.13000000","0.00000000"],["15496.01000000","0.00000000"],["15490.27000000","0.41393700"],["15483.52000000","0.35150000"]],"a":[["15497.99000000","0.39471900"],["15498.14000000","0.78253600"],["15498.15000000","0.61028800"],["15499.98000000","0.40154900"],["15500.59000000","0.22806700"],["15505.20000000","0.00200000"],["15513.38000000","0.01031300"],["15530.26000000","0.00000000"],["15531.70000000","0.00200000"],["15612.17000000","0.00000000"]]}}
2020-11-09T11:26:30.54066 btcusdt {"stream":"btcusdt@depth@100ms","data":{"e":"depthUpdate","E":1604921190532,"s":"BTCUSDT","U":6511138657,"u":6511138680,"b":[["15496.82000000","0.00000000"],["15491.02000000","0.00000000"],["15489.52000000","0.00000000"],["15484.75000000","1.50000000"],["15468.46000000","0.03878800"],["15408.00000000","0.05500000"]],"a":[["15497.71000000","9.06670700"],["15497.79000000","0.00000000"],["15497.96000000","0.12800000"],["15497.99000000","0.00000000"],["15498.14000000","0.00000000"],["15498.15000000","0.00000000"],["15498.91000000","0.00000000"],["15501.08000000","0.00000000"],["15502.03000000","0.01519600"],["15508.96000000","0.00000000"],["15510.39000000","0.05681900"],["15512.39000000","0.00000000"],["15519.10000000","0.00433200"],["15530.45000000","0.03863300"],["15531.70000000","0.00000000"]]}}
