2020-11-09T11:24:46.86962 btcusdt {"stream":"btcusdt@depth@100ms","data":{"e":"depthUpdate","E":1604921086675,"s":"BTCUSDT","U":6511122227,"u":6511122238,"b":[["15510.68000000","13.11268400"],["15507.83000000","1.00000000"],["15506.88000000","0.03223200"],["15495.00000000","0.00816200"],["15441.91000000","0.00000000"]],"a":[["15510.69000000","0.48973200"],["15511.46000000","0.01646600"],["15526.77000000","0.00000000"]]}}
2020-11-09T11:24:46.86995 btcusdt {"stream":"btcusdt@depth@100ms","data":{"e":"depthUpdate","E":1604921086775,"s":"BTCUSDT","U":6511122239,"u":6511122243,"b":[["15510.68000000","13.61268400"]],"a":[["15510.69000000","0.48653200"],["15511.46000000","0.01648400"]]}}
2020-11-09T11:24:46.88137 btcusdt {"stream":"btcusdt@depth@100ms","data":{"e":"depthUpdate","E":1604921086875,"s":"BTCUSDT","U":6511122244,"u":6511122245,"b":[["15510.68000000","9.21268400"]],"a":[["15515.01000000","0.00000000"]]}}
2020-11-09T11:24:46.98190 btcusdt {"stream":"btcusdt@depth@100ms","data":{"e":"depthUpdate","E":1604921086975,"s":"BTCUSDT","U":6511122246,"u":6511122247,"b":[["15350.00000000","5.14084600"]],"a":[["15516.75000000","0.13585000"]]}}
2020-11-09T11:24:47.08116 btcusdt {"stream":"btcusdt@depth@100ms","data":{"e":"depthUpdate","E":1604921087075,"s":"BTCUSDT","U":6511122248,"u":6511122249,"b":[["15501.39000000","0.00000000"]],"a":[["15510.69000000","0.48853200"]]}}
2020-11-09T11:24:47.18301 btcusdt {"stream":"btcusdt@depth@100ms","data":{"e":"depthUpdate","E":1604921087175,"s":"BTCUSDT","U":6511122250,"u":6511122255,"b":[["15510.68000000","9.08916200"],["15499.76000000","0.30199500"]],"a":[["15511.46000000","0.01893900"],["15515.33000000","0.00000000"],["15515.42000000","0.01000000"]]}}
2020-11-09T11:24:47.28367 btcusdt {"stream":"btcusdt@depth@100ms","data":{"e":"depthUpdate","E":1604921087275,"s":"BTCUSDT","U":6511122256,"u":6511122256,"b":[["15510.68000000","9.21268400"]],"a":[]}}
2020-11-09T11:24:47.38248 btcusdt {"stream":"btcusdt@depth@100ms","data":{"e":"depthUpdate","E":1604921087375,"s":"BTCUSDT","U":6511122257,"u":6511122261,"b":[["15510.68000000","9.08916200"],["15399.00000000","0.48510300"]],"a":[["15510.69000000","0.49053200"],["15511.46000000","0.01234600"]]}}
2020-11-09T11:24:47.48214 btcusdt {"stream":"btcusdt@depth@100ms","data":{"e":"depthUpdate","E":1604921087475,"s":"BTCUSDT","U":6511122262,"u":6511122268,"b":[["15510.68000000","14.51268400"]],"a":[["15510.69000000","0.43253100"],["15511.46000000","0.01808500"],["15516.75000000","0.00690000"]]}}
2020-11-09T11:24:47.68208 btcusdt {"stream":"btcusdt@depth@100ms","data":{"e":"depthUpdate","E":1604921087675,"s":"BTCUSDT","U":6511122269,"u":6511122272,"b":[["15510.68000000","14.41308400"]],"a":[["15511.46000000","0.01779300"],["15800.00000000","302.81014800"]]}}
2020-11-09T11:24:47.78201 btcusdt {"stream":"btcusdt@depth@100ms","data":{"e":"depthUpdate","E":1604921087775,"s":"BTCUSDT","U":6511122273,"u":6511122274,"b":[["15503.93000000","0.22500000"]],"a":[["15511.46000000","0.00000000"]]}}
2020-11-09T11:24:47.88599 btcusdt {"stream":"btcusdt@depth@100ms","data":{"e":"depthUpdate","E":1604921087875,"s":"BTCUSDT","U":6511122275,"u":6511122275,"b":[["14643.20000000","0.00171000"]],"a":[]}}
2020-11-09T11:24:48.01983 btcusdt {"stream":"btcusdt@depth@100ms","data":{"e":"depthUpdate","E":1604921087975,"s":"BTCUSDT","U":6511122276,"u":6511122280,"b":[["15510.68000000","9.11308400"]],"a":[["15511.46000000","0.01628800"],["15516.75000000","0.13584800"],["15516.80000000","0.20000000"],["15582.00000000","0.11339800"]]}}
2020-11-09T11:24:48.08274 btcusdt {"stream":"btcusdt@depth@100ms","data":{"e":"depthUpdate","E":1604921088075,"s":"BTCUSDT","U":6511122281,"u":6511122288,"b":[["15510.68000000","14.41308400"]],"a":[["15510.69000000","0.42934200"],["15511.46000000","0.01827700"],["15516.75000000","0.00690000"],["15516.80000000","0.00000000"]]}}
2020-11-09T11:24:48.18151 btcusdt {"stream":"btcusdt@depth@100ms","data":{"e":"depthUpdate","E":1604921088175,"s":"BTCUSDT","U":6511122289,"u":6511122293,"b":[["15510.68000000","9.11308400"],["15396.00000000","0.00000000"],["15241.97000000","0.00000000"]],"a":[["15511.46000000","0.01202100"]]}}
2020-11-09T11:24:48.28226 btcusdt {"stream":"btcusdt@depth@100ms","data":{"e":"depthUpdate","E":1604921088275,"s":"BTCUSDT","U":6511122294,"u":6511122294,"b":[],"a":[["15525.42000000","0.30900000"]]}}
2020-11-09T11:24:48.52871 btcusdt {"stream":"btcusdt@depth@100ms","data":{"e":"depthUpdate","E":1604921088375,"s":"BTCUSDT","U":6511122295,"u":6511122298,"b":[["15503.93000000","0.00000000"],["14643.20000000","0.02511000"],["9595.00000000","0.35552500"]],"a":[["15522.89000000","0.10085100"]]}}
2020-11-09T11:24:48.52890 btcusdt {"stream":"btcusdt@depth@100ms","data":{"e":"depthUpdate","E":1604921088475,"s":"BTCUSDT","U":6511122299,"u":6511122304,"b":[["15510.68000000","14.41308400"],["15509.91000000","0.01493100"],["15507.44000000","0.00000000"]],"a":[["15510.69000000","0.36786900"],["15511.46000000","0.01387700"]]}}
2020-11-09T11:24:48.58181 btcusdt {"stream":"btcusdt@depth@100ms","data":{"e":"depthUpdate","E":1604921088575,"s":"BTCUSDT","U":6511122305,"u":6511122308,"b":[["15510.68000000","14.41021700"],["15510.17000000","0.00815700"],["15507.13000000","0.00000000"],["15450.00000000","1.85130800"]],"a":[]}}
2020-11-09T11:24:48.68440 btcusdt {"stream":"btcusdt@depth@100ms","data":{"e":"depthUpdate","E":1604921088676,"s":"BTCUSDT","U":6511122309,"u":6511122313,"b":[["15508.25000000","0.16500000"],["15420.00000000","0.97585000"]],"a":[["15511.46000000","0.01209200"],["15524.80000000","0.00000000"]]}}
2020-11-09T11:24:48.78360 btcusdt {"stream":"btcusdt@depth@100ms","data":{"e":"depthUpdate","E":1604921088776,"s":"BTCUSDT","U":6511122314,"u":6511122316,"b":[["15510.68000000","14.40944900"]],"a":[["15511.46000000","0.00000000"],["15520.18000000","0.33563100"]]}}
2020-11-09T11:24:48.88478 btcusdt {"stream":"btcusdt@depth@100ms","data":{"e":"depthUpdate","E":1604921088876,"s":"BTCUSDT","U":6511122317,"u":6511122318,"b":[["15421.21000000","0.00000000"]],"a":[["15612.00000000","0.48510300"]]}}
2020-11-09T11:24:48.98258 btcusdt {"stream":"btcusdt@depth@100ms","data":{"e":"depthUpdate","E":1604921088976,"s":"BTCUSDT","U":6511122319,"u":6511122319,"b":[],"a":[["15510.69000000","0.37297600"]]}}
2020-11-09T11:24:49.08783 btcusdt {"stream":"btcusdt@depth@100ms","data":{"e":"depthUpdate","E":1604921089076,"s":"BTCUSDT","U":6511122320,"u":6511122323,"b":[["15507.84000000","0.15680600"],["15506.60000000","0.00000000"]],"a":[["15510.69000000","0.30656600"]]}}
2020-11-09T11:24:49.18312 btcusdt {"stream":"btcusdt@depth@100ms","data":{"e":"depthUpdate","E":1604921089176,"s":"BTCUSDT","U":6511122324,"u":6511122325,"b":[],"a":[["15515.42000000","0.00000000"],["15515.50000000","0.01000000"]]}}
2020-11-09T11:24:50.11088 btcusdt {"stream":"btcusdt@depth@100ms","data":{"e":"depthUpdate","E":1604921089376,"s":"BTCUSDT","U":6511122326,"u":6511122332,"b":[["15508.76000000","0.50000000"]],"a":[["15510.69000000","0.30256600"],["15511.46000000","0.01259700"],["15514.75000000","0.50000000"]]}}
2020-11-09T11:24:50.11124 btcusdt {"stream":"btcusdt@depth@100ms","data":{"e":"depthUpdate","E":1604921089476,"s":"BTCUSDT","U":6511122333,"u":6511122337,"b":[["15510.68000000","9.10944900"],["15502.76000000","0.00000000"]],"a":[["15511.46000000","0.01974600"],["15569.70000000","0.00000000"]]}}
2020-11-09T11:24:50.11161 btcusdt {"stream":"btcusdt@depth@100ms","data":{"e":"depthUpdate","E":1604921089576,"s":"BTCUSDT","U":6511122338,"u":6511122344,"b":[["15510.68000000","14.40944900"],["15241.97000000","0.00590400"]],"a":[["15510.69000000","0.24249000"],["15511.46000000","0.01657500"],["15525.33000000","0.00000000"],["15570.00000000","48.53853300"]]}}
2020-11-09T11:24:50.11259 btcusdt {"stream":"btcusdt@depth@100ms","data":{"e":"depthUpdate","E":1604921089676,"s":"BTCUSDT","U":6511122345,"u":6511122349,"b":[],"a":[["15511.46000000","0.01902600"],["15523.44000000","0.13429000"]]}}
2020-11-09T11:24:50.11297 btcusdt {"stream":"btcusdt@depth@100ms","data":{"e":"depthUpdate","E":1604921089776,"s":"BTCUSDT","U":6511122350,"u":6511122352,"b":[["15510.68000000","9.10944900"],["15507.84000000","0.00000000"],["15506.89000000","0.15680600"]],"a":[]}}
2020-11-09T11:24:50.11325 btcusdt {"stream":"btcusdt@depth@100ms","data":{"e":"depthUpdate","E":1604921089876,"s":"BTCUSDT","U":6511122353,"u":6511122358,"b":[],"a":[["15511.46000000","0.01780000"],["15523.04000000","0.02806500"],["15523.84000000","0.00000000"]]}}
2020-11-09T11:24:50.11351 btcusdt {"stream":"btcusdt@depth@100ms","data":{"e":"depthUpdate","E":1604921089976,"s":"BTCUSDT","U":6511122359,"u":6511122364,"b":[["15510.69000000","0.43151000"]],"a":[["15510.69000000","0.00000000"],["15516.75000000","0.13584900"],["15523.75000000","0.45568200"],["15524.11000000","0.00000000"],["15569.88000000","0.00408000"]]}}
2020-11-09T11:24:50.11382 btcusdt {"stream":"btcusdt@depth@100ms","data":{"e":"depthUpdate","E":1604921090076,"s":"BTCUSDT","U":6511122365,"u":6511122385,"b":[["15511.14000000","7.05124600"],["15510.92000000","0.00690000"],["15510.71000000","0.03893100"],["15510.68000000","2.33334500"],["15508.43000000","0.11427900"],["15507.95000000","0.00000000"]],"a":[["15511.15000000","0.00147300"],["15511.46000000","0.01536400"],["15515.51000000","0.00000000"],["15516.75000000","0.00690000"]]}}
2020-11-09T11:24:50.18361 btcusdt {"stream":"btcusdt@depth@100ms","data":{"e":"depthUpdate","E":1604921090176,"s":"BTCUSDT","U":6511122386,"u":6511122427,"b":[["15511.24000000","9.21813300"],["15511.23000000","0.06224000"],["15511.14000000","0.35491000"],["15510.71000000","0.00000000"],["15510.68000000","2.12352200"],["15510.22000000","0.00707500"],["15510.17000000","0.00000000"],["15509.01000000","0.18000000"],["15508.99000000","0.00690000"],["15508.76000000","0.00000000"],["15508.25000000","0.00000000"],["15508.07000000","0.00000000"],["15506.22000000","0.05000000"],["15505.91000000","0.00000000"],["15500.00000000","14.33045700"]],"a":[["15511.15000000","0.00000000"],["15511.46000000","0.01669300"],["15513.32000000","0.00000000"],["15514.51000000","0.10000000"],["15514.85000000","0.00000000"],["15514.99000000","0.00000000"],["15515.36000000","0.13127900"],["15515.49000000","0.05000000"],["15515.50000000","0.00000000"],["15515.86000000","0.01000000"],["15517.10000000","0.00000000"],["15517.50000000","0.00000000"],["15517.67000000","0.01000000"],["15518.07000000","0.01500000"]]}}
2020-11-09T11:24:50.28844 btcusdt {"stream":"btcusdt@depth@100ms","data":{"e":"depthUpdate","E":1604921090276,"s":"BTCUSDT","U":6511122428,"u":6511122510,"b":[["15512.27000000","1.05690000"],["15511.75000000","0.06224000"],["15511.29000000","0.05035700"],["15511.28000000","0.04196400"],["15511.27000000","0.00000000"],["15511.26000000","0.10281200"],["15511.25000000","5.33268400"],["15511.24000000","3.58403700"],["15511.23000000","0.00000000"],["15511.14000000","0.00000000"],["15510.29000000","0.01660700"],["15509.91000000","0.00000000"],["15509.01000000","0.00000000"],["15508.62000000","0.03223200"],["15508.44000000","0.19999900"],["15507.93000000","1.00000000"],["15507.15000000","1.58300000"],["15506.98000000","1.59300000"],["15506.88000000","0.00000000"],["15506.71000000","2.00000000"],["15506.04000000","0.00000000"],["15505.90000000","0.00000000"],["15505.82000000","0.00000000"],["15505.75000000","0.12893000"],["15504.93000000","0.00000000"],["15502.55000000","0.00000000"],["15496.56000000","1.50000000"],["15169.00000000","0.02000000"]],"a":[["15511.25000000","0.00000000"],["15511.26000000","0.00000000"],["15511.46000000","0.00000000"],["15512.28000000","0.00690000"],["15513.00000000","0.17222100"],["15513.12000000","0.00000000"],["15513.31000000","0.00000000"],["15513.37000000","0.00000000"],["15514.51000000","0.00000000"],["15514.52000000","0.00000000"],["15515.34000000","0.00000000"],["15515.36000000","0.11427900"],["15515.79000000","0.00000000"],["15516.12000000","0.10000000"],["15516.13000000","0.00000000"],["15516.26000000","0.00690000"],["15516.32000000","0.00000000"],["15516.48000000","0.31800000"],["15516.53000000","0.01700000"],["15516.55000000","0.01700000"],["15516.59000000","0.06000000"],["15516.85000000","0.00000000"],["15516.92000000","0.00000000"],["15517.08000000","1.19800000"],["15517.25000000","1.58300000"],["15517.34000000","1.74800000"],["15517.38000000","1.59300000"],["15517.45000000","0.00000000"],["15517.55000000","0.04000000"],["15517.86000000","0.32000000"],["15518.31000000","0.75000000"],["15518.78000000","0.00000000"],["15519.44000000","0.50000000"],["15520.18000000","0.00000000"],["15558.00000000","2.00287900"],["15582.00000000","0.49022800"]]}}
2020-11-09T11:24:50.38509 btcusdt {"stream":"btcusdt@depth@100ms","data":{"e":"depthUpdate","E":1604921090376,"s":"BTCUSDT","U":6511122511,"u":6511122592,"b":[["15512.99000000","1.71894100"],["15512.63000000","0.00690000"],["15512.31000000","0.08418400"],["15512.30000000","0.00000000"],["15512.27000000","3.54778100"],["15511.84000000","0.06192000"],["15511.75000000","0.00000000"],["15511.29000000","0.00000000"],["15511.28000000","0.00000000"],["15511.26000000","0.00000000"],["15511.25000000","0.03268400"],["15511.24000000","2.21667800"],["15510.68000000","2.00000000"],["15510.23000000","0.00000000"],["15510.12000000","0.00690000"],["15508.44000000","0.27999900"],["15505.80000000","1.25000000"],["15505.16000000","0.00000000"],["15503.29000000","0.00000000"],["15502.57000000","0.30600000"],["15433.12000000","0.00000000"]],"a":[["15512.28000000","0.00000000"],["15513.00000000","0.12439500"],["15513.71000000","0.03941700"],["15513.76000000","0.05411500"],["15513.82000000","0.09641200"],["15514.23000000","0.00000000"],["15514.97000000","0.00000000"],["15515.36000000","0.00000000"],["15515.49000000","0.00000000"],["15515.86000000","0.00000000"],["15516.11000000","0.20000000"],["15516.12000000","0.00000000"],["15516.52000000","0.05000000"],["15516.59000000","0.00000000"],["15516.78000000","0.00000000"],["15516.88000000","0.01000000"],["15517.08000000","0.00000000"],["15517.17000000","0.00000000"],["15517.25000000","0.00000000"],["15517.38000000","0.00000000"],["15517.55000000","0.00000000"],["15517.62000000","1.20490000"],["15517.67000000","0.00000000"],["15517.86000000","0.00000000"],["15518.20000000","1.58300000"],["15518.31000000","0.00000000"],["15518.35000000","1.59300000"],["15518.45000000","0.06000000"],["15518.62000000","0.00000000"],["15518.69000000","0.01000000"],["15518.86000000","0.38300000"],["15519.41000000","0.04000000"],["15519.44000000","0.00000000"],["15519.59000000","0.00000000"],["15519.74000000","0.75000000"],["15520.11000000","0.50000000"],["15522.63000000","0.10607100"],["15529.98000000","0.00000000"]]}}
2020-11-09T11:24:50.48464 btcusdt {"stream":"btcusdt@depth@100ms","data":{"e":"depthUpdate","E":1604921090476,"s":"BTCUSDT","U":6511122593,"u":6511122639,"b":[["15512.99000000","4.03185900"],["15512.49000000","0.06192000"],["15512.27000000","3.23287700"],["15511.84000000","0.00000000"],["15510.68000000","0.00000000"],["15510.43000000","0.00813900"],["15510.22000000","0.00000000"],["15510.08000000","0.19330500"],["15510.07000000","0.11427900"],["15509.80000000","0.20000000"],["15508.46000000","1.58300000"],["15508.43000000","0.00000000"],["15508.39000000","2.00000000"],["15508.28000000","1.59300000"],["15507.83000000","0.00000000"],["15507.15000000","0.00000000"],["15506.98000000","0.00000000"],["15506.71000000","0.00000000"],["15503.76000000","0.00297000"],["15496.56000000","0.00000000"],["15494.71000000","0.30300000"],["15493.16000000","0.21429300"]],"a":[["15513.34000000","0.00000000"],["15513.71000000","0.00000000"],["15513.76000000","0.00000000"],["15513.82000000","0.00690000"],["15516.11000000","0.00000000"],["15516.52000000","0.00000000"],["15516.81000000","0.08223100"],["15517.17000000","0.00000000"],["15517.62000000","0.00690000"],["15517.82000000","0.32100000"],["15518.07000000","0.00000000"],["15518.21000000","1.19800000"],["15518.69000000","0.00000000"],["15518.86000000","0.08000000"],["15519.25000000","0.09621700"],["15519.41000000","0.05000000"],["15519.50000000","0.00000000"],["15519.81000000","0.01500000"],["15521.25000000","0.00000000"],["15521.46000000","1.25000000"],["15523.44000000","0.00000000"],["15557.00000000","2.00065500"]]}}
2020-11-09T11:24:50.58337 btcusdt {"stream":"btcusdt@depth@100ms","data":{"e":"depthUpdate","E":1604921090577,"s":"BTCUSDT","U":6511122640,"u":6511122653,"b":[["15511.30000000","0.16000000"],["15510.09000000","0.02106400"],["15510.08000000","0.00000000"],["15507.94000000","0.02500000"],["15506.58000000","0.00000000"],["15497.00000000","1.50000000"],["15489.88000000","0.00000000"]],"a":[["15516.47000000","0.08000000"],["15517.27000000","0.11427900"],["15518.19000000","0.20000000"],["15518.95000000","0.10000000"],["15526.83000000","0.00000000"],["15528.98000000","0.13428400"],["15529.76000000","0.02500000"]]}}
2020-11-09T11:24:50.69085 btcusdt {"stream":"btcusdt@depth@100ms","data":{"e":"depthUpdate","E":1604921090677,"s":"BTCUSDT","U":6511122654,"u":6511122661,"b":[["15512.50000000","0.15680600"],["15506.89000000","0.00000000"]],"a":[["15516.76000000","0.00000000"],["15518.95000000","0.10000000"],["15521.46000000","0.00000000"],["15523.10000000","1.25000000"],["15525.09000000","0.25760000"]]}}
2020-11-09T11:24:50.78686 btcusdt {"stream":"btcusdt@depth@100ms","data":{"e":"depthUpdate","E":1604921090777,"s":"BTCUSDT","U":6511122662,"u":6511122665,"b":[["15510.29000000","0.00000000"],["15506.59000000","0.00000000"],["15442.05000000","0.00000000"]],"a":[["15513.00000000","0.12639500"]]}}
2020-11-09T11:24:50.88567 btcusdt {"stream":"btcusdt@depth@100ms","data":{"e":"depthUpdate","E":1604921090877,"s":"BTCUSDT","U":6511122666,"u":6511122686,"b":[["15510.43000000","0.00000000"],["15505.64000000","0.20000000"],["15502.15000000","0.00000000"],["15502.06000000","0.50427300"],["15501.68000000","1.00854500"],["15501.67000000","0.00000000"],["15499.97000000","0.30000000"],["15497.53000000","0.50000000"],["15495.03000000","0.00000000"],["15435.42000000","0.00647800"],["15399.00000000","0.37683000"]],"a":[["15516.53000000","0.00000000"],["15516.55000000","0.00000000"],["15517.34000000","0.01700000"],["15518.16000000","1.74800000"],["15518.85000000","0.02907100"],["15522.71000000","0.42931700"],["15523.04000000","0.00000000"],["15530.09000000","0.00000000"]]}}
2020-11-09T11:24:50.98499 btcusdt {"stream":"btcusdt@depth@100ms","data":{"e":"depthUpdate","E":1604921090977,"s":"BTCUSDT","U":6511122687,"u":6511122706,"b":[["15508.29000000","0.05000000"],["15506.22000000","0.00000000"],["15499.80000000","1.00000000"]],"a":[["15516.81000000","0.03223100"],["15517.37000000","0.01700000"],["15517.55000000","0.05000000"],["15518.19000000","0.00000000"],["15518.85000000","0.00000000"],["15519.49000000","0.00000000"],["15519.99000000","0.00000000"],["15522.71000000","0.40548900"],["15522.83000000","0.05875900"],["15523.09000000","0.02422500"],["15523.75000000","0.00000000"],["15524.30000000","0.04934600"],["15528.63000000","0.02806500"],["15529.03000000","0.45568200"]]}}
2020-11-09T11:24:51.08565 btcusdt {"stream":"btcusdt@depth@100ms","data":{"e":"depthUpdate","E":1604921091077,"s":"BTCUSDT","U":6511122707,"u":6511122720,"b":[["15512.99000000","4.23185800"],["15508.44000000","0.08000000"],["15420.00000000","1.08412300"],["15050.00000000","17.57719100"]],"a":[["15513.00000000","0.13039500"],["15514.98000000","0.00000000"],["15517.17000000","0.20000000"],["15517.81000000","0.10000000"],["15518.95000000","0.00000000"],["15519.25000000","0.00000000"],["15521.25000000","1.25000000"],["15523.10000000","0.00000000"],["15526.23000000","0.24000000"]]}}
2020-11-09T11:24:51.18417 btcusdt {"stream":"btcusdt@depth@100ms","data":{"e":"depthUpdate","E":1604921091177,"s":"BTCUSDT","U":6511122721,"u":6511122732,"b":[["15512.99000000","9.53185800"],["15512.67000000","0.06192000"],["15512.49000000","0.00000000"],["15504.01000000","0.14550000"],["15470.00000000","0.03232000"]],"a":[["15513.00000000","0.07027900"],["15514.75000000","0.00000000"],["15516.88000000","0.00000000"],["15517.18000000","0.00000000"],["15517.60000000","0.01000000"],["15520.00000000","5.47780900"],["15550.00000000","39.54706500"]]}}
2020-11-09T11:24:51.28450 btcusdt {"stream":"btcusdt@depth@100ms","data":{"e":"depthUpdate","E":1604921091277,"s":"BTCUSDT","U":6511122733,"u":6511122737,"b":[["15512.76000000","0.06192000"],["15512.67000000","0.00000000"],["15502.65000000","0.06714400"],["15501.94000000","0.00000000"]],"a":[["15518.60000000","0.00000000"]]}}
2020-11-09T11:24:51.38345 btcusdt {"stream":"btcusdt@depth@100ms","data":{"e":"depthUpdate","E":1604921091377,"s":"BTCUSDT","U":6511122738,"u":6511122743,"b":[["15508.11000000","1.25000000"],["15505.80000000","0.00000000"],["15469.00000000","2.00000000"]],"a":[["15515.00000000","24.15164500"],["15517.72000000","0.51522600"],["15519.71000000","0.20000000"]]}}
2020-11-09T11:24:51.48401 btcusdt {"stream":"btcusdt@depth@100ms","data":{"e":"depthUpdate","E":1604921091477,"s":"BTCUSDT","U":6511122744,"u":6511122754,"b":[["15512.50000000","0.00000000"],["15508.11000000","0.00000000"],["15507.22000000","1.25000000"],["15500.35000000","0.50000000"],["15497.53000000","0.00000000"],["15495.37000000","0.00000000"]],"a":[["15519.71000000","0.00000000"],["15521.25000000","1.25000000"],["15522.16000000","0.00000000"]]}}
2020-11-09T11:24:51.58512 btcusdt {"stream":"btcusdt@depth@100ms","data":{"e":"depthUpdate","E":1604921091577,"s":"BTCUSDT","U":6511122755,"u":6511122768,"b":[["15512.99000000","3.63285900"],["15511.31000000","0.19999900"],["15510.10000000","0.15680600"],["15508.48000000","0.08000000"],["15508.39000000","0.00000000"],["15507.22000000","0.00000000"],["15505.99000000","1.25000000"],["15505.01000000","0.00000000"],["15498.28000000","1.06030100"]],"a":[["15516.47000000","0.00000000"],["15521.88000000","0.00000000"],["15526.23000000","0.00000000"]]}}
2020-11-09T11:24:51.69082 btcusdt {"stream":"btcusdt@depth@100ms","data":{"e":"depthUpdate","E":1604921091677,"s":"BTCUSDT","U":6511122769,"u":6511122780,"b":[["15512.53000000","0.00954300"],["15512.22000000","0.01388900"],["15510.10000000","0.00000000"],["15509.81000000","0.08000000"],["15508.63000000","0.15680600"]],"a":[["15514.99000000","0.10000000"],["15516.27000000","0.00746700"],["15516.77000000","0.01207500"],["15517.81000000","0.00000000"],["15518.57000000","0.20000000"],["15520.63000000","0.12892500"],["15529.80000000","0.24000000"]]}}
2020-11-09T11:24:51.78516 btcusdt {"stream":"btcusdt@depth@100ms","data":{"e":"depthUpdate","E":1604921091777,"s":"BTCUSDT","U":6511122781,"u":6511122786,"b":[["15504.96000000","0.01900000"],["15498.28000000","0.00202500"]],"a":[["15514.98000000","0.20000000"],["15517.17000000","0.00000000"],["15523.58000000","0.01382400"],["15529.80000000","0.00000000"]]}}
2020-11-09T11:24:51.88571 btcusdt {"stream":"btcusdt@depth@100ms","data":{"e":"depthUpdate","E":1604921091877,"s":"BTCUSDT","U":6511122787,"u":6511122792,"b":[["15512.22000000","0.00000000"],["15496.24000000","1.06950700"],["15449.91000000","0.24000000"]],"a":[["15516.74000000","0.08000000"],["15517.23000000","0.28000000"],["15525.94000000","0.24000000"]]}}
2020-11-09T11:24:51.98617 btcusdt {"stream":"btcusdt@depth@100ms","data":{"e":"depthUpdate","E":1604921091977,"s":"BTCUSDT","U":6511122793,"u":6511122804,"b":[["15512.27000000","3.10935500"],["15511.31000000","0.00000000"],["15510.10000000","0.19999900"],["15508.45000000","0.05000000"],["15508.29000000","0.00000000"],["15505.99000000","0.00000000"]],"a":[["15513.00000000","0.01027500"],["15517.33000000","0.05000000"],["15517.55000000","0.00000000"],["15517.59000000","0.12893000"],["15518.15000000","0.12893800"],["15518.57000000","0.00000000"]]}}
2020-11-09T11:24:52.08452 btcusdt {"stream":"btcusdt@depth@100ms","data":{"e":"depthUpdate","E":1604921092077,"s":"BTCUSDT","U":6511122805,"u":6511122812,"b":[["15512.99000000","3.69477900"],["15512.76000000","0.00000000"],["15506.06000000","0.22500000"],["15505.99000000","1.25000000"]],"a":[["15516.27000000","0.00000000"],["15516.77000000","0.00000000"],["15517.59000000","0.00000000"],["15517.82000000","0.00000000"]]}}
2020-11-09T11:24:52.18419 btcusdt {"stream":"btcusdt@depth@100ms","data":{"e":"depthUpdate","E":1604921092178,"s":"BTCUSDT","U":6511122813,"u":6511122815,"b":[],"a":[["15516.80000000","0.11427900"],["15517.27000000","0.00000000"],["15518.15000000","0.00000000"]]}}
2020-11-09T11:24:52.28645 btcusdt {"stream":"btcusdt@depth@100ms","data":{"e":"depthUpdate","E":1604921092278,"s":"BTCUSDT","U":6511122816,"u":6511122820,"b":[["15512.22000000","0.01359500"],["15508.64000000","0.15680600"],["15508.63000000","0.00000000"],["15506.06000000","0.00000000"]],"a":[["15517.92000000","0.01949400"]]}}
2020-11-09T11:24:52.38569 btcusdt {"stream":"btcusdt@depth@100ms","data":{"e":"depthUpdate","E":1604921092378,"s":"BTCUSDT","U":6511122821,"u":6511122831,"b":[["15512.99000000","3.38299800"],["15511.25000000","0.00000000"],["15511.24000000","2.00000000"],["15510.07000000","0.00000000"],["15509.45000000","0.11427900"]],"a":[["15513.00000000","5.31027500"],["15517.50000000","0.00613700"]]}}
2020-11-09T11:24:52.48541 btcusdt {"stream":"btcusdt@depth@100ms","data":{"e":"depthUpdate","E":1604921092478,"s":"BTCUSDT","U":6511122832,"u":6511122837,"b":[["15512.99000000","3.44491800"],["15512.22000000","0.01727200"]],"a":[["15513.00000000","0.01027500"],["15517.82000000","0.32100000"],["15519.68000000","0.88519200"]]}}
2020-11-09T11:24:52.58413 btcusdt {"stream":"btcusdt@depth@100ms","data":{"e":"depthUpdate","E":1604921092578,"s":"BTCUSDT","U":6511122838,"u":6511122841,"b":[["15512.22000000","0.01208800"],["15511.30000000","0.00000000"]],"a":[["15517.82000000","0.00000000"]]}}
2020-11-09T11:24:52.68397 btcusdt {"stream":"btcusdt@depth@100ms","data":{"e":"depthUpdate","E":1604921092678,"s":"BTCUSDT","U":6511122842,"u":6511122845,"b":[["15512.27000000","2.05935500"],["15509.80000000","0.00000000"],["15508.41000000","0.04000000"],["15449.91000000","0.00000000"]],"a":[]}}
2020-11-09T11:24:52.78447 btcusdt {"stream":"btcusdt@depth@100ms","data":{"e":"depthUpdate","E":1604921092778,"s":"BTCUSDT","U":6511122846,"u":6511122861,"b":[["15509.81000000","0.00000000"],["15508.48000000","0.00000000"],["15507.93000000","0.00000000"],["15507.47000000","0.04000000"],["15506.74000000","0.16000000"],["15449.24000000","0.24000000"]],"a":[["15516.25000000","0.11427900"],["15516.63000000","0.01700000"],["15516.65000000","0.01700000"],["15516.80000000","0.00000000"],["15517.34000000","0.00000000"],["15517.37000000","0.00000000"],["15517.42000000","0.00777700"],["15517.50000000","0.00000000"],["15521.45000000","0.00000000"],["15524.30000000","0.02551800"]]}}
2020-11-09T11:24:52.88549 btcusdt {"stream":"btcusdt@depth@100ms","data":{"e":"depthUpdate","E":1604921092878,"s":"BTCUSDT","U":6511122862,"u":6511122867,"b":[["15512.22000000","0.01689800"]],"a":[["15515.69000000","0.08000000"],["15519.70000000","0.32100000"],["15524.11000000","0.02382800"],["15525.94000000","0.00000000"]]}}
2020-11-09T11:24:52.98578 btcusdt {"stream":"btcusdt@depth@100ms","data":{"e":"depthUpdate","E":1604921092978,"s":"BTCUSDT","U":6511122868,"u":6511122917,"b":[["15513.98000000","0.00690000"],["15513.00000000","0.45651000"],["15512.99000000","3.50652000"],["15512.31000000","0.00000000"],["15510.69000000","0.00000000"],["15508.46000000","1.69124000"],["15508.45000000","0.00000000"],["15507.86000000","0.05000000"],["15507.48000000","0.03626500"],["15505.99000000","0.00000000"],["15505.98000000","1.25000000"],["15386.17000000","0.38346100"],["15384.62000000","0.00000000"]],"a":[["15513.00000000","0.00000000"],["15513.79000000","0.00000000"],["15513.82000000","0.00000000"],["15513.99000000","6.00193300"],["15514.45000000","0.03941700"],["15514.89000000","4.93118600"],["15514.90000000","0.11419000"],["15514.93000000","0.03957500"],["15514.94000000","0.03715000"],["15514.96000000","0.02614300"],["15514.97000000","4.08927000"],["15514.98000000","0.16373500"],["15515.69000000","0.00000000"],["15516.63000000","0.00000000"],["15516.65000000","0.00000000"],["15517.22000000","0.05000000"],["15517.33000000","0.00000000"],["15517.59000000","0.12893600"],["15517.62000000","0.00690000"],["15517.77000000","0.01700000"],["15517.80000000","0.01700000"],["15518.16000000","0.00000000"],["15518.20000000","0.00000000"],["15518.21000000","0.00000000"],["15518.61000000","1.74800000"],["15518.70000000","1.19800000"],["15518.90000000","1.58300000"],["15522.92000000","0.00000000"],["15524.92000000","0.24000000"]]}}
2020-11-09T11:24:53.08527 btcusdt {"stream":"btcusdt@depth@100ms","data":{"e":"depthUpdate","E":1604921093078,"s":"BTCUSDT","U":6511122918,"u":6511122941,"b":[["15513.98000000","0.00453400"],["15512.99000000","3.06809400"],["14900.00000000","110.63732800"]],"a":[["15513.99000000","8.15193300"],["15514.90000000","0.00000000"],["15514.93000000","0.00000000"],["15514.94000000","0.00000000"],["15514.96000000","0.00000000"],["15514.97000000","0.00625200"],["15514.98000000","0.16373500"],["15517.22000000","0.00000000"],["15517.60000000","0.00000000"],["15517.65000000","0.30600000"],["15517.80000000","0.06700000"],["15518.60000000","0.01000000"],["15519.41000000","0.04000000"],["15519.81000000","0.00000000"],["15520.40000000","0.01000000"],["15520.80000000","0.24200000"],["15527.74000000","0.58249900"]]}}
2020-11-09T11:24:53.18487 btcusdt {"stream":"btcusdt@depth@100ms","data":{"e":"depthUpdate","E":1604921093178,"s":"BTCUSDT","U":6511122942,"u":6511122985,"b":[["15513.98000000","0.00000000"],["15513.00000000","1.45487400"],["15512.99000000","2.06994100"],["15512.80000000","0.00200000"],["15512.57000000","0.00000000"],["15512.22000000","0.01287700"],["15510.10000000","0.00000000"],["15502.39000000","0.00000000"],["15449.24000000","0.00000000"],["15430.01000000","0.00000000"]],"a":[["15513.01000000","4.74900000"],["15513.52000000","0.00000000"],["15513.94000000","0.05262700"],["15513.95000000","0.05111600"],["15513.97000000","0.00000000"],["15513.98000000","5.33840400"],["15513.99000000","2.50601200"],["15514.89000000","4.87010600"],["15516.25000000","0.00000000"],["15516.32000000","0.11427900"],["15516.78000000","0.27461800"],["15516.81000000","0.04923100"],["15517.77000000","0.00000000"],["15517.79000000","1.74800000"],["15517.80000000","0.05000000"],["15518.61000000","0.00000000"],["15525.09000000","0.00000000"]]}}
2020-11-09T11:24:53.28556 btcusdt {"stream":"btcusdt@depth@100ms","data":{"e":"depthUpdate","E":1604921093278,"s":"BTCUSDT","U":6511122986,"u":6511123010,"b":[["15513.00000000","2.08096200"],["15512.80000000","0.00600000"],["15509.46000000","0.08000000"],["15508.65000000","0.19999900"],["15508.41000000","2.04000000"],["15507.86000000","0.00000000"],["15507.49000000","0.05000000"],["15506.74000000","0.00000000"],["15503.76000000","0.00000000"],["15502.69000000","0.03361300"],["15494.71000000","0.00000000"],["15447.55000000","0.24000000"]],"a":[["15513.01000000","0.39900000"],["15513.50000000","0.00690000"],["15513.93000000","0.00000000"],["15513.94000000","0.00000000"],["15513.95000000","0.00000000"],["15513.99000000","2.20293300"],["15516.46000000","0.00735200"],["15517.42000000","0.00000000"]]}}
2020-11-09T11:24:53.38749 btcusdt {"stream":"btcusdt@depth@100ms","data":{"e":"depthUpdate","E":1604921093378,"s":"BTCUSDT","U":6511123011,"u":6511123044,"b":[["15513.49000000","6.40556000"],["15513.25000000","0.00690000"],["15513.04000000","0.10634100"],["15513.02000000","0.11562600"],["15513.00000000","2.87953200"],["15512.81000000","0.06192000"],["15512.56000000","0.00000000"],["15512.22000000","0.01522700"],["15511.24000000","0.00000000"],["15510.09000000","0.00000000"],["15509.93000000","0.11427900"],["15509.45000000","0.00000000"],["15506.58000000","0.02106400"],["15435.42000000","0.00000000"]],"a":[["15513.01000000","0.00000000"],["15513.50000000","0.01380000"],["15513.97000000","0.37090200"],["15513.98000000","0.00000000"],["15513.99000000","2.15690000"],["15514.98000000","0.00000000"],["15514.99000000","0.00000000"],["15516.46000000","0.00000000"],["15516.78000000","0.25761800"],["15517.22000000","0.26373500"],["15517.25000000","0.00704300"],["15517.59000000","0.00000000"]]}}
2020-11-09T11:24:53.48690 btcusdt {"stream":"btcusdt@depth@100ms","data":{"e":"depthUpdate","E":1604921093478,"s":"BTCUSDT","U":6511123045,"u":6511123074,"b":[["15513.49000000","3.40537300"],["15513.00000000","2.57645300"],["15512.27000000","0.05935500"],["15512.22000000","0.01821700"],["15502.87000000","0.03361300"],["15502.69000000","0.00000000"],["15447.55000000","0.00000000"],["15420.00000000","0.97585000"]],"a":[["15513.50000000","5.31380000"],["15513.93000000","0.00000000"],["15513.95000000","0.00000000"],["15513.97000000","0.00000000"],["15513.99000000","0.15690000"],["15516.81000000","0.03223100"],["15517.30000000","0.01700000"],["15517.31000000","0.05000000"],["15517.33000000","0.01700000"],["15517.79000000","0.00000000"],["15517.80000000","0.00000000"],["15518.11000000","0.01000000"],["15518.56000000","1.74800000"],["15518.60000000","0.00000000"],["15519.91000000","0.01000000"],["15520.40000000","0.00000000"]]}}
2020-11-09T11:24:53.58560 btcusdt {"stream":"btcusdt@depth@100ms","data":{"e":"depthUpdate","E":1604921093578,"s":"BTCUSDT","U":6511123075,"u":6511123083,"b":[["15512.22000000","0.01768800"],["15446.35000000","0.24000000"]],"a":[["15513.50000000","0.01380000"],["15516.32000000","0.00000000"],["15516.87000000","0.12117900"],["15517.22000000","0.10000000"],["15519.70000000","0.00000000"],["15544.82000000","0.00000000"]]}}
2020-11-09T11:24:53.68498 btcusdt {"stream":"btcusdt@depth@100ms","data":{"e":"depthUpdate","E":1604921093678,"s":"BTCUSDT","U":6511123084,"u":6511123107,"b":[["15513.19000000","0.06192000"],["15512.95000000","0.00000000"],["15512.81000000","0.00000000"],["15396.00000000","0.10827300"]],"a":[["15513.98000000","0.00000000"],["15513.99000000","0.00690000"],["15514.45000000","0.00000000"],["15514.82000000","2.24797300"],["15514.83000000","0.00000000"],["15514.85000000","0.00000000"],["15514.87000000","0.00000000"],["15514.88000000","0.16373500"],["15516.47000000","0.10000000"],["15517.22000000","0.00000000"],["15650.00000000","85.26586100"]]}}
2020-11-09T11:24:53.78916 btcusdt {"stream":"btcusdt@depth@100ms","data":{"e":"depthUpdate","E":1604921093778,"s":"BTCUSDT","U":6511123108,"u":6511123141,"b":[["15514.15000000","0.00000000"],["15513.51000000","0.13597200"],["15513.50000000","0.41964600"],["15513.49000000","3.50963600"],["15513.23000000","0.06192000"],["15513.19000000","0.00000000"],["15513.03000000","0.00979900"],["15512.53000000","0.00000000"],["15507.48000000","0.00000000"],["15446.35000000","0.00000000"]],"a":[["15513.50000000","0.00000000"],["15513.99000000","0.00000000"],["15514.10000000","2.00000000"],["15514.16000000","0.00690000"],["15514.82000000","0.00000000"],["15514.87000000","4.52575500"],["15515.10000000","0.03941700"],["15517.00000000","0.00748900"],["15517.25000000","0.00000000"],["15517.30000000","0.00000000"],["15517.33000000","0.00000000"],["15517.85000000","0.01700000"],["15517.87000000","0.01700000"],["15518.35000000","0.00000000"],["15518.56000000","0.00000000"],["15519.28000000","3.34100000"],["15522.71000000","0.00000000"],["15525.41000000","0.40548900"]]}}
2020-11-09T11:24:53.88754 btcusdt {"stream":"btcusdt@depth@100ms","data":{"e":"depthUpdate","E":1604921093878,"s":"BTCUSDT","U":6511123142,"u":6511123180,"b":[["15513.51000000","1.14689600"],["15513.50000000","0.00000000"],["15513.49000000","2.00000000"],["15513.23000000","0.00000000"],["15513.04000000","0.00000000"],["15513.02000000","0.00000000"],["15512.99000000","0.00000000"],["15512.27000000","0.00690000"],["15508.66000000","0.03626500"],["15439.56000000","0.00000000"],["15435.94000000","0.00647800"],["15404.19000000","0.00000000"]],"a":[["15513.52000000","5.69900000"],["15514.09000000","0.00000000"],["15514.15000000","0.00000000"],["15514.75000000","0.03941700"],["15514.81000000","0.05000000"],["15514.86000000","0.00000000"],["15514.88000000","0.00000000"],["15514.89000000","0.00000000"],["15515.10000000","0.00000000"],["15516.46000000","0.16373500"],["15516.47000000","0.00000000"],["15516.78000000","0.00000000"],["15517.60000000","0.10000000"],["15518.82000000","0.32100000"],["15524.69000000","0.25760000"],["15544.83000000","0.01200000"]]}}
2020-11-09T11:24:53.98549 btcusdt {"stream":"btcusdt@depth@100ms","data":{"e":"depthUpdate","E":1604921093978,"s":"BTCUSDT","U":6511123181,"u":6511123193,"b":[["15513.51000000","1.42381600"],["15513.49000000","0.00000000"],["15508.64000000","0.00000000"],["15508.29000000","0.05000000"],["15507.50000000","0.15680600"],["15507.49000000","0.00000000"],["15443.18000000","0.24000000"]],"a":[["15517.22000000","0.12894100"],["15517.30000000","0.12893600"],["15518.82000000","0.00000000"]]}}
2020-11-09T11:24:54.08515 btcusdt {"stream":"btcusdt@depth@100ms","data":{"e":"depthUpdate","E":1604921094079,"s":"BTCUSDT","U":6511123194,"u":6511123205,"b":[["15512.72000000","0.01383500"],["15512.22000000","0.00000000"],["15508.66000000","0.00000000"],["15507.50000000","0.00000000"],["15506.59000000","0.19307100"]],"a":[["15513.52000000","7.69900000"],["15514.10000000","2.04860600"],["15514.29000000","0.01580500"],["15516.46000000","0.00000000"],["15516.80000000","0.20000000"],["15517.92000000","0.00000000"]]}}
2020-11-09T11:24:54.18506 btcusdt {"stream":"btcusdt@depth@100ms","data":{"e":"depthUpdate","E":1604921094179,"s":"BTCUSDT","U":6511123206,"u":6511123221,"b":[["15513.03000000","0.00000000"],["15512.70000000","0.00885700"],["15480.00000000","0.09195300"],["15471.91000000","0.00000000"],["15403.56000000","0.00383000"]],"a":[["15513.52000000","2.59400000"],["15513.96000000","0.00752200"],["15514.09000000","0.16373500"],["15514.74000000","0.10000000"],["15517.00000000","0.00000000"],["15517.30000000","0.00000000"],["15517.60000000","0.00000000"],["15520.31000000","0.01500000"],["15520.80000000","0.22700000"],["15549.46000000","0.00000000"]]}}
2020-11-09T11:24:54.28580 btcusdt {"stream":"btcusdt@depth@100ms","data":{"e":"depthUpdate","E":1604921094279,"s":"BTCUSDT","U":6511123222,"u":6511123222,"b":[],"a":[["15518.34000000","0.32100000"]]}}
2020-11-09T11:24:54.38531 btcusdt {"stream":"btcusdt@depth@100ms","data":{"e":"depthUpdate","E":1604921094379,"s":"BTCUSDT","U":6511123223,"u":6511123228,"b":[["15510.18000000","0.50000000"],["15451.21000000","0.02226300"],["15420.00000000","0.59902000"]],"a":[["15514.74000000","0.00000000"],["15516.66000000","0.50000000"],["15683.91000000","0.00000000"]]}}
2020-11-09T11:24:54.48539 btcusdt {"stream":"btcusdt@depth@100ms","data":{"e":"depthUpdate","E":1604921094479,"s":"BTCUSDT","U":6511123229,"u":6511123232,"b":[["15512.72000000","0.01237600"]],"a":[["15516.73000000","0.10000000"],["15518.78000000","0.09621900"]]}}
2020-11-09T11:24:54.58577 btcusdt {"stream":"btcusdt@depth@100ms","data":{"e":"depthUpdate","E":1604921094579,"s":"BTCUSDT","U":6511123233,"u":6511123236,"b":[["15513.03000000","0.00600000"],["15512.70000000","0.00000000"]],"a":[["15513.96000000","0.00000000"],["15514.02000000","0.00713200"]]}}
2020-11-09T11:24:54.68699 btcusdt {"stream":"btcusdt@depth@100ms","data":{"e":"depthUpdate","E":1604921094679,"s":"BTCUSDT","U":6511123237,"u":6511123243,"b":[["15513.51000000","1.42581600"],["15508.66000000","0.15680600"],["15506.59000000","0.03626500"]],"a":[["15513.52000000","2.53773300"],["15676.96000000","0.00450600"]]}}
2020-11-09T11:24:54.78594 btcusdt {"stream":"btcusdt@depth@100ms","data":{"e":"depthUpdate","E":1604921094779,"s":"BTCUSDT","U":6511123244,"u":6511123246,"b":[["15508.66000000","0.00000000"],["15507.48000000","0.15680600"]],"a":[["15514.87000000","0.00000000"]]}}
2020-11-09T11:24:54.88542 btcusdt {"stream":"btcusdt@depth@100ms","data":{"e":"depthUpdate","E":1604921094879,"s":"BTCUSDT","U":6511123247,"u":6511123251,"b":[["15513.51000000","3.42581600"]],"a":[["15513.52000000","0.53773300"],["15514.09000000","0.00000000"],["15516.47000000","0.16373500"],["15516.80000000","0.00000000"]]}}
2020-11-09T11:24:54.98522 btcusdt {"stream":"btcusdt@depth@100ms","data":{"e":"depthUpdate","E":1604921094979,"s":"BTCUSDT","U":6511123252,"u":6511123258,"b":[["15513.51000000","3.43794800"],["15506.59000000","0.00000000"],["15486.63000000","0.00160000"]],"a":[["15513.52000000","0.51137900"],["15514.81000000","0.00000000"],["15528.63000000","0.00000000"],["15529.03000000","0.00000000"]]}}
2020-11-09T11:24:55.08671 btcusdt {"stream":"btcusdt@depth@100ms","data":{"e":"depthUpdate","E":1604921095079,"s":"BTCUSDT","U":6511123259,"u":6511123267,"b":[["15508.66000000","0.03626500"],["15500.01000000","0.02236400"]],"a":[["15514.09000000","0.00000000"],["15514.10000000","0.04860600"],["15514.96000000","2.44818800"],["15527.37000000","0.48374700"],["15612.00000000","0.10827300"]]}}
2020-11-09T11:24:55.18579 btcusdt {"stream":"btcusdt@depth@100ms","data":{"e":"depthUpdate","E":1604921095179,"s":"BTCUSDT","U":6511123268,"u":6511123272,"b":[["15474.73000000","0.25000000"]],"a":[["15513.52000000","0.44437900"],["15518.34000000","0.92338700"],["15552.30000000","0.25240000"]]}}
2020-11-09T11:24:55.28843 btcusdt {"stream":"btcusdt@depth@100ms","data":{"e":"depthUpdate","E":1604921095279,"s":"BTCUSDT","U":6511123273,"u":6511123279,"b":[["15512.74000000","0.01857400"],["15512.72000000","0.00000000"],["15510.19000000","0.15680600"],["15507.48000000","0.00000000"],["15396.00000000","0.48510300"]],"a":[["15514.29000000","0.00000000"],["15517.33000000","0.01526000"]]}}
2020-11-09T11:24:55.38665 btcusdt {"stream":"btcusdt@depth@100ms","data":{"e":"depthUpdate","E":1604921095379,"s":"BTCUSDT","U":6511123280,"u":6511123290,"b":[["15513.05000000","0.00761700"],["15513.03000000","0.00000000"],["15510.19000000","0.00000000"],["15509.47000000","0.15680600"]],"a":[["15513.52000000","0.44437900"],["15514.02000000","0.00000000"],["15514.96000000","2.08556300"],["15516.81000000","0.03881200"],["15518.10000000","0.20000000"]]}}
2020-11-09T11:24:55.48679 btcusdt {"stream":"btcusdt@depth@100ms","data":{"e":"depthUpdate","E":1604921095479,"s":"BTCUSDT","U":6511123291,"u":6511123307,"b":[["15513.05000000","0.00860400"],["15512.84000000","0.06192000"],["15510.19000000","0.22106300"],["15508.65000000","0.00000000"],["15506.58000000","0.00000000"]],"a":[["15513.52000000","0.13200000"],["15514.95000000","0.16373500"],["15514.96000000","2.08556300"],["15516.47000000","0.00000000"],["15518.10000000","0.00000000"],["15518.34000000","0.60238700"],["15521.06000000","1.00850100"],["15522.72000000","0.00000000"],["15570.00000000","48.91536300"]]}}
2020-11-09T11:24:55.58592 btcusdt {"stream":"btcusdt@depth@100ms","data":{"e":"depthUpdate","E":1604921095579,"s":"BTCUSDT","U":6511123308,"u":6511123317,"b":[["15513.05000000","0.00630000"],["15513.01000000","0.06192000"],["15512.84000000","0.00000000"],["15509.47000000","0.00000000"],["15508.67000000","0.15680600"],["15508.66000000","0.00000000"],["15507.28000000","0.03626500"]],"a":[["15513.52000000","0.07145200"],["15514.96000000","2.29475400"]]}}
2020-11-09T11:24:55.68753 btcusdt {"stream":"btcusdt@depth@100ms","data":{"e":"depthUpdate","E":1604921095679,"s":"BTCUSDT","U":6511123318,"u":6511123326,"b":[["15513.05000000","0.00919400"]],"a":[["15513.52000000","0.09981800"],["15514.95000000","0.00000000"],["15514.96000000","2.45849000"],["15516.47000000","0.16373500"],["15518.10000000","0.20000000"]]}}
2020-11-09T11:24:55.78579 btcusdt {"stream":"btcusdt@depth@100ms","data":{"e":"depthUpdate","E":1604921095779,"s":"BTCUSDT","U":6511123327,"u":6511123329,"b":[["15513.05000000","0.00616200"]],"a":[["15514.96000000","2.65640300"]]}}
2020-11-09T11:24:55.88714 btcusdt {"stream":"btcusdt@depth@100ms","data":{"e":"depthUpdate","E":1604921095879,"s":"BTCUSDT","U":6511123330,"u":6511123337,"b":[["15513.32000000","0.00400000"],["15508.47000000","0.00000000"],["15507.28000000","0.03626500"],["15499.33000000","0.00000000"]],"a":[["15516.47000000","0.00000000"]]}}
2020-11-09T11:24:55.98565 btcusdt {"stream":"btcusdt@depth@100ms","data":{"e":"depthUpdate","E":1604921095979,"s":"BTCUSDT","U":6511123338,"u":6511123346,"b":[["15513.00000000","2.13042200"],["15501.14000000","0.13441800"],["15443.18000000","0.00000000"]],"a":[["15514.74000000","0.26373500"],["15514.96000000","2.45849000"],["15514.97000000","0.00000000"],["15516.73000000","0.00000000"],["15517.30000000","0.12893200"]]}}
2020-11-09T11:24:56.08547 btcusdt {"stream":"btcusdt@depth@100ms","data":{"e":"depthUpdate","E":1604921096080,"s":"BTCUSDT","U":6511123347,"u":6511123349,"b":[["15513.05000000","0.00793900"]],"a":[["15518.82000000","0.32100000"]]}}
2020-11-09T11:24:56.18743 btcusdt {"stream":"btcusdt@depth@100ms","data":{"e":"depthUpdate","E":1604921096180,"s":"BTCUSDT","U":6511123350,"u":6511123375,"b":[["15513.81000000","1.03752000"],["15513.54000000","0.04082600"],["15513.53000000","0.04252700"],["15513.52000000","0.37810800"],["15513.51000000","2.43794800"],["15513.27000000","0.06192000"],["15513.14000000","0.00000000"],["15513.05000000","0.00746800"],["15513.01000000","0.00000000"],["15508.68000000","0.03626500"],["15507.28000000","0.00000000"]],"a":[["15513.52000000","0.00000000"],["15513.82000000","0.00690000"],["15514.73000000","0.00000000"],["15514.75000000","0.00000000"],["15514.96000000","0.00000000"],["15518.10000000","0.00000000"],["15522.63000000","0.00000000"],["15524.10000000","0.14374300"]]}}
2020-11-09T11:24:56.28636 btcusdt {"stream":"btcusdt@depth@100ms","data":{"e":"depthUpdate","E":1604921096280,"s":"BTCUSDT","U":6511123376,"u":6511123423,"b":[["15513.81000000","3.29588400"],["15513.54000000","0.00000000"],["15513.53000000","0.00000000"],["15513.51000000","2.13602600"],["15513.45000000","0.06192000"],["15513.37000000","0.00000000"],["15513.27000000","0.00000000"],["15513.05000000","0.00982200"],["15510.41000000","0.11427900"],["15509.93000000","0.00000000"],["15508.63000000","0.05000000"],["15508.29000000","0.00000000"],["15506.83000000","0.22500000"],["15505.98000000","0.00000000"],["15505.64000000","0.00000000"],["15396.00000000","0.37683000"]],"a":[["15513.82000000","0.00690000"],["15514.10000000","0.00000000"],["15514.74000000","0.00000000"],["15516.47000000","0.00000000"],["15516.87000000","0.00690000"],["15517.22000000","0.00000000"],["15517.30000000","0.00000000"],["15517.31000000","0.00000000"],["15517.35000000","0.11427900"],["15517.60000000","0.26373500"],["15517.63000000","0.05000000"],["15517.72000000","0.00000000"],["15518.11000000","0.00000000"],["15518.43000000","0.01000000"],["15519.68000000","0.00000000"],["15519.91000000","0.00000000"],["15520.23000000","0.01000000"],["15520.31000000","0.00000000"],["15520.63000000","0.14392500"],["16133.00000000","0.12914100"]]}}
2020-11-09T11:24:56.38718 btcusdt {"stream":"btcusdt@depth@100ms","data":{"e":"depthUpdate","E":1604921096380,"s":"BTCUSDT","U":6511123424,"u":6511123430,"b":[["15513.81000000","8.58449300"],["15513.05000000","0.00903300"],["15507.57000000","1.25000000"],["15435.94000000","0.00000000"]],"a":[["15517.65000000","0.00000000"]]}}
2020-11-09T11:24:56.48726 btcusdt {"stream":"btcusdt@depth@100ms","data":{"e":"depthUpdate","E":1604921096480,"s":"BTCUSDT","U":6511123431,"u":6511123473,"b":[["15514.99000000","1.72377400"],["15514.60000000","0.09782800"],["15514.59000000","0.02066000"],["15514.40000000","0.00690000"],["15514.19000000","0.10799700"],["15514.18000000","0.09642500"],["15514.16000000","0.09543400"],["15514.15000000","0.00000000"],["15513.91000000","0.16392500"],["15513.82000000","4.45000000"],["15513.81000000","2.30515900"],["15513.48000000","0.06192000"],["15513.45000000","0.00000000"],["15510.18000000","0.00000000"],["15505.01000000","0.00000000"],["15503.95000000","0.00294000"],["15494.90000000","0.29700000"]],"a":[["15513.82000000","0.00000000"],["15514.16000000","0.00000000"],["15515.00000000","24.11211400"],["15515.35000000","0.00000000"],["15517.85000000","0.00000000"],["15517.87000000","0.00000000"],["15518.35000000","0.01700000"],["15518.37000000","0.01700000"],["15518.70000000","0.00000000"],["15519.08000000","1.19800000"],["15519.74000000","0.00000000"],["15520.50000000","0.75000000"],["15521.25000000","0.00000000"],["15522.78000000","1.25000000"],["15524.92000000","0.00000000"],["15612.00000000","0.00000000"]]}}
2020-11-09T11:24:56.58689 btcusdt {"stream":"btcusdt@depth@100ms","data":{"e":"depthUpdate","E":1604921096580,"s":"BTCUSDT","U":6511123474,"u":6511123507,"b":[["15514.99000000","4.00185300"],["15513.81000000","2.02385800"],["15513.51000000","2.13402600"],["15513.00000000","0.13042200"],["15510.42000000","0.15680600"],["15508.67000000","0.00000000"],["15507.57000000","1.25000000"],["15506.17000000","0.29700000"],["15490.22000000","0.00000000"],["15039.00000000","0.15367800"]],"a":[["15516.81000000","0.00658100"],["15517.60000000","0.00000000"],["15517.63000000","0.00000000"],["15518.43000000","0.00000000"],["15518.69000000","0.00000000"],["15518.78000000","0.00000000"],["15518.81000000","0.05000000"],["15518.82000000","0.00000000"],["15519.61000000","0.01000000"],["15520.23000000","0.00000000"],["15520.63000000","0.12892500"],["15521.06000000","0.00000000"],["15521.41000000","0.01000000"],["15521.81000000","0.01500000"],["15522.78000000","0.00000000"],["15524.00000000","0.00000000"],["15524.75000000","0.00000000"]]}}
2020-11-09T11:24:56.68678 btcusdt {"stream":"btcusdt@depth@100ms","data":{"e":"depthUpdate","E":1604921096680,"s":"BTCUSDT","U":6511123508,"u":6511123533,"b":[["15514.99000000","3.99244700"],["15513.05000000","0.00620200"],["15511.23000000","0.11427900"],["15510.75000000","0.03222800"],["15510.41000000","0.00000000"],["15508.62000000","0.00000000"],["15507.91000000","0.12891200"],["15507.57000000","0.00000000"],["15505.98000000","1.25000000"],["15505.75000000","0.00000000"],["15503.19000000","1.00840300"],["15502.06000000","0.00000000"],["15501.68000000","0.00000000"],["15451.21000000","0.00000000"],["15399.00000000","0.48510300"],["15391.11000000","0.00000000"]],"a":[["15516.66000000","0.00000000"],["15517.35000000","0.00000000"],["15518.10000000","0.11427900"],["15518.42000000","0.03223000"],["15518.57000000","0.16373500"],["15518.77000000","0.10000000"],["15525.31000000","1.00845200"],["15525.52000000","0.00000000"]]}}
2020-11-09T11:24:56.78828 btcusdt {"stream":"btcusdt@depth@100ms","data":{"e":"depthUpdate","E":1604921096780,"s":"BTCUSDT","U":6511123534,"u":6511123545,"b":[["15513.05000000","0.00920200"],["15503.56000000","0.50420200"],["14700.00000000","59.53313900"]],"a":[["15519.77000000","0.00000000"],["15522.13000000","1.30600000"],["15523.38000000","0.00000000"],["15524.03000000","0.00000000"],["15524.36000000","1.25000000"],["15965.05000000","0.04000000"]]}}
2020-11-09T11:24:56.88798 btcusdt {"stream":"btcusdt@depth@100ms","data":{"e":"depthUpdate","E":1604921096880,"s":"BTCUSDT","U":6511123546,"u":6511123560,"b":[["15507.57000000","1.25000000"],["15505.98000000","0.00000000"],["15504.27000000","0.00000000"],["15455.42000000","0.24000000"],["15437.41000000","0.00647700"]],"a":[["15522.83000000","0.00000000"],["15524.11000000","0.00000000"],["15524.30000000","0.00000000"],["15525.40000000","0.08427700"],["15527.36000000","0.24000000"],["15560.69000000","0.00000000"],["15567.00000000","0.11938000"]]}}
2020-11-09T11:24:56.98666 btcusdt {"stream":"btcusdt@depth@100ms","data":{"e":"depthUpdate","E":1604921096980,"s":"BTCUSDT","U":6511123561,"u":6511123576,"b":[["15514.99000000","3.60607500"],["15514.20000000","0.19999900"],["15513.22000000","0.01871100"],["15512.74000000","0.00000000"],["15510.43000000","0.05000000"],["15510.19000000","0.02106400"],["15508.63000000","0.00000000"],["15506.84000000","0.00000000"],["15475.92000000","0.03100000"],["15455.42000000","0.00000000"]],"a":[["15519.82000000","0.32100000"],["15525.40000000","0.10810500"],["15562.79000000","0.03100000"],["15570.00000000","48.53853300"]]}}
2020-11-09T11:24:57.08765 btcusdt {"stream":"btcusdt@depth@100ms","data":{"e":"depthUpdate","E":1604921097080,"s":"BTCUSDT","U":6511123577,"u":6511123591,"b":[["15514.99000000","3.35607500"],["15513.82000000","0.00000000"],["15508.46000000","1.58300000"],["15501.93000000","0.10000000"],["15499.47000000","1.50000000"],["15498.30000000","0.00000000"],["15497.00000000","0.00000000"],["15460.39000000","0.24000000"],["15400.00000000","4.38912600"]],"a":[["15515.00000000","24.11611400"],["15524.36000000","0.00000000"],["15524.75000000","1.25000000"],["15649.00000000","3.27601800"]]}}
2020-11-09T11:24:57.18695 btcusdt {"stream":"btcusdt@depth@100ms","data":{"e":"depthUpdate","E":1604921097180,"s":"BTCUSDT","U":6511123592,"u":6511123597,"b":[["15514.20000000","0.00000000"],["15511.24000000","0.35680500"],["15510.42000000","0.00000000"],["15460.39000000","0.00000000"],["15396.00000000","0.00000000"]],"a":[]}}
2020-11-09T11:24:57.28734 btcusdt {"stream":"btcusdt@depth@100ms","data":{"e":"depthUpdate","E":1604921097280,"s":"BTCUSDT","U":6511123598,"u":6511123607,"b":[["15513.22000000","0.01824300"],["15513.05000000","0.00000000"],["15503.19000000","0.00000000"],["15501.59000000","1.00845200"]],"a":[["15515.77000000","0.01368600"],["15516.81000000","0.00000000"],["15517.33000000","0.00000000"],["15518.60000000","0.43026900"],["15670.16000000","0.00000000"]]}}
2020-11-09T11:24:57.38998 btcusdt {"stream":"btcusdt@depth@100ms","data":{"e":"depthUpdate","E":1604921097380,"s":"BTCUSDT","U":6511123608,"u":6511123615,"b":[["15513.30000000","0.00885600"],["15509.04000000","0.48203200"],["15504.33000000","0.00000000"],["15500.15000000","0.00000000"],["15466.88000000","0.24000000"],["15420.00000000","0.97585000"]],"a":[["15515.00000000","24.05600600"],["15515.46000000","0.00940900"]]}}
2020-11-09T11:24:57.48834 btcusdt {"stream":"btcusdt@depth@100ms","data":{"e":"depthUpdate","E":1604921097480,"s":"BTCUSDT","U":6511123616,"u":6511123621,"b":[["15514.99000000","3.35272200"],["15513.82000000","0.01431100"],["15513.22000000","0.00000000"],["15501.51000000","0.13419300"],["15466.88000000","0.00000000"]],"a":[["15527.36000000","0.00000000"]]}}
2020-11-09T11:24:57.58911 btcusdt {"stream":"btcusdt@depth@100ms","data":{"e":"depthUpdate","E":1604921097580,"s":"BTCUSDT","U":6511123622,"u":6511123640,"b":[["15514.99000000","1.35272200"],["15514.14000000","0.00699100"],["15513.30000000","0.00000000"],["15511.23000000","0.00000000"],["15510.76000000","0.11427900"],["15510.75000000","0.00000000"],["15509.04000000","0.00000000"],["15507.91000000","0.00000000"],["15507.57000000","0.00000000"],["15471.04000000","0.24000000"]],"a":[["15515.00000000","26.09690000"],["15515.46000000","0.00920700"],["15523.05000000","1.38416500"],["15524.75000000","0.00000000"],["15530.91000000","0.24000000"],["15567.00000000","0.01110700"],["15612.00000000","0.37683000"]]}}
2020-11-09T11:24:57.69383 btcusdt {"stream":"btcusdt@depth@100ms","data":{"e":"depthUpdate","E":1604921097681,"s":"BTCUSDT","U":6511123641,"u":6511123649,"b":[["15514.99000000","0.37673500"],["15514.59000000","0.00000000"],["15511.24000000","0.19999900"],["15510.44000000","0.15680600"],["15505.98000000","1.25000000"],["15503.56000000","0.00000000"],["15501.94000000","0.50422600"]],"a":[["15521.43000000","1.25000000"],["15523.05000000","0.13416500"]]}}
2020-11-09T11:24:57.78791 btcusdt {"stream":"btcusdt@depth@100ms","data":{"e":"depthUpdate","E":1604921097781,"s":"BTCUSDT","U":6511123650,"u":6511123657,"b":[["15514.99000000","0.09543400"],["15514.22000000","0.01991700"],["15513.82000000","0.00000000"]],"a":[["15518.80000000","0.20000000"],["15521.43000000","1.25000000"],["15523.05000000","0.13416500"]]}}
2020-11-09T11:24:57.89061 btcusdt {"stream":"btcusdt@depth@100ms","data":{"e":"depthUpdate","E":1604921097881,"s":"BTCUSDT","U":6511123658,"u":6511123723,"b":[["15514.99000000","0.00000000"],["15514.60000000","0.00000000"],["15514.53000000","0.01641200"],["15514.22000000","0.01491000"],["15514.19000000","0.00000000"],["15514.18000000","0.00000000"],["15514.16000000","0.00000000"],["15514.14000000","0.00000000"],["15513.91000000","0.00000000"],["15513.81000000","0.00000000"],["15513.52000000","0.34621300"],["15513.51000000","2.00000000"],["15511.24000000","0.00000000"],["15510.44000000","0.00000000"],["15509.47000000","0.19999900"],["15508.69000000","0.15680600"],["15508.68000000","0.00000000"],["15508.47000000","1.85150200"],["15507.28000000","0.03626500"],["15471.04000000","0.00000000"],["15452.70000000","0.02226100"],["15358.82000000","0.00900000"]],"a":[["15514.54000000","4.27268800"],["15514.60000000","0.84081700"],["15514.61000000","5.44866200"],["15514.81000000","0.00690000"],["15514.99000000","0.00000000"],["15515.00000000","26.05600600"],["15515.05000000","0.03853800"],["15515.36000000","0.00000000"],["15515.46000000","0.00646500"],["15515.63000000","0.00000000"],["15516.47000000","0.26373500"],["15517.61000000","0.19427900"],["15518.10000000","0.00000000"],["15518.57000000","0.00000000"],["15518.77000000","0.00000000"],["15521.43000000","0.00000000"],["15524.36000000","1.25000000"],["15530.91000000","0.00000000"],["15597.35000000","0.00000000"]]}}
2020-11-09T11:24:57.98783 btcusdt {"stream":"btcusdt@depth@100ms","data":{"e":"depthUpdate","E":1604921097981,"s":"BTCUSDT","U":6511123724,"u":6511123855,"b":[["15514.53000000","12.83536000"],["15514.22000000","0.00000000"],["15514.13000000","1.00000000"],["15514.07000000","0.00788800"],["15513.76000000","0.01235400"],["15513.53000000","0.00000000"],["15513.51000000","0.00000000"],["15513.33000000","0.00000000"],["15513.20000000","1.00000000"],["15512.39000000","2.00000000"],["15511.41000000","1.58300000"],["15511.25000000","1.59300000"],["15511.24000000","0.11427900"],["15510.79000000","0.19229100"],["15510.76000000","0.00000000"],["15510.43000000","0.00000000"],["15508.69000000","0.00000000"],["15508.47000000","0.00000000"],["15508.46000000","0.00000000"],["15508.45000000","0.05000000"],["15508.41000000","0.00000000"],["15508.28000000","0.00000000"],["15507.48000000","0.15680600"],["15507.47000000","0.00000000"],["15506.58000000","0.00000000"],["15506.17000000","0.00000000"],["15505.99000000","0.00000000"],["15505.02000000","0.90260900"],["15505.01000000","0.20000000"],["15504.97000000","0.14550000"],["15504.33000000","0.00000000"],["15503.60000000","0.00000000"],["15501.95000000","0.30311800"],["15501.60000000","0.57132300"],["15467.09000000","0.24000000"]],"a":[["15514.54000000","1.33567700"],["15514.60000000","0.05828100"],["15514.61000000","0.14866200"],["15515.05000000","0.00000000"],["15515.23000000","0.00602900"],["15515.46000000","0.00000000"],["15515.60000000","0.01546700"],["15515.77000000","0.00000000"],["15516.47000000","0.00000000"],["15516.48000000","0.00000000"],["15516.74000000","0.00000000"],["15517.23000000","0.00000000"],["15517.60000000","0.12893100"],["15517.61000000","0.11427900"],["15518.35000000","0.05000000"],["15518.37000000","0.00000000"],["15518.45000000","0.00000000"],["15518.51000000","0.28800000"],["15518.57000000","0.00000000"],["15518.59000000","0.30000000"],["15518.60000000","0.00000000"],["15518.80000000","0.00000000"],["15518.81000000","0.00000000"],["15518.86000000","0.00000000"],["15518.90000000","0.00000000"],["15519.08000000","0.00000000"],["15519.15000000","0.01000000"],["15519.22000000","0.00000000"],["15519.28000000","0.00000000"],["15519.41000000","0.00000000"],["15519.61000000","0.00000000"],["15519.62000000","0.00000000"],["15519.82000000","0.00000000"],["15519.92000000","0.00000000"],["15520.08000000","0.25757100"],["15520.11000000","0.00000000"],["15520.46000000","0.01700000"],["15520.48000000","0.01700000"],["15520.77000000","0.00000000"],["15520.95000000","0.01000000"],["15521.07000000","1.74800000"],["15521.23000000","1.00000000"],["15521.32000000","1.19800000"],["15521.35000000","0.01500000"],["15521.41000000","0.00000000"],["15521.42000000","0.00000000"],["15521.50000000","1.58300000"],["15521.66000000","1.59300000"],["15521.70000000","0.00000000"],["15521.81000000","0.00000000"],["15522.78000000","2.00000000"],["15523.09000000","0.00000000"],["15523.27000000","0.50000000"],["15523.43000000","2.00000000"],["15523.79000000","0.12000000"],["15524.10000000","0.14374300"],["15524.36000000","0.00000000"],["15524.75000000","1.25000000"],["15525.30000000","0.04805300"],["15525.40000000","0.08427700"],["15526.69000000","0.24000000"],["15527.37000000","0.00000000"],["15529.99000000","0.48374700"]]}}
2020-11-09T11:24:58.08880 btcusdt {"stream":"btcusdt@depth@100ms","data":{"e":"depthUpdate","E":1604921098081,"s":"BTCUSDT","U":6511123856,"u":6511123922,"b":[["15514.99000000","0.39900000"],["15514.60000000","15.32168000"],["15514.57000000","0.00690000"],["15514.54000000","0.00000000"],["15514.53000000","2.26800800"],["15513.85000000","0.06279800"],["15513.82000000","0.00000000"],["15513.53000000","0.02569400"],["15513.48000000","0.00000000"],["15511.25000000","1.67300000"],["15509.26000000","1.25000000"],["15507.57000000","0.00000000"],["15507.27000000","0.00000000"],["15505.98000000","0.00000000"],["15505.02000000","0.00000000"],["15504.50000000","0.14400000"],["15504.32000000","0.00000000"],["15501.95000000","0.00000000"],["15501.60000000","0.00000000"],["15467.09000000","0.00000000"],["14332.31000000","0.00000000"]],"a":[["15514.54000000","0.00000000"],["15514.60000000","0.00000000"],["15514.61000000","0.00000000"],["15514.81000000","0.00000000"],["15515.00000000","24.03969300"],["15517.60000000","0.00000000"],["15517.61000000","0.00000000"],["15518.51000000","0.00000000"],["15519.71000000","0.16373500"],["15519.99000000","0.10000000"],["15520.50000000","0.00000000"],["15522.25000000","0.75000000"],["15523.05000000","1.38416500"],["15524.33000000","0.00000000"],["15524.75000000","0.00000000"],["15526.69000000","0.00000000"],["15541.43000000","0.00000000"]]}}
2020-11-09T11:24:58.19496 btcusdt {"stream":"btcusdt@depth@100ms","data":{"e":"depthUpdate","E":1604921098181,"s":"BTCUSDT","U":6511123923,"u":6511124178,"b":[["15518.33000000","5.74561000"],["15516.78000000","2.14900000"],["15516.42000000","0.08537900"],["15516.41000000","0.08448800"],["15516.37000000","0.95638000"],["15516.36000000","0.31428900"],["15516.29000000","0.05729700"],["15516.25000000","0.05340700"],["15516.04000000","0.00000000"],["15516.03000000","0.00000000"],["15516.02000000","0.00000000"],["15516.01000000","0.03195900"],["15515.97000000","0.36841100"],["15515.75000000","8.25688500"],["15515.74000000","0.00000000"],["15515.72000000","0.07370600"],["15515.38000000","0.00000000"],["15515.37000000","0.00000000"],["15515.32000000","14.00000000"],["15515.30000000","0.29938600"],["15515.29000000","0.00000000"],["15515.24000000","0.00000000"],["15515.23000000","0.00000000"],["15515.22000000","0.00000000"],["15514.99000000","2.15226900"],["15514.80000000","0.00690000"],["15514.68000000","0.00000000"],["15514.67000000","0.00000000"],["15514.61000000","0.03268400"],["15514.60000000","0.39670400"],["15514.53000000","2.00690000"],["15514.23000000","0.00000000"],["15513.88000000","0.00000000"],["15513.85000000","0.00000000"],["15513.77000000","0.08000000"],["15513.53000000","0.00000000"],["15513.04000000","1.58300000"],["15513.00000000","0.00690000"],["15512.25000000","0.00000000"],["15512.22000000","0.00000000"],["15511.42000000","0.03626500"],["15511.41000000","0.00000000"],["15511.25000000","0.08000000"],["15509.68000000","0.30000000"],["15509.48000000","0.50000000"],["15509.15000000","0.15000000"],["15508.44000000","0.00000000"],["15508.17000000","0.14850000"],["15507.64000000","0.15150000"],["15507.51000000","0.00309000"],["15507.28000000","0.00000000"],["15505.74000000","0.00000000"],["15505.73000000","0.29400000"],["15505.01000000","0.00000000"],["15498.49000000","0.30900000"],["15495.38000000","0.00000000"],["15494.09000000","0.00000000"],["15493.16000000","0.00000000"],["15484.55000000","0.00000000"],["15465.68000000","0.24000000"],["15206.44000000","0.00174700"]],"a":[["15515.00000000","0.00000000"],["15515.08000000","0.00000000"],["15515.20000000","0.00000000"],["15515.23000000","0.00000000"],["15515.30000000","0.00000000"],["15515.32000000","0.00000000"],["15515.43000000","0.00000000"],["15515.60000000","0.00000000"],["15515.70000000","0.00000000"],["15515.71000000","0.00000000"],["15515.75000000","0.00000000"],["15515.90000000","0.00000000"],["15516.26000000","0.00000000"],["15516.75000000","0.00000000"],["15516.79000000","0.00000000"],["15516.87000000","0.00000000"],["15517.56000000","0.00000000"],["15517.62000000","0.00000000"],["15517.64000000","0.00000000"],["15517.83000000","0.00000000"],["15517.94000000","0.00000000"],["15517.96000000","0.00000000"],["15518.13000000","0.00000000"],["15518.17000000","0.00000000"],["15518.25000000","0.00000000"],["15518.34000000","0.00000000"],["15518.35000000","0.00000000"],["15518.42000000","0.00000000"],["15518.56000000","0.00000000"],["15518.58000000","0.00000000"],["15518.59000000","0.00000000"],["15518.81000000","0.00000000"],["15518.96000000","0.04999800"],["15519.15000000","0.00000000"],["15519.61000000","0.01000000"],["15519.71000000","0.00000000"],["15519.99000000","0.00000000"],["15520.46000000","0.00000000"],["15520.48000000","0.00000000"],["15520.53000000","0.00000000"],["15520.63000000","0.00000000"],["15520.95000000","0.00000000"],["15521.04000000","0.00000000"],["15521.07000000","0.00000000"],["15521.23000000","0.00000000"],["15521.32000000","0.00000000"],["15521.41000000","0.01000000"],["15521.50000000","0.00000000"],["15521.66000000","0.00000000"],["15521.73000000","0.00000000"],["15521.84000000","0.00364300"],["15521.88000000","0.00000000"],["15521.98000000","0.08000000"],["15522.05000000","0.00000000"],["15522.13000000","1.00000000"],["15522.25000000","0.00000000"],["15522.27000000","0.01700000"],["15522.29000000","0.01700000"],["15522.59000000","0.00000000"],["15522.65000000","0.00000000"],["15522.70000000","0.00000000"],["15522.78000000","0.00000000"],["15522.81000000","1.19800000"],["15522.84000000","0.00000000"],["15523.05000000","0.00000000"],["15523.26000000","0.00000000"],["15523.27000000","0.00000000"],["15523.43000000","0.00000000"],["15524.09000000","0.00000000"],["15524.12000000","0.22700000"],["15524.43000000","0.00000000"],["15524.47000000","0.00000000"],["15524.69000000","0.75760000"],["15524.75000000","1.25000000"],["15525.10000000","0.00000000"],["15527.24000000","0.24000000"],["15527.38000000","0.00000000"],["15527.62000000","0.00000000"],["15530.97000000","0.00000000"],["15535.17000000","0.15150000"],["15535.30000000","0.30000000"],["15670.14000000","0.00100000"]]}}
2020-11-09T11:24:58.29586 btcusdt {"stream":"btcusdt@depth@100ms","data":{"e":"depthUpdate","E":1604921098281,"s":"BTCUSDT","U":6511124179,"u":6511124306,"b":[["15518.95000000","7.15990600"],["15518.64000000","0.05728800"],["15518.62000000","0.05796900"],["15518.55000000","0.12352200"],["15518.48000000","0.06075600"],["15518.43000000","0.13892300"],["15518.42000000","0.12919700"],["15518.38000000","0.07207300"],["15518.34000000","2.00000000"],["15518.33000000","0.00000000"],["15518.21000000","0.00000000"],["15517.67000000","0.00000000"],["15516.78000000","0.50000000"],["15516.41000000","0.00000000"],["15516.37000000","0.00000000"],["15516.36000000","0.00000000"],["15516.29000000","0.00000000"],["15516.25000000","0.00000000"],["15516.01000000","0.00000000"],["15515.97000000","0.00000000"],["15515.78000000","0.08000000"],["15515.76000000","0.14000000"],["15515.75000000","5.30128800"],["15515.72000000","0.00000000"],["15515.23000000","6.08652600"],["15514.99000000","2.02874700"],["15514.85000000","0.04000000"],["15514.60000000","0.21670400"],["15514.13000000","1.58300000"],["15513.97000000","0.48000000"],["15513.52000000","1.65892800"],["15513.20000000","0.00000000"],["15513.07000000","0.15300000"],["15513.04000000","0.00000000"],["15512.44000000","0.19275400"],["15512.39000000","0.00000000"],["15512.04000000","0.15150000"],["15511.85000000","1.25000000"],["15511.14000000","0.00309000"],["15509.26000000","0.00000000"],["15509.00000000","0.00000000"],["15503.59000000","0.00000000"],["15502.10000000","0.30300000"],["15501.93000000","0.00000000"],["15501.14000000","0.00000000"],["15500.35000000","0.00000000"],["15499.97000000","0.00000000"],["15499.80000000","0.00000000"],["15499.76000000","0.00000000"],["15499.31000000","0.00000000"],["15497.26000000","0.00000000"],["15465.68000000","0.00000000"]],"a":[["15518.96000000","0.00000000"],["15519.30000000","0.01566300"],["15520.08000000","0.00000000"],["15520.94000000","0.00000000"],["15521.35000000","0.00000000"],["15521.41000000","0.00000000"],["15521.50000000","0.10000000"],["15521.64000000","0.30000000"],["15522.13000000","0.00000000"],["15522.27000000","0.00000000"],["15522.29000000","0.00000000"],["15522.66000000","0.00000000"],["15522.81000000","0.00000000"],["15522.84000000","0.01700000"],["15523.05000000","0.03222000"],["15523.29000000","0.11427900"],["15523.38000000","0.00000000"],["15523.39000000","0.01700000"],["15523.40000000","0.00000000"],["15523.61000000","0.00000000"],["15523.74000000","0.00000000"],["15523.78000000","0.16373500"],["15523.79000000","0.00000000"],["15524.17000000","1.74800000"],["15524.32000000","1.58300000"],["15524.66000000","1.59300000"],["15524.69000000","0.25760000"],["15524.75000000","0.00000000"],["15524.92000000","0.00000000"],["15525.18000000","0.00000000"],["15525.26000000","0.01000000"],["15525.31000000","0.00000000"],["15525.42000000","0.00000000"],["15525.66000000","0.76500000"],["15525.74000000","0.50000000"],["15525.75000000","0.00000000"],["15526.01000000","0.12887900"],["15526.37000000","0.92224400"],["15526.42000000","0.00000000"],["15526.60000000","1.50000000"],["15527.24000000","0.00000000"],["15527.74000000","0.28040800"],["15528.58000000","0.00000000"],["15531.02000000","0.30600000"],["15533.11000000","1.04458100"],["15585.00000000","0.44541400"]]}}
2020-11-09T11:24:58.38959 btcusdt {"stream":"btcusdt@depth@100ms","data":{"e":"depthUpdate","E":1604921098381,"s":"BTCUSDT","U":6511124307,"u":6511124384,"b":[["15519.29000000","8.18377100"],["15519.10000000","0.07307100"],["15519.02000000","0.05492200"],["15519.01000000","0.04509900"],["15518.98000000","0.04461200"],["15518.96000000","0.03626500"],["15518.95000000","0.05579700"],["15518.82000000","0.07340800"],["15518.65000000","0.00000000"],["15518.64000000","0.00000000"],["15518.62000000","0.00000000"],["15518.57000000","0.00000000"],["15518.48000000","0.00000000"],["15518.43000000","0.00000000"],["15518.42000000","0.00000000"],["15518.38000000","0.00000000"],["15516.75000000","0.11427900"],["15516.42000000","0.00000000"],["15515.76000000","0.19000000"],["15515.75000000","0.38128800"],["15514.36000000","1.59300000"],["15511.42000000","0.00000000"],["15511.24000000","0.00000000"],["15509.48000000","0.00000000"],["15508.45000000","0.00000000"],["15505.74000000","1.60000000"],["15504.96000000","0.00000000"],["15503.82000000","0.30000000"],["15501.32000000","0.00000000"],["15499.66000000","0.00000000"],["15499.47000000","0.00000000"],["15496.66000000","0.00000000"],["15494.39000000","0.00000000"],["15488.20000000","0.00000000"],["15470.94000000","0.24000000"],["15437.41000000","0.00000000"]],"a":[["15519.61000000","0.00000000"],["15520.15000000","0.12800000"],["15520.80000000","0.00000000"],["15521.22000000","0.00000000"],["15521.98000000","0.00000000"],["15522.29000000","0.25755400"],["15522.64000000","0.00000000"],["15522.84000000","0.00000000"],["15522.89000000","0.00000000"],["15523.42000000","0.01700000"],["15523.58000000","0.00000000"],["15523.71000000","0.04000000"],["15523.78000000","0.00000000"],["15523.86000000","0.01000000"],["15524.30000000","0.00000000"],["15524.91000000","1.19800000"],["15525.26000000","0.00000000"],["15525.43000000","0.00000000"],["15525.55000000","1.25000000"],["15525.66000000","0.77500000"],["15525.68000000","1.00000000"],["15525.74000000","0.00000000"],["15526.23000000","0.25759200"],["15526.45000000","0.50000000"],["15527.04000000","0.00000000"],["15527.84000000","0.25758000"],["15528.21000000","1.01514700"],["15531.64000000","0.24000000"],["15537.55000000","0.14850000"],["15537.66000000","0.28800000"],["15573.00000000","0.17227700"]]}}
2020-11-09T11:24:58.48881 btcusdt {"stream":"btcusdt@depth@100ms","data":{"e":"depthUpdate","E":1604921098481,"s":"BTCUSDT","U":6511124385,"u":6511124412,"b":[["15519.29000000","8.44487900"],["15518.96000000","0.00000000"],["15518.34000000","0.00000000"],["15516.79000000","0.19732900"],["15515.76000000","0.05000000"],["15514.80000000","0.01090000"],["15513.78000000","0.06738200"],["15510.90000000","0.14700000"],["15510.19000000","0.00000000"],["15507.48000000","0.00000000"],["15502.69000000","0.13427200"],["15501.68000000","1.50000000"],["15496.86000000","0.00000000"]],"a":[["15519.30000000","2.01566300"],["15521.50000000","0.00000000"],["15521.64000000","0.00000000"],["15524.29000000","0.00000000"],["15524.31000000","0.00000000"],["15524.65000000","0.10000000"],["15525.77000000","0.50201100"],["15527.19000000","0.00000000"],["15528.00000000","0.00000000"],["15528.28000000","0.00000000"],["15531.29000000","0.15450000"],["15612.00000000","0.48510300"]]}}
2020-11-09T11:24:58.59115 btcusdt {"stream":"btcusdt@depth@100ms","data":{"e":"depthUpdate","E":1604921098581,"s":"BTCUSDT","U":6511124413,"u":6511124440,"b":[["15519.29000000","12.49487900"],["15519.10000000","0.00000000"],["15519.02000000","0.00000000"],["15519.01000000","0.00000000"],["15518.98000000","0.00000000"],["15518.95000000","0.00000000"],["15516.78000000","0.00000000"],["15515.75000000","0.08128800"],["15513.78000000","0.00000000"],["15505.97000000","0.20000000"],["15503.82000000","0.00000000"],["15501.86000000","0.06723900"],["15501.68000000","0.00000000"]],"a":[["15519.30000000","1.91112300"],["15520.15000000","0.00000000"],["15521.76000000","0.00000000"],["15523.29000000","0.00000000"],["15523.76000000","0.00000000"],["15525.55000000","0.00000000"],["15525.61000000","0.10000000"],["15525.66000000","0.02500000"],["15525.99000000","0.30000000"],["15526.31000000","1.25000000"],["15526.33000000","0.75000000"],["15526.60000000","0.00000000"],["15527.73000000","0.00137900"],["15531.64000000","0.00000000"],["15537.76000000","0.24000000"]]}}
2020-11-09T11:24:58.69678 btcusdt {"stream":"btcusdt@depth@100ms","data":{"e":"depthUpdate","E":1604921098681,"s":"BTCUSDT","U":6511124441,"u":6511124461,"b":[["15519.29000000","1.30883300"],["15516.80000000","0.35680500"],["15516.79000000","0.02106400"],["15515.79000000","0.03626500"],["15513.52000000","0.65521300"],["15509.47000000","0.00000000"],["15507.36000000","0.30000000"]],"a":[["15519.30000000","7.21112300"],["15523.42000000","0.18073500"],["15524.37000000","0.11427900"],["15526.45000000","0.00000000"],["15526.89000000","0.50690000"],["15529.32000000","0.10771300"],["15530.83000000","0.36964900"],["15537.76000000","0.00000000"]]}}
2020-11-09T11:24:58.79099 btcusdt {"stream":"btcusdt@depth@100ms","data":{"e":"depthUpdate","E":1604921098781,"s":"BTCUSDT","U":6511124462,"u":6511124478,"b":[["15519.29000000","1.07682200"],["15513.76000000","0.00000000"],["15513.68000000","0.01964500"],["15508.57000000","0.01900000"],["15505.91000000","1.50000000"],["15496.24000000","0.00000000"]],"a":[["15519.30000000","7.28100400"],["15522.29000000","0.00000000"],["15526.83000000","0.13419500"],["15527.19000000","0.01382400"],["15527.98000000","0.30000000"],["15528.52000000","0.04050600"],["15528.71000000","1.50000000"],["15529.71000000","0.15150000"],["15531.39000000","0.25753500"],["15534.60000000","0.06723800"]]}}
2020-11-09T11:24:58.88938 btcusdt {"stream":"btcusdt@depth@100ms","data":{"e":"depthUpdate","E":1604921098881,"s":"BTCUSDT","U":6511124479,"u":6511124495,"b":[["15519.29000000","0.77748200"],["15511.85000000","0.00000000"],["15511.26000000","1.25000000"],["15501.39000000","1.20343300"],["15441.69000000","0.00647500"]],"a":[["15519.30000000","7.22099000"],["15524.12000000","0.54800000"],["15524.87000000","0.00000000"],["15526.83000000","0.00000000"],["15528.98000000","0.00000000"],["15530.44000000","0.05681600"],["15532.39000000","0.00000000"],["15541.24000000","0.31800000"]]}}
2020-11-09T11:24:58.99084 btcusdt {"stream":"btcusdt@depth@100ms","data":{"e":"depthUpdate","E":1604921098981,"s":"BTCUSDT","U":6511124496,"u":6511124522,"b":[["15519.29000000","2.77748200"],["15515.76000000","0.00000000"],["15515.33000000","0.05000000"],["15514.30000000","0.00600200"],["15514.07000000","0.00000000"],["15513.52000000","0.30900000"],["15512.46000000","0.25754200"],["15511.92000000","0.41964800"],["15511.03000000","0.25755400"],["15509.36000000","0.25760000"],["15470.94000000","0.00000000"]],"a":[["15519.30000000","5.30000000"],["15519.76000000","0.01300200"],["15520.18000000","0.14000000"],["15521.64000000","0.41912900"],["15524.16000000","0.05000000"],["15525.40000000","0.02551800"],["15525.41000000","0.00000000"],["15527.98000000","0.00000000"],["15529.98000000","0.02907100"],["15533.75000000","0.13428500"],["15547.62000000","0.00000000"]]}}
2020-11-09T11:24:59.09030 btcusdt {"stream":"btcusdt@depth@100ms","data":{"e":"depthUpdate","E":1604921099081,"s":"BTCUSDT","U":6511124523,"u":6511124541,"b":[["15519.29000000","3.56843100"],["15452.70000000","0.00000000"]],"a":[["15520.18000000","0.00000000"],["15521.64000000","0.00000000"],["15524.37000000","0.00000000"],["15525.30000000","0.00000000"],["15525.40000000","0.00000000"],["15529.99000000","0.05391300"],["15532.69000000","0.02382800"],["15536.06000000","0.40548900"],["15537.09000000","0.45568200"],["15539.99000000","0.02806500"],["15542.72000000","0.24000000"],["15596.66000000","0.02205600"],["15615.00000000","8.36685100"]]}}
2020-11-09T11:24:59.19002 btcusdt {"stream":"btcusdt@depth@100ms","data":{"e":"depthUpdate","E":1604921099181,"s":"BTCUSDT","U":6511124542,"u":6511124552,"b":[["15487.60000000","0.00000000"]],"a":[["15519.30000000","5.30200000"],["15522.10000000","0.00000000"],["15523.86000000","0.00000000"],["15524.15000000","0.01000000"],["15525.66000000","0.01000000"],["15526.06000000","0.01500000"],["15529.57000000","0.13418500"],["15532.39000000","0.23534300"],["15532.69000000","0.04934600"]]}}
2020-11-09T11:24:59.29147 btcusdt {"stream":"btcusdt@depth@100ms","data":{"e":"depthUpdate","E":1604921099281,"s":"BTCUSDT","U":6511124553,"u":6511124564,"b":[["15518.84000000","0.07827400"],["15518.82000000","0.00000000"],["15515.32000000","0.00000000"],["15501.59000000","0.00000000"],["15491.23000000","0.24000000"]],"a":[["15519.30000000","0.00200000"],["15519.71000000","0.05650300"],["15519.99000000","2.06795400"],["15523.13000000","0.08000000"],["15529.30000000","0.10830700"],["15542.72000000","0.00000000"],["15570.00000000","48.43026000"]]}}
2020-11-09T11:24:59.39119 btcusdt {"stream":"btcusdt@depth@100ms","data":{"e":"depthUpdate","E":1604921099381,"s":"BTCUSDT","U":6511124565,"u":6511124585,"b":[["15519.29000000","3.56733800"],["15516.80000000","0.19999900"],["15516.41000000","0.50000000"],["15515.80000000","0.15680600"],["15515.33000000","0.00000000"],["15515.24000000","0.05000000"],["15515.23000000","0.00000000"],["15505.11000000","1.00807900"]],"a":[["15519.30000000","5.30200000"],["15519.71000000","0.00000000"],["15519.99000000","0.00000000"],["15522.46000000","0.50000000"],["15524.11000000","0.05000000"],["15524.15000000","0.00000000"],["15524.16000000","0.00000000"],["15524.18000000","0.01000000"],["15525.58000000","0.20000000"],["15525.66000000","0.00000000"],["15525.98000000","0.01000000"],["15527.68000000","0.30600000"],["15538.88000000","0.24000000"]]}}
2020-11-09T11:24:59.48973 btcusdt {"stream":"btcusdt@depth@100ms","data":{"e":"depthUpdate","E":1604921099482,"s":"BTCUSDT","U":6511124586,"u":6511124602,"b":[["15515.79000000","0.00000000"],["15514.62000000","0.03626500"],["15513.52000000","0.00000000"],["15510.90000000","0.00000000"],["15499.85000000","0.87000000"],["15491.94000000","0.00000000"],["15100.00000000","50.51469400"],["15000.00000000","214.13257100"]],"a":[["15519.72000000","0.00000000"],["15521.83000000","0.00000000"],["15523.38000000","0.10000000"],["15524.10000000","0.24374300"],["15524.12000000","0.22700000"],["15524.65000000","0.00000000"],["15527.90000000","0.14400000"],["15528.21000000","0.00690000"],["15530.86000000","1.00807900"]]}}
2020-11-09T11:24:59.59160 btcusdt {"stream":"btcusdt@depth@100ms","data":{"e":"depthUpdate","E":1604921099582,"s":"BTCUSDT","U":6511124603,"u":6511124615,"b":[["15519.29000000","6.61733800"],["15518.67000000","0.00766900"],["15514.62000000","0.00000000"],["15514.60000000","0.23611800"],["15514.30000000","0.00000000"],["15513.68000000","0.00000000"],["15512.47000000","0.03626500"],["15499.57000000","0.00000000"]],"a":[["15519.30000000","5.24156600"],["15519.76000000","0.00690000"],["15520.07000000","0.01626800"],["15522.21000000","0.00700900"],["15523.77000000","0.11427900"]]}}
2020-11-09T11:24:59.69420 btcusdt {"stream":"btcusdt@depth@100ms","data":{"e":"depthUpdate","E":1604921099682,"s":"BTCUSDT","U":6511124616,"u":6511124619,"b":[["15519.29000000","3.55193900"],["15505.47000000","0.50403900"],["15501.94000000","0.00000000"]],"a":[]}}
2020-11-09T11:24:59.78999 btcusdt {"stream":"btcusdt@depth@100ms","data":{"e":"depthUpdate","E":1604921099782,"s":"BTCUSDT","U":6511124620,"u":6511124632,"b":[["15519.29000000","3.55393900"],["15518.83000000","0.00975600"],["15518.67000000","0.00000000"],["15518.52000000","0.01572800"],["15514.60000000","0.21670400"],["15514.14000000","0.06732600"],["15503.97000000","0.20000000"],["15500.01000000","0.00000000"]],"a":[["15519.30000000","5.24356600"],["15520.07000000","0.00000000"],["15522.21000000","0.00000000"],["15522.76000000","0.00917600"],["15524.28000000","0.01632100"]]}}
2020-11-09T11:24:59.89100 btcusdt {"stream":"btcusdt@depth@100ms","data":{"e":"depthUpdate","E":1604921099882,"s":"BTCUSDT","U":6511124633,"u":6511124643,"b":[["15517.23000000","0.04000000"],["15505.92000000","0.02236400"],["15500.88000000","0.00000000"],["15500.00000000","14.39045700"],["15399.00000000","0.37683000"]],"a":[["15522.52000000","0.00778700"],["15522.76000000","0.00000000"],["15524.12000000","0.24487000"],["15524.28000000","0.00000000"],["15530.44000000","0.00000000"],["15530.87000000","0.05681600"]]}}
2020-11-09T11:24:59.99003 btcusdt {"stream":"btcusdt@depth@100ms","data":{"e":"depthUpdate","E":1604921099982,"s":"BTCUSDT","U":6511124644,"u":6511124654,"b":[["15519.10000000","0.00200000"],["15515.24000000","0.00000000"],["15514.54000000","0.05000000"]],"a":[["15522.95000000","0.22500100"],["15524.09000000","0.21110100"],["15524.11000000","0.00000000"],["15524.12000000","0.56587000"],["15528.04000000","0.20000000"],["15533.11000000","0.00000000"],["15538.88000000","0.00000000"]]}}
2020-11-09T11:25:00.08897 btcusdt {"stream":"btcusdt@depth@100ms","data":{"e":"depthUpdate","E":1604921100082,"s":"BTCUSDT","U":6511124655,"u":6511124662,"b":[["15505.91000000","0.00000000"],["15503.51000000","1.50000000"],["15420.00000000","1.08412300"]],"a":[["15522.46000000","0.99909100"],["15525.68000000","0.00000000"],["15529.03000000","1.00000000"],["15534.82000000","1.15736600"],["15537.93000000","0.24000000"]]}}
2020-11-09T11:25:00.19085 btcusdt {"stream":"btcusdt@depth@100ms","data":{"e":"depthUpdate","E":1604921100182,"s":"BTCUSDT","U":6511124663,"u":6511124669,"b":[["15510.00000000","0.00696100"],["15474.73000000","0.00000000"]],"a":[["15524.12000000","0.54800000"],["15524.30000000","0.01903800"],["15526.06000000","0.00000000"],["15526.38000000","0.01500000"],["15552.30000000","0.00240000"]]}}
2020-11-09T11:25:00.28896 btcusdt {"stream":"btcusdt@depth@100ms","data":{"e":"depthUpdate","E":1604921100282,"s":"BTCUSDT","U":6511124670,"u":6511124681,"b":[["15517.23000000","0.00000000"],["15514.61000000","0.00000000"],["15514.60000000","0.00000000"],["15441.46000000","0.02227700"]],"a":[["15522.52000000","0.00000000"],["15522.73000000","0.00835800"],["15523.77000000","0.00000000"],["15524.91000000","0.00000000"],["15530.04000000","0.20000000"],["15585.00000000","0.55368700"]]}}
2020-11-09T11:25:00.39058 btcusdt {"stream":"btcusdt@depth@100ms","data":{"e":"depthUpdate","E":1604921100382,"s":"BTCUSDT","U":6511124682,"u":6511124693,"b":[["15519.29000000","3.55475100"],["15515.78000000","0.00000000"],["15515.75000000","0.00128800"],["15514.41000000","0.04000000"],["15513.97000000","0.00000000"],["15512.45000000","0.24000000"],["15512.44000000","0.00000000"],["15512.04000000","0.00000000"]],"a":[["15519.30000000","5.18142900"],["15521.64000000","0.08000000"],["15524.28000000","1.19800000"],["15526.26000000","0.14400000"]]}}
2020-11-09T11:25:00.48958 btcusdt {"stream":"btcusdt@depth@100ms","data":{"e":"depthUpdate","E":1604921100482,"s":"BTCUSDT","U":6511124694,"u":6511124701,"b":[["15516.81000000","0.02589200"],["15511.04000000","0.20000000"],["15399.00000000","0.00000000"]],"a":[["15522.10000000","1.00000000"],["15523.04000000","0.01000000"],["15523.71000000","0.00000000"],["15524.09000000","0.05000000"],["15524.18000000","0.02000000"]]}}
2020-11-09T11:25:00.58840 btcusdt {"stream":"btcusdt@depth@100ms","data":{"e":"depthUpdate","E":1604921100582,"s":"BTCUSDT","U":6511124702,"u":6511124707,"b":[["15514.58000000","0.08000000"],["15511.04000000","0.00000000"],["15217.67000000","0.00000000"],["14420.93000000","0.00000000"]],"a":[["15524.30000000","0.00000000"],["15622.00000000","0.00000000"]]}}
2020-11-09T11:25:00.69268 btcusdt {"stream":"btcusdt@depth@100ms","data":{"e":"depthUpdate","E":1604921100682,"s":"BTCUSDT","U":6511124708,"u":6511124714,"b":[["15512.96000000","1.11600800"]],"a":[["15522.09000000","0.10000000"],["15522.46000000","0.50000000"],["15522.66000000","0.00797500"],["15522.73000000","0.00000000"],["15523.38000000","0.00000000"],["15524.06000000","0.01278800"]]}}
2020-11-09T11:25:00.78961 btcusdt {"stream":"btcusdt@depth@100ms","data":{"e":"depthUpdate","E":1604921100782,"s":"BTCUSDT","U":6511124715,"u":6511124723,"b":[["15423.00000000","0.37683000"],["15197.75000000","0.03289900"],["14423.13000000","0.17333200"]],"a":[["15522.08000000","0.16373500"],["15522.10000000","0.00000000"],["15523.16000000","0.11427900"],["15523.42000000","0.01700000"],["15523.68000000","0.12000000"],["15625.50000000","0.06408100"]]}}
2020-11-09T11:25:00.89765 btcusdt {"stream":"btcusdt@depth@100ms","data":{"e":"depthUpdate","E":1604921100882,"s":"BTCUSDT","U":6511124724,"u":6511124726,"b":[],"a":[["15525.58000000","0.00000000"],["17842.58000000","0.01910000"],["17847.18000000","0.90120000"]]}}
2020-11-09T11:25:00.98912 btcusdt {"stream":"btcusdt@depth@100ms","data":{"e":"depthUpdate","E":1604921100982,"s":"BTCUSDT","U":6511124727,"u":6511124733,"b":[["15519.29000000","3.55417000"]],"a":[["15519.30000000","5.14166100"],["15523.84000000","0.05000000"],["15524.08000000","0.12887700"],["15524.09000000","0.00000000"],["15527.56000000","0.30000000"]]}}
2020-11-09T11:25:01.08888 btcusdt {"stream":"btcusdt@depth@100ms","data":{"e":"depthUpdate","E":1604921101082,"s":"BTCUSDT","U":6511124734,"u":6511124738,"b":[["15519.29000000","1.25757000"]],"a":[["15519.30000000","7.14166100"],["15524.65000000","0.20000000"],["17842.58000000","0.00500000"]]}}
2020-11-09T11:25:01.18920 btcusdt {"stream":"btcusdt@depth@100ms","data":{"e":"depthUpdate","E":1604921101182,"s":"BTCUSDT","U":6511124739,"u":6511124746,"b":[["15519.29000000","0.41889600"],["15514.99000000","2.00000000"],["15513.07000000","0.00000000"],["15494.10000000","0.00000000"],["15480.50000000","0.25000000"],["15206.44000000","0.00000000"]],"a":[["15519.30000000","7.64166100"]]}}
2020-11-09T11:25:01.29197 btcusdt {"stream":"btcusdt@depth@100ms","data":{"e":"depthUpdate","E":1604921101282,"s":"BTCUSDT","U":6511124747,"u":6511124757,"b":[["15516.81000000","0.00000000"],["15515.30000000","0.00000000"],["15514.86000000","0.02588900"],["15512.48000000","0.50000000"],["15511.14000000","0.00000000"],["15502.10000000","0.00000000"],["15436.51000000","0.00000000"]],"a":[["15519.30000000","7.58133900"],["15520.99000000","0.30373500"],["15522.08000000","0.00000000"]]}}
2020-11-09T11:25:01.38888 btcusdt {"stream":"btcusdt@depth@100ms","data":{"e":"depthUpdate","E":1604921101383,"s":"BTCUSDT","U":6511124758,"u":6511124767,"b":[["15519.29000000","0.41983200"],["15515.80000000","0.00000000"],["15515.00000000","0.15680600"],["15508.21000000","0.10000000"],["15505.74000000","1.50000000"],["15437.51000000","0.66963000"],["14800.00000000","91.36979600"]],"a":[["15523.04000000","0.00000000"],["15558.09000000","0.25000000"],["17847.18000000","0.91530000"]]}}
2020-11-09T11:25:01.48939 btcusdt {"stream":"btcusdt@depth@100ms","data":{"e":"depthUpdate","E":1604921101483,"s":"BTCUSDT","U":6511124768,"u":6511124772,"b":[["15519.29000000","0.42318000"]],"a":[["15523.68000000","0.00000000"],["15523.83000000","0.00325900"],["15585.28000000","0.00080000"]]}}
2020-11-09T11:25:01.58994 btcusdt {"stream":"btcusdt@depth@100ms","data":{"e":"depthUpdate","E":1604921101583,"s":"BTCUSDT","U":6511124773,"u":6511124782,"b":[["15516.75000000","0.00000000"],["15516.26000000","0.11427900"]],"a":[["15519.99000000","0.16373500"],["15520.99000000","0.14000000"],["15522.10000000","1.00000000"],["15522.60000000","0.00736400"],["15522.66000000","0.00000000"],["15522.67000000","0.11427900"],["15523.16000000","0.00000000"],["15596.66000000","0.00000000"]]}}
2020-11-09T11:25:01.69033 btcusdt {"stream":"btcusdt@depth@100ms","data":{"e":"depthUpdate","E":1604921101683,"s":"BTCUSDT","U":6511124783,"u":6511124785,"b":[["15519.29000000","0.27712300"]],"a":[["15522.19000000","0.47342300"],["17842.58000000","0.00000000"]]}}
2020-11-09T11:25:01.79267 btcusdt {"stream":"btcusdt@depth@100ms","data":{"e":"depthUpdate","E":1604921101783,"s":"BTCUSDT","U":6511124786,"u":6511124797,"b":[["15519.29000000","0.00002400"],["15518.84000000","0.00000000"],["15516.79000000","0.00000000"],["15511.27000000","0.02106400"],["15503.51000000","0.00000000"],["15500.65000000","1.50000000"]],"a":[["15519.30000000","7.07933900"],["15519.72000000","0.01547000"],["15519.75000000","0.16000000"],["15615.00000000","8.47512400"],["25000.00000000","20.89396300"]]}}
2020-11-09T11:25:01.89274 btcusdt {"stream":"btcusdt@depth@100ms","data":{"e":"depthUpdate","E":1604921101883,"s":"BTCUSDT","U":6511124798,"u":6511124815,"b":[["15519.29000000","0.87096500"],["15518.56000000","0.07907500"],["15514.54000000","0.00000000"],["15500.82000000","1.50000000"],["15500.65000000","0.00000000"]],"a":[["15519.30000000","7.88365300"],["15519.72000000","0.00000000"],["15523.61000000","0.01000000"],["15523.84000000","0.00000000"],["15524.18000000","0.01000000"],["15525.41000000","0.01000000"],["15525.81000000","0.01500000"],["15525.98000000","0.00000000"],["15526.38000000","0.00000000"],["15530.37000000","0.05681600"],["15530.87000000","0.00000000"]]}}
2020-11-09T11:25:01.99025 btcusdt {"stream":"btcusdt@depth@100ms","data":{"e":"depthUpdate","E":1604921101983,"s":"BTCUSDT","U":6511124816,"u":6511124834,"b":[["15519.29000000","1.10443900"],["15516.42000000","0.02799400"],["15514.37000000","0.05000000"],["15500.82000000","0.00000000"]],"a":[["15519.30000000","7.72933900"],["15519.49000000","0.00200000"],["15520.99000000","0.00000000"],["15523.26000000","0.05000000"],["15523.83000000","0.00000000"],["15524.10000000","0.10000000"],["15528.28000000","0.03355300"],["15549.80000000","0.26226700"],["15553.83000000","0.25000000"],["17847.18000000","0.92030000"],["25000.00000000","20.89296300"]]}}
2020-11-09T11:25:02.08972 btcusdt {"stream":"btcusdt@depth@100ms","data":{"e":"depthUpdate","E":1604921102083,"s":"BTCUSDT","U":6511124835,"u":6511124843,"b":[["15519.29000000","0.35262900"],["15516.81000000","0.02799400"],["15516.42000000","0.00000000"],["15469.00000000","0.00000000"]],"a":[["15519.30000000","7.66867900"],["15519.75000000","0.00000000"],["15528.89000000","0.14377500"],["15537.93000000","0.00000000"]]}}
2020-11-09T11:25:02.18951 btcusdt {"stream":"btcusdt@depth@100ms","data":{"e":"depthUpdate","E":1604921102183,"s":"BTCUSDT","U":6511124844,"u":6511124845,"b":[["15516.81000000","0.00000000"]],"a":[["15615.00000000","8.09829400"]]}}
2020-11-09T11:25:02.29123 btcusdt {"stream":"btcusdt@depth@100ms","data":{"e":"depthUpdate","E":1604921102283,"s":"BTCUSDT","U":6511124846,"u":6511124851,"b":[["15500.87000000","0.00000000"],["15491.23000000","0.00000000"]],"a":[["15519.30000000","7.66802800"],["15522.10000000","0.00000000"],["15523.28000000","0.04000000"]]}}
2020-11-09T11:25:02.39187 btcusdt {"stream":"btcusdt@depth@100ms","data":{"e":"depthUpdate","E":1604921102383,"s":"BTCUSDT","U":6511124852,"u":6511124853,"b":[["15287.39000000","0.00000000"]],"a":[["15573.00000000","0.54910700"]]}}
2020-11-09T11:25:02.49001 btcusdt {"stream":"btcusdt@depth@100ms","data":{"e":"depthUpdate","E":1604921102483,"s":"BTCUSDT","U":6511124854,"u":6511124857,"b":[["15502.87000000","0.00000000"],["15500.62000000","0.00000000"],["15289.54000000","0.00100000"]],"a":[["15519.49000000","0.00400000"]]}}
2020-11-09T11:25:02.59022 btcusdt {"stream":"btcusdt@depth@100ms","data":{"e":"depthUpdate","E":1604921102583,"s":"BTCUSDT","U":6511124858,"u":6511124859,"b":[["15519.29000000","0.33973700"]],"a":[["15519.30000000","7.73043000"]]}}
2020-11-09T11:25:02.68992 btcusdt {"stream":"btcusdt@depth@100ms","data":{"e":"depthUpdate","E":1604921102683,"s":"BTCUSDT","U":6511124860,"u":6511124869,"b":[["15519.29000000","0.33973700"],["15518.55000000","0.00000000"],["15515.01000000","0.02106400"],["15511.27000000","0.00000000"],["15473.50000000","2.00000000"]],"a":[["15523.62000000","0.00000000"],["15524.06000000","0.00000000"],["15549.76000000","0.00000000"]]}}
2020-11-09T11:25:02.79110 btcusdt {"stream":"btcusdt@depth@100ms","data":{"e":"depthUpdate","E":1604921102783,"s":"BTCUSDT","U":6511124870,"u":6511124874,"b":[["15505.31000000","0.03360400"]],"a":[["15523.98000000","0.01887000"],["15524.07000000","0.00326000"],["15585.92000000","0.00963200"],["15612.17000000","0.02203400"]]}}
2020-11-09T11:25:02.89124 btcusdt {"stream":"btcusdt@depth@100ms","data":{"e":"depthUpdate","E":1604921102883,"s":"BTCUSDT","U":6511124875,"u":6511124880,"b":[["15511.26000000","0.00000000"],["15508.80000000","1.25000000"]],"a":[["15519.30000000","7.67042600"],["15524.07000000","0.00000000"],["15529.87000000","0.05681600"],["15530.37000000","0.00000000"]]}}
2020-11-09T11:25:02.99014 btcusdt {"stream":"btcusdt@depth@100ms","data":{"e":"depthUpdate","E":1604921102983,"s":"BTCUSDT","U":6511124881,"u":6511124892,"b":[["15514.42000000","0.05000000"],["15514.37000000","0.00000000"],["15512.47000000","0.00000000"],["15511.26000000","0.03626500"],["15509.69000000","0.20000000"],["15490.50000000","0.24000000"]],"a":[["15523.26000000","0.00000000"],["15523.38000000","0.05000000"],["15523.97000000","0.00000000"],["15535.30000000","0.54000000"],["15622.08000000","0.00000000"]]}}
2020-11-09T11:25:03.09039 btcusdt {"stream":"btcusdt@depth@100ms","data":{"e":"depthUpdate","E":1604921103084,"s":"BTCUSDT","U":6511124893,"u":6511124897,"b":[["15497.63000000","0.14497500"],["15477.43000000","0.00000000"]],"a":[["15522.20000000","0.11427900"],["15522.67000000","0.00000000"],["15523.38000000","0.17888200"]]}}
2020-11-09T11:25:03.19033 btcusdt {"stream":"btcusdt@depth@100ms","data":{"e":"depthUpdate","E":1604921103184,"s":"BTCUSDT","U":6511124898,"u":6511124899,"b":[],"a":[["15523.65000000","2.00000000"],["15524.28000000","3.19800000"]]}}
2020-11-09T11:25:03.28960 btcusdt {"stream":"btcusdt@depth@100ms","data":{"e":"depthUpdate","E":1604921103284,"s":"BTCUSDT","U":6511124900,"u":6511124901,"b":[["15441.27000000","0.00000000"]],"a":[["15524.56000000","3.44000000"]]}}
2020-11-09T11:25:03.39359 btcusdt {"stream":"btcusdt@depth@100ms","data":{"e":"depthUpdate","E":1604921103384,"s":"BTCUSDT","U":6511124902,"u":6511124908,"b":[["15512.96000000","0.00000000"],["15503.64000000","0.10081100"],["15500.89000000","1.50000000"],["15405.11000000","0.00000000"]],"a":[["15519.30000000","7.67442600"],["15524.16000000","0.30000000"]]}}
2020-11-09T11:25:03.49270 btcusdt {"stream":"btcusdt@depth@100ms","data":{"e":"depthUpdate","E":1604921103484,"s":"BTCUSDT","U":6511124909,"u":6511124912,"b":[["15500.89000000","0.00000000"]],"a":[["15519.30000000","7.97874000"],["15520.99000000","0.10000000"],["15522.09000000","0.00000000"]]}}
2020-11-09T11:25:03.59007 btcusdt {"stream":"btcusdt@depth@100ms","data":{"e":"depthUpdate","E":1604921103584,"s":"BTCUSDT","U":6511124913,"u":6511124922,"b":[["15519.29000000","0.13268700"],["15518.56000000","0.00000000"],["15516.26000000","0.00000000"],["15515.00000000","0.00000000"],["15512.49000000","0.15680600"],["15511.92000000","0.00000000"],["15501.68000000","1.50000000"],["15368.95000000","0.00000000"]],"a":[["15519.30000000","7.47874000"],["15519.95000000","0.01547000"]]}}
2020-11-09T11:25:03.69143 btcusdt {"stream":"btcusdt@depth@100ms","data":{"e":"depthUpdate","E":1604921103684,"s":"BTCUSDT","U":6511124923,"u":6511124931,"b":[["15519.29000000","0.12832600"],["15332.79000000","0.00000000"]],"a":[["15519.30000000","8.28904900"],["15519.93000000","0.01547000"],["15519.94000000","0.10000000"],["15519.95000000","0.00000000"],["15520.99000000","0.00000000"],["15530.86000000","0.00000000"]]}}
2020-11-09T11:25:03.79057 btcusdt {"stream":"btcusdt@depth@100ms","data":{"e":"depthUpdate","E":1604921103784,"s":"BTCUSDT","U":6511124932,"u":6511124933,"b":[],"a":[["15519.30000000","8.40404900"],["15527.02000000","1.00820900"]]}}
2020-11-09T11:25:03.89052 btcusdt {"stream":"btcusdt@depth@100ms","data":{"e":"depthUpdate","E":1604921103884,"s":"BTCUSDT","U":6511124934,"u":6511124935,"b":[["15506.72000000","0.05000000"],["15296.63000000","0.00000000"]],"a":[]}}
2020-11-09T11:25:03.99107 btcusdt {"stream":"btcusdt@depth@100ms","data":{"e":"depthUpdate","E":1604921103984,"s":"BTCUSDT","U":6511124936,"u":6511124941,"b":[["15514.42000000","0.00000000"],["15514.37000000","0.05000000"],["15512.79000000","0.19472200"],["15512.50000000","0.10817600"],["15260.47000000","0.00000000"]],"a":[["15535.30000000","0.30000000"]]}}
2020-11-09T11:25:04.09101 btcusdt {"stream":"btcusdt@depth@100ms","data":{"e":"depthUpdate","E":1604921104084,"s":"BTCUSDT","U":6511124942,"u":6511124948,"b":[["15512.79000000","0.00000000"],["15490.50000000","0.00000000"],["13560.12000000","0.00000000"]],"a":[["15519.30000000","8.40327400"],["15519.94000000","0.00000000"],["15520.99000000","0.10000000"],["15531.53000000","0.24000000"]]}}
2020-11-09T11:25:04.19519 btcusdt {"stream":"btcusdt@depth@100ms","data":{"e":"depthUpdate","E":1604921104184,"s":"BTCUSDT","U":6511124949,"u":6511125035,"b":[["15519.29000000","0.00000000"],["15519.10000000","0.00000000"],["15518.83000000","0.00000000"],["15518.52000000","0.00000000"],["15518.05000000","3.70690000"],["15517.87000000","0.07865300"],["15517.58000000","0.00000000"],["15516.84000000","0.00000000"],["15516.81000000","0.00128800"],["15516.80000000","0.00000000"],["15515.75000000","0.00000000"],["15515.02000000","0.16429600"],["15515.01000000","0.00000000"],["15514.36000000","0.00000000"],["15514.13000000","0.00000000"],["15513.56000000","1.58300000"],["15513.39000000","1.59300000"],["15512.49000000","0.00000000"],["15511.27000000","0.17787000"],["15509.68000000","0.00000000"],["15485.54000000","0.24000000"]],"a":[["15518.06000000","0.00608700"],["15518.52000000","0.00000000"],["15518.53000000","0.00000000"],["15518.84000000","0.00000000"],["15519.11000000","0.00000000"],["15519.12000000","0.00000000"],["15519.14000000","2.52026800"],["15519.15000000","0.00000000"],["15519.29000000","5.30754100"],["15519.30000000","7.53250400"],["15519.93000000","0.00000000"],["15521.84000000","0.00364300"],["15522.20000000","0.00000000"],["15522.47000000","0.01700000"],["15522.77000000","1.74800000"],["15523.38000000","0.05000000"],["15523.39000000","0.00000000"],["15523.42000000","0.00000000"],["15523.48000000","1.19800000"],["15524.17000000","0.00000000"],["15524.28000000","2.00000000"],["15524.65000000","0.00000000"],["15525.29000000","0.29400000"],["15526.43000000","1.00000000"],["15528.25000000","0.00300000"],["15529.03000000","0.00000000"],["15615.00000000","7.99002100"],["15622.27000000","2.00000000"]]}}
2020-11-09T11:25:04.30724 btcusdt {"stream":"btcusdt@depth@100ms","data":{"e":"depthUpdate","E":1604921104284,"s":"BTCUSDT","U":6511125036,"u":6511125064,"b":[["15518.05000000","3.32395300"],["15515.35000000","0.50000000"],["15514.37000000","0.00000000"],["15513.57000000","0.05000000"],["15375.63000000","0.00582600"]],"a":[["15518.06000000","5.30000700"],["15519.14000000","2.57890600"],["15519.30000000","6.96319000"],["15519.73000000","0.01547000"],["15522.46000000","0.00000000"],["15522.47000000","0.03400000"],["15523.12000000","0.06000000"],["15523.38000000","0.00000000"],["15523.53000000","0.01916400"],["15523.61000000","0.00000000"],["15523.98000000","0.00000000"],["15524.47000000","0.01000000"],["15524.87000000","0.01500000"],["15525.41000000","0.00000000"],["15525.81000000","0.00000000"],["15586.11000000","2.00000000"]]}}
2020-11-09T11:25:04.39175 btcusdt {"stream":"btcusdt@depth@100ms","data":{"e":"depthUpdate","E":1604921104384,"s":"BTCUSDT","U":6511125065,"u":6511125094,"b":[["15518.05000000","2.70772300"],["15517.87000000","0.00000000"],["15517.32000000","0.07799400"],["15511.26000000","0.00000000"],["15509.70000000","0.03626500"],["15502.69000000","0.00000000"],["15502.65000000","0.00000000"],["15441.69000000","0.00000000"]],"a":[["15518.06000000","5.73132100"],["15519.13000000","0.78253600"],["15519.14000000","0.00000000"],["15519.30000000","4.90078800"],["15522.19000000","0.00000000"],["15523.05000000","0.00000000"],["15524.12000000","0.22700000"],["15525.77000000","0.00201100"],["15525.91000000","0.03221600"],["15526.01000000","0.00000000"],["15526.43000000","0.00000000"],["15527.99000000","0.12886500"],["15528.32000000","0.50000000"],["15528.82000000","1.00000000"],["15570.00000000","48.53853300"]]}}
2020-11-09T11:25:04.49251 btcusdt {"stream":"btcusdt@depth@100ms","data":{"e":"depthUpdate","E":1604921104484,"s":"BTCUSDT","U":6511125095,"u":6511125114,"b":[["15515.36000000","0.02824600"],["15514.86000000","0.00000000"],["15505.47000000","0.00000000"],["15505.11000000","0.00000000"],["15485.54000000","0.00000000"]],"a":[["15518.06000000","5.67126900"],["15519.13000000","0.00000000"],["15519.99000000","0.00000000"],["15521.63000000","0.16373500"],["15523.05000000","0.03222000"],["15523.47000000","0.20000000"],["15524.03000000","1.25000000"],["15525.91000000","0.00000000"],["15526.31000000","0.00000000"],["15527.02000000","0.00000000"],["15527.99000000","0.00000000"],["15529.04000000","0.00000000"],["15529.07000000","0.19119600"],["15537.07000000","0.19608300"],["15549.95000000","2.00067800"]]}}
2020-11-09T11:25:04.59082 btcusdt {"stream":"btcusdt@depth@100ms","data":{"e":"depthUpdate","E":1604921104584,"s":"BTCUSDT","U":6511125115,"u":6511125124,"b":[["15507.35000000","0.00000000"],["15506.99000000","0.00000000"],["15500.00000000","14.44015700"],["15260.67000000","2.00000000"]],"a":[["15521.85000000","0.11427900"],["15525.13000000","0.12887900"],["15529.87000000","1.06502500"],["15530.83000000","0.00000000"]]}}
2020-11-09T11:25:04.69151 btcusdt {"stream":"btcusdt@depth@100ms","data":{"e":"depthUpdate","E":1604921104684,"s":"BTCUSDT","U":6511125125,"u":6511125139,"b":[["15517.59000000","0.00704000"],["15517.28000000","0.01652400"],["15508.80000000","0.00000000"],["15508.65000000","1.25000000"],["15505.76000000","0.50410400"],["15505.33000000","1.00820900"]],"a":[["15518.06000000","0.43131400"],["15519.28000000","2.46428200"],["15521.63000000","0.00000000"],["15524.55000000","2.20000000"],["15524.56000000","0.00000000"],["15530.63000000","0.36965200"],["15532.39000000","0.00000000"],["15535.63000000","0.23534500"],["15567.50000000","0.00000000"]]}}
2020-11-09T11:25:04.79359 btcusdt {"stream":"btcusdt@depth@100ms","data":{"e":"depthUpdate","E":1604921104784,"s":"BTCUSDT","U":6511125140,"u":6511125159,"b":[["15518.05000000","3.40125400"],["15517.62000000","0.07635800"],["15517.32000000","0.00000000"],["15511.62000000","1.25000000"],["15508.65000000","0.00000000"],["15505.74000000","0.50000000"],["15503.86000000","1.00000000"],["15472.12000000","0.50220200"],["15469.02000000","0.00000000"],["15296.83000000","2.00000000"]],"a":[["15518.06000000","0.12700000"],["15519.27000000","0.10000000"],["15519.28000000","2.93232900"],["15520.99000000","0.00000000"],["15523.65000000","0.00000000"],["15524.03000000","0.00000000"],["15524.27000000","0.64000000"],["15524.28000000","0.00000000"],["15525.55000000","1.25000000"]]}}
2020-11-09T11:25:04.89065 btcusdt {"stream":"btcusdt@depth@100ms","data":{"e":"depthUpdate","E":1604921104885,"s":"BTCUSDT","U":6511125160,"u":6511125172,"b":[["15515.46000000","0.11427900"],["15511.63000000","0.03626500"],["15509.70000000","0.00000000"],["15440.45000000","0.00647600"],["15332.99000000","2.00000000"]],"a":[["15519.27000000","0.00000000"],["15520.99000000","0.10000000"],["15523.65000000","0.68000000"],["15523.84000000","0.01000000"],["15523.99000000","0.32790000"],["15524.18000000","0.00000000"],["15524.55000000","0.68000000"]]}}
2020-11-09T11:25:04.99241 btcusdt {"stream":"btcusdt@depth@100ms","data":{"e":"depthUpdate","E":1604921104985,"s":"BTCUSDT","U":6511125173,"u":6511125198,"b":[["15518.83000000","0.50000000"],["15518.66000000","0.00690000"],["15518.05000000","3.25684400"],["15517.93000000","0.07497400"],["15517.62000000","0.00000000"],["15515.47000000","0.02824200"],["15514.15000000","0.05000000"],["15513.57000000","0.00000000"],["15511.28000000","0.15680600"],["15511.27000000","0.02106400"],["15509.69000000","0.00000000"],["15480.35000000","0.24000000"]],"a":[["15518.06000000","0.00000000"],["15519.27000000","2.87297500"],["15519.28000000","0.00000000"],["15519.73000000","0.00000000"],["15521.85000000","0.00000000"],["15522.55000000","0.11427900"],["15522.77000000","0.00000000"],["15523.48000000","0.00000000"],["15523.64000000","0.01000000"],["15523.99000000","0.00690000"]]}}
2020-11-09T11:25:05.09145 btcusdt {"stream":"btcusdt@depth@100ms","data":{"e":"depthUpdate","E":1604921105085,"s":"BTCUSDT","U":6511125199,"u":6511125230,"b":[["15518.32000000","0.07419700"],["15518.06000000","0.00401800"],["15518.05000000","2.20082300"],["15517.93000000","0.00000000"],["15515.47000000","0.00000000"],["15514.53000000","0.00690000"],["15509.20000000","0.30900000"],["15394.29000000","0.38325800"],["15386.17000000","0.00000000"],["15369.15000000","2.00000000"]],"a":[["15518.84000000","6.37398600"],["15519.27000000","0.00000000"],["15519.30000000","0.00400000"],["15520.99000000","0.00000000"],["15521.63000000","0.16373500"],["15522.46000000","0.10000000"],["15523.12000000","0.00000000"],["15523.40000000","1.74800000"],["15523.46000000","0.05000000"],["15523.60000000","0.01000000"],["15523.97000000","1.19800000"],["15524.47000000","0.00000000"],["15524.87000000","0.00000000"],["15525.40000000","0.01000000"],["15525.80000000","0.01500000"],["15531.53000000","0.00000000"]]}}
2020-11-09T11:25:05.19244 btcusdt {"stream":"btcusdt@depth@100ms","data":{"e":"depthUpdate","E":1604921105185,"s":"BTCUSDT","U":6511125231,"u":6511125238,"b":[["15518.83000000","0.49306200"],["15480.35000000","0.00000000"],["15405.31000000","2.00000000"]],"a":[["15519.29000000","5.32381100"],["15523.39000000","0.01000000"],["15523.64000000","0.00000000"],["15534.58000000","0.24000000"]]}}
2020-11-09T11:25:05.29086 btcusdt {"stream":"btcusdt@depth@100ms","data":{"e":"depthUpdate","E":1604921105285,"s":"BTCUSDT","U":6511125239,"u":6511125246,"b":[["15484.21000000","0.24000000"],["15220.74000000","0.00078300"]],"a":[["15518.84000000","6.31388600"],["15519.99000000","0.13500000"],["15521.25000000","0.00685400"],["15522.60000000","0.00000000"],["15522.81000000","0.01953200"],["15523.53000000","0.00000000"]]}}
2020-11-09T11:25:05.39116 btcusdt {"stream":"btcusdt@depth@100ms","data":{"e":"depthUpdate","E":1604921105385,"s":"BTCUSDT","U":6511125247,"u":6511125252,"b":[["15512.39000000","0.99115600"],["15441.47000000","2.00000000"],["15440.45000000","0.00000000"]],"a":[["15519.30000000","0.00200000"],["15523.39000000","0.00000000"],["15571.00000000","5.17150100"]]}}
2020-11-09T11:25:05.49321 btcusdt {"stream":"btcusdt@depth@100ms","data":{"e":"depthUpdate","E":1604921105485,"s":"BTCUSDT","U":6511125253,"u":6511125265,"b":[["15518.83000000","2.49306200"],["15516.09000000","0.11427900"],["15515.47000000","0.02106400"],["15515.46000000","0.00000000"],["15513.78000000","0.15680600"],["15512.57000000","0.49457000"],["15511.28000000","0.00000000"],["15511.27000000","0.00000000"],["15501.68000000","0.00000000"],["15477.63000000","2.00000000"],["15065.01000000","0.00597500"]],"a":[["15522.28000000","0.43219600"],["15534.76000000","0.19357200"]]}}
2020-11-09T11:25:05.59335 btcusdt {"stream":"btcusdt@depth@100ms","data":{"e":"depthUpdate","E":1604921105585,"s":"BTCUSDT","U":6511125266,"u":6511125274,"b":[["15518.83000000","3.16437200"],["15517.66000000","0.01823500"],["15517.28000000","0.00000000"],["15515.36000000","0.00000000"],["15500.73000000","1.50000000"]],"a":[["15518.84000000","6.31588600"],["15519.30000000","0.00000000"],["15522.20000000","0.01309700"],["15522.81000000","0.00000000"]]}}
2020-11-09T11:25:05.69184 btcusdt {"stream":"btcusdt@depth@100ms","data":{"e":"depthUpdate","E":1604921105685,"s":"BTCUSDT","U":6511125275,"u":6511125291,"b":[],"a":[["15518.84000000","0.00200000"],["15519.29000000","0.02381100"],["15521.63000000","0.00000000"],["15522.28000000","0.00000000"],["15522.55000000","0.00000000"],["15523.02000000","0.11427900"],["15523.47000000","0.00000000"],["15523.65000000","0.32000000"],["15524.27000000","0.32000000"],["15524.55000000","0.32000000"],["15525.13000000","0.00000000"],["15527.98000000","0.12887700"]]}}
2020-11-09T11:25:05.79145 btcusdt {"stream":"btcusdt@depth@100ms","data":{"e":"depthUpdate","E":1604921105785,"s":"BTCUSDT","U":6511125292,"u":6511125313,"b":[["15518.83000000","3.19361600"],["15518.63000000","0.07327900"],["15518.32000000","0.00000000"],["15507.36000000","1.30000000"],["15505.22000000","1.50000000"],["15503.86000000","0.00000000"],["15500.73000000","0.00000000"],["15460.10000000","0.00000000"]],"a":[["15519.99000000","0.00000000"],["15522.94000000","0.16373500"],["15523.05000000","0.00000000"],["15523.76000000","0.03221800"],["15524.16000000","0.00000000"],["15525.29000000","0.00000000"],["15525.90000000","0.00000000"],["15528.25000000","0.00000000"],["15528.32000000","0.00000000"],["15528.35000000","0.50000000"],["15528.36000000","1.00000000"],["15528.82000000","0.00000000"],["15530.63000000","0.00000000"]]}}
2020-11-09T11:25:05.89225 btcusdt {"stream":"btcusdt@depth@100ms","data":{"e":"depthUpdate","E":1604921105885,"s":"BTCUSDT","U":6511125314,"u":6511125321,"b":[["15517.71000000","0.00774900"],["15517.59000000","0.00000000"],["15515.48000000","0.03626500"],["15511.63000000","0.00000000"],["15475.92000000","0.00000000"],["15441.23000000","0.00647600"]],"a":[["15532.60000000","0.36961800"],["15562.79000000","0.00000000"]]}}
2020-11-09T11:25:06.05364 btcusdt {"stream":"btcusdt@depth@100ms","data":{"e":"depthUpdate","E":1604921105985,"s":"BTCUSDT","U":6511125322,"u":6511125330,"b":[["15514.15000000","0.00000000"],["15513.79000000","0.05000000"]],"a":[["15518.84000000","0.06440200"],["15519.99000000","1.52412600"],["15523.39000000","0.05000000"],["15523.46000000","0.00000000"],["15524.72000000","0.32100000"],["15525.84000000","0.12887100"],["15527.98000000","0.00000000"]]}}
2020-11-09T11:25:06.09337 btcusdt {"stream":"btcusdt@depth@100ms","data":{"e":"depthUpdate","E":1604921106085,"s":"BTCUSDT","U":6511125331,"u":6511125362,"b":[["15519.28000000","1.40493400"],["15518.84000000","4.05000000"],["15518.83000000","8.00055400"],["15518.77000000","0.07876600"],["15518.63000000","0.00000000"],["15518.06000000","0.02126100"],["15517.71000000","0.00000000"],["15517.66000000","0.00000000"],["15516.64000000","0.11427900"],["15516.41000000","0.00000000"],["15516.09000000","0.00000000"],["15515.35000000","0.00000000"],["15511.04000000","0.00000000"],["15478.97000000","0.03100000"],["15462.09000000","0.03020000"]],"a":[["15518.84000000","0.00000000"],["15519.99000000","0.00000000"],["15521.25000000","0.00000000"],["15522.20000000","0.00000000"],["15523.02000000","0.00000000"],["15523.22000000","0.01239300"],["15523.66000000","0.11427900"],["15524.72000000","0.00000000"],["15565.87000000","0.03100000"]]}}
2020-11-09T11:25:06.19279 btcusdt {"stream":"btcusdt@depth@100ms","data":{"e":"depthUpdate","E":1604921106185,"s":"BTCUSDT","U":6511125363,"u":6511125376,"b":[["15519.28000000","4.21728100"],["15518.86000000","0.07430100"],["15518.83000000","7.32924400"],["15518.77000000","0.00000000"],["15514.99000000","0.00000000"],["15513.78000000","0.00000000"]],"a":[["15522.46000000","0.00000000"],["15522.94000000","0.00000000"],["15524.08000000","0.00000000"],["15524.26000000","0.26373500"],["15558.09000000","0.00000000"]]}}
2020-11-09T11:25:06.29376 btcusdt {"stream":"btcusdt@depth@100ms","data":{"e":"depthUpdate","E":1604921106285,"s":"BTCUSDT","U":6511125377,"u":6511125379,"b":[["15519.28000000","7.66728100"],["15518.83000000","2.02924400"],["15480.50000000","0.00000000"]],"a":[]}}
2020-11-09T11:25:06.39401 btcusdt {"stream":"btcusdt@depth@100ms","data":{"e":"depthUpdate","E":1604921106385,"s":"BTCUSDT","U":6511125380,"u":6511125400,"b":[["15519.28000000","7.23060400"],["15518.84000000","4.05088500"],["15516.65000000","0.15680600"],["15515.02000000","0.00000000"],["15441.23000000","0.00000000"]],"a":[["15519.29000000","0.08059300"],["15522.47000000","0.00000000"],["15523.10000000","0.01700000"],["15523.12000000","0.16373500"],["15523.14000000","0.02554400"],["15523.22000000","0.00000000"],["15523.84000000","0.00000000"],["15524.26000000","0.10000000"],["15524.72000000","0.32100000"],["15544.83000000","0.00000000"],["15570.00000000","48.43026000"],["15573.00000000","0.17227700"]]}}
2020-11-09T11:25:06.49288 btcusdt {"stream":"btcusdt@depth@100ms","data":{"e":"depthUpdate","E":1604921106485,"s":"BTCUSDT","U":6511125401,"u":6511125410,"b":[["15519.28000000","3.78060400"],["15518.64000000","0.00200000"],["15516.65000000","0.00000000"],["15515.49000000","0.15680600"],["15515.48000000","0.00000000"],["15514.42000000","0.03626500"],["15508.23000000","0.50000000"],["15505.74000000","0.00000000"]],"a":[["15523.08000000","0.01700000"],["15524.72000000","0.00000000"]]}}
2020-11-09T11:25:06.59195 btcusdt {"stream":"btcusdt@depth@100ms","data":{"e":"depthUpdate","E":1604921106585,"s":"BTCUSDT","U":6511125411,"u":6511125411,"b":[["15511.26000000","0.20000000"]],"a":[]}}
2020-11-09T11:25:06.69601 btcusdt {"stream":"btcusdt@depth@100ms","data":{"e":"depthUpdate","E":1604921106685,"s":"BTCUSDT","U":6511125412,"u":6511125426,"b":[["15519.28000000","9.08060400"],["15518.51000000","0.01801600"],["15518.06000000","0.00401800"],["15507.01000000","0.50410400"],["15506.32000000","1.00820900"],["15505.76000000","0.00000000"],["15505.33000000","0.00000000"],["14834.95000000","0.00221900"]],"a":[["15519.29000000","0.04297100"],["15522.94000000","0.10000000"],["15523.13000000","0.52446400"],["15523.14000000","0.00690000"],["15523.52000000","0.01333500"],["15524.26000000","0.00000000"],["15544.82000000","0.01210000"]]}}
2020-11-09T11:25:06.89180 btcusdt {"stream":"btcusdt@depth@100ms","data":{"e":"depthUpdate","E":1604921106886,"s":"BTCUSDT","U":6511125427,"u":6511125434,"b":[["15518.82000000","0.00800600"],["15441.68000000","0.00647500"]],"a":[["15519.30000000","0.03227000"],["15522.81000000","0.00660700"],["15523.13000000","0.08000000"],["15523.52000000","0.00000000"],["15523.66000000","0.00000000"],["15524.14000000","0.11427900"]]}}
2020-11-09T11:25:06.99282 btcusdt {"stream":"btcusdt@depth@100ms","data":{"e":"depthUpdate","E":1604921106986,"s":"BTCUSDT","U":6511125435,"u":6511125459,"b":[["15519.29000000","5.25956500"],["15519.28000000","8.33060400"],["15518.88000000","0.07482000"],["15518.86000000","0.00000000"],["15518.84000000","0.00088500"],["15518.83000000","2.00000000"],["15515.49000000","0.00000000"],["15513.79000000","0.00000000"],["15513.78000000","0.05000000"],["15508.22000000","0.02236400"],["15505.92000000","0.00000000"]],"a":[["15519.29000000","0.00000000"],["15519.30000000","0.01493200"],["15523.39000000","0.00000000"],["15523.40000000","0.00000000"],["15523.59000000","0.05000000"],["15524.02000000","1.74800000"],["15524.48000000","0.32100000"]]}}
2020-11-09T11:25:07.09272 btcusdt {"stream":"btcusdt@depth@100ms","data":{"e":"depthUpdate","E":1604921107086,"s":"BTCUSDT","U":6511125460,"u":6511125490,"b":[["15519.29000000","8.74173900"],["15519.28000000","2.37506300"],["15518.05000000","0.20082300"],["15516.65000000","0.15680600"],["15480.49000000","0.25000000"]],"a":[["15519.30000000","0.01176300"],["15522.41000000","0.25753300"],["15523.59000000","0.00000000"],["15523.60000000","0.00000000"],["15523.65000000","0.10000000"],["15523.75000000","0.05000000"],["15523.92000000","0.01000000"],["15524.27000000","0.08000000"],["15524.55000000","0.08000000"],["15525.40000000","0.00000000"],["15525.72000000","0.01000000"],["15525.80000000","0.00000000"],["15526.12000000","0.01500000"],["15531.39000000","0.00000000"],["15558.08000000","0.25000000"],["15615.00000000","8.36685100"]]}}
2020-11-09T11:25:07.19372 btcusdt {"stream":"btcusdt@depth@100ms","data":{"e":"depthUpdate","E":1604921107186,"s":"BTCUSDT","U":6511125491,"u":6511125499,"b":[["15519.29000000","3.44173900"],["15519.28000000","2.21076700"],["15516.66000000","0.16429600"]],"a":[["15519.30000000","0.01031000"],["15522.81000000","0.00000000"],["15524.47000000","0.20000000"],["15524.48000000","0.00000000"],["15615.00000000","8.47512400"]]}}
2020-11-09T11:25:07.29272 btcusdt {"stream":"btcusdt@depth@100ms","data":{"e":"depthUpdate","E":1604921107286,"s":"BTCUSDT","U":6511125500,"u":6511125503,"b":[["15475.00000000","0.00000000"]],"a":[["15519.30000000","0.01231000"],["15522.41000000","0.00000000"],["15531.95000000","0.25753000"]]}}
2020-11-09T11:25:07.39260 btcusdt {"stream":"btcusdt@depth@100ms","data":{"e":"depthUpdate","E":1604921107386,"s":"BTCUSDT","U":6511125504,"u":6511125505,"b":[["15441.68000000","0.00000000"]],"a":[["15524.72000000","0.32100000"]]}}
2020-11-09T11:25:07.49438 btcusdt {"stream":"btcusdt@depth@100ms","data":{"e":"depthUpdate","E":1604921107486,"s":"BTCUSDT","U":6511125506,"u":6511125515,"b":[["15519.28000000","2.27836700"],["15518.82000000","0.00000000"],["15518.51000000","0.00000000"],["15516.66000000","0.00000000"],["15516.65000000","0.00000000"],["15515.48000000","0.32110200"]],"a":[["15519.30000000","1.01231000"],["15523.46000000","0.11427900"],["15524.14000000","0.00000000"]]}}
2020-11-09T11:25:07.59519 btcusdt {"stream":"btcusdt@depth@100ms","data":{"e":"depthUpdate","E":1604921107586,"s":"BTCUSDT","U":6511125516,"u":6511125517,"b":[["15519.29000000","3.19173900"]],"a":[["15519.30000000","1.01137400"]]}}
2020-11-09T11:25:07.69338 btcusdt {"stream":"btcusdt@depth@100ms","data":{"e":"depthUpdate","E":1604921107686,"s":"BTCUSDT","U":6511125518,"u":6511125527,"b":[["15519.29000000","7.87234900"],["15515.48000000","0.16429600"],["15514.42000000","0.00000000"],["15513.79000000","0.15680600"],["15512.58000000","0.03626500"],["15510.00000000","0.00857200"]],"a":[["15519.30000000","1.01050400"],["15527.59000000","1.00820900"],["15529.87000000","0.05681600"]]}}
2020-11-09T11:25:07.80245 btcusdt {"stream":"btcusdt@depth@100ms","data":{"e":"depthUpdate","E":1604921107786,"s":"BTCUSDT","U":6511125528,"u":6511125537,"b":[["15519.29000000","6.62234900"],["15519.28000000","2.28420300"],["15518.83000000","2.00988200"],["15518.52000000","0.01292400"],["15504.67000000","0.06716300"]],"a":[["15519.30000000","0.95189300"],["15522.90000000","0.00664900"],["15523.90000000","0.02467600"]]}}
2020-11-09T11:25:07.89728 btcusdt {"stream":"btcusdt@depth@100ms","data":{"e":"depthUpdate","E":1604921107886,"s":"BTCUSDT","U":6511125538,"u":6511125542,"b":[["15519.29000000","6.61894700"],["15511.26000000","0.00000000"],["15503.78000000","0.13432600"],["15441.69000000","0.00647500"]],"a":[["15524.47000000","0.00000000"]]}}
2020-11-09T11:25:07.99362 btcusdt {"stream":"btcusdt@depth@100ms","data":{"e":"depthUpdate","E":1604921107986,"s":"BTCUSDT","U":6511125543,"u":6511125560,"b":[["15519.29000000","6.61211400"],["15512.59000000","0.03626500"],["15512.58000000","0.00000000"],["15507.36000000","0.30000000"],["15506.62000000","1.00000000"],["15505.22000000","0.00000000"],["15503.82000000","1.50000000"],["15484.21000000","0.00000000"],["14613.95000000","0.00000000"]],"a":[["15519.30000000","6.25189300"],["15522.58000000","0.45493700"],["15522.94000000","0.21427900"],["15523.46000000","0.00000000"],["15525.00000000","0.00000000"],["15525.49000000","0.50000000"],["15528.35000000","0.00000000"],["15534.58000000","0.00000000"]]}}
2020-11-09T11:25:08.09416 btcusdt {"stream":"btcusdt@depth@100ms","data":{"e":"depthUpdate","E":1604921108086,"s":"BTCUSDT","U":6511125561,"u":6511125573,"b":[["15519.29000000","3.25153300"],["15519.10000000","0.00400000"],["15510.80000000","0.00000000"],["15503.79000000","0.30198600"]],"a":[["15519.30000000","6.45309700"],["15523.27000000","0.12888200"],["15523.75000000","0.17889100"],["15527.49000000","0.30198600"],["15546.88000000","1.28430500"]]}}
2020-11-09T11:25:08.19325 btcusdt {"stream":"btcusdt@depth@100ms","data":{"e":"depthUpdate","E":1604921108186,"s":"BTCUSDT","U":6511125574,"u":6511125584,"b":[["15519.29000000","2.61255300"],["15512.57000000","0.00000000"],["15504.77000000","0.13421600"],["15489.05000000","0.00000000"],["15473.53000000","0.00404400"],["15100.00000000","50.52001500"]],"a":[["15519.30000000","6.75741100"],["15523.64000000","0.20000000"],["15525.00000000","0.00317600"],["15527.11000000","0.13421600"],["15527.49000000","0.00000000"]]}}
2020-11-09T11:25:08.29329 btcusdt {"stream":"btcusdt@depth@100ms","data":{"e":"depthUpdate","E":1604921108286,"s":"BTCUSDT","U":6511125585,"u":6511125604,"b":[["15519.29000000","2.61459000"],["15511.62000000","0.00000000"],["15510.27000000","1.25000000"],["15506.62000000","0.00000000"],["15504.28000000","1.00000000"],["15503.82000000","0.00000000"],["15501.12000000","1.50000000"],["15491.10000000","0.15910000"],["15475.58000000","0.52760000"],["15433.26000000","0.00000000"],["13560.12000000","0.00147500"]],"a":[["15519.99000000","0.16373500"],["15520.99000000","0.10000000"],["15522.94000000","0.11427900"],["15523.12000000","0.00000000"],["15523.90000000","0.00690000"],["15527.49000000","0.30198800"],["15543.47000000","0.00000000"],["15599.28000000","0.00105000"]]}}
2020-11-09T11:25:08.39366 btcusdt {"stream":"btcusdt@depth@100ms","data":{"e":"depthUpdate","E":1604921108386,"s":"BTCUSDT","U":6511125605,"u":6511125617,"b":[["15519.29000000","3.22505800"],["15513.79000000","0.00000000"],["15512.60000000","0.15680600"],["15512.59000000","0.00000000"],["15511.26000000","0.03626500"],["15509.74000000","0.06710800"]],"a":[["15519.30000000","6.45309700"],["15519.99000000","0.00000000"],["15520.99000000","0.24500000"],["15522.90000000","0.00000000"],["15526.67000000","0.06710800"],["16900.00000000","23.63947400"]]}}
2020-11-09T11:25:08.49480 btcusdt {"stream":"btcusdt@depth@100ms","data":{"e":"depthUpdate","E":1604921108487,"s":"BTCUSDT","U":6511125618,"u":6511125623,"b":[["15435.30000000","5.05350000"]],"a":[["15521.63000000","0.16373500"],["15527.49000000","0.00000000"],["15558.99000000","0.00000000"],["15567.53000000","0.52760000"],["15600.99000000","5.05350000"]]}}
2020-11-09T11:25:08.59961 btcusdt {"stream":"btcusdt@depth@100ms","data":{"e":"depthUpdate","E":1604921108587,"s":"BTCUSDT","U":6511125624,"u":6511125629,"b":[["15519.29000000","3.20452600"],["15519.28000000","2.13574000"],["15510.28000000","0.20000000"]],"a":[["15519.30000000","6.39281300"],["15527.49000000","0.30198600"]]}}
2020-11-09T11:25:08.69358 btcusdt {"stream":"btcusdt@depth@100ms","data":{"e":"depthUpdate","E":1604921108687,"s":"BTCUSDT","U":6511125630,"u":6511125632,"b":[["15519.29000000","2.59553900"]],"a":[["15519.30000000","6.69712700"],["15520.41000000","0.01239000"]]}}
2020-11-09T11:25:08.79401 btcusdt {"stream":"btcusdt@depth@100ms","data":{"e":"depthUpdate","E":1604921108787,"s":"BTCUSDT","U":6511125633,"u":6511125633,"b":[],"a":[["15519.76000000","0.01438700"]]}}
2020-11-09T11:25:08.89397 btcusdt {"stream":"btcusdt@depth@100ms","data":{"e":"depthUpdate","E":1604921108887,"s":"BTCUSDT","U":6511125634,"u":6511125638,"b":[["15519.29000000","2.59741000"],["15513.57000000","0.15680600"],["15512.60000000","0.00000000"],["15502.10000000","1.50000000"],["15501.12000000","0.00000000"]],"a":[]}}
2020-11-09T11:25:08.99591 btcusdt {"stream":"btcusdt@depth@100ms","data":{"e":"depthUpdate","E":1604921108987,"s":"BTCUSDT","U":6511125639,"u":6511125651,"b":[["15519.29000000","7.09811800"]],"a":[["15519.30000000","0.62392300"],["15520.99000000","0.14500000"],["15522.57000000","0.10000000"],["15523.27000000","0.00000000"],["15523.63000000","0.05000000"],["15523.64000000","0.00000000"],["15523.75000000","0.00000000"]]}}
2020-11-09T11:25:09.09446 btcusdt {"stream":"btcusdt@depth@100ms","data":{"e":"depthUpdate","E":1604921109087,"s":"BTCUSDT","U":6511125652,"u":6511125657,"b":[["15519.29000000","7.68049000"],["15480.41000000","0.24000000"]],"a":[["15519.30000000","0.31960900"],["15524.65000000","0.00000000"],["15530.84000000","0.24000000"]]}}
2020-11-09T11:25:09.19572 btcusdt {"stream":"btcusdt@depth@100ms","data":{"e":"depthUpdate","E":1604921109187,"s":"BTCUSDT","U":6511125658,"u":6511125664,"b":[["15519.29000000","7.67764200"],["15512.68000000","0.50328900"],["15511.26000000","0.00000000"],["15502.10000000","0.00000000"],["15501.16000000","1.50000000"]],"a":[["15519.30000000","4.76960900"],["15520.99000000","0.00000000"]]}}
2020-11-09T11:25:09.29325 btcusdt {"stream":"btcusdt@depth@100ms","data":{"e":"depthUpdate","E":1604921109287,"s":"BTCUSDT","U":6511125665,"u":6511125673,"b":[["15519.29000000","7.38200300"],["15516.86000000","0.50000000"],["15507.01000000","0.00000000"]],"a":[["15519.30000000","0.31960900"],["15521.63000000","0.00000000"],["15522.58000000","0.95493700"],["15522.93000000","0.16373500"],["15527.59000000","0.00000000"]]}}
2020-11-09T11:25:09.39355 btcusdt {"stream":"btcusdt@depth@100ms","data":{"e":"depthUpdate","E":1604921109387,"s":"BTCUSDT","U":6511125674,"u":6511125680,"b":[["15514.42000000","0.00000000"],["15512.51000000","0.03626500"],["15507.76000000","0.50410400"]],"a":[["15519.30000000","3.86960900"],["15529.81000000","1.00820900"],["15901.98000000","0.00000000"]]}}
2020-11-09T11:25:09.49362 btcusdt {"stream":"btcusdt@depth@100ms","data":{"e":"depthUpdate","E":1604921109487,"s":"BTCUSDT","U":6511125681,"u":6511125697,"b":[["15519.29000000","8.17999400"],["15519.28000000","2.10699300"],["15515.49000000","0.15680600"],["15514.42000000","0.03626500"],["15513.57000000","0.00000000"],["15512.51000000","0.00000000"],["15510.28000000","0.00000000"]],"a":[["15519.30000000","0.25937200"],["15549.31000000","0.15910000"],["15965.05000000","0.00000000"]]}}
2020-11-09T11:25:09.59392 btcusdt {"stream":"btcusdt@depth@100ms","data":{"e":"depthUpdate","E":1604921109587,"s":"BTCUSDT","U":6511125698,"u":6511125705,"b":[["15519.29000000","8.17769800"],["15514.42000000","0.00000000"],["15512.69000000","0.03626500"],["15511.85000000","1.25000000"],["15510.80000000","0.20000000"],["15510.27000000","0.00000000"]],"a":[["15519.30000000","0.13000000"]]}}
2020-11-09T11:25:09.69531 btcusdt {"stream":"btcusdt@depth@100ms","data":{"e":"depthUpdate","E":1604921109687,"s":"BTCUSDT","U":6511125706,"u":6511125715,"b":[["15519.29000000","8.17566400"],["15510.80000000","0.00000000"],["15507.59000000","1.00000000"],["15506.32000000","0.00000000"],["15505.00000000","2.94071900"],["15504.28000000","0.00000000"],["15501.16000000","0.00000000"]],"a":[["15519.30000000","0.13000000"],["15888.00000000","5.84921800"]]}}
2020-11-09T11:25:09.79412 btcusdt {"stream":"btcusdt@depth@100ms","data":{"e":"depthUpdate","E":1604921109787,"s":"BTCUSDT","U":6511125716,"u":6511125727,"b":[["15518.83000000","2.00000000"],["15518.52000000","0.00000000"],["15516.04000000","0.01665000"],["15515.83000000","0.00683000"],["15507.20000000","1.00820900"]],"a":[["15522.57000000","0.00000000"],["15522.58000000","0.50000000"],["15522.94000000","0.00000000"],["15523.62000000","0.10000000"],["15523.76000000","0.00000000"],["15525.84000000","0.00000000"],["15527.95000000","0.12887100"]]}}
2020-11-09T11:25:09.89436 btcusdt {"stream":"btcusdt@depth@100ms","data":{"e":"depthUpdate","E":1604921109887,"s":"BTCUSDT","U":6511125728,"u":6511125739,"b":[["15514.86000000","0.03626500"],["15512.69000000","0.00000000"],["15480.41000000","0.00000000"]],"a":[["15519.30000000","0.00200000"],["15519.96000000","0.12700000"],["15524.79000000","0.16104400"],["15525.45000000","0.00000000"],["15525.49000000","0.00000000"],["15527.49000000","0.00000000"],["15529.57000000","0.00000000"],["15530.84000000","0.00000000"]]}}
2020-11-09T11:25:09.99392 btcusdt {"stream":"btcusdt@depth@100ms","data":{"e":"depthUpdate","E":1604921109987,"s":"BTCUSDT","U":6511125740,"u":6511125749,"b":[["15519.29000000","2.87566400"],["15514.42000000","0.05000000"],["15513.78000000","0.00000000"],["15484.28000000","0.24000000"]],"a":[["15523.63000000","0.00000000"],["15523.64000000","0.05000000"],["15528.35000000","0.50000000"],["15529.23000000","0.30236700"],["15531.20000000","0.13419500"],["15534.70000000","0.24000000"]]}}
2020-11-09T11:25:10.09562 btcusdt {"stream":"btcusdt@depth@100ms","data":{"e":"depthUpdate","E":1604921110088,"s":"BTCUSDT","U":6511125750,"u":6511125760,"b":[["15519.29000000","2.23166400"],["15511.04000000","0.20000000"],["15484.28000000","0.00000000"],["15483.62000000","0.01000000"]],"a":[["15519.30000000","3.25200000"],["15523.91000000","0.12888200"],["15524.79000000","0.03221800"],["15525.80000000","0.12887100"],["15527.95000000","0.00000000"],["15531.94000000","0.12876700"],["15534.70000000","0.00000000"]]}}
2020-11-09T11:25:10.19469 btcusdt {"stream":"btcusdt@depth@100ms","data":{"e":"depthUpdate","E":1604921110188,"s":"BTCUSDT","U":6511125761,"u":6511125768,"b":[["15519.29000000","1.64929200"],["15511.04000000","0.00000000"],["15481.67000000","0.24000000"]],"a":[["15519.30000000","3.55631400"],["15523.30000000","0.11427900"],["15524.54000000","0.01000000"],["15524.72000000","0.00000000"],["15536.90000000","0.24690000"]]}}
2020-11-09T11:25:10.29559 btcusdt {"stream":"btcusdt@depth@100ms","data":{"e":"depthUpdate","E":1604921110288,"s":"BTCUSDT","U":6511125769,"u":6511125772,"b":[["15514.86000000","0.00000000"],["15512.69000000","0.03626500"],["15241.97000000","0.00000000"]],"a":[["15523.84000000","0.20000000"]]}}
2020-11-09T11:25:10.39472 btcusdt {"stream":"btcusdt@depth@100ms","data":{"e":"depthUpdate","E":1604921110388,"s":"BTCUSDT","U":6511125773,"u":6511125780,"b":[["15519.29000000","7.44929200"],["15516.87000000","0.02900000"]],"a":[["15519.30000000","3.49624000"],["15521.63000000","0.10000000"],["15523.62000000","0.00000000"],["15523.84000000","0.00000000"],["15524.12000000","0.54800000"]]}}
2020-11-09T11:25:10.49605 btcusdt {"stream":"btcusdt@depth@100ms","data":{"e":"depthUpdate","E":1604921110488,"s":"BTCUSDT","U":6511125781,"u":6511125797,"b":[["15519.29000000","2.71812800"],["15515.49000000","0.00000000"],["15514.15000000","0.15680600"],["15512.68000000","0.00000000"],["15507.76000000","0.00000000"],["15507.59000000","0.00000000"],["15507.20000000","0.00000000"],["15505.67000000","0.50408800"],["15505.24000000","1.00817600"],["15505.00000000","1.44071900"],["15504.73000000","1.00000000"],["15501.24000000","1.50000000"]],"a":[["15519.30000000","3.91174600"],["15521.62000000","0.16373500"],["15522.93000000","0.00000000"]]}}
2020-11-09T11:25:10.59468 btcusdt {"stream":"btcusdt@depth@100ms","data":{"e":"depthUpdate","E":1604921110588,"s":"BTCUSDT","U":6511125798,"u":6511125804,"b":[["15519.29000000","2.14929200"],["15519.10000000","0.00600000"],["15511.85000000","0.00000000"],["15510.27000000","1.25000000"]],"a":[["15519.30000000","4.21606000"],["15523.30000000","0.00000000"],["15523.63000000","0.20000000"]]}}
2020-11-09T11:25:10.69651 btcusdt {"stream":"btcusdt@depth@100ms","data":{"e":"depthUpdate","E":1604921110688,"s":"BTCUSDT","U":6511125805,"u":6511125809,"b":[["15512.69000000","0.00000000"],["15511.26000000","0.03626500"],["15501.52000000","1.50000000"],["15501.24000000","0.00000000"]],"a":[["15536.90000000","0.00690000"]]}}
2020-11-09T11:25:10.79514 btcusdt {"stream":"btcusdt@depth@100ms","data":{"e":"depthUpdate","E":1604921110788,"s":"BTCUSDT","U":6511125810,"u":6511125849,"b":[["15519.29000000","0.00000000"],["15519.28000000","0.00000000"],["15519.10000000","0.50600000"],["15518.88000000","0.00000000"],["15518.37000000","0.07696800"],["15516.64000000","0.00000000"],["15515.48000000","0.00000000"],["15514.15000000","0.00000000"],["15513.57000000","0.00000000"],["15512.50000000","0.00000000"],["15481.67000000","0.00000000"],["15478.42000000","0.24000000"]],"a":[["15519.11000000","9.55927800"],["15519.20000000","0.00690000"],["15519.27000000","0.08673600"],["15519.29000000","5.61267500"],["15519.30000000","5.49624000"],["15531.28000000","0.24000000"]]}}
2020-11-09T11:25:10.89480 btcusdt {"stream":"btcusdt@depth@100ms","data":{"e":"depthUpdate","E":1604921110888,"s":"BTCUSDT","U":6511125850,"u":6511125876,"b":[["15519.10000000","0.51290000"],["15518.83000000","0.00000000"],["15516.15000000","0.00789500"],["15515.83000000","0.00000000"],["15511.27000000","0.00000000"],["15510.27000000","1.25000000"],["15509.20000000","0.00000000"],["15501.52000000","0.00000000"],["15441.69000000","0.00000000"]],"a":[["15519.11000000","11.68727800"],["15519.30000000","2.00000000"],["15519.76000000","0.00690000"],["15519.84000000","0.00735800"],["15519.96000000","0.00000000"],["15522.15000000","0.30900000"],["15524.26000000","0.00000000"],["15524.31000000","0.01000000"],["15524.48000000","0.29400000"],["15524.54000000","0.15550000"],["15527.44000000","0.00294000"],["15527.87000000","0.14700000"],["15585.28000000","0.00000000"]]}}
2020-11-09T11:25:10.99602 btcusdt {"stream":"btcusdt@depth@100ms","data":{"e":"depthUpdate","E":1604921110988,"s":"BTCUSDT","U":6511125877,"u":6511125890,"b":[["15514.42000000","0.00000000"],["15514.14000000","0.00000000"],["15513.40000000","0.05000000"],["15512.49000000","0.10818400"],["15511.27000000","0.16429600"],["15501.86000000","1.56723900"]],"a":[["15519.11000000","12.25532700"],["15519.48000000","0.14000000"],["15521.62000000","0.00000000"],["15521.63000000","0.00000000"],["15523.57000000","0.05000000"],["15523.64000000","0.00000000"]]}}
2020-11-09T11:25:11.09474 btcusdt {"stream":"btcusdt@depth@100ms","data":{"e":"depthUpdate","E":1604921111088,"s":"BTCUSDT","U":6511125891,"u":6511125895,"b":[["15510.27000000","0.00000000"],["15509.63000000","1.25000000"]],"a":[["15521.63000000","0.12890100"],["15523.27000000","0.01000000"],["15524.31000000","0.00000000"]]}}
2020-11-09T11:25:11.19584 btcusdt {"stream":"btcusdt@depth@100ms","data":{"e":"depthUpdate","E":1604921111188,"s":"BTCUSDT","U":6511125896,"u":6511125901,"b":[["15516.15000000","0.00000000"],["15515.36000000","0.11427900"]],"a":[["15519.11000000","11.79626100"],["15519.84000000","0.00000000"],["15524.54000000","0.14550000"]]}}
2020-11-09T11:25:11.29527 btcusdt {"stream":"btcusdt@depth@100ms","data":{"e":"depthUpdate","E":1604921111288,"s":"BTCUSDT","U":6511125902,"u":6511125903,"b":[["15511.28000000","0.06734000"],["15478.42000000","0.00000000"]],"a":[]}}
2020-11-09T11:25:11.39507 btcusdt {"stream":"btcusdt@depth@100ms","data":{"e":"depthUpdate","E":1604921111388,"s":"BTCUSDT","U":6511125904,"u":6511125907,"b":[["15519.10000000","0.51490000"],["15476.00000000","0.24000000"],["15441.50000000","0.00647600"]],"a":[["15519.11000000","12.00126100"]]}}
2020-11-09T11:25:11.49535 btcusdt {"stream":"btcusdt@depth@100ms","data":{"e":"depthUpdate","E":1604921111488,"s":"BTCUSDT","U":6511125908,"u":6511125912,"b":[["15515.82000000","0.00747700"],["15511.59000000","0.54293400"]],"a":[["15519.57000000","0.00867600"],["15521.31000000","0.52366200"],["15522.94000000","0.00323900"]]}}
2020-11-09T11:25:11.69905 btcusdt {"stream":"btcusdt@depth@100ms","data":{"e":"depthUpdate","E":1604921111689,"s":"BTCUSDT","U":6511125913,"u":6511125913,"b":[["15242.99000000","0.00590400"]],"a":[]}}
2020-11-09T11:25:11.79785 btcusdt {"stream":"btcusdt@depth@100ms","data":{"e":"depthUpdate","E":1604921111789,"s":"BTCUSDT","U":6511125914,"u":6511125925,"b":[["15518.05000000","0.07730100"],["15514.85000000","0.00000000"],["15513.54000000","0.02000000"],["15512.50000000","0.16429600"],["15512.39000000","0.00000000"],["15511.59000000","0.00000000"],["15511.27000000","0.00000000"],["15510.79000000","0.00000000"],["15476.00000000","0.00000000"],["15402.00000000","0.57882000"]],"a":[["15519.11000000","12.00714600"],["15615.00000000","8.48965800"]]}}
2020-11-09T11:25:11.89628 btcusdt {"stream":"btcusdt@depth@100ms","data":{"e":"depthUpdate","E":1604921111889,"s":"BTCUSDT","U":6511125926,"u":6511125939,"b":[["15516.04000000","0.00000000"],["15515.91000000","0.01619700"],["15515.82000000","0.00000000"],["15515.68000000","0.00643200"],["15515.47000000","0.00000000"],["15512.50000000","0.00000000"],["15511.29000000","0.18536000"],["15507.94000000","0.00000000"],["15462.52000000","0.24000000"],["15441.50000000","0.00000000"]],"a":[["15520.14000000","0.01542000"],["15520.41000000","0.00000000"],["15529.76000000","0.00000000"]]}}
2020-11-09T11:25:11.99666 btcusdt {"stream":"btcusdt@depth@100ms","data":{"e":"depthUpdate","E":1604921111989,"s":"BTCUSDT","U":6511125940,"u":6511126028,"b":[["15519.10000000","0.00000000"],["15518.84000000","0.00000000"],["15518.66000000","0.00000000"],["15518.37000000","0.00000000"],["15516.87000000","0.00000000"],["15515.36000000","0.00000000"],["15514.58000000","0.00000000"],["15513.77000000","0.00000000"],["15511.30000000","0.02500000"],["15511.29000000","0.02106400"],["15511.26000000","0.00000000"],["15509.75000000","0.03626500"],["15509.63000000","0.00000000"],["15508.65000000","1.25000000"],["15507.64000000","0.00000000"],["15496.75000000","0.23534600"],["15490.69000000","0.00000000"],["15423.00000000","0.48510300"]],"a":[["15518.65000000","12.34465900"],["15518.66000000","0.08163800"],["15518.67000000","0.00000000"],["15518.81000000","0.14317200"],["15518.82000000","0.07071200"],["15518.84000000","0.80000000"],["15518.85000000","5.36121600"],["15518.95000000","0.06136800"],["15518.97000000","0.00000000"],["15518.98000000","0.00690000"],["15519.06000000","0.00000000"],["15519.10000000","0.80428000"],["15519.11000000","2.90693400"],["15519.22000000","0.00000000"],["15519.27000000","0.00000000"],["15519.29000000","0.04875200"],["15519.41000000","0.00000000"],["15522.29000000","0.25755500"],["15522.58000000","0.00000000"],["15523.02000000","0.50000000"],["15523.28000000","0.00000000"],["15523.45000000","1.19800000"],["15523.97000000","0.00000000"],["15526.89000000","0.00690000"],["15531.95000000","0.00000000"],["15533.39000000","0.02500000"]]}}
2020-11-09T11:25:12.09689 btcusdt {"stream":"btcusdt@depth@100ms","data":{"e":"depthUpdate","E":1604921112089,"s":"BTCUSDT","U":6511126029,"u":6511126083,"b":[["15518.64000000","0.00890000"],["15514.81000000","0.02900000"],["15514.41000000","0.00000000"],["15513.54000000","0.00000000"],["15513.40000000","0.00000000"],["15512.46000000","0.30754200"],["15512.45000000","0.00000000"],["15512.34000000","0.04000000"],["15511.74000000","0.02000000"],["15510.46000000","0.48000000"],["15509.76000000","0.32110200"],["15508.24000000","0.00690000"],["15480.49000000","0.00000000"]],"a":[["15518.65000000","14.34465900"],["15518.67000000","0.14909400"],["15518.95000000","0.00000000"],["15519.10000000","0.17174400"],["15519.11000000","2.60262000"],["15519.48000000","0.00000000"],["15519.75000000","0.08000000"],["15520.66000000","0.08000000"],["15522.31000000","0.01700000"],["15522.33000000","0.01700000"],["15522.40000000","0.05000000"],["15522.75000000","0.01000000"],["15522.94000000","0.00000000"],["15522.95000000","1.42300100"],["15523.01000000","0.01000000"],["15523.04000000","0.00000000"],["15523.08000000","0.00000000"],["15523.10000000","1.58300000"],["15523.20000000","1.74800000"],["15523.28000000","1.59300000"],["15523.45000000","0.00000000"],["15523.57000000","0.00000000"],["15523.65000000","0.00000000"],["15523.92000000","0.00000000"],["15524.02000000","0.00000000"],["15524.27000000","0.00000000"],["15524.32000000","0.00000000"],["15524.55000000","0.01000000"],["15524.66000000","0.00000000"],["15524.79000000","0.00000000"],["15524.95000000","0.01500000"],["15525.72000000","0.00000000"],["15526.12000000","0.00000000"],["15527.74000000","1.28864100"],["15529.81000000","0.00000000"],["15558.08000000","0.00000000"]]}}
2020-11-09T11:25:12.19668 btcusdt {"stream":"btcusdt@depth@100ms","data":{"e":"depthUpdate","E":1604921112189,"s":"BTCUSDT","U":6511126084,"u":6511126138,"b":[["15518.64000000","0.00000000"],["15518.06000000","0.00893800"],["15516.86000000","0.00000000"],["15513.56000000","0.00000000"],["15513.39000000","0.00000000"],["15512.48000000","2.08300000"],["15512.46000000","0.25754200"],["15512.35000000","1.59300000"],["15511.75000000","0.05000000"],["15508.57000000","0.00000000"],["15508.23000000","0.00000000"],["15504.48000000","0.50000000"]],"a":[["15518.07000000","13.83434800"],["15518.36000000","0.00690000"],["15518.55000000","0.15666700"],["15518.64000000","0.78253600"],["15518.65000000","7.83362600"],["15518.66000000","0.00000000"],["15518.67000000","0.00000000"],["15518.81000000","0.00000000"],["15518.82000000","0.00000000"],["15518.85000000","0.00000000"],["15519.10000000","0.15627400"],["15519.11000000","2.39762000"],["15519.30000000","2.00200000"],["15520.49000000","0.03222500"],["15521.00000000","1.31800000"],["15522.40000000","0.00000000"],["15522.43000000","1.19800000"],["15522.91000000","0.05000000"],["15522.95000000","0.22500100"],["15523.01000000","0.00000000"],["15524.55000000","0.00000000"],["15525.06000000","0.01000000"],["15527.19000000","0.00000000"]]}}
2020-11-09T11:25:12.29534 btcusdt {"stream":"btcusdt@depth@100ms","data":{"e":"depthUpdate","E":1604921112289,"s":"BTCUSDT","U":6511126139,"u":6511126163,"b":[["15511.75000000","0.00000000"],["15511.30000000","0.07500000"],["15508.17000000","0.00000000"]],"a":[["15518.07000000","16.12434800"],["15518.65000000","7.77931200"],["15518.97000000","0.08000000"],["15519.10000000","0.00627400"],["15519.30000000","0.00200000"],["15521.30000000","0.01700000"],["15521.32000000","0.01700000"],["15521.60000000","0.25000000"],["15522.18000000","1.75490000"],["15522.31000000","0.00000000"],["15522.33000000","0.00000000"],["15522.42000000","0.01000000"],["15522.74000000","0.10160900"],["15522.90000000","0.01000000"],["15523.20000000","0.00000000"],["15523.27000000","0.00000000"],["15524.12000000","0.22700000"],["15526.33000000","0.00000000"]]}}
2020-11-09T11:25:12.39541 btcusdt {"stream":"btcusdt@depth@100ms","data":{"e":"depthUpdate","E":1604921112389,"s":"BTCUSDT","U":6511126164,"u":6511126183,"b":[["15518.06000000","0.00002900"],["15509.47000000","0.01900000"],["15508.65000000","0.00000000"],["15508.27000000","1.25000000"],["15440.46000000","0.00647600"]],"a":[["15518.07000000","15.59239700"],["15518.65000000","2.47931200"],["15518.84000000","0.00000000"],["15519.11000000","2.13388500"],["15522.90000000","0.00000000"],["15523.10000000","1.73000000"],["15523.77000000","0.00000000"],["15525.55000000","0.00000000"],["15525.93000000","0.01382400"],["15537.07000000","0.00000000"],["15537.55000000","0.00000000"]]}}
2020-11-09T11:25:12.49593 btcusdt {"stream":"btcusdt@depth@100ms","data":{"e":"depthUpdate","E":1604921112489,"s":"BTCUSDT","U":6511126184,"u":6511126197,"b":[["15506.72000000","0.00000000"],["15483.61000000","0.08297000"],["15478.97000000","0.00000000"]],"a":[["15518.07000000","14.69239700"],["15518.64000000","0.00000000"],["15519.34000000","0.00875800"],["15519.57000000","0.00000000"],["15522.74000000","0.00000000"],["15523.53000000","0.00000000"],["15525.55000000","1.25000000"],["15565.87000000","0.00000000"]]}}
2020-11-09T11:25:12.59566 btcusdt {"stream":"btcusdt@depth@100ms","data":{"e":"depthUpdate","E":1604921112589,"s":"BTCUSDT","U":6511126198,"u":6511126224,"b":[["15518.06000000","0.00000000"],["15518.05000000","0.00968000"],["15510.75000000","0.03222500"],["15508.34000000","0.12889800"],["15506.84000000","0.20000000"],["15501.51000000","0.00000000"],["15501.39000000","0.00000000"],["15483.61000000","0.08801900"],["15462.52000000","0.00000000"],["15100.00000000","50.52104100"]],"a":[["15518.06000000","16.85709700"],["15518.07000000","6.32418500"],["15518.55000000","0.00000000"],["15518.65000000","2.40000000"],["15524.48000000","0.30400000"],["15525.06000000","0.00000000"],["15546.88000000","0.00690000"]]}}
2020-11-09T11:25:12.76210 btcusdt {"stream":"btcusdt@depth@100ms","data":{"e":"depthUpdate","E":1604921112689,"s":"BTCUSDT","U":6511126225,"u":6511126233,"b":[["15502.45000000","0.13420700"],["15498.42000000","1.15762500"],["15477.24000000","0.03100000"],["15452.16000000","0.24000000"],["15423.00000000","0.37683000"]],"a":[["15518.07000000","6.01987100"],["15518.65000000","2.00000000"],["15520.49000000","0.00000000"],["15564.14000000","0.03100000"]]}}
2020-11-09T11:25:12.79540 btcusdt {"stream":"btcusdt@depth@100ms","data":{"e":"depthUpdate","E":1604921112789,"s":"BTCUSDT","U":6511126234,"u":6511126242,"b":[["15508.27000000","0.00000000"],["15483.61000000","0.00000000"],["13250.00000000","13.21191300"]],"a":[["15518.06000000","17.56141100"],["15521.29000000","0.00320900"],["15523.76000000","0.03222500"],["15531.28000000","0.00000000"]]}}
2020-11-09T11:25:12.89725 btcusdt {"stream":"btcusdt@depth@100ms","data":{"e":"depthUpdate","E":1604921112889,"s":"BTCUSDT","U":6511126243,"u":6511126308,"b":[["15518.05000000","0.00000000"],["15516.81000000","0.00818800"],["15515.91000000","0.00000000"],["15515.68000000","0.00000000"],["15514.54000000","0.01937800"],["15514.48000000","0.00774500"],["15512.48000000","0.50000000"],["15512.35000000","0.00000000"],["15511.58000000","1.58300000"],["15511.45000000","1.59300000"],["15509.76000000","0.16429600"],["15508.78000000","0.19272200"],["15508.55000000","0.00000000"],["15508.35000000","0.15680600"],["15507.32000000","1.25000000"],["15504.05000000","0.05000000"],["15452.16000000","0.00000000"],["15440.46000000","0.00000000"]],"a":[["15516.82000000","6.59352500"],["15517.21000000","0.02865500"],["15517.27000000","0.00000000"],["15517.28000000","0.00000000"],["15517.44000000","0.00690000"],["15517.83000000","0.03296300"],["15517.84000000","0.03231600"],["15517.86000000","0.03057000"],["15517.94000000","0.00000000"],["15517.95000000","0.00000000"],["15518.05000000","0.78253600"],["15518.06000000","8.03367600"],["15518.07000000","0.40373500"],["15519.11000000","2.14305300"],["15519.34000000","0.00000000"],["15519.42000000","0.01701700"],["15520.14000000","0.00000000"],["15521.59000000","0.32100000"],["15521.72000000","1.19800000"],["15521.87000000","1.58300000"],["15522.05000000","1.59300000"],["15522.18000000","0.00690000"],["15522.43000000","0.00000000"],["15523.10000000","0.14700000"],["15523.12000000","0.10164100"],["15523.28000000","0.00000000"],["15523.76000000","0.00000000"]]}}
2020-11-09T11:25:12.99833 btcusdt {"stream":"btcusdt@depth@100ms","data":{"e":"depthUpdate","E":1604921112989,"s":"BTCUSDT","U":6511126309,"u":6511126351,"b":[["15516.81000000","2.00818800"],["15516.08000000","0.07690700"],["15511.30000000","0.02500000"],["15511.26000000","0.05000000"],["15507.36000000","0.00000000"],["15507.32000000","0.00000000"],["15506.90000000","1.25000000"],["15506.84000000","0.00000000"],["15505.09000000","0.30000000"],["15501.86000000","0.06723900"],["15500.58000000","1.50000000"],["15432.17000000","0.24000000"],["14689.52000000","0.00000000"]],"a":[["15516.82000000","6.57805500"],["15517.27000000","0.28500000"],["15517.91000000","4.25695000"],["15517.93000000","0.00000000"],["15517.94000000","0.00000000"],["15518.06000000","7.73136200"],["15518.07000000","0.26373500"],["15519.29000000","0.00000000"],["15520.44000000","0.01700000"],["15520.45000000","0.01700000"],["15521.08000000","0.05000000"],["15521.13000000","0.03222500"],["15521.30000000","0.00000000"],["15521.31000000","2.27166200"],["15521.32000000","0.00000000"],["15521.43000000","0.01000000"],["15521.63000000","0.00000000"],["15522.28000000","0.01000000"],["15522.75000000","0.00000000"],["15522.91000000","0.00000000"],["15523.12000000","0.00000000"],["15523.23000000","0.01000000"],["15524.48000000","0.29400000"],["15525.55000000","0.00000000"]]}}
2020-11-09T11:25:13.09833 btcusdt {"stream":"btcusdt@depth@100ms","data":{"e":"depthUpdate","E":1604921113089,"s":"BTCUSDT","U":6511126352,"u":6511126371,"b":[["15516.81000000","1.98154800"],["15512.48000000","0.00000000"],["15509.74000000","0.00000000"],["15506.90000000","0.00000000"],["15506.66000000","1.25000000"],["15500.58000000","0.00000000"],["15500.01000000","1.50000000"],["15497.63000000","0.00000000"],["15479.26000000","0.25200000"]],"a":[["15516.82000000","6.88236900"],["15517.91000000","0.00000000"],["15518.05000000","0.00000000"],["15518.06000000","7.33136200"],["15518.07000000","0.00000000"],["15521.29000000","0.00000000"],["15522.73000000","1.25000000"],["15529.85000000","0.24000000"],["15543.49000000","0.80507500"]]}}
2020-11-09T11:25:13.19648 btcusdt {"stream":"btcusdt@depth@100ms","data":{"e":"depthUpdate","E":1604921113189,"s":"BTCUSDT","U":6511126372,"u":6511126385,"b":[["15516.81000000","7.22184200"],["15508.28000000","1.25000000"],["15506.66000000","0.00000000"],["15432.17000000","0.00000000"]],"a":[["15516.82000000","2.14610400"],["15518.05000000","3.66568300"],["15523.63000000","0.21500000"],["15524.95000000","0.00000000"],["15540.00000000","2.19291100"]]}}
2020-11-09T11:25:13.30085 btcusdt {"stream":"btcusdt@depth@100ms","data":{"e":"depthUpdate","E":1604921113289,"s":"BTCUSDT","U":6511126386,"u":6511126404,"b":[["15516.81000000","7.81362600"],["15509.48000000","0.50000000"],["15500.01000000","0.00000000"],["15430.30000000","0.24000000"]],"a":[["15516.82000000","1.67805500"],["15517.27000000","0.00000000"],["15517.82000000","0.26373500"],["15519.00000000","0.01734300"],["15519.42000000","0.00000000"],["15521.60000000","0.00000000"],["15521.86000000","0.20000000"],["15522.73000000","0.00000000"],["15523.63000000","0.01500000"],["15523.91000000","0.00000000"],["15525.55000000","1.25000000"],["15529.85000000","0.00000000"],["15556.85000000","0.25160700"]]}}
2020-11-09T11:25:13.39731 btcusdt {"stream":"btcusdt@depth@100ms","data":{"e":"depthUpdate","E":1604921113390,"s":"BTCUSDT","U":6511126405,"u":6511126424,"b":[["15516.81000000","7.80463400"],["15514.48000000","0.00000000"],["15514.33000000","0.00826900"],["15500.44000000","1.50000000"],["15500.43000000","0.00000000"],["15439.22000000","0.00647700"],["15430.30000000","0.00000000"],["15423.00000000","0.00000000"],["15402.00000000","0.68709300"]],"a":[["15517.82000000","0.16373500"],["15518.05000000","3.67528500"],["15518.06000000","5.33136200"],["15519.11000000","2.13388500"],["15521.86000000","0.00000000"],["15522.42000000","0.00000000"],["15523.02000000","1.25000000"],["15528.83000000","0.24000000"]]}}
2020-11-09T11:25:13.49693 btcusdt {"stream":"btcusdt@depth@100ms","data":{"e":"depthUpdate","E":1604921113490,"s":"BTCUSDT","U":6511126425,"u":6511126436,"b":[["15516.81000000","8.30045300"],["15509.77000000","0.15680600"],["15508.35000000","0.00000000"],["15500.44000000","0.00000000"],["15500.35000000","0.00000000"]],"a":[["15516.82000000","1.43205500"],["15519.99000000","0.10000000"]]}}
2020-11-09T11:25:13.59651 btcusdt {"stream":"btcusdt@depth@100ms","data":{"e":"depthUpdate","E":1604921113590,"s":"BTCUSDT","U":6511126437,"u":6511126451,"b":[["15516.81000000","8.21281100"],["15514.54000000","0.00000000"],["15513.34000000","0.01258600"],["15500.57000000","1.50000000"],["15430.56000000","0.24000000"],["14834.95000000","0.00142200"]],"a":[["15519.00000000","0.00000000"],["15519.11000000","2.12800000"],["15522.14000000","0.00000000"],["15525.52000000","0.00000000"],["15525.55000000","1.25000000"],["15528.83000000","0.00000000"]]}}
2020-11-09T11:25:13.69893 btcusdt {"stream":"btcusdt@depth@100ms","data":{"e":"depthUpdate","E":1604921113690,"s":"BTCUSDT","U":6511126452,"u":6511126460,"b":[["15514.33000000","0.00000000"],["15513.13000000","0.00819300"],["15500.57000000","0.00000000"],["15430.56000000","0.00000000"]],"a":[["15516.82000000","1.41366500"],["15517.28000000","0.00873000"],["15517.79000000","0.01608500"],["15518.05000000","3.66568300"],["15530.29000000","0.24000000"]]}}
2020-11-09T11:25:13.80160 btcusdt {"stream":"btcusdt@depth@100ms","data":{"e":"depthUpdate","E":1604921113790,"s":"BTCUSDT","U":6511126461,"u":6511126469,"b":[["15513.45000000","0.01689100"],["15513.34000000","0.00000000"],["15431.58000000","0.00000000"],["15200.01000000","3.53369400"]],"a":[["15516.82000000","1.40913700"],["15517.79000000","0.00000000"],["15517.99000000","0.01720500"],["15530.29000000","0.00000000"]]}}
2020-11-09T11:25:13.89613 btcusdt {"stream":"btcusdt@depth@100ms","data":{"e":"depthUpdate","E":1604921113890,"s":"BTCUSDT","U":6511126470,"u":6511126478,"b":[["15513.30000000","0.00890200"],["15513.13000000","0.00000000"],["15510.09000000","0.42327400"],["15509.76000000","1.13540300"],["15500.64000000","0.00306000"],["15435.43000000","0.24000000"],["15020.19000000","0.00000000"]],"a":[["15516.82000000","1.34912500"],["15533.07000000","0.24000000"]]}}
2020-11-09T11:25:13.99975 btcusdt {"stream":"btcusdt@depth@100ms","data":{"e":"depthUpdate","E":1604921113990,"s":"BTCUSDT","U":6511126479,"u":6511126520,"b":[["15516.81000000","0.59178400"],["15511.75000000","0.16429600"],["15511.29000000","0.07106400"],["15511.26000000","0.00000000"],["15510.75000000","0.00000000"],["15510.09000000","0.00000000"],["15509.76000000","0.00000000"],["15508.96000000","0.12890500"],["15508.55000000","0.30000000"],["15508.34000000","0.00000000"],["15508.22000000","0.00000000"],["15506.82000000","0.50000000"],["15505.80000000","0.00000000"],["15505.10000000","0.02236400"],["15505.09000000","0.00000000"],["15504.48000000","0.00000000"],["15503.07000000","0.00000000"],["15502.99000000","1.50000000"],["15502.86000000","0.03355100"]],"a":[["15516.82000000","6.64912500"],["15517.81000000","0.78253600"],["15518.05000000","0.00000000"],["15518.97000000","0.00000000"],["15521.61000000","1.01133200"],["15521.73000000","0.12890600"],["15525.61000000","0.00000000"],["15525.80000000","0.00000000"],["15525.99000000","0.00000000"],["15526.37000000","0.00000000"],["15528.00000000","0.10000000"],["15528.71000000","0.00000000"],["15530.39000000","0.30000000"],["15531.38000000","1.50000000"]]}}
2020-11-09T11:25:14.09840 btcusdt {"stream":"btcusdt@depth@100ms","data":{"e":"depthUpdate","E":1604921114090,"s":"BTCUSDT","U":6511126521,"u":6511126568,"b":[["15516.81000000","0.00000000"],["15516.08000000","5.80690000"],["15514.20000000","0.07431600"],["15512.28000000","0.00000000"],["15508.53000000","1.00000000"],["15507.78000000","1.50000000"],["15506.84000000","0.20000000"],["15504.73000000","0.00000000"],["15502.99000000","0.00000000"],["15420.00000000","0.97585000"]],"a":[["15516.09000000","1.42640000"],["15516.46000000","0.00690000"],["15516.71000000","0.85188400"],["15516.72000000","0.00000000"],["15516.75000000","0.00000000"],["15516.81000000","0.00000000"],["15516.82000000","8.03636900"],["15517.21000000","0.00000000"],["15517.81000000","0.00000000"],["15517.83000000","0.00000000"],["15517.84000000","0.00000000"],["15517.86000000","0.00000000"],["15518.06000000","0.03136200"],["15520.43000000","0.12891000"],["15520.65000000","0.00000000"],["15520.97000000","1.19800000"],["15521.72000000","0.00000000"],["15522.63000000","0.09618800"],["15524.03000000","0.19440700"],["15526.38000000","0.30000000"],["15529.62000000","0.13433300"],["15530.39000000","0.00000000"],["15533.75000000","0.00000000"],["15615.00000000","8.11282800"]]}}
2020-11-09T11:25:14.19686 btcusdt {"stream":"btcusdt@depth@100ms","data":{"e":"depthUpdate","E":1604921114190,"s":"BTCUSDT","U":6511126569,"u":6511126607,"b":[["15516.08000000","8.36480200"],["15513.79000000","0.50000000"],["15513.59000000","0.01255300"],["15513.45000000","0.00000000"],["15513.36000000","0.00843500"],["15513.30000000","0.00000000"],["15506.84000000","0.00000000"],["15505.24000000","0.00000000"],["15435.43000000","0.00000000"],["15018.25000000","0.00070400"]],"a":[["15516.09000000","4.51933400"],["15516.71000000","0.00000000"],["15516.81000000","0.40000000"],["15516.82000000","5.33205500"],["15517.82000000","0.00000000"],["15519.07000000","0.50000000"],["15519.74000000","0.16373500"],["15520.44000000","0.06700000"],["15520.70000000","0.01000000"],["15521.08000000","0.00000000"],["15521.43000000","0.00000000"],["15521.59000000","0.00000000"],["15522.50000000","0.01000000"],["15522.90000000","0.01500000"],["15523.23000000","0.00000000"],["15523.63000000","0.00000000"],["15533.07000000","0.00000000"]]}}
2020-11-09T11:25:14.29720 btcusdt {"stream":"btcusdt@depth@100ms","data":{"e":"depthUpdate","E":1604921114290,"s":"BTCUSDT","U":6511126608,"u":6511126617,"b":[["15503.26000000","1.00832000"],["15435.97000000","0.24000000"],["15399.00000000","0.37683000"]],"a":[["15516.09000000","1.41613400"],["15516.80000000","2.19703800"],["15519.75000000","0.19427900"],["15522.04000000","0.20000000"],["15532.60000000","0.60961800"]]}}
2020-11-09T11:25:14.39692 btcusdt {"stream":"btcusdt@depth@100ms","data":{"e":"depthUpdate","E":1604921114390,"s":"BTCUSDT","U":6511126618,"u":6511126625,"b":[["15516.08000000","3.06480200"],["15512.28000000","0.08000000"],["15511.75000000","0.00000000"],["15510.47000000","0.16429600"],["15439.22000000","0.00000000"]],"a":[["15516.09000000","1.37089900"],["15520.91000000","0.32100000"],["16084.47000000","0.00000000"]]}}
2020-11-09T11:25:14.49727 btcusdt {"stream":"btcusdt@depth@100ms","data":{"e":"depthUpdate","E":1604921114490,"s":"BTCUSDT","U":6511126626,"u":6511126644,"b":[["15516.08000000","2.50690000"],["15510.48000000","0.15680600"],["15509.77000000","0.00000000"],["15435.97000000","0.00000000"],["14687.95000000","0.00085700"]],"a":[["15516.09000000","1.81868800"],["15516.79000000","1.92907300"],["15516.80000000","0.00000000"],["15517.98000000","0.10000000"],["15519.74000000","0.00000000"],["15519.99000000","0.00000000"],["15532.60000000","0.36961800"],["15573.00000000","0.54910700"]]}}
2020-11-09T11:25:14.59658 btcusdt {"stream":"btcusdt@depth@100ms","data":{"e":"depthUpdate","E":1604921114590,"s":"BTCUSDT","U":6511126645,"u":6511126646,"b":[["15431.75000000","0.24000000"]],"a":[["15528.74000000","0.24000000"]]}}
2020-11-09T11:25:14.69869 btcusdt {"stream":"btcusdt@depth@100ms","data":{"e":"depthUpdate","E":1604921114690,"s":"BTCUSDT","U":6511126647,"u":6511126648,"b":[],"a":[["15517.28000000","0.00000000"],["16086.98000000","0.00062500"]]}}
2020-11-09T11:25:14.79756 btcusdt {"stream":"btcusdt@depth@100ms","data":{"e":"depthUpdate","E":1604921114790,"s":"BTCUSDT","U":6511126649,"u":6511126655,"b":[["15510.48000000","0.00000000"],["15509.76000000","0.15680600"],["15509.15000000","0.00000000"],["15431.75000000","0.00000000"],["15420.00000000","1.08412300"]],"a":[["15516.09000000","1.75823600"],["15528.74000000","0.00000000"]]}}
2020-11-09T11:25:14.89697 btcusdt {"stream":"btcusdt@depth@100ms","data":{"e":"depthUpdate","E":1604921114890,"s":"BTCUSDT","U":6511126656,"u":6511126667,"b":[["15513.59000000","0.00000000"],["15512.78000000","0.01528700"],["15512.56000000","0.11427900"],["15508.96000000","0.00000000"],["15438.49000000","0.00647700"],["15435.61000000","0.24000000"]],"a":[["15516.79000000","2.67481200"],["15517.25000000","0.01978600"],["15517.99000000","0.00000000"],["15518.06000000","0.02936200"],["15519.75000000","0.08000000"],["15532.10000000","0.24000000"]]}}
2020-11-09T11:25:14.99888 btcusdt {"stream":"btcusdt@depth@100ms","data":{"e":"depthUpdate","E":1604921114990,"s":"BTCUSDT","U":6511126668,"u":6511126676,"b":[["15516.08000000","2.63042200"],["15513.36000000","0.00000000"],["15511.31000000","0.05000000"],["15511.29000000","0.02106400"],["15509.08000000","0.51059500"],["15507.34000000","0.12890500"],["15505.67000000","0.00000000"]],"a":[["15516.79000000","0.16373500"]]}}
2020-11-09T11:25:15.09803 btcusdt {"stream":"btcusdt@depth@100ms","data":{"e":"depthUpdate","E":1604921115091,"s":"BTCUSDT","U":6511126677,"u":6511126679,"b":[["15511.75000000","0.16429600"],["15510.47000000","0.00000000"],["15504.04000000","0.50415200"]],"a":[]}}
2020-11-09T11:25:15.20055 btcusdt {"stream":"btcusdt@depth@100ms","data":{"e":"depthUpdate","E":1604921115191,"s":"BTCUSDT","U":6511126680,"u":6511126682,"b":[],"a":[["15516.09000000","6.10823600"],["15519.10000000","0.00000000"],["15573.00000000","0.17227700"]]}}
2020-11-09T11:25:15.29765 btcusdt {"stream":"btcusdt@depth@100ms","data":{"e":"depthUpdate","E":1604921115291,"s":"BTCUSDT","U":6511126683,"u":6511126688,"b":[["15516.08000000","2.00690000"],["15512.28000000","0.00000000"],["15509.08000000","0.00000000"]],"a":[["15518.97000000","0.08000000"],["15519.19000000","0.11427900"]]}}
2020-11-09T11:25:15.39821 btcusdt {"stream":"btcusdt@depth@100ms","data":{"e":"depthUpdate","E":1604921115391,"s":"BTCUSDT","U":6511126689,"u":6511126695,"b":[["15512.63000000","0.01432200"],["15511.75000000","0.00000000"],["15510.47000000","0.16429600"]],"a":[["15516.09000000","6.23623600"],["15516.55000000","0.00848500"],["15516.82000000","5.33005500"],["15519.11000000","2.00000000"]]}}
2020-11-09T11:25:15.49721 btcusdt {"stream":"btcusdt@depth@100ms","data":{"e":"depthUpdate","E":1604921115491,"s":"BTCUSDT","U":6511126696,"u":6511126701,"b":[["15509.76000000","0.00000000"],["15508.53000000","0.00000000"],["15507.78000000","0.00000000"],["15505.83000000","1.00000000"],["15502.93000000","1.50000000"]],"a":[["15516.82000000","5.32805500"]]}}
2020-11-09T11:25:15.59770 btcusdt {"stream":"btcusdt@depth@100ms","data":{"e":"depthUpdate","E":1604921115591,"s":"BTCUSDT","U":6511126702,"u":6511126706,"b":[["15510.47000000","0.32429600"],["15510.46000000","0.00000000"],["15435.61000000","0.00000000"]],"a":[["15532.10000000","0.00000000"],["15571.00000000","3.17150100"]]}}
2020-11-09T11:25:15.69790 btcusdt {"stream":"btcusdt@depth@100ms","data":{"e":"depthUpdate","E":1604921115691,"s":"BTCUSDT","U":6511126707,"u":6511126717,"b":[["15516.08000000","2.00481600"],["15512.56000000","0.00000000"],["15512.09000000","0.11427900"],["15509.49000000","0.15680600"],["14643.20000000","0.00171000"]],"a":[["15516.09000000","7.12617800"],["15516.78000000","0.10000000"],["15517.98000000","0.00000000"],["15518.00000000","12.89394700"],["15532.13000000","0.24000000"]]}}
2020-11-09T11:25:15.79771 btcusdt {"stream":"btcusdt@depth@100ms","data":{"e":"depthUpdate","E":1604921115791,"s":"BTCUSDT","U":6511126718,"u":6511126727,"b":[["15516.08000000","0.00481600"],["15512.49000000","0.00000000"],["15509.49000000","0.00000000"],["15434.59000000","0.24000000"]],"a":[["15516.14000000","0.01916300"],["15516.55000000","0.00706300"],["15516.77000000","0.78253600"],["15518.06000000","0.00000000"],["15532.13000000","0.00000000"]]}}
2020-11-09T11:25:15.89752 btcusdt {"stream":"btcusdt@depth@100ms","data":{"e":"depthUpdate","E":1604921115891,"s":"BTCUSDT","U":6511126728,"u":6511126736,"b":[["15516.08000000","0.00385000"],["15511.28000000","0.00000000"],["15434.59000000","0.00000000"],["15430.74000000","0.24000000"]],"a":[["15516.09000000","9.12617800"],["15516.55000000","0.00000000"],["15527.75000000","0.24000000"],["15570.00000000","50.43026000"],["15573.00000000","0.54910700"]]}}
2020-11-09T11:25:15.99767 btcusdt {"stream":"btcusdt@depth@100ms","data":{"e":"depthUpdate","E":1604921115991,"s":"BTCUSDT","U":6511126737,"u":6511126753,"b":[["15511.31000000","0.00000000"],["15511.26000000","0.05000000"],["15508.22000000","0.06731400"],["15507.37000000","1.14047300"],["15505.97000000","0.00000000"],["15503.97000000","0.00000000"]],"a":[["15516.55000000","0.00857900"],["15519.99000000","0.06000000"],["15520.44000000","0.01700000"],["15520.70000000","0.00000000"],["15521.36000000","0.01000000"],["15521.76000000","0.01500000"],["15522.50000000","0.00000000"],["15522.90000000","0.00000000"]]}}
2020-11-09T11:25:16.09759 btcusdt {"stream":"btcusdt@depth@100ms","data":{"e":"depthUpdate","E":1604921116091,"s":"BTCUSDT","U":6511126754,"u":6511126760,"b":[["15512.09000000","0.00000000"],["15501.58000000","0.20000000"],["14643.20000000","0.02511000"]],"a":[["15516.55000000","0.00682600"],["15518.96000000","0.12892000"],["15520.42000000","0.16114100"]]}}
2020-11-09T11:25:16.19813 btcusdt {"stream":"btcusdt@depth@100ms","data":{"e":"depthUpdate","E":1604921116191,"s":"BTCUSDT","U":6511126761,"u":6511126764,"b":[["15511.30000000","0.00000000"]],"a":[["15516.55000000","0.00813200"],["15533.39000000","0.00000000"]]}}
2020-11-09T11:25:16.30115 btcusdt {"stream":"btcusdt@depth@100ms","data":{"e":"depthUpdate","E":1604921116291,"s":"BTCUSDT","U":6511126765,"u":6511126770,"b":[["15509.37000000","0.02500000"],["15508.79000000","0.15680600"],["15499.58000000","0.20000000"]],"a":[["15516.55000000","0.00769200"],["15531.12000000","0.02500000"]]}}
2020-11-09T11:25:16.39928 btcusdt {"stream":"btcusdt@depth@100ms","data":{"e":"depthUpdate","E":1604921116391,"s":"BTCUSDT","U":6511126771,"u":6511126772,"b":[["15508.79000000","0.00000000"],["15507.20000000","0.48811800"]],"a":[]}}
2020-11-09T11:25:16.50258 btcusdt {"stream":"btcusdt@depth@100ms","data":{"e":"depthUpdate","E":1604921116491,"s":"BTCUSDT","U":6511126773,"u":6511126786,"b":[["15516.08000000","0.00036700"],["15514.25000000","0.07901300"],["15514.20000000","0.00000000"],["15510.47000000","0.16000000"],["15508.79000000","0.16429600"],["15507.20000000","0.00000000"],["15502.93000000","0.00000000"],["15502.45000000","1.63420700"]],"a":[["15516.12000000","0.01916300"],["15516.14000000","0.00000000"],["15516.64000000","0.52054700"],["15516.82000000","0.02805500"],["15519.07000000","0.00000000"],["15521.31000000","1.74800000"]]}}
2020-11-09T11:25:16.60052 btcusdt {"stream":"btcusdt@depth@100ms","data":{"e":"depthUpdate","E":1604921116591,"s":"BTCUSDT","U":6511126787,"u":6511126796,"b":[["15511.02000000","0.11427900"],["15508.79000000","0.00000000"],["15508.28000000","0.00000000"],["15505.98000000","1.25000000"]],"a":[["15516.09000000","9.03806700"],["15516.63000000","0.78253600"],["15516.64000000","0.00000000"],["15516.77000000","0.00000000"],["15520.41000000","0.00318800"]]}}
2020-11-09T11:25:16.69924 btcusdt {"stream":"btcusdt@depth@100ms","data":{"e":"depthUpdate","E":1604921116691,"s":"BTCUSDT","U":6511126797,"u":6511126806,"b":[["15511.29000000","0.00000000"],["15508.79000000","0.00000000"],["15507.52000000","0.02106400"]],"a":[["15516.55000000","0.00854900"],["15516.63000000","0.00000000"],["15531.74000000","1.22566800"],["15534.82000000","0.00000000"],["15550.00000000","39.55049600"]]}}
2020-11-09T11:25:16.79919 btcusdt {"stream":"btcusdt@depth@100ms","data":{"e":"depthUpdate","E":1604921116792,"s":"BTCUSDT","U":6511126807,"u":6511126815,"b":[["15512.78000000","0.00000000"],["15511.96000000","0.01563200"],["15508.79000000","0.16429600"],["15420.00000000","0.97585000"]],"a":[["15516.09000000","9.28806700"],["15516.62000000","0.78253600"],["15516.81000000","0.00000000"],["15516.86000000","0.01294300"],["15517.25000000","0.00000000"]]}}
2020-11-09T11:25:16.89914 btcusdt {"stream":"btcusdt@depth@100ms","data":{"e":"depthUpdate","E":1604921116892,"s":"BTCUSDT","U":6511126816,"u":6511126821,"b":[["15512.63000000","0.00690000"]],"a":[["15516.55000000","0.00000000"],["15516.61000000","0.78253600"],["15516.62000000","0.00000000"],["15526.37000000","0.05681600"],["15529.87000000","0.00000000"]]}}
2020-11-09T11:25:16.99839 btcusdt {"stream":"btcusdt@depth@100ms","data":{"e":"depthUpdate","E":1604921116992,"s":"BTCUSDT","U":6511126822,"u":6511126888,"b":[["15516.08000000","0.00000000"],["15515.45000000","0.00690000"],["15514.99000000","2.00000000"],["15514.81000000","0.00000000"],["15511.58000000","0.00000000"],["15511.45000000","0.00000000"],["15511.26000000","0.00000000"],["15511.02000000","0.00000000"],["15510.93000000","0.05000000"],["15510.80000000","1.58300000"],["15510.64000000","1.59300000"],["15509.92000000","0.11427900"],["15509.47000000","0.00000000"],["15508.78000000","0.00000000"],["15507.38000000","0.02236400"],["15507.37000000","0.00000000"],["15505.10000000","0.00000000"]],"a":[["15515.46000000","6.85804900"],["15515.75000000","0.00000000"],["15515.76000000","0.05914800"],["15515.85000000","0.05285500"],["15515.90000000","0.78253600"],["15515.91000000","0.06039000"],["15515.93000000","0.00000000"],["15516.02000000","0.05202100"],["15516.08000000","5.30000000"],["15516.09000000","2.85952600"],["15516.10000000","0.00000000"],["15516.12000000","0.00000000"],["15516.61000000","0.00000000"],["15516.82000000","0.00000000"],["15519.19000000","0.00000000"],["15519.23000000","1.00000000"],["15519.43000000","0.03400000"],["15520.28000000","1.74800000"],["15520.44000000","0.00000000"],["15520.45000000","0.00000000"],["15521.31000000","0.00000000"],["15525.93000000","0.00000000"],["15526.07000000","1.00832200"],["15527.74000000","0.28040800"]]}}
2020-11-09T11:25:17.09915 btcusdt {"stream":"btcusdt@depth@100ms","data":{"e":"depthUpdate","E":1604921117092,"s":"BTCUSDT","U":6511126889,"u":6511126924,"b":[["15512.46000000","0.00000000"],["15510.93000000","0.00000000"],["15510.48000000","0.05000000"],["15509.75000000","0.00000000"],["15508.79000000","0.00000000"],["15508.23000000","0.03626500"],["15394.29000000","0.00000000"]],"a":[["15515.46000000","6.72213500"],["15515.89000000","0.78253600"],["15515.90000000","0.16000000"],["15516.09000000","2.31109700"],["15518.96000000","0.00000000"],["15519.72000000","0.05000000"],["15519.99000000","0.00000000"],["15520.07000000","0.01000000"],["15520.41000000","0.00000000"],["15520.42000000","0.00000000"],["15520.74000000","0.25758300"],["15520.78000000","2.00000000"],["15520.91000000","0.00000000"],["15521.20000000","0.08200000"],["15521.36000000","0.00000000"],["15521.65000000","3.90055300"],["15521.76000000","0.00000000"],["15521.87000000","1.59300000"],["15522.28000000","0.00000000"],["15525.80000000","0.20000000"],["15527.84000000","0.00000000"],["15530.04000000","0.00000000"],["15537.09000000","0.00000000"]]}}
2020-11-09T11:25:17.20267 btcusdt {"stream":"btcusdt@depth@100ms","data":{"e":"depthUpdate","E":1604921117192,"s":"BTCUSDT","U":6511126925,"u":6511126938,"b":[["15505.85000000","0.01900000"],["15462.09000000","0.00000000"],["15405.32000000","0.38298400"]],"a":[["15515.46000000","7.35718400"],["15516.09000000","2.16109700"],["15516.78000000","0.00000000"],["15516.79000000","0.00000000"],["15522.27000000","0.01500000"],["15524.47000000","0.01382400"],["15527.73000000","0.45706100"]]}}
2020-11-09T11:25:17.30378 btcusdt {"stream":"btcusdt@depth@100ms","data":{"e":"depthUpdate","E":1604921117292,"s":"BTCUSDT","U":6511126939,"u":6511126941,"b":[["15508.24000000","0.17119600"]],"a":[["15515.88000000","0.78253600"],["15515.89000000","0.00000000"]]}}
2020-11-09T11:25:17.40351 btcusdt {"stream":"btcusdt@depth@100ms","data":{"e":"depthUpdate","E":1604921117392,"s":"BTCUSDT","U":6511126942,"u":6511126953,"b":[["15515.45000000","0.00000000"],["15514.99000000","1.98707600"],["15514.41000000","0.07687500"],["15514.25000000","0.00000000"],["15507.51000000","0.00000000"],["15498.49000000","0.00000000"],["15438.49000000","0.00000000"]],"a":[["15515.46000000","6.55096400"],["15515.87000000","0.78253600"],["15515.88000000","0.00000000"],["15518.20000000","0.11427900"],["15521.27000000","0.15150000"]]}}
2020-11-09T11:25:17.49850 btcusdt {"stream":"btcusdt@depth@100ms","data":{"e":"depthUpdate","E":1604921117492,"s":"BTCUSDT","U":6511126954,"u":6511126995,"b":[["15514.99000000","1.99397600"],["15511.87000000","0.00612700"],["15510.54000000","0.11427900"],["15510.48000000","0.00000000"],["15510.01000000","0.05000000"],["15509.92000000","0.00000000"],["15508.24000000","0.17119600"],["15459.26000000","0.03020000"]],"a":[["15515.00000000","7.40343200"],["15515.23000000","0.00690000"],["15515.40000000","0.39240300"],["15515.41000000","0.74335500"],["15515.45000000","0.16127400"],["15515.46000000","5.68311200"],["15515.87000000","0.00000000"],["15515.90000000","0.00000000"],["15515.92000000","0.00734400"],["15516.08000000","0.00000000"],["15516.09000000","2.13388500"],["15516.43000000","0.01453200"],["15516.86000000","0.00000000"],["15519.42000000","0.05000000"],["15519.71000000","0.01000000"],["15519.72000000","0.00000000"],["15520.07000000","0.00000000"],["15521.49000000","0.01000000"],["15521.87000000","1.58300000"],["15525.62000000","0.10000000"],["15528.00000000","0.00000000"],["15535.17000000","0.00000000"],["15615.00000000","8.00455500"]]}}
2020-11-09T11:25:17.59867 btcusdt {"stream":"btcusdt@depth@100ms","data":{"e":"depthUpdate","E":1604921117592,"s":"BTCUSDT","U":6511126996,"u":6511127004,"b":[["15514.99000000","1.84988800"],["15506.75000000","0.48493200"],["15505.99000000","0.20000000"]],"a":[["15515.00000000","7.69581300"],["15515.45000000","0.94381000"],["15516.46000000","0.51390600"],["15519.82000000","0.32100000"]]}}
2020-11-09T11:25:17.69849 btcusdt {"stream":"btcusdt@depth@100ms","data":{"e":"depthUpdate","E":1604921117692,"s":"BTCUSDT","U":6511127005,"u":6511127020,"b":[["15514.99000000","0.00890000"],["15514.41000000","0.00000000"],["15507.34000000","0.00000000"],["15506.75000000","0.00000000"],["15505.99000000","0.00000000"],["15505.46000000","0.12890500"],["15399.00000000","0.48510300"],["14461.21000000","3.50000000"]],"a":[["15515.00000000","7.77581300"],["15515.39000000","0.78253600"],["15515.45000000","0.16127400"],["15515.46000000","5.61811200"],["15515.52000000","0.02055300"],["15518.36000000","0.25690000"],["15523.02000000","0.50000000"]]}}
2020-11-09T11:25:17.80117 btcusdt {"stream":"btcusdt@depth@100ms","data":{"e":"depthUpdate","E":1604921117792,"s":"BTCUSDT","U":6511127021,"u":6511127037,"b":[["15514.99000000","0.00001900"],["15511.96000000","0.00000000"],["15511.87000000","0.00000000"],["15510.54000000","0.00000000"],["15507.53000000","0.00000000"]],"a":[["15515.00000000","9.77581300"],["15515.46000000","0.31811200"],["15515.50000000","0.02055300"],["15515.52000000","0.00000000"],["15516.43000000","0.00000000"],["15519.11000000","0.00000000"],["15519.19000000","0.03222700"],["15521.13000000","0.00000000"],["15544.82000000","0.00000000"]]}}
2020-11-09T11:25:17.89858 btcusdt {"stream":"btcusdt@depth@100ms","data":{"e":"depthUpdate","E":1604921117892,"s":"BTCUSDT","U":6511127038,"u":6511127078,"b":[["15513.79000000","0.00000000"],["15512.34000000","0.00000000"],["15511.74000000","0.00000000"],["15511.25000000","0.00000000"],["15510.80000000","0.00000000"],["15510.64000000","0.00000000"],["15510.63000000","0.28000000"],["15510.47000000","0.00000000"],["15509.91000000","0.02000000"],["15509.89000000","1.58300000"],["15509.74000000","0.11427900"],["15509.73000000","1.59300000"],["15508.47000000","0.16000000"],["15508.23000000","0.00000000"],["15507.52000000","0.00000000"],["15506.84000000","0.05732900"],["15505.83000000","0.00000000"],["15505.73000000","0.00000000"],["15504.50000000","0.00000000"],["15502.75000000","1.00000000"],["15437.41000000","0.00647700"],["15420.00000000","0.59902000"]],"a":[["15515.00000000","9.79636600"],["15515.50000000","0.00000000"],["15517.43000000","0.33823100"],["15519.19000000","0.00000000"],["15519.75000000","0.58000000"],["15520.06000000","1.19800000"],["15520.23000000","1.59300000"],["15520.24000000","1.58300000"],["15520.97000000","0.00000000"],["15521.87000000","0.00000000"],["15522.05000000","0.00000000"],["15523.02000000","0.00000000"],["15523.13000000","0.00000000"],["15524.64000000","0.14700000"],["15570.00000000","50.53853300"]]}}
2020-11-09T11:25:17.99912 btcusdt {"stream":"btcusdt@depth@100ms","data":{"e":"depthUpdate","E":1604921117992,"s":"BTCUSDT","U":6511127079,"u":6511127095,"b":[["15510.01000000","0.00000000"],["15509.37000000","0.07500000"],["15506.84000000","0.21413500"],["15506.82000000","0.00000000"],["15505.46000000","0.00000000"],["15504.30000000","0.50000000"],["15503.50000000","0.12892400"],["15493.75000000","0.28500000"]],"a":[["15515.39000000","0.00000000"],["15517.43000000","0.41823100"],["15519.33000000","0.05000000"],["15519.42000000","0.00000000"],["15520.43000000","0.00000000"],["15526.06000000","0.02422500"],["15529.99000000","0.00000000"],["15535.30000000","0.00000000"]]}}
2020-11-09T11:25:18.09840 btcusdt {"stream":"btcusdt@depth@100ms","data":{"e":"depthUpdate","E":1604921118092,"s":"BTCUSDT","U":6511127096,"u":6511127110,"b":[["15508.55000000","0.49512300"],["15506.72000000","0.12892400"],["15503.50000000","0.00000000"],["15492.37000000","0.19115400"],["15479.26000000","0.00200000"]],"a":[["15515.39000000","0.78253600"],["15515.84000000","0.12894500"],["15525.54000000","0.02968800"],["15526.06000000","0.04805300"],["15526.37000000","0.08233400"],["15532.69000000","0.00000000"],["15539.99000000","0.00000000"],["15547.67000000","0.01200000"],["15556.85000000","0.00160700"]]}}
2020-11-09T11:25:18.20099 btcusdt {"stream":"btcusdt@depth@100ms","data":{"e":"depthUpdate","E":1604921118192,"s":"BTCUSDT","U":6511127111,"u":6511127124,"b":[["15509.74000000","0.00000000"],["15506.84000000","0.05732900"],["15505.99000000","0.15680600"]],"a":[["15515.39000000","0.00000000"],["15515.92000000","0.00000000"],["15519.69000000","0.01000000"],["15519.71000000","0.00000000"],["15521.34000000","1.25000000"],["15521.89000000","0.01500000"],["15522.27000000","0.00000000"],["15524.47000000","0.41931300"],["15525.55000000","0.00000000"],["15527.74000000","0.30847300"],["15536.06000000","0.00000000"]]}}
2020-11-09T11:25:18.29928 btcusdt {"stream":"btcusdt@depth@100ms","data":{"e":"depthUpdate","E":1604921118292,"s":"BTCUSDT","U":6511127125,"u":6511127128,"b":[["15511.03000000","0.00000000"],["15509.08000000","0.11427900"]],"a":[["15515.00000000","7.79636600"],["15526.23000000","0.00000000"]]}}
2020-11-09T11:25:18.40183 btcusdt {"stream":"btcusdt@depth@100ms","data":{"e":"depthUpdate","E":1604921118392,"s":"BTCUSDT","U":6511127129,"u":6511127136,"b":[["15511.82000000","0.01780800"],["15504.05000000","0.00000000"],["15502.45000000","0.13420700"]],"a":[["15515.00000000","7.73633900"],["15519.03000000","0.25761500"],["15521.34000000","0.00000000"]]}}
2020-11-09T11:25:18.50202 btcusdt {"stream":"btcusdt@depth@100ms","data":{"e":"depthUpdate","E":1604921118492,"s":"BTCUSDT","U":6511127137,"u":6511127164,"b":[["15514.99000000","1.97822700"],["15511.66000000","0.00648300"],["15509.37000000","0.05000000"],["15506.84000000","0.02106400"],["15506.73000000","0.50000000"],["15505.99000000","0.00000000"],["15505.70000000","1.00000000"],["15505.64000000","0.03626500"],["15504.30000000","0.00000000"],["15502.75000000","0.00000000"],["15501.80000000","1.50000000"],["15493.45000000","0.14850000"]],"a":[["15515.00000000","7.61327900"],["15515.47000000","0.00679300"],["15516.37000000","0.01311800"],["15518.50000000","0.10000000"],["15521.29000000","0.29400000"],["15524.24000000","0.00288000"],["15524.26000000","1.25000000"],["15525.39000000","0.50000000"],["15525.94000000","1.00000000"],["15527.34000000","1.50000000"],["15528.35000000","0.00000000"],["15528.36000000","0.00000000"],["15531.12000000","0.00000000"],["15531.38000000","0.00000000"]]}}
2020-11-09T11:25:18.60131 btcusdt {"stream":"btcusdt@depth@100ms","data":{"e":"depthUpdate","E":1604921118593,"s":"BTCUSDT","U":6511127165,"u":6511127175,"b":[["15511.82000000","0.00000000"],["15511.70000000","0.01937200"],["15508.55000000","0.30000000"],["15507.39000000","0.02500000"],["15505.99000000","0.15680600"],["15505.65000000","0.20000000"],["15417.00000000","0.37683000"]],"a":[["15516.20000000","0.01625400"],["15516.37000000","0.00000000"],["15529.18000000","0.02500000"],["15612.00000000","0.10827300"]]}}
2020-11-09T11:25:18.70168 btcusdt {"stream":"btcusdt@depth@100ms","data":{"e":"depthUpdate","E":1604921118693,"s":"BTCUSDT","U":6511127176,"u":6511127189,"b":[["15511.66000000","0.00000000"],["15511.49000000","0.00609500"],["15510.44000000","0.11427900"],["15509.08000000","0.00000000"],["15507.40000000","0.03626500"],["15506.06000000","0.50684400"],["15505.64000000","0.00000000"],["15499.85000000","0.00000000"],["15491.97000000","0.87000000"]],"a":[["15515.00000000","7.60825100"],["15515.46000000","0.32455200"],["15515.47000000","0.00000000"],["15524.26000000","0.00000000"],["15525.03000000","1.25000000"]]}}
2020-11-09T11:25:18.80095 btcusdt {"stream":"btcusdt@depth@100ms","data":{"e":"depthUpdate","E":1604921118793,"s":"BTCUSDT","U":6511127190,"u":6511127194,"b":[["15511.70000000","0.00000000"],["15511.02000000","0.01376900"],["15396.00000000","0.37683000"]],"a":[["15515.19000000","0.00200000"],["15515.84000000","0.00000000"]]}}
2020-11-09T11:25:18.90052 btcusdt {"stream":"btcusdt@depth@100ms","data":{"e":"depthUpdate","E":1604921118893,"s":"BTCUSDT","U":6511127195,"u":6511127212,"b":[["15511.49000000","0.00000000"],["15510.45000000","0.08000000"],["15509.82000000","0.00638100"],["15475.22000000","0.50000000"],["15472.12000000","0.00220200"]],"a":[["15515.46000000","0.32432200"],["15515.77000000","0.01897800"],["15516.09000000","2.12800000"],["15516.20000000","0.00000000"],["15519.75000000","0.08000000"],["15520.76000000","0.00000000"],["15522.04000000","0.00000000"],["15525.03000000","0.00000000"],["15525.37000000","0.05681600"],["15525.53000000","1.25000000"],["15526.37000000","0.02551800"]]}}
2020-11-09T11:25:19.04350 btcusdt {"stream":"btcusdt@depth@100ms","data":{"e":"depthUpdate","E":1604921118993,"s":"BTCUSDT","U":6511127213,"u":6511127228,"b":[["15514.99000000","1.96606500"],["15510.00000000","0.04080000"],["15509.47000000","0.05000000"],["15509.37000000","0.00000000"],["15506.53000000","0.96703100"]],"a":[["15515.46000000","0.22432200"],["15517.42000000","0.10000000"],["15519.99000000","0.20000000"],["15521.11000000","0.50000000"],["15524.10000000","0.00000000"],["15527.67000000","0.02806500"],["15527.74000000","0.28040800"],["15531.00000000","0.00969100"],["15570.00000000","50.91536300"]]}}
2020-11-09T11:25:19.09967 btcusdt {"stream":"btcusdt@depth@100ms","data":{"e":"depthUpdate","E":1604921119093,"s":"BTCUSDT","U":6511127229,"u":6511127233,"b":[["15510.64000000","0.10821000"],["15505.99000000","0.00000000"]],"a":[["15515.46000000","0.22032200"],["15519.02000000","0.12891500"]]}}
2020-11-09T11:25:19.19976 btcusdt {"stream":"btcusdt@depth@100ms","data":{"e":"depthUpdate","E":1604921119193,"s":"BTCUSDT","U":6511127234,"u":6511127243,"b":[["15511.47000000","0.50000000"],["15510.01000000","0.03626500"],["15507.41000000","0.15680600"],["15507.40000000","0.00000000"],["15504.25000000","1.50000000"],["15501.80000000","0.00000000"],["15476.21000000","0.25000000"]],"a":[["15517.53000000","0.50000000"],["15525.94000000","0.00000000"],["15528.36000000","1.00000000"]]}}
2020-11-09T11:25:19.31660 btcusdt {"stream":"btcusdt@depth@100ms","data":{"e":"depthUpdate","E":1604921119293,"s":"BTCUSDT","U":6511127244,"u":6511127252,"b":[["15514.99000000","1.96145300"],["15511.03000000","0.16429600"],["15511.02000000","0.00000000"],["15509.73000000","1.60543900"],["15508.24000000","0.00690000"],["15505.65000000","0.00000000"],["15417.00000000","0.48510300"]],"a":[["15553.78000000","0.25097800"]]}}
2020-11-09T11:25:19.40067 btcusdt {"stream":"btcusdt@depth@100ms","data":{"e":"depthUpdate","E":1604921119393,"s":"BTCUSDT","U":6511127253,"u":6511127261,"b":[["15512.75000000","0.00807800"],["15509.82000000","0.00000000"],["15465.00000000","0.07175200"]],"a":[["15515.00000000","7.68783100"],["15515.45000000","0.00627400"],["15515.46000000","0.22315700"],["15518.36000000","0.00690000"]]}}
2020-11-09T11:25:19.50155 btcusdt {"stream":"btcusdt@depth@100ms","data":{"e":"depthUpdate","E":1604921119493,"s":"BTCUSDT","U":6511127262,"u":6511127264,"b":[["15510.01000000","0.00000000"],["15509.73000000","1.59300000"],["15508.14000000","0.32100000"]],"a":[]}}
2020-11-09T11:25:19.60021 btcusdt {"stream":"btcusdt@depth@100ms","data":{"e":"depthUpdate","E":1604921119593,"s":"BTCUSDT","U":6511127265,"u":6511127270,"b":[["15512.75000000","0.00000000"],["15508.56000000","0.03626500"]],"a":[["15515.46000000","0.21411200"],["15515.77000000","0.00000000"],["15519.78000000","0.75000000"],["15525.83000000","0.02072300"]]}}
2020-11-09T11:25:19.70056 btcusdt {"stream":"btcusdt@depth@100ms","data":{"e":"depthUpdate","E":1604921119693,"s":"BTCUSDT","U":6511127271,"u":6511127275,"b":[["15514.99000000","1.94152100"],["15250.00000000","10.94044200"]],"a":[["15517.42000000","0.00000000"],["15525.37000000","0.00000000"],["15570.00000000","50.53853300"]]}}
2020-11-09T11:25:19.80108 btcusdt {"stream":"btcusdt@depth@100ms","data":{"e":"depthUpdate","E":1604921119793,"s":"BTCUSDT","U":6511127276,"u":6511127285,"b":[["15514.99000000","2.44152100"],["15514.22000000","0.01793000"],["15510.93000000","0.11427900"],["15510.44000000","0.00000000"]],"a":[["15515.00000000","7.65233100"],["15516.09000000","0.12800000"],["15516.46000000","0.00690000"],["15516.56000000","0.01395700"],["15517.42000000","0.10000000"],["15525.54000000","0.00000000"]]}}
2020-11-09T11:25:19.90215 btcusdt {"stream":"btcusdt@depth@100ms","data":{"e":"depthUpdate","E":1604921119893,"s":"BTCUSDT","U":6511127286,"u":6511127298,"b":[["15514.22000000","0.01954500"],["15510.01000000","0.05732900"],["15508.56000000","0.00000000"],["15507.41000000","0.00000000"],["15506.84000000","0.00000000"]],"a":[["15515.46000000","0.05037700"],["15516.55000000","0.16373500"],["15517.43000000","0.11223100"],["15525.52000000","0.02968800"],["15527.34000000","0.00000000"],["15529.69000000","1.50000000"]]}}
2020-11-09T11:25:20.00017 btcusdt {"stream":"btcusdt@depth@100ms","data":{"e":"depthUpdate","E":1604921119993,"s":"BTCUSDT","U":6511127299,"u":6511127314,"b":[["15514.22000000","0.01440600"],["15509.74000000","0.05000000"],["15509.47000000","0.00000000"],["15507.42000000","0.15680600"]],"a":[["15515.00000000","7.78133100"],["15516.09000000","0.00000000"],["15519.10000000","0.03364100"],["15519.99000000","0.00000000"],["15527.33000000","0.48374700"],["15527.67000000","0.00000000"],["15527.73000000","0.00137900"]]}}
2020-11-09T11:25:20.10090 btcusdt {"stream":"btcusdt@depth@100ms","data":{"e":"depthUpdate","E":1604921120093,"s":"BTCUSDT","U":6511127315,"u":6511127316,"b":[["15430.74000000","0.00000000"]],"a":[["15570.00000000","50.43026000"]]}}
2020-11-09T11:25:20.20161 btcusdt {"stream":"btcusdt@depth@100ms","data":{"e":"depthUpdate","E":1604921120193,"s":"BTCUSDT","U":6511127317,"u":6511127317,"b":[],"a":[["15528.89000000","0.00000000"]]}}
2020-11-09T11:25:20.30024 btcusdt {"stream":"btcusdt@depth@100ms","data":{"e":"depthUpdate","E":1604921120293,"s":"BTCUSDT","U":6511127318,"u":6511127327,"b":[["15514.22000000","0.00000000"],["15511.61000000","0.01829100"]],"a":[["15515.00000000","2.34133100"],["15516.13000000","0.01271700"],["15516.56000000","0.00000000"],["15517.41000000","0.35956500"],["15517.99000000","2.72533500"],["15524.54000000","0.29137400"],["15528.04000000","0.00000000"]]}}
2020-11-09T11:25:20.40226 btcusdt {"stream":"btcusdt@depth@100ms","data":{"e":"depthUpdate","E":1604921120393,"s":"BTCUSDT","U":6511127328,"u":6511127333,"b":[["15511.57000000","0.00777400"],["15510.45000000","0.00000000"],["15396.00000000","0.00000000"]],"a":[["15515.00000000","2.28127300"],["15515.46000000","0.05756800"],["15522.32000000","0.20000000"]]}}
2020-11-09T11:25:20.50445 btcusdt {"stream":"btcusdt@depth@100ms","data":{"e":"depthUpdate","E":1604921120494,"s":"BTCUSDT","U":6511127334,"u":6511127338,"b":[["15508.56000000","0.15680600"],["15507.42000000","0.00000000"]],"a":[["15517.99000000","2.91944300"],["15519.55000000","1.19800000"],["15520.06000000","0.00000000"]]}}
2020-11-09T11:25:20.60574 btcusdt {"stream":"btcusdt@depth@100ms","data":{"e":"depthUpdate","E":1604921120594,"s":"BTCUSDT","U":6511127339,"u":6511127346,"b":[["15507.18000000","0.00000000"],["15506.58000000","0.20000000"],["15420.00000000","0.97585000"]],"a":[["15519.03000000","0.00000000"],["15520.28000000","2.18800000"],["15521.65000000","0.01055300"],["15528.39000000","0.26448000"]]}}
2020-11-09T11:25:20.70147 btcusdt {"stream":"btcusdt@depth@100ms","data":{"e":"depthUpdate","E":1604921120694,"s":"BTCUSDT","U":6511127347,"u":6511127353,"b":[["15514.99000000","2.43637000"]],"a":[["15515.00000000","7.58127300"],["15515.46000000","0.05037700"],["15517.41000000","0.00000000"],["15517.99000000","0.00000000"],["15524.54000000","0.14550000"]]}}
2020-11-09T11:25:20.80160 btcusdt {"stream":"btcusdt@depth@100ms","data":{"e":"depthUpdate","E":1604921120794,"s":"BTCUSDT","U":6511127354,"u":6511127359,"b":[["15506.58000000","0.00000000"]],"a":[["15516.16000000","0.39387300"],["15524.53000000","0.17732300"],["15600.00000000","211.95420500"],["15612.00000000","0.48510300"],["15615.00000000","8.11282800"]]}}
2020-11-09T11:25:20.90018 btcusdt {"stream":"btcusdt@depth@100ms","data":{"e":"depthUpdate","E":1604921120894,"s":"BTCUSDT","U":6511127360,"u":6511127361,"b":[],"a":[["15519.51000000","0.08200000"],["15521.20000000","0.00000000"]]}}
2020-11-09T11:25:21.00166 btcusdt {"stream":"btcusdt@depth@100ms","data":{"e":"depthUpdate","E":1604921120994,"s":"BTCUSDT","U":6511127362,"u":6511127368,"b":[["15510.01000000","0.02106400"],["15509.90000000","0.05000000"],["15509.74000000","0.00000000"]],"a":[["15516.09000000","0.10586200"],["15519.68000000","0.20000000"],["15585.28000000","0.00080000"],["15625.50000000","0.05308100"]]}}
2020-11-09T11:25:21.10090 btcusdt {"stream":"btcusdt@depth@100ms","data":{"e":"depthUpdate","E":1604921121094,"s":"BTCUSDT","U":6511127369,"u":6511127370,"b":[["15508.57000000","0.03626500"]],"a":[["15518.96000000","0.12891900"]]}}
2020-11-09T11:25:21.20143 btcusdt {"stream":"btcusdt@depth@100ms","data":{"e":"depthUpdate","E":1604921121194,"s":"BTCUSDT","U":6511127371,"u":6511127371,"b":[["15430.15000000","0.24000000"]],"a":[]}}
2020-11-09T11:25:21.30111 btcusdt {"stream":"btcusdt@depth@100ms","data":{"e":"depthUpdate","E":1604921121294,"s":"BTCUSDT","U":6511127372,"u":6511127375,"b":[["15514.99000000","2.43265000"]],"a":[["15515.46000000","0.05711000"],["15518.96000000","0.00000000"],["15624.00000000","0.01268300"]]}}
2020-11-09T11:25:21.40135 btcusdt {"stream":"btcusdt@depth@100ms","data":{"e":"depthUpdate","E":1604921121394,"s":"BTCUSDT","U":6511127376,"u":6511127379,"b":[["15514.99000000","1.88265000"]],"a":[["15515.46000000","0.06018600"]]}}
2020-11-09T11:25:21.50033 btcusdt {"stream":"btcusdt@depth@100ms","data":{"e":"depthUpdate","E":1604921121494,"s":"BTCUSDT","U":6511127380,"u":6511127386,"b":[],"a":[["15515.00000000","7.52123600"],["15515.46000000","0.05758100"],["15518.68000000","0.03400000"],["15519.43000000","0.00000000"]]}}
2020-11-09T11:25:21.60080 btcusdt {"stream":"btcusdt@depth@100ms","data":{"e":"depthUpdate","E":1604921121594,"s":"BTCUSDT","U":6511127387,"u":6511127395,"b":[],"a":[["15515.46000000","0.05907500"],["15516.12000000","0.10000000"],["15517.42000000","0.00000000"],["15518.85000000","1.78000000"],["15519.23000000","0.00000000"],["15520.78000000","0.00000000"]]}}
2020-11-09T11:25:21.70123 btcusdt {"stream":"btcusdt@depth@100ms","data":{"e":"depthUpdate","E":1604921121694,"s":"BTCUSDT","U":6511127396,"u":6511127403,"b":[["15514.99000000","1.88193000"]],"a":[["15515.46000000","0.05939000"],["15519.37000000","1.74800000"],["15519.68000000","0.00000000"],["15520.28000000","0.44000000"]]}}
2020-11-09T11:25:21.80153 btcusdt {"stream":"btcusdt@depth@100ms","data":{"e":"depthUpdate","E":1604921121794,"s":"BTCUSDT","U":6511127404,"u":6511127404,"b":[],"a":[["15515.00000000","7.59123600"]]}}
2020-11-09T11:25:21.91149 btcusdt {"stream":"btcusdt@depth@100ms","data":{"e":"depthUpdate","E":1604921121894,"s":"BTCUSDT","U":6511127405,"u":6511127407,"b":[["15497.13000000","0.05000000"]],"a":[["15515.46000000","0.05845800"]]}}
2020-11-09T11:25:22.00846 btcusdt {"stream":"btcusdt@depth@100ms","data":{"e":"depthUpdate","E":1604921121994,"s":"BTCUSDT","U":6511127408,"u":6511127408,"b":[],"a":[["15515.00000000","7.58923600"]]}}
2020-11-09T11:25:22.21010 btcusdt {"stream":"btcusdt@depth@100ms","data":{"e":"depthUpdate","E":1604921122194,"s":"BTCUSDT","U":6511127409,"u":6511127417,"b":[["15508.14000000","0.00000000"],["15506.58000000","0.20000000"],["15399.00000000","0.37683000"]],"a":[["15515.46000000","0.05719100"],["15519.76000000","0.06142300"],["15521.64000000","0.00000000"]]}}
2020-11-09T11:25:22.38906 btcusdt {"stream":"btcusdt@depth@100ms","data":{"e":"depthUpdate","E":1604921122295,"s":"BTCUSDT","U":6511127418,"u":6511127424,"b":[["15506.58000000","0.00000000"]],"a":[["15515.00000000","7.59184000"],["15515.46000000","0.05692900"],["15516.12000000","0.00000000"],["15516.45000000","0.08000000"]]}}
2020-11-09T11:25:22.40350 btcusdt {"stream":"btcusdt@depth@100ms","data":{"e":"depthUpdate","E":1604921122395,"s":"BTCUSDT","U":6511127425,"u":6511127432,"b":[],"a":[["15515.46000000","0.05643800"],["15517.42000000","0.10000000"],["15519.68000000","0.20000000"],["15527.33000000","0.02806500"],["15615.00000000","8.00455500"]]}}
2020-11-09T11:25:22.56884 btcusdt {"stream":"btcusdt@depth@100ms","data":{"e":"depthUpdate","E":1604921122495,"s":"BTCUSDT","U":6511127433,"u":6511127434,"b":[["15507.74000000","0.32100000"]],"a":[["15515.00000000","7.53177500"]]}}
2020-11-09T11:25:22.60168 btcusdt {"stream":"btcusdt@depth@100ms","data":{"e":"depthUpdate","E":1604921122595,"s":"BTCUSDT","U":6511127435,"u":6511127435,"b":[["15420.00000000","1.08412300"]],"a":[]}}
2020-11-09T11:25:22.70170 btcusdt {"stream":"btcusdt@depth@100ms","data":{"e":"depthUpdate","E":1604921122695,"s":"BTCUSDT","U":6511127436,"u":6511127440,"b":[["15514.99000000","1.81087400"],["15511.68000000","0.01679700"],["15511.61000000","0.00000000"]],"a":[["15515.46000000","0.05939200"]]}}
2020-11-09T11:25:22.80129 btcusdt {"stream":"btcusdt@depth@100ms","data":{"e":"depthUpdate","E":1604921122795,"s":"BTCUSDT","U":6511127441,"u":6511127448,"b":[["15508.58000000","0.03626500"],["15508.57000000","0.00000000"],["15506.06000000","0.00000000"]],"a":[["15515.00000000","7.53385800"],["15516.01000000","0.10000000"],["15517.42000000","0.00000000"],["15570.00000000","50.53853300"]]}}
2020-11-09T11:25:22.90180 btcusdt {"stream":"btcusdt@depth@100ms","data":{"e":"depthUpdate","E":1604921122895,"s":"BTCUSDT","U":6511127449,"u":6511127454,"b":[["15473.50000000","0.00000000"]],"a":[["15515.46000000","0.06019700"],["15528.38000000","0.45568200"]]}}
2020-11-09T11:25:23.00218 btcusdt {"stream":"btcusdt@depth@100ms","data":{"e":"depthUpdate","E":1604921122995,"s":"BTCUSDT","U":6511127455,"u":6511127489,"b":[["15514.99000000","0.00000000"],["15514.80000000","0.01780000"],["15511.03000000","0.00000000"],["15510.93000000","0.00000000"],["15510.64000000","0.00000000"],["15510.02000000","0.16429600"],["15509.68000000","0.11427900"],["15508.56000000","0.00000000"],["15507.75000000","0.15680600"],["15506.53000000","0.00000000"]],"a":[["15514.81000000","10.64522200"],["15514.91000000","0.00690000"],["15514.96000000","0.00000000"],["15514.99000000","0.78253600"],["15515.00000000","5.91156000"],["15515.39000000","0.16373500"],["15515.46000000","0.05748200"],["15516.01000000","0.00000000"],["15516.55000000","0.00000000"],["15517.57000000","0.11427900"],["15518.20000000","0.00000000"],["15521.10000000","1.25000000"],["15525.53000000","0.00000000"]]}}
2020-11-09T11:25:23.10282 btcusdt {"stream":"btcusdt@depth@100ms","data":{"e":"depthUpdate","E":1604921123095,"s":"BTCUSDT","U":6511127490,"u":6511127621,"b":[["15514.80000000","0.00000000"],["15514.57000000","0.00000000"],["15514.53000000","0.00000000"],["15514.40000000","0.00000000"],["15513.32000000","0.00000000"],["15513.25000000","0.00000000"],["15513.00000000","0.00000000"],["15512.91000000","5.80690000"],["15512.80000000","0.00000000"],["15512.63000000","0.00000000"],["15512.30000000","0.00000000"],["15512.27000000","0.00000000"],["15512.24000000","2.00000000"],["15511.68000000","0.00000000"],["15511.57000000","0.00000000"],["15511.55000000","0.00000000"],["15511.48000000","0.00128900"],["15511.47000000","0.40802800"],["15511.38000000","0.07687700"],["15510.02000000","0.00000000"],["15509.89000000","0.00000000"],["15509.73000000","0.00000000"],["15508.58000000","0.00000000"],["15508.48000000","1.58300000"],["15508.31000000","1.59300000"],["15508.23000000","0.16429600"],["15507.75000000","0.00000000"],["15507.74000000","0.00000000"],["15507.40000000","0.03626500"],["15506.84000000","0.00000000"],["15506.72000000","0.00000000"],["15503.95000000","0.00000000"],["15503.26000000","0.00000000"],["15494.90000000","0.00000000"]],"a":[["15512.92000000","1.71749700"],["15513.13000000","0.18749000"],["15513.25000000","0.00000000"],["15513.33000000","0.00000000"],["15513.67000000","0.00000000"],["15513.68000000","0.00000000"],["15514.02000000","0.00000000"],["15514.03000000","0.38756000"],["15514.09000000","0.00000000"],["15514.19000000","0.00000000"],["15514.40000000","0.00000000"],["15514.41000000","0.00000000"],["15514.53000000","0.00000000"],["15514.54000000","0.00000000"],["15514.58000000","0.00000000"],["15514.69000000","0.00000000"],["15514.70000000","0.00690000"],["15514.78000000","0.00000000"],["15514.80000000","0.00128800"],["15514.81000000","7.49699400"],["15514.99000000","0.00000000"],["15515.00000000","2.21288500"],["15515.27000000","0.00933800"],["15515.40000000","0.00000000"],["15515.41000000","0.00000000"],["15515.45000000","0.00000000"],["15515.46000000","0.00000000"],["15515.76000000","0.00000000"],["15515.85000000","0.00000000"],["15515.90000000","0.12899000"],["15515.91000000","0.00000000"],["15516.02000000","0.00000000"],["15516.68000000","0.03400000"],["15517.53000000","0.00000000"],["15517.55000000","1.74800000"],["15518.16000000","0.29700000"],["15518.36000000","1.20490000"],["15518.57000000","1.58300000"],["15518.68000000","0.00000000"],["15518.71000000","1.59300000"],["15519.01000000","0.30300000"],["15519.37000000","0.00000000"],["15519.40000000","0.12892400"],["15519.55000000","0.00000000"],["15520.23000000","0.00000000"],["15520.24000000","0.00000000"],["15521.73000000","0.00000000"],["15526.07000000","0.00000000"],["15537.66000000","0.00000000"]]}}
2020-11-09T11:25:23.20224 btcusdt {"stream":"btcusdt@depth@100ms","data":{"e":"depthUpdate","E":1604921123195,"s":"BTCUSDT","U":6511127622,"u":6511127682,"b":[["15512.91000000","2.73053300"],["15512.24000000","2.07365300"],["15510.00000000","0.00857200"],["15509.90000000","0.00000000"],["15508.55000000","0.00000000"],["15508.23000000","0.00000000"],["15508.22000000","0.11731400"],["15507.59000000","0.03223300"],["15507.40000000","0.00000000"],["15506.84000000","0.00000000"],["15506.73000000","0.00000000"],["15505.99000000","0.00000000"],["15505.71000000","0.03626500"],["15505.66000000","0.30000000"],["15504.68000000","0.12893300"],["15504.19000000","0.50000000"],["15501.08000000","1.00843600"],["15494.13000000","0.00300000"],["15485.11000000","0.28500000"],["15470.00000000","2.03232000"]],"a":[["15512.92000000","1.34906600"],["15513.12000000","0.16373500"],["15513.13000000","0.00000000"],["15514.03000000","0.00000000"],["15514.69000000","1.97905100"],["15514.80000000","0.78382400"],["15514.99000000","0.16000000"],["15515.00000000","2.13288500"],["15515.39000000","0.00000000"],["15516.68000000","0.00000000"],["15517.36000000","0.03400000"],["15517.99000000","0.06000000"],["15519.33000000","0.01000000"],["15519.36000000","0.25760500"],["15519.69000000","0.00000000"],["15519.73000000","0.01500000"],["15519.82000000","0.00000000"],["15521.49000000","0.00000000"],["15521.89000000","0.00000000"],["15522.86000000","1.00843600"],["15528.39000000","0.00690000"],["15534.76000000","0.00000000"]]}}
