2020-11-09T11:24:01.25664 btcusdt {"stream":"btcusdt@depth@100ms","data":{"e":"depthUpdate","E":1604921041249,"s":"BTCUSDT","U":6511117710,"u":6511117723,"a":[["15521.75000000","0.00000000"],["15522.41000000","0.00000000"],["15524.56000000","0.00000000"],["15524.86000000","1.00000000"],["17835.41000000","0.00000000"]],"b":[["15516.38000000","0.00000000"],["15515.32000000","0.00000000"],["15515.28000000","0.01303500"],["15513.42000000","0.20000000"],["15510.49000000","0.00000000"],["15503.64000000","1.00000000"],["15502.17000000","1.50000000"],["15498.25000000","0.00120000"],["15496.99000000","0.00000000"]]}}
2020-11-09T11:24:00.75639 btcusdt {"stream":"btcusdt@depth@100ms","data":{"e":"depthUpdate","E":1604921040749,"s":"BTCUSDT","U":6511117518,"u":6511117589,"b":[["15516.37000000","5.97061300"],["15516.12000000","0.01571900"],["15516.11000000","0.06686400"],["15516.08000000","1.00000000"],["15515.78000000","0.01869700"],["15515.76000000","0.01710800"],["15515.75000000","0.01667900"],["15515.54000000","0.01534700"],["15515.53000000","0.01487500"],["15515.52000000","0.00000000"],["15515.51000000","0.00000000"],["15515.36000000","0.00000000"],["15515.31000000","0.06297200"],["15515.30000000","2.49663900"],["15515.28000000","2.19203500"],["15515.06000000","0.00000000"],["15514.82000000","0.00000000"],["15514.73000000","0.00000000"],["15514.71000000","0.00000000"],["15512.46000000","0.10000000"],["15511.14000000","1.19900000"],["15510.99000000","0.00000000"],["15510.51000000","0.00000000"],["15506.74000000","0.00000000"],["15479.01000000","0.08297000"]],"a":[["15515.31000000","0.00000000"],["15515.52000000","0.00000000"],["15515.71000000","0.00000000"],["15516.38000000","0.00690000"],["15516.39000000","0.00000000"],["15516.69000000","0.00000000"],["15516.74000000","0.00000000"],["15516.79000000","0.00000000"],["15517.29000000","0.00000000"],["15517.44000000","0.00128800"],["15517.45000000","0.00000000"],["15517.86000000","0.00000000"],["15518.78000000","0.00000000"],["15519.66000000","0.00000000"],["15519.70000000","0.00000000"],["15519.82000000","0.20000000"],["15519.96000000","0.00000000"],["15520.01000000","0.00000000"],["15520.22000000","0.00000000"],["15520.29000000","0.00000000"],["15520.30000000","0.00000000"],["15520.92000000","1.61700000"],["15521.17000000","1.58300000"],["15521.30000000","1.74800000"],["15522.17000000","0.00000000"],["15524.95000000","0.00000000"],["15525.13000000","0.00000000"],["15526.12000000","0.00000000"],["15527.93000000","0.13426800"],["15528.26000000","0.25756200"],["15531.90000000","0.00000000"]]}}
2020-11-09T11:24:00.85892 btcusdt {"stream":"btcusdt@depth@100ms","data":{"e":"depthUpdate","E":1604921040849,"s":"BTCUSDT","U":6511117590,"u":6511117628,"b":[["15516.37000000","9.32860300"],["15516.11000000","0.00000000"],["15516.08000000","0.00000000"],["15515.54000000","0.00000000"],["15515.53000000","0.00000000"],["15515.31000000","0.03397200"],["15515.30000000","2.30674600"],["15511.77000000","0.05000000"],["15510.72000000","0.00000000"],["15506.20000000","0.50415600"],["15504.82000000","0.00000000"],["15437.70000000","0.00000000"]],"a":[["15518.60000000","0.00000000"],["15519.82000000","0.00000000"],["15519.83000000","0.00000000"],["15520.18000000","0.00000000"],["15520.53000000","0.01700000"],["15520.79000000","0.05000000"],["15520.88000000","0.01700000"],["15521.00000000","1.01096800"],["15521.42000000","0.20000000"],["15521.75000000","0.10000000"],["15521.94000000","0.00000000"],["15521.98000000","0.00000000"],["15522.33000000","0.12890200"],["15522.38000000","0.00000000"],["15522.65000000","0.00000000"],["15522.80000000","0.01000000"],["15523.20000000","0.01500000"],["15523.34000000","0.00000000"],["15525.05000000","0.00690000"],["15525.52000000","0.00000000"],["15527.97000000","1.00831300"],["15534.14000000","1.06748100"],["17835.41000000","0.00500000"]]}}
2020-11-09T11:24:01.05809 btcusdt {"stream":"btcusdt@depth@100ms","data":{"e":"depthUpdate","E":1604921041049,"s":"BTCUSDT","U":6511117650,"u":6511117684,"b":[["15516.86000000","0.88448700"],["15516.62000000","0.00690000"],["15516.51000000","0.00000000"],["15516.42000000","0.01490400"],["15516.41000000","0.01281400"],["15516.38000000","0.02900000"],["15516.37000000","2.30583900"],["15515.29000000","0.00198300"],["15513.40000000","0.08000000"],["15500.00000000","14.33045700"],["15479.01000000","0.00000000"],["15436.51000000","0.66967300"]],"a":[["15516.38000000","0.00000000"],["15516.87000000","4.38146800"],["15518.78000000","0.25000100"],["15519.90000000","3.27707400"],["15519.91000000","0.20000000"],["15520.47000000","0.03222400"],["15521.42000000","0.00000000"],["15522.30000000","0.00000000"],["15524.16000000","0.12889500"],["15524.23000000","0.00000000"],["15526.17000000","0.00000000"],["15526.98000000","0.00000000"]]}}
2020-11-09T11:24:01.17584 btcusdt {"stream":"btcusdt@depth@100ms","data":{"e":"depthUpdate","E":1604921041149,"s":"BTCUSDT","U":6511117685,"u":6511117709,"b":[["15516.86000000","3.17375700"],["15516.37000000","2.01556300"],["15515.79000000","0.15500000"],["15515.32000000","0.20000000"],["15515.28000000","0.04203500"],["15513.41000000","0.15680600"],["15512.71000000","0.11427900"],["15512.21000000","0.00000000"],["15511.24000000","0.00200000"]],"a":[["15516.87000000","0.58146800"],["15520.91000000","0.00000000"],["15521.00000000","1.00096800"],["15521.13000000","0.05000000"],["15521.48000000","0.01000000"],["15522.14000000","0.00000000"],["15522.80000000","0.00000000"],["15523.20000000","0.00000000"],["15523.28000000","0.01000000"],["15523.68000000","0.76500000"],["17842.58000000","0.91530000"]]}}
2020-11-09T11:24:01.35551 btcusdt {"stream":"btcusdt@depth@100ms","data":{"e":"depthUpdate","E":1604921041349,"s":"BTCUSDT","U":6511117724,"u":6511117736,"b":[["15516.37000000","2.01641900"],["15514.81000000","0.00609300"],["15514.51000000","0.01898000"],["15513.39000000","0.00000000"],["15510.22000000","0.50000000"],["15439.27000000","0.00647600"]],"a":[["15518.52000000","0.00000000"],["15518.95000000","0.00760200"],["15519.89000000","0.10000000"],["15519.96000000","0.01916300"],["15524.46000000","0.00000000"],["15524.56000000","1.25000000"],["15531.03000000","0.01931600"]]}}
2020-11-09T11:24:01.45580 btcusdt {"stream":"btcusdt@depth@100ms","data":{"e":"depthUpdate","E":1604921041449,"s":"BTCUSDT","U":6511117737,"u":6511117738,"b":[["15515.79000000","0.00000000"],["15294.09000000","0.00000000"]],"a":[]}}
2020-11-09T11:24:01.55704 btcusdt {"stream":"btcusdt@depth@100ms","data":{"e":"depthUpdate","E":1604921041549,"s":"BTCUSDT","U":6511117739,"u":6511117742,"b":[["15287.39000000","0.00100000"]],"a":[["15524.56000000","1.25000000"],["17842.58000000","0.92030000"]]}}
2020-11-09T11:24:01.65884 btcusdt {"stream":"btcusdt@depth@100ms","data":{"e":"depthUpdate","E":1604921041649,"s":"BTCUSDT","U":6511117743,"u":6511117750,"b":[["15514.82000000","0.00619200"],["15514.81000000","0.00000000"],["15510.22000000","0.00000000"],["15498.18000000","0.00000000"]],"a":[["15518.32000000","0.32100000"],["15518.95000000","0.00000000"],["15519.53000000","0.00658900"],["15726.97000000","0.00100000"]]}}
2020-11-09T11:24:01.75592 btcusdt {"stream":"btcusdt@depth@100ms","data":{"e":"depthUpdate","E":1604921041749,"s":"BTCUSDT","U":6511117751,"u":6511117752,"b":[],"a":[["15519.90000000","3.53837400"],["15520.05000000","0.50344200"]]}}
2020-11-09T11:24:01.85805 btcusdt {"stream":"btcusdt@depth@100ms","data":{"e":"depthUpdate","E":1604921041849,"s":"BTCUSDT","U":6511117753,"u":6511117760,"b":[["15516.86000000","3.11252200"],["15499.05000000","0.01900000"]],"a":[["15516.87000000","5.82532100"],["15519.96000000","0.00000000"],["15521.99000000","0.01971700"]]}}
2020-11-09T11:24:01.96097 btcusdt {"stream":"btcusdt@depth@100ms","data":{"e":"depthUpdate","E":1604921041950,"s":"BTCUSDT","U":6511117761,"u":6511117768,"b":[["15514.82000000","0.00000000"],["15512.46000000","0.15000000"],["15511.58000000","0.00000000"],["15449.72000000","0.00000000"]],"a":[["15516.87000000","5.82732100"],["15519.53000000","0.00000000"],["15519.90000000","3.27707400"],["15525.43000000","0.19058300"]]}}
2020-11-09T11:24:02.05743 btcusdt {"stream":"btcusdt@depth@100ms","data":{"e":"depthUpdate","E":1604921042050,"s":"BTCUSDT","U":6511117769,"u":6511117772,"b":[["15300.00000000","35.94317600"],["14741.02000000","0.00000000"]],"a":[["15519.90000000","3.52879400"]]}}
2020-11-09T11:24:02.15954 btcusdt {"stream":"btcusdt@depth@100ms","data":{"e":"depthUpdate","E":1604921042150,"s":"BTCUSDT","U":6511117773,"u":6511117773,"b":[],"a":[["15570.00000000","48.43026000"]]}}
2020-11-09T11:24:02.25996 btcusdt {"stream":"btcusdt@depth@100ms","data":{"e":"depthUpdate","E":1604921042250,"s":"BTCUSDT","U":6511117774,"u":6511117777,"b":[["15502.32000000","0.00000000"],["15399.00000000","0.00000000"]],"a":[["15518.77000000","0.20000000"],["15519.91000000","0.00000000"]]}}
2020-11-09T11:24:02.35755 btcusdt {"stream":"btcusdt@depth@100ms","data":{"e":"depthUpdate","E":1604921042350,"s":"BTCUSDT","U":6511117778,"u":6511117790,"b":[["15516.86000000","0.30405400"],["15516.37000000","0.01641900"],["15512.71000000","0.00000000"],["15512.46000000","0.05000000"],["15512.21000000","0.11427900"],["15511.15000000","0.10000000"],["15503.73000000","0.13417000"]],"a":[["15516.87000000","7.82732100"],["15518.78000000","0.00000000"],["15519.90000000","3.27707400"],["15549.59000000","0.00101200"]]}}
2020-11-09T11:24:02.45660 btcusdt {"stream":"btcusdt@depth@100ms","data":{"e":"depthUpdate","E":1604921042450,"s":"BTCUSDT","U":6511117791,"u":6511117835,"b":[["15516.86000000","0.00000000"],["15516.62000000","0.01150400"],["15516.42000000","0.00000000"],["15516.41000000","0.00000000"],["15516.37000000","0.00170600"],["15516.12000000","0.00000000"],["15516.09000000","0.01742800"],["15515.78000000","0.00000000"],["15515.76000000","0.00000000"],["15515.75000000","0.00000000"],["15515.32000000","0.02900000"],["15514.51000000","0.00000000"],["15513.41000000","0.00000000"],["15507.28000000","0.00000000"],["15502.17000000","0.00000000"],["15499.53000000","1.50000000"],["15496.13000000","0.00000000"],["15423.00000000","0.37683000"]],"a":[["15516.63000000","10.18086800"],["15516.75000000","0.00690000"],["15516.85000000","0.00000000"],["15516.87000000","7.68830300"],["15516.95000000","0.03447200"],["15517.24000000","0.00000000"],["15518.11000000","0.01299500"],["15519.88000000","0.78253600"],["15519.90000000","0.00000000"],["15520.08000000","0.25757100"],["15521.84000000","0.30364300"],["15521.99000000","0.00000000"],["15528.26000000","0.00000000"],["15585.77000000","0.00000000"]]}}
2020-11-09T11:24:02.55762 btcusdt {"stream":"btcusdt@depth@100ms","data":{"e":"depthUpdate","E":1604921042550,"s":"BTCUSDT","U":6511117836,"u":6511117865,"b":[["15516.62000000","0.01030300"],["15516.40000000","0.00705300"],["15513.42000000","0.00000000"],["15512.47000000","0.00000000"],["15512.45000000","0.00000000"],["15511.27000000","0.20000000"],["15511.15000000","0.00000000"],["15509.79000000","0.00000000"],["15508.70000000","0.10000000"],["15507.73000000","0.02106400"],["15507.72000000","0.00000000"],["15507.18000000","0.20000000"],["15505.70000000","0.12890400"],["15339.50000000","0.00000000"]],"a":[["15516.63000000","12.76731400"],["15516.87000000","7.40105400"],["15517.33000000","0.00855300"],["15518.32000000","0.00000000"],["15518.77000000","0.00000000"],["15519.88000000","0.00000000"],["15519.89000000","0.00000000"],["15522.16000000","0.30000000"],["15522.66000000","0.09618800"],["15525.12000000","0.00309000"],["15707.93000000","1.27323700"]]}}
2020-11-09T11:24:02.65671 btcusdt {"stream":"btcusdt@depth@100ms","data":{"e":"depthUpdate","E":1604921042650,"s":"BTCUSDT","U":6511117866,"u":6511117876,"b":[["15512.21000000","0.00000000"],["15508.11000000","1.25000000"],["15507.73000000","0.02106400"],["15507.18000000","0.00000000"],["15503.48000000","0.00000000"],["15501.36000000","1.00830600"],["15446.21000000","0.24000000"]],"a":[["15520.73000000","0.87784200"],["15525.04000000","0.00000000"],["15621.94000000","0.00000000"]]}}
2020-11-09T11:24:02.75691 btcusdt {"stream":"btcusdt@depth@100ms","data":{"e":"depthUpdate","E":1604921042750,"s":"BTCUSDT","U":6511117877,"u":6511117886,"b":[["15515.30000000","2.00000000"],["15510.74000000","0.11427900"],["15506.20000000","0.00000000"],["15503.47000000","0.50416100"],["15500.94000000","0.31604900"]],"a":[["15516.63000000","12.70720400"],["15518.96000000","0.25758800"],["15519.91000000","0.00318600"]]}}
2020-11-09T11:24:02.85734 btcusdt {"stream":"btcusdt@depth@100ms","data":{"e":"depthUpdate","E":1604921042850,"s":"BTCUSDT","U":6511117887,"u":6511117897,"b":[["15508.12000000","0.20000000"],["15507.73000000","0.00000000"],["15477.23000000","0.00000000"],["15439.27000000","0.00000000"],["15283.67000000","0.00000000"]],"a":[["15516.63000000","12.70640100"],["15518.10000000","0.12893300"],["15525.41000000","1.00834000"],["15527.97000000","0.00000000"],["15533.35000000","0.05853300"],["15615.00000000","8.09829400"]]}}
2020-11-09T11:24:02.95701 btcusdt {"stream":"btcusdt@depth@100ms","data":{"e":"depthUpdate","E":1604921042950,"s":"BTCUSDT","U":6511117898,"u":6511117907,"b":[["15515.31000000","0.00128800"],["15512.46000000","0.00000000"],["15511.28000000","0.05000000"],["15507.27000000","0.00000000"],["15441.06000000","0.00000000"]],"a":[["15518.03000000","0.32100000"],["15521.12000000","0.10139200"],["15529.99000000","0.48374700"],["15707.93000000","0.00000000"]]}}
2020-11-09T11:24:03.05919 btcusdt {"stream":"btcusdt@depth@100ms","data":{"e":"depthUpdate","E":1604921043050,"s":"BTCUSDT","U":6511117908,"u":6511117935,"b":[["15516.62000000","0.00000000"],["15511.27000000","0.00000000"],["15499.53000000","0.00000000"],["15404.88000000","0.00000000"]],"a":[["15516.41000000","5.24282300"],["15516.60000000","0.02456300"],["15516.62000000","3.43878800"],["15516.63000000","7.91599600"],["15516.86000000","0.03447200"],["15516.87000000","2.02732100"],["15516.90000000","0.25758800"],["15516.95000000","0.00000000"],["15518.79000000","0.00000000"],["15524.59000000","0.00000000"],["15526.98000000","0.00957500"]]}}
2020-11-09T11:24:03.15771 btcusdt {"stream":"btcusdt@depth@100ms","data":{"e":"depthUpdate","E":1604921043150,"s":"BTCUSDT","U":6511117936,"u":6511117994,"b":[["15516.40000000","0.00000000"],["15516.37000000","0.00000000"],["15516.09000000","0.00690000"],["15515.63000000","0.01220000"],["15515.32000000","0.00000000"],["15511.28000000","0.00000000"],["15511.27000000","0.05000000"],["15510.61000000","0.00000000"],["15508.71000000","0.20000000"],["15507.27000000","0.02106400"],["15503.64000000","0.00000000"],["15499.04000000","1.00000000"],["14700.00000000","59.53424500"]],"a":[["15516.10000000","9.86299100"],["15516.26000000","0.00690000"],["15516.34000000","0.04081300"],["15516.35000000","0.03873800"],["15516.37000000","0.04121600"],["15516.38000000","0.00000000"],["15516.40000000","0.78253600"],["15516.41000000","7.60557300"],["15516.60000000","0.00000000"],["15516.62000000","0.00625200"],["15516.63000000","2.32874700"],["15516.69000000","0.03447200"],["15516.84000000","0.00000000"],["15516.86000000","0.00000000"],["15518.03000000","0.00000000"],["15519.91000000","0.20318600"],["15520.67000000","0.05690000"],["15521.02000000","0.01000000"],["15521.13000000","0.00000000"],["15521.48000000","0.00000000"],["15522.82000000","0.01000000"],["15523.22000000","0.01500000"],["15523.28000000","0.00000000"],["15523.68000000","0.75000000"],["15573.00000000","0.17227700"]]}}
2020-11-09T11:24:03.25697 btcusdt {"stream":"btcusdt@depth@100ms","data":{"e":"depthUpdate","E":1604921043250,"s":"BTCUSDT","U":6511117995,"u":6511118007,"b":[["15515.94000000","0.00915100"],["15513.82000000","0.03094000"],["15368.71000000","0.00000000"]],"a":[["15516.10000000","12.14465900"],["15516.41000000","7.32390500"],["15516.67000000","0.03447200"],["15516.69000000","0.00000000"],["15516.87000000","0.02732100"],["15516.90000000","0.00000000"],["15517.15000000","0.00785700"],["15517.33000000","0.00000000"],["15525.02000000","0.25758800"]]}}
2020-11-09T11:24:03.35668 btcusdt {"stream":"btcusdt@depth@100ms","data":{"e":"depthUpdate","E":1604921043350,"s":"BTCUSDT","U":6511118008,"u":6511118013,"b":[["15508.71000000","0.00000000"],["15476.54000000","0.00000000"],["15438.50000000","0.00647700"]],"a":[["15516.10000000","12.14381300"],["15516.40000000","0.00000000"],["15554.11000000","0.00000000"]]}}
2020-11-09T11:24:03.45668 btcusdt {"stream":"btcusdt@depth@100ms","data":{"e":"depthUpdate","E":1604921043450,"s":"BTCUSDT","U":6511118014,"u":6511118020,"b":[["15515.63000000","0.01758700"],["15508.71000000","0.50000000"],["15332.54000000","0.00000000"]],"a":[["15517.92000000","0.01370400"],["15518.11000000","0.00000000"],["15521.12000000","0.00000000"]]}}
2020-11-09T11:24:03.55683 btcusdt {"stream":"btcusdt@depth@100ms","data":{"e":"depthUpdate","E":1604921043550,"s":"BTCUSDT","U":6511118021,"u":6511118030,"b":[["15516.09000000","0.00586700"],["15508.71000000","0.70000000"],["15296.36000000","0.00000000"]],"a":[["15516.10000000","12.04914600"],["15517.10000000","0.00843800"],["15517.15000000","0.00000000"],["15524.55000000","1.25000000"],["15524.56000000","0.00000000"],["15540.00000000","2.22317500"]]}}
2020-11-09T11:24:03.65746 btcusdt {"stream":"btcusdt@depth@100ms","data":{"e":"depthUpdate","E":1604921043650,"s":"BTCUSDT","U":6511118031,"u":6511118036,"b":[["15460.00000000","0.46656700"],["15260.19000000","0.00000000"]],"a":[["15517.50000000","0.32100000"],["15518.15000000","0.25758800"],["15520.92000000","0.00000000"],["15525.02000000","0.00000000"]]}}
2020-11-09T11:24:03.75901 btcusdt {"stream":"btcusdt@depth@100ms","data":{"e":"depthUpdate","E":1604921043750,"s":"BTCUSDT","U":6511118037,"u":6511118056,"b":[["15515.94000000","0.00000000"],["15515.74000000","0.00634400"],["15515.63000000","0.00000000"],["15515.58000000","0.01886000"],["15513.40000000","0.00000000"],["15511.14000000","0.00000000"],["15510.64000000","1.19900000"],["15507.17000000","0.00000000"],["14920.00000000","6.41867600"]],"a":[["15516.10000000","11.96914600"],["15516.56000000","0.00741000"],["15517.03000000","0.01952200"],["15517.10000000","0.00000000"],["15517.61000000","0.08000000"],["15517.92000000","0.00000000"],["15520.42000000","1.61700000"],["15521.28000000","0.00000000"],["15531.97000000","0.00000000"],["15707.93000000","1.27323700"]]}}
2020-11-09T11:24:03.86140 btcusdt {"stream":"btcusdt@depth@100ms","data":{"e":"depthUpdate","E":1604921043851,"s":"BTCUSDT","U":6511118057,"u":6511118063,"b":[["15508.72000000","0.15680600"]],"a":[["15516.87000000","0.02332100"],["15520.00000000","6.28264300"],["15524.55000000","0.00000000"],["15615.00000000","8.47512400"],["15622.08000000","2.00000000"]]}}
2020-11-09T11:24:03.95684 btcusdt {"stream":"btcusdt@depth@100ms","data":{"e":"depthUpdate","E":1604921043951,"s":"BTCUSDT","U":6511118064,"u":6511118069,"b":[["15511.27000000","0.00000000"],["15510.99000000","0.05000000"],["15499.05000000","0.00000000"]],"a":[["15516.87000000","0.02132100"],["15524.33000000","0.14700000"],["15524.53000000","1.25000000"]]}}
2020-11-09T11:24:04.05852 btcusdt {"stream":"btcusdt@depth@100ms","data":{"e":"depthUpdate","E":1604921044051,"s":"BTCUSDT","U":6511118070,"u":6511118079,"b":[["15515.74000000","0.00000000"],["15515.58000000","0.00000000"],["15515.47000000","0.01379900"],["15515.46000000","0.00806000"],["15442.53000000","0.00706100"],["15241.07000000","0.00000000"]],"a":[["15524.53000000","0.00000000"],["15585.92000000","2.00963200"]]}}
2020-11-09T11:24:04.19197 btcusdt {"stream":"btcusdt@depth@100ms","data":{"e":"depthUpdate","E":1604921044151,"s":"BTCUSDT","U":6511118080,"u":6511118087,"b":[["15508.72000000","0.00000000"],["15498.29000000","0.01900000"],["15477.30000000","0.25202600"]],"a":[["15524.53000000","1.25000000"],["15548.26000000","1.76187500"],["15549.76000000","2.00000000"],["15554.89000000","0.25100000"],["15707.93000000","0.00000000"]]}}
2020-11-09T11:24:04.25814 btcusdt {"stream":"btcusdt@depth@100ms","data":{"e":"depthUpdate","E":1604921044251,"s":"BTCUSDT","U":6511118088,"u":6511118100,"b":[["15511.00000000","0.20000000"],["15508.72000000","0.15680600"],["15508.71000000","0.50000000"],["15386.67000000","0.01309400"]],"a":[["15516.10000000","10.15902600"],["15519.21000000","0.01700000"],["15519.84000000","0.01700000"],["15519.89000000","1.74800000"],["15520.53000000","0.00000000"],["15520.88000000","0.00000000"],["15521.30000000","0.00000000"]]}}
2020-11-09T11:24:04.35751 btcusdt {"stream":"btcusdt@depth@100ms","data":{"e":"depthUpdate","E":1604921044351,"s":"BTCUSDT","U":6511118101,"u":6511118136,"b":[["15516.09000000","0.00000000"],["15515.47000000","0.00000000"],["15515.46000000","0.00000000"],["15515.31000000","0.00000000"],["15515.30000000","1.99976300"],["15514.79000000","0.00000000"],["15511.08000000","0.27724200"],["15508.72000000","0.00000000"],["15260.47000000","2.00000000"],["15205.77000000","0.00174700"]],"a":[["15515.31000000","5.95593300"],["15515.32000000","0.00000000"],["15515.47000000","0.00000000"],["15515.48000000","0.11288500"],["15515.71000000","0.00690000"],["15516.02000000","0.12578000"],["15516.09000000","0.10458600"],["15516.10000000","7.62542200"],["15516.41000000","2.02390500"],["15519.91000000","0.20000000"]]}}
2020-11-09T11:24:04.45849 btcusdt {"stream":"btcusdt@depth@100ms","data":{"e":"depthUpdate","E":1604921044451,"s":"BTCUSDT","U":6511118137,"u":6511118190,"b":[["15515.30000000","8.48181300"],["15511.21000000","0.11427900"],["15511.08000000","0.00000000"],["15511.00000000","0.00000000"],["15510.99000000","0.00000000"],["15510.75000000","0.05000000"],["15510.74000000","0.00000000"],["15508.72000000","0.20000000"],["15505.70000000","0.00000000"],["15504.76000000","0.12890400"],["15502.04000000","0.32896800"],["15497.69000000","0.10000000"],["15296.63000000","2.00000000"]],"a":[["15515.31000000","4.00578500"],["15515.32000000","0.11336800"],["15515.47000000","0.00000000"],["15515.48000000","0.00000000"],["15516.02000000","0.00000000"],["15516.09000000","0.78253600"],["15516.10000000","7.34375400"],["15516.34000000","0.00000000"],["15516.35000000","0.00000000"],["15516.37000000","0.00000000"],["15516.41000000","2.00000000"],["15516.63000000","2.02874700"],["15516.87000000","0.03433400"],["15517.03000000","0.00000000"],["15517.22000000","0.25759800"],["15518.09000000","0.20000000"],["15518.58000000","0.10000000"],["15519.57000000","0.05000000"],["15519.91000000","0.00000000"],["15519.92000000","0.09000000"],["15520.67000000","0.00690000"],["15521.02000000","0.00000000"],["15521.72000000","0.01000000"],["15522.12000000","0.01500000"],["15522.82000000","0.00000000"],["15522.99000000","0.00000000"],["15523.22000000","0.00000000"]]}}
2020-11-09T11:24:04.55863 btcusdt {"stream":"btcusdt@depth@100ms","data":{"e":"depthUpdate","E":1604921044551,"s":"BTCUSDT","U":6511118191,"u":6511118200,"b":[["15515.30000000","8.75053200"],["15508.72000000","0.35680600"]],"a":[["15515.31000000","0.21378700"],["15515.32000000","0.00000000"],["15516.09000000","0.00000000"],["15516.10000000","7.30000000"],["15517.22000000","0.00000000"],["15518.10000000","0.00000000"]]}}
2020-11-09T11:24:04.66036 btcusdt {"stream":"btcusdt@depth@100ms","data":{"e":"depthUpdate","E":1604921044651,"s":"BTCUSDT","U":6511118201,"u":6511118212,"b":[["15510.99000000","0.10000000"],["15508.70000000","0.00000000"],["15507.75000000","0.12890400"],["15504.76000000","0.00000000"],["15423.00000000","0.00000000"],["15332.79000000","2.00000000"],["15093.39000000","0.00000000"]],"a":[["15516.10000000","5.30000000"],["15516.41000000","0.00000000"],["15516.63000000","0.02874700"],["15524.37000000","0.25758600"],["15531.45000000","0.24000000"]]}}
2020-11-09T11:24:04.75829 btcusdt {"stream":"btcusdt@depth@100ms","data":{"e":"depthUpdate","E":1604921044751,"s":"BTCUSDT","U":6511118213,"u":6511118218,"b":[["15507.08000000","0.19117700"],["15503.47000000","0.00000000"],["15502.54000000","1.00836900"],["15501.36000000","0.00000000"],["15368.95000000","2.00000000"]],"a":[["15554.51000000","0.01077900"]]}}
2020-11-09T11:24:04.85903 btcusdt {"stream":"btcusdt@depth@100ms","data":{"e":"depthUpdate","E":1604921044851,"s":"BTCUSDT","U":6511118219,"u":6511118223,"b":[["15510.76000000","0.10943800"],["15504.43000000","0.50418400"],["15438.50000000","0.00000000"],["15405.11000000","2.00000000"]],"a":[["15521.28000000","0.20000000"]]}}
2020-11-09T11:24:04.95769 btcusdt {"stream":"btcusdt@depth@100ms","data":{"e":"depthUpdate","E":1604921044951,"s":"BTCUSDT","U":6511118224,"u":6511118230,"b":[["15512.76000000","0.50000000"],["15511.91000000","0.02106400"],["15510.77000000","0.05000000"],["15510.75000000","0.00000000"],["15507.27000000","0.00000000"]],"a":[["15518.65000000","0.50000000"],["15707.93000000","1.27323700"]]}}
2020-11-09T11:24:05.05732 btcusdt {"stream":"btcusdt@depth@100ms","data":{"e":"depthUpdate","E":1604921045051,"s":"BTCUSDT","U":6511118231,"u":6511118232,"b":[["15508.72000000","0.20000000"],["15441.27000000","2.00000000"]],"a":[]}}
2020-11-09T11:24:05.15980 btcusdt {"stream":"btcusdt@depth@100ms","data":{"e":"depthUpdate","E":1604921045151,"s":"BTCUSDT","U":6511118233,"u":6511118240,"b":[["15515.30000000","8.74770400"],["15514.84000000","0.00994300"],["15508.72000000","0.35680600"],["15472.50000000","0.00000000"]],"a":[["15515.31000000","0.21096700"],["15515.95000000","0.00757000"],["15516.56000000","0.00000000"],["15526.98000000","0.00000000"]]}}
2020-11-09T11:24:05.25922 btcusdt {"stream":"btcusdt@depth@100ms","data":{"e":"depthUpdate","E":1604921045251,"s":"BTCUSDT","U":6511118241,"u":6511118247,"b":[["15515.30000000","8.74232600"],["15514.54000000","0.06686400"],["15511.71000000","0.11493100"],["15511.21000000","0.00000000"],["15508.72000000","0.15680600"],["15477.43000000","2.00000000"]],"a":[["15515.31000000","0.15079400"]]}}
2020-11-09T11:24:05.35819 btcusdt {"stream":"btcusdt@depth@100ms","data":{"e":"depthUpdate","E":1604921045351,"s":"BTCUSDT","U":6511118248,"u":6511118252,"b":[["15511.92000000","0.20000000"],["15511.26000000","0.00000000"],["15437.72000000","0.00647700"]],"a":[["15615.00000000","8.09829400"],["15707.93000000","0.00000000"]]}}
2020-11-09T11:24:05.45827 btcusdt {"stream":"btcusdt@depth@100ms","data":{"e":"depthUpdate","E":1604921045451,"s":"BTCUSDT","U":6511118253,"u":6511118258,"b":[["15514.53000000","0.01723500"],["15471.50000000","2.00000000"],["15205.00000000","1.20443100"]],"a":[["15516.08000000","0.01748500"],["15516.87000000","0.02132100"],["15587.98000000","0.00190700"]]}}
2020-11-09T11:24:05.55888 btcusdt {"stream":"btcusdt@depth@100ms","data":{"e":"depthUpdate","E":1604921045552,"s":"BTCUSDT","U":6511118259,"u":6511118272,"b":[["15515.30000000","3.34432600"],["15510.76000000","0.00000000"],["15508.69000000","0.00000000"],["15508.12000000","0.00000000"],["15497.44000000","1.50000000"],["15399.00000000","0.37683000"],["15241.97000000","0.00590400"]],"a":[["15515.31000000","0.27779400"],["15515.77000000","0.00905900"],["15515.95000000","0.00000000"],["15516.87000000","0.00690000"],["15531.45000000","0.00000000"]]}}
2020-11-09T11:24:05.65911 btcusdt {"stream":"btcusdt@depth@100ms","data":{"e":"depthUpdate","E":1604921045652,"s":"BTCUSDT","U":6511118273,"u":6511118286,"b":[["15511.71000000","0.00065200"],["15511.23000000","0.11427900"],["15510.99000000","0.00000000"],["15510.64000000","0.00000000"],["15510.22000000","0.00000000"],["15510.17000000","1.19900000"],["15509.58000000","0.10000000"],["15508.72000000","0.00000000"],["15507.75000000","0.00000000"],["15505.38000000","0.12890400"],["15504.43000000","0.00000000"]],"a":[["15519.90000000","1.61700000"],["15520.42000000","0.00000000"]]}}
2020-11-09T11:24:05.75900 btcusdt {"stream":"btcusdt@depth@100ms","data":{"e":"depthUpdate","E":1604921045752,"s":"BTCUSDT","U":6511118287,"u":6511118305,"b":[["15511.91000000","0.00000000"],["15507.71000000","0.22500000"],["15507.09000000","0.02106400"],["15501.91000000","0.50418400"]],"a":[["15515.31000000","0.27693900"],["15517.49000000","0.10000000"],["15518.58000000","0.00000000"],["15519.10000000","0.88000000"],["15519.67000000","0.88000000"],["15519.72000000","0.10000000"],["15519.80000000","0.88000000"],["15520.66000000","0.00000000"],["15521.18000000","0.30000000"],["15521.29000000","0.00000000"],["15521.43000000","0.00000000"],["15523.01000000","0.00000000"],["15523.86000000","0.00000000"],["15530.78000000","0.24000000"],["15573.00000000","0.54910700"]]}}
2020-11-09T11:24:05.85991 btcusdt {"stream":"btcusdt@depth@100ms","data":{"e":"depthUpdate","E":1604921045852,"s":"BTCUSDT","U":6511118306,"u":6511118309,"b":[["15507.09000000","0.00000000"]],"a":[["15515.31000000","5.57693900"],["15516.07000000","0.20000000"],["15518.09000000","0.00000000"]]}}
2020-11-09T11:24:05.95900 btcusdt {"stream":"btcusdt@depth@100ms","data":{"e":"depthUpdate","E":1604921045952,"s":"BTCUSDT","U":6511118310,"u":6511118327,"b":[["15515.30000000","0.00890000"],["15514.54000000","0.00000000"],["15511.23000000","0.00000000"],["15510.99000000","0.05000000"],["15510.77000000","0.00000000"],["15510.61000000","0.83995000"],["15505.38000000","0.00000000"],["15504.10000000","0.12890400"]],"a":[["15515.31000000","7.83726400"],["15515.35000000","0.03447200"],["15516.67000000","0.00000000"],["15519.72000000","0.00000000"],["15522.27000000","0.10000000"],["15522.33000000","0.00000000"]]}}
2020-11-09T11:24:06.06055 btcusdt {"stream":"btcusdt@depth@100ms","data":{"e":"depthUpdate","E":1604921046052,"s":"BTCUSDT","U":6511118328,"u":6511118342,"b":[["15509.65000000","0.11427900"],["15508.72000000","0.15680600"],["15508.11000000","0.00000000"],["15506.86000000","0.02106400"],["15506.73000000","0.00000000"],["15504.79000000","0.00000000"],["15504.18000000","1.25000000"],["15446.21000000","0.00000000"]],"a":[["15516.06000000","0.88253600"],["15517.49000000","0.00000000"],["15522.05000000","1.25000000"],["15524.53000000","0.00000000"],["15527.12000000","0.00000000"]]}}
2020-11-09T11:24:06.16147 btcusdt {"stream":"btcusdt@depth@100ms","data":{"e":"depthUpdate","E":1604921046152,"s":"BTCUSDT","U":6511118343,"u":6511118357,"b":[["15513.82000000","0.00690000"],["15511.80000000","0.02492400"],["15511.25000000","0.16000000"],["15511.07000000","0.02492400"],["15508.72000000","0.00000000"],["15506.86000000","0.00000000"],["15504.18000000","0.00000000"],["15504.07000000","1.25000000"]],"a":[["15515.31000000","7.77672800"],["15516.05000000","0.78253600"],["15516.06000000","0.10000000"],["15520.05000000","1.75344200"],["15522.05000000","0.00000000"],["15522.99000000","0.03353500"],["15707.93000000","1.27323700"]]}}
2020-11-09T11:24:06.25795 btcusdt {"stream":"btcusdt@depth@100ms","data":{"e":"depthUpdate","E":1604921046252,"s":"BTCUSDT","U":6511118358,"u":6511118375,"b":[["15511.60000000","0.00000000"],["15511.07000000","0.00690000"],["15511.02000000","0.03222700"],["15510.94000000","0.00000000"],["15504.14000000","1.25000000"],["15504.07000000","0.00000000"],["15502.55000000","0.50418500"],["15497.44000000","0.00000000"]],"a":[["15515.31000000","7.80854000"],["15515.35000000","0.00000000"],["15516.07000000","0.33500000"],["15516.69000000","0.25761100"],["15520.47000000","0.00000000"],["15524.16000000","0.00000000"],["15524.37000000","0.00000000"],["15530.78000000","0.00000000"],["15541.43000000","1.20049600"]]}}
2020-11-09T11:24:06.36002 btcusdt {"stream":"btcusdt@depth@100ms","data":{"e":"depthUpdate","E":1604921046352,"s":"BTCUSDT","U":6511118376,"u":6511118385,"b":[["15515.30000000","0.00602700"],["15506.86000000","0.02106400"],["15505.62000000","0.00000000"],["15503.17000000","0.10000000"],["15503.04000000","0.00000000"],["15500.18000000","0.56712800"]],"a":[["15518.89000000","0.03222700"],["15522.29000000","1.00000000"],["15522.57000000","0.12890800"],["15524.86000000","0.00000000"]]}}
2020-11-09T11:24:06.45909 btcusdt {"stream":"btcusdt@depth@100ms","data":{"e":"depthUpdate","E":1604921046452,"s":"BTCUSDT","U":6511118386,"u":6511118402,"b":[["15515.30000000","0.00000200"],["15511.02000000","0.00000000"],["15507.09000000","0.20000000"],["15506.85000000","0.00000000"],["15504.16000000","0.70063400"],["15504.14000000","0.00000000"],["15504.07000000","1.25000000"],["15503.28000000","0.30016700"],["15502.64000000","0.00000000"],["15474.03000000","0.00000000"],["15420.00000000","0.97585000"]],"a":[["15518.58000000","0.00316000"],["15520.99000000","0.10149100"],["15527.45000000","0.00000000"],["15544.60000000","0.00000000"],["15560.90000000","0.00000000"],["15700.00000000","71.81271600"]]}}
2020-11-09T11:24:06.55936 btcusdt {"stream":"btcusdt@depth@100ms","data":{"e":"depthUpdate","E":1604921046552,"s":"BTCUSDT","U":6511118403,"u":6511118419,"b":[["15511.92000000","0.00000000"],["15510.62000000","0.20000000"],["15509.65000000","0.00000000"],["15509.07000000","0.11427900"],["15507.41000000","0.03222800"],["15506.86000000","0.00000000"],["15504.16000000","0.00000000"],["15504.07000000","0.00000000"],["15503.53000000","0.62500100"],["15503.52000000","1.25000000"]],"a":[["15515.31000000","13.05218700"],["15518.81000000","0.25000000"],["15519.05000000","0.09621400"],["15523.68000000","0.00000000"],["15560.00000000","4.52878300"]]}}
2020-11-09T11:24:06.66255 btcusdt {"stream":"btcusdt@depth@100ms","data":{"e":"depthUpdate","E":1604921046652,"s":"BTCUSDT","U":6511118420,"u":6511118440,"b":[["15509.58000000","0.00000000"],["15507.72000000","0.10000000"],["15506.58000000","0.02106400"],["15506.38000000","0.00000000"],["15506.04000000","0.00000000"],["15505.57000000","0.00000000"],["15499.47000000","0.00000000"],["15494.81000000","0.00000000"],["15441.11000000","0.24000000"]],"a":[["15515.31000000","7.98273000"],["15516.04000000","0.78253600"],["15516.05000000","0.00000000"],["15520.53000000","0.14700000"],["15524.82000000","0.01932400"],["15526.85000000","0.24000000"],["15531.03000000","0.00000000"],["15534.14000000","0.00000000"],["15615.00000000","7.99002100"]]}}
2020-11-09T11:24:06.76216 btcusdt {"stream":"btcusdt@depth@100ms","data":{"e":"depthUpdate","E":1604921046752,"s":"BTCUSDT","U":6511118441,"u":6511118449,"b":[["15484.55000000","0.30900000"]],"a":[["15515.31000000","8.00483000"],["15516.04000000","0.00000000"],["15517.55000000","1.00000000"],["15523.54000000","1.00843600"],["15525.41000000","0.00000000"],["15526.98000000","0.00957500"],["15530.24000000","1.06939900"],["15559.00000000","3.06556200"]]}}
2020-11-09T11:24:06.85841 btcusdt {"stream":"btcusdt@depth@100ms","data":{"e":"depthUpdate","E":1604921046852,"s":"BTCUSDT","U":6511118450,"u":6511118462,"b":[["15510.35000000","0.00000000"],["15508.72000000","0.10000000"],["15507.72000000","0.00000000"],["15507.41000000","0.00000000"],["15496.36000000","1.10346700"],["15399.00000000","0.48510300"]],"a":[["15518.58000000","0.00000000"],["15519.56000000","0.12891500"],["15520.99000000","0.00000000"],["15525.04000000","0.09571800"],["15527.87000000","0.00000000"],["15529.60000000","0.00690000"]]}}
2020-11-09T11:24:06.95951 btcusdt {"stream":"btcusdt@depth@100ms","data":{"e":"depthUpdate","E":1604921046952,"s":"BTCUSDT","U":6511118463,"u":6511118559,"b":[["15515.30000000","0.00000000"],["15515.29000000","0.00000000"],["15515.28000000","0.00000000"],["15515.24000000","0.00000000"],["15515.13000000","0.00000000"],["15515.05000000","0.00000000"],["15514.84000000","0.00000000"],["15514.53000000","0.00000000"],["15514.03000000","0.00690000"],["15513.82000000","0.00000000"],["15513.53000000","2.00000000"],["15512.79000000","0.06686400"],["15512.77000000","0.00128900"],["15512.76000000","0.61329800"],["15510.99000000","0.00000000"],["15510.62000000","0.05000000"],["15510.61000000","0.00000000"],["15510.60000000","0.00000000"],["15510.17000000","0.00000000"],["15510.10000000","0.00000000"],["15509.40000000","1.19900000"],["15509.28000000","1.58300000"],["15509.22000000","1.59300000"],["15509.07000000","0.00000000"],["15508.72000000","0.00000000"],["15508.35000000","0.03222800"],["15508.10000000","0.11427900"],["15507.72000000","0.30000000"],["15507.71000000","0.00000000"],["15503.53000000","0.00000000"],["15503.28000000","0.00000000"],["15502.55000000","0.00000000"],["15502.04000000","0.00000000"],["15496.66000000","0.14850000"]],"a":[["15514.04000000","6.32132600"],["15514.17000000","0.00000000"],["15514.38000000","0.03447200"],["15514.52000000","0.00000000"],["15514.53000000","0.00000000"],["15514.94000000","0.00000000"],["15514.95000000","0.00000000"],["15515.00000000","0.09148400"],["15515.28000000","0.00000000"],["15515.29000000","0.00000000"],["15515.30000000","0.00128800"],["15515.31000000","7.82535800"],["15516.10000000","0.00000000"],["15516.62000000","0.00000000"],["15516.63000000","0.00000000"],["15517.44000000","0.00000000"],["15517.49000000","0.12893300"],["15517.50000000","0.00000000"],["15517.64000000","0.00200000"],["15518.26000000","0.00000000"],["15518.65000000","0.00000000"],["15518.77000000","0.29400000"],["15518.85000000","1.74800000"],["15519.18000000","1.61700000"],["15519.21000000","0.00000000"],["15519.38000000","1.58300000"],["15519.56000000","0.00000000"],["15519.62000000","1.59300000"],["15519.84000000","0.00000000"],["15519.89000000","0.00000000"],["15519.90000000","0.00000000"],["15521.17000000","0.00000000"],["15521.47000000","0.00000000"],["15526.87000000","0.05681600"],["15531.80000000","0.00000000"]]}}
2020-11-09T11:24:07.06312 btcusdt {"stream":"btcusdt@depth@100ms","data":{"e":"depthUpdate","E":1604921047052,"s":"BTCUSDT","U":6511118560,"u":6511118598,"b":[["15514.03000000","4.45690000"],["15513.93000000","0.00948400"],["15513.77000000","0.01868900"],["15512.76000000","0.46329800"],["15510.62000000","0.00000000"],["15509.96000000","0.05000000"],["15506.19000000","0.42853600"],["15504.55000000","0.20000000"],["15503.36000000","0.00000000"],["15500.25000000","0.30000000"]],"a":[["15514.04000000","4.97461800"],["15514.38000000","0.00000000"],["15515.30000000","0.18995500"],["15515.31000000","7.56503300"],["15515.49000000","0.32100000"],["15516.07000000","0.20000000"],["15517.78000000","0.00000000"],["15518.28000000","0.01700000"],["15518.30000000","0.05000000"],["15518.65000000","0.01000000"],["15518.90000000","0.01700000"],["15519.57000000","0.00000000"],["15519.92000000","0.08000000"],["15520.45000000","0.01000000"],["15520.85000000","0.01500000"],["15521.28000000","0.00000000"],["15521.72000000","0.00000000"],["15522.12000000","0.00000000"],["15524.47000000","0.00000000"],["15525.31000000","0.06710000"],["15570.00000000","48.53853300"],["15707.93000000","0.00000000"]]}}
2020-11-09T11:24:07.19466 btcusdt {"stream":"btcusdt@depth@100ms","data":{"e":"depthUpdate","E":1604921047152,"s":"BTCUSDT","U":6511118599,"u":6511118614,"b":[["15514.03000000","5.95690000"],["15512.76000000","0.46625000"],["15506.19000000","0.00000000"],["15497.22000000","1.50000000"]],"a":[["15514.04000000","2.97924900"],["15514.77000000","0.03447200"],["15515.29000000","0.20000000"],["15515.30000000","2.37222100"],["15515.50000000","0.00200000"],["15516.07000000","0.00000000"],["15521.22000000","0.50000000"],["15522.52000000","1.50000000"]]}}
2020-11-09T11:24:07.25959 btcusdt {"stream":"btcusdt@depth@100ms","data":{"e":"depthUpdate","E":1604921047252,"s":"BTCUSDT","U":6511118615,"u":6511118620,"b":[["15514.03000000","2.00690000"],["15513.77000000","0.00000000"],["15513.67000000","0.01806500"]],"a":[["15514.04000000","2.97368700"],["15515.29000000","0.00000000"],["15540.00000000","2.18816500"]]}}
2020-11-09T11:24:07.36190 btcusdt {"stream":"btcusdt@depth@100ms","data":{"e":"depthUpdate","E":1604921047353,"s":"BTCUSDT","U":6511118621,"u":6511118627,"b":[["15513.93000000","0.00000000"],["15513.62000000","0.00734700"],["15508.93000000","0.11427900"],["15508.10000000","0.00000000"],["15437.72000000","0.00000000"],["15205.77000000","0.00000000"]],"a":[["15514.04000000","2.96728700"]]}}
2020-11-09T11:24:07.45945 btcusdt {"stream":"btcusdt@depth@100ms","data":{"e":"depthUpdate","E":1604921047453,"s":"BTCUSDT","U":6511118628,"u":6511118634,"b":[["15514.03000000","6.60617700"],["15510.00000000","0.55755000"]],"a":[["15514.04000000","2.97324100"],["15516.06000000","0.00000000"],["15516.68000000","0.20000000"],["15517.48000000","0.10000000"]]}}
2020-11-09T11:24:07.55939 btcusdt {"stream":"btcusdt@depth@100ms","data":{"e":"depthUpdate","E":1604921047553,"s":"BTCUSDT","U":6511118635,"u":6511118637,"b":[["15514.03000000","2.00617700"]],"a":[["15514.04000000","2.97004100"],["15519.72000000","0.10000000"]]}}
2020-11-09T11:24:07.66919 btcusdt {"stream":"btcusdt@depth@100ms","data":{"e":"depthUpdate","E":1604921047653,"s":"BTCUSDT","U":6511118638,"u":6511118642,"b":[["15514.03000000","0.00617700"]],"a":[["15514.04000000","4.98044600"],["15515.30000000","0.18995500"]]}}
2020-11-09T11:24:07.75912 btcusdt {"stream":"btcusdt@depth@100ms","data":{"e":"depthUpdate","E":1604921047753,"s":"BTCUSDT","U":6511118643,"u":6511118655,"b":[["15514.03000000","0.00542900"],["15510.01000000","0.20000000"],["15508.93000000","0.00000000"],["15507.72000000","0.10000000"]],"a":[["15514.04000000","4.97724600"],["15515.29000000","0.20000000"],["15515.30000000","0.00128800"],["15516.68000000","0.00000000"],["15517.47000000","0.10000000"],["15517.48000000","0.00000000"],["15570.00000000","48.43026000"]]}}
2020-11-09T11:24:07.85892 btcusdt {"stream":"btcusdt@depth@100ms","data":{"e":"depthUpdate","E":1604921047853,"s":"BTCUSDT","U":6511118656,"u":6511118663,"b":[["15513.67000000","0.00000000"],["15513.31000000","0.01981500"],["15508.48000000","0.11427900"],["15473.48000000","0.00000000"],["15436.45000000","0.00647800"]],"a":[["15514.04000000","4.91699700"],["15516.86000000","0.00122500"],["15518.76000000","0.20000000"]]}}
2020-11-09T11:24:07.96150 btcusdt {"stream":"btcusdt@depth@100ms","data":{"e":"depthUpdate","E":1604921047953,"s":"BTCUSDT","U":6511118664,"u":6511118669,"b":[["15513.62000000","0.00000000"],["15510.01000000","0.25000000"],["15509.96000000","0.00000000"]],"a":[["15514.75000000","0.03447200"],["15514.77000000","0.00000000"],["15515.77000000","0.00000000"]]}}
2020-11-09T11:24:08.05992 btcusdt {"stream":"btcusdt@depth@100ms","data":{"e":"depthUpdate","E":1604921048053,"s":"BTCUSDT","U":6511118670,"u":6511118670,"b":[],"a":[["15514.04000000","4.93238700"]]}}
2020-11-09T11:24:08.15981 btcusdt {"stream":"btcusdt@depth@100ms","data":{"e":"depthUpdate","E":1604921048153,"s":"BTCUSDT","U":6511118671,"u":6511118671,"b":[["15505.82000000","0.42530300"]],"a":[]}}
2020-11-09T11:24:08.25932 btcusdt {"stream":"btcusdt@depth@100ms","data":{"e":"depthUpdate","E":1604921048253,"s":"BTCUSDT","U":6511118672,"u":6511118689,"b":[["15514.03000000","5.44264100"],["15509.02000000","0.11427900"],["15508.48000000","0.00000000"],["15501.86000000","0.02500000"],["15498.29000000","0.00000000"],["15473.25000000","0.03100000"],["15462.09000000","0.00000000"]],"a":[["15514.04000000","2.58157000"],["15515.29000000","2.47420600"],["15516.68000000","0.20000000"],["15518.76000000","0.00000000"],["15526.67000000","0.02500000"],["15560.12000000","0.03685300"],["15707.01000000","1.27331200"]]}}
2020-11-09T11:24:08.35954 btcusdt {"stream":"btcusdt@depth@100ms","data":{"e":"depthUpdate","E":1604921048353,"s":"BTCUSDT","U":6511118690,"u":6511118694,"b":[["15514.03000000","2.37829300"]],"a":[["15514.04000000","2.33258300"],["15515.29000000","2.72319400"]]}}
2020-11-09T11:24:08.45990 btcusdt {"stream":"btcusdt@depth@100ms","data":{"e":"depthUpdate","E":1604921048453,"s":"BTCUSDT","U":6511118695,"u":6511118712,"b":[["15514.03000000","5.30542900"],["15513.31000000","0.00000000"],["15510.78000000","0.01921800"],["15505.72000000","0.98969100"],["15502.54000000","1.14262800"],["15501.66000000","0.00000000"],["15497.41000000","0.01900000"]],"a":[["15514.04000000","4.56743500"],["15514.81000000","0.01588700"],["15515.29000000","0.00000000"],["15516.08000000","0.00000000"],["15524.12000000","0.38000000"]]}}
2020-11-09T11:24:08.56054 btcusdt {"stream":"btcusdt@depth@100ms","data":{"e":"depthUpdate","E":1604921048553,"s":"BTCUSDT","U":6511118713,"u":6511118724,"b":[["15514.03000000","7.54108100"],["15510.63000000","0.00939500"],["15504.55000000","0.00000000"],["15460.10000000","0.03020000"]],"a":[["15514.04000000","2.33578300"],["15514.50000000","0.00988500"],["15515.29000000","2.70810800"],["15530.24000000","0.00000000"]]}}
2020-11-09T11:24:08.67172 btcusdt {"stream":"btcusdt@depth@100ms","data":{"e":"depthUpdate","E":1604921048653,"s":"BTCUSDT","U":6511118725,"u":6511118736,"b":[["15514.03000000","8.54108100"]],"a":[["15514.04000000","2.23422200"],["15515.00000000","0.00000000"],["15515.29000000","2.88726600"],["15530.88000000","1.05657500"],["15540.00000000","2.19018200"],["15570.00000000","48.53853300"],["15707.01000000","0.00000000"]]}}
2020-11-09T11:24:08.76304 btcusdt {"stream":"btcusdt@depth@100ms","data":{"e":"depthUpdate","E":1604921048753,"s":"BTCUSDT","U":6511118737,"u":6511118742,"b":[["15509.58000000","0.10000000"],["15507.72000000","0.00000000"],["15506.58000000","0.00000000"]],"a":[["15514.04000000","2.23235100"],["15515.30000000","0.00523200"],["15515.31000000","2.26503300"]]}}
2020-11-09T11:24:08.86092 btcusdt {"stream":"btcusdt@depth@100ms","data":{"e":"depthUpdate","E":1604921048853,"s":"BTCUSDT","U":6511118743,"u":6511118764,"b":[["15510.78000000","0.00000000"],["15510.63000000","0.00000000"],["15510.44000000","0.01874000"],["15510.02000000","0.02106400"],["15509.58000000","0.20943800"],["15507.72000000","0.15680600"],["15505.46000000","0.29100000"]],"a":[["15514.04000000","0.94247100"],["15515.28000000","1.13513400"],["15515.29000000","0.00000000"],["15516.67000000","0.00000000"],["15516.69000000","0.00000000"],["15517.46000000","0.65720400"],["15518.76000000","1.17061400"],["15518.81000000","0.00000000"],["15519.33000000","0.75000000"],["15524.87000000","0.25759800"],["15544.73000000","0.00000000"]]}}
2020-11-09T11:24:08.96059 btcusdt {"stream":"btcusdt@depth@100ms","data":{"e":"depthUpdate","E":1604921048953,"s":"BTCUSDT","U":6511118765,"u":6511118766,"b":[],"a":[["15517.49000000","0.00000000"],["15526.98000000","0.00000000"]]}}
2020-11-09T11:24:09.06038 btcusdt {"stream":"btcusdt@depth@100ms","data":{"e":"depthUpdate","E":1604921049054,"s":"BTCUSDT","U":6511118767,"u":6511118770,"b":[["15505.83000000","0.20000000"],["15467.56000000","0.01551600"]],"a":[["15518.77000000","0.00000000"],["15589.36000000","0.00200000"]]}}
2020-11-09T11:24:09.16286 btcusdt {"stream":"btcusdt@depth@100ms","data":{"e":"depthUpdate","E":1604921049154,"s":"BTCUSDT","U":6511118771,"u":6511118780,"b":[["15514.03000000","8.69108100"],["15513.48000000","0.06686400"],["15512.79000000","0.00000000"],["15509.51000000","0.11427900"],["15509.02000000","0.00000000"],["15477.30000000","0.00202600"]],"a":[["15514.04000000","0.09276000"],["15514.75000000","0.00000000"],["15544.74000000","0.01200000"],["15554.89000000","0.00100000"]]}}
2020-11-09T11:24:09.36208 btcusdt {"stream":"btcusdt@depth@100ms","data":{"e":"depthUpdate","E":1604921049354,"s":"BTCUSDT","U":6511118781,"u":6511118783,"b":[["15512.80000000","0.13500000"],["15510.99000000","0.15680600"],["15507.72000000","0.00000000"]],"a":[]}}
2020-11-09T11:24:09.46134 btcusdt {"stream":"btcusdt@depth@100ms","data":{"e":"depthUpdate","E":1604921049454,"s":"BTCUSDT","U":6511118784,"u":6511118785,"b":[["13910.00000000","1.25005600"]],"a":[["15514.04000000","0.03216900"]]}}
2020-11-09T11:24:09.56253 btcusdt {"stream":"btcusdt@depth@100ms","data":{"e":"depthUpdate","E":1604921049554,"s":"BTCUSDT","U":6511118786,"u":6511118807,"b":[["15514.03000000","2.24108100"],["15513.63000000","0.06686400"],["15513.48000000","0.00000000"],["15512.76000000","0.00295200"],["15511.91000000","0.01796300"],["15511.80000000","0.00690000"],["15510.99000000","0.00000000"],["15509.59000000","0.15680600"],["15502.54000000","0.13425900"],["15501.91000000","0.00000000"],["15494.96000000","0.29100000"]],"a":[["15515.27000000","0.13513400"],["15515.28000000","0.00000000"],["15515.31000000","0.26503300"],["15519.04000000","1.29660800"],["15519.33000000","0.00000000"],["15519.61000000","0.20000000"],["15519.75000000","0.75000000"]]}}
2020-11-09T11:24:09.67203 btcusdt {"stream":"btcusdt@depth@100ms","data":{"e":"depthUpdate","E":1604921049654,"s":"BTCUSDT","U":6511118808,"u":6511118837,"b":[["15515.00000000","0.07786600"],["15514.04000000","5.30000000"],["15514.03000000","2.24108100"],["15510.67000000","0.01548600"],["15510.56000000","0.00781000"],["15510.44000000","0.00000000"],["15510.15000000","0.03222900"],["15508.35000000","0.00000000"],["15504.19000000","0.00000000"],["15503.96000000","0.50422700"],["15502.31000000","1.00845500"],["15497.41000000","0.00000000"]],"a":[["15514.04000000","0.00000000"],["15514.50000000","0.00000000"],["15514.81000000","0.00000000"],["15515.01000000","5.82874700"],["15515.14000000","0.00690000"],["15515.27000000","0.00000000"],["15515.49000000","0.00000000"],["15515.62000000","0.03447200"],["15515.76000000","0.00000000"],["15517.46000000","0.00000000"],["15518.76000000","0.00000000"],["15519.04000000","0.00000000"],["15519.18000000","0.00000000"],["15519.61000000","0.00000000"],["15519.72000000","1.71700000"]]}}
2020-11-09T11:24:09.76320 btcusdt {"stream":"btcusdt@depth@100ms","data":{"e":"depthUpdate","E":1604921049754,"s":"BTCUSDT","U":6511118838,"u":6511118862,"b":[["15515.00000000","2.35959000"],["15514.03000000","2.00542900"],["15513.54000000","0.13500000"],["15512.80000000","0.00000000"],["15510.64000000","0.00951400"],["15510.56000000","0.00000000"],["15510.47000000","0.13000000"],["15510.01000000","0.20000000"],["15509.99000000","0.11427900"],["15509.51000000","0.00000000"],["15505.83000000","0.00000000"],["15504.87000000","0.00303000"],["15497.60000000","0.01900000"]],"a":[["15515.01000000","0.52874700"],["15515.31000000","0.24293300"],["15518.30000000","0.00000000"],["15518.65000000","0.00000000"],["15519.28000000","0.05000000"],["15519.63000000","0.01000000"],["15520.45000000","0.00000000"],["15520.85000000","0.00000000"],["15521.43000000","0.01000000"],["15521.83000000","0.01500000"]]}}
2020-11-09T11:24:09.86044 btcusdt {"stream":"btcusdt@depth@100ms","data":{"e":"depthUpdate","E":1604921049854,"s":"BTCUSDT","U":6511118863,"u":6511118877,"b":[["15515.00000000","8.88850700"],["15514.04000000","0.00000000"],["15506.49000000","0.12891500"],["15504.10000000","0.00000000"],["15436.45000000","0.00000000"]],"a":[["15515.01000000","0.54587200"],["15516.68000000","0.00000000"],["15517.47000000","0.00000000"],["15518.14000000","0.20000000"],["15518.44000000","0.50000000"],["15518.58000000","0.10000000"],["15518.85000000","0.00000000"]]}}
2020-11-09T11:24:09.96226 btcusdt {"stream":"btcusdt@depth@100ms","data":{"e":"depthUpdate","E":1604921049954,"s":"BTCUSDT","U":6511118878,"u":6511118888,"b":[["15513.84000000","0.00400000"],["15510.68000000","0.10000000"],["15510.47000000","0.08000000"],["15510.22000000","0.05000000"],["15509.58000000","0.10943800"]],"a":[["15519.05000000","0.00000000"],["15519.43000000","1.74800000"],["15519.75000000","0.00000000"],["15520.05000000","0.50344200"],["15524.05000000","0.00000000"]]}}
2020-11-09T11:24:10.06298 btcusdt {"stream":"btcusdt@depth@100ms","data":{"e":"depthUpdate","E":1604921050054,"s":"BTCUSDT","U":6511118889,"u":6511118901,"b":[["15513.84000000","0.00600000"],["15511.92000000","0.15680600"],["15510.64000000","0.00000000"],["15509.59000000","0.00000000"],["15507.10000000","0.20000000"],["15506.69000000","1.25000000"],["15503.52000000","0.00000000"]],"a":[["15515.78000000","0.01668600"],["15516.46000000","0.32100000"],["15521.05000000","0.75000000"],["15522.88000000","1.25000000"],["15522.99000000","0.00000000"],["15526.16000000","0.06712800"]]}}
2020-11-09T11:24:10.17679 btcusdt {"stream":"btcusdt@depth@100ms","data":{"e":"depthUpdate","E":1604921050154,"s":"BTCUSDT","U":6511118902,"u":6511118910,"b":[["15515.00000000","3.58850700"],["15510.66000000","0.11427900"],["15509.99000000","0.00000000"],["15476.22000000","0.25000000"],["15441.11000000","0.00000000"]],"a":[["15524.96000000","0.03353200"],["15526.85000000","0.00000000"],["15530.88000000","0.00000000"],["15553.79000000","0.25000000"]]}}
2020-11-09T11:24:10.26313 btcusdt {"stream":"btcusdt@depth@100ms","data":{"e":"depthUpdate","E":1604921050254,"s":"BTCUSDT","U":6511118911,"u":6511118912,"b":[["15515.00000000","3.86850700"],["15496.36000000","0.00000000"]],"a":[]}}
2020-11-09T11:24:10.36114 btcusdt {"stream":"btcusdt@depth@100ms","data":{"e":"depthUpdate","E":1604921050354,"s":"BTCUSDT","U":6511118913,"u":6511118919,"b":[["15515.00000000","9.16850700"],["15499.15000000","1.07991800"],["15437.42000000","0.00647700"]],"a":[["15515.01000000","0.48576300"],["15522.88000000","0.00000000"],["15524.05000000","1.25000000"],["15532.63000000","1.05272600"]]}}
2020-11-09T11:24:10.46446 btcusdt {"stream":"btcusdt@depth@100ms","data":{"e":"depthUpdate","E":1604921050454,"s":"BTCUSDT","U":6511118920,"u":6511118926,"b":[["15514.39000000","0.00656900"],["15513.66000000","0.01478100"],["15511.93000000","0.20000000"],["15510.67000000","0.00000000"],["15510.01000000","0.00000000"],["15399.00000000","0.37683000"]],"a":[["15515.47000000","0.00649500"]]}}
2020-11-09T11:24:10.56096 btcusdt {"stream":"btcusdt@depth@100ms","data":{"e":"depthUpdate","E":1604921050554,"s":"BTCUSDT","U":6511118927,"u":6511118929,"b":[["15514.14000000","0.01663500"],["15513.66000000","0.00000000"],["15497.22000000","0.00000000"]],"a":[]}}
2020-11-09T11:24:10.68722 btcusdt {"stream":"btcusdt@depth@100ms","data":{"e":"depthUpdate","E":1604921050654,"s":"BTCUSDT","U":6511118930,"u":6511118938,"b":[["15514.39000000","0.00000000"],["15514.29000000","0.00614400"],["15511.44000000","0.00452000"],["15498.89000000","1.50000000"],["15445.44000000","0.24000000"],["15420.00000000","1.08412300"]],"a":[["15515.47000000","0.00847800"],["15531.88000000","0.24000000"]]}}
2020-11-09T11:24:10.76176 btcusdt {"stream":"btcusdt@depth@100ms","data":{"e":"depthUpdate","E":1604921050754,"s":"BTCUSDT","U":6511118939,"u":6511118946,"b":[["15514.54000000","0.00815000"],["15514.29000000","0.00000000"],["15514.23000000","0.01738700"],["15514.14000000","0.00000000"],["15511.90000000","0.08000000"]],"a":[["15515.01000000","0.48475200"],["15515.47000000","0.00800300"]]}}
2020-11-09T11:24:10.86080 btcusdt {"stream":"btcusdt@depth@100ms","data":{"e":"depthUpdate","E":1604921050855,"s":"BTCUSDT","U":6511118947,"u":6511118947,"b":[["15437.42000000","0.00000000"]],"a":[]}}
2020-11-09T11:24:10.96267 btcusdt {"stream":"btcusdt@depth@100ms","data":{"e":"depthUpdate","E":1604921050955,"s":"BTCUSDT","U":6511118948,"u":6511118950,"b":[["15510.99000000","0.05000000"],["15510.22000000","0.00000000"]],"a":[["15515.47000000","0.00000000"]]}}
2020-11-09T11:24:11.16185 btcusdt {"stream":"btcusdt@depth@100ms","data":{"e":"depthUpdate","E":1604921051155,"s":"BTCUSDT","U":6511118951,"u":6511118953,"b":[["15515.00000000","9.01251000"]],"a":[["15515.67000000","0.04339400"],["15526.98000000","0.00957500"]]}}
2020-11-09T11:24:11.27486 btcusdt {"stream":"btcusdt@depth@100ms","data":{"e":"depthUpdate","E":1604921051255,"s":"BTCUSDT","U":6511118954,"u":6511118960,"b":[["15511.44000000","0.00386800"],["15503.27000000","0.45459500"],["15501.95000000","0.00000000"]],"a":[["15515.01000000","0.43057400"]]}}
2020-11-09T11:24:11.36129 btcusdt {"stream":"btcusdt@depth@100ms","data":{"e":"depthUpdate","E":1604921051355,"s":"BTCUSDT","U":6511118961,"u":6511118963,"b":[["15437.42000000","0.00647700"],["15399.00000000","0.00000000"]],"a":[["15515.47000000","0.00856800"]]}}
2020-11-09T11:24:11.46126 btcusdt {"stream":"btcusdt@depth@100ms","data":{"e":"depthUpdate","E":1604921051455,"s":"BTCUSDT","U":6511118964,"u":6511118965,"b":[],"a":[["15515.47000000","0.00811200"]]}}
2020-11-09T11:24:11.56217 btcusdt {"stream":"btcusdt@depth@100ms","data":{"e":"depthUpdate","E":1604921051555,"s":"BTCUSDT","U":6511118966,"u":6511118968,"b":[["15423.00000000","0.37683000"]],"a":[["15515.47000000","0.00697100"]]}}
2020-11-09T11:24:11.67366 btcusdt {"stream":"btcusdt@depth@100ms","data":{"e":"depthUpdate","E":1604921051655,"s":"BTCUSDT","U":6511118969,"u":6511118977,"b":[["15515.00000000","8.92381600"],["15514.04000000","0.00065200"],["15502.31000000","0.00000000"]],"a":[["15515.01000000","0.55857400"],["15515.31000000","0.11593300"],["15515.47000000","0.00775300"],["15570.00000000","48.43026000"]]}}
2020-11-09T11:24:11.76251 btcusdt {"stream":"btcusdt@depth@100ms","data":{"e":"depthUpdate","E":1604921051755,"s":"BTCUSDT","U":6511118978,"u":6511118980,"b":[["15503.01000000","1.00843600"]],"a":[["15515.47000000","0.00616600"]]}}
2020-11-09T11:24:11.86276 btcusdt {"stream":"btcusdt@depth@100ms","data":{"e":"depthUpdate","E":1604921051855,"s":"BTCUSDT","U":6511118981,"u":6511118981,"b":[],"a":[["15518.58000000","0.00000000"]]}}
2020-11-09T11:24:11.96290 btcusdt {"stream":"btcusdt@depth@100ms","data":{"e":"depthUpdate","E":1604921051955,"s":"BTCUSDT","U":6511118982,"u":6511118990,"b":[["15515.00000000","3.62381600"],["15511.44000000","0.00000000"],["15511.08000000","0.05000000"],["15510.99000000","0.00000000"],["15506.69000000","0.00000000"],["15504.80000000","1.25000000"],["15497.60000000","0.00000000"],["15300.00000000","35.99317600"]],"a":[["15517.54000000","0.10000000"]]}}
2020-11-09T11:24:12.06303 btcusdt {"stream":"btcusdt@depth@100ms","data":{"e":"depthUpdate","E":1604921052055,"s":"BTCUSDT","U":6511118991,"u":6511119000,"b":[["15515.00000000","3.50851000"],["15511.92000000","0.00000000"],["15510.68000000","0.00000000"],["15510.66000000","0.00000000"],["15510.17000000","0.11427900"],["15509.59000000","0.10000000"],["15509.58000000","0.00000000"],["15498.04000000","0.01900000"]],"a":[["15515.01000000","5.85857400"]]}}
2020-11-09T11:24:12.16180 btcusdt {"stream":"btcusdt@depth@100ms","data":{"e":"depthUpdate","E":1604921052155,"s":"BTCUSDT","U":6511119001,"u":6511119017,"b":[["15515.00000000","8.57959300"],["15513.55000000","0.01799600"],["15513.54000000","0.00000000"],["15511.91000000","0.00000000"],["15511.09000000","0.15680600"],["15510.02000000","0.00000000"],["15506.58000000","0.00000000"]],"a":[["15515.01000000","0.72180100"],["15515.47000000","0.00723100"],["16450.38000000","10.88017700"]]}}
2020-11-09T11:24:12.26283 btcusdt {"stream":"btcusdt@depth@100ms","data":{"e":"depthUpdate","E":1604921052255,"s":"BTCUSDT","U":6511119018,"u":6511119023,"b":[["15515.00000000","8.80286500"],["15506.58000000","0.02106400"]],"a":[["15515.01000000","0.49852900"],["15515.47000000","0.00700600"],["15517.55000000","0.00000000"]]}}
2020-11-09T11:24:12.36501 btcusdt {"stream":"btcusdt@depth@100ms","data":{"e":"depthUpdate","E":1604921052355,"s":"BTCUSDT","U":6511119024,"u":6511119026,"b":[],"a":[["15515.01000000","0.49787800"],["15515.47000000","0.00831800"]]}}
2020-11-09T11:24:12.46248 btcusdt {"stream":"btcusdt@depth@100ms","data":{"e":"depthUpdate","E":1604921052456,"s":"BTCUSDT","U":6511119027,"u":6511119032,"b":[["15511.71000000","0.00000000"]],"a":[["15515.47000000","0.00848900"],["15523.54000000","0.00000000"],["15550.00000000","38.72345100"],["15615.00000000","8.09829400"]]}}
2020-11-09T11:24:12.56272 btcusdt {"stream":"btcusdt@depth@100ms","data":{"e":"depthUpdate","E":1604921052556,"s":"BTCUSDT","U":6511119033,"u":6511119038,"b":[["15515.00000000","8.80286500"]],"a":[["15515.01000000","0.44019300"],["15522.52000000","0.00000000"],["15525.12000000","1.50309000"],["15525.17000000","1.00843600"]]}}
2020-11-09T11:24:12.67181 btcusdt {"stream":"btcusdt@depth@100ms","data":{"e":"depthUpdate","E":1604921052656,"s":"BTCUSDT","U":6511119039,"u":6511119042,"b":[["15515.00000000","8.76786500"]],"a":[["15515.01000000","4.94019300"],["15515.47000000","0.00984500"]]}}
2020-11-09T11:24:12.76431 btcusdt {"stream":"btcusdt@depth@100ms","data":{"e":"depthUpdate","E":1604921052756,"s":"BTCUSDT","U":6511119043,"u":6511119045,"b":[["15515.00000000","8.76253700"]],"a":[["15515.01000000","4.59019300"]]}}
2020-11-09T11:24:12.86312 btcusdt {"stream":"btcusdt@depth@100ms","data":{"e":"depthUpdate","E":1604921052856,"s":"BTCUSDT","U":6511119046,"u":6511119051,"b":[["15515.00000000","8.61253700"],["15328.15000000","0.22905100"]],"a":[["15515.01000000","4.58697000"],["15524.81000000","0.13031800"],["15525.04000000","0.00000000"]]}}
2020-11-09T11:24:12.96257 btcusdt {"stream":"btcusdt@depth@100ms","data":{"e":"depthUpdate","E":1604921052956,"s":"BTCUSDT","U":6511119052,"u":6511119056,"b":[["15511.08000000","0.00000000"],["15510.48000000","0.05000000"]],"a":[["15515.47000000","0.00791300"],["15520.07000000","0.12892100"]]}}
2020-11-09T11:24:13.06191 btcusdt {"stream":"btcusdt@depth@100ms","data":{"e":"depthUpdate","E":1604921053056,"s":"BTCUSDT","U":6511119057,"u":6511119068,"b":[["15515.00000000","8.76253700"],["15504.80000000","0.00000000"],["15504.79000000","1.25000000"]],"a":[["15515.01000000","0.34795100"],["15515.47000000","0.00000000"],["15520.07000000","0.00000000"],["15531.88000000","0.00000000"]]}}
2020-11-09T11:24:13.26344 btcusdt {"stream":"btcusdt@depth@100ms","data":{"e":"depthUpdate","E":1604921053256,"s":"BTCUSDT","U":6511119069,"u":6511119074,"b":[["15515.00000000","3.46253700"],["15464.53000000","0.00129400"],["15445.44000000","0.00000000"]],"a":[["15526.98000000","0.00000000"]]}}
2020-11-09T11:24:13.36334 btcusdt {"stream":"btcusdt@depth@100ms","data":{"e":"depthUpdate","E":1604921053356,"s":"BTCUSDT","U":6511119075,"u":6511119084,"b":[["15515.00000000","8.55910100"],["15513.64000000","0.01798100"],["15513.55000000","0.00000000"],["15511.09000000","0.00000000"],["15510.22000000","0.15680600"],["15509.60000000","0.02106400"],["15506.58000000","0.00000000"]],"a":[["15515.01000000","5.64408300"]]}}
2020-11-09T11:24:13.46482 btcusdt {"stream":"btcusdt@depth@100ms","data":{"e":"depthUpdate","E":1604921053456,"s":"BTCUSDT","U":6511119085,"u":6511119085,"b":[["15515.00000000","3.45910100"]],"a":[]}}
2020-11-09T11:24:13.56422 btcusdt {"stream":"btcusdt@depth@100ms","data":{"e":"depthUpdate","E":1604921053556,"s":"BTCUSDT","U":6511119086,"u":6511119090,"b":[["15515.00000000","3.45910100"]],"a":[["15515.01000000","5.64343200"],["15520.52000000","0.00000000"]]}}
2020-11-09T11:24:13.67766 btcusdt {"stream":"btcusdt@depth@100ms","data":{"e":"depthUpdate","E":1604921053656,"s":"BTCUSDT","U":6511119091,"u":6511119093,"b":[["15441.31000000","0.24000000"]],"a":[["15515.47000000","0.00770300"],["15526.85000000","0.24000000"]]}}
2020-11-09T11:24:13.76428 btcusdt {"stream":"btcusdt@depth@100ms","data":{"e":"depthUpdate","E":1604921053756,"s":"BTCUSDT","U":6511119094,"u":6511119098,"b":[["15021.83000000","0.00000000"]],"a":[["15515.47000000","0.00727900"]]}}
2020-11-09T11:24:13.86281 btcusdt {"stream":"btcusdt@depth@100ms","data":{"e":"depthUpdate","E":1604921053856,"s":"BTCUSDT","U":6511119099,"u":6511119099,"b":[["15363.92000000","0.00260400"]],"a":[]}}
2020-11-09T11:24:13.96446 btcusdt {"stream":"btcusdt@depth@100ms","data":{"e":"depthUpdate","E":1604921053956,"s":"BTCUSDT","U":6511119100,"u":6511119110,"b":[["15515.00000000","6.80910100"],["15510.48000000","0.00000000"],["15510.47000000","0.13000000"],["15020.19000000","0.00070100"]],"a":[["15515.01000000","0.28315500"],["15515.47000000","0.00787200"],["15519.61000000","0.00000000"]]}}
2020-11-09T11:24:14.06270 btcusdt {"stream":"btcusdt@depth@100ms","data":{"e":"depthUpdate","E":1604921054056,"s":"BTCUSDT","U":6511119111,"u":6511119117,"b":[["15515.00000000","1.90237700"],["15423.00000000","0.00000000"]],"a":[["15515.01000000","5.58315500"],["15515.47000000","0.00781800"]]}}
2020-11-09T11:24:14.16287 btcusdt {"stream":"btcusdt@depth@100ms","data":{"e":"depthUpdate","E":1604921054157,"s":"BTCUSDT","U":6511119118,"u":6511119121,"b":[["15511.25000000","0.00000000"],["15510.17000000","0.00000000"],["15509.66000000","0.11427900"],["15449.01000000","0.00064800"]],"a":[]}}
2020-11-09T11:24:14.26410 btcusdt {"stream":"btcusdt@depth@100ms","data":{"e":"depthUpdate","E":1604921054257,"s":"BTCUSDT","U":6511119122,"u":6511119134,"b":[["15511.93000000","0.00000000"],["15510.48000000","0.20000000"],["15510.22000000","0.00000000"],["15509.61000000","0.00000000"],["15509.59000000","0.00000000"],["15507.11000000","0.10000000"],["15399.00000000","0.37683000"]],"a":[["15515.01000000","0.28315500"],["15520.04000000","0.00000000"],["15615.00000000","7.99002100"],["16140.76000000","0.00000000"]]}}
2020-11-09T11:24:14.36361 btcusdt {"stream":"btcusdt@depth@100ms","data":{"e":"depthUpdate","E":1604921054357,"s":"BTCUSDT","U":6511119135,"u":6511119144,"b":[["15509.61000000","0.15680600"],["15501.86000000","0.00000000"],["15473.25000000","0.00000000"]],"a":[["15518.14000000","0.00000000"],["15522.57000000","0.12890800"],["15522.58000000","1.25000000"],["15524.05000000","0.00000000"],["15526.67000000","0.00000000"],["15560.12000000","0.00585300"]]}}
2020-11-09T11:24:14.46514 btcusdt {"stream":"btcusdt@depth@100ms","data":{"e":"depthUpdate","E":1604921054457,"s":"BTCUSDT","U":6511119145,"u":6511119149,"b":[["15514.23000000","0.00000000"],["15511.74000000","0.01836300"],["15386.90000000","0.00065000"]],"a":[["15516.45000000","0.20000000"],["16084.47000000","0.00062200"]]}}
2020-11-09T11:24:14.56398 btcusdt {"stream":"btcusdt@depth@100ms","data":{"e":"depthUpdate","E":1604921054557,"s":"BTCUSDT","U":6511119150,"u":6511119159,"b":[["15514.54000000","0.00000000"],["15511.84000000","0.00775900"],["15510.22000000","0.10000000"],["15509.61000000","0.00000000"],["15507.11000000","0.00000000"],["15403.98000000","0.00389600"]],"a":[["15515.47000000","0.00711100"],["15516.45000000","0.00000000"],["15517.53000000","0.20000000"]]}}
2020-11-09T11:24:14.69556 btcusdt {"stream":"btcusdt@depth@100ms","data":{"e":"depthUpdate","E":1604921054657,"s":"BTCUSDT","U":6511119160,"u":6511119166,"b":[["15510.15000000","0.14650800"],["15509.66000000","0.00000000"],["15509.41000000","0.15680600"],["15371.37000000","0.00065100"]],"a":[["15515.47000000","0.00795800"],["15526.98000000","0.00957500"]]}}
2020-11-09T11:24:14.76414 btcusdt {"stream":"btcusdt@depth@100ms","data":{"e":"depthUpdate","E":1604921054757,"s":"BTCUSDT","U":6511119167,"u":6511119180,"b":[["15515.00000000","2.90237700"],["15512.18000000","0.50000000"],["15509.41000000","0.15680600"]],"a":[["15515.47000000","0.00882300"],["15517.52000000","0.30000000"],["15517.53000000","0.00000000"],["15517.54000000","0.00000000"],["15518.64000000","0.50000000"],["15570.00000000","48.53853300"]]}}
2020-11-09T11:24:14.86393 btcusdt {"stream":"btcusdt@depth@100ms","data":{"e":"depthUpdate","E":1604921054857,"s":"BTCUSDT","U":6511119181,"u":6511119188,"b":[["15515.00000000","8.20237700"],["15510.49000000","0.10941800"],["15500.34000000","0.00000000"],["15200.93000000","0.00526300"]],"a":[["15515.01000000","0.22312100"],["15515.47000000","0.00703600"],["15911.93000000","0.04000000"]]}}
2020-11-09T11:24:14.96288 btcusdt {"stream":"btcusdt@depth@100ms","data":{"e":"depthUpdate","E":1604921054957,"s":"BTCUSDT","U":6511119189,"u":6511119190,"b":[["15510.48000000","0.00000000"],["15502.28000000","0.03353200"]],"a":[]}}
2020-11-09T11:24:15.06329 btcusdt {"stream":"btcusdt@depth@100ms","data":{"e":"depthUpdate","E":1604921055057,"s":"BTCUSDT","U":6511119191,"u":6511119195,"b":[["15515.00000000","2.90237700"],["15512.19000000","0.00000000"],["15510.99000000","0.20000000"],["15507.08000000","0.00000000"]],"a":[]}}
2020-11-09T11:24:15.26338 btcusdt {"stream":"btcusdt@depth@100ms","data":{"e":"depthUpdate","E":1604921055257,"s":"BTCUSDT","U":6511119196,"u":6511119197,"b":[["15509.41000000","0.15680600"]],"a":[]}}
2020-11-09T11:24:15.36412 btcusdt {"stream":"btcusdt@depth@100ms","data":{"e":"depthUpdate","E":1604921055357,"s":"BTCUSDT","U":6511119198,"u":6511119200,"b":[["15509.41000000","0.15680600"],["14936.88000000","0.01071200"]],"a":[]}}
2020-11-09T11:24:15.46532 btcusdt {"stream":"btcusdt@depth@100ms","data":{"e":"depthUpdate","E":1604921055457,"s":"BTCUSDT","U":6511119201,"u":6511119205,"b":[["15509.41000000","0.15680600"],["15420.00000000","0.97585000"]],"a":[["15519.47000000","0.09621200"],["15526.85000000","0.00000000"]]}}
2020-11-09T11:24:15.56599 btcusdt {"stream":"btcusdt@depth@100ms","data":{"e":"depthUpdate","E":1604921055557,"s":"BTCUSDT","U":6511119206,"u":6511119210,"b":[["15441.31000000","0.00000000"],["15293.74000000","0.00065400"]],"a":[["15515.47000000","0.00999100"],["15519.47000000","0.00000000"]]}}
2020-11-09T11:24:15.67781 btcusdt {"stream":"btcusdt@depth@100ms","data":{"e":"depthUpdate","E":1604921055657,"s":"BTCUSDT","U":6511119211,"u":6511119213,"b":[["15441.51000000","0.24000000"]],"a":[["15515.47000000","0.00661000"]]}}
2020-11-09T11:24:15.76348 btcusdt {"stream":"btcusdt@depth@100ms","data":{"e":"depthUpdate","E":1604921055757,"s":"BTCUSDT","U":6511119214,"u":6511119224,"b":[["15515.00000000","7.05237700"],["15510.67000000","0.11427900"],["15510.15000000","0.03222900"]],"a":[["15515.01000000","0.16294800"],["15515.47000000","0.00867400"],["15515.62000000","0.00000000"],["15526.85000000","0.24000000"],["15591.00000000","0.54527600"]]}}
2020-11-09T11:24:15.86405 btcusdt {"stream":"btcusdt@depth@100ms","data":{"e":"depthUpdate","E":1604921055858,"s":"BTCUSDT","U":6511119225,"u":6511119230,"b":[["15515.00000000","2.90237700"]],"a":[["15515.47000000","0.00935600"],["15516.46000000","0.00000000"],["15524.80000000","0.08738700"],["15524.81000000","0.00000000"]]}}
2020-11-09T11:24:15.96364 btcusdt {"stream":"btcusdt@depth@100ms","data":{"e":"depthUpdate","E":1604921055958,"s":"BTCUSDT","U":6511119231,"u":6511119239,"b":[["15515.00000000","2.90159700"],["15510.68000000","0.15680600"],["15510.48000000","0.05000000"],["15510.47000000","0.08000000"],["15509.41000000","0.00000000"],["14509.12000000","0.02205600"]],"a":[["15515.47000000","0.00635200"],["15520.04000000","0.12891200"]]}}
2020-11-09T11:24:16.06375 btcusdt {"stream":"btcusdt@depth@100ms","data":{"e":"depthUpdate","E":1604921056058,"s":"BTCUSDT","U":6511119240,"u":6511119241,"b":[],"a":[["15525.31000000","0.00000000"],["15527.71000000","0.00000000"]]}}
2020-11-09T11:24:16.20896 btcusdt {"stream":"btcusdt@depth@100ms","data":{"e":"depthUpdate","E":1604921056158,"s":"BTCUSDT","U":6511119242,"u":6511119244,"b":[["15216.11000000","0.00065800"]],"a":[["15522.91000000","0.06679800"],["15523.83000000","0.30059300"]]}}
2020-11-09T11:24:16.26395 btcusdt {"stream":"btcusdt@depth@100ms","data":{"e":"depthUpdate","E":1604921056258,"s":"BTCUSDT","U":6511119245,"u":6511119250,"b":[["15502.73000000","0.02500000"],["15498.04000000","0.00000000"],["15474.12000000","0.03100000"]],"a":[["15515.47000000","0.00000000"],["15527.54000000","0.02500000"],["15560.99000000","0.03100000"]]}}
2020-11-09T11:24:16.36423 btcusdt {"stream":"btcusdt@depth@100ms","data":{"e":"depthUpdate","E":1604921056358,"s":"BTCUSDT","U":6511119251,"u":6511119252,"b":[["15507.97000000","0.22500000"],["15399.00000000","0.48510300"]],"a":[]}}
2020-11-09T11:24:16.46409 btcusdt {"stream":"btcusdt@depth@100ms","data":{"e":"depthUpdate","E":1604921056458,"s":"BTCUSDT","U":6511119253,"u":6511119256,"b":[["15515.00000000","1.78442500"],["15498.22000000","0.01900000"]],"a":[["15515.01000000","5.46294800"]]}}
2020-11-09T11:24:16.56529 btcusdt {"stream":"btcusdt@depth@100ms","data":{"e":"depthUpdate","E":1604921056558,"s":"BTCUSDT","U":6511119257,"u":6511119272,"b":[["15515.00000000","0.37988900"],["15510.68000000","0.00000000"],["15510.67000000","0.00000000"],["15510.49000000","0.00000000"],["15510.18000000","0.11427900"],["15509.61000000","0.15680600"],["15507.10000000","0.00000000"],["15465.91000000","0.50000000"],["15462.78000000","0.00000000"]],"a":[["15515.01000000","7.67487500"],["15516.46000000","0.32100000"],["15522.69000000","1.50000000"],["15525.12000000","0.00309000"]]}}
2020-11-09T11:24:16.67359 btcusdt {"stream":"btcusdt@depth@100ms","data":{"e":"depthUpdate","E":1604921056658,"s":"BTCUSDT","U":6511119273,"u":6511119282,"b":[["15515.00000000","0.08242900"],["15138.48000000","0.00066100"]],"a":[["15515.01000000","5.68684900"],["15515.64000000","0.03383600"],["15515.68000000","0.00000000"],["15527.15000000","0.00000000"]]}}
2020-11-09T11:24:16.76886 btcusdt {"stream":"btcusdt@depth@100ms","data":{"e":"depthUpdate","E":1604921056758,"s":"BTCUSDT","U":6511119283,"u":6511119286,"b":[["15509.61000000","0.00000000"],["15509.41000000","0.15680600"]],"a":[["15523.93000000","0.13414400"],["15526.98000000","0.00000000"]]}}
2020-11-09T11:24:16.86567 btcusdt {"stream":"btcusdt@depth@100ms","data":{"e":"depthUpdate","E":1604921056858,"s":"BTCUSDT","U":6511119287,"u":6511119291,"b":[["15514.81000000","0.00600000"],["13816.16000000","0.04632300"]],"a":[["15515.01000000","0.38684900"]]}}
2020-11-09T11:24:16.98521 btcusdt {"stream":"btcusdt@depth@100ms","data":{"e":"depthUpdate","E":1604921056958,"s":"BTCUSDT","U":6511119292,"u":6511119292,"b":[],"a":[["15515.01000000","0.17492200"]]}}
2020-11-09T11:24:17.06505 btcusdt {"stream":"btcusdt@depth@100ms","data":{"e":"depthUpdate","E":1604921057058,"s":"BTCUSDT","U":6511119293,"u":6511119294,"b":[["15512.76000000","0.00000000"]],"a":[["15570.00000000","48.43026000"]]}}
2020-11-09T11:24:17.16606 btcusdt {"stream":"btcusdt@depth@100ms","data":{"e":"depthUpdate","E":1604921057158,"s":"BTCUSDT","U":6511119295,"u":6511119301,"b":[["15515.00000000","5.18242900"],["15514.23000000","0.01555700"],["15511.74000000","0.00000000"],["15506.58000000","0.20000000"],["15441.51000000","0.00000000"]],"a":[["15515.01000000","0.17197000"],["15526.85000000","0.00000000"]]}}
2020-11-09T11:24:17.26548 btcusdt {"stream":"btcusdt@depth@100ms","data":{"e":"depthUpdate","E":1604921057258,"s":"BTCUSDT","U":6511119302,"u":6511119315,"b":[["15515.00000000","8.39105800"],["15514.54000000","0.00899600"],["15511.84000000","0.00000000"],["15511.00000000","0.15680600"],["15510.70000000","0.11427900"],["15510.18000000","0.00000000"],["15509.41000000","0.00000000"],["12693.55000000","0.10083900"]],"a":[["15515.01000000","0.09994300"],["15515.47000000","0.00899100"],["15515.64000000","0.00000000"],["15520.04000000","0.00000000"]]}}
2020-11-09T11:24:17.36786 btcusdt {"stream":"btcusdt@depth@100ms","data":{"e":"depthUpdate","E":1604921057358,"s":"BTCUSDT","U":6511119316,"u":6511119319,"b":[["15515.00000000","3.29105800"],["15513.85000000","0.14000000"]],"a":[["15515.01000000","0.00000000"],["15516.46000000","0.00000000"]]}}
2020-11-09T11:24:17.46550 btcusdt {"stream":"btcusdt@depth@100ms","data":{"e":"depthUpdate","E":1604921057458,"s":"BTCUSDT","U":6511119320,"u":6511119332,"b":[["15515.07000000","0.03045800"],["15515.00000000","2.08242900"],["15514.46000000","0.06750100"],["15513.85000000","0.00000000"],["15513.63000000","0.00000000"],["15506.58000000","0.00000000"]],"a":[["15515.08000000","5.30690000"],["15515.47000000","0.00743900"],["15578.06000000","0.03694300"]]}}
2020-11-09T11:24:17.57930 btcusdt {"stream":"btcusdt@depth@100ms","data":{"e":"depthUpdate","E":1604921057558,"s":"BTCUSDT","U":6511119333,"u":6511119341,"b":[["15514.24000000","0.16500000"],["15510.70000000","0.00000000"],["15502.35000000","0.03361100"]],"a":[["15515.08000000","5.45552900"],["15516.48000000","0.32100000"],["15522.63000000","0.03361100"],["15523.42000000","0.10083300"],["15524.94000000","0.36972200"]]}}
2020-11-09T11:24:17.68204 btcusdt {"stream":"btcusdt@depth@100ms","data":{"e":"depthUpdate","E":1604921057658,"s":"BTCUSDT","U":6511119342,"u":6511119355,"b":[["15515.07000000","6.08045800"],["15514.54000000","0.00000000"],["15514.30000000","0.00634000"],["15509.91000000","0.11427900"],["15506.58000000","0.20000000"],["15498.22000000","0.00000000"]],"a":[["15515.08000000","0.20862900"],["15515.47000000","0.00789200"],["15518.28000000","0.00000000"],["15518.78000000","0.01700000"],["15519.79000000","0.00000000"]]}}
2020-11-09T11:24:17.76533 btcusdt {"stream":"btcusdt@depth@100ms","data":{"e":"depthUpdate","E":1604921057758,"s":"BTCUSDT","U":6511119356,"u":6511119382,"b":[["15515.10000000","6.33153000"],["15515.07000000","2.47408700"],["15513.53000000","0.00000000"],["15512.18000000","0.00000000"],["15511.91000000","0.15680600"],["15511.00000000","0.00000000"],["15506.70000000","1.25000000"],["15506.58000000","0.00000000"],["15504.79000000","0.00000000"],["15498.14000000","0.01900000"],["15445.49000000","0.24000000"],["15399.00000000","0.37683000"]],"a":[["15515.08000000","0.00000000"],["15515.11000000","5.30690000"],["15516.48000000","0.00000000"],["15517.52000000","0.00000000"],["15518.58000000","0.20000000"],["15519.27000000","0.10000000"]]}}
2020-11-09T11:24:17.86528 btcusdt {"stream":"btcusdt@depth@100ms","data":{"e":"depthUpdate","E":1604921057859,"s":"BTCUSDT","U":6511119383,"u":6511119399,"b":[["15515.10000000","8.59226600"],["15515.07000000","2.26545800"],["15514.24000000","0.00000000"],["15514.23000000","0.00000000"],["15514.15000000","0.01805300"],["15514.03000000","0.00542900"],["15511.91000000","0.00000000"],["15511.00000000","0.15680600"],["15506.70000000","0.00000000"],["15506.69000000","1.25000000"],["15437.42000000","0.00000000"],["15399.00000000","0.00000000"]],"a":[["15515.78000000","0.00000000"],["15515.88000000","0.01809800"],["15530.71000000","0.24000000"]]}}
2020-11-09T11:24:17.96585 btcusdt {"stream":"btcusdt@depth@100ms","data":{"e":"depthUpdate","E":1604921057959,"s":"BTCUSDT","U":6511119400,"u":6511119414,"b":[["15515.10000000","2.21273900"],["15515.07000000","2.24190000"],["15514.30000000","0.00000000"],["15506.69000000","0.00000000"],["15504.79000000","1.25000000"],["15500.18000000","0.50000000"],["15420.00000000","1.08412300"]],"a":[["15515.47000000","0.00000000"],["15515.57000000","0.00755700"],["15515.88000000","0.01342900"],["15519.79000000","0.12892600"]]}}
2020-11-09T11:24:18.06534 btcusdt {"stream":"btcusdt@depth@100ms","data":{"e":"depthUpdate","E":1604921058059,"s":"BTCUSDT","U":6511119415,"u":6511119437,"b":[["15515.10000000","3.22706500"],["15514.30000000","0.00983000"],["15510.42000000","0.11427900"],["15509.91000000","0.00000000"],["15508.10000000","1.25000000"],["15504.79000000","0.00000000"],["15503.18000000","0.13424200"],["15502.54000000","0.00000000"],["15501.94000000","0.06712100"],["15423.00000000","0.37683000"]],"a":[["15515.11000000","0.08180800"],["15517.60000000","0.10000000"],["15519.27000000","0.00000000"],["15519.79000000","0.00000000"],["15522.58000000","0.00000000"],["15523.27000000","1.25000000"]]}}
2020-11-09T11:24:18.16664 btcusdt {"stream":"btcusdt@depth@100ms","data":{"e":"depthUpdate","E":1604921058159,"s":"BTCUSDT","U":6511119438,"u":6511119458,"b":[["15515.13000000","1.02081100"],["15515.12000000","0.00690000"],["15515.10000000","7.52906500"],["15508.10000000","0.00000000"],["15507.86000000","1.25000000"],["15506.58000000","0.20000000"]],"a":[["15515.11000000","0.00000000"],["15522.63000000","0.00000000"],["15523.27000000","0.00000000"],["15523.42000000","0.00000000"],["15523.93000000","0.00000000"],["15524.29000000","0.03361100"],["15524.55000000","1.25000000"],["15524.94000000","0.00000000"],["15526.98000000","0.00957500"],["15527.04000000","0.36972200"],["15615.00000000","8.09829400"]]}}
2020-11-09T11:24:18.26617 btcusdt {"stream":"btcusdt@depth@100ms","data":{"e":"depthUpdate","E":1604921058259,"s":"BTCUSDT","U":6511119459,"u":6511119480,"b":[["15515.13000000","7.74863900"],["15515.11000000","0.39500000"],["15515.10000000","2.08372400"],["15515.07000000","2.00690000"],["15515.00000000","0.08242900"],["15514.52000000","0.05021200"],["15514.50000000","0.00000000"],["15514.46000000","0.00000000"],["15511.91000000","0.10000000"],["15510.22000000","0.00000000"]],"a":[["15515.14000000","0.01380000"],["15515.88000000","0.00000000"],["15516.66000000","0.32100000"],["15517.60000000","0.00000000"],["15519.09000000","0.10000000"],["15525.42000000","0.40983300"],["15526.00000000","0.14060300"],["15530.71000000","0.00000000"]]}}
2020-11-09T11:24:18.36972 btcusdt {"stream":"btcusdt@depth@100ms","data":{"e":"depthUpdate","E":1604921058359,"s":"BTCUSDT","U":6511119481,"u":6511119494,"b":[["15514.30000000","0.00000000"],["15514.15000000","0.00000000"],["15437.55000000","0.00647700"],["14175.43000000","0.00000000"]],"a":[["15515.14000000","0.01580000"],["15518.15000000","0.00000000"],["15521.05000000","0.00000000"],["15521.67000000","0.12890800"],["15521.87000000","0.75000000"],["15522.57000000","0.00000000"],["15523.49000000","0.00000000"],["15526.79000000","0.25756700"],["15531.91000000","0.39000000"]]}}
2020-11-09T11:24:18.46744 btcusdt {"stream":"btcusdt@depth@100ms","data":{"e":"depthUpdate","E":1604921058459,"s":"BTCUSDT","U":6511119495,"u":6511119504,"b":[["15515.13000000","8.14863900"],["15515.10000000","2.02872400"],["15511.92000000","0.15680600"],["15511.71000000","0.11427900"],["15511.00000000","0.00000000"],["15510.42000000","0.00000000"],["15503.71000000","1.00838700"],["15503.01000000","0.00000000"]],"a":[["15521.67000000","0.00000000"],["15523.49000000","0.12890800"]]}}
2020-11-09T11:24:18.56756 btcusdt {"stream":"btcusdt@depth@100ms","data":{"e":"depthUpdate","E":1604921058559,"s":"BTCUSDT","U":6511119505,"u":6511119529,"b":[["15515.30000000","3.97700500"],["15515.22000000","0.00690000"],["15515.15000000","0.00000000"],["15515.14000000","0.00000000"],["15515.13000000","2.42081100"],["15514.71000000","0.05021200"],["15514.63000000","0.00000000"],["15514.52000000","0.00000000"],["15505.50000000","0.50419400"],["15503.96000000","0.00000000"]],"a":[["15515.14000000","0.00000000"],["15515.30000000","0.00000000"],["15515.31000000","0.08378900"],["15520.73000000","0.00000000"],["15525.17000000","0.00000000"],["15526.77000000","1.00838700"]]}}
2020-11-09T11:24:18.67168 btcusdt {"stream":"btcusdt@depth@100ms","data":{"e":"depthUpdate","E":1604921058659,"s":"BTCUSDT","U":6511119530,"u":6511119538,"b":[["15515.30000000","6.28700500"],["15515.11000000","0.00000000"],["15515.07000000","0.00690000"],["15514.94000000","0.00200000"],["15502.14000000","1.00000000"],["15499.04000000","0.00000000"]],"a":[["15522.69000000","0.00000000"],["15525.39000000","1.50000000"]]}}
2020-11-09T11:24:18.76541 btcusdt {"stream":"btcusdt@depth@100ms","data":{"e":"depthUpdate","E":1604921058759,"s":"BTCUSDT","U":6511119539,"u":6511119541,"b":[["15515.30000000","8.88700500"],["15511.91000000","0.00000000"]],"a":[["15515.57000000","0.00000000"]]}}
2020-11-09T11:24:18.86888 btcusdt {"stream":"btcusdt@depth@100ms","data":{"e":"depthUpdate","E":1604921058859,"s":"BTCUSDT","U":6511119542,"u":6511119548,"b":[["15511.00000000","0.10941200"],["15510.49000000","0.10000000"],["15509.79000000","1.25000000"],["15507.86000000","0.00000000"],["15437.55000000","0.00000000"]],"a":[["15518.57000000","0.10000000"],["15519.09000000","0.00000000"]]}}
2020-11-09T11:24:18.96689 btcusdt {"stream":"btcusdt@depth@100ms","data":{"e":"depthUpdate","E":1604921058959,"s":"BTCUSDT","U":6511119549,"u":6511119555,"b":[["15511.08000000","0.05000000"],["15510.48000000","0.00000000"],["15509.79000000","0.00000000"],["15507.86000000","1.25000000"]],"a":[["15524.55000000","0.00000000"],["15525.55000000","1.25000000"],["15546.00000000","0.38000000"]]}}
2020-11-09T11:24:19.07219 btcusdt {"stream":"btcusdt@depth@100ms","data":{"e":"depthUpdate","E":1604921059059,"s":"BTCUSDT","U":6511119556,"u":6511119558,"b":[["15507.86000000","1.25000000"]],"a":[["15546.00000000","0.00000000"]]}}
2020-11-09T11:24:19.21223 btcusdt {"stream":"btcusdt@depth@100ms","data":{"e":"depthUpdate","E":1604921059159,"s":"BTCUSDT","U":6511119559,"u":6511119560,"b":[],"a":[["15526.36000000","0.13425200"],["15527.93000000","0.00000000"]]}}
2020-11-09T11:24:19.26688 btcusdt {"stream":"btcusdt@depth@100ms","data":{"e":"depthUpdate","E":1604921059259,"s":"BTCUSDT","U":6511119561,"u":6511119563,"b":[["15501.32000000","1.50000000"],["15498.89000000","0.00000000"]],"a":[["15524.80000000","0.00000000"]]}}
2020-11-09T11:24:19.36768 btcusdt {"stream":"btcusdt@depth@100ms","data":{"e":"depthUpdate","E":1604921059359,"s":"BTCUSDT","U":6511119564,"u":6511119566,"b":[["15514.53000000","0.01251000"],["15437.72000000","0.00647700"]],"a":[["15516.08000000","0.01866300"]]}}
2020-11-09T11:24:19.46743 btcusdt {"stream":"btcusdt@depth@100ms","data":{"e":"depthUpdate","E":1604921059459,"s":"BTCUSDT","U":6511119567,"u":6511119578,"b":[["15515.30000000","5.28700500"],["15514.87000000","0.05021200"],["15514.84000000","0.00800300"],["15514.71000000","0.00000000"]],"a":[["15515.31000000","0.02374500"],["15515.77000000","0.00893200"],["15516.66000000","0.00000000"],["15517.02000000","0.32100000"],["15526.36000000","0.00000000"],["15528.18000000","0.13425100"],["15550.00000000","38.68844100"]]}}
2020-11-09T11:24:19.56613 btcusdt {"stream":"btcusdt@depth@100ms","data":{"e":"depthUpdate","E":1604921059559,"s":"BTCUSDT","U":6511119579,"u":6511119583,"b":[["15514.93000000","0.05021200"],["15514.87000000","0.00000000"],["15508.35000000","1.25000000"],["15507.86000000","0.00000000"],["15453.00000000","0.00130000"]],"a":[]}}
2020-11-09T11:24:19.68084 btcusdt {"stream":"btcusdt@depth@100ms","data":{"e":"depthUpdate","E":1604921059659,"s":"BTCUSDT","U":6511119584,"u":6511119586,"b":[["15511.71000000","0.00000000"],["15511.23000000","0.11427900"],["15460.10000000","0.00000000"]],"a":[]}}
2020-11-09T11:24:19.76655 btcusdt {"stream":"btcusdt@depth@100ms","data":{"e":"depthUpdate","E":1604921059760,"s":"BTCUSDT","U":6511119587,"u":6511119589,"b":[["15512.69000000","0.50000000"],["15445.49000000","0.00000000"]],"a":[["15519.22000000","0.50000000"]]}}
2020-11-09T11:24:19.86696 btcusdt {"stream":"btcusdt@depth@100ms","data":{"e":"depthUpdate","E":1604921059860,"s":"BTCUSDT","U":6511119590,"u":6511119590,"b":[["15498.14000000","0.00000000"]],"a":[]}}
2020-11-09T11:24:19.96610 btcusdt {"stream":"btcusdt@depth@100ms","data":{"e":"depthUpdate","E":1604921059960,"s":"BTCUSDT","U":6511119591,"u":6511119599,"b":[["15515.30000000","6.28700500"],["15514.95000000","0.05021200"],["15514.93000000","0.00000000"],["15512.69000000","0.00000000"],["15511.58000000","0.05000000"],["15511.08000000","0.00000000"],["15459.10000000","0.03020000"],["15022.43000000","0.00000000"]],"a":[["15515.31000000","0.01650500"]]}}
2020-11-09T11:24:20.06642 btcusdt {"stream":"btcusdt@depth@100ms","data":{"e":"depthUpdate","E":1604921060060,"s":"BTCUSDT","U":6511119600,"u":6511119601,"b":[["15515.10000000","2.02672400"],["15498.55000000","0.01900000"]],"a":[]}}
2020-11-09T11:24:20.16736 btcusdt {"stream":"btcusdt@depth@100ms","data":{"e":"depthUpdate","E":1604921060160,"s":"BTCUSDT","U":6511119602,"u":6511119604,"b":[["15510.49000000","0.00000000"],["15476.22000000","0.00000000"]],"a":[["15553.79000000","0.00000000"]]}}
2020-11-09T11:24:20.26655 btcusdt {"stream":"btcusdt@depth@100ms","data":{"e":"depthUpdate","E":1604921060260,"s":"BTCUSDT","U":6511119605,"u":6511119614,"b":[["15515.00000000","1.08242900"],["15511.77000000","0.20000000"],["15511.59000000","0.10000000"],["15508.35000000","0.00000000"],["15507.91000000","1.25000000"],["15507.09000000","0.00000000"]],"a":[["15515.31000000","0.01850500"],["15526.00000000","0.00645500"],["15526.98000000","0.00000000"],["15544.74000000","0.00000000"]]}}
2020-11-09T11:24:20.36698 btcusdt {"stream":"btcusdt@depth@100ms","data":{"e":"depthUpdate","E":1604921060360,"s":"BTCUSDT","U":6511119615,"u":6511119616,"b":[["15515.30000000","6.48708700"]],"a":[["15527.82000000","0.13414500"]]}}
2020-11-09T11:24:20.46613 btcusdt {"stream":"btcusdt@depth@100ms","data":{"e":"depthUpdate","E":1604921060460,"s":"BTCUSDT","U":6511119617,"u":6511119645,"b":[["15515.70000000","1.22160000"],["15515.67000000","3.00000000"],["15515.66000000","0.02425400"],["15515.48000000","0.00690000"],["15515.33000000","0.07239200"],["15515.31000000","5.30000000"],["15515.30000000","2.51008200"],["15515.12000000","0.00690000"],["15514.95000000","0.00000000"],["15510.03000000","1.19900000"],["15509.40000000","0.00000000"],["15507.91000000","0.00000000"]],"a":[["15515.31000000","0.00000000"],["15515.50000000","0.00000000"],["15515.67000000","0.00000000"],["15515.71000000","0.01380000"],["15516.86000000","0.00000000"],["15517.02000000","0.00000000"],["15518.90000000","0.00000000"],["15519.41000000","0.01700000"],["15790.00000000","2.37476600"]]}}
2020-11-09T11:24:20.56677 btcusdt {"stream":"btcusdt@depth@100ms","data":{"e":"depthUpdate","E":1604921060560,"s":"BTCUSDT","U":6511119646,"u":6511119675,"b":[["15515.70000000","3.42168200"],["15515.67000000","3.05021200"],["15515.33000000","0.02218000"],["15515.31000000","5.70000000"],["15515.30000000","2.31000000"],["15515.13000000","2.02081100"],["15515.10000000","0.00000000"],["15511.91000000","0.05000000"],["15511.71000000","0.11427900"],["15511.58000000","0.00000000"],["15511.23000000","0.00000000"],["15509.79000000","0.00000000"],["15507.91000000","1.25000000"],["15506.58000000","0.00000000"],["15506.52000000","0.15450000"]],"a":[["15518.22000000","0.32100000"],["15519.28000000","0.00000000"],["15519.63000000","0.00000000"],["15519.98000000","0.05000000"],["15520.33000000","0.01000000"],["15521.43000000","0.00000000"],["15521.83000000","0.00000000"],["15522.13000000","0.01000000"],["15522.16000000","0.00000000"],["15522.53000000","0.01500000"],["15525.12000000","0.00000000"],["15544.73000000","0.01210000"]]}}
2020-11-09T11:24:20.67916 btcusdt {"stream":"btcusdt@depth@100ms","data":{"e":"depthUpdate","E":1604921060660,"s":"BTCUSDT","U":6511119676,"u":6511119681,"b":[["15515.70000000","3.82168200"],["15515.31000000","0.40000000"],["15515.11000000","0.00200000"],["15508.72000000","0.20000000"]],"a":[["15705.98000000","1.27339600"],["16375.66000000","0.00067900"]]}}
2020-11-09T11:24:20.76959 btcusdt {"stream":"btcusdt@depth@100ms","data":{"e":"depthUpdate","E":1604921060760,"s":"BTCUSDT","U":6511119682,"u":6511119686,"b":[["15515.70000000","7.70189400"],["15515.30000000","2.00000000"],["15445.88000000","0.24000000"]],"a":[["15522.08000000","1.01699200"]]}}
2020-11-09T11:24:20.87024 btcusdt {"stream":"btcusdt@depth@100ms","data":{"e":"depthUpdate","E":1604921060860,"s":"BTCUSDT","U":6511119687,"u":6511119687,"b":[["15437.72000000","0.00000000"]],"a":[]}}
2020-11-09T11:24:20.96866 btcusdt {"stream":"btcusdt@depth@100ms","data":{"e":"depthUpdate","E":1604921060960,"s":"BTCUSDT","U":6511119688,"u":6511119694,"b":[["15515.70000000","7.66830200"],["15515.24000000","0.00867000"],["15514.84000000","0.00000000"],["15511.93000000","0.05000000"],["15511.91000000","0.00000000"]],"a":[["15515.77000000","0.00000000"],["15516.17000000","0.00752500"]]}}
2020-11-09T11:24:21.06826 btcusdt {"stream":"btcusdt@depth@100ms","data":{"e":"depthUpdate","E":1604921061060,"s":"BTCUSDT","U":6511119695,"u":6511119702,"b":[["15515.69000000","0.05021200"],["15515.67000000","3.00000000"],["15514.93000000","0.01902000"],["15514.53000000","0.00000000"],["14643.20000000","0.00171000"]],"a":[["15516.08000000","0.00000000"],["15516.48000000","0.01333100"],["15705.98000000","0.00000000"]]}}
2020-11-09T11:24:21.16775 btcusdt {"stream":"btcusdt@depth@100ms","data":{"e":"depthUpdate","E":1604921061160,"s":"BTCUSDT","U":6511119703,"u":6511119706,"b":[["15515.70000000","7.67030200"],["15508.72000000","0.00000000"],["15476.92000000","0.25000000"]],"a":[["15554.49000000","0.25000000"]]}}
2020-11-09T11:24:21.27023 btcusdt {"stream":"btcusdt@depth@100ms","data":{"e":"depthUpdate","E":1604921061260,"s":"BTCUSDT","U":6511119707,"u":6511119707,"b":[["14643.20000000","0.02511000"]],"a":[]}}
2020-11-09T11:24:21.36781 btcusdt {"stream":"btcusdt@depth@100ms","data":{"e":"depthUpdate","E":1604921061360,"s":"BTCUSDT","U":6511119708,"u":6511119713,"b":[["15515.70000000","7.66512800"],["15515.67000000","0.00000000"],["15499.66000000","0.06725600"],["15497.84000000","0.00000000"],["15438.12000000","0.00647700"]],"a":[["15520.00000000","5.78264300"]]}}
2020-11-09T11:24:21.46703 btcusdt {"stream":"btcusdt@depth@100ms","data":{"e":"depthUpdate","E":1604921061460,"s":"BTCUSDT","U":6511119714,"u":6511119714,"b":[["15515.70000000","7.66390300"]],"a":[]}}
2020-11-09T11:24:21.67295 btcusdt {"stream":"btcusdt@depth@100ms","data":{"e":"depthUpdate","E":1604921061560,"s":"BTCUSDT","U":6511119715,"u":6511119715,"b":[["15515.70000000","3.71390300"]],"a":[]}}
2020-11-09T11:24:21.67735 btcusdt {"stream":"btcusdt@depth@100ms","data":{"e":"depthUpdate","E":1604921061660,"s":"BTCUSDT","U":6511119716,"u":6511119722,"b":[["15515.31000000","0.00000000"],["15508.72000000","0.20000000"],["10550.00000000","9.99446800"]],"a":[["15516.17000000","0.00000000"],["15516.48000000","0.00000000"],["15516.58000000","0.00873500"],["15516.97000000","0.01467100"]]}}
2020-11-09T11:24:21.76730 btcusdt {"stream":"btcusdt@depth@100ms","data":{"e":"depthUpdate","E":1604921061761,"s":"BTCUSDT","U":6511119723,"u":6511119746,"b":[["15515.70000000","0.00000000"],["15515.69000000","0.00000000"],["15515.66000000","0.00000000"],["15515.48000000","0.00000000"],["15515.33000000","0.00000000"],["15515.30000000","0.00000000"],["15515.24000000","0.00000000"],["15515.22000000","0.00000000"],["15515.13000000","6.62976300"],["15511.92000000","0.00000000"],["15511.71000000","0.00000000"],["15511.59000000","0.00000000"],["15511.10000000","0.11427900"],["15510.16000000","0.00000000"]],"a":[["15515.14000000","6.18673300"],["15515.43000000","0.00690000"],["15515.69000000","0.04918600"],["15515.70000000","0.00000000"],["15518.43000000","0.40000000"],["15518.58000000","0.00000000"],["15518.95000000","0.56879500"],["15519.37000000","1.67400200"]]}}
2020-11-09T11:24:21.87052 btcusdt {"stream":"btcusdt@depth@100ms","data":{"e":"depthUpdate","E":1604921061861,"s":"BTCUSDT","U":6511119747,"u":6511119777,"b":[["15515.13000000","3.00690000"],["15511.93000000","0.00000000"],["15511.77000000","0.00000000"],["15511.01000000","0.05000000"],["15511.00000000","0.00000000"],["15510.04000000","0.10000000"],["15509.61000000","0.15680600"],["15507.91000000","0.00000000"],["15507.50000000","1.25000000"],["15438.12000000","0.00000000"]],"a":[["15515.14000000","6.37861100"],["15516.96000000","0.20000000"],["15518.63000000","0.25850000"],["15519.41000000","0.06700000"],["15519.76000000","0.01690000"],["15519.98000000","0.00000000"],["15520.33000000","0.00000000"],["15521.56000000","0.01000000"],["15521.66000000","0.12890800"],["15521.96000000","0.01500000"],["15522.13000000","0.30600000"],["15522.53000000","0.00000000"],["15523.49000000","0.00000000"],["15525.10000000","0.00288000"],["15705.98000000","1.27339600"]]}}
2020-11-09T11:24:21.96760 btcusdt {"stream":"btcusdt@depth@100ms","data":{"e":"depthUpdate","E":1604921061961,"s":"BTCUSDT","U":6511119778,"u":6511119798,"b":[["15515.13000000","1.00690000"],["15514.93000000","0.00000000"],["15511.01000000","0.00000000"],["15510.99000000","0.25000000"],["15507.98000000","0.20000000"],["15507.50000000","0.00000000"],["15506.49000000","0.00000000"],["15505.50000000","0.00000000"],["15505.46000000","0.00000000"],["15503.71000000","0.00000000"],["15502.02000000","1.31433800"],["15497.25000000","0.23540500"],["15494.82000000","0.00000000"]],"a":[["15515.14000000","2.88673300"],["15515.90000000","0.00200000"],["15518.42000000","0.12892500"],["15518.64000000","0.80900000"],["15519.09000000","0.12892900"],["15526.77000000","0.00000000"]]}}
2020-11-09T11:24:22.07187 btcusdt {"stream":"btcusdt@depth@100ms","data":{"e":"depthUpdate","E":1604921062061,"s":"BTCUSDT","U":6511119799,"u":6511119814,"b":[["15514.36000000","0.01815000"],["15511.10000000","0.00000000"],["15510.16000000","0.16000000"],["15506.92000000","0.00000000"],["15505.57000000","0.12890800"],["15504.80000000","0.00000000"],["15502.38000000","0.50416900"]],"a":[["15516.59000000","0.32100000"],["15516.95000000","0.10000000"],["15516.97000000","0.00000000"],["15517.03000000","0.01702000"],["15518.22000000","0.00000000"],["15518.57000000","0.00000000"],["15524.37000000","1.00833800"]]}}
2020-11-09T11:24:22.22789 btcusdt {"stream":"btcusdt@depth@100ms","data":{"e":"depthUpdate","E":1604921062161,"s":"BTCUSDT","U":6511119815,"u":6511119828,"b":[["15509.61000000","0.00000000"],["15508.73000000","0.15680600"],["15506.69000000","1.25000000"],["15506.52000000","0.00000000"],["15502.14000000","0.00000000"],["15501.32000000","0.00000000"],["15497.93000000","1.00000000"],["15150.00000000","38.60694800"]],"a":[["15515.14000000","2.88873300"],["15515.90000000","0.00400000"],["15522.84000000","1.50000000"],["15525.39000000","0.00000000"],["15534.52000000","0.00000000"],["15705.98000000","0.00000000"]]}}
2020-11-09T11:24:22.26903 btcusdt {"stream":"btcusdt@depth@100ms","data":{"e":"depthUpdate","E":1604921062261,"s":"BTCUSDT","U":6511119829,"u":6511119837,"b":[["15510.05000000","0.11427900"],["15502.73000000","0.00000000"],["15497.10000000","1.50000000"],["15474.12000000","0.00000000"]],"a":[["15517.26000000","0.50000100"],["15517.27000000","1.00000000"],["15519.48000000","0.09621100"],["15527.54000000","0.00000000"],["15560.99000000","0.00000000"]]}}
2020-11-09T11:24:22.36743 btcusdt {"stream":"btcusdt@depth@100ms","data":{"e":"depthUpdate","E":1604921062361,"s":"BTCUSDT","U":6511119838,"u":6511119845,"b":[["15508.73000000","0.00000000"],["15506.69000000","0.00000000"],["15504.83000000","0.00000000"],["15497.10000000","0.00000000"],["15437.55000000","0.00647700"]],"a":[["15519.21000000","0.20000000"],["15525.55000000","0.00000000"]]}}
2020-11-09T11:24:22.46844 btcusdt {"stream":"btcusdt@depth@100ms","data":{"e":"depthUpdate","E":1604921062461,"s":"BTCUSDT","U":6511119846,"u":6511119857,"b":[["15515.13000000","0.00460400"],["15504.82000000","0.00000000"],["15504.79000000","1.25000000"]],"a":[["15515.14000000","13.20641800"],["15519.37000000","0.00000000"],["15520.04000000","1.25000000"],["15628.40000000","0.00000000"]]}}
2020-11-09T11:24:22.57036 btcusdt {"stream":"btcusdt@depth@100ms","data":{"e":"depthUpdate","E":1604921062561,"s":"BTCUSDT","U":6511119858,"u":6511119922,"b":[["15515.13000000","0.00000000"],["15515.12000000","0.00000000"],["15515.11000000","0.00000000"],["15515.07000000","0.00000000"],["15515.01000000","0.00000000"],["15515.00000000","0.81441800"],["15514.67000000","0.00687300"],["15510.05000000","0.00000000"],["15510.04000000","0.00000000"],["15508.72000000","0.00000000"],["15507.99000000","0.10000000"],["15505.82000000","0.00000000"],["15504.87000000","0.00000000"],["15497.04000000","1.50000000"]],"a":[["15515.01000000","8.66594500"],["15515.02000000","0.00000000"],["15515.08000000","0.00690000"],["15515.11000000","0.40000000"],["15515.12000000","0.18765100"],["15515.13000000","0.27985100"],["15515.14000000","2.26984300"],["15515.29000000","0.53335400"],["15515.68000000","0.20000000"],["15515.69000000","0.00000000"],["15516.58000000","0.00000000"],["15516.67000000","0.00997200"],["15516.96000000","0.00000000"],["15517.03000000","0.00000000"],["15517.15000000","0.01304100"],["15517.26000000","0.00000000"],["15517.83000000","0.25759400"],["15518.43000000","0.00000000"],["15518.44000000","0.00000000"],["15518.63000000","0.00000000"],["15518.64000000","0.30900000"],["15518.95000000","0.00000000"],["15519.22000000","0.00000000"],["15520.05000000","0.00000000"],["15526.79000000","0.00000000"],["15531.91000000","0.15000000"]]}}
2020-11-09T11:24:22.68421 btcusdt {"stream":"btcusdt@depth@100ms","data":{"e":"depthUpdate","E":1604921062661,"s":"BTCUSDT","U":6511119923,"u":6511119945,"b":[["15515.00000000","0.82131800"],["15510.99000000","0.05000000"],["15509.49000000","0.11427900"],["15509.29000000","0.00000000"],["15507.99000000","0.00000000"],["15506.58000000","0.30000000"],["15504.80000000","0.20000000"],["15504.79000000","0.00000000"],["15503.52000000","1.25000000"],["15445.88000000","0.00000000"]],"a":[["15515.01000000","17.48061000"],["15515.11000000","0.00000000"],["15515.12000000","0.00000000"],["15515.13000000","0.39862300"],["15515.14000000","2.03074700"],["15515.29000000","0.00000000"]]}}
2020-11-09T11:24:22.76747 btcusdt {"stream":"btcusdt@depth@100ms","data":{"e":"depthUpdate","E":1604921062761,"s":"BTCUSDT","U":6511119946,"u":6511119955,"b":[["15515.00000000","0.78528300"],["15503.21000000","0.00000000"]],"a":[["15515.01000000","7.68062100"],["15518.41000000","0.00316200"],["15520.04000000","0.00000000"],["15522.58000000","1.25000000"],["15615.00000000","7.99002100"]]}}
2020-11-09T11:24:22.86898 btcusdt {"stream":"btcusdt@depth@100ms","data":{"e":"depthUpdate","E":1604921062861,"s":"BTCUSDT","U":6511119956,"u":6511119960,"b":[["15507.99000000","0.00000000"],["15506.58000000","0.45680600"],["15437.55000000","0.00000000"]],"a":[["15526.85000000","0.24000000"]]}}
2020-11-09T11:24:22.96885 btcusdt {"stream":"btcusdt@depth@100ms","data":{"e":"depthUpdate","E":1604921062961,"s":"BTCUSDT","U":6511119961,"u":6511119968,"b":[["15510.99000000","0.00000000"],["15510.17000000","0.05000000"],["15509.50000000","0.10000000"],["15506.58000000","0.35680600"]],"a":[["15516.67000000","0.00000000"],["15517.15000000","0.00000000"],["15570.00000000","48.53853300"],["15705.98000000","1.27339600"]]}}
2020-11-09T11:24:23.06951 btcusdt {"stream":"btcusdt@depth@100ms","data":{"e":"depthUpdate","E":1604921063061,"s":"BTCUSDT","U":6511119969,"u":6511119969,"b":[],"a":[["15515.60000000","0.00640900"]]}}
2020-11-09T11:24:23.16740 btcusdt {"stream":"btcusdt@depth@100ms","data":{"e":"depthUpdate","E":1604921063161,"s":"BTCUSDT","U":6511119970,"u":6511119974,"b":[["15423.00000000","0.00000000"]],"a":[["15520.04000000","0.00000000"],["15521.58000000","1.25000000"],["15522.58000000","0.00000000"]]}}
2020-11-09T11:24:23.26902 btcusdt {"stream":"btcusdt@depth@100ms","data":{"e":"depthUpdate","E":1604921063261,"s":"BTCUSDT","U":6511119975,"u":6511119979,"b":[["15515.00000000","0.78728300"],["15507.99000000","0.15680600"],["15506.58000000","0.20000000"]],"a":[["15515.01000000","5.63278200"],["15515.13000000","0.20362300"]]}}
2020-11-09T11:24:23.37039 btcusdt {"stream":"btcusdt@depth@100ms","data":{"e":"depthUpdate","E":1604921063362,"s":"BTCUSDT","U":6511119980,"u":6511119983,"b":[["15514.36000000","0.00000000"],["15468.84000000","0.00258500"],["15437.42000000","0.00647700"]],"a":[["15705.98000000","0.00000000"]]}}
2020-11-09T11:24:23.46984 btcusdt {"stream":"btcusdt@depth@100ms","data":{"e":"depthUpdate","E":1604921063462,"s":"BTCUSDT","U":6511119984,"u":6511119989,"b":[["15514.67000000","0.00000000"],["15510.48000000","0.20000000"],["15506.58000000","0.00000000"]],"a":[["15515.01000000","5.63118200"],["15515.60000000","0.00000000"],["15519.09000000","0.00000000"]]}}
2020-11-09T11:24:23.56812 btcusdt {"stream":"btcusdt@depth@100ms","data":{"e":"depthUpdate","E":1604921063562,"s":"BTCUSDT","U":6511119990,"u":6511119995,"b":[["15515.00000000","0.66925500"],["15514.23000000","0.01990600"],["15507.99000000","0.00000000"]],"a":[["15515.01000000","10.93118200"],["15515.30000000","0.15821600"],["15515.78000000","0.01902100"]]}}
2020-11-09T11:24:23.68218 btcusdt {"stream":"btcusdt@depth@100ms","data":{"e":"depthUpdate","E":1604921063662,"s":"BTCUSDT","U":6511119996,"u":6511120000,"b":[["15515.00000000","2.10561300"],["15509.98000000","0.11427900"],["15509.49000000","0.00000000"]],"a":[["15515.01000000","10.87099100"],["15518.41000000","0.00000000"]]}}
2020-11-09T11:24:23.76836 btcusdt {"stream":"btcusdt@depth@100ms","data":{"e":"depthUpdate","E":1604921063762,"s":"BTCUSDT","U":6511120001,"u":6511120005,"b":[["15506.13000000","0.40929000"],["15441.35000000","0.24000000"],["15420.00000000","0.97585000"]],"a":[["15515.01000000","10.99899100"],["15515.84000000","0.43918700"]]}}
2020-11-09T11:24:23.86814 btcusdt {"stream":"btcusdt@depth@100ms","data":{"e":"depthUpdate","E":1604921063862,"s":"BTCUSDT","U":6511120006,"u":6511120011,"b":[["15509.29000000","0.10943500"],["15507.99000000","0.15680600"]],"a":[["15515.01000000","3.69899100"],["15515.71000000","0.06066700"],["15519.21000000","0.00000000"]]}}
2020-11-09T11:24:23.96783 btcusdt {"stream":"btcusdt@depth@100ms","data":{"e":"depthUpdate","E":1604921063962,"s":"BTCUSDT","U":6511120012,"u":6511120024,"b":[["15515.00000000","4.42039500"],["15474.00000000","0.00000000"],["15399.00000000","0.37683000"]],"a":[["15515.01000000","3.25711300"],["15515.14000000","0.03074700"],["15515.68000000","0.00000000"],["15516.94000000","0.20000000"],["15517.26000000","0.50000100"],["15518.95000000","0.56879600"],["15519.37000000","1.74710500"],["15550.30000000","0.38000000"]]}}
2020-11-09T11:24:24.06839 btcusdt {"stream":"btcusdt@depth@100ms","data":{"e":"depthUpdate","E":1604921064062,"s":"BTCUSDT","U":6511120025,"u":6511120035,"b":[["15509.98000000","0.00000000"],["15506.69000000","1.25000000"],["15503.52000000","0.00000000"],["15441.35000000","0.00000000"]],"a":[["15515.01000000","1.20927100"],["15515.14000000","0.02874700"],["15515.84000000","0.00000000"],["15521.58000000","0.00000000"],["15524.55000000","1.25000000"]]}}
2020-11-09T11:24:24.16882 btcusdt {"stream":"btcusdt@depth@100ms","data":{"e":"depthUpdate","E":1604921064162,"s":"BTCUSDT","U":6511120036,"u":6511120057,"b":[["15515.00000000","4.41967000"],["15510.57000000","0.11427900"],["15508.90000000","1.25000000"],["15506.69000000","0.00000000"],["15502.49000000","0.02500000"],["15498.55000000","0.00000000"],["15473.87000000","0.03100000"],["15473.00000000","2.00000000"],["15440.21000000","0.24000000"]],"a":[["15515.01000000","1.07427100"],["15516.95000000","0.00000000"],["15518.41000000","0.10000000"],["15518.42000000","0.00000000"],["15524.55000000","0.00000000"],["15525.04000000","1.25000000"],["15525.51000000","0.00000000"],["15527.30000000","0.02500000"],["15560.74000000","0.03100000"],["15705.98000000","1.27339600"]]}}
2020-11-09T11:24:24.26837 btcusdt {"stream":"btcusdt@depth@100ms","data":{"e":"depthUpdate","E":1604921064262,"s":"BTCUSDT","U":6511120058,"u":6511120061,"b":[["15510.99000000","0.10000000"],["15509.50000000","0.00000000"],["15440.21000000","0.00000000"]],"a":[["15526.85000000","0.00000000"]]}}
2020-11-09T11:24:24.37115 btcusdt {"stream":"btcusdt@depth@100ms","data":{"e":"depthUpdate","E":1604921064362,"s":"BTCUSDT","U":6511120062,"u":6511120070,"b":[["15511.91000000","0.15680600"],["15507.99000000","0.00000000"],["15497.84000000","0.01900000"],["15446.63000000","0.24000000"]],"a":[["15516.94000000","0.00000000"],["15518.40000000","0.20000000"],["15518.41000000","0.00000000"],["15519.36000000","0.10000000"],["15519.48000000","0.00000000"]]}}
2020-11-09T11:24:24.47237 btcusdt {"stream":"btcusdt@depth@100ms","data":{"e":"depthUpdate","E":1604921064462,"s":"BTCUSDT","U":6511120071,"u":6511120073,"b":[["15514.23000000","0.00000000"],["15511.85000000","0.01866300"],["15399.00000000","0.48510300"]],"a":[]}}
2020-11-09T11:24:24.57022 btcusdt {"stream":"btcusdt@depth@100ms","data":{"e":"depthUpdate","E":1604921064562,"s":"BTCUSDT","U":6511120074,"u":6511120078,"b":[["15511.92000000","0.20000000"],["15511.70000000","0.01042200"],["15510.48000000","0.00000000"]],"a":[["15515.47000000","0.00722300"],["15705.98000000","0.00000000"]]}}
2020-11-09T11:24:24.67685 btcusdt {"stream":"btcusdt@depth@100ms","data":{"e":"depthUpdate","E":1604921064662,"s":"BTCUSDT","U":6511120079,"u":6511120090,"b":[["15515.00000000","8.88512600"],["15512.35000000","0.50000000"],["15511.07000000","0.12117900"],["15510.57000000","0.00000000"]],"a":[["15515.01000000","0.62800000"],["15518.39000000","0.35000100"],["15518.47000000","0.50000000"],["15518.64000000","0.00000000"]]}}
2020-11-09T11:24:24.76935 btcusdt {"stream":"btcusdt@depth@100ms","data":{"e":"depthUpdate","E":1604921064762,"s":"BTCUSDT","U":6511120091,"u":6511120099,"b":[["15515.00000000","5.48512600"],["15508.25000000","0.12890800"],["15505.76000000","0.29100000"],["15505.57000000","0.00000000"],["15400.00000000","4.38417000"]],"a":[["15515.47000000","0.00754100"],["15524.81000000","0.27075300"],["15530.71000000","0.24000000"]]}}
2020-11-09T11:24:24.86893 btcusdt {"stream":"btcusdt@depth@100ms","data":{"e":"depthUpdate","E":1604921064862,"s":"BTCUSDT","U":6511120100,"u":6511120111,"b":[["15511.76000000","0.00000000"],["15510.98000000","0.00000000"],["15510.21000000","0.00000000"],["15509.13000000","0.24000000"],["15508.11000000","0.26000000"],["15504.80000000","0.00000000"],["15503.42000000","0.50421800"],["15502.38000000","0.00000000"]],"a":[["15515.47000000","0.00944300"],["15517.25000000","0.20000000"],["15518.40000000","0.00000000"]]}}
2020-11-09T11:24:24.96960 btcusdt {"stream":"btcusdt@depth@100ms","data":{"e":"depthUpdate","E":1604921064962,"s":"BTCUSDT","U":6511120112,"u":6511120113,"b":[],"a":[["15515.47000000","0.00967900"]]}}
2020-11-09T11:24:25.07015 btcusdt {"stream":"btcusdt@depth@100ms","data":{"e":"depthUpdate","E":1604921065063,"s":"BTCUSDT","U":6511120114,"u":6511120117,"b":[],"a":[["15515.47000000","0.00669800"],["15516.77000000","0.24242500"],["15516.78000000","0.47794700"]]}}
2020-11-09T11:24:25.16914 btcusdt {"stream":"btcusdt@depth@100ms","data":{"e":"depthUpdate","E":1604921065163,"s":"BTCUSDT","U":6511120118,"u":6511120128,"b":[["15515.00000000","5.48302400"],["15508.25000000","0.00000000"],["15507.40000000","0.12890800"],["15506.58000000","0.20000000"],["15505.61000000","0.00000000"],["15504.40000000","0.00309000"]],"a":[["15515.01000000","5.92800000"],["15515.47000000","0.00988400"],["15570.00000000","48.43026000"]]}}
2020-11-09T11:24:25.26924 btcusdt {"stream":"btcusdt@depth@100ms","data":{"e":"depthUpdate","E":1604921065263,"s":"BTCUSDT","U":6511120129,"u":6511120140,"b":[["15515.00000000","5.10391000"],["15514.98000000","0.00312400"],["15514.96000000","0.00312400"],["15507.40000000","0.00000000"],["15505.61000000","0.12890800"]],"a":[["15515.01000000","6.23773800"],["15515.47000000","0.00848500"],["15519.37000000","0.00000000"]]}}
2020-11-09T11:24:25.37009 btcusdt {"stream":"btcusdt@depth@100ms","data":{"e":"depthUpdate","E":1604921065363,"s":"BTCUSDT","U":6511120141,"u":6511120144,"b":[["15501.24000000","0.10083200"]],"a":[["15515.01000000","0.87513200"],["15519.35000000","1.74900000"]]}}
2020-11-09T11:24:25.46990 btcusdt {"stream":"btcusdt@depth@100ms","data":{"e":"depthUpdate","E":1604921065463,"s":"BTCUSDT","U":6511120145,"u":6511120152,"b":[["15515.00000000","5.70369700"],["14927.42000000","0.00000000"]],"a":[["15515.01000000","0.56539400"],["15515.47000000","0.00000000"],["15521.76000000","0.00000000"],["15525.76000000","0.20000000"],["15705.98000000","1.27339600"]]}}
2020-11-09T11:24:25.57049 btcusdt {"stream":"btcusdt@depth@100ms","data":{"e":"depthUpdate","E":1604921065563,"s":"BTCUSDT","U":6511120153,"u":6511120157,"b":[["15497.84000000","0.00000000"]],"a":[["15515.47000000","0.00666700"],["15519.36000000","0.00000000"]]}}
2020-11-09T11:24:25.67196 btcusdt {"stream":"btcusdt@depth@100ms","data":{"e":"depthUpdate","E":1604921065663,"s":"BTCUSDT","U":6511120158,"u":6511120167,"b":[["15515.00000000","11.00369700"],["15502.35000000","0.00000000"],["15501.24000000","0.00000000"],["15497.96000000","0.01900000"]],"a":[["15515.01000000","0.50533100"],["15515.13000000","0.19737100"],["15515.47000000","0.00769900"],["15517.60000000","0.10000000"],["15521.76000000","0.20000000"]]}}
2020-11-09T11:24:25.76953 btcusdt {"stream":"btcusdt@depth@100ms","data":{"e":"depthUpdate","E":1604921065763,"s":"BTCUSDT","U":6511120168,"u":6511120174,"b":[["15515.00000000","5.59337700"]],"a":[["15515.01000000","5.80533100"],["15515.47000000","0.00934100"],["15525.76000000","0.00000000"],["15705.98000000","0.00000000"]]}}
2020-11-09T11:24:25.86905 btcusdt {"stream":"btcusdt@depth@100ms","data":{"e":"depthUpdate","E":1604921065863,"s":"BTCUSDT","U":6511120175,"u":6511120187,"b":[["15515.00000000","3.27927900"],["15511.07000000","0.00690000"],["15510.99000000","0.00000000"],["15510.53000000","0.11427900"],["15509.61000000","0.10000000"],["15503.55000000","0.03361100"]],"a":[["15515.01000000","0.80835100"],["15515.47000000","0.00912400"],["15573.00000000","0.17227700"]]}}
2020-11-09T11:24:25.97078 btcusdt {"stream":"btcusdt@depth@100ms","data":{"e":"depthUpdate","E":1604921065963,"s":"BTCUSDT","U":6511120188,"u":6511120202,"b":[["15515.00000000","5.27927900"],["15511.92000000","0.00000000"],["15511.91000000","0.00000000"],["15510.54000000","0.20000000"],["15510.21000000","0.05000000"],["15510.18000000","0.15680600"],["15510.17000000","0.00000000"],["15509.61000000","0.00000000"],["15508.12000000","0.10000000"]],"a":[["15515.01000000","0.50533100"],["15515.47000000","0.00852200"],["15518.77000000","0.12892200"]]}}
2020-11-09T11:24:26.06976 btcusdt {"stream":"btcusdt@depth@100ms","data":{"e":"depthUpdate","E":1604921066063,"s":"BTCUSDT","U":6511120203,"u":6511120207,"b":[["15505.00000000","1.44071900"]],"a":[["15515.47000000","0.00913900"]]}}
2020-11-09T11:24:26.16977 btcusdt {"stream":"btcusdt@depth@100ms","data":{"e":"depthUpdate","E":1604921066163,"s":"BTCUSDT","U":6511120208,"u":6511120217,"b":[["15510.18000000","0.00000000"],["15502.18000000","0.10083300"],["15476.92000000","0.00000000"],["15241.97000000","0.00000000"],["6239.61000000","0.00436000"]],"a":[["15515.70000000","0.20000000"],["15516.58000000","0.10000000"],["15517.25000000","0.00000000"],["15517.60000000","0.00000000"],["15554.49000000","0.00000000"]]}}
2020-11-09T11:24:26.27002 btcusdt {"stream":"btcusdt@depth@100ms","data":{"e":"depthUpdate","E":1604921066263,"s":"BTCUSDT","U":6511120218,"u":6511120220,"b":[["15509.30000000","0.15680600"],["15399.00000000","0.37683000"]],"a":[["15670.48000000","0.00000000"]]}}
2020-11-09T11:24:26.37053 btcusdt {"stream":"btcusdt@depth@100ms","data":{"e":"depthUpdate","E":1604921066363,"s":"BTCUSDT","U":6511120221,"u":6511120222,"b":[["15515.00000000","8.62927900"]],"a":[["15515.01000000","0.48183000"]]}}
2020-11-09T11:24:26.46959 btcusdt {"stream":"btcusdt@depth@100ms","data":{"e":"depthUpdate","E":1604921066463,"s":"BTCUSDT","U":6511120223,"u":6511120227,"b":[["15515.00000000","5.27927900"],["15420.00000000","1.08412300"]],"a":[["15515.47000000","0.00620200"],["15518.77000000","0.00000000"]]}}
2020-11-09T11:24:26.57024 btcusdt {"stream":"btcusdt@depth@100ms","data":{"e":"depthUpdate","E":1604921066563,"s":"BTCUSDT","U":6511120228,"u":6511120237,"b":[["15508.90000000","0.00000000"],["15506.40000000","1.25000000"]],"a":[["15515.01000000","0.42175800"],["15515.47000000","0.00825600"],["15515.69000000","0.49509500"],["15515.70000000","0.91050000"],["15573.00000000","0.54910700"]]}}
2020-11-09T11:24:26.68185 btcusdt {"stream":"btcusdt@depth@100ms","data":{"e":"depthUpdate","E":1604921066663,"s":"BTCUSDT","U":6511120238,"u":6511120242,"b":[["15377.00000000","0.22209600"]],"a":[["15515.47000000","0.00000000"],["15615.00000000","8.09829400"]]}}
2020-11-09T11:24:26.76955 btcusdt {"stream":"btcusdt@depth@100ms","data":{"e":"depthUpdate","E":1604921066763,"s":"BTCUSDT","U":6511120243,"u":6511120255,"b":[["15515.00000000","5.02122300"],["15509.30000000","0.00000000"],["15508.72000000","0.25680600"],["15508.12000000","0.00000000"]],"a":[["15515.01000000","5.72175800"],["15515.47000000","0.00771700"],["15515.69000000","0.00000000"],["15516.77000000","0.00000000"],["15519.35000000","0.00000000"],["15519.61000000","0.20000000"]]}}
2020-11-09T11:24:26.87126 btcusdt {"stream":"btcusdt@depth@100ms","data":{"e":"depthUpdate","E":1604921066864,"s":"BTCUSDT","U":6511120256,"u":6511120277,"b":[["15515.00000000","2.02122300"],["15510.53000000","0.00000000"],["15510.03000000","1.31327900"],["15508.72000000","0.25680600"],["15506.58000000","0.00000000"],["15506.40000000","0.00000000"],["15506.13000000","0.00000000"],["15504.79000000","0.00000000"],["15503.29000000","1.25000000"],["15446.63000000","0.00000000"]],"a":[["15515.01000000","8.01673100"],["15515.47000000","0.00878500"],["15517.26000000","0.00000000"],["15518.39000000","0.00000000"],["15523.26000000","1.40000000"],["15525.04000000","0.00000000"],["15530.71000000","0.00000000"]]}}
2020-11-09T11:24:26.97031 btcusdt {"stream":"btcusdt@depth@100ms","data":{"e":"depthUpdate","E":1604921066964,"s":"BTCUSDT","U":6511120278,"u":6511120286,"b":[["15515.00000000","1.89653500"],["15510.21000000","0.00000000"],["15510.17000000","0.05000000"],["15508.72000000","0.10000000"]],"a":[["15515.47000000","0.00739200"],["15517.26000000","0.12893700"],["15705.98000000","1.27339600"]]}}
2020-11-09T11:24:27.07183 btcusdt {"stream":"btcusdt@depth@100ms","data":{"e":"depthUpdate","E":1604921067064,"s":"BTCUSDT","U":6511120287,"u":6511120293,"b":[["15514.96000000","0.00000000"],["15508.12000000","0.15680600"],["15506.70000000","1.25000000"],["15503.55000000","0.00000000"],["15503.29000000","0.00000000"],["15502.18000000","0.00000000"],["13989.53000000","0.00000000"]],"a":[]}}
2020-11-09T11:24:27.17114 btcusdt {"stream":"btcusdt@depth@100ms","data":{"e":"depthUpdate","E":1604921067164,"s":"BTCUSDT","U":6511120294,"u":6511120296,"b":[],"a":[["15515.01000000","8.01360700"],["15515.47000000","0.00000000"],["15553.79000000","0.25000000"]]}}
2020-11-09T11:24:27.27059 btcusdt {"stream":"btcusdt@depth@100ms","data":{"e":"depthUpdate","E":1604921067264,"s":"BTCUSDT","U":6511120297,"u":6511120304,"b":[["15515.00000000","1.84573800"],["15505.77000000","0.20000000"],["15504.26000000","0.03361200"]],"a":[["15515.07000000","0.14000000"],["15515.29000000","0.13500000"],["15515.47000000","0.00619900"],["15518.95000000","0.00000000"],["15670.16000000","0.00100000"]]}}
2020-11-09T11:24:27.37084 btcusdt {"stream":"btcusdt@depth@100ms","data":{"e":"depthUpdate","E":1604921067364,"s":"BTCUSDT","U":6511120305,"u":6511120308,"b":[["15476.22000000","0.25000000"]],"a":[["15515.01000000","7.98401300"],["15515.47000000","0.00792100"]]}}
2020-11-09T11:24:27.47057 btcusdt {"stream":"btcusdt@depth@100ms","data":{"e":"depthUpdate","E":1604921067464,"s":"BTCUSDT","U":6511120309,"u":6511120318,"b":[["15506.70000000","0.00000000"],["15502.75000000","0.10083600"],["15241.97000000","0.00590400"]],"a":[["15515.01000000","8.14901300"],["15515.29000000","0.00000000"],["15515.47000000","0.00790500"],["15705.98000000","0.00000000"]]}}
2020-11-09T11:24:27.57032 btcusdt {"stream":"btcusdt@depth@100ms","data":{"e":"depthUpdate","E":1604921067564,"s":"BTCUSDT","U":6511120319,"u":6511120326,"b":[["15513.60000000","0.00497600"],["15505.99000000","1.25000000"]],"a":[["15515.01000000","6.08899600"],["15515.47000000","0.00990800"]]}}
2020-11-09T11:24:27.68004 btcusdt {"stream":"btcusdt@depth@100ms","data":{"e":"depthUpdate","E":1604921067664,"s":"BTCUSDT","U":6511120327,"u":6511120330,"b":[["15515.00000000","3.84573800"],["15508.73000000","0.15680600"],["15508.12000000","0.00000000"]],"a":[["15519.61000000","0.00000000"]]}}
2020-11-09T11:24:27.77168 btcusdt {"stream":"btcusdt@depth@100ms","data":{"e":"depthUpdate","E":1604921067764,"s":"BTCUSDT","U":6511120331,"u":6511120333,"b":[["15497.96000000","0.00000000"],["15440.70000000","0.24000000"]],"a":[["15526.38000000","0.24000000"]]}}
2020-11-09T11:24:27.87115 btcusdt {"stream":"btcusdt@depth@100ms","data":{"e":"depthUpdate","E":1604921067864,"s":"BTCUSDT","U":6511120334,"u":6511120337,"b":[["15505.51000000","0.40325700"],["12412.00000000","1.16402800"]],"a":[["15515.70000000","0.71050000"],["15516.77000000","0.20000000"]]}}
2020-11-09T11:24:27.97075 btcusdt {"stream":"btcusdt@depth@100ms","data":{"e":"depthUpdate","E":1604921067964,"s":"BTCUSDT","U":6511120338,"u":6511120344,"b":[["15497.81000000","0.01900000"],["15399.00000000","0.00000000"],["12930.02000000","0.00000000"]],"a":[["15515.47000000","0.00807600"]]}}
2020-11-09T11:24:28.07097 btcusdt {"stream":"btcusdt@depth@100ms","data":{"e":"depthUpdate","E":1604921068064,"s":"BTCUSDT","U":6511120345,"u":6511120351,"b":[["15510.17000000","0.15000000"],["15508.72000000","0.00000000"],["15503.73000000","0.00000000"]],"a":[["15515.47000000","0.00000000"],["15550.00000000","38.69043900"]]}}
2020-11-09T11:24:28.21457 btcusdt {"stream":"btcusdt@depth@100ms","data":{"e":"depthUpdate","E":1604921068164,"s":"BTCUSDT","U":6511120352,"u":6511120362,"b":[["15510.16000000","0.00000000"],["15502.17000000","0.13414500"],["15440.70000000","0.00000000"],["15423.00000000","0.37683000"]],"a":[["15515.47000000","0.00995200"],["15524.80000000","0.22875300"],["15524.81000000","0.00000000"],["15526.38000000","0.00000000"],["15530.24000000","0.24000000"],["15532.63000000","0.00000000"],["15705.98000000","1.27339600"]]}}
2020-11-09T11:24:28.27107 btcusdt {"stream":"btcusdt@depth@100ms","data":{"e":"depthUpdate","E":1604921068264,"s":"BTCUSDT","U":6511120363,"u":6511120366,"b":[["15444.94000000","0.24000000"]],"a":[["15515.47000000","0.00809600"],["15529.49000000","0.98360300"]]}}
2020-11-09T11:24:28.37303 btcusdt {"stream":"btcusdt@depth@100ms","data":{"e":"depthUpdate","E":1604921068364,"s":"BTCUSDT","U":6511120367,"u":6511120373,"b":[["15507.97000000","0.00000000"],["15444.94000000","0.00000000"]],"a":[["15515.47000000","0.00982900"],["15523.05000000","0.13416500"],["15529.59000000","0.00000000"],["15530.24000000","0.00000000"]]}}
2020-11-09T11:24:28.47114 btcusdt {"stream":"btcusdt@depth@100ms","data":{"e":"depthUpdate","E":1604921068464,"s":"BTCUSDT","U":6511120374,"u":6511120377,"b":[["15509.58000000","0.15680600"],["15508.73000000","0.00000000"],["15441.09000000","0.24000000"]],"a":[["15526.38000000","0.24000000"]]}}
2020-11-09T11:24:28.57259 btcusdt {"stream":"btcusdt@depth@100ms","data":{"e":"depthUpdate","E":1604921068565,"s":"BTCUSDT","U":6511120378,"u":6511120387,"b":[["15510.17000000","0.05000000"],["15509.58000000","0.00000000"],["15508.12000000","0.25680600"]],"a":[["15515.01000000","6.02865300"],["15515.47000000","0.00771900"],["15705.98000000","0.00000000"]]}}
2020-11-09T11:24:28.68057 btcusdt {"stream":"btcusdt@depth@100ms","data":{"e":"depthUpdate","E":1604921068665,"s":"BTCUSDT","U":6511120388,"u":6511120395,"b":[],"a":[["15515.01000000","0.72865300"],["15515.07000000","0.00000000"],["15515.69000000","0.39509600"],["15516.74000000","0.34587300"],["15517.25000000","0.56446900"],["15518.46000000","0.29000200"],["15518.95000000","0.56879400"],["15519.37000000","1.69900100"]]}}
2020-11-09T11:24:28.77147 btcusdt {"stream":"btcusdt@depth@100ms","data":{"e":"depthUpdate","E":1604921068765,"s":"BTCUSDT","U":6511120396,"u":6511120399,"b":[["15515.00000000","4.13363400"]],"a":[["15515.01000000","0.43368000"],["15515.47000000","0.00815000"]]}}
2020-11-09T11:24:28.87156 btcusdt {"stream":"btcusdt@depth@100ms","data":{"e":"depthUpdate","E":1604921068865,"s":"BTCUSDT","U":6511120400,"u":6511120408,"b":[["15515.00000000","4.13163400"],["15509.61000000","0.10000000"],["15508.12000000","0.15680600"]],"a":[["15515.01000000","0.43249500"],["15515.47000000","0.00949100"],["15529.73000000","0.00000000"]]}}
2020-11-09T11:24:28.97217 btcusdt {"stream":"btcusdt@depth@100ms","data":{"e":"depthUpdate","E":1604921068965,"s":"BTCUSDT","U":6511120409,"u":6511120413,"b":[["15510.17000000","0.00000000"],["15510.16000000","0.05000000"]],"a":[["15515.47000000","0.00893400"],["15527.19000000","0.06725900"]]}}
2020-11-09T11:24:29.07207 btcusdt {"stream":"btcusdt@depth@100ms","data":{"e":"depthUpdate","E":1604921069065,"s":"BTCUSDT","U":6511120414,"u":6511120415,"b":[["15514.98000000","0.00000000"]],"a":[["15615.00000000","7.99002100"]]}}
2020-11-09T11:24:29.17256 btcusdt {"stream":"btcusdt@depth@100ms","data":{"e":"depthUpdate","E":1604921069165,"s":"BTCUSDT","U":6511120416,"u":6511120420,"b":[["15500.00000000","14.25874600"]],"a":[["15515.01000000","0.42293300"],["15529.49000000","0.00000000"],["15530.82000000","0.00000000"]]}}
2020-11-09T11:24:29.27142 btcusdt {"stream":"btcusdt@depth@100ms","data":{"e":"depthUpdate","E":1604921069265,"s":"BTCUSDT","U":6511120421,"u":6511120427,"b":[["15515.00000000","5.13163400"]],"a":[["15515.01000000","0.25793300"],["15515.47000000","0.00877300"],["15528.28000000","0.23540500"],["15529.49000000","0.98072600"],["15570.00000000","48.53853300"]]}}
2020-11-09T11:24:29.37274 btcusdt {"stream":"btcusdt@depth@100ms","data":{"e":"depthUpdate","E":1604921069365,"s":"BTCUSDT","U":6511120428,"u":6511120430,"b":[],"a":[["15515.47000000","0.00708700"],["15705.98000000","1.27339600"]]}}
2020-11-09T11:24:29.47148 btcusdt {"stream":"btcusdt@depth@100ms","data":{"e":"depthUpdate","E":1604921069465,"s":"BTCUSDT","U":6511120431,"u":6511120440,"b":[["15515.00000000","1.08111600"]],"a":[["15515.01000000","7.55793300"],["15515.47000000","0.00752000"],["15515.69000000","0.00000000"],["15519.37000000","0.00000000"]]}}
2020-11-09T11:24:29.57189 btcusdt {"stream":"btcusdt@depth@100ms","data":{"e":"depthUpdate","E":1604921069565,"s":"BTCUSDT","U":6511120441,"u":6511120458,"b":[["15515.00000000","0.79322000"],["15510.03000000","1.19900000"],["15509.55000000","0.11427900"],["15508.09000000","0.22500000"],["15505.77000000","0.00000000"]],"a":[["15515.01000000","14.44995300"],["15515.47000000","0.00000000"],["15516.74000000","0.00000000"],["15517.25000000","0.00000000"],["15518.46000000","0.00000000"],["15518.95000000","0.00000000"],["15521.43000000","0.00000000"],["15523.26000000","0.15000000"]]}}
2020-11-09T11:24:29.67300 btcusdt {"stream":"btcusdt@depth@100ms","data":{"e":"depthUpdate","E":1604921069665,"s":"BTCUSDT","U":6511120459,"u":6511120471,"b":[["15511.36000000","0.50000000"],["15510.17000000","0.16000000"],["15509.60000000","0.00000000"],["15508.12000000","0.00000000"],["15505.99000000","0.00000000"],["15505.48000000","1.25000000"]],"a":[["15515.01000000","14.60995300"],["15516.77000000","0.00000000"],["15517.51000000","0.50000000"],["15524.40000000","1.25000000"],["15705.98000000","0.00000000"]]}}
2020-11-09T11:24:29.77294 btcusdt {"stream":"btcusdt@depth@100ms","data":{"e":"depthUpdate","E":1604921069765,"s":"BTCUSDT","U":6511120472,"u":6511120484,"b":[["15509.29000000","0.00000000"],["15508.09000000","0.00000000"],["15506.58000000","0.02106400"],["15505.51000000","0.00000000"],["15505.48000000","0.00000000"],["15504.79000000","0.00000000"],["15503.30000000","1.25000000"]],"a":[["15515.32000000","0.08575200"],["15515.69000000","0.20000000"],["15518.46000000","0.20000000"],["15524.40000000","0.00000000"],["15525.55000000","1.25000000"]]}}
2020-11-09T11:24:29.87254 btcusdt {"stream":"btcusdt@depth@100ms","data":{"e":"depthUpdate","E":1604921069865,"s":"BTCUSDT","U":6511120485,"u":6511120487,"b":[["15441.09000000","0.00000000"]],"a":[["15519.50000000","0.09621200"],["15526.38000000","0.00000000"]]}}
2020-11-09T11:24:29.97312 btcusdt {"stream":"btcusdt@depth@100ms","data":{"e":"depthUpdate","E":1604921069965,"s":"BTCUSDT","U":6511120488,"u":6511120500,"b":[["15515.00000000","0.14922000"],["15511.85000000","0.00000000"],["15510.18000000","0.05000000"],["15510.16000000","0.00000000"],["15509.61000000","0.00000000"],["15508.12000000","0.10000000"],["15505.76000000","0.00000000"]],"a":[["15515.51000000","0.06819800"],["15517.42000000","1.10691900"],["15518.45000000","0.12892400"],["15522.08000000","0.00000000"],["15523.26000000","1.40000000"],["15525.55000000","0.00000000"]]}}
2020-11-09T11:24:30.07302 btcusdt {"stream":"btcusdt@depth@100ms","data":{"e":"depthUpdate","E":1604921070065,"s":"BTCUSDT","U":6511120501,"u":6511120511,"b":[["15515.00000000","0.14809800"],["15514.54000000","0.00737600"],["15514.23000000","0.01537000"],["15511.70000000","0.00200000"],["15503.30000000","0.00000000"],["15503.29000000","1.25000000"]],"a":[["15515.47000000","0.00845900"],["15518.60000000","0.29400000"],["15519.79000000","0.00000000"],["15523.26000000","0.15000000"]]}}
2020-11-09T11:24:30.17264 btcusdt {"stream":"btcusdt@depth@100ms","data":{"e":"depthUpdate","E":1604921070165,"s":"BTCUSDT","U":6511120512,"u":6511120524,"b":[["15515.00000000","0.14481100"],["15509.55000000","0.00000000"],["15509.07000000","0.11427900"],["15502.49000000","0.00000000"],["15473.87000000","0.00000000"]],"a":[["15515.01000000","14.69495300"],["15515.29000000","0.10000000"],["15516.58000000","0.00000000"],["15523.26000000","0.15000000"],["15523.85000000","1.25000000"],["15527.30000000","0.00000000"],["15560.74000000","0.00000000"]]}}
2020-11-09T11:24:30.27231 btcusdt {"stream":"btcusdt@depth@100ms","data":{"e":"depthUpdate","E":1604921070265,"s":"BTCUSDT","U":6511120525,"u":6511120534,"b":[["15504.55000000","0.00000000"],["15503.42000000","0.00000000"],["15501.08000000","0.50424200"]],"a":[["15515.47000000","0.00666000"],["15518.44000000","0.00000000"]]}}
2020-11-09T11:24:30.37246 btcusdt {"stream":"btcusdt@depth@100ms","data":{"e":"depthUpdate","E":1604921070366,"s":"BTCUSDT","U":6511120535,"u":6511120539,"b":[["15515.00000000","0.11242200"]],"a":[["15515.41000000","0.06819800"],["15515.47000000","0.00614800"],["15515.51000000","0.00000000"]]}}
2020-11-09T11:24:30.47545 btcusdt {"stream":"btcusdt@depth@100ms","data":{"e":"depthUpdate","E":1604921070466,"s":"BTCUSDT","U":6511120540,"u":6511120541,"b":[],"a":[["15515.47000000","0.00867100"]]}}
2020-11-09T11:24:30.57214 btcusdt {"stream":"btcusdt@depth@100ms","data":{"e":"depthUpdate","E":1604921070566,"s":"BTCUSDT","U":6511120542,"u":6511120546,"b":[["15515.00000000","0.11442200"],["14585.93000000","0.00487500"]],"a":[["15515.01000000","14.63482900"],["15705.98000000","1.27339600"],["25000.00000000","20.89396300"]]}}
2020-11-09T11:24:30.68062 btcusdt {"stream":"btcusdt@depth@100ms","data":{"e":"depthUpdate","E":1604921070666,"s":"BTCUSDT","U":6511120547,"u":6511120554,"b":[["15514.54000000","0.00000000"],["15514.23000000","0.00000000"],["15511.86000000","0.01962900"],["15511.72000000","0.00694800"],["15509.29000000","0.10000000"],["15508.12000000","0.00000000"],["15497.04000000","0.00000000"]],"a":[["15515.47000000","0.00000000"]]}}
2020-11-09T11:24:30.77269 btcusdt {"stream":"btcusdt@depth@100ms","data":{"e":"depthUpdate","E":1604921070766,"s":"BTCUSDT","U":6511120555,"u":6511120559,"b":[["15444.22000000","0.24000000"]],"a":[["15515.36000000","0.06819800"],["15515.41000000","0.00000000"],["15515.47000000","0.00831500"],["15529.46000000","0.24000000"]]}}
2020-11-09T11:24:30.87459 btcusdt {"stream":"btcusdt@depth@100ms","data":{"e":"depthUpdate","E":1604921070866,"s":"BTCUSDT","U":6511120560,"u":6511120573,"b":[["15509.54000000","0.11427900"],["15509.07000000","0.00000000"],["15508.12000000","0.15680600"],["15504.93000000","0.52290000"]],"a":[["15515.01000000","7.94458200"],["15515.29000000","0.00000000"],["15515.33000000","0.06819800"],["15515.36000000","0.00000000"],["15516.58000000","0.10000000"],["15518.45000000","0.00000000"],["15523.85000000","0.00000000"],["15524.04000000","1.25000000"],["15705.98000000","0.00000000"],["25000.00000000","20.89296300"]]}}
2020-11-09T11:24:30.97303 btcusdt {"stream":"btcusdt@depth@100ms","data":{"e":"depthUpdate","E":1604921070966,"s":"BTCUSDT","U":6511120574,"u":6511120583,"b":[["15515.00000000","0.09442200"],["15510.21000000","0.05000000"],["15510.18000000","0.00000000"],["7913.61000000","0.00137900"]],"a":[["15515.22000000","0.06819800"],["15515.33000000","0.00000000"],["15515.47000000","0.00679000"],["15524.04000000","0.00000000"],["15524.19000000","1.25000000"]]}}
2020-11-09T11:24:31.07329 btcusdt {"stream":"btcusdt@depth@100ms","data":{"e":"depthUpdate","E":1604921071066,"s":"BTCUSDT","U":6511120584,"u":6511120587,"b":[["15409.00000000","0.38472700"],["12412.00000000","1.15402800"]],"a":[["15515.47000000","0.00719900"]]}}
2020-11-09T11:24:31.23229 btcusdt {"stream":"btcusdt@depth@100ms","data":{"e":"depthUpdate","E":1604921071166,"s":"BTCUSDT","U":6511120588,"u":6511120591,"b":[["15423.00000000","0.00000000"],["15420.00000000","0.97585000"]],"a":[["15515.47000000","0.00883300"]]}}
2020-11-09T11:24:31.37304 btcusdt {"stream":"btcusdt@depth@100ms","data":{"e":"depthUpdate","E":1604921071366,"s":"BTCUSDT","U":6511120592,"u":6511120595,"b":[["15510.22000000","0.02106400"],["15508.12000000","0.00000000"],["15506.58000000","0.00000000"],["14884.03000000","0.00000000"]],"a":[]}}
2020-11-09T11:24:31.47210 btcusdt {"stream":"btcusdt@depth@100ms","data":{"e":"depthUpdate","E":1604921071466,"s":"BTCUSDT","U":6511120596,"u":6511120602,"b":[["15509.30000000","0.00000000"]],"a":[["15515.47000000","0.00911300"],["15544.73000000","0.00000000"]]}}
2020-11-09T11:24:31.57371 btcusdt {"stream":"btcusdt@depth@100ms","data":{"e":"depthUpdate","E":1604921071566,"s":"BTCUSDT","U":6511120603,"u":6511120605,"b":[],"a":[["15515.01000000","7.88432400"],["15515.47000000","0.00913000"]]}}
2020-11-09T11:24:31.67376 btcusdt {"stream":"btcusdt@depth@100ms","data":{"e":"depthUpdate","E":1604921071666,"s":"BTCUSDT","U":6511120606,"u":6511120606,"b":[["14882.06000000","0.00069600"]],"a":[]}}
2020-11-09T11:24:31.77355 btcusdt {"stream":"btcusdt@depth@100ms","data":{"e":"depthUpdate","E":1604921071766,"s":"BTCUSDT","U":6511120607,"u":6511120612,"b":[["14907.00000000","0.03417000"],["10323.61000000","0.00105400"]],"a":[["15515.47000000","0.00000000"],["15522.91000000","0.00000000"],["15544.74000000","0.01200000"],["15705.98000000","1.27339600"]]}}
2020-11-09T11:24:31.87317 btcusdt {"stream":"btcusdt@depth@100ms","data":{"e":"depthUpdate","E":1604921071866,"s":"BTCUSDT","U":6511120613,"u":6511120615,"b":[["15399.00000000","0.37683000"]],"a":[["15521.04000000","0.06708000"],["15837.37000000","0.00000000"]]}}
2020-11-09T11:24:31.97417 btcusdt {"stream":"btcusdt@depth@100ms","data":{"e":"depthUpdate","E":1604921071966,"s":"BTCUSDT","U":6511120616,"u":6511120619,"b":[["15510.23000000","0.05000000"],["15510.21000000","0.00000000"],["15399.00000000","0.48510300"]],"a":[["15559.00000000","1.06556200"]]}}
2020-11-09T11:24:32.07465 btcusdt {"stream":"btcusdt@depth@100ms","data":{"e":"depthUpdate","E":1604921072066,"s":"BTCUSDT","U":6511120620,"u":6511120623,"b":[["15515.00000000","0.11483100"],["15323.87000000","0.00254500"]],"a":[["15515.01000000","7.62651500"],["15705.98000000","0.00000000"]]}}
2020-11-09T11:24:32.17374 btcusdt {"stream":"btcusdt@depth@100ms","data":{"e":"depthUpdate","E":1604921072167,"s":"BTCUSDT","U":6511120624,"u":6511120632,"b":[["15508.62000000","0.00000000"],["15501.89000000","0.02500000"],["15497.81000000","0.00000000"],["15473.28000000","0.03100000"]],"a":[["15526.70000000","0.02500000"],["15558.00000000","4.00287900"],["15560.15000000","0.03100000"],["15839.46000000","0.00066200"]]}}
2020-11-09T11:24:32.27578 btcusdt {"stream":"btcusdt@depth@100ms","data":{"e":"depthUpdate","E":1604921072267,"s":"BTCUSDT","U":6511120633,"u":6511120638,"b":[["15508.62000000","0.15680600"],["15324.57000000","0.00065800"]],"a":[["15515.47000000","0.00766900"],["15524.19000000","0.00000000"]]}}
2020-11-09T11:24:32.37432 btcusdt {"stream":"btcusdt@depth@100ms","data":{"e":"depthUpdate","E":1604921072367,"s":"BTCUSDT","U":6511120639,"u":6511120641,"b":[["15515.00000000","0.11409700"],["15497.38000000","0.01900000"]],"a":[["15522.71000000","1.25000000"]]}}
2020-11-09T11:24:32.47463 btcusdt {"stream":"btcusdt@depth@100ms","data":{"e":"depthUpdate","E":1604921072467,"s":"BTCUSDT","U":6511120642,"u":6511120650,"b":[["15515.00000000","0.00000000"],["15514.97000000","0.00690000"],["15511.37000000","0.25100100"],["14900.00000000","109.38172900"]],"a":[["15514.98000000","0.07443800"],["15514.99000000","0.02386400"],["15515.00000000","0.36012200"],["15515.22000000","0.00000000"]]}}
2020-11-09T11:24:32.57550 btcusdt {"stream":"btcusdt@depth@100ms","data":{"e":"depthUpdate","E":1604921072567,"s":"BTCUSDT","U":6511120651,"u":6511120675,"b":[["15510.22000000","0.00000000"],["15510.18000000","0.69561600"],["15508.62000000","0.00000000"],["15506.58000000","0.02106400"]],"a":[["15514.98000000","5.98343800"],["15514.99000000","0.43944700"],["15515.00000000","24.45127300"],["15515.01000000","2.00000000"],["15515.47000000","0.00689100"],["15517.51000000","0.00000000"],["15518.47000000","0.00000000"],["15529.49000000","0.00000000"],["15621.85000000","0.00000000"]]}}
2020-11-09T11:24:32.68272 btcusdt {"stream":"btcusdt@depth@100ms","data":{"e":"depthUpdate","E":1604921072667,"s":"BTCUSDT","U":6511120676,"u":6511120690,"b":[["15509.29000000","0.00000000"],["15507.99000000","0.10000000"],["14689.52000000","0.01000000"]],"a":[["15514.98000000","9.19401800"],["15515.00000000","24.15822900"],["15515.44000000","0.00689400"],["15515.47000000","0.00000000"],["15515.75000000","0.01327300"],["15515.78000000","0.00000000"],["15530.28000000","1.00824800"]]}}
2020-11-09T11:24:32.77407 btcusdt {"stream":"btcusdt@depth@100ms","data":{"e":"depthUpdate","E":1604921072767,"s":"BTCUSDT","U":6511120691,"u":6511120695,"b":[],"a":[["15514.98000000","9.29401800"],["15515.00000000","24.16975200"],["15515.20000000","0.00200000"],["15516.58000000","0.00000000"],["15621.25000000","0.00067300"]]}}
2020-11-09T11:24:32.87390 btcusdt {"stream":"btcusdt@depth@100ms","data":{"e":"depthUpdate","E":1604921072867,"s":"BTCUSDT","U":6511120696,"u":6511120700,"b":[["15511.80000000","0.16763400"],["15437.42000000","0.00000000"]],"a":[["15522.70000000","0.02422500"],["15527.73000000","0.30137900"],["15705.98000000","1.27339600"]]}}
2020-11-09T11:24:32.97380 btcusdt {"stream":"btcusdt@depth@100ms","data":{"e":"depthUpdate","E":1604921072967,"s":"BTCUSDT","U":6511120701,"u":6511120719,"b":[["15514.97000000","0.15690000"],["15510.47000000","0.13000000"],["15510.23000000","0.00000000"],["15509.29000000","0.10000000"],["15507.99000000","0.00000000"],["14800.13000000","0.00000000"]],"a":[["15514.98000000","8.39704400"],["15515.00000000","24.15164500"],["15515.53000000","0.06756700"],["15516.58000000","0.10000000"],["15518.45000000","0.00000000"],["15523.25000000","0.40548900"],["15529.98000000","0.00000000"],["15533.35000000","0.00000000"]]}}
2020-11-09T11:24:33.07487 btcusdt {"stream":"btcusdt@depth@100ms","data":{"e":"depthUpdate","E":1604921073067,"s":"BTCUSDT","U":6511120720,"u":6511120731,"b":[["15506.58000000","0.00000000"]],"a":[["15514.98000000","9.17958000"],["15516.76000000","0.25760400"],["15522.14000000","0.02968800"],["15522.71000000","0.00000000"],["15523.26000000","1.40000000"],["15524.11000000","0.02907100"],["15524.87000000","0.00000000"],["15529.99000000","0.45568200"],["15549.99000000","0.80099900"]]}}
2020-11-09T11:24:33.17557 btcusdt {"stream":"btcusdt@depth@100ms","data":{"e":"depthUpdate","E":1604921073167,"s":"BTCUSDT","U":6511120732,"u":6511120733,"b":[],"a":[["15529.99000000","0.00000000"],["15539.13000000","0.00000000"]]}}
2020-11-09T11:24:33.27464 btcusdt {"stream":"btcusdt@depth@100ms","data":{"e":"depthUpdate","E":1604921073267,"s":"BTCUSDT","U":6511120734,"u":6511120743,"b":[["15511.72000000","0.00000000"],["15510.47000000","0.13698800"],["15509.29000000","0.00000000"],["15506.58000000","0.10000000"],["15505.01000000","0.20000000"]],"a":[["15514.98000000","8.49704400"],["15516.58000000","0.00000000"],["15523.26000000","0.15000000"],["15705.98000000","0.00000000"]]}}
2020-11-09T11:24:33.37526 btcusdt {"stream":"btcusdt@depth@100ms","data":{"e":"depthUpdate","E":1604921073367,"s":"BTCUSDT","U":6511120744,"u":6511120754,"b":[["15514.97000000","0.00690000"],["15511.86000000","0.00000000"],["15510.53000000","0.01334200"],["15437.39000000","0.00647700"]],"a":[["15514.98000000","9.45827900"],["15514.99000000","0.39625200"],["15515.53000000","0.00000000"],["15523.26000000","1.40000000"]]}}
2020-11-09T11:24:33.47468 btcusdt {"stream":"btcusdt@depth@100ms","data":{"e":"depthUpdate","E":1604921073467,"s":"BTCUSDT","U":6511120755,"u":6511120755,"b":[["15497.38000000","0.00000000"]],"a":[]}}
2020-11-09T11:24:33.57510 btcusdt {"stream":"btcusdt@depth@100ms","data":{"e":"depthUpdate","E":1604921073567,"s":"BTCUSDT","U":6511120756,"u":6511120757,"b":[],"a":[["15514.98000000","9.39790300"],["15625.00000000","12.36549600"]]}}
2020-11-09T11:24:33.67780 btcusdt {"stream":"btcusdt@depth@100ms","data":{"e":"depthUpdate","E":1604921073667,"s":"BTCUSDT","U":6511120758,"u":6511120763,"b":[["15511.32000000","0.00609200"],["15510.53000000","0.00000000"],["15510.47000000","0.13000000"],["15510.05000000","0.01294200"],["15497.31000000","0.01900000"]],"a":[["15514.98000000","9.39671400"]]}}
2020-11-09T11:24:33.77732 btcusdt {"stream":"btcusdt@depth@100ms","data":{"e":"depthUpdate","E":1604921073767,"s":"BTCUSDT","U":6511120764,"u":6511120767,"b":[["15505.73000000","0.02106400"]],"a":[["15900.00000000","115.81600100"]]}}
2020-11-09T11:24:33.87633 btcusdt {"stream":"btcusdt@depth@100ms","data":{"e":"depthUpdate","E":1604921073868,"s":"BTCUSDT","U":6511120768,"u":6511120774,"b":[["15514.97000000","0.00617700"],["15508.12000000","0.10000000"],["15506.58000000","0.00000000"],["15505.01000000","0.00000000"],["15480.00000000","0.06235700"]],"a":[["15522.63000000","0.02422500"],["15522.70000000","0.00000000"]]}}
2020-11-09T11:24:33.97400 btcusdt {"stream":"btcusdt@depth@100ms","data":{"e":"depthUpdate","E":1604921073967,"s":"BTCUSDT","U":6511120775,"u":6511120782,"b":[["15511.28000000","0.01842000"],["15510.47000000","0.08000000"],["15510.19000000","0.05000000"],["15510.05000000","0.00000000"]],"a":[["15515.75000000","0.00000000"],["15516.05000000","0.01940700"],["15522.12000000","0.02907100"],["15524.11000000","0.00000000"]]}}
2020-11-09T11:24:34.07416 btcusdt {"stream":"btcusdt@depth@100ms","data":{"e":"depthUpdate","E":1604921074068,"s":"BTCUSDT","U":6511120783,"u":6511120784,"b":[["15505.73000000","0.00000000"]],"a":[["15705.98000000","1.27339600"]]}}
2020-11-09T11:24:34.17460 btcusdt {"stream":"btcusdt@depth@100ms","data":{"e":"depthUpdate","E":1604921074168,"s":"BTCUSDT","U":6511120785,"u":6511120788,"b":[["15511.28000000","0.00000000"],["15510.16000000","0.01257400"]],"a":[["15515.75000000","0.01209800"],["15516.05000000","0.00000000"]]}}
2020-11-09T11:24:34.27786 btcusdt {"stream":"btcusdt@depth@100ms","data":{"e":"depthUpdate","E":1604921074268,"s":"BTCUSDT","U":6511120789,"u":6511120789,"b":[["15511.32000000","0.00000000"]],"a":[]}}
2020-11-09T11:24:34.37732 btcusdt {"stream":"btcusdt@depth@100ms","data":{"e":"depthUpdate","E":1604921074368,"s":"BTCUSDT","U":6511120790,"u":6511120790,"b":[["15505.73000000","0.02106400"]],"a":[]}}
2020-11-09T11:24:34.47457 btcusdt {"stream":"btcusdt@depth@100ms","data":{"e":"depthUpdate","E":1604921074468,"s":"BTCUSDT","U":6511120791,"u":6511120793,"b":[],"a":[["15528.18000000","0.00000000"],["15529.46000000","0.00000000"],["15705.98000000","0.00000000"]]}}
2020-11-09T11:24:34.57468 btcusdt {"stream":"btcusdt@depth@100ms","data":{"e":"depthUpdate","E":1604921074568,"s":"BTCUSDT","U":6511120794,"u":6511120796,"b":[["15510.85000000","0.50000000"]],"a":[["15517.13000000","0.50000000"],["15525.33000000","0.13426400"]]}}
2020-11-09T11:24:34.73038 btcusdt {"stream":"btcusdt@depth@100ms","data":{"e":"depthUpdate","E":1604921074668,"s":"BTCUSDT","U":6511120797,"u":6511120798,"b":[["15505.73000000","0.00000000"]],"a":[["15514.98000000","9.33664800"]]}}
2020-11-09T11:24:34.77539 btcusdt {"stream":"btcusdt@depth@100ms","data":{"e":"depthUpdate","E":1604921074768,"s":"BTCUSDT","U":6511120799,"u":6511120877,"b":[["15514.97000000","0.00000000"],["15514.94000000","0.00000000"],["15514.81000000","0.00000000"],["15514.04000000","0.00000000"],["15514.03000000","0.00000000"],["15513.84000000","0.00000000"],["15513.64000000","0.00000000"],["15513.60000000","0.00000000"],["15513.17000000","0.00690000"],["15512.77000000","0.00000000"],["15512.44000000","0.00000000"],["15512.35000000","0.00000000"],["15511.90000000","0.00000000"],["15511.80000000","0.00000000"],["15511.70000000","0.00000000"],["15511.57000000","0.00000000"],["15511.44000000","0.05063700"],["15511.37000000","0.00000000"],["15511.36000000","0.18550300"],["15510.18000000","0.00000000"],["15510.03000000","0.00000000"],["15509.54000000","0.00000000"],["15509.28000000","0.00000000"],["15509.22000000","0.00000000"],["15508.98000000","0.00000000"],["15508.74000000","1.58300000"],["15508.63000000","1.59300000"],["15508.53000000","1.19900000"],["15508.43000000","0.11427900"],["15508.12000000","0.00000000"],["15507.56000000","0.22500000"],["15506.58000000","0.10000000"],["15505.73000000","0.02106400"],["15505.72000000","0.00000000"],["15504.94000000","0.20000000"],["15504.93000000","0.00000000"],["15504.40000000","0.00000000"],["15495.18000000","0.00000000"],["15495.04000000","1.50000000"],["15494.96000000","0.00000000"]],"a":[["15513.18000000","0.05084500"],["15513.73000000","0.05069900"],["15513.88000000","0.00000000"],["15514.57000000","0.14566800"],["15514.58000000","0.00000000"],["15514.60000000","0.14792500"],["15514.62000000","0.00000000"],["15514.82000000","3.04191300"],["15514.89000000","0.00000000"],["15514.95000000","0.00000000"],["15514.97000000","6.08382400"],["15514.98000000","2.67604400"],["15515.13000000","0.00000000"],["15516.59000000","0.00000000"],["15517.05000000","0.01700000"],["15517.13000000","0.00000000"],["15517.44000000","0.01700000"],["15517.62000000","1.75490000"],["15518.77000000","1.61700000"],["15518.78000000","0.00000000"],["15518.96000000","0.54858800"],["15519.41000000","0.05000000"],["15519.43000000","0.00000000"],["15519.72000000","0.10000000"],["15522.12000000","0.00000000"],["15522.14000000","0.00000000"],["15522.63000000","0.00000000"],["15524.36000000","0.02382800"],["15528.51000000","0.00000000"],["15530.01000000","0.24000000"]]}}
2020-11-09T11:24:34.87551 btcusdt {"stream":"btcusdt@depth@100ms","data":{"e":"depthUpdate","E":1604921074868,"s":"BTCUSDT","U":6511120878,"u":6511120917,"b":[["15513.17000000","1.00690000"],["15510.54000000","0.00000000"],["15510.19000000","0.00000000"],["15510.12000000","0.00945300"],["15509.14000000","0.20000000"],["15508.64000000","0.05000000"],["15503.29000000","0.00000000"],["15503.27000000","0.15300000"],["15495.04000000","0.00000000"],["15437.39000000","0.00000000"]],"a":[["15513.18000000","2.04598100"],["15513.73000000","0.00000000"],["15514.58000000","0.32100000"],["15514.82000000","1.94603600"],["15514.98000000","2.36300000"],["15514.99000000","0.00625200"],["15517.05000000","0.00000000"],["15517.42000000","0.00000000"],["15517.44000000","0.05000000"],["15517.62000000","0.00690000"],["15517.69000000","0.01700000"],["15517.78000000","0.01000000"],["15518.13000000","0.02390000"],["15518.31000000","1.74800000"],["15519.41000000","0.00000000"],["15519.59000000","0.01000000"],["15519.76000000","0.00690000"],["15519.99000000","0.01500000"],["15520.00000000","5.76780900"],["15521.56000000","0.00000000"],["15521.96000000","0.00000000"],["15522.11000000","0.02968800"],["15522.33000000","0.02422500"],["15523.25000000","0.43456000"]]}}
2020-11-09T11:24:34.97557 btcusdt {"stream":"btcusdt@depth@100ms","data":{"e":"depthUpdate","E":1604921074968,"s":"BTCUSDT","U":6511120918,"u":6511120934,"b":[["15513.17000000","4.35690000"],["15506.58000000","0.25680600"],["15504.79000000","1.25000000"],["15501.39000000","0.30188600"]],"a":[["15513.18000000","2.41861200"],["15514.56000000","0.78253600"],["15514.57000000","0.10290400"],["15514.82000000","0.00000000"],["15514.97000000","5.30128800"],["15515.69000000","0.00000000"],["15516.75000000","0.00690000"],["15518.46000000","0.00000000"],["15523.26000000","0.15000000"]]}}
2020-11-09T11:24:35.07716 btcusdt {"stream":"btcusdt@depth@100ms","data":{"e":"depthUpdate","E":1604921075068,"s":"BTCUSDT","U":6511120935,"u":6511120952,"b":[["15513.17000000","3.00690000"],["15506.69000000","0.00000000"],["15504.94000000","0.00000000"],["15504.79000000","1.25000000"],["15473.42000000","0.00000000"]],"a":[["15513.18000000","0.42495400"],["15514.15000000","0.00913200"],["15514.55000000","0.67718400"],["15514.56000000","0.98253600"],["15514.96000000","1.75232900"],["15515.44000000","0.00000000"],["15515.75000000","0.00000000"],["15523.28000000","0.00000000"],["15524.19000000","1.25000000"]]}}
2020-11-09T11:24:35.17684 btcusdt {"stream":"btcusdt@depth@100ms","data":{"e":"depthUpdate","E":1604921075168,"s":"BTCUSDT","U":6511120953,"u":6511120970,"b":[["15512.52000000","0.05063700"],["15511.44000000","0.00000000"],["15509.57000000","0.19427900"],["15509.00000000","1.19900000"],["15508.53000000","0.00000000"],["15508.43000000","0.00000000"],["15473.53000000","0.53164400"]],"a":[["15513.18000000","0.14624500"],["15514.53000000","0.77718200"],["15514.54000000","0.78253600"],["15514.55000000","0.00000000"],["15514.56000000","0.20000000"],["15514.95000000","1.69928400"],["15514.96000000","0.00000000"]]}}
2020-11-09T11:24:35.27569 btcusdt {"stream":"btcusdt@depth@100ms","data":{"e":"depthUpdate","E":1604921075268,"s":"BTCUSDT","U":6511120971,"u":6511120980,"b":[["15512.71000000","0.00947900"],["15512.40000000","0.01496100"],["15510.16000000","0.00000000"],["15510.12000000","0.00000000"],["15504.80000000","0.20000000"],["15494.73000000","1.50000000"]],"a":[["15514.80000000","0.01663600"],["15514.98000000","2.22800000"],["15515.01000000","2.00651500"],["15705.98000000","1.27339600"]]}}
2020-11-09T11:24:35.37801 btcusdt {"stream":"btcusdt@depth@100ms","data":{"e":"depthUpdate","E":1604921075368,"s":"BTCUSDT","U":6511120981,"u":6511120991,"b":[["15435.60000000","0.00647800"]],"a":[["15513.31000000","0.12800000"],["15514.52000000","0.38591500"],["15514.53000000","0.00000000"],["15514.54000000","0.00000000"],["15514.95000000","2.72844900"],["15514.98000000","2.10000000"],["15524.11000000","0.02884500"],["15524.37000000","0.00000000"]]}}
2020-11-09T11:24:35.47604 btcusdt {"stream":"btcusdt@depth@100ms","data":{"e":"depthUpdate","E":1604921075468,"s":"BTCUSDT","U":6511120992,"u":6511121003,"b":[["15513.17000000","3.28560900"],["15512.71000000","0.00924900"],["15512.40000000","0.00000000"],["15511.90000000","0.01738700"],["15466.65000000","0.01034400"]],"a":[["15513.95000000","0.01585100"],["15514.80000000","0.00000000"],["15514.99000000","0.00000000"],["15518.12000000","0.20000000"],["15522.72000000","1.00846800"],["15527.82000000","0.00000000"]]}}
2020-11-09T11:24:35.57718 btcusdt {"stream":"btcusdt@depth@100ms","data":{"e":"depthUpdate","E":1604921075568,"s":"BTCUSDT","U":6511121004,"u":6511121013,"b":[["15399.00000000","0.37683000"]],"a":[["15513.18000000","5.03591400"],["15513.66000000","0.00862600"],["15514.15000000","0.00000000"],["15514.52000000","0.00000000"],["15514.95000000","0.00000000"],["15514.97000000","0.00128800"],["15524.31000000","0.13414800"]]}}
2020-11-09T11:24:35.68855 btcusdt {"stream":"btcusdt@depth@100ms","data":{"e":"depthUpdate","E":1604921075668,"s":"BTCUSDT","U":6511121014,"u":6511121021,"b":[["15513.17000000","3.00690000"],["15506.69000000","1.25000000"],["15504.79000000","0.00000000"],["15466.75000000","0.01034400"],["15420.00000000","1.08412300"]],"a":[["15513.18000000","5.31662300"],["15705.98000000","0.00000000"]]}}
2020-11-09T11:24:35.77627 btcusdt {"stream":"btcusdt@depth@100ms","data":{"e":"depthUpdate","E":1604921075768,"s":"BTCUSDT","U":6511121022,"u":6511121031,"b":[["15512.40000000","0.01654100"],["15511.90000000","0.00000000"],["15504.80000000","0.00000000"],["15504.64000000","0.53152100"],["15497.31000000","0.00000000"]],"a":[["15513.18000000","5.31959500"],["15513.95000000","0.00000000"],["15514.15000000","0.01351800"],["15514.55000000","0.13500000"]]}}
2020-11-09T11:24:35.87560 btcusdt {"stream":"btcusdt@depth@100ms","data":{"e":"depthUpdate","E":1604921075869,"s":"BTCUSDT","U":6511121032,"u":6511121055,"b":[["15513.17000000","1.00690000"],["15509.57000000","0.08000000"],["15509.09000000","0.11427900"],["15507.98000000","0.00000000"],["15506.69000000","0.00000000"],["15505.42000000","1.25000000"],["15504.15000000","0.00000000"],["15500.26000000","0.02236400"],["15497.07000000","0.01900000"]],"a":[["15513.18000000","7.31959500"],["15513.30000000","0.01900000"],["15518.58000000","0.10000000"],["15518.59000000","0.38000000"],["15521.18000000","0.00000000"],["15522.27000000","0.00000000"],["15522.33000000","0.42971400"],["15522.71000000","0.02907100"],["15523.25000000","0.00000000"],["15523.82000000","0.02551800"],["15523.83000000","0.00000000"],["15524.79000000","0.45568200"],["15530.11000000","0.24000000"],["15534.76000000","0.00000000"]]}}
2020-11-09T11:24:35.97553 btcusdt {"stream":"btcusdt@depth@100ms","data":{"e":"depthUpdate","E":1604921075969,"s":"BTCUSDT","U":6511121056,"u":6511121070,"b":[["15513.17000000","1.00529400"],["15508.72000000","0.05000000"],["15508.64000000","0.00000000"],["15505.42000000","0.00000000"],["15504.64000000","0.00000000"],["15500.94000000","0.21604900"],["15497.93000000","0.00000000"],["15495.36000000","1.00000000"]],"a":[["15513.18000000","7.66959500"],["15516.74000000","0.00000000"],["15522.97000000","0.02382800"],["15524.30000000","0.02806500"],["15524.36000000","0.00000000"]]}}
2020-11-09T11:24:36.07572 btcusdt {"stream":"btcusdt@depth@100ms","data":{"e":"depthUpdate","E":1604921076069,"s":"BTCUSDT","U":6511121071,"u":6511121076,"b":[["15504.79000000","1.25000000"],["15494.73000000","0.00000000"]],"a":[["15513.18000000","7.67159500"],["15514.15000000","0.00000000"],["15516.92000000","0.01275000"],["15522.92000000","0.30187500"]]}}
2020-11-09T11:24:36.17635 btcusdt {"stream":"btcusdt@depth@100ms","data":{"e":"depthUpdate","E":1604921076169,"s":"BTCUSDT","U":6511121077,"u":6511121083,"b":[["15512.71000000","0.00650500"],["15505.74000000","0.06735300"]],"a":[["15513.18000000","2.37159500"],["15513.65000000","0.16500000"],["15513.66000000","0.00000000"],["15516.43000000","0.00662500"]]}}
2020-11-09T11:24:36.27618 btcusdt {"stream":"btcusdt@depth@100ms","data":{"e":"depthUpdate","E":1604921076269,"s":"BTCUSDT","U":6511121084,"u":6511121086,"b":[["15512.71000000","0.00000000"],["15506.69000000","1.25000000"],["15504.79000000","0.00000000"]],"a":[]}}
2020-11-09T11:24:36.37986 btcusdt {"stream":"btcusdt@depth@100ms","data":{"e":"depthUpdate","E":1604921076369,"s":"BTCUSDT","U":6511121087,"u":6511121095,"b":[["15513.17000000","0.92895100"],["15512.71000000","0.00678600"],["15507.57000000","0.10000000"],["15506.58000000","0.15680600"],["15505.61000000","0.00000000"]],"a":[["15513.18000000","8.17159500"]]}}
2020-11-09T11:24:36.47721 btcusdt {"stream":"btcusdt@depth@100ms","data":{"e":"depthUpdate","E":1604921076469,"s":"BTCUSDT","U":6511121096,"u":6511121105,"b":[["15512.71000000","0.00644800"],["15506.69000000","0.00000000"],["15506.58000000","0.00000000"],["15504.79000000","1.25000000"],["15420.00000000","0.97585000"]],"a":[["15513.18000000","2.87159500"],["15524.11000000","0.00000000"]]}}
2020-11-09T11:24:36.57718 btcusdt {"stream":"btcusdt@depth@100ms","data":{"e":"depthUpdate","E":1604921076569,"s":"BTCUSDT","U":6511121106,"u":6511121116,"b":[["15512.71000000","0.00974500"],["15506.69000000","1.25000000"],["15504.79000000","0.00000000"]],"a":[["15513.18000000","3.10219700"],["15514.55000000","0.00000000"],["15522.91000000","0.02884500"]]}}
2020-11-09T11:24:36.68201 btcusdt {"stream":"btcusdt@depth@100ms","data":{"e":"depthUpdate","E":1604921076669,"s":"BTCUSDT","U":6511121117,"u":6511121117,"b":[["15506.69000000","0.00000000"]],"a":[]}}
2020-11-09T11:24:36.77704 btcusdt {"stream":"btcusdt@depth@100ms","data":{"e":"depthUpdate","E":1604921076769,"s":"BTCUSDT","U":6511121118,"u":6511121121,"b":[["15513.17000000","0.91828900"],["15504.79000000","1.25000000"],["15503.28000000","0.20000000"]],"a":[["15513.18000000","8.40219700"]]}}
2020-11-09T11:24:36.87643 btcusdt {"stream":"btcusdt@depth@100ms","data":{"e":"depthUpdate","E":1604921076869,"s":"BTCUSDT","U":6511121122,"u":6511121131,"b":[["15513.17000000","0.91560200"],["15512.71000000","0.00000000"],["15509.88000000","0.00741800"],["15503.59000000","0.93469000"],["15503.28000000","0.00000000"]],"a":[["15513.64000000","0.00637800"],["15514.23000000","0.09661100"],["15516.27000000","1.09307400"],["15516.43000000","0.00000000"],["15705.94000000","1.27339900"]]}}
2020-11-09T11:24:36.97945 btcusdt {"stream":"btcusdt@depth@100ms","data":{"e":"depthUpdate","E":1604921076969,"s":"BTCUSDT","U":6511121132,"u":6511121148,"b":[["15513.17000000","1.06560200"],["15512.40000000","0.00000000"],["15509.92000000","0.01230200"],["15508.75000000","0.05000000"],["15508.72000000","0.00000000"],["15503.61000000","0.42505700"]],"a":[["15513.18000000","8.53019700"],["15513.31000000","0.00000000"],["15513.95000000","0.01905500"],["15516.81000000","0.03223100"],["15516.92000000","0.00000000"],["15518.89000000","0.00000000"],["15522.97000000","0.00000000"],["15523.89000000","0.02382800"],["15524.30000000","0.00000000"],["15525.58000000","0.02806500"],["15911.93000000","0.00000000"]]}}
2020-11-09T11:24:37.07771 btcusdt {"stream":"btcusdt@depth@100ms","data":{"e":"depthUpdate","E":1604921077069,"s":"BTCUSDT","U":6511121149,"u":6511121157,"b":[["15513.17000000","6.36560200"],["15509.14000000","0.00000000"]],"a":[["15513.18000000","7.87297400"],["15514.98000000","2.00000000"],["15516.26000000","0.10690000"],["15518.12000000","0.00000000"],["15524.79000000","0.00000000"],["15526.57000000","0.45568200"]]}}
2020-11-09T11:24:37.17853 btcusdt {"stream":"btcusdt@depth@100ms","data":{"e":"depthUpdate","E":1604921077169,"s":"BTCUSDT","U":6511121158,"u":6511121171,"b":[["15513.17000000","5.51560200"],["15506.58000000","0.35680600"],["15503.17000000","0.00000000"],["15500.74000000","0.10000000"],["15476.22000000","0.00000000"],["15399.00000000","0.48510300"]],"a":[["15513.18000000","0.92075300"],["15517.26000000","0.00000000"],["15522.83000000","0.02884500"],["15522.91000000","0.00000000"],["15553.79000000","0.00000000"]]}}
2020-11-09T11:24:37.27664 btcusdt {"stream":"btcusdt@depth@100ms","data":{"e":"depthUpdate","E":1604921077269,"s":"BTCUSDT","U":6511121172,"u":6511121173,"b":[["15512.98000000","0.00200000"]],"a":[["15705.94000000","0.00000000"]]}}
2020-11-09T11:24:37.37989 btcusdt {"stream":"btcusdt@depth@100ms","data":{"e":"depthUpdate","E":1604921077369,"s":"BTCUSDT","U":6511121174,"u":6511121177,"b":[["15512.98000000","0.00400000"]],"a":[["15514.97000000","0.10128800"],["15516.26000000","0.00690000"],["15516.27000000","0.00000000"]]}}
2020-11-09T11:24:37.47758 btcusdt {"stream":"btcusdt@depth@100ms","data":{"e":"depthUpdate","E":1604921077469,"s":"BTCUSDT","U":6511121178,"u":6511121186,"b":[["15513.17000000","8.36560200"],["15509.59000000","0.11427900"],["15509.09000000","0.00000000"],["15501.70000000","0.50423400"],["15501.08000000","0.00000000"],["15494.23000000","1.50000000"]],"a":[["15513.18000000","0.86009400"],["15514.97000000","0.00128800"]]}}
2020-11-09T11:24:37.57673 btcusdt {"stream":"btcusdt@depth@100ms","data":{"e":"depthUpdate","E":1604921077569,"s":"BTCUSDT","U":6511121187,"u":6511121189,"b":[["15513.17000000","3.06560200"]],"a":[["15513.65000000","0.00000000"],["15516.75000000","0.10690000"]]}}
2020-11-09T11:24:37.68303 btcusdt {"stream":"btcusdt@depth@100ms","data":{"e":"depthUpdate","E":1604921077670,"s":"BTCUSDT","U":6511121190,"u":6511121195,"b":[["15508.76000000","0.10000000"],["15507.57000000","0.00000000"],["15495.36000000","0.00000000"],["15000.00000000","214.17257100"]],"a":[["15515.34000000","0.25760200"],["15521.31000000","0.00000000"]]}}
2020-11-09T11:24:37.77694 btcusdt {"stream":"btcusdt@depth@100ms","data":{"e":"depthUpdate","E":1604921077770,"s":"BTCUSDT","U":6511121196,"u":6511121204,"b":[["15509.60000000","0.02106400"],["15509.14000000","0.15680600"],["15506.58000000","0.20000000"],["15505.73000000","0.00000000"],["15504.27000000","0.20000000"],["15498.59000000","1.00000000"]],"a":[["15522.34000000","0.00000000"],["15522.83000000","0.00000000"],["15530.11000000","0.00000000"]]}}
2020-11-09T11:24:37.87673 btcusdt {"stream":"btcusdt@depth@100ms","data":{"e":"depthUpdate","E":1604921077870,"s":"BTCUSDT","U":6511121205,"u":6511121213,"b":[["15512.98000000","0.00600000"],["15510.01000000","0.20000000"],["15509.14000000","0.00000000"],["15508.76000000","0.00000000"],["15506.59000000","0.10000000"],["15506.58000000","0.00000000"],["15504.27000000","0.00000000"]],"a":[["15518.30000000","0.20000000"],["15524.18000000","0.02884500"]]}}
2020-11-09T11:24:37.97642 btcusdt {"stream":"btcusdt@depth@100ms","data":{"e":"depthUpdate","E":1604921077970,"s":"BTCUSDT","U":6511121214,"u":6511121216,"b":[["15509.01000000","0.05000000"],["15508.75000000","0.00000000"]],"a":[["15517.26000000","0.12894000"]]}}
2020-11-09T11:24:38.07633 btcusdt {"stream":"btcusdt@depth@100ms","data":{"e":"depthUpdate","E":1604921078070,"s":"BTCUSDT","U":6511121217,"u":6511121224,"b":[["15509.60000000","0.00000000"],["15506.60000000","0.02106400"]],"a":[["15513.18000000","0.90009400"],["15514.22000000","0.10000000"],["15515.34000000","0.00000000"],["15516.75000000","0.00690000"],["15523.85000000","0.25760200"],["15705.94000000","1.27339900"]]}}
2020-11-09T11:24:38.17669 btcusdt {"stream":"btcusdt@depth@100ms","data":{"e":"depthUpdate","E":1604921078170,"s":"BTCUSDT","U":6511121225,"u":6511121228,"b":[["15506.61000000","0.15680600"],["15474.39000000","0.25000000"]],"a":[["15513.18000000","0.86009400"],["15551.96000000","0.25120000"]]}}
2020-11-09T11:24:38.37614 btcusdt {"stream":"btcusdt@depth@100ms","data":{"e":"depthUpdate","E":1604921078370,"s":"BTCUSDT","U":6511121229,"u":6511121241,"b":[["15512.40000000","0.01578700"],["15509.92000000","0.00000000"],["15508.64000000","1.52000000"],["15508.61000000","0.00000000"]],"a":[["15513.95000000","0.00000000"],["15516.86000000","0.01270100"],["15518.78000000","2.00000000"],["15519.10000000","0.00000000"],["15519.18000000","2.00000000"],["15519.67000000","0.00000000"],["15519.77000000","2.76000000"],["15519.80000000","0.00000000"],["15705.94000000","0.00000000"]]}}
2020-11-09T11:24:38.47856 btcusdt {"stream":"btcusdt@depth@100ms","data":{"e":"depthUpdate","E":1604921078470,"s":"BTCUSDT","U":6511121242,"u":6511121250,"b":[["15513.17000000","8.59746200"],["15509.02000000","0.10000000"],["15506.59000000","0.00000000"]],"a":[["15513.18000000","0.80004700"],["15514.22000000","0.00000000"],["15516.75000000","0.10690000"],["15517.26000000","0.00000000"],["15518.30000000","0.00000000"]]}}
2020-11-09T11:24:38.57737 btcusdt {"stream":"btcusdt@depth@100ms","data":{"e":"depthUpdate","E":1604921078570,"s":"BTCUSDT","U":6511121251,"u":6511121261,"b":[["15513.17000000","8.18343700"],["15512.71000000","0.00645800"],["15509.88000000","0.00000000"]],"a":[["15513.18000000","0.12800000"],["15513.64000000","0.00000000"],["15514.57000000","0.00000000"],["15514.60000000","0.00000000"],["15514.96000000","0.80011600"]]}}
2020-11-09T11:24:38.68111 btcusdt {"stream":"btcusdt@depth@100ms","data":{"e":"depthUpdate","E":1604921078670,"s":"BTCUSDT","U":6511121262,"u":6511121289,"b":[["15513.17000000","2.88343700"],["15504.79000000","0.00000000"]],"a":[["15513.18000000","0.12800000"],["15514.52000000","0.00000000"],["15514.54000000","0.00000000"],["15514.55000000","0.00000000"],["15514.58000000","0.00000000"],["15514.92000000","1.41190200"],["15514.93000000","0.00000000"],["15514.95000000","0.00000000"],["15514.96000000","0.00000000"],["15515.58000000","0.32100000"],["15516.42000000","0.00759100"],["15523.26000000","1.40000000"],["15524.19000000","0.00000000"],["15530.01000000","0.00000000"]]}}
2020-11-09T11:24:38.77675 btcusdt {"stream":"btcusdt@depth@100ms","data":{"e":"depthUpdate","E":1604921078770,"s":"BTCUSDT","U":6511121290,"u":6511121322,"b":[["15513.29000000","6.17912900"],["15513.23000000","0.00690000"],["15513.17000000","2.38186000"],["15512.82000000","0.00000000"],["15512.71000000","0.00000000"],["15512.52000000","0.00000000"],["15510.44000000","0.11427900"],["15509.59000000","0.00000000"],["15508.75000000","0.00000000"],["15506.69000000","1.25000000"],["15506.61000000","0.00000000"],["15504.55000000","0.20000000"],["15502.03000000","0.00000000"],["15493.97000000","0.10000000"],["15203.02000000","0.00174700"]],"a":[["15513.18000000","0.00000000"],["15513.30000000","5.42590000"],["15514.22000000","0.00000000"],["15514.91000000","0.78253600"],["15515.58000000","0.00000000"],["15516.75000000","0.00690000"]]}}
2020-11-09T11:24:38.87680 btcusdt {"stream":"btcusdt@depth@100ms","data":{"e":"depthUpdate","E":1604921078870,"s":"BTCUSDT","U":6511121323,"u":6511121353,"b":[["15513.29000000","8.71284900"],["15513.17000000","2.15000000"],["15512.95000000","0.05123100"],["15512.86000000","0.00000000"],["15512.83000000","0.00810600"],["15512.71000000","0.00000000"],["15512.52000000","0.01338800"],["15512.40000000","0.00000000"],["15507.57000000","0.15680600"],["15503.23000000","1.00850800"],["15502.02000000","0.30600000"],["15494.10000000","0.05000000"],["15435.60000000","0.00000000"]],"a":[["15513.30000000","0.02590000"],["15514.22000000","0.04830700"],["15514.56000000","0.00000000"],["15514.90000000","1.63943900"],["15514.92000000","0.00000000"],["15515.58000000","0.32100000"],["15516.74000000","0.20000000"],["15516.85000000","0.10000000"],["15523.75000000","0.02382800"],["15523.89000000","0.00000000"],["16452.78000000","6.91495700"]]}}
2020-11-09T11:24:38.97838 btcusdt {"stream":"btcusdt@depth@100ms","data":{"e":"depthUpdate","E":1604921078970,"s":"BTCUSDT","U":6511121354,"u":6511121364,"b":[["15510.48000000","0.02106400"],["15509.14000000","0.15822200"],["15509.01000000","0.00000000"],["15506.60000000","0.00000000"],["15504.55000000","0.00000000"],["15503.23000000","0.00000000"],["15500.56000000","1.00850800"],["15325.39000000","0.00065300"]],"a":[["15514.91000000","0.00000000"],["15521.00000000","1.00000000"]]}}
2020-11-09T11:24:39.07769 btcusdt {"stream":"btcusdt@depth@100ms","data":{"e":"depthUpdate","E":1604921079070,"s":"BTCUSDT","U":6511121365,"u":6511121366,"b":[["15513.29000000","8.71484900"]],"a":[["15525.00000000","0.03610500"]]}}
2020-11-09T11:24:39.17769 btcusdt {"stream":"btcusdt@depth@100ms","data":{"e":"depthUpdate","E":1604921079170,"s":"BTCUSDT","U":6511121367,"u":6511121368,"b":[],"a":[["15514.89000000","0.20000000"],["15516.74000000","0.00000000"]]}}
2020-11-09T11:24:39.27857 btcusdt {"stream":"btcusdt@depth@100ms","data":{"e":"depthUpdate","E":1604921079270,"s":"BTCUSDT","U":6511121369,"u":6511121369,"b":[["15505.01000000","0.20000000"]],"a":[]}}
2020-11-09T11:24:39.37918 btcusdt {"stream":"btcusdt@depth@100ms","data":{"e":"depthUpdate","E":1604921079371,"s":"BTCUSDT","U":6511121370,"u":6511121374,"b":[["15509.15000000","0.15680600"],["15507.57000000","0.00000000"],["15435.72000000","0.00647800"]],"a":[["15513.30000000","0.02162100"],["15518.62000000","0.86264600"]]}}
2020-11-09T11:24:39.47847 btcusdt {"stream":"btcusdt@depth@100ms","data":{"e":"depthUpdate","E":1604921079471,"s":"BTCUSDT","U":6511121375,"u":6511121407,"b":[["15513.81000000","0.25000000"],["15513.75000000","0.00690000"],["15513.30000000","4.65000000"],["15513.29000000","3.36365100"],["15513.27000000","0.00000000"],["15513.01000000","0.00000000"],["15512.95000000","0.00000000"],["15511.36000000","0.00000000"],["15511.00000000","0.00969100"],["15510.85000000","0.00000000"],["15510.72000000","0.50000000"],["15509.14000000","0.05000000"],["15505.01000000","0.00000000"],["15497.07000000","0.00000000"]],"a":[["15513.30000000","0.00000000"],["15513.82000000","5.80690000"],["15514.22000000","0.00000000"],["15514.89000000","0.05010500"],["15514.90000000","0.00000000"],["15516.14000000","0.50000000"],["15516.75000000","0.20690000"],["15518.96000000","0.25758800"]]}}
2020-11-09T11:24:39.57966 btcusdt {"stream":"btcusdt@depth@100ms","data":{"e":"depthUpdate","E":1604921079571,"s":"BTCUSDT","U":6511121408,"u":6511121430,"b":[["15513.30000000","0.00000000"],["15513.29000000","2.82850000"],["15509.58000000","0.05000000"],["15509.14000000","0.00000000"],["15505.03000000","0.01900000"],["15501.89000000","0.00000000"],["15203.02000000","0.00000000"]],"a":[["15513.82000000","6.19970300"],["15516.86000000","0.00000000"],["15517.44000000","0.00000000"],["15517.78000000","0.00000000"],["15518.08000000","0.05000000"],["15518.43000000","0.01000000"],["15519.59000000","0.00000000"],["15519.99000000","0.00000000"],["15520.23000000","0.01000000"],["15520.63000000","0.01500000"],["15523.65000000","0.01382400"],["15524.18000000","0.00000000"],["15526.70000000","0.00000000"],["15622.00000000","0.00000000"]]}}
2020-11-09T11:24:39.67942 btcusdt {"stream":"btcusdt@depth@100ms","data":{"e":"depthUpdate","E":1604921079671,"s":"BTCUSDT","U":6511121431,"u":6511121453,"b":[["15513.81000000","0.00000000"],["15513.75000000","0.84030000"],["15513.29000000","0.00200000"],["15512.83000000","0.00000000"],["15510.44000000","0.00000000"],["15509.76000000","0.11427900"],["15509.15000000","0.00000000"],["15509.02000000","0.00000000"],["15506.70000000","0.10000000"]],"a":[["15513.76000000","6.25311500"],["15513.79000000","0.00690000"],["15513.81000000","0.05523600"],["15513.82000000","7.70170300"],["15514.50000000","0.05010500"],["15514.89000000","0.00000000"],["15517.03000000","0.01772200"]]}}
2020-11-09T11:24:39.78194 btcusdt {"stream":"btcusdt@depth@100ms","data":{"e":"depthUpdate","E":1604921079771,"s":"BTCUSDT","U":6511121454,"u":6511121473,"b":[["15513.35000000","0.00718300"],["15513.17000000","0.15000000"],["15513.04000000","0.00550400"],["15506.71000000","0.15680600"],["15505.16000000","0.02500000"],["15504.27000000","0.20000000"]],"a":[["15513.76000000","8.81724700"],["15513.82000000","7.39841200"],["15515.01000000","0.00651500"],["15516.42000000","0.00000000"],["15516.75000000","0.00690000"],["15516.85000000","0.00000000"],["15516.93000000","0.00606000"],["15520.08000000","0.40607100"],["15529.98000000","0.02500000"],["15530.31000000","0.24000000"]]}}
2020-11-09T11:24:39.88003 btcusdt {"stream":"btcusdt@depth@100ms","data":{"e":"depthUpdate","E":1604921079871,"s":"BTCUSDT","U":6511121474,"u":6511121489,"b":[["15510.73000000","0.25000000"],["15510.02000000","0.38567600"],["15509.14000000","0.71950200"],["15506.69000000","0.00000000"],["15505.84000000","1.25000000"],["15504.81000000","0.00000000"],["15504.27000000","0.00000000"],["15435.72000000","0.00000000"]],"a":[["15513.80000000","0.78253600"],["15514.96000000","0.14500000"],["15517.26000000","0.20000000"],["15519.99000000","0.02422500"],["15522.33000000","0.40548900"],["15523.75000000","0.00000000"],["15624.00000000","0.01268300"]]}}
2020-11-09T11:24:39.97795 btcusdt {"stream":"btcusdt@depth@100ms","data":{"e":"depthUpdate","E":1604921079971,"s":"BTCUSDT","U":6511121490,"u":6511121511,"b":[["15513.75000000","0.00690000"],["15513.04000000","0.02188800"],["15512.52000000","0.00000000"],["15510.48000000","0.00000000"],["15509.77000000","0.05000000"],["15509.58000000","0.00000000"],["15508.75000000","2.59800000"],["15506.71000000","0.00000000"],["15506.58000000","0.02106400"],["15502.15000000","0.50425400"],["15501.70000000","0.00000000"],["15500.64000000","1.00850800"],["15500.56000000","0.00000000"]],"a":[["15514.15000000","0.05010500"],["15514.50000000","0.00000000"],["15515.29000000","0.12895300"],["15516.13000000","0.12894900"],["15517.03000000","0.00000000"],["15520.07000000","0.02968800"],["15522.11000000","0.00000000"],["15526.57000000","0.00000000"]]}}
2020-11-09T11:24:40.08018 btcusdt {"stream":"btcusdt@depth@100ms","data":{"e":"depthUpdate","E":1604921080071,"s":"BTCUSDT","U":6511121512,"u":6511121520,"b":[],"a":[["15513.76000000","9.00224700"],["15517.47000000","0.01477200"],["15519.99000000","0.45878500"],["15522.33000000","0.00000000"],["15522.71000000","0.00000000"],["15523.82000000","0.00000000"],["15525.58000000","0.00000000"],["15526.16000000","0.00000000"]]}}
2020-11-09T11:24:40.17848 btcusdt {"stream":"btcusdt@depth@100ms","data":{"e":"depthUpdate","E":1604921080171,"s":"BTCUSDT","U":6511121521,"u":6511121522,"b":[],"a":[["15516.80000000","0.06713900"],["15524.96000000","0.00000000"]]}}
2020-11-09T11:24:40.37869 btcusdt {"stream":"btcusdt@depth@100ms","data":{"e":"depthUpdate","E":1604921080371,"s":"BTCUSDT","U":6511121523,"u":6511121524,"b":[["15436.18000000","0.00647800"]],"a":[["15515.32000000","0.18575200"]]}}
2020-11-09T11:24:40.47970 btcusdt {"stream":"btcusdt@depth@100ms","data":{"e":"depthUpdate","E":1604921080471,"s":"BTCUSDT","U":6511121525,"u":6511121530,"b":[],"a":[["15513.76000000","8.60324700"],["15516.93000000","0.00000000"],["15517.12000000","0.00946700"],["15517.47000000","0.00000000"],["15517.50000000","0.01550700"]]}}
2020-11-09T11:24:40.57864 btcusdt {"stream":"btcusdt@depth@100ms","data":{"e":"depthUpdate","E":1604921080571,"s":"BTCUSDT","U":6511121531,"u":6511121535,"b":[["15513.75000000","0.00612900"],["15498.59000000","0.00000000"],["15494.74000000","1.00000000"],["15494.23000000","0.00000000"]],"a":[["15515.29000000","0.00000000"]]}}
2020-11-09T11:24:40.68144 btcusdt {"stream":"btcusdt@depth@100ms","data":{"e":"depthUpdate","E":1604921080671,"s":"BTCUSDT","U":6511121536,"u":6511121540,"b":[["15471.50000000","0.00000000"],["15469.02000000","0.50000000"],["15465.91000000","0.00000000"],["15399.00000000","0.37683000"]],"a":[["15517.04000000","0.03353400"]]}}
2020-11-09T11:24:40.87787 btcusdt {"stream":"btcusdt@depth@100ms","data":{"e":"depthUpdate","E":1604921080871,"s":"BTCUSDT","U":6511121541,"u":6511121552,"b":[["15513.35000000","0.00000000"],["15513.04000000","0.00550400"],["15510.52000000","0.01697800"],["15510.23000000","0.00863200"],["15470.00000000","2.03393600"],["15420.00000000","1.08412300"]],"a":[["15514.15000000","0.00000000"],["15514.53000000","0.01248200"],["15517.12000000","0.00000000"],["15517.50000000","0.00000000"],["15519.99000000","0.48847300"],["15520.07000000","0.00000000"]]}}
2020-11-09T11:24:40.98041 btcusdt {"stream":"btcusdt@depth@100ms","data":{"e":"depthUpdate","E":1604921080971,"s":"BTCUSDT","U":6511121553,"u":6511121559,"b":[["15513.29000000","0.00000000"],["15386.17000000","0.00000000"],["15384.62000000","0.38349900"]],"a":[["15514.06000000","0.05010500"],["15514.10000000","0.00000000"],["15514.22000000","0.00869800"]]}}
2020-11-09T11:24:41.17948 btcusdt {"stream":"btcusdt@depth@100ms","data":{"e":"depthUpdate","E":1604921081172,"s":"BTCUSDT","U":6511121560,"u":6511121564,"b":[["15510.52000000","0.00000000"],["15510.26000000","0.01295000"],["15506.70000000","0.00000000"]],"a":[["15514.22000000","0.00695200"]]}}
2020-11-09T11:24:41.27819 btcusdt {"stream":"btcusdt@depth@100ms","data":{"e":"depthUpdate","E":1604921081272,"s":"BTCUSDT","U":6511121565,"u":6511121569,"b":[["15509.15000000","0.10000000"]],"a":[["15513.76000000","8.50324700"],["15514.22000000","0.00000000"],["15514.95000000","0.10000000"],["15514.96000000","0.00000000"]]}}
2020-11-09T11:24:41.37843 btcusdt {"stream":"btcusdt@depth@100ms","data":{"e":"depthUpdate","E":1604921081372,"s":"BTCUSDT","U":6511121570,"u":6511121572,"b":[["15436.18000000","0.00000000"]],"a":[["15530.28000000","0.00000000"],["15530.47000000","0.97506100"]]}}
2020-11-09T11:24:41.47769 btcusdt {"stream":"btcusdt@depth@100ms","data":{"e":"depthUpdate","E":1604921081472,"s":"BTCUSDT","U":6511121573,"u":6511121573,"b":[],"a":[["15513.76000000","8.44321200"]]}}
2020-11-09T11:24:41.59078 btcusdt {"stream":"btcusdt@depth@100ms","data":{"e":"depthUpdate","E":1604921081572,"s":"BTCUSDT","U":6511121574,"u":6511121607,"b":[["15513.75000000","0.00000000"],["15513.23000000","0.00000000"],["15513.17000000","0.00000000"],["15513.04000000","0.00000000"],["15512.98000000","0.00000000"],["15511.24000000","0.00000000"],["15511.07000000","0.00000000"],["15511.00000000","0.00000000"],["15510.73000000","0.00000000"],["15510.72000000","0.00000000"],["15510.47000000","0.00000000"],["15510.46000000","0.00000000"],["15510.26000000","0.00000000"],["15510.23000000","0.00000000"],["15510.20000000","0.00000000"],["15510.17000000","0.00000000"],["15510.15000000","0.00000000"],["15510.10000000","0.00000000"],["15510.02000000","0.00000000"],["15510.01000000","0.00000000"],["15510.00000000","0.00000000"],["15509.97000000","0.00000000"],["15509.95000000","0.00000000"],["15509.77000000","0.00000000"],["15509.76000000","0.00000000"],["15509.57000000","0.00000000"],["15509.56000000","0.00000000"],["15509.20000000","0.00000000"],["15509.15000000","0.00000000"],["15509.14000000","0.00000000"],["15509.13000000","0.00000000"],["15509.00000000","0.00000000"],["15508.99000000","4.93424400"],["15508.90000000","0.05010000"],["15508.76000000","0.16164000"],["15508.75000000","0.00000000"],["15508.74000000","0.00000000"],["15508.63000000","0.00000000"],["15507.56000000","0.00000000"],["15506.59000000","0.15680600"],["15495.43000000","1.50000000"],["15494.74000000","0.00000000"],["15479.40000000","0.00000000"]],"a":[["15509.00000000","0.00096300"],["15511.26000000","0.00690000"],["15513.34000000","0.08916700"],["15513.61000000","0.05123700"],["15513.75000000","0.34570100"],["15513.76000000","8.00324700"],["15513.80000000","0.00000000"],["15514.06000000","0.00000000"],["15515.14000000","0.00000000"],["15516.59000000","1.61700000"],["15516.92000000","0.25000000"],["15518.77000000","0.00000000"],["15519.38000000","0.00000000"],["15519.62000000","0.00000000"],["15625.00000000","12.36453300"]]}}
2020-11-09T11:24:41.68776 btcusdt {"stream":"btcusdt@depth@100ms","data":{"e":"depthUpdate","E":1604921081672,"s":"BTCUSDT","U":6511121608,"u":6511121705,"b":[["15508.99000000","14.46892800"],["15508.98000000","0.00000000"],["15508.90000000","0.00000000"],["15508.76000000","0.03268400"],["15508.75000000","0.00000000"],["15508.64000000","0.00000000"],["15508.48000000","0.11427900"],["15508.25000000","0.12500000"],["15508.11000000","0.00000000"],["15507.83000000","0.04000000"],["15507.66000000","1.28000000"],["15506.56000000","1.58300000"],["15506.44000000","1.59300000"],["15505.84000000","0.00000000"],["15505.81000000","1.25000000"],["15504.54000000","0.00000000"],["15503.27000000","0.00000000"],["15502.02000000","0.00000000"],["15501.19000000","0.00000000"],["15500.08000000","0.14850000"],["15497.26000000","0.00288000"],["15497.19000000","1.00000000"],["15494.39000000","0.14850000"],["15491.64000000","0.00000000"],["15490.22000000","0.31500000"],["15488.20000000","0.30300000"],["15473.28000000","0.00000000"]],"a":[["15509.00000000","0.50000500"],["15513.33000000","0.04458500"],["15513.69000000","3.63257300"],["15513.70000000","0.00000000"],["15513.72000000","0.00000000"],["15513.74000000","0.00000000"],["15513.75000000","0.83878800"],["15513.76000000","7.55611500"],["15513.81000000","0.00000000"],["15513.82000000","7.39641200"],["15514.40000000","0.29700000"],["15514.99000000","0.01000000"],["15515.47000000","0.01700000"],["15515.58000000","0.00000000"],["15515.96000000","0.01000000"],["15516.14000000","0.61427900"],["15516.30000000","0.01700000"],["15516.36000000","0.01500000"],["15516.82000000","1.74800000"],["15517.18000000","0.14850000"],["15517.69000000","0.00000000"],["15517.85000000","1.58300000"],["15518.03000000","1.59300000"],["15518.08000000","0.00000000"],["15518.13000000","0.00690000"],["15518.31000000","0.00000000"],["15518.43000000","0.00000000"],["15518.53000000","0.32100000"],["15518.86000000","0.30300000"],["15518.89000000","0.20000000"],["15520.23000000","0.00000000"],["15520.63000000","0.00000000"],["15521.66000000","0.00000000"],["15521.87000000","0.00000000"],["15522.15000000","0.00000000"],["15531.91000000","0.00000000"],["15560.15000000","0.00000000"]]}}
2020-11-09T11:24:41.77981 btcusdt {"stream":"btcusdt@depth@100ms","data":{"e":"depthUpdate","E":1604921081772,"s":"BTCUSDT","U":6511121706,"u":6511121770,"b":[["15510.12000000","0.00690000"],["15509.07000000","0.04836700"],["15509.06000000","0.04830400"],["15509.04000000","0.09274400"],["15509.02000000","0.04830400"],["15509.00000000","5.05128900"],["15508.99000000","3.77749900"],["15507.66000000","0.00000000"],["15506.56000000","0.00000000"],["15506.44000000","0.00000000"],["15506.04000000","1.58300000"],["15505.81000000","0.48000000"],["15504.31000000","0.22500000"],["15504.27000000","0.03100000"],["15503.61000000","0.00000000"],["15503.60000000","0.05000000"],["15500.74000000","0.00000000"],["15500.25000000","0.00000000"],["15500.18000000","0.00000000"],["15499.31000000","0.30000000"],["15497.53000000","0.50000000"],["15497.25000000","0.00000000"],["15495.43000000","0.00000000"],["15484.31000000","0.00000000"]],"a":[["15509.00000000","0.00000000"],["15510.13000000","0.00690000"],["15510.48000000","0.50000000"],["15511.26000000","0.00342100"],["15512.55000000","0.00000000"],["15513.33000000","0.00000000"],["15513.68000000","0.00000000"],["15513.69000000","0.00000000"],["15513.75000000","0.05625200"],["15513.76000000","7.55411500"],["15514.22000000","0.00868900"],["15514.23000000","0.00000000"],["15514.95000000","0.00000000"],["15514.97000000","0.00000000"],["15515.47000000","0.00000000"],["15516.30000000","0.00000000"],["15516.40000000","0.01700000"],["15517.26000000","0.00000000"],["15518.53000000","0.00000000"],["15518.78000000","2.50000000"],["15524.79000000","0.12882600"],["15528.91000000","0.00000000"],["15531.04000000","0.00000000"],["15560.69000000","0.03100000"]]}}
2020-11-09T11:24:41.88018 btcusdt {"stream":"btcusdt@depth@100ms","data":{"e":"depthUpdate","E":1604921081872,"s":"BTCUSDT","U":6511121771,"u":6511121841,"b":[["15510.12000000","8.21104300"],["15509.91000000","0.00674500"],["15509.18000000","0.00000000"],["15509.12000000","0.04379000"],["15509.06000000","0.00000000"],["15509.04000000","0.04637200"],["15509.00000000","0.09128900"],["15508.99000000","2.52860500"],["15508.77000000","0.00000000"],["15508.71000000","0.00000000"],["15508.25000000","0.00000000"],["15507.83000000","0.00000000"],["15506.59000000","0.00000000"],["15505.90000000","1.59300000"],["15505.82000000","0.72000000"],["15505.64000000","0.15680600"],["15503.29000000","1.25000000"],["15502.76000000","0.20000000"],["15502.75000000","0.00000000"],["15498.30000000","0.10000000"],["15497.53000000","0.80000000"],["15492.34000000","0.00000000"],["15489.88000000","0.05819100"],["15432.56000000","0.00647900"]],"a":[["15510.13000000","0.50370000"],["15510.48000000","0.00000000"],["15511.25000000","0.00128800"],["15513.32000000","0.10000000"],["15513.74000000","0.78253600"],["15513.75000000","0.00625200"],["15514.22000000","0.00624600"],["15514.99000000","0.06000000"],["15515.96000000","0.00000000"],["15516.13000000","1.71194900"],["15516.32000000","1.59300000"],["15516.42000000","0.01700000"],["15516.54000000","0.01000000"],["15516.81000000","0.06191900"],["15517.21000000","2.00000000"],["15517.27000000","0.00000000"],["15517.60000000","2.00000000"],["15517.85000000","0.00000000"],["15518.03000000","0.00000000"],["15518.04000000","1.25000000"],["15518.18000000","3.44000000"],["15518.78000000","0.50000000"],["15519.18000000","0.00000000"],["15519.77000000","0.00000000"],["15519.99000000","0.45878500"],["15521.44000000","0.00000000"],["15523.26000000","0.15000000"],["15530.31000000","0.00000000"]]}}
2020-11-09T11:24:41.97904 btcusdt {"stream":"btcusdt@depth@100ms","data":{"e":"depthUpdate","E":1604921081972,"s":"BTCUSDT","U":6511121842,"u":6511121871,"b":[["15510.12000000","8.60984200"],["15508.48000000","0.00000000"],["15505.81000000","0.00000000"],["15504.93000000","0.08000000"],["15500.62000000","0.10085300"],["15499.15000000","0.00000000"],["15497.69000000","0.00000000"],["15493.35000000","0.00000000"],["15490.69000000","0.23545400"]],"a":[["15510.13000000","0.50050000"],["15513.73000000","0.78253600"],["15513.74000000","0.00000000"],["15514.22000000","0.00621200"],["15514.52000000","0.08000000"],["15515.29000000","0.12894800"],["15515.69000000","0.16118000"],["15517.17000000","0.00000000"],["15518.04000000","0.00000000"],["15519.71000000","0.02382800"],["15519.76000000","0.03241800"],["15519.99000000","0.40548900"],["15522.66000000","0.09618800"],["15522.98000000","0.00000000"],["15523.27000000","1.25000000"]]}}
2020-11-09T11:24:42.07920 btcusdt {"stream":"btcusdt@depth@100ms","data":{"e":"depthUpdate","E":1604921082072,"s":"BTCUSDT","U":6511121872,"u":6511121920,"b":[["15510.12000000","10.38267800"],["15509.35000000","0.01327400"],["15509.12000000","0.00000000"],["15509.07000000","0.00000000"],["15509.04000000","0.00000000"],["15509.02000000","0.00000000"],["15508.99000000","2.34860500"],["15507.38000000","0.11427900"],["15507.27000000","0.08000000"],["15504.32000000","0.50000000"],["15504.31000000","0.00000000"],["15503.29000000","1.25000000"],["15500.26000000","0.00000000"],["15495.37000000","1.08232000"],["15486.63000000","0.02396400"],["15444.22000000","0.00000000"]],"a":[["15510.13000000","0.47970000"],["15513.68000000","0.00000000"],["15513.73000000","0.00000000"],["15513.87000000","0.01296400"],["15514.53000000","0.00000000"],["15514.85000000","0.11427900"],["15514.95000000","0.32100000"],["15515.34000000","0.01700000"],["15515.36000000","0.01700000"],["15516.13000000","1.58300000"],["15516.14000000","0.50000000"],["15516.40000000","0.00000000"],["15516.42000000","0.00000000"],["15516.48000000","1.04000000"],["15516.58000000","0.02422500"],["15516.81000000","0.49647900"],["15516.85000000","0.72000000"],["15517.21000000","0.00000000"],["15517.45000000","0.00000000"],["15517.60000000","0.00000000"],["15518.05000000","1.25000000"],["15518.18000000","0.00000000"],["15519.98000000","0.02806500"],["15519.99000000","0.45568200"],["15523.27000000","0.00000000"],["15530.47000000","0.00000000"]]}}
2020-11-09T11:24:42.17982 btcusdt {"stream":"btcusdt@depth@100ms","data":{"e":"depthUpdate","E":1604921082172,"s":"BTCUSDT","U":6511121921,"u":6511121934,"b":[["15510.12000000","15.68267800"],["15503.18000000","0.00000000"],["15488.34000000","0.00000000"],["15459.10000000","0.00000000"]],"a":[["15510.13000000","0.47001700"],["15515.29000000","0.00000000"],["15515.69000000","0.00000000"],["15516.36000000","0.00000000"],["15516.48000000","0.28000000"],["15516.85000000","0.24000000"],["15516.94000000","0.01500000"],["15517.45000000","0.28000000"]]}}
2020-11-09T11:24:42.27955 btcusdt {"stream":"btcusdt@depth@100ms","data":{"e":"depthUpdate","E":1604921082272,"s":"BTCUSDT","U":6511121935,"u":6511121945,"b":[["15510.12000000","15.75002000"],["15508.99000000","2.22508300"],["15502.17000000","0.00000000"],["15501.32000000","0.13428900"],["15500.64000000","1.01156800"],["15500.15000000","0.13416900"],["15491.59000000","0.30600000"]],"a":[["15510.13000000","0.46500000"],["15515.79000000","1.74800000"],["15516.82000000","0.00000000"],["15528.16000000","1.06554500"]]}}
2020-11-09T11:24:42.38390 btcusdt {"stream":"btcusdt@depth@100ms","data":{"e":"depthUpdate","E":1604921082372,"s":"BTCUSDT","U":6511121946,"u":6511121981,"b":[["15510.68000000","6.97101000"],["15510.34000000","0.00000000"],["15510.19000000","0.00000000"],["15510.17000000","0.02898200"],["15510.15000000","0.03312200"],["15510.14000000","0.03019000"],["15510.13000000","0.00000000"],["15510.12000000","2.51329400"],["15504.26000000","0.00000000"],["15502.39000000","0.03361800"]],"a":[["15510.13000000","0.00000000"],["15510.69000000","0.50561200"],["15511.39000000","0.04918600"],["15513.31000000","0.20000000"],["15513.61000000","0.00000000"],["15514.95000000","0.00000000"],["15518.05000000","0.00000000"],["15518.89000000","0.00000000"],["15519.77000000","1.00000000"],["15521.25000000","0.00000000"],["15522.29000000","0.00000000"],["15523.31000000","0.00000000"]]}}
2020-11-09T11:24:42.47963 btcusdt {"stream":"btcusdt@depth@100ms","data":{"e":"depthUpdate","E":1604921082472,"s":"BTCUSDT","U":6511121982,"u":6511122008,"b":[["15510.68000000","9.36291400"],["15510.12000000","2.11449500"],["15509.91000000","0.00000000"],["15509.00000000","0.00128900"],["15507.95000000","0.11427900"],["15507.38000000","0.00000000"],["15505.83000000","0.05000000"],["15503.60000000","0.00000000"],["15497.19000000","0.00000000"],["15495.03000000","1.00000000"],["15491.34000000","0.10000000"],["15460.10000000","0.03020000"]],"a":[["15510.69000000","0.44368600"],["15514.22000000","0.00000000"],["15514.99000000","0.05000000"],["15515.33000000","0.01000000"],["15516.54000000","0.00000000"],["15516.94000000","0.00000000"],["15517.10000000","0.01000000"],["15517.50000000","0.01500000"],["15521.25000000","1.25000000"],["15541.24000000","0.00000000"]]}}
2020-11-09T11:24:42.57925 btcusdt {"stream":"btcusdt@depth@100ms","data":{"e":"depthUpdate","E":1604921082572,"s":"BTCUSDT","U":6511122009,"u":6511122017,"b":[["15510.68000000","9.44827100"],["15510.17000000","0.00000000"],["15510.15000000","0.00000000"],["15510.14000000","0.00000000"],["15507.59000000","0.00713900"]],"a":[["15510.69000000","0.44048600"],["15511.41000000","0.00992800"],["15750.00000000","68.18015200"]]}}
2020-11-09T11:24:42.68744 btcusdt {"stream":"btcusdt@depth@100ms","data":{"e":"depthUpdate","E":1604921082672,"s":"BTCUSDT","U":6511122018,"u":6511122034,"b":[["15510.68000000","9.41099000"],["15510.12000000","2.04715300"],["15509.35000000","0.00000000"],["15506.36000000","0.01326400"],["15501.67000000","1.00861400"],["15500.64000000","0.00306000"],["15481.45000000","0.03875600"]],"a":[["15510.69000000","0.43928600"],["15510.90000000","0.01642500"],["15513.82000000","2.09641200"],["15513.87000000","0.00000000"],["15515.51000000","0.32100000"],["15516.14000000","0.00000000"],["15516.48000000","0.59800000"]]}}
2020-11-09T11:24:42.78041 btcusdt {"stream":"btcusdt@depth@100ms","data":{"e":"depthUpdate","E":1604921082772,"s":"BTCUSDT","U":6511122035,"u":6511122047,"b":[["15510.68000000","9.47119700"],["15507.59000000","0.00000000"],["15506.46000000","0.00873100"],["15504.33000000","0.47715400"],["15473.00000000","0.00000000"],["15284.00000000","0.10970200"]],"a":[["15510.69000000","0.43454100"],["15511.41000000","0.00000000"],["15514.40000000","0.00000000"],["15516.80000000","0.00000000"],["15522.10000000","0.06714400"],["15544.74000000","0.00000000"]]}}
2020-11-09T11:24:42.87961 btcusdt {"stream":"btcusdt@depth@100ms","data":{"e":"depthUpdate","E":1604921082872,"s":"BTCUSDT","U":6511122048,"u":6511122067,"b":[["15432.56000000","0.00000000"],["15420.00000000","0.97585000"],["15360.63000000","0.00000000"]],"a":[["15510.69000000","0.43134100"],["15516.58000000","0.00000000"],["15516.81000000","0.06130200"],["15517.04000000","0.00000000"],["15518.85000000","0.40548900"],["15519.49000000","0.02968800"],["15519.71000000","0.00000000"],["15519.76000000","0.00690000"],["15519.98000000","0.00000000"],["15519.99000000","0.47990700"],["15521.83000000","0.03354200"],["15522.71000000","0.02382800"],["15522.83000000","0.02551800"],["15523.84000000","0.02806500"],["15524.87000000","0.05681600"],["15526.87000000","0.00000000"]]}}
2020-11-09T11:24:42.97860 btcusdt {"stream":"btcusdt@depth@100ms","data":{"e":"depthUpdate","E":1604921082972,"s":"BTCUSDT","U":6511122068,"u":6511122078,"b":[["15506.74000000","0.01839200"],["15506.59000000","0.10825800"],["15506.36000000","0.00000000"],["15472.00000000","2.02510000"],["15441.91000000","0.24000000"]],"a":[["15516.47000000","0.12895100"],["15516.81000000","0.03223100"],["15518.85000000","0.43456000"],["15519.99000000","0.02422500"],["15524.32000000","0.45568200"],["15526.77000000","0.24000000"]]}}
2020-11-09T11:24:43.08096 btcusdt {"stream":"btcusdt@depth@100ms","data":{"e":"depthUpdate","E":1604921083073,"s":"BTCUSDT","U":6511122079,"u":6511122084,"b":[["15499.07000000","0.00000000"],["15491.94000000","0.87000000"],["15474.39000000","0.00000000"],["15360.23000000","0.00067500"]],"a":[["15510.69000000","0.42928700"],["15544.82000000","0.01210000"]]}}
2020-11-09T11:24:43.17967 btcusdt {"stream":"btcusdt@depth@100ms","data":{"e":"depthUpdate","E":1604921083173,"s":"BTCUSDT","U":6511122085,"u":6511122090,"b":[["15506.60000000","0.15680600"],["15505.64000000","0.00000000"]],"a":[["15510.69000000","0.42468700"],["15515.33000000","0.00000000"],["15515.35000000","0.01000000"],["15551.96000000","0.00120000"]]}}
2020-11-09T11:24:43.37986 btcusdt {"stream":"btcusdt@depth@100ms","data":{"e":"depthUpdate","E":1604921083373,"s":"BTCUSDT","U":6511122091,"u":6511122093,"b":[["15433.12000000","0.00647900"]],"a":[["15510.69000000","0.42668700"],["15577.22000000","0.00000000"]]}}
2020-11-09T11:24:43.48021 btcusdt {"stream":"btcusdt@depth@100ms","data":{"e":"depthUpdate","E":1604921083473,"s":"BTCUSDT","U":6511122094,"u":6511122098,"b":[["15506.82000000","0.01750700"],["15506.74000000","0.00000000"]],"a":[["15510.69000000","0.36849000"],["15515.00000000","24.17140300"]]}}
2020-11-09T11:24:43.57953 btcusdt {"stream":"btcusdt@depth@100ms","data":{"e":"depthUpdate","E":1604921083573,"s":"BTCUSDT","U":6511122099,"u":6511122104,"b":[["15505.03000000","0.00000000"],["15396.00000000","0.10827300"]],"a":[["15510.90000000","0.00000000"],["15511.46000000","0.01229100"],["15523.65000000","0.00000000"],["15577.62000000","0.00067100"]]}}
2020-11-09T11:24:43.68658 btcusdt {"stream":"btcusdt@depth@100ms","data":{"e":"depthUpdate","E":1604921083673,"s":"BTCUSDT","U":6511122105,"u":6511122112,"b":[["15508.99000000","2.00690000"],["15508.76000000","0.00000000"],["15507.13000000","0.00840500"],["15506.46000000","0.00000000"],["15502.28000000","0.00000000"]],"a":[["15511.15000000","0.00746700"]]}}
2020-11-09T11:24:43.78039 btcusdt {"stream":"btcusdt@depth@100ms","data":{"e":"depthUpdate","E":1604921083773,"s":"BTCUSDT","U":6511122113,"u":6511122116,"b":[["15505.01000000","0.01900000"],["15442.05000000","0.24000000"]],"a":[["15521.88000000","0.01382400"],["15526.83000000","0.24000000"]]}}
2020-11-09T11:24:43.87962 btcusdt {"stream":"btcusdt@depth@100ms","data":{"e":"depthUpdate","E":1604921083873,"s":"BTCUSDT","U":6511122117,"u":6511122124,"b":[["15507.44000000","0.01635500"],["15506.82000000","0.00000000"],["15500.64000000","0.03659900"]],"a":[["15511.46000000","0.01575800"],["15612.00000000","0.10827300"]]}}
2020-11-09T11:24:43.97904 btcusdt {"stream":"btcusdt@depth@100ms","data":{"e":"depthUpdate","E":1604921083973,"s":"BTCUSDT","U":6511122125,"u":6511122129,"b":[["15510.68000000","9.40802200"],["15505.91000000","0.05000000"],["15505.83000000","0.00000000"]],"a":[["15510.69000000","0.36849000"]]}}
2020-11-09T11:24:44.07921 btcusdt {"stream":"btcusdt@depth@100ms","data":{"e":"depthUpdate","E":1604921084073,"s":"BTCUSDT","U":6511122130,"u":6511122132,"b":[["15470.00000000","2.03232000"]],"a":[["15510.69000000","0.49649000"],["15570.00000000","48.91536300"]]}}
2020-11-09T11:24:44.24616 btcusdt {"stream":"btcusdt@depth@100ms","data":{"e":"depthUpdate","E":1604921084173,"s":"BTCUSDT","U":6511122133,"u":6511122138,"b":[["15471.91000000","0.25000000"]],"a":[["15511.46000000","0.01216700"],["15515.33000000","0.01000000"],["15515.35000000","0.00000000"],["15549.46000000","0.25000000"]]}}
2020-11-09T11:24:44.27967 btcusdt {"stream":"btcusdt@depth@100ms","data":{"e":"depthUpdate","E":1604921084273,"s":"BTCUSDT","U":6511122139,"u":6511122143,"b":[["15417.00000000","0.37683000"]],"a":[["15511.46000000","0.01881600"],["15516.75000000","0.20690000"],["15569.50000000","0.00000000"]]}}
2020-11-09T11:24:44.38428 btcusdt {"stream":"btcusdt@depth@100ms","data":{"e":"depthUpdate","E":1604921084373,"s":"BTCUSDT","U":6511122144,"u":6511122145,"b":[],"a":[["15511.46000000","0.00000000"],["15516.75000000","0.00690000"]]}}
2020-11-09T11:24:44.48098 btcusdt {"stream":"btcusdt@depth@100ms","data":{"e":"depthUpdate","E":1604921084473,"s":"BTCUSDT","U":6511122146,"u":6511122154,"b":[["15510.68000000","9.26410600"],["15508.07000000","0.50000000"]],"a":[["15510.69000000","4.93600200"],["15511.46000000","0.01510300"],["15514.23000000","0.50000000"],["15567.50000000","2.00000000"]]}}
2020-11-09T11:24:44.58077 btcusdt {"stream":"btcusdt@depth@100ms","data":{"e":"depthUpdate","E":1604921084573,"s":"BTCUSDT","U":6511122155,"u":6511122159,"b":[["15510.68000000","8.86530700"]],"a":[["15510.69000000","0.78698900"],["15511.46000000","0.01433000"]]}}
2020-11-09T11:24:44.68116 btcusdt {"stream":"btcusdt@depth@100ms","data":{"e":"depthUpdate","E":1604921084673,"s":"BTCUSDT","U":6511122160,"u":6511122164,"b":[["15510.68000000","9.21629400"],["14500.00000000","265.07951400"]],"a":[["15510.69000000","0.43600200"],["15511.46000000","0.01206400"]]}}
2020-11-09T11:24:44.78105 btcusdt {"stream":"btcusdt@depth@100ms","data":{"e":"depthUpdate","E":1604921084774,"s":"BTCUSDT","U":6511122165,"u":6511122165,"b":[["15420.00000000","0.59902000"]],"a":[]}}
2020-11-09T11:24:44.97991 btcusdt {"stream":"btcusdt@depth@100ms","data":{"e":"depthUpdate","E":1604921084974,"s":"BTCUSDT","U":6511122166,"u":6511122168,"b":[["15396.00000000","0.00000000"]],"a":[["15511.46000000","0.01648600"]]}}
2020-11-09T11:24:45.08400 btcusdt {"stream":"btcusdt@depth@100ms","data":{"e":"depthUpdate","E":1604921085074,"s":"BTCUSDT","U":6511122169,"u":6511122173,"b":[],"a":[["15511.46000000","0.01720000"],["15524.11000000","0.45568200"],["15524.32000000","0.00000000"],["15624.00000000","0.00168300"]]}}
2020-11-09T11:24:45.18092 btcusdt {"stream":"btcusdt@depth@100ms","data":{"e":"depthUpdate","E":1604921085174,"s":"BTCUSDT","U":6511122174,"u":6511122178,"b":[],"a":[["15511.46000000","0.01353100"],["15513.75000000","0.00000000"],["15515.31000000","0.01000000"],["15515.33000000","0.00000000"]]}}
2020-11-09T11:24:45.28315 btcusdt {"stream":"btcusdt@depth@100ms","data":{"e":"depthUpdate","E":1604921085274,"s":"BTCUSDT","U":6511122179,"u":6511122180,"b":[["15510.68000000","9.21268400"]],"a":[["15511.46000000","0.03183100"]]}}
2020-11-09T11:24:45.38309 btcusdt {"stream":"btcusdt@depth@100ms","data":{"e":"depthUpdate","E":1604921085374,"s":"BTCUSDT","U":6511122181,"u":6511122185,"b":[],"a":[["15510.69000000","0.43400200"],["15511.46000000","0.01987200"],["15622.00000000","0.01100000"]]}}
2020-11-09T11:24:45.48141 btcusdt {"stream":"btcusdt@depth@100ms","data":{"e":"depthUpdate","E":1604921085474,"s":"BTCUSDT","U":6511122186,"u":6511122188,"b":[],"a":[["15510.69000000","0.37170400"],["15511.46000000","0.00000000"]]}}
2020-11-09T11:24:45.58065 btcusdt {"stream":"btcusdt@depth@100ms","data":{"e":"depthUpdate","E":1604921085574,"s":"BTCUSDT","U":6511122189,"u":6511122190,"b":[["15417.00000000","0.48510300"]],"a":[["15510.69000000","0.36970400"]]}}
2020-11-09T11:24:45.78142 btcusdt {"stream":"btcusdt@depth@100ms","data":{"e":"depthUpdate","E":1604921085774,"s":"BTCUSDT","U":6511122191,"u":6511122193,"b":[["15396.00000000","0.37683000"]],"a":[["15516.47000000","0.00000000"],["15528.16000000","0.00000000"]]}}
2020-11-09T11:24:45.88152 btcusdt {"stream":"btcusdt@depth@100ms","data":{"e":"depthUpdate","E":1604921085874,"s":"BTCUSDT","U":6511122194,"u":6511122197,"b":[],"a":[["15511.46000000","0.01468400"],["15530.97000000","1.02236500"]]}}
2020-11-09T11:24:45.98163 btcusdt {"stream":"btcusdt@depth@100ms","data":{"e":"depthUpdate","E":1604921085974,"s":"BTCUSDT","U":6511122198,"u":6511122203,"b":[],"a":[["15511.46000000","0.01898600"],["15516.47000000","0.12895300"],["15516.80000000","0.20000000"]]}}
2020-11-09T11:24:46.08122 btcusdt {"stream":"btcusdt@depth@100ms","data":{"e":"depthUpdate","E":1604921086074,"s":"BTCUSDT","U":6511122204,"u":6511122205,"b":[],"a":[["15511.46000000","0.01904700"]]}}
2020-11-09T11:24:46.18177 btcusdt {"stream":"btcusdt@depth@100ms","data":{"e":"depthUpdate","E":1604921086174,"s":"BTCUSDT","U":6511122206,"u":6511122208,"b":[],"a":[["15515.31000000","0.00000000"],["15515.33000000","0.01000000"],["15516.80000000","0.00000000"]]}}
2020-11-09T11:24:46.38202 btcusdt {"stream":"btcusdt@depth@100ms","data":{"e":"depthUpdate","E":1604921086374,"s":"BTCUSDT","U":6511122209,"u":6511122211,"b":[["15502.55000000","0.12893000"]],"a":[["15511.46000000","0.01299200"]]}}
2020-11-09T11:24:46.48241 btcusdt {"stream":"btcusdt@depth@100ms","data":{"e":"depthUpdate","E":1604921086474,"s":"BTCUSDT","U":6511122212,"u":6511122221,"b":[["15510.68000000","9.21268400"],["15510.60000000","0.00000000"]],"a":[["15510.69000000","0.51989300"],["15511.39000000","0.00000000"],["15515.51000000","0.00000000"],["15516.47000000","0.00000000"]]}}
2020-11-09T11:24:46.58167 btcusdt {"stream":"btcusdt@depth@100ms","data":{"e":"depthUpdate","E":1604921086574,"s":"BTCUSDT","U":6511122222,"u":6511122226,"b":[["15510.68000000","13.86268400"],["15510.12000000","2.00690000"]],"a":[["15510.69000000","0.49293200"],["15515.51000000","0.32100000"]]}}
2020-11-09T11:24:46.86962 btcusdt {"stream":"btcusdt@depth@100ms","data":{"e":"depthUpdate","E":1604921086675,"s":"BTCUSDT","U":6511122227,"u":6511122238,"b":[["15510.68000000","13.11268400"],["15507.83000000","1.00000000"],["15506.88000000","0.03223200"],["15495.00000000","0.00816200"],["15441.91000000","0.00000000"]],"a":[["15510.69000000","0.48973200"],["15511.46000000","0.01646600"],["15526.77000000","0.00000000"]]}}
2020-11-09T11:24:46.86995 btcusdt {"stream":"btcusdt@depth@100ms","data":{"e":"depthUpdate","E":1604921086775,"s":"BTCUSDT","U":6511122239,"u":6511122243,"b":[["15510.68000000","13.61268400"]],"a":[["15510.69000000","0.48653200"],["15511.46000000","0.01648400"]]}}
